
# Created by Ruins mod version 14.4 Ingame Parser
# authoring Player: Mikhaila666

weight=1
embed_into_distance=0
acceptable_target_blocks=
unacceptable_target_blocks=flowing_water,water,flowing_lava,lava
dimensions=7,11,11
allowable_overhang=0
max_leveling=2
leveling_buffer=0
preserve_water=0
preserve_lava=0

rule1=0,100,minecraft:jungle_stairs-0
rule2=0,100,minecraft:jungle_stairs-2
rule3=0,100,minecraft:grass-0
rule4=0,100,minecraft:jungle_stairs-3
rule5=0,100,minecraft:dirt-0
rule6=0,100,minecraft:jungle_stairs-1
rule7=0,100,Railcraft:tile.railcraft.residual.heat-0
rule8=0,100,arsmagica2:liquidEssence-0
rule9=0,100,ganyssurface:fence_3-0
rule10=0,100,arsmagica2:Aum-0
rule11=0,100,minecraft:wooden_slab-3
rule12=0,100,minecraft:wooden_slab-11

layer
1,1,1,1,1,1,1,1,1,1,1
4,3,3,3,3,3,3,3,3,3,2
4,3,3,3,3,3,3,3,3,3,2
4,3,3,5,5,5,5,5,3,3,2
4,3,3,5,3,3,3,5,3,3,2
4,3,3,5,3,3,3,5,3,3,2
4,3,3,5,3,3,3,5,3,3,2
4,3,3,5,5,5,5,5,3,3,2
4,3,3,3,3,3,3,3,3,3,2
4,3,3,3,3,3,3,3,3,3,2
6,6,6,6,6,6,6,6,6,6,2
endlayer

layer
0,7,7,0,7,0,7,7,0,0,7
7,7,0,7,0,7,7,0,0,0,0
0,0,4,1,1,1,1,1,2,0,0
0,7,4,3,3,3,3,3,2,0,0
0,0,4,3,8,8,8,3,2,0,0
0,0,4,3,8,8,8,3,2,0,0
0,7,4,3,8,8,8,3,2,0,0
0,7,4,3,3,3,3,3,2,0,0
0,0,6,6,6,6,6,6,2,0,0
0,0,0,0,0,0,0,0,0,7,0
0,7,7,0,0,0,0,0,0,0,0
endlayer

layer
0,0,0,0,0,0,0,0,0,0,0
0,0,0,0,7,7,0,0,0,0,0
0,0,0,0,7,7,7,0,0,0,0
0,0,0,9,0,10,0,9,7,0,0
0,0,0,0,0,0,0,0,0,0,0
0,0,0,10,0,7,7,10,7,0,0
0,0,0,0,0,0,7,7,0,7,7
0,0,0,9,0,10,0,9,0,0,7
0,0,0,0,0,0,0,0,0,0,0
0,0,0,0,0,0,0,0,0,0,0
0,0,0,0,0,0,0,0,0,0,0
endlayer

layer
0,0,0,0,0,0,0,0,0,0,0
0,0,0,0,0,0,0,0,0,0,0
0,0,0,0,0,0,0,0,0,0,0
0,0,0,9,0,0,0,9,0,0,0
0,0,0,0,0,0,0,0,0,0,0
0,0,0,0,0,0,0,0,0,0,0
0,0,7,7,0,0,0,0,0,0,0
0,0,0,9,0,0,0,9,0,0,0
0,0,0,0,0,0,0,0,0,0,0
0,0,0,0,0,0,0,0,0,0,0
0,0,0,0,0,0,0,0,0,0,0
endlayer

layer
0,0,0,0,0,0,0,0,0,0,0
0,0,0,0,0,0,7,0,0,0,0
0,7,0,0,7,0,0,7,0,0,0
0,0,0,9,0,0,0,9,0,7,0
7,0,0,0,0,7,0,0,0,7,0
0,0,0,7,7,7,7,0,7,0,0
7,0,0,7,7,7,0,0,7,0,0
0,7,0,9,0,0,0,9,0,0,0
0,0,0,0,0,0,0,0,0,0,0
0,0,7,7,0,0,0,0,0,0,0
0,0,0,0,0,0,0,0,0,0,0
endlayer

layer
0,0,0,0,0,0,0,0,0,0,0
0,0,0,0,0,0,0,0,0,0,0
0,0,0,0,0,0,0,0,0,0,0
0,0,0,11,11,11,11,11,0,0,0
0,0,0,11,12,12,12,11,0,0,0
0,0,0,11,12,12,12,11,0,0,0
0,0,0,11,12,12,12,11,0,0,0
0,0,0,11,11,11,11,11,0,0,0
0,0,0,0,0,0,0,0,0,0,0
0,0,0,0,0,0,0,0,0,0,0
0,0,0,0,0,0,0,0,0,0,0
endlayer

layer
0,0,0,0,0,0,0,0,0,0,0
0,0,0,0,0,0,0,0,0,0,0
0,0,0,0,0,0,7,0,0,0,0
0,0,0,0,0,0,7,0,0,0,0
0,0,0,0,0,0,0,0,0,0,0
0,0,0,0,7,0,0,7,0,0,0
0,0,0,0,7,0,7,0,0,0,0
0,0,0,0,7,0,0,0,0,0,0
0,0,0,7,0,0,0,0,0,0,0
0,0,0,0,0,0,0,0,0,0,0
0,0,0,0,0,0,0,0,0,0,0
endlayer

