
# Created by Ruins mod version 14.4 Ingame Parser
# authoring Player: Mikhaila666

weight=1
embed_into_distance=0
acceptable_target_blocks=
unacceptable_target_blocks=flowing_water,water,flowing_lava,lava
dimensions=20,20,20
allowable_overhang=0
max_leveling=2
leveling_buffer=0
preserve_water=0
preserve_lava=0

rule1=0,100,minecraft:grass-0
rule2=0,100,minecraft:dirt-0
rule3=0,100,Railcraft:tile.railcraft.residual.heat-0
rule4=0,100,minecraft:quartz_stairs-2
rule5=0,100,minecraft:quartz_stairs-0
rule6=0,100,minecraft:quartz_stairs-3
rule7=0,100,minecraft:quartz_stairs-1
rule8=0,100,arsmagica2:liquidEssence-0
rule9=0,100,TConstruct:GlassBlock.StainedClear-9
rule10=0,100,Highlands:tile.hl_poplarWood-0
rule11=0,100,arsmagica2:liquidEssence-1
rule12=0,100,Railcraft:tile.railcraft.lantern.stone-6
rule13=0,100,Highlands:tile.hl_poplarLeaves-0

layer
0,0,0,0,1,1,1,1,1,1,1,1,1,1,1,1,1,1,0,0
0,0,0,1,1,1,1,1,1,1,1,1,1,1,1,1,1,1,1,0
0,0,1,1,1,1,1,1,1,1,1,1,1,1,1,1,1,1,1,1
0,0,1,1,1,1,2,1,1,1,2,2,1,2,2,2,1,1,1,1
0,0,1,1,1,2,2,2,2,2,2,2,1,2,2,2,2,1,1,1
0,0,1,1,1,2,2,1,1,1,1,1,1,1,2,2,2,1,1,1
0,0,1,1,1,2,1,1,1,1,1,1,1,1,1,2,2,1,1,1
0,0,1,1,1,2,2,1,1,1,1,1,1,1,1,2,2,1,1,1
0,0,1,1,1,2,2,1,1,1,1,1,1,1,1,2,2,1,1,1
0,0,1,1,1,2,2,1,1,1,1,1,1,1,1,2,2,1,1,1
3,0,1,1,1,2,2,1,1,1,1,1,1,1,1,2,2,1,1,1
0,0,1,1,1,2,2,1,1,1,1,1,1,1,1,2,2,1,1,1
0,0,1,1,1,2,1,1,1,1,1,1,1,1,2,1,1,1,1,1
0,0,1,1,1,2,1,2,2,2,1,2,1,2,1,1,2,1,1,1
0,0,1,1,1,1,2,2,2,2,2,2,2,2,2,2,1,1,1,1
0,0,1,1,1,1,1,1,1,1,1,1,1,1,1,1,1,1,1,1
0,0,0,1,1,1,1,1,1,1,1,1,1,1,1,1,1,1,1,0
0,0,0,0,1,1,1,1,1,1,1,1,1,1,1,1,1,1,0,0
0,0,0,0,3,0,0,0,0,0,0,0,3,0,0,0,0,0,0,0
0,0,0,0,0,3,0,0,0,0,0,0,0,0,0,0,0,0,0,0
endlayer

layer
3,0,0,0,0,0,0,0,0,0,0,0,0,0,0,0,0,0,0,0
0,0,0,0,0,3,0,0,0,0,0,0,0,0,0,3,0,0,0,0
0,0,0,0,0,5,5,5,5,5,5,5,5,5,5,5,4,3,0,0
0,0,0,0,5,6,1,1,1,1,1,1,1,1,1,1,5,4,0,0
0,0,0,0,6,1,1,1,1,1,1,1,1,1,1,2,1,4,3,0
0,3,0,0,6,1,1,2,4,7,7,7,7,7,1,1,1,4,0,0
0,3,0,0,6,1,1,4,7,8,8,8,8,6,7,1,1,4,0,0
0,0,0,0,6,1,1,4,8,9,8,8,9,8,6,1,1,4,0,0
0,0,0,0,6,1,1,4,8,8,8,8,8,8,6,1,1,4,3,0
0,0,3,0,6,1,1,4,8,8,8,8,8,8,6,1,1,4,0,0
0,0,0,0,6,1,1,4,8,9,8,8,9,8,6,1,1,4,0,0
0,0,3,0,6,1,1,5,4,8,8,8,8,5,6,1,1,4,3,0
0,0,0,0,6,1,1,2,5,5,5,5,5,6,2,1,1,4,0,0
0,0,0,0,6,1,1,1,1,1,1,1,1,1,1,1,1,4,0,0
0,0,3,0,6,7,1,1,1,1,1,1,1,1,1,1,4,7,0,0
0,0,0,0,0,6,7,7,7,7,7,7,7,7,7,7,7,0,3,0
0,0,0,0,0,0,0,0,0,0,0,0,0,0,0,0,0,0,0,0
3,0,3,0,0,0,0,3,0,3,0,0,3,0,3,0,0,3,0,0
0,0,3,3,0,0,0,0,0,0,0,0,0,0,0,0,0,0,0,0
0,0,0,0,0,0,0,0,0,0,0,0,0,0,0,0,0,0,0,0
endlayer

layer
0,0,0,0,0,0,0,0,0,0,0,0,0,0,0,0,0,0,0,0
0,0,0,0,0,0,0,0,0,0,0,0,0,0,0,0,0,0,0,0
0,0,0,0,0,0,0,0,0,0,3,3,0,0,0,0,0,0,0,0
0,0,0,0,3,0,0,0,3,0,0,0,0,0,0,0,0,0,0,0
0,0,0,0,0,0,0,0,0,3,0,3,0,0,0,0,0,0,0,0
0,0,0,0,0,0,3,10,0,3,3,0,0,0,10,0,0,3,0,0
0,0,0,0,0,3,0,3,3,3,3,3,0,0,0,0,3,3,0,0
0,0,0,0,0,3,3,3,3,9,11,11,9,3,3,3,0,0,0,0
0,0,0,0,0,0,3,3,3,11,11,11,11,3,0,0,0,0,0,0
0,0,0,3,3,0,3,3,3,11,11,11,11,3,3,0,3,0,0,0
0,0,0,0,0,0,3,3,3,9,11,11,9,3,3,0,0,0,0,0
0,0,0,0,0,0,0,3,3,0,3,3,3,3,0,0,0,0,0,0
0,0,0,0,3,3,0,10,3,3,3,3,3,0,10,0,0,0,0,0
0,0,0,0,0,3,0,3,3,3,0,0,3,0,0,0,3,0,0,0
0,0,0,0,3,0,0,0,3,0,0,0,0,0,0,0,0,0,0,0
0,0,0,0,3,0,0,0,0,0,0,0,0,3,3,0,0,3,0,0
3,3,0,0,0,0,0,0,0,0,0,0,0,0,0,0,0,0,0,0
0,0,0,0,0,0,0,0,0,0,0,0,0,0,0,0,0,0,0,0
0,0,0,0,0,0,0,0,0,0,0,0,0,0,0,0,0,0,0,0
0,0,0,0,0,0,0,0,0,0,0,0,0,0,0,0,0,0,0,0
endlayer

layer
0,0,0,0,0,0,0,0,0,0,0,0,0,0,0,0,0,0,0,0
0,0,0,0,0,0,0,0,0,0,0,0,0,0,0,0,0,0,0,0
0,0,0,0,0,0,3,0,3,0,3,0,0,0,3,3,0,0,0,0
0,0,0,0,3,3,0,3,3,3,3,3,3,0,0,0,0,0,0,0
0,0,0,0,3,3,0,3,0,3,0,0,0,0,3,0,0,3,0,0
0,0,0,0,3,0,3,10,0,3,3,3,3,3,10,0,3,0,0,0
0,0,0,0,0,3,0,0,3,3,3,3,3,3,3,0,3,0,0,0
0,0,0,0,0,0,3,0,0,9,11,11,9,3,0,3,3,0,0,0
0,0,0,0,0,3,0,3,3,11,11,11,11,3,3,3,0,0,0,0
0,0,0,0,0,3,0,3,3,11,11,11,11,3,3,3,0,3,0,0
0,0,0,0,3,0,0,3,0,9,11,11,9,3,0,0,0,0,0,0
0,0,0,0,0,0,3,3,3,3,0,3,3,3,3,0,3,0,0,0
0,0,0,0,0,3,3,10,3,0,3,3,3,3,10,3,0,0,0,0
0,0,0,0,0,3,0,3,3,0,3,0,3,3,0,3,0,3,0,0
0,0,0,0,0,3,3,0,3,0,3,0,3,0,3,0,3,3,0,0
0,0,0,0,0,0,0,0,0,0,3,3,3,0,0,3,0,0,0,0
0,0,0,0,0,0,0,0,0,0,0,0,0,0,0,0,0,0,0,3
0,0,0,0,0,0,0,0,0,0,0,0,0,0,0,0,0,0,0,0
0,0,0,0,0,0,0,0,0,0,0,0,0,0,0,3,0,0,0,0
0,0,0,0,0,0,0,0,0,0,0,0,0,0,0,0,0,0,0,0
endlayer

layer
0,0,0,0,0,0,0,0,0,0,0,0,0,0,0,0,0,0,0,0
0,0,0,0,0,0,0,0,0,0,0,0,0,0,0,0,0,0,0,0
0,0,0,0,0,0,3,0,0,0,0,0,0,0,3,0,0,0,0,0
0,0,0,0,0,0,0,0,0,0,0,0,0,0,0,0,3,3,0,0
0,0,0,0,0,3,0,3,0,3,3,0,0,0,0,0,0,0,0,0
0,0,0,0,0,0,0,10,0,0,3,0,0,0,10,3,0,3,0,0
0,0,0,0,0,0,0,0,0,0,0,0,0,0,0,0,3,3,0,0
0,0,0,0,3,3,3,0,0,12,11,11,12,0,3,0,0,0,0,0
0,0,0,0,0,3,0,0,3,11,11,11,11,0,0,0,0,0,0,0
0,0,0,0,3,0,0,0,0,11,11,11,11,0,0,0,0,0,0,0
0,0,0,0,0,0,0,0,0,12,11,11,12,0,0,3,0,0,0,0
0,0,0,0,0,0,0,0,0,0,3,0,0,0,0,0,0,0,0,0
0,0,0,0,0,3,0,10,3,0,3,0,3,0,10,0,0,0,0,0
0,0,0,0,0,0,0,0,0,0,0,0,0,0,0,0,0,0,0,0
0,0,0,0,3,0,0,0,0,0,0,0,3,0,3,0,0,0,0,0
0,0,0,0,3,0,0,0,0,0,3,0,0,0,3,0,3,0,0,0
0,0,0,0,0,0,0,0,0,0,0,0,0,0,0,0,0,0,0,0
0,0,0,0,0,0,0,0,0,0,0,0,0,0,0,0,0,0,0,0
0,0,0,0,0,0,0,0,0,0,0,0,0,0,0,0,0,0,0,0
0,0,0,0,0,0,0,0,0,0,0,0,0,0,0,0,0,0,0,0
endlayer

layer
0,0,0,0,0,0,0,0,0,0,0,0,0,0,0,0,0,0,0,0
0,0,0,0,0,0,0,0,0,0,0,0,0,0,0,3,0,0,0,0
0,0,0,0,0,0,0,0,0,0,0,0,0,0,0,0,0,0,0,0
0,0,0,0,3,0,0,0,0,0,0,0,0,0,0,0,0,0,0,0
0,0,0,0,0,0,0,13,0,0,0,0,0,0,13,0,0,0,0,0
0,0,0,0,0,0,13,10,13,0,0,0,0,13,10,13,0,0,0,0
0,0,0,0,0,0,0,13,0,0,0,0,0,0,13,0,0,0,0,0
0,0,0,0,0,0,0,0,0,0,11,11,0,0,0,0,0,0,0,0
0,0,0,0,0,0,0,0,0,11,8,8,11,0,0,0,0,0,0,0
0,0,0,0,0,0,0,0,3,11,8,8,11,3,3,0,3,0,0,0
0,0,0,0,0,0,0,0,0,0,11,11,0,0,0,0,0,0,0,0
0,0,0,0,0,0,0,13,0,0,0,0,0,0,13,0,0,0,0,0
0,0,0,0,0,0,13,10,13,0,0,0,0,13,10,13,0,0,0,0
0,0,0,0,0,0,0,13,0,0,0,0,0,0,13,0,0,0,0,0
0,0,0,0,0,0,0,0,0,0,0,0,0,0,0,0,0,0,0,0
0,0,0,0,0,0,0,0,0,0,0,0,0,0,0,0,0,0,0,0
0,0,0,0,0,0,0,0,0,0,0,0,0,0,0,0,0,0,0,0
0,0,0,0,0,0,0,0,0,0,0,3,0,0,0,0,0,0,0,0
0,0,0,0,0,0,0,0,0,0,0,0,0,0,0,0,0,0,0,0
0,0,0,0,0,0,0,0,0,0,0,0,0,0,0,0,0,0,0,0
endlayer

layer
0,0,0,0,0,0,0,0,0,0,0,0,0,0,0,0,0,0,0,0
0,0,0,0,0,0,0,0,0,0,0,0,0,0,0,0,0,0,0,0
0,0,0,0,0,0,0,0,0,0,0,0,0,0,0,0,0,0,0,0
0,0,0,0,0,0,0,0,0,0,0,0,0,0,0,0,0,0,0,0
0,0,0,0,0,0,13,13,13,0,0,0,0,13,13,13,0,0,0,0
0,0,0,0,0,0,13,10,13,0,0,0,0,13,10,13,0,0,0,0
0,0,0,0,0,0,13,13,13,0,0,0,0,13,13,13,0,0,0,0
0,0,0,0,0,0,0,0,0,0,0,0,0,0,0,0,0,0,0,0
0,0,0,0,0,0,0,0,3,3,0,0,0,0,0,0,0,0,0,0
0,0,0,0,0,0,0,0,0,0,0,0,0,0,3,0,0,0,0,0
0,0,0,0,0,0,0,0,0,0,0,0,0,0,0,0,0,0,0,0
0,0,0,0,0,0,13,13,13,0,0,0,0,13,13,13,0,0,0,0
0,0,0,0,0,0,13,10,13,0,0,0,0,13,10,13,0,0,0,0
0,0,0,0,0,0,13,13,13,0,0,0,0,13,13,13,0,0,0,0
0,0,0,0,0,0,0,0,0,0,0,0,0,0,0,0,0,0,0,0
0,0,0,0,0,0,0,0,0,0,0,0,0,0,0,0,0,0,0,0
0,0,0,0,0,0,0,0,0,0,0,0,0,0,0,0,0,0,0,0
0,0,0,0,0,0,0,0,0,0,0,0,0,0,0,0,0,0,0,0
0,0,0,0,0,0,0,0,0,0,0,0,0,0,0,0,0,0,0,0
0,0,0,0,0,0,0,0,0,0,0,0,0,0,0,0,0,0,0,0
endlayer

layer
0,0,0,0,0,0,0,0,0,0,0,0,0,0,0,0,0,0,0,0
0,0,0,0,0,0,0,0,0,0,0,0,0,0,0,0,0,0,0,0
0,0,0,0,0,0,0,0,0,0,0,0,0,0,0,0,0,0,0,0
0,0,0,0,0,0,0,13,0,0,0,0,0,0,13,0,0,0,0,0
0,0,0,0,0,0,13,13,13,0,0,0,3,13,13,13,0,0,0,0
0,0,0,0,0,13,13,10,13,13,0,0,13,13,10,13,13,0,0,0
0,0,0,0,0,0,13,13,13,0,0,0,0,13,13,13,0,0,0,0
0,0,0,0,0,0,0,13,0,3,0,0,0,0,13,0,0,0,0,0
0,0,0,0,0,0,0,0,0,0,0,0,0,0,0,0,0,0,0,0
0,0,0,0,0,0,0,0,0,0,0,0,0,0,0,0,0,0,0,0
0,0,0,0,0,0,0,13,0,0,0,0,0,0,13,0,0,0,0,0
0,0,0,0,0,0,13,13,13,0,0,0,0,13,13,13,0,0,0,0
0,0,0,0,0,13,13,10,13,13,0,0,13,13,10,13,13,0,0,0
0,0,0,0,0,0,13,13,13,0,0,0,0,13,13,13,0,0,0,0
0,0,0,0,0,0,0,13,0,0,0,0,0,0,13,0,0,0,0,0
0,0,0,0,0,0,0,0,0,0,0,0,0,0,0,0,0,0,0,0
0,0,0,0,0,0,0,0,0,0,0,0,0,0,0,0,0,0,0,0
3,0,0,0,0,0,0,0,0,0,0,0,0,0,0,0,0,0,0,0
0,0,0,0,0,0,0,0,0,0,0,0,0,0,0,0,0,0,0,0
0,0,0,0,0,0,0,0,0,0,0,0,0,0,0,0,0,0,0,0
endlayer

layer
0,0,0,0,0,0,0,0,0,0,0,0,0,0,0,0,0,0,0,0
0,0,0,0,0,0,0,0,0,0,0,0,0,0,0,0,0,0,0,0
0,0,0,0,0,0,0,0,0,0,0,0,0,0,0,0,0,0,0,0
0,0,0,0,0,0,13,13,13,0,0,0,0,0,13,0,0,0,0,0
0,0,0,0,0,13,13,13,13,0,0,0,13,13,13,13,13,0,0,0
0,0,0,0,0,0,13,10,13,13,0,0,0,13,10,13,0,0,0,0
0,0,0,0,0,0,13,13,13,0,0,0,0,13,13,13,13,0,0,0
0,0,0,0,0,0,13,0,13,0,0,0,0,13,13,13,0,0,0,0
0,0,0,0,0,0,0,0,0,0,3,3,0,0,0,0,0,0,0,0
0,0,0,0,0,0,0,0,0,0,0,0,3,0,0,0,0,0,0,0
0,0,0,0,0,0,13,0,13,0,0,0,0,13,0,13,0,0,0,0
0,0,0,0,0,13,13,13,13,0,0,0,13,13,13,13,0,0,0,0
0,0,0,0,0,13,13,10,13,13,0,0,0,13,10,13,0,0,0,0
0,0,0,0,0,13,13,13,13,0,0,0,13,13,13,13,0,0,0,0
0,0,0,0,0,0,13,0,13,0,0,0,0,0,0,0,0,0,0,0
0,0,0,0,0,0,0,0,0,0,0,0,0,0,0,0,0,0,0,0
0,0,0,0,0,0,0,0,0,0,0,0,0,0,0,0,0,0,0,0
0,0,0,0,0,0,0,0,0,0,0,0,0,0,0,0,0,0,0,0
0,0,0,0,0,0,0,0,0,0,0,0,0,0,0,0,0,0,0,0
0,0,0,0,0,0,0,0,0,0,0,0,0,0,0,0,0,0,0,0
endlayer

layer
0,0,0,0,0,0,0,0,0,0,0,0,0,0,0,0,0,0,0,0
0,0,0,0,0,0,0,0,0,0,0,0,0,0,0,0,0,0,0,0
0,0,0,0,0,0,0,0,0,0,0,0,0,0,0,0,0,0,0,0
0,0,0,0,0,0,0,0,0,0,0,0,0,13,0,0,0,0,0,0
0,0,0,0,0,13,13,13,13,0,0,0,0,13,13,13,0,0,0,0
0,0,0,0,0,13,13,10,13,13,0,0,13,13,10,13,0,0,0,0
0,0,0,0,0,0,13,13,13,0,0,0,13,13,13,13,13,0,0,0
0,0,0,0,0,0,13,0,13,0,0,0,0,0,13,13,0,0,0,0
0,0,0,0,0,0,0,0,0,0,0,0,0,0,0,0,0,0,0,0
0,0,0,0,0,0,0,0,0,0,0,0,0,0,0,0,0,0,0,0
0,0,0,0,0,0,0,13,13,0,0,0,0,13,0,13,0,0,0,0
0,0,0,0,0,13,13,13,13,13,0,0,13,13,13,13,0,0,0,0
0,0,0,0,0,13,13,10,13,0,0,0,13,13,10,13,13,0,0,0
0,0,0,0,0,0,13,13,13,0,0,0,0,13,13,13,13,0,0,0
0,0,0,0,0,0,13,0,0,0,0,0,0,13,0,0,0,0,0,0
0,0,0,0,0,0,0,0,0,0,0,0,0,0,0,0,0,0,0,0
0,0,0,0,0,0,0,0,0,0,0,0,0,0,0,0,0,0,0,0
0,0,0,0,0,0,0,0,3,0,0,3,0,0,0,0,0,0,0,0
0,0,0,0,0,0,0,0,0,0,0,0,0,0,0,0,0,0,0,0
0,0,0,0,0,0,0,0,0,0,0,0,0,0,0,0,0,0,0,0
endlayer

layer
0,0,0,0,0,0,0,0,0,0,0,0,0,0,0,0,0,0,0,0
0,0,0,0,0,0,0,0,0,0,0,0,0,0,0,0,0,0,0,0
0,0,0,0,0,0,0,0,0,0,0,0,0,0,0,0,0,0,0,0
0,0,0,0,0,0,13,13,13,0,0,0,0,0,0,0,0,0,0,0
0,0,0,0,0,13,13,13,13,13,0,0,0,13,13,13,0,0,0,0
0,0,0,0,0,0,13,10,13,13,0,0,0,13,10,13,0,0,0,0
0,0,0,0,0,13,13,13,13,13,0,0,13,13,13,13,0,0,0,0
0,0,0,0,0,0,0,0,0,0,0,0,0,13,13,0,0,0,0,0
0,0,0,0,0,0,0,0,0,0,0,0,0,0,0,0,0,0,0,0
0,0,0,0,0,0,0,0,0,0,0,0,0,0,0,0,0,0,0,0
0,0,0,0,0,0,0,13,13,0,0,0,0,13,0,13,0,0,0,0
0,0,0,0,0,13,13,13,13,0,0,0,13,13,13,13,13,0,0,0
0,0,0,0,0,0,13,10,13,0,0,0,0,13,10,13,13,0,0,0
0,0,0,0,0,13,13,13,13,0,0,0,13,13,13,13,13,0,0,0
0,0,0,0,0,0,13,0,0,0,0,0,0,0,13,0,0,0,0,0
0,0,0,0,0,0,0,0,0,0,0,0,0,0,0,0,0,0,0,0
0,0,0,0,0,0,0,0,0,0,0,0,0,0,0,0,0,0,0,0
0,0,0,0,0,0,0,0,0,0,0,0,0,0,0,0,0,0,0,0
0,0,0,0,0,0,0,0,0,0,0,0,0,0,0,0,0,0,0,0
0,0,0,0,0,0,0,0,0,0,0,0,0,0,0,0,0,0,0,0
endlayer

layer
0,0,0,0,0,0,0,0,0,0,0,0,0,0,0,0,0,0,0,0
0,0,0,0,0,3,0,0,0,0,0,0,0,0,0,0,0,0,0,0
0,0,0,0,0,0,0,0,0,0,0,0,0,0,0,0,0,0,0,0
0,0,0,0,0,0,13,0,0,0,0,0,0,0,13,0,0,0,0,0
0,0,0,0,0,0,13,13,13,0,0,0,13,13,13,13,13,0,0,0
0,0,0,0,0,13,13,10,13,0,0,0,0,13,10,13,0,0,0,0
0,0,0,0,0,0,13,13,13,13,0,0,13,13,13,13,13,0,0,0
0,0,0,0,0,0,13,0,13,0,0,0,0,0,0,13,0,0,0,0
0,0,0,0,0,0,0,0,0,0,0,0,0,0,0,0,0,0,0,0
0,0,0,0,0,0,0,0,0,0,0,0,0,0,0,0,0,0,0,0
0,0,0,0,0,0,0,13,13,0,0,0,0,0,13,13,0,0,0,0
0,0,0,0,0,0,13,13,13,13,0,0,0,13,13,13,13,0,0,0
0,0,0,0,0,13,13,10,13,0,0,0,0,13,10,13,13,0,0,0
0,0,0,0,0,13,13,13,13,0,0,0,0,13,13,13,0,0,0,0
0,0,0,0,0,0,13,13,0,0,0,0,0,0,0,13,0,0,0,0
0,0,0,0,0,0,0,0,0,0,0,0,0,0,0,0,0,0,0,0
0,0,0,0,0,0,0,0,0,0,0,0,0,0,0,0,0,0,0,0
0,0,0,0,0,0,0,0,0,0,0,0,0,0,0,0,0,0,0,0
0,0,0,0,0,0,0,0,0,0,0,0,0,0,0,0,0,0,0,0
0,0,0,0,0,0,0,0,0,0,0,0,0,0,0,0,0,0,0,0
endlayer

layer
0,0,0,0,0,0,0,0,0,0,0,0,0,0,0,0,0,0,0,0
0,0,0,0,0,0,0,0,0,0,0,0,0,0,0,0,0,0,0,0
0,0,0,0,0,0,0,0,0,0,0,0,0,0,0,0,0,0,0,0
0,0,0,0,0,0,13,0,0,0,0,0,0,13,13,13,0,0,0,0
0,0,0,0,0,0,13,13,13,13,0,0,13,13,13,13,13,0,0,0
0,0,0,0,0,13,13,10,13,0,0,0,13,13,10,13,13,0,0,0
0,0,0,0,0,0,13,13,13,0,0,0,0,13,13,13,13,0,0,0
0,0,0,0,0,0,0,13,13,0,0,0,0,0,0,0,0,0,0,0
0,0,0,0,0,0,0,0,0,0,0,0,0,0,0,0,0,0,0,0
0,0,0,0,0,0,0,0,0,0,0,0,0,0,0,0,0,0,0,0
0,0,0,0,0,0,13,0,0,0,0,0,0,0,0,0,0,0,0,0
0,0,0,0,0,13,13,13,13,13,0,0,13,13,13,13,13,0,0,0
0,0,0,0,0,0,13,10,13,13,0,0,13,13,10,13,0,0,0,0
0,0,0,0,0,0,13,13,13,13,0,0,0,13,13,13,0,0,0,0
0,0,0,0,0,0,13,13,13,0,0,0,0,0,13,0,0,0,0,0
0,0,0,0,0,0,0,0,0,0,0,0,0,3,0,0,0,0,0,0
0,0,0,0,0,0,0,0,0,0,0,0,0,0,0,0,0,0,0,0
0,0,0,0,0,0,0,0,0,0,0,0,0,0,0,0,0,0,0,0
0,0,0,0,0,0,0,0,0,0,0,0,0,0,0,0,0,0,0,0
0,0,0,0,0,0,0,0,0,0,0,0,0,0,0,0,0,0,0,0
endlayer

layer
0,0,0,0,0,0,0,0,0,0,0,0,0,0,0,0,0,0,0,0
0,0,0,0,0,0,0,0,0,0,0,0,0,0,0,0,0,0,0,0
0,0,0,0,0,0,0,0,0,0,0,0,0,0,0,0,0,0,0,0
0,0,0,0,0,0,0,13,13,0,0,0,0,0,13,0,0,0,0,0
0,0,0,0,0,0,13,13,13,13,0,0,0,13,13,13,0,0,0,0
0,0,0,0,0,13,13,10,13,13,0,0,0,13,13,13,0,0,0,0
0,0,0,0,0,13,13,13,13,0,0,0,0,13,13,0,0,0,0,0
0,0,0,0,0,0,13,0,13,0,0,0,0,0,13,0,0,0,0,0
0,0,0,0,0,0,0,0,0,0,0,0,0,0,0,0,0,0,0,0
0,0,0,0,0,0,0,0,0,0,0,0,0,0,0,0,0,0,0,0
0,0,0,0,0,0,13,13,0,0,0,0,0,0,0,0,0,0,0,0
0,0,0,0,0,13,13,13,13,0,0,0,0,0,13,13,0,0,0,0
0,0,0,0,0,0,13,10,13,0,0,0,0,13,13,13,0,0,0,0
0,0,0,0,0,0,13,13,13,0,0,0,0,0,13,0,0,0,0,0
0,0,0,0,0,0,0,0,13,0,0,0,0,0,0,0,0,0,0,0
0,0,0,0,0,0,0,0,0,0,0,0,0,0,0,0,0,0,0,0
0,0,0,0,0,0,0,0,0,0,0,0,0,0,0,0,0,0,0,0
0,0,0,0,0,0,0,0,0,0,0,0,0,0,0,0,0,0,0,0
0,0,0,0,0,0,0,0,0,0,0,0,0,0,0,0,0,0,0,0
0,0,0,0,0,0,0,0,0,0,0,0,0,0,0,0,0,0,0,0
endlayer

layer
0,0,0,0,0,0,0,0,0,0,0,0,0,0,0,0,0,0,0,0
0,0,0,0,0,0,0,0,0,0,0,0,0,0,0,0,0,0,0,0
0,0,0,0,0,0,0,0,0,0,0,0,0,0,0,0,0,0,0,0
0,0,0,0,0,0,13,13,13,0,0,0,0,0,0,0,0,0,0,0
0,0,0,0,0,0,13,13,13,13,0,0,0,0,0,13,0,0,0,0
0,0,0,0,0,13,13,10,13,13,0,0,0,0,13,13,0,0,0,0
0,0,0,0,0,0,13,13,13,13,0,0,0,13,13,13,0,0,0,0
0,0,0,0,0,0,0,0,0,0,0,0,0,0,0,0,0,0,0,0
0,0,0,0,0,0,0,0,0,0,0,0,0,0,0,0,0,0,0,0
0,0,0,0,0,0,0,0,0,0,0,0,0,0,0,0,0,0,0,0
0,0,0,0,0,0,13,0,13,0,0,0,0,0,0,0,0,0,0,0
0,0,0,0,0,13,13,13,13,0,0,0,0,13,13,0,0,0,0,0
0,0,0,0,0,13,13,10,13,0,0,0,0,0,13,0,0,0,0,0
0,0,0,0,0,0,13,13,13,0,0,0,0,0,0,0,0,0,0,0
0,0,0,0,0,0,13,13,0,0,0,0,0,0,0,0,0,0,0,0
0,0,0,0,0,0,0,0,0,0,0,0,0,0,0,0,0,0,0,0
0,0,0,0,0,0,0,0,0,0,0,0,0,0,0,0,0,0,0,0
0,0,0,0,0,0,0,0,0,0,0,0,0,0,0,0,0,0,0,0
0,0,0,0,0,0,0,0,0,0,0,0,0,0,0,0,0,0,0,0
0,0,0,0,0,0,0,0,0,0,0,0,0,0,0,0,0,0,0,0
endlayer

layer
0,0,0,0,0,0,0,0,0,0,0,0,0,0,0,0,0,0,0,0
0,0,0,0,0,0,0,0,0,0,0,0,0,0,0,0,0,0,0,0
0,0,0,0,0,0,0,0,0,0,0,0,0,0,0,0,0,0,0,0
0,0,0,0,0,0,0,13,0,0,0,0,0,0,0,0,0,0,0,0
0,0,0,0,0,0,13,13,13,0,0,0,0,0,13,0,0,0,0,0
0,0,0,0,0,13,13,13,13,0,0,0,0,13,13,13,0,0,0,0
0,0,0,0,0,0,0,13,0,0,0,0,0,0,0,0,0,0,0,0
0,0,0,0,0,0,0,13,0,0,0,0,0,0,0,0,0,0,0,0
0,0,0,0,0,0,0,0,0,0,0,0,0,0,0,0,0,0,0,0
0,0,0,0,0,0,0,0,0,0,0,0,0,0,0,0,0,0,0,0
0,0,0,0,0,0,0,0,0,0,0,0,0,0,0,0,0,0,0,0
0,0,0,0,0,0,0,13,0,0,0,0,0,0,0,0,0,0,0,0
0,0,0,0,0,0,13,13,13,13,0,0,0,0,13,0,0,0,0,0
0,0,0,0,0,0,0,13,13,0,0,0,0,0,0,0,0,0,0,0
0,0,0,0,0,0,0,13,0,0,0,0,0,0,0,0,0,0,0,0
0,0,0,0,0,0,0,0,0,0,0,0,0,0,0,0,0,0,0,0
0,0,0,0,0,0,0,0,0,0,0,0,0,0,0,0,0,0,0,0
0,0,0,0,0,0,0,0,0,0,0,0,0,0,0,0,0,0,0,0
0,0,0,0,0,0,0,0,0,0,0,0,0,0,0,0,0,0,0,0
0,0,0,0,0,0,0,0,0,0,0,0,0,0,0,0,0,0,0,0
endlayer

layer
0,0,0,0,0,0,0,0,0,0,0,0,0,0,0,0,0,0,0,0
0,0,0,0,0,0,0,0,0,0,0,0,0,0,0,0,0,0,0,0
0,0,0,0,0,0,0,0,0,0,0,0,0,0,0,0,0,0,0,0
0,0,0,0,0,0,0,0,0,0,0,0,0,0,0,0,0,0,0,0
0,0,0,0,0,0,0,0,0,0,0,0,0,0,0,0,0,0,0,0
0,0,0,0,0,0,13,13,13,0,0,0,0,0,13,0,0,0,0,0
0,0,0,0,0,0,13,13,0,0,0,0,0,0,0,0,0,0,0,0
0,0,0,0,0,0,0,0,0,0,0,0,0,0,0,0,0,0,0,0
0,0,0,0,0,0,0,0,0,0,0,0,0,0,0,0,0,0,0,0
0,0,0,0,0,0,0,0,0,0,0,0,0,0,0,0,0,0,0,0
0,0,0,0,0,0,0,0,0,0,0,0,0,0,0,0,0,0,0,0
0,0,0,0,0,0,0,13,13,0,0,0,0,0,0,0,0,0,0,0
0,0,0,0,0,0,13,13,13,0,0,0,0,0,13,0,0,0,0,0
0,0,0,0,0,0,0,0,0,0,0,0,0,0,0,0,0,0,0,0
0,0,0,0,0,0,0,0,0,0,0,0,0,0,0,0,0,0,0,0
0,0,0,0,0,0,0,0,0,0,0,0,0,0,0,0,0,0,0,0
0,0,0,0,0,0,0,0,0,0,0,0,0,0,0,0,0,0,0,0
0,0,0,0,0,0,0,0,0,0,0,0,0,0,0,0,0,0,0,0
0,0,0,0,0,0,0,0,0,0,0,0,0,0,0,0,0,0,0,0
0,0,0,0,0,0,0,0,0,0,0,0,0,0,0,0,0,0,0,0
endlayer

layer
0,0,0,0,0,0,0,0,0,0,0,0,0,0,0,0,0,0,0,0
0,0,0,0,0,0,0,0,0,0,0,0,0,0,0,0,0,0,0,0
0,0,0,0,0,0,0,0,0,0,0,0,0,0,0,0,0,0,0,0
0,0,0,0,0,0,0,0,0,0,0,0,0,0,0,0,0,0,0,0
0,0,0,0,0,0,0,0,0,0,0,0,0,0,0,0,0,0,0,0
0,0,0,0,0,0,0,13,0,0,0,0,0,0,13,0,0,0,0,0
0,0,0,0,0,0,0,0,0,0,0,0,0,0,0,0,0,0,0,0
0,0,0,0,0,0,0,0,0,0,0,0,0,0,0,0,0,0,0,0
0,0,0,0,0,0,0,0,0,0,0,0,0,0,0,0,0,0,0,0
0,0,0,0,0,0,0,0,0,0,0,0,0,0,0,0,0,0,0,0
0,0,0,0,0,0,0,0,0,0,0,0,0,0,0,0,0,0,0,0
0,0,0,0,0,0,0,13,0,0,0,0,0,0,0,0,0,0,0,0
0,0,0,0,0,0,13,13,13,0,0,0,0,0,13,0,0,0,0,0
0,0,0,0,0,0,0,0,0,0,0,0,0,0,0,0,0,0,0,0
0,0,0,0,0,0,0,0,0,0,0,0,0,0,0,0,0,0,0,0
0,0,0,0,0,0,0,0,0,0,0,0,0,0,0,0,0,0,0,0
0,0,0,0,0,0,0,0,0,0,0,0,0,0,0,0,0,0,0,0
0,0,0,0,0,0,0,0,0,0,0,0,0,0,0,0,0,0,0,0
0,0,0,0,0,0,0,0,0,0,0,0,0,0,0,0,0,0,0,0
0,0,0,0,0,0,0,0,0,0,0,0,0,0,0,0,0,0,0,0
endlayer

layer
0,0,0,0,0,0,0,0,0,0,0,0,0,0,0,0,0,0,0,0
0,0,0,0,0,0,0,0,0,0,0,0,0,0,0,0,0,0,0,0
0,0,0,0,0,0,0,0,0,0,0,0,0,0,0,0,0,0,0,0
0,0,0,0,0,0,0,0,0,0,0,0,0,0,0,0,0,0,0,0
0,0,0,0,0,0,0,0,0,0,0,0,0,0,0,0,0,0,0,0
0,0,0,0,0,0,0,13,0,0,0,0,0,0,0,0,0,0,0,0
0,0,0,0,0,0,0,0,0,0,0,0,0,0,0,0,0,0,0,0
0,0,0,0,0,0,0,0,0,0,0,0,0,0,0,0,0,0,0,0
0,0,0,0,0,0,0,0,0,0,0,0,0,0,0,0,0,0,0,0
0,0,0,0,0,0,0,0,0,0,0,0,0,0,0,0,0,0,0,0
0,0,0,0,0,0,0,0,0,0,0,0,0,0,0,0,0,0,0,0
0,0,0,0,0,0,0,0,0,0,0,0,0,0,0,0,0,0,0,0
0,0,0,0,0,0,0,13,0,0,0,0,0,0,0,0,0,0,0,0
0,0,0,0,0,0,0,0,0,0,0,0,0,0,0,0,0,0,0,0
0,0,0,0,0,0,0,0,0,0,0,0,0,0,0,0,0,0,0,0
0,0,0,0,0,0,0,0,0,0,0,0,0,0,0,0,0,0,0,0
0,0,0,0,0,0,0,0,0,0,0,0,0,0,0,0,0,0,0,0
0,0,0,0,0,0,0,0,0,0,0,0,0,0,0,0,0,0,0,0
0,0,0,0,0,0,0,0,0,0,0,0,0,0,0,0,0,0,0,0
0,0,0,0,0,0,0,0,0,0,0,0,0,0,0,0,0,0,0,0
endlayer

layer
0,0,0,0,0,0,0,0,0,0,0,0,0,0,0,0,0,0,0,0
0,0,0,0,0,0,0,0,0,0,0,0,0,0,0,0,0,0,0,0
0,0,0,0,0,0,0,0,0,0,0,0,0,0,0,0,0,0,0,0
0,0,0,0,0,0,0,0,0,0,0,0,0,0,0,0,0,0,0,0
0,0,0,0,0,0,0,0,0,0,0,0,0,0,0,0,0,0,0,0
0,0,0,0,0,0,0,13,0,0,0,0,0,0,0,0,0,0,0,0
0,0,0,0,0,0,0,0,0,0,0,0,0,0,0,0,0,0,0,0
0,0,0,0,0,0,0,0,0,0,0,0,0,0,0,0,0,0,0,0
0,0,0,0,0,0,0,0,0,0,0,0,0,0,0,0,0,0,0,0
0,0,0,0,0,0,0,0,0,0,0,0,0,0,0,0,0,0,0,0
0,0,0,0,0,0,0,0,0,0,0,0,0,0,0,0,0,0,0,0
0,0,0,0,0,0,0,0,0,0,0,0,0,0,0,0,0,0,0,0
0,0,0,0,0,0,0,13,0,0,0,0,0,0,0,0,0,0,0,0
0,0,0,0,0,0,0,0,0,0,0,0,0,0,0,0,0,0,0,0
0,0,0,0,0,0,0,0,0,0,0,0,0,0,0,0,0,0,0,0
0,0,0,0,0,0,0,0,0,0,0,0,0,0,0,0,0,0,0,0
0,0,0,0,0,0,0,0,0,0,0,0,0,0,0,0,0,0,0,0
0,0,0,0,0,0,0,0,0,0,0,0,0,0,0,0,0,0,0,0
0,0,0,0,0,0,0,0,0,0,0,0,0,0,0,0,0,0,0,0
0,0,0,0,0,0,0,0,0,0,0,0,0,0,0,0,0,0,0,0
endlayer

