
# Created by Ruins mod version 14.4 Ingame Parser
# authoring Player: Mikhaila666

weight=1
embed_into_distance=0
acceptable_target_blocks=
unacceptable_target_blocks=flowing_water,water,flowing_lava,lava
dimensions=19,14,14
allowable_overhang=0
max_leveling=2
leveling_buffer=0
preserve_water=0
preserve_lava=0

rule1=0,100,Railcraft:tile.railcraft.residual.heat-0
rule2=0,100,minecraft:quartz_stairs-2
rule3=0,100,minecraft:quartz_stairs-0
rule4=0,100,minecraft:grass-0
rule5=0,100,minecraft:quartz_stairs-3
rule6=0,100,minecraft:dirt-0
rule7=0,100,minecraft:quartz_stairs-1
rule8=0,100,arsmagica2:liquidEssence-0
rule9=0,100,TConstruct:GlassBlock.StainedClear-9
rule10=0,100,Highlands:tile.hl_poplarWood-0
rule11=0,100,arsmagica2:liquidEssence-1
rule12=0,100,Highlands:tile.hl_poplarSapling-1
rule13=0,100,Railcraft:tile.railcraft.lantern.stone-6
rule14=0,100,Highlands:tile.hl_poplarLeaves-0

layer
0,3,3,3,3,3,3,3,3,3,3,3,2,1
3,5,4,4,4,4,4,4,4,4,4,4,3,2
5,4,4,4,4,4,4,4,4,4,4,6,4,2
5,4,4,6,2,7,7,7,7,7,4,4,4,2
5,4,4,2,7,8,8,8,8,5,7,4,4,2
5,4,4,2,8,9,8,8,9,8,5,4,4,2
5,4,4,2,8,8,8,8,8,8,5,4,4,2
5,4,4,2,8,8,8,8,8,8,5,4,4,2
5,4,4,2,8,9,8,8,9,8,5,4,4,2
5,4,4,3,2,8,8,8,8,3,5,4,4,2
5,4,4,4,3,3,3,3,3,5,6,4,4,2
5,4,4,4,4,4,4,4,4,4,4,4,4,2
5,7,4,4,4,4,4,4,4,4,4,4,2,7
0,5,7,7,7,7,7,7,7,7,7,7,7,0
endlayer

layer
0,0,0,0,0,0,1,1,0,0,0,0,0,0
1,0,0,0,1,0,0,0,0,0,0,0,0,0
0,0,0,0,0,1,0,1,0,0,0,0,0,0
0,0,1,10,0,1,1,0,0,0,10,0,0,1
0,1,0,1,1,1,1,1,0,0,0,0,1,1
0,1,1,1,1,9,11,11,9,1,1,1,0,0
0,0,1,1,1,11,11,11,11,1,0,0,0,0
1,0,1,1,1,11,11,11,11,1,1,0,1,0
0,0,1,1,1,9,11,11,9,1,1,0,0,0
0,0,0,1,1,0,1,1,1,1,0,0,0,0
1,1,0,12,1,1,1,1,1,0,10,0,0,0
0,1,0,1,1,1,0,0,1,0,0,0,1,0
0,0,0,0,1,0,0,0,0,0,0,0,0,0
1,0,0,0,0,0,0,0,0,1,1,0,0,1
endlayer

layer
0,0,1,0,1,0,1,0,0,0,1,1,0,0
1,1,0,1,1,1,1,1,1,0,0,0,0,0
1,1,0,1,0,1,0,0,0,0,1,0,0,1
1,0,1,10,0,1,1,1,1,1,10,0,1,0
0,1,0,0,1,1,1,1,1,1,1,0,1,0
0,0,1,0,0,9,11,11,9,1,0,1,1,0
0,1,0,1,1,11,11,11,11,1,1,1,0,0
0,1,0,1,1,11,11,11,11,1,1,1,0,1
1,0,0,1,0,9,11,11,9,1,0,0,0,0
0,0,1,1,1,1,0,1,1,1,1,0,1,0
0,1,1,0,1,0,1,1,1,1,10,1,0,0
0,1,0,1,1,0,0,0,1,1,0,1,0,1
0,1,1,0,1,0,1,0,1,0,1,0,1,1
0,0,0,0,0,0,1,0,1,0,0,1,0,0
endlayer

layer
0,0,1,0,0,0,0,0,0,0,1,0,0,0
0,0,0,0,0,0,0,0,0,0,0,0,1,1
0,1,0,1,0,1,1,0,0,0,0,0,0,0
0,0,0,10,0,0,1,0,0,0,10,1,0,1
0,0,0,0,0,0,0,0,0,0,0,0,1,1
1,1,1,0,0,13,11,11,13,0,1,0,0,0
0,1,0,0,1,11,11,11,11,0,0,0,0,0
1,0,0,0,0,11,11,11,11,0,0,0,0,0
0,0,0,0,0,13,11,11,13,0,0,1,0,0
0,0,0,0,0,0,1,0,0,0,0,0,0,0
0,1,0,0,1,0,1,0,1,0,10,0,0,0
0,0,0,0,0,0,0,0,0,0,0,0,0,0
1,0,0,0,0,0,0,0,1,0,1,0,0,0
1,0,0,0,0,0,0,0,0,0,1,0,1,0
endlayer

layer
0,0,0,0,0,0,0,0,0,0,0,0,0,0
1,0,0,0,0,0,0,0,0,0,0,0,0,0
0,0,0,14,0,0,0,0,0,0,14,0,0,0
0,0,14,10,14,0,0,0,0,14,10,14,0,0
0,0,0,14,0,0,0,0,0,0,14,0,0,0
0,0,0,0,0,0,11,11,0,0,0,0,0,0
0,0,0,0,0,11,8,8,11,0,0,0,0,0
0,0,0,0,1,11,8,8,11,1,1,0,1,0
0,0,0,0,0,0,11,11,0,0,0,0,0,0
0,0,0,0,0,0,0,0,0,0,14,0,0,0
0,0,0,0,0,0,0,0,0,14,10,14,0,0
0,0,0,0,0,0,0,0,0,0,14,0,0,0
0,0,0,0,0,0,0,0,0,0,0,0,0,0
0,0,0,0,0,0,0,0,0,0,0,0,0,0
endlayer

layer
0,0,0,0,0,0,0,0,0,0,0,0,0,0
0,0,0,0,0,0,0,0,0,0,0,0,0,0
0,0,14,14,14,0,0,0,0,14,14,14,0,0
0,0,14,10,14,0,0,0,0,14,10,14,0,0
0,0,14,14,14,0,0,0,0,14,14,14,0,0
0,0,0,0,0,0,0,0,0,0,0,0,0,0
0,0,0,0,1,1,0,0,0,0,0,0,0,0
0,0,0,0,0,0,0,0,0,0,1,0,0,0
0,0,0,0,0,0,0,0,0,0,0,0,0,0
0,0,0,0,0,0,0,0,0,14,14,14,0,0
0,0,0,0,0,0,0,0,0,14,10,14,0,0
0,0,0,0,0,0,0,0,0,14,14,14,0,0
0,0,0,0,0,0,0,0,0,0,0,0,0,0
0,0,0,0,0,0,0,0,0,0,0,0,0,0
endlayer

layer
0,0,0,0,0,0,0,0,0,0,0,0,0,0
0,0,0,14,0,0,0,0,0,0,14,0,0,0
0,0,14,14,14,0,0,0,1,14,14,14,0,0
0,14,14,10,14,14,0,0,14,14,10,14,14,0
0,0,14,14,14,0,0,0,0,14,14,14,0,0
0,0,0,14,0,1,0,0,0,0,14,0,0,0
0,0,0,0,0,0,0,0,0,0,0,0,0,0
0,0,0,0,0,0,0,0,0,0,0,0,0,0
0,0,0,0,0,0,0,0,0,0,14,0,0,0
0,0,0,0,0,0,0,0,0,14,14,14,0,0
0,0,0,0,0,0,0,0,14,14,10,14,14,0
0,0,0,0,0,0,0,0,0,14,14,14,0,0
0,0,0,1,0,0,0,0,0,0,14,0,0,0
0,0,0,0,0,0,0,0,0,0,0,0,0,0
endlayer

layer
0,0,0,0,0,0,0,0,0,0,0,0,0,0
0,0,14,14,14,0,0,0,0,0,14,0,0,0
0,14,14,14,14,0,0,0,14,14,14,14,14,0
0,0,14,10,14,14,0,0,0,14,10,14,0,0
0,0,14,14,14,0,0,0,0,14,14,14,14,0
0,0,14,0,14,0,0,0,0,14,14,14,0,0
0,0,0,0,0,0,1,1,0,0,0,0,0,0
0,0,0,0,0,0,0,0,1,0,0,0,0,0
0,0,0,0,0,0,0,0,0,14,0,14,0,0
0,0,0,0,0,0,0,0,14,14,14,14,0,0
0,0,0,0,0,0,0,0,0,14,10,14,0,0
0,0,0,0,0,0,0,0,14,14,14,14,0,0
0,0,0,0,0,0,0,0,0,0,0,0,0,0
0,0,0,0,0,0,0,0,0,0,0,0,0,0
endlayer

layer
0,0,0,0,0,0,0,0,0,0,0,0,0,0
0,0,0,0,0,0,0,0,0,14,0,0,0,0
0,14,14,14,14,0,0,0,0,14,14,14,0,0
0,14,14,10,14,14,0,0,14,14,10,14,0,0
0,0,14,14,14,0,0,0,14,14,14,14,14,0
0,0,14,0,14,0,0,0,0,0,14,14,0,0
0,0,0,0,0,0,0,0,0,0,0,0,0,0
0,0,0,0,0,0,0,0,0,0,0,0,0,0
0,0,0,0,0,0,0,0,0,14,0,14,0,0
0,0,0,0,0,0,0,0,14,14,14,14,0,0
0,0,0,0,0,0,0,0,14,14,10,14,14,0
0,0,0,0,0,0,0,0,0,14,14,14,14,0
0,0,0,0,0,0,0,0,0,14,0,0,0,0
0,0,0,0,0,0,0,0,0,0,0,0,0,0
endlayer

layer
0,0,0,0,0,0,0,0,0,0,0,0,0,0
0,0,14,14,14,0,0,0,0,0,0,0,0,0
0,14,14,14,14,14,0,0,0,14,14,14,0,0
0,0,14,10,14,14,0,0,0,14,10,14,0,0
0,14,14,14,14,14,0,0,14,14,14,14,0,0
0,0,0,0,0,0,0,0,0,14,14,0,0,0
0,0,0,0,0,0,0,0,0,0,0,0,0,0
0,0,0,0,0,0,0,0,0,0,0,0,0,0
0,0,0,0,0,0,0,0,0,14,0,14,0,0
0,0,0,0,0,0,0,0,14,14,14,14,14,0
0,0,0,0,0,0,0,0,0,14,10,14,14,0
0,0,0,0,0,0,0,0,14,14,14,14,14,0
0,0,0,0,0,0,0,0,0,0,14,0,0,0
0,0,0,0,0,0,0,0,0,0,0,0,0,0
endlayer

layer
0,0,0,0,0,0,0,0,0,0,0,0,0,0
0,0,14,0,0,0,0,0,0,0,14,0,0,0
0,0,14,14,14,0,0,0,14,14,14,14,14,0
0,14,14,10,14,0,0,0,0,14,10,14,0,0
0,0,14,14,14,14,0,0,14,14,14,14,14,0
0,0,14,0,14,0,0,0,0,0,0,14,0,0
0,0,0,0,0,0,0,0,0,0,0,0,0,0
0,0,0,0,0,0,0,0,0,0,0,0,0,0
0,0,0,0,0,0,0,0,0,0,14,14,0,0
0,0,0,0,0,0,0,0,0,14,14,14,14,0
0,0,0,0,0,0,0,0,0,14,10,14,14,0
0,0,0,0,0,0,0,0,0,14,14,14,0,0
0,0,0,0,0,0,0,0,0,0,0,14,0,0
0,0,0,0,0,0,0,0,0,0,0,0,0,0
endlayer

layer
0,0,0,0,0,0,0,0,0,0,0,0,0,0
0,0,14,0,0,0,0,0,0,14,14,14,0,0
0,0,14,14,14,14,0,0,14,14,14,14,14,0
0,14,14,10,14,0,0,0,14,14,10,14,14,0
0,0,14,14,14,0,0,0,0,14,14,14,14,0
0,0,0,14,14,0,0,0,0,0,0,0,0,0
0,0,0,0,0,0,0,0,0,0,0,0,0,0
0,0,0,0,0,0,0,0,0,0,0,0,0,0
0,0,0,0,0,0,0,0,0,0,0,0,0,0
0,0,0,0,0,0,0,0,14,14,14,14,14,0
0,0,0,0,0,0,0,0,14,14,10,14,0,0
0,0,0,0,0,0,0,0,0,14,14,14,0,0
0,0,0,0,0,0,0,0,0,0,14,0,0,0
0,0,0,0,0,0,0,0,0,1,0,0,0,0
endlayer

layer
0,0,0,0,0,0,0,0,0,0,0,0,0,0
0,0,0,14,14,0,0,0,0,0,14,0,0,0
0,0,14,14,14,14,0,0,0,14,14,14,0,0
0,14,14,10,14,14,0,0,0,14,14,14,0,0
0,14,14,14,14,0,0,0,0,14,14,0,0,0
0,0,14,0,14,0,0,0,0,0,14,0,0,0
0,0,0,0,0,0,0,0,0,0,0,0,0,0
0,0,0,0,0,0,0,0,0,0,0,0,0,0
0,0,0,0,0,0,0,0,0,0,0,0,0,0
0,0,0,0,0,0,0,0,0,0,14,14,0,0
0,0,0,0,0,0,0,0,0,14,14,14,0,0
0,0,0,0,0,0,0,0,0,0,14,0,0,0
0,0,0,0,0,0,0,0,0,0,0,0,0,0
0,0,0,0,0,0,0,0,0,0,0,0,0,0
endlayer

layer
0,0,0,0,0,0,0,0,0,0,0,0,0,0
0,0,14,14,14,0,0,0,0,0,0,0,0,0
0,0,14,14,14,14,0,0,0,0,0,14,0,0
0,14,14,10,14,14,0,0,0,0,14,14,0,0
0,0,14,14,14,14,0,0,0,14,14,14,0,0
0,0,0,0,0,0,0,0,0,0,0,0,0,0
0,0,0,0,0,0,0,0,0,0,0,0,0,0
0,0,0,0,0,0,0,0,0,0,0,0,0,0
0,0,0,0,0,0,0,0,0,0,0,0,0,0
0,0,0,0,0,0,0,0,0,14,14,0,0,0
0,0,0,0,0,0,0,0,0,0,14,0,0,0
0,0,0,0,0,0,0,0,0,0,0,0,0,0
0,0,0,0,0,0,0,0,0,0,0,0,0,0
0,0,0,0,0,0,0,0,0,0,0,0,0,0
endlayer

layer
0,0,0,0,0,0,0,0,0,0,0,0,0,0
0,0,0,14,0,0,0,0,0,0,0,0,0,0
0,0,14,14,14,0,0,0,0,0,14,0,0,0
0,14,14,14,14,0,0,0,0,14,14,14,0,0
0,0,0,14,0,0,0,0,0,0,0,0,0,0
0,0,0,14,0,0,0,0,0,0,0,0,0,0
0,0,0,0,0,0,0,0,0,0,0,0,0,0
0,0,0,0,0,0,0,0,0,0,0,0,0,0
0,0,0,0,0,0,0,0,0,0,0,0,0,0
0,0,0,0,0,0,0,0,0,0,0,0,0,0
0,0,0,0,0,0,0,0,0,0,14,0,0,0
0,0,0,0,0,0,0,0,0,0,0,0,0,0
0,0,0,0,0,0,0,0,0,0,0,0,0,0
0,0,0,0,0,0,0,0,0,0,0,0,0,0
endlayer

layer
0,0,0,0,0,0,0,0,0,0,0,0,0,0
0,0,0,0,0,0,0,0,0,0,0,0,0,0
0,0,0,0,0,0,0,0,0,0,0,0,0,0
0,0,14,14,14,0,0,0,0,0,14,0,0,0
0,0,14,14,0,0,0,0,0,0,0,0,0,0
0,0,0,0,0,0,0,0,0,0,0,0,0,0
0,0,0,0,0,0,0,0,0,0,0,0,0,0
0,0,0,0,0,0,0,0,0,0,0,0,0,0
0,0,0,0,0,0,0,0,0,0,0,0,0,0
0,0,0,0,0,0,0,0,0,0,0,0,0,0
0,0,0,0,0,0,0,0,0,0,14,0,0,0
0,0,0,0,0,0,0,0,0,0,0,0,0,0
0,0,0,0,0,0,0,0,0,0,0,0,0,0
0,0,0,0,0,0,0,0,0,0,0,0,0,0
endlayer

layer
0,0,0,0,0,0,0,0,0,0,0,0,0,0
0,0,0,0,0,0,0,0,0,0,0,0,0,0
0,0,0,0,0,0,0,0,0,0,0,0,0,0
0,0,0,14,0,0,0,0,0,0,14,0,0,0
0,0,0,0,0,0,0,0,0,0,0,0,0,0
0,0,0,0,0,0,0,0,0,0,0,0,0,0
0,0,0,0,0,0,0,0,0,0,0,0,0,0
0,0,0,0,0,0,0,0,0,0,0,0,0,0
0,0,0,0,0,0,0,0,0,0,0,0,0,0
0,0,0,0,0,0,0,0,0,0,0,0,0,0
0,0,0,0,0,0,0,0,0,0,14,0,0,0
0,0,0,0,0,0,0,0,0,0,0,0,0,0
0,0,0,0,0,0,0,0,0,0,0,0,0,0
0,0,0,0,0,0,0,0,0,0,0,0,0,0
endlayer

layer
0,0,0,0,0,0,0,0,0,0,0,0,0,0
0,0,0,0,0,0,0,0,0,0,0,0,0,0
0,0,0,0,0,0,0,0,0,0,0,0,0,0
0,0,0,14,0,0,0,0,0,0,0,0,0,0
0,0,0,0,0,0,0,0,0,0,0,0,0,0
0,0,0,0,0,0,0,0,0,0,0,0,0,0
0,0,0,0,0,0,0,0,0,0,0,0,0,0
0,0,0,0,0,0,0,0,0,0,0,0,0,0
0,0,0,0,0,0,0,0,0,0,0,0,0,0
0,0,0,0,0,0,0,0,0,0,0,0,0,0
0,0,0,0,0,0,0,0,0,0,0,0,0,0
0,0,0,0,0,0,0,0,0,0,0,0,0,0
0,0,0,0,0,0,0,0,0,0,0,0,0,0
0,0,0,0,0,0,0,0,0,0,0,0,0,0
endlayer

layer
0,0,0,0,0,0,0,0,0,0,0,0,0,0
0,0,0,0,0,0,0,0,0,0,0,0,0,0
0,0,0,0,0,0,0,0,0,0,0,0,0,0
0,0,0,14,0,0,0,0,0,0,0,0,0,0
0,0,0,0,0,0,0,0,0,0,0,0,0,0
0,0,0,0,0,0,0,0,0,0,0,0,0,0
0,0,0,0,0,0,0,0,0,0,0,0,0,0
0,0,0,0,0,0,0,0,0,0,0,0,0,0
0,0,0,0,0,0,0,0,0,0,0,0,0,0
0,0,0,0,0,0,0,0,0,0,0,0,0,0
0,0,0,0,0,0,0,0,0,0,0,0,0,0
0,0,0,0,0,0,0,0,0,0,0,0,0,0
0,0,0,0,0,0,0,0,0,0,0,0,0,0
0,0,0,0,0,0,0,0,0,0,0,0,0,0
endlayer

