
# Created by Ruins mod version 14.4 Ingame Parser
# authoring Player: Mikhaila666

weight=1
embed_into_distance=0
acceptable_target_blocks=
unacceptable_target_blocks=flowing_water,water,flowing_lava,lava
dimensions=19,30,30
allowable_overhang=0
max_leveling=2
leveling_buffer=0
preserve_water=0
preserve_lava=0

rule1=0,100,minecraft:dirt-0
rule2=0,100,minecraft:grass-0
rule3=0,100,minecraft:gravel-0
rule4=0,100,minecraft:stone-0
rule5=0,100,Railcraft:tile.railcraft.residual.heat-0
rule6=0,100,minecraft:sand-0
rule7=0,100,minecraft:sandstone-0
rule8=0,100,minecraft:cobblestone-0
rule9=0,100,minecraft:netherrack-0
rule10=0,100,minecraft:tallgrass-1
rule11=0,100,minecraft:cobblestone_wall-0
rule12=0,100,minecraft:stone_stairs-0
rule13=0,100,minecraft:log-0
rule14=0,100,minecraft:fence-0
rule15=0,100,minecraft:stonebrick-2
rule16=0,100,minecraft:stone_stairs-3
rule17=0,100,minecraft:stone_stairs-1
rule18=0,100,minecraft:stone_stairs-2
rule19=0,100,minecraft:stone_slab-3
rule20=0,100,minecraft:spruce_stairs-0
rule21=0,100,minecraft:wooden_door-2
rule22=0,100,minecraft:wooden_slab-1
rule23=0,100,minecraft:stone_stairs-7
rule24=0,100,minecraft:stone_stairs-6
rule25=0,100,ChestGenHook:dungeonChest:5-3
rule26=0,100,ChestGenHook:dungeonChest:5-2
rule27=0,100,minecraft:ladder-4
rule28=0,100,minecraft:crafting_table-0
rule29=0,100,minecraft:cauldron-2
rule30=0,100,minecraft:anvil-1
rule31=0,100,minecraft:wooden_door-8
rule32=2,100,minecraft:torch-1
rule33=0,100,minecraft:spruce_stairs-6
rule34=0,100,minecraft:spruce_stairs-7
rule35=0,100,minecraft:stone_stairs-4
rule36=0,100,minecraft:spruce_stairs-5
rule37=0,100,minecraft:wooden_slab-10
rule38=0,100,minecraft:wooden_slab-9
rule39=0,100,minecraft:stone_stairs-5
rule40=0,100,minecraft:iron_bars-0
rule41=0,100,minecraft:stone_slab-11
rule42=0,100,minecraft:wooden_slab-2
rule43=0,100,minecraft:spruce_stairs-2
rule44=0,100,minecraft:spruce_stairs-4
rule45=0,100,minecraft:spruce_stairs-3
rule46=0,100,minecraft:hay_block-0
rule47=0,100,minecraft:double_stone_slab-3
rule48=0,100,minecraft:spruce_stairs-1
rule49=2,100,minecraft:torch-2
rule50=0,100,minecraft:birch_stairs-0
rule51=0,100,minecraft:planks-1

layer
0,0,0,0,0,0,0,0,0,0,0,0,0,0,0,0,0,0,0,0,0,0,0,0,0,0,0,0,0,0
0,0,0,0,0,0,0,0,0,0,0,2,2,2,2,2,2,2,2,2,3,3,2,2,2,2,1,2,1,0
0,0,0,0,0,0,0,0,0,0,0,2,2,2,2,2,0,2,2,0,1,1,2,2,0,1,2,1,2,0
0,0,0,0,0,0,0,0,0,0,0,2,2,2,2,0,0,0,0,0,0,0,0,0,0,2,4,2,1,0
0,0,0,0,0,0,0,0,0,5,0,2,2,2,2,2,0,0,0,0,0,0,0,0,0,4,1,1,1,0
0,0,0,0,0,0,0,0,5,5,0,2,2,2,2,2,0,0,0,0,0,0,0,0,0,4,2,1,1,0
0,0,0,0,0,0,0,0,0,0,0,2,2,2,2,2,0,0,0,0,0,0,0,0,0,4,1,2,1,0
0,0,0,0,0,0,0,0,0,0,0,2,2,2,2,0,0,0,0,0,0,0,0,0,0,0,2,1,1,0
0,0,0,0,0,0,0,0,5,0,0,2,2,2,2,2,0,0,0,0,0,0,0,0,0,2,2,2,1,0
0,0,0,0,0,5,0,0,0,0,0,2,2,2,2,2,0,0,0,0,0,0,0,0,0,2,2,2,1,0
0,0,0,0,0,0,0,0,5,5,0,2,2,2,2,2,0,0,0,0,0,0,0,0,0,2,2,2,2,0
0,0,0,0,5,0,0,0,0,0,5,2,2,2,2,0,0,0,0,0,0,0,0,0,0,0,2,2,2,0
0,0,0,0,0,0,0,0,0,5,5,2,2,2,2,2,0,0,0,0,0,0,0,0,0,2,2,2,2,0
0,0,0,0,0,0,0,0,0,5,0,2,2,2,2,2,1,1,1,1,0,0,0,0,0,2,2,2,2,0
0,0,0,0,0,0,0,5,0,5,0,2,2,2,2,2,0,0,0,6,7,0,0,0,0,6,2,2,2,0
0,0,0,0,0,0,0,0,0,5,5,2,2,2,2,0,1,1,1,1,0,0,0,0,0,1,2,2,2,0
0,0,0,0,0,0,5,0,5,0,0,2,2,2,2,2,0,0,0,0,0,0,0,0,0,2,2,2,2,0
0,0,0,0,0,0,0,0,5,5,0,2,2,2,2,2,0,0,0,0,0,0,0,0,0,2,2,2,2,0
0,0,0,0,0,5,0,0,5,0,0,2,2,2,2,2,0,0,0,0,0,0,0,0,0,2,2,2,2,0
0,0,0,0,5,0,5,5,0,0,0,2,2,2,2,0,0,0,0,0,0,0,0,0,0,0,2,2,2,0
0,0,0,0,0,0,0,0,0,0,0,2,2,2,2,2,2,0,0,0,0,0,0,0,2,2,2,2,2,0
0,0,0,0,0,0,0,0,0,0,0,2,2,2,2,2,2,2,0,0,0,0,0,2,2,2,2,2,2,0
0,0,0,0,0,0,0,0,0,0,0,2,2,2,2,2,2,0,0,0,0,0,0,0,0,2,2,2,2,0
0,0,0,0,5,0,0,0,0,0,0,2,2,2,2,2,2,2,0,0,0,0,0,0,0,8,2,2,2,0
0,0,0,0,0,5,0,0,0,0,0,2,2,2,2,2,2,0,0,4,8,8,0,0,0,2,2,2,2,0
0,0,0,0,0,0,0,0,0,0,5,2,2,2,2,2,2,0,0,0,4,0,0,0,0,2,2,2,2,5
0,0,0,0,0,0,0,0,0,0,0,2,2,2,2,2,2,0,0,0,9,0,0,0,8,2,2,2,2,0
0,0,0,0,0,0,0,0,0,0,0,2,2,2,2,2,2,2,4,8,4,4,4,2,2,2,2,2,2,0
0,0,0,0,0,0,0,0,0,0,5,2,2,2,2,2,2,2,2,2,2,2,2,2,2,2,2,2,2,0
0,0,0,0,0,0,0,0,0,0,0,0,5,0,0,0,0,0,0,0,0,0,0,0,0,0,0,5,0,0
endlayer

layer
0,0,0,0,0,0,0,0,0,0,0,0,0,0,0,0,0,0,0,0,0,0,0,0,0,0,0,0,0,0
0,0,0,0,0,0,0,0,0,0,0,0,0,0,0,10,0,10,10,11,12,11,10,0,0,2,2,2,2,0
0,0,0,0,0,0,0,0,0,0,0,0,0,0,0,0,13,14,14,13,15,13,14,14,13,2,2,2,2,0
0,0,0,0,0,0,0,0,0,0,0,0,0,0,11,15,0,15,15,0,15,0,15,15,0,15,11,2,2,0
0,0,0,0,0,0,0,0,0,0,0,0,0,0,0,11,15,15,15,15,15,15,15,15,15,11,2,2,2,0
0,0,0,0,0,0,0,0,0,0,0,0,0,0,0,14,15,15,15,15,15,15,15,15,15,14,2,2,2,0
0,0,0,0,0,5,0,0,0,0,0,0,0,0,0,11,15,15,15,15,15,15,15,15,15,11,2,2,2,0
0,0,0,0,0,0,0,0,0,0,0,0,0,0,11,15,15,15,15,15,15,15,15,15,15,15,11,2,2,0
0,0,0,0,0,0,0,0,0,0,0,0,0,0,0,11,15,15,15,15,15,15,15,15,15,11,0,0,2,0
0,0,0,0,0,0,0,0,0,0,0,0,0,0,0,14,15,15,15,15,15,15,15,15,15,14,0,0,2,0
0,0,0,0,0,0,0,0,0,0,0,0,0,0,0,11,15,15,15,15,15,15,15,15,15,11,0,0,0,0
0,0,0,0,0,0,0,0,0,0,0,0,0,0,11,15,15,15,15,15,15,15,15,15,15,15,11,0,0,0
0,0,0,0,0,0,0,0,0,0,0,0,0,0,0,11,15,15,15,15,15,15,15,15,15,11,0,0,0,0
0,0,0,0,0,0,0,0,0,0,0,0,0,0,0,14,15,15,15,15,15,15,15,15,15,14,0,0,0,0
0,0,0,0,0,0,0,0,0,0,0,0,0,0,0,11,15,15,15,15,15,15,15,15,15,11,0,0,0,0
0,0,0,0,0,0,0,0,0,0,0,0,0,0,11,15,15,15,15,15,15,15,15,15,15,15,11,0,0,0
0,0,0,0,0,0,0,0,0,0,0,0,0,0,0,11,15,15,15,15,15,15,15,15,15,11,0,0,0,0
0,0,0,0,0,0,0,0,0,0,0,0,0,0,0,14,15,15,15,15,15,15,15,15,15,14,0,0,0,0
0,0,0,0,0,0,0,0,0,0,0,0,0,0,0,11,15,15,0,15,15,15,0,15,15,11,0,0,0,0
0,0,0,0,0,0,0,0,0,0,0,0,0,0,11,15,15,0,0,15,15,15,0,0,15,15,11,0,0,0
0,0,0,0,0,0,0,0,0,0,0,0,0,0,0,0,0,13,0,15,15,15,0,13,0,0,0,0,0,0
0,0,0,0,0,0,0,0,0,0,0,0,0,0,0,0,0,0,15,15,15,15,15,0,0,0,0,0,0,0
0,0,0,0,0,0,0,0,0,0,0,0,0,0,0,0,0,13,0,15,15,15,0,13,2,0,0,0,0,0
0,0,0,0,0,0,0,0,0,0,0,0,0,0,0,0,0,0,15,15,15,15,0,2,2,2,0,0,0,0
0,0,0,0,0,0,0,0,0,0,0,0,0,0,0,0,0,13,15,18,17,16,15,0,2,0,0,0,0,0
0,0,0,0,0,0,0,0,0,0,0,0,0,0,0,0,0,2,0,15,19,15,0,2,2,10,0,0,0,0
0,0,0,0,0,0,0,0,0,0,0,0,0,0,0,0,0,13,0,15,0,15,0,13,2,0,0,0,0,0
0,0,0,0,0,0,0,0,0,0,0,0,0,0,0,0,0,0,2,15,15,15,2,0,0,0,0,0,0,0
0,0,0,0,0,0,0,0,0,0,0,0,0,0,0,0,0,0,0,0,0,0,0,0,0,0,0,0,0,0
0,0,0,0,0,0,0,0,0,0,0,0,0,0,0,0,0,0,0,0,0,0,0,0,0,0,0,0,0,0
endlayer

layer
0,0,0,0,0,0,0,0,0,0,0,0,0,0,0,0,0,0,0,0,0,0,0,0,0,0,0,0,0,0
0,0,0,0,0,0,0,0,0,0,0,0,0,0,0,0,0,0,0,14,0,14,0,0,0,10,10,0,10,0
0,0,0,0,0,0,0,0,0,0,0,0,0,0,0,0,13,20,20,13,21,13,20,20,13,0,10,10,10,0
0,0,0,0,0,0,0,0,0,0,0,0,0,0,14,13,0,13,13,15,0,15,13,13,0,13,14,10,10,0
0,0,0,0,0,0,0,0,0,0,0,0,0,0,0,22,15,24,0,0,0,0,0,23,15,22,0,10,10,0
0,0,0,0,0,0,0,0,0,0,0,0,0,0,0,22,16,26,0,0,0,0,0,25,18,22,10,0,10,0
0,0,0,0,0,0,0,0,0,0,0,0,0,0,0,22,15,24,0,0,0,0,0,23,15,22,0,10,0,0
0,0,0,0,0,0,0,0,0,0,0,0,0,0,14,13,0,0,0,0,0,0,0,0,0,13,14,0,10,0
0,0,0,0,5,0,0,0,0,0,0,0,0,0,0,22,15,24,0,0,0,0,0,23,15,22,0,0,0,0
0,0,0,0,0,0,0,0,0,0,0,0,0,0,0,22,16,26,0,0,0,0,0,25,18,22,0,0,0,0
0,0,0,0,0,0,0,0,0,0,0,0,0,0,0,22,15,24,0,0,0,0,0,23,15,22,0,0,0,0
0,0,0,0,0,0,0,0,0,0,0,0,0,0,14,13,0,0,0,0,0,0,0,0,0,13,14,0,0,0
0,0,0,0,0,0,0,0,0,0,0,0,0,0,0,22,15,24,0,0,0,0,0,23,15,22,0,0,0,0
0,0,0,0,0,0,0,0,0,0,0,0,0,0,0,22,16,26,0,0,0,0,0,25,18,22,0,0,0,0
0,0,0,5,0,0,0,0,0,0,0,0,0,0,0,22,15,24,0,0,0,0,0,23,15,22,0,0,0,0
0,0,0,0,0,0,0,0,0,0,0,0,0,0,14,13,0,0,0,0,0,0,0,0,0,13,14,0,0,0
0,0,0,0,0,0,0,0,0,0,0,0,0,0,0,22,15,0,0,0,0,0,0,0,15,22,0,0,0,0
0,0,0,0,0,0,0,0,0,0,0,0,0,0,0,22,16,0,11,0,0,0,11,0,18,22,0,0,0,0
0,0,0,0,0,0,0,0,0,0,0,0,0,0,0,22,15,27,13,0,0,0,13,27,15,22,0,0,0,0
0,0,0,0,0,0,0,0,0,0,0,0,0,0,14,13,15,15,15,0,0,0,15,15,15,13,14,0,0,0
0,0,0,0,0,0,0,0,0,0,0,0,0,0,0,0,0,13,15,0,0,0,15,13,0,0,0,0,0,0
0,5,0,0,0,0,0,0,0,0,0,0,0,0,0,0,0,0,15,0,0,28,15,0,0,0,0,0,0,0
0,0,0,0,0,0,0,0,0,0,0,0,0,0,0,0,0,13,15,0,0,29,15,13,10,0,0,0,0,0
0,0,0,0,0,0,0,0,0,0,0,0,0,0,0,0,0,0,15,0,0,30,15,10,0,10,0,0,0,0
0,0,0,0,0,0,0,0,0,0,0,0,0,0,0,0,0,13,15,0,0,0,15,13,10,0,0,0,0,0
0,0,0,0,0,0,0,0,0,0,0,0,0,0,0,0,0,0,15,15,0,15,15,10,10,0,0,0,0,0
0,0,0,0,0,0,0,0,0,0,0,0,0,0,0,0,0,13,15,15,0,15,15,13,0,0,0,0,0,0
0,0,0,0,0,0,0,0,0,0,0,0,0,0,0,0,0,0,0,15,15,15,0,0,0,0,0,0,0,0
0,0,0,0,0,0,0,0,0,0,0,0,0,0,0,0,0,0,0,0,0,0,0,0,0,0,0,0,0,0
0,0,0,0,0,0,0,0,0,5,0,0,0,0,0,0,0,0,0,0,0,0,0,0,0,0,0,0,0,0
endlayer

layer
0,0,0,0,0,0,0,0,0,0,0,0,0,0,0,0,0,0,0,0,0,0,0,0,0,0,0,0,0,0
0,0,0,0,0,0,0,0,0,0,0,0,0,0,0,0,0,0,0,14,0,14,0,0,0,0,0,0,0,0
0,0,0,0,0,0,0,0,0,0,0,0,0,0,0,0,13,0,0,13,31,13,0,0,13,0,0,0,0,0
0,0,0,0,0,0,0,0,0,0,0,0,0,0,14,13,15,14,14,15,0,15,14,14,15,13,14,0,0,0
0,0,0,0,0,0,0,0,0,0,0,0,0,0,0,0,15,26,0,32,0,32,0,25,15,0,0,0,0,0
0,0,0,0,0,0,0,0,0,0,0,0,0,0,0,0,14,0,0,0,0,0,0,0,14,0,0,0,0,0
0,0,0,0,0,0,0,0,0,0,0,0,0,0,0,0,15,26,0,0,0,0,0,25,15,0,0,0,0,0
0,0,0,0,0,0,0,0,0,0,0,0,0,0,14,13,0,0,0,0,0,0,0,0,0,13,14,0,0,0
0,0,0,0,0,0,0,0,0,0,0,0,0,0,0,0,15,26,0,0,0,0,0,25,15,0,0,0,0,0
0,0,0,0,0,0,0,0,0,0,0,0,0,0,0,0,14,0,0,0,0,0,0,0,14,0,0,0,0,0
0,0,0,0,0,0,0,0,0,0,0,0,0,0,0,0,15,26,0,0,0,0,0,25,15,0,0,0,0,0
0,0,0,0,0,0,0,0,0,0,0,0,0,0,14,13,0,0,0,0,0,0,0,0,0,13,14,0,0,0
0,0,0,0,0,0,0,0,0,0,0,0,0,0,0,0,15,26,0,0,0,0,0,25,15,0,0,0,0,0
0,0,0,0,0,0,0,0,0,0,0,0,0,0,0,0,14,0,0,0,0,0,0,0,14,0,0,0,0,0
0,0,0,0,0,0,0,0,0,0,0,0,0,0,0,0,15,26,0,0,0,0,0,25,15,0,0,0,0,0
0,0,0,0,0,0,0,0,0,0,0,0,0,0,14,13,0,0,0,0,0,0,0,0,0,13,14,0,0,0
0,0,0,0,0,0,0,0,0,0,0,0,0,0,0,0,15,0,0,0,0,0,0,0,15,0,0,0,0,0
0,0,0,0,0,0,0,0,0,0,0,0,0,0,0,0,14,0,14,0,0,0,14,0,14,0,0,0,0,0
0,0,0,0,0,0,0,0,0,0,0,0,0,0,0,0,15,27,13,0,0,0,13,27,15,0,0,0,0,0
0,0,0,0,0,0,0,0,0,0,0,0,0,0,14,13,15,15,15,0,0,0,15,15,15,13,14,0,0,0
0,0,0,0,0,0,0,0,0,0,0,0,0,0,0,0,0,13,15,0,0,0,15,13,0,0,0,0,0,0
0,0,0,0,0,0,0,0,0,0,0,0,0,0,0,0,0,34,15,0,0,0,15,33,0,0,0,0,0,0
0,0,0,0,0,0,0,0,0,0,0,0,0,0,0,0,0,13,15,0,0,0,15,13,0,0,0,0,0,0
0,0,0,0,0,0,0,0,0,0,0,0,0,0,0,0,0,34,15,0,0,0,15,33,0,0,0,0,0,0
0,0,0,0,0,0,0,0,0,0,0,0,0,0,0,0,0,13,15,0,0,0,15,13,0,0,0,0,0,0
0,0,0,0,0,0,0,0,0,0,0,0,0,0,0,0,0,34,15,16,35,18,15,33,0,0,0,0,0,0
0,0,0,0,0,0,0,0,0,0,0,0,0,0,0,0,0,13,15,15,0,15,15,13,0,0,0,0,0,0
0,0,0,0,0,0,0,0,0,0,0,0,0,0,0,0,0,36,36,15,15,15,36,36,0,0,0,0,0,0
0,0,0,0,0,0,0,0,0,0,0,0,0,0,0,0,0,0,0,0,0,0,0,0,0,0,0,0,0,0
0,0,0,0,0,0,0,0,0,0,0,0,0,0,0,0,0,0,0,0,0,0,0,0,0,0,0,0,0,0
endlayer

layer
0,0,0,0,0,0,0,0,0,0,0,0,0,0,0,0,0,0,0,0,0,0,0,0,0,0,0,0,0,0
0,0,0,0,0,0,0,0,0,0,0,0,37,0,0,0,0,0,0,14,0,14,0,0,0,0,0,0,37,0
0,0,0,0,0,0,0,0,0,0,0,0,38,0,0,0,13,0,0,13,14,13,0,0,13,0,0,0,38,0
0,0,0,0,0,0,0,0,0,0,0,0,38,0,11,15,15,14,14,15,14,15,14,14,15,15,11,0,38,0
0,0,0,0,0,0,0,0,0,0,0,0,38,0,0,39,15,11,40,0,0,0,0,11,15,39,0,0,38,0
0,0,0,0,0,0,0,0,0,0,0,0,38,0,0,0,14,0,0,0,0,0,0,0,14,0,0,0,38,0
0,0,0,0,0,0,0,0,0,0,0,0,38,0,0,35,15,11,0,0,0,0,0,11,15,35,0,0,38,0
0,0,0,0,0,0,0,0,0,0,0,0,38,0,11,15,24,0,0,0,0,0,0,0,23,15,11,0,38,0
0,0,0,0,0,0,0,0,0,0,0,0,38,0,0,39,15,11,0,0,0,0,40,11,15,39,0,0,38,0
0,0,0,0,0,0,0,0,0,0,0,0,38,0,0,0,14,0,0,0,0,0,0,0,14,0,0,0,38,0
0,0,0,0,0,0,0,0,0,0,0,0,38,0,0,35,15,11,40,0,0,0,0,11,15,35,0,0,38,0
0,0,0,0,0,0,0,0,0,0,0,0,38,0,11,15,24,0,0,0,0,0,0,0,23,15,11,0,38,0
0,0,0,0,0,0,0,0,0,0,0,0,38,0,0,39,15,11,0,0,0,0,0,11,15,39,0,0,38,0
0,0,0,0,0,0,0,0,0,0,0,0,38,0,0,0,14,0,0,0,0,0,0,0,14,0,0,0,38,0
0,0,0,0,0,0,0,0,0,0,0,0,38,0,0,35,15,11,0,0,0,0,40,11,15,35,0,0,38,0
0,0,0,0,0,0,0,0,0,0,0,0,38,0,11,15,24,0,0,0,0,0,0,0,23,15,11,0,38,0
0,0,0,0,0,0,0,0,0,0,0,0,38,0,0,39,15,0,40,0,0,0,0,0,15,39,0,0,38,0
0,0,0,0,0,0,0,0,0,0,0,0,38,0,0,0,14,0,14,0,0,0,14,0,14,0,0,0,38,0
0,0,0,0,0,0,0,0,0,0,0,0,38,0,0,35,15,27,13,0,0,0,13,27,15,35,0,0,38,0
0,0,0,0,0,0,0,0,0,0,0,0,38,0,11,15,15,15,15,0,0,0,15,15,15,15,11,0,38,0
0,0,0,0,0,0,0,0,0,0,0,0,38,0,0,0,0,11,15,0,0,0,15,11,0,0,0,0,38,0
0,0,0,0,0,0,0,0,0,0,0,0,0,0,0,0,0,0,41,0,0,0,41,0,0,0,0,0,0,0
0,0,0,0,0,0,0,0,0,0,0,0,0,0,0,0,0,11,15,0,0,0,15,11,0,0,0,0,0,0
0,0,0,0,0,0,0,0,0,0,0,0,0,0,0,0,0,0,41,0,0,0,41,0,0,0,0,0,0,0
0,0,0,0,0,0,0,0,0,0,0,0,0,0,0,0,0,11,15,0,0,0,15,11,0,0,0,0,0,0
0,0,0,0,0,0,0,0,0,0,0,0,0,0,0,0,0,0,41,0,15,0,41,0,0,0,0,0,0,0
0,0,0,0,0,0,0,0,0,0,0,0,0,0,0,0,0,11,15,15,0,15,15,11,0,0,0,0,0,0
0,0,0,0,0,0,0,0,0,0,0,0,0,0,0,0,0,0,0,15,15,15,0,0,0,0,0,0,0,0
0,0,0,0,0,0,0,0,0,0,0,0,0,0,0,0,0,0,0,0,0,0,0,0,0,0,0,0,0,0
0,0,0,0,0,0,0,0,0,0,0,0,0,0,0,0,0,0,0,0,0,0,0,0,0,0,0,0,0,0
endlayer

layer
0,0,0,0,0,0,0,0,0,0,0,0,0,0,0,0,0,0,0,0,0,0,0,0,0,0,0,0,0,0
0,0,0,0,0,0,0,0,0,0,0,0,0,42,37,0,0,0,0,42,37,42,0,0,0,0,37,42,0,0
0,0,0,0,0,0,0,0,0,0,0,0,0,45,33,37,13,0,0,13,44,13,0,0,13,37,34,43,0,0
0,0,0,0,0,0,0,0,0,0,0,0,14,46,13,15,15,33,34,15,36,15,33,34,15,15,13,46,14,0
0,0,0,0,0,0,0,0,0,0,0,0,0,46,0,0,15,22,40,11,0,11,0,22,15,0,0,46,0,0
0,0,0,0,0,0,0,0,0,0,0,0,14,46,0,19,15,22,0,0,0,0,0,22,15,19,0,46,14,0
0,0,0,0,0,0,0,0,0,0,0,0,0,46,0,0,15,22,40,0,0,0,40,22,15,0,0,46,0,0
0,0,0,0,0,0,0,0,0,0,0,0,14,46,13,15,15,22,0,0,0,0,0,22,15,15,13,46,14,0
0,0,0,0,0,0,0,0,0,0,0,0,0,46,0,0,15,22,0,0,0,0,40,22,15,0,0,46,0,0
0,0,0,0,0,0,0,0,0,0,0,0,14,46,0,19,15,22,0,0,0,0,0,22,15,19,0,46,14,0
0,0,0,0,0,0,0,0,0,0,0,0,0,46,0,0,15,22,40,0,0,0,0,22,15,0,0,46,0,0
0,0,0,0,0,0,0,0,0,0,0,0,14,46,13,15,15,22,0,0,0,0,0,22,15,15,13,46,14,0
0,0,0,0,0,0,0,0,0,0,0,0,0,46,0,0,15,22,0,0,0,0,0,22,15,0,0,46,0,0
0,0,0,0,0,0,0,0,0,0,0,0,14,46,0,19,15,22,0,0,0,0,0,22,15,19,0,46,14,0
0,0,0,0,0,0,0,0,0,0,0,0,0,46,0,0,15,22,40,0,0,0,40,22,15,0,0,46,0,0
0,0,0,0,0,0,0,0,0,0,0,0,14,46,13,15,15,0,0,0,0,0,0,0,15,15,13,46,14,0
0,0,0,0,0,0,0,0,0,0,0,0,0,46,0,0,15,0,40,0,0,0,0,0,15,0,0,46,0,0
0,0,0,0,0,0,0,0,0,0,0,0,14,46,0,19,15,0,14,0,0,0,14,0,15,19,0,46,14,0
0,0,0,0,0,0,0,0,0,0,0,0,0,46,0,0,15,27,13,0,0,0,13,27,15,0,0,46,0,0
0,0,0,0,0,0,0,0,0,0,0,0,14,46,13,15,15,15,15,0,0,0,15,15,15,15,13,46,14,0
0,0,0,0,0,0,0,0,0,0,0,0,0,45,33,0,0,14,15,0,0,0,15,14,0,0,34,43,0,0
0,0,0,0,0,0,0,0,0,0,0,0,0,0,0,0,0,0,15,0,0,0,15,0,0,0,0,0,0,0
0,0,0,0,0,0,0,0,0,0,0,0,0,0,0,0,0,14,15,0,0,0,15,14,0,0,0,0,0,0
0,0,0,0,0,0,0,0,0,0,0,0,0,0,0,0,0,0,15,0,0,0,15,0,0,0,0,0,0,0
0,0,0,0,0,0,0,0,0,0,0,0,0,0,0,0,0,14,15,0,0,0,15,14,0,0,0,0,0,0
0,0,0,0,0,0,0,0,0,0,0,0,0,0,0,0,0,0,15,23,15,24,15,0,0,0,0,0,0,0
0,0,0,0,0,0,0,0,0,0,0,0,0,0,0,0,0,14,15,15,0,15,15,14,0,0,0,0,0,0
0,0,0,0,0,0,0,0,0,0,0,0,0,0,0,0,0,0,0,15,15,15,0,0,0,0,0,0,0,0
0,0,0,0,0,0,0,0,0,0,0,0,0,0,0,0,0,0,0,0,0,0,0,0,0,0,0,0,0,0
0,0,0,0,0,0,0,0,0,0,0,0,0,0,0,0,0,0,0,0,0,0,0,0,0,0,0,0,0,0
endlayer

layer
0,0,0,0,0,0,0,0,0,0,0,0,0,0,0,0,0,0,0,0,0,0,0,0,0,0,0,0,0,0
0,0,0,0,0,0,0,0,0,0,0,0,0,0,0,42,37,0,0,0,0,0,0,0,37,42,0,0,0,0
0,0,0,0,0,0,0,0,0,0,0,0,0,0,45,33,13,42,42,13,15,13,42,42,13,34,43,0,0,0
0,0,0,0,0,0,0,0,0,0,0,0,0,14,46,15,0,15,15,15,15,15,15,15,0,15,46,14,0,0
0,0,0,0,0,0,0,0,0,0,0,0,0,0,46,0,15,14,14,22,22,22,14,14,15,0,46,0,0,0
0,0,0,0,0,0,0,0,0,0,0,0,0,14,46,0,15,0,0,0,0,0,0,0,15,0,46,14,0,0
0,0,0,0,0,0,0,0,0,0,0,0,0,0,46,0,15,14,14,0,0,0,14,14,15,0,46,0,0,0
0,0,0,0,0,0,0,0,0,0,0,0,0,14,46,15,15,0,0,0,0,0,0,0,15,15,46,14,0,0
0,0,0,0,0,0,0,0,0,0,0,0,0,0,46,0,15,14,14,0,0,0,14,14,15,0,46,0,0,0
0,0,0,0,0,0,0,0,0,0,0,0,0,14,46,0,15,0,0,0,0,0,0,0,15,0,46,14,0,0
0,0,0,0,0,0,0,0,0,0,0,0,0,0,46,0,15,14,14,0,0,0,14,14,15,0,46,0,0,0
0,0,0,0,0,0,0,0,0,0,0,0,0,14,46,15,15,0,0,0,0,0,0,0,15,15,46,14,0,0
0,0,0,0,0,0,0,0,0,0,0,0,0,0,46,0,15,14,14,0,0,0,14,14,15,0,46,0,0,0
0,0,0,0,0,0,0,0,0,0,0,0,0,14,46,0,15,0,0,0,0,0,0,0,15,0,46,14,0,0
0,0,0,0,0,0,0,0,0,0,0,0,0,0,46,0,15,14,14,0,0,0,14,14,15,0,46,0,0,0
0,0,0,0,0,0,0,0,0,0,0,0,0,14,46,15,15,0,0,0,0,0,0,0,15,15,46,14,0,0
0,0,0,0,0,0,0,0,0,0,0,0,0,0,46,0,15,14,14,0,0,0,14,14,15,0,46,0,0,0
0,0,0,0,0,0,0,0,0,0,0,0,0,14,46,0,15,11,11,11,11,11,11,11,15,0,46,14,0,0
0,0,0,0,0,0,0,0,0,0,0,0,0,0,46,0,15,27,13,37,37,37,13,27,15,0,46,0,0,0
0,0,0,0,0,0,0,0,0,0,0,0,0,14,46,15,15,15,15,37,37,37,15,15,15,15,46,14,0,0
0,0,0,0,0,0,0,0,0,0,0,0,0,0,45,33,0,14,15,37,37,37,15,14,0,34,43,0,0,0
0,0,0,0,0,0,0,0,0,0,0,0,0,0,0,0,0,0,15,37,37,37,15,0,0,0,0,0,0,0
0,0,0,0,0,0,0,0,0,0,0,0,0,0,0,0,0,14,15,37,37,37,15,14,0,0,0,0,0,0
0,0,0,0,0,0,0,0,0,0,0,0,0,0,0,0,0,0,15,37,37,37,15,0,0,0,0,0,0,0
0,0,0,0,0,0,0,0,0,0,0,0,0,0,0,0,0,14,15,37,37,37,15,14,0,0,0,0,0,0
0,0,0,0,0,0,0,0,0,0,0,0,0,0,0,0,0,0,15,47,15,47,15,0,0,0,0,0,0,0
0,0,0,0,0,0,0,0,0,0,0,0,0,0,0,0,0,14,15,15,0,15,15,14,0,0,0,0,0,0
0,0,0,0,0,0,0,0,0,0,0,0,0,0,0,0,0,0,0,15,15,15,0,0,0,0,0,0,0,0
0,0,0,0,0,0,0,0,0,0,0,0,0,0,0,0,0,0,0,0,0,0,0,0,0,0,0,0,0,0
0,0,0,0,0,0,0,0,0,0,0,0,0,0,0,0,0,0,0,0,0,0,0,0,0,0,0,0,0,0
endlayer

layer
0,0,0,0,0,0,0,0,0,0,0,0,0,0,0,0,0,0,0,0,0,0,0,0,0,0,0,0,0,0
0,0,0,0,0,0,0,0,0,0,0,0,0,0,0,0,0,42,42,37,37,37,42,42,0,0,0,0,0,0
0,0,0,0,0,0,0,0,0,0,0,0,0,0,0,45,13,0,0,13,15,13,0,0,13,43,0,0,0,0
0,0,0,0,0,0,0,0,0,0,0,0,0,0,14,46,0,15,15,15,15,15,15,15,0,46,14,0,0,0
0,0,0,0,0,0,0,0,0,0,0,0,0,0,0,46,15,14,42,37,0,37,42,14,15,46,0,0,0,0
0,0,0,0,0,0,0,0,0,0,0,0,0,0,14,46,15,0,0,0,0,0,0,0,15,46,14,0,0,0
0,0,0,0,0,0,0,0,0,0,0,0,0,0,0,46,15,14,42,37,0,37,42,14,15,46,0,0,0,0
0,0,0,0,0,0,0,0,0,0,0,0,0,0,14,46,15,0,0,0,0,0,0,0,15,46,14,0,0,0
0,0,0,0,0,0,0,0,0,0,0,0,0,0,0,46,15,14,42,37,0,37,42,14,15,46,0,0,0,0
0,0,0,0,0,0,0,0,0,0,0,0,0,0,14,46,15,0,0,0,0,0,0,0,15,46,14,0,0,0
0,0,0,0,0,0,0,0,0,0,0,0,0,0,0,46,15,14,42,37,0,37,42,14,15,46,0,0,0,0
0,0,0,0,0,0,0,0,0,0,0,0,0,0,14,46,15,0,0,0,0,0,0,0,15,46,14,0,0,0
0,0,0,0,0,0,0,0,0,0,0,0,0,0,0,46,15,14,42,37,0,37,42,14,15,46,0,0,0,0
0,0,0,0,0,0,0,0,0,0,0,0,0,0,14,46,15,0,0,0,0,0,0,0,15,46,14,0,0,0
0,0,0,0,0,0,0,0,0,0,0,0,0,0,0,46,15,14,42,37,0,37,42,14,15,46,0,0,0,0
0,0,0,0,0,0,0,0,0,0,0,0,0,0,14,46,15,0,0,0,0,0,0,0,15,46,14,0,0,0
0,0,0,0,0,0,0,0,0,0,0,0,0,0,0,46,15,14,42,37,0,37,42,14,15,46,0,0,0,0
0,0,0,0,0,0,0,0,0,0,0,0,0,0,14,46,15,14,14,14,14,14,14,14,15,46,14,0,0,0
0,0,0,0,0,0,0,0,0,0,0,0,0,0,0,46,15,0,0,0,0,0,0,0,15,46,0,0,0,0
0,0,0,0,0,0,0,0,0,0,0,0,0,0,14,46,15,15,15,0,0,0,15,15,15,46,14,0,0,0
0,0,0,0,0,0,0,0,0,0,0,0,0,0,0,45,33,14,15,0,0,0,15,14,34,43,0,0,0,0
0,0,0,0,0,0,0,0,0,0,0,0,0,0,0,0,0,0,16,0,0,0,18,0,0,0,0,0,0,0
0,0,0,0,0,0,0,0,0,0,0,0,0,0,0,0,0,14,15,0,0,0,15,14,0,0,0,0,0,0
0,0,0,0,0,0,0,0,0,0,0,0,0,0,0,0,0,0,16,0,0,0,18,0,0,0,0,0,0,0
0,0,0,0,0,0,0,0,0,0,0,0,0,0,0,0,0,14,15,0,0,0,15,14,0,0,0,0,0,0
0,0,0,0,0,0,0,0,0,0,0,0,0,0,0,0,0,0,16,0,15,0,18,0,0,0,0,0,0,0
0,0,0,0,0,0,0,0,0,0,0,0,0,0,0,0,0,14,15,15,0,15,15,14,0,0,0,0,0,0
0,0,0,0,0,0,0,0,0,0,0,0,0,0,0,0,0,0,0,15,15,15,0,0,0,0,0,0,0,0
0,0,0,0,0,0,0,0,0,0,0,0,0,0,0,0,0,0,0,0,0,0,0,0,0,0,0,0,0,0
0,0,0,0,0,0,0,0,0,0,0,0,0,0,0,0,0,0,0,0,0,0,0,0,0,0,0,0,0,0
endlayer

layer
0,0,0,0,0,0,0,0,0,0,0,0,0,0,0,0,0,0,0,0,0,0,0,0,0,0,0,0,0,0
0,0,0,0,0,0,0,0,0,0,0,0,0,0,0,0,0,0,0,0,0,0,0,0,0,0,0,0,0,0
0,0,0,0,0,0,0,0,0,0,0,0,0,0,0,0,45,33,0,13,20,13,0,34,43,0,0,0,0,0
0,0,0,0,0,0,0,0,0,0,0,0,0,0,0,14,46,15,15,15,48,15,15,15,46,14,0,0,0,0
0,0,0,0,0,0,0,0,0,0,0,0,0,0,0,0,46,14,0,14,42,14,0,14,46,0,0,0,0,0
0,0,0,0,0,0,0,0,0,0,0,0,0,0,0,14,46,0,0,0,0,0,0,0,46,14,0,0,0,0
0,0,0,0,0,0,0,0,0,0,0,0,0,0,0,0,46,14,0,14,42,14,0,14,46,0,0,0,0,0
0,0,0,0,0,0,0,0,0,0,0,0,0,0,0,14,46,0,0,0,0,0,0,0,46,14,0,0,0,0
0,0,0,0,0,0,0,0,0,0,0,0,0,0,0,0,46,14,0,14,42,14,0,14,46,0,0,0,0,0
0,0,0,0,0,0,0,0,0,0,0,0,0,0,0,14,46,0,0,0,0,0,0,0,46,14,0,0,0,0
0,0,0,0,0,0,0,0,0,0,0,0,0,0,0,0,46,14,0,14,42,14,0,14,46,0,0,0,0,0
0,0,0,0,0,0,0,0,0,0,0,0,0,0,0,14,46,0,0,0,0,0,0,0,46,14,0,0,0,0
0,0,0,0,0,0,0,0,0,0,0,0,0,0,0,0,46,14,0,14,42,14,0,14,46,0,0,0,0,0
0,0,0,0,0,0,0,0,0,0,0,0,0,0,0,14,46,0,0,0,0,0,0,0,46,14,0,0,0,0
0,0,0,0,0,0,0,0,0,0,0,0,0,0,0,0,46,14,0,14,42,14,0,14,46,0,0,0,0,0
0,0,0,0,0,0,0,0,0,0,0,0,0,0,0,14,46,0,0,0,0,0,0,0,46,14,0,0,0,0
0,0,0,0,0,0,0,0,0,0,0,0,0,0,0,0,46,14,0,14,42,14,0,14,46,0,0,0,0,0
0,0,0,0,0,0,0,0,0,0,0,0,0,0,0,14,46,0,14,0,14,0,14,0,46,14,0,0,0,0
0,0,0,0,0,0,0,0,0,0,0,0,0,0,0,0,46,0,0,0,0,0,0,0,46,0,0,0,0,0
0,0,0,0,0,0,0,0,0,0,0,0,0,0,0,14,46,15,15,0,0,0,15,15,46,14,0,0,0,0
0,0,0,0,0,0,0,0,0,0,0,0,0,0,0,0,45,13,15,0,0,0,15,13,43,0,0,0,0,0
0,0,0,0,0,0,0,0,0,0,0,0,0,0,0,0,0,0,0,0,0,0,0,0,0,0,0,0,0,0
0,0,0,0,0,0,0,0,0,0,0,0,0,0,0,0,0,11,15,0,0,0,15,11,0,0,0,0,0,0
0,0,0,0,0,0,0,0,0,0,0,0,0,0,0,0,0,0,0,0,0,0,0,0,0,0,0,0,0,0
0,0,0,0,0,0,0,0,0,0,0,0,0,0,0,0,0,11,15,0,49,0,15,11,0,0,0,0,0,0
0,0,0,0,0,0,0,0,0,0,0,0,0,0,0,0,0,0,0,0,15,0,0,0,0,0,0,0,0,0
0,0,0,0,0,0,0,0,0,0,0,0,0,0,0,0,0,11,15,15,0,15,15,11,0,0,0,0,0,0
0,0,0,0,0,0,0,0,0,0,0,0,0,0,0,0,0,0,0,15,15,15,0,0,0,0,0,0,0,0
0,0,0,0,0,0,0,0,0,0,0,0,0,0,0,0,0,0,0,0,0,0,0,0,0,0,0,0,0,0
0,0,0,0,0,0,0,0,0,0,0,0,0,0,0,0,0,0,0,0,0,0,0,0,0,0,0,0,0,0
endlayer

layer
0,0,0,0,0,0,0,0,0,0,0,0,0,0,0,0,0,0,0,0,0,0,0,0,0,0,0,0,0,0
0,0,0,0,0,0,0,0,0,0,0,0,0,0,0,0,0,0,0,0,0,0,0,0,0,0,0,0,0,0
0,0,0,0,0,0,0,0,0,0,0,0,0,0,0,0,0,45,33,13,14,13,34,43,0,0,0,0,0,0
0,0,0,0,0,0,0,0,0,0,0,0,0,0,0,0,14,46,15,15,0,15,15,46,14,0,0,0,0,0
0,0,0,0,0,0,0,0,0,0,0,0,0,0,0,0,0,46,0,14,0,14,0,46,0,0,0,0,0,0
0,0,0,0,0,0,0,0,0,0,0,0,0,0,0,0,14,46,0,0,0,0,0,46,14,0,0,0,0,0
0,0,0,0,0,0,0,0,0,0,0,0,0,0,0,0,0,46,0,14,0,14,0,46,0,0,0,0,0,0
0,0,0,0,0,0,0,0,0,0,0,0,0,0,0,0,14,46,0,0,0,0,0,46,14,0,0,0,0,0
0,0,0,0,0,0,0,0,0,0,0,0,0,0,0,0,0,46,0,14,0,14,0,46,0,0,0,0,0,0
0,0,0,0,0,0,0,0,0,0,0,0,0,0,0,0,14,46,0,0,0,0,0,46,14,0,0,0,0,0
0,0,0,0,0,0,0,0,0,0,0,0,0,0,0,0,0,46,0,14,0,14,0,46,0,0,0,0,0,0
0,0,0,0,0,0,0,0,0,0,0,0,0,0,0,0,14,46,0,0,0,0,0,46,14,0,0,0,0,0
0,0,0,0,0,0,0,0,0,0,0,0,0,0,0,0,0,46,0,14,0,14,0,46,0,0,0,0,0,0
0,0,0,0,0,0,0,0,0,0,0,0,0,0,0,0,14,46,0,0,0,0,0,46,14,0,0,0,0,0
0,0,0,0,0,0,0,0,0,0,0,0,0,0,0,0,0,46,0,14,0,14,0,46,0,0,0,0,0,0
0,0,0,0,0,0,0,0,0,0,0,0,0,0,0,0,14,46,0,0,0,0,0,46,14,0,0,0,0,0
0,0,0,0,0,0,0,0,0,0,0,0,0,0,0,0,0,46,0,14,0,14,0,46,0,0,0,0,0,0
0,0,0,0,0,0,0,0,0,0,0,0,0,0,0,0,14,46,14,0,14,0,14,46,14,0,0,0,0,0
0,0,0,0,0,0,0,0,0,0,0,0,0,0,0,0,0,46,0,0,0,0,0,46,0,0,0,0,0,0
0,0,0,0,0,0,0,0,0,0,0,0,0,0,0,0,14,46,15,0,0,0,15,46,14,0,0,0,0,0
0,0,0,0,0,0,0,0,0,0,0,0,0,0,0,0,22,46,15,0,0,0,15,46,22,0,0,0,0,0
0,0,0,0,0,0,0,0,0,0,0,0,0,0,0,0,22,46,23,0,0,0,24,46,22,0,0,0,0,0
0,0,0,0,0,0,0,0,0,0,0,0,0,0,0,0,22,46,15,0,0,0,15,46,22,0,0,0,0,0
0,0,0,0,0,0,0,0,0,0,0,0,0,0,0,0,22,46,23,0,0,0,24,46,22,0,0,0,0,0
0,0,0,0,0,0,0,0,0,0,0,0,0,0,0,0,22,46,15,0,0,0,15,46,22,0,0,0,0,0
0,0,0,0,0,0,0,0,0,0,0,0,0,0,0,0,22,46,23,0,15,0,24,46,22,0,0,0,0,0
0,0,0,0,0,0,0,0,0,0,0,0,0,0,0,0,22,46,15,15,0,15,15,46,22,0,0,0,0,0
0,0,0,0,0,0,0,0,0,0,0,0,0,0,0,0,22,45,33,15,15,15,34,43,22,0,0,0,0,0
0,0,0,0,0,0,0,0,0,0,0,0,0,0,0,0,0,0,0,0,0,0,0,0,0,0,0,0,0,0
0,0,0,0,0,0,0,0,0,0,0,0,0,0,0,0,0,0,0,0,0,0,0,0,0,0,0,0,0,0
endlayer

layer
0,0,0,0,0,0,0,0,0,0,0,0,0,0,0,0,0,0,0,0,0,0,0,0,0,0,0,0,0,0
0,0,0,0,0,0,0,0,0,0,0,0,0,0,0,0,0,0,0,0,0,0,0,0,0,0,0,0,0,0
0,0,0,0,0,0,0,0,0,0,0,0,0,0,0,0,0,0,45,13,14,13,43,0,0,0,0,0,0,0
0,0,0,0,0,0,0,0,0,0,0,0,0,0,0,0,0,14,46,15,0,15,46,14,0,0,0,0,0,0
0,0,0,0,0,0,0,0,0,0,0,0,0,0,0,0,0,0,46,14,0,14,46,0,0,0,0,0,0,0
0,0,0,0,0,0,0,0,0,0,0,0,0,0,0,0,0,14,46,0,0,0,46,14,0,0,0,0,0,0
0,0,0,0,0,0,0,0,0,0,0,0,0,0,0,0,0,0,46,14,0,14,46,0,0,0,0,0,0,0
0,0,0,0,0,0,0,0,0,0,0,0,0,0,0,0,0,14,46,0,0,0,46,14,0,0,0,0,0,0
0,0,0,0,0,0,0,0,0,0,0,0,0,0,0,0,0,0,46,14,0,14,46,0,0,0,0,0,0,0
0,0,0,0,0,0,0,0,0,0,0,0,0,0,0,0,0,14,46,0,0,0,46,14,0,0,0,0,0,0
0,0,0,0,0,0,0,0,0,0,0,0,0,0,0,0,0,0,46,14,0,14,46,0,0,0,0,0,0,0
0,0,0,0,0,0,0,0,0,0,0,0,0,0,0,0,0,14,46,0,0,0,46,14,0,0,0,0,0,0
0,0,0,0,0,0,0,0,0,0,0,0,0,0,0,0,0,0,46,14,0,14,46,0,0,0,0,0,0,0
0,0,0,0,0,0,0,0,0,0,0,0,0,0,0,0,0,14,46,0,0,0,46,14,0,0,0,0,0,0
0,0,0,0,0,0,0,0,0,0,0,0,0,0,0,0,0,0,46,14,0,14,46,0,0,0,0,0,0,0
0,0,0,0,0,0,0,0,0,0,0,0,0,0,0,0,0,14,46,0,0,0,46,14,0,0,0,0,0,0
0,0,0,0,0,0,0,0,0,0,0,0,0,0,0,0,0,0,46,14,0,14,46,0,0,0,0,0,0,0
0,0,0,0,0,0,0,0,0,0,0,0,0,0,0,0,0,14,46,0,14,0,46,14,0,0,0,0,0,0
0,0,0,0,0,0,0,0,0,0,0,0,0,0,0,0,0,0,46,0,0,0,46,0,0,0,0,0,0,0
0,0,0,0,0,0,0,0,0,0,0,0,0,0,0,0,0,14,46,0,0,0,46,14,0,0,0,0,0,0
0,0,0,0,0,0,0,0,0,0,0,0,0,0,0,0,0,0,46,0,0,0,46,0,0,0,0,0,0,0
0,0,0,0,0,0,0,0,0,0,0,0,0,0,0,0,0,14,46,0,0,0,46,14,0,0,0,0,0,0
0,0,0,0,0,0,0,0,0,0,0,0,0,0,0,0,0,0,46,0,0,0,46,0,0,0,0,0,0,0
0,0,0,0,0,0,0,0,0,0,0,0,0,0,0,0,0,14,46,0,0,0,46,14,0,0,0,0,0,0
0,0,0,0,0,0,0,0,0,0,0,0,0,0,0,0,0,0,46,0,0,0,46,0,0,0,0,0,0,0
0,0,0,0,0,0,0,0,0,0,0,0,0,0,0,0,0,14,46,0,15,0,46,14,0,0,0,0,0,0
0,0,0,0,0,0,0,0,0,0,0,0,0,0,0,0,0,0,46,15,0,15,46,0,0,0,0,0,0,0
0,0,0,0,0,0,0,0,0,0,0,0,0,0,0,0,0,0,45,15,15,15,43,0,0,0,0,0,0,0
0,0,0,0,0,0,0,0,0,0,0,0,0,0,0,0,0,0,0,0,0,0,0,0,0,0,0,0,0,0
0,0,0,0,0,0,0,0,0,0,0,0,0,0,0,0,0,0,0,0,0,0,0,0,0,0,0,0,0,0
endlayer

layer
0,0,0,0,0,0,0,0,0,0,0,0,0,0,0,0,0,0,0,0,0,0,0,0,0,0,0,0,0,0
0,0,0,0,0,0,0,0,0,0,0,0,0,0,0,0,0,0,0,0,0,0,0,0,0,0,0,0,0,0
0,0,0,0,0,0,0,0,0,0,0,0,0,0,0,0,0,0,0,45,44,43,0,0,0,0,0,0,0,0
0,0,0,0,0,0,0,0,0,0,0,0,0,0,0,0,0,0,14,46,0,46,14,0,0,0,0,0,0,0
0,0,0,0,0,0,0,0,0,0,0,0,0,0,0,0,0,0,0,46,0,46,0,0,0,0,0,0,0,0
0,0,0,0,0,0,0,0,0,0,0,0,0,0,0,0,0,0,14,46,0,46,14,0,0,0,0,0,0,0
0,0,0,0,0,0,0,0,0,0,0,0,0,0,0,0,0,0,0,46,0,46,0,0,0,0,0,0,0,0
0,0,0,0,0,0,0,0,0,0,0,0,0,0,0,0,0,0,14,46,0,46,14,0,0,0,0,0,0,0
0,0,0,0,0,0,0,0,0,0,0,0,0,0,0,0,0,0,0,46,0,46,0,0,0,0,0,0,0,0
0,0,0,0,0,0,0,0,0,0,0,0,0,0,0,0,0,0,14,46,0,46,14,0,0,0,0,0,0,0
0,0,0,0,0,0,0,0,0,0,0,0,0,0,0,0,0,0,0,46,0,46,0,0,0,0,0,0,0,0
0,0,0,0,0,0,0,0,0,0,0,0,0,0,0,0,0,0,14,46,0,46,14,0,0,0,0,0,0,0
0,0,0,0,0,0,0,0,0,0,0,0,0,0,0,0,0,0,0,46,0,46,0,0,0,0,0,0,0,0
0,0,0,0,0,0,0,0,0,0,0,0,0,0,0,0,0,0,14,46,0,46,14,0,0,0,0,0,0,0
0,0,0,0,0,0,0,0,0,0,0,0,0,0,0,0,0,0,0,46,0,46,0,0,0,0,0,0,0,0
0,0,0,0,0,0,0,0,0,0,0,0,0,0,0,0,0,0,14,46,0,46,14,0,0,0,0,0,0,0
0,0,0,0,0,0,0,0,0,0,0,0,0,0,0,0,0,0,0,46,0,46,0,0,0,0,0,0,0,0
0,0,0,0,0,0,0,0,0,0,0,0,0,0,0,0,0,0,14,46,14,46,14,0,0,0,0,0,0,0
0,0,0,0,0,0,0,0,0,0,0,0,0,0,0,0,0,0,0,46,0,46,0,0,0,0,0,0,0,0
0,0,0,0,0,0,0,0,0,0,0,0,0,0,0,0,0,0,14,46,0,46,14,0,0,0,0,0,0,0
0,0,0,0,0,0,0,0,0,0,0,0,0,0,0,0,0,0,0,46,0,46,0,0,0,0,0,0,0,0
0,0,0,0,0,0,0,0,0,0,0,0,0,0,0,0,0,0,14,46,0,46,14,0,0,0,0,0,0,0
0,0,0,0,0,0,0,0,0,0,0,0,0,0,0,0,0,0,0,46,0,46,0,0,0,0,0,0,0,0
0,0,0,0,0,0,0,0,0,0,0,0,0,0,0,0,0,0,14,46,0,46,14,0,0,0,0,0,0,0
0,0,0,0,0,0,0,0,0,0,0,0,0,0,0,0,0,0,0,46,0,46,0,0,0,0,0,0,0,0
0,0,0,0,0,0,0,0,0,0,0,0,0,0,0,0,0,0,14,46,15,46,14,0,0,0,0,0,0,0
0,0,0,0,0,0,0,0,0,0,0,0,0,0,0,0,0,0,0,15,0,15,0,0,0,0,0,0,0,0
0,0,0,0,0,0,0,0,0,0,0,0,0,0,0,0,0,0,0,15,15,15,0,0,0,0,0,0,0,0
0,0,0,0,0,0,0,0,0,0,0,0,0,0,0,0,0,0,0,0,0,0,0,0,0,0,0,0,0,0
0,0,0,0,0,0,0,0,0,0,0,0,0,0,0,0,0,0,0,0,0,0,0,0,0,0,0,0,0,0
endlayer

layer
0,0,0,0,0,0,0,0,0,0,0,0,0,0,0,0,0,0,0,0,0,0,0,0,0,0,0,0,0,0
0,0,0,0,0,0,0,0,0,0,0,0,0,0,0,0,0,0,0,0,0,0,0,0,0,0,0,0,0,0
0,0,0,0,0,0,0,0,0,0,0,0,0,0,0,0,0,0,0,34,50,33,0,0,0,0,0,0,0,0
0,0,0,0,0,0,0,0,0,0,0,0,0,0,0,0,0,0,0,14,46,14,0,0,0,0,0,0,0,0
0,0,0,0,0,0,0,0,0,0,0,0,0,0,0,0,0,0,0,0,46,0,0,0,0,0,0,0,0,0
0,0,0,0,0,0,0,0,0,0,0,0,0,0,0,0,0,0,0,14,46,14,0,0,0,0,0,0,0,0
0,0,0,0,0,0,0,0,0,0,0,0,0,0,0,0,0,0,0,0,46,0,0,0,0,0,0,0,0,0
0,0,0,0,0,0,0,0,0,0,0,0,0,0,0,0,0,0,0,14,46,14,0,0,0,0,0,0,0,0
0,0,0,0,0,0,0,0,0,0,0,0,0,0,0,0,0,0,0,0,46,0,0,0,0,0,0,0,0,0
0,0,0,0,0,0,0,0,0,0,0,0,0,0,0,0,0,0,0,14,46,14,0,0,0,0,0,0,0,0
0,0,0,0,0,0,0,0,0,0,0,0,0,0,0,0,0,0,0,0,46,0,0,0,0,0,0,0,0,0
0,0,0,0,0,0,0,0,0,0,0,0,0,0,0,0,0,0,0,14,46,14,0,0,0,0,0,0,0,0
0,0,0,0,0,0,0,0,0,0,0,0,0,0,0,0,0,0,0,0,46,0,0,0,0,0,0,0,0,0
0,0,0,0,0,0,0,0,0,0,0,0,0,0,0,0,0,0,0,14,46,14,0,0,0,0,0,0,0,0
0,0,0,0,0,0,0,0,0,0,0,0,0,0,0,0,0,0,0,0,46,0,0,0,0,0,0,0,0,0
0,0,0,0,0,0,0,0,0,0,0,0,0,0,0,0,0,0,0,14,46,14,0,0,0,0,0,0,0,0
0,0,0,0,0,0,0,0,0,0,0,0,0,0,0,0,0,0,0,0,46,0,0,0,0,0,0,0,0,0
0,0,0,0,0,0,0,0,0,0,0,0,0,0,0,0,0,0,0,14,46,14,0,0,0,0,0,0,0,0
0,0,0,0,0,0,0,0,0,0,0,0,0,0,0,0,0,0,0,0,46,0,0,0,0,0,0,0,0,0
0,0,0,0,0,0,0,0,0,0,0,0,0,0,0,0,0,0,0,14,46,14,0,0,0,0,0,0,0,0
0,0,0,0,0,0,0,0,0,0,0,0,0,0,0,0,0,0,0,0,46,0,0,0,0,0,0,0,0,0
0,0,0,0,0,0,0,0,0,0,0,0,0,0,0,0,0,0,0,14,46,14,0,0,0,0,0,0,0,0
0,0,0,0,0,0,0,0,0,0,0,0,0,0,0,0,0,0,0,0,46,0,0,0,0,0,0,0,0,0
0,0,0,0,0,0,0,0,0,0,0,0,0,0,0,0,0,0,0,14,46,14,0,0,0,0,0,0,0,0
0,0,0,0,0,0,0,0,0,0,0,0,0,0,0,0,0,0,0,0,46,0,0,0,0,0,0,0,0,0
0,0,0,0,0,0,0,0,0,0,0,0,0,0,0,0,0,0,0,15,15,15,0,0,0,0,0,0,0,0
0,0,0,0,0,0,0,0,0,0,0,0,0,0,0,0,0,0,0,15,0,15,0,0,0,0,0,0,0,0
0,0,0,0,0,0,0,0,0,0,0,0,0,0,0,0,0,0,0,15,15,15,0,0,0,0,0,0,0,0
0,0,0,0,0,0,0,0,0,0,0,0,0,0,0,0,0,0,0,0,0,0,0,0,0,0,0,0,0,0
0,0,0,0,0,0,0,0,0,0,0,0,0,0,0,0,0,0,0,0,0,0,0,0,0,0,0,0,0,0
endlayer

layer
0,0,0,0,0,0,0,0,0,0,0,0,0,0,0,0,0,0,0,0,0,0,0,0,0,0,0,0,0,0
0,0,0,0,0,0,0,0,0,0,0,0,0,0,0,0,0,0,0,0,0,0,0,0,0,0,0,0,0,0
0,0,0,0,0,0,0,0,0,0,0,0,0,0,0,0,0,0,0,43,0,45,0,0,0,0,0,0,0,0
0,0,0,0,0,0,0,0,0,0,0,0,0,0,0,0,0,0,0,0,22,0,0,0,0,0,0,0,0,0
0,0,0,0,0,0,0,0,0,0,0,0,0,0,0,0,0,0,0,0,22,0,0,0,0,0,0,0,0,0
0,0,0,0,0,0,0,0,0,0,0,0,0,0,0,0,0,0,0,0,22,0,0,0,0,0,0,0,0,0
0,0,0,0,0,0,0,0,0,0,0,0,0,0,0,0,0,0,0,0,22,0,0,0,0,0,0,0,0,0
0,0,0,0,0,0,0,0,0,0,0,0,0,0,0,0,0,0,0,0,22,0,0,0,0,0,0,0,0,0
0,0,0,0,0,0,0,0,0,0,0,0,0,0,0,0,0,0,0,0,22,0,0,0,0,0,0,0,0,0
0,0,0,0,0,0,0,0,0,0,0,0,0,0,0,0,0,0,0,0,22,0,0,0,0,0,0,0,0,0
0,0,0,0,0,0,0,0,0,0,0,0,0,0,0,0,0,0,0,0,22,0,0,0,0,0,0,0,0,0
0,0,0,0,0,0,0,0,0,0,0,0,0,0,0,0,0,0,0,0,22,0,0,0,0,0,0,0,0,0
0,0,0,0,0,0,0,0,0,0,0,0,0,0,0,0,0,0,0,0,22,0,0,0,0,0,0,0,0,0
0,0,0,0,0,0,0,0,0,0,0,0,0,0,0,0,0,0,0,0,22,0,0,0,0,0,0,0,0,0
0,0,0,0,0,0,0,0,0,0,0,0,0,0,0,0,0,0,0,0,22,0,0,0,0,0,0,0,0,0
0,0,0,0,0,0,0,0,0,0,0,0,0,0,0,0,0,0,0,0,22,0,0,0,0,0,0,0,0,0
0,0,0,0,0,0,0,0,0,0,0,0,0,0,0,0,0,0,0,0,22,0,0,0,0,0,0,0,0,0
0,0,0,0,0,0,0,0,0,0,0,0,0,0,0,0,0,0,0,0,22,0,0,0,0,0,0,0,0,0
0,0,0,0,0,0,0,0,0,0,0,0,0,0,0,0,0,0,0,0,22,0,0,0,0,0,0,0,0,0
0,0,0,0,0,0,0,0,0,0,0,0,0,0,0,0,0,0,0,0,22,0,0,0,0,0,0,0,0,0
0,0,0,0,0,0,0,0,0,0,0,0,0,0,0,0,0,0,0,0,22,0,0,0,0,0,0,0,0,0
0,0,0,0,0,0,0,0,0,0,0,0,0,0,0,0,0,0,0,0,22,0,0,0,0,0,0,0,0,0
0,0,0,0,0,0,0,0,0,0,0,0,0,0,0,0,0,0,0,0,22,0,0,0,0,0,0,0,0,0
0,0,0,0,0,0,0,0,0,0,0,0,0,0,0,0,0,0,0,0,22,0,0,0,0,0,0,0,0,0
0,0,0,0,0,0,0,0,0,0,0,0,0,0,0,0,0,0,0,0,22,0,0,0,0,0,0,0,0,0
0,0,0,0,0,0,0,0,0,0,0,0,0,0,0,0,0,0,0,15,15,15,0,0,0,0,0,0,0,0
0,0,0,0,0,0,0,0,0,0,0,0,0,0,0,0,0,0,0,15,0,15,0,0,0,0,0,0,0,0
0,0,0,0,0,0,0,0,0,0,0,0,0,0,0,0,0,0,0,15,15,15,0,0,0,0,0,0,0,0
0,0,0,0,0,0,0,0,0,0,0,0,0,0,0,0,0,0,0,0,0,0,0,0,0,0,0,0,0,0
0,0,0,0,0,0,0,0,0,0,0,0,0,0,0,0,0,0,0,0,0,0,0,0,0,0,0,0,0,0
endlayer

layer
0,0,0,0,0,0,0,0,0,0,0,0,0,0,0,0,0,0,0,0,0,0,0,0,0,0,0,0,0,0
0,0,0,0,0,0,0,0,0,0,0,0,0,0,0,0,0,0,0,0,0,0,0,0,0,0,0,0,0,0
0,0,0,0,0,0,0,0,0,0,0,0,0,0,0,0,0,0,0,0,0,0,0,0,0,0,0,0,0,0
0,0,0,0,0,0,0,0,0,0,0,0,0,0,0,0,0,0,0,0,0,0,0,0,0,0,0,0,0,0
0,0,0,0,0,0,0,0,0,0,0,0,0,0,0,0,0,0,0,0,0,0,0,0,0,0,0,0,0,0
0,0,0,0,0,0,0,0,0,0,0,0,0,0,0,0,0,0,0,0,0,0,0,0,0,0,0,0,0,0
0,0,0,0,0,0,0,0,0,0,0,0,0,0,0,0,0,0,0,0,0,0,0,0,0,0,0,0,0,0
0,0,0,0,0,0,0,0,0,0,0,0,0,0,0,0,0,0,0,0,0,0,0,0,0,0,0,0,0,0
0,0,0,0,0,0,0,0,0,0,0,0,0,0,0,0,0,0,0,0,0,0,0,0,0,0,0,0,0,0
0,0,0,0,0,0,0,0,0,0,0,0,0,0,0,0,0,0,0,0,0,0,0,0,0,0,0,0,0,0
0,0,0,0,0,0,0,0,0,0,0,0,0,0,0,0,0,0,0,0,0,0,0,0,0,0,0,0,0,0
0,0,0,0,0,0,0,0,0,0,0,0,0,0,0,0,0,0,0,0,0,0,0,0,0,0,0,0,0,0
0,0,0,0,0,0,0,0,0,0,0,0,0,0,0,0,0,0,0,0,0,0,0,0,0,0,0,0,0,0
0,0,0,0,0,0,0,0,0,0,0,0,0,0,0,0,0,0,0,0,0,0,0,0,0,0,0,0,0,0
0,0,0,0,0,0,0,0,0,0,0,0,0,0,0,0,0,0,0,0,0,0,0,0,0,0,0,0,0,0
0,0,0,0,0,0,0,0,0,0,0,0,0,0,0,0,0,0,0,0,0,0,0,0,0,0,0,0,0,0
0,0,0,0,0,0,0,0,0,0,0,0,0,0,0,0,0,0,0,0,0,0,0,0,0,0,0,0,0,0
0,0,0,0,0,0,0,0,0,0,0,0,0,0,0,0,0,0,0,0,0,0,0,0,0,0,0,0,0,0
0,0,0,0,0,0,0,0,0,0,0,0,0,0,0,0,0,0,0,0,0,0,0,0,0,0,0,0,0,0
0,0,0,0,0,0,0,0,0,0,0,0,0,0,0,0,0,0,0,0,0,0,0,0,0,0,0,0,0,0
0,0,0,0,0,0,0,0,0,0,0,0,0,0,0,0,0,0,0,0,0,0,0,0,0,0,0,0,0,0
0,0,0,0,0,0,0,0,0,0,0,0,0,0,0,0,0,0,0,0,0,0,0,0,0,0,0,0,0,0
0,0,0,0,0,0,0,0,0,0,0,0,0,0,0,0,0,0,0,0,0,0,0,0,0,0,0,0,0,0
0,0,0,0,0,0,0,0,0,0,0,0,0,0,0,0,0,0,0,0,0,0,0,0,0,0,0,0,0,0
0,0,0,0,0,0,0,0,0,0,0,0,0,0,0,0,0,0,0,0,0,0,0,0,0,0,0,0,0,0
0,0,0,0,0,0,0,0,0,0,0,0,0,0,0,0,0,0,0,11,14,11,0,0,0,0,0,0,0,0
0,0,0,0,0,0,0,0,0,0,0,0,0,0,0,0,0,0,0,14,0,14,0,0,0,0,0,0,0,0
0,0,0,0,0,0,0,0,0,0,0,0,0,0,0,0,0,0,0,11,14,11,0,0,0,0,0,0,0,0
0,0,0,0,0,0,0,0,0,0,0,0,0,0,0,0,0,0,0,0,0,0,0,0,0,0,0,0,0,0
0,0,0,0,0,0,0,0,0,0,0,0,0,0,0,0,0,0,0,0,0,0,0,0,0,0,0,0,0,0
endlayer

layer
0,0,0,0,0,0,0,0,0,0,0,0,0,0,0,0,0,0,0,0,0,0,0,0,0,0,0,0,0,0
0,0,0,0,0,0,0,0,0,0,0,0,0,0,0,0,0,0,0,0,0,0,0,0,0,0,0,0,0,0
0,0,0,0,0,0,0,0,0,0,0,0,0,0,0,0,0,0,0,0,0,0,0,0,0,0,0,0,0,0
0,0,0,0,0,0,0,0,0,0,0,0,0,0,0,0,0,0,0,0,0,0,0,0,0,0,0,0,0,0
0,0,0,0,0,0,0,0,0,0,0,0,0,0,0,0,0,0,0,0,0,0,0,0,0,0,0,0,0,0
0,0,0,0,0,0,0,0,0,0,0,0,0,0,0,0,0,0,0,0,0,0,0,0,0,0,0,0,0,0
0,0,0,0,0,0,0,0,0,0,0,0,0,0,0,0,0,0,0,0,0,0,0,0,0,0,0,0,0,0
0,0,0,0,0,0,0,0,0,0,0,0,0,0,0,0,0,0,0,0,0,0,0,0,0,0,0,0,0,0
0,0,0,0,0,0,0,0,0,0,0,0,0,0,0,0,0,0,0,0,0,0,0,0,0,0,0,0,0,0
0,0,0,0,0,0,0,0,0,0,0,0,0,0,0,0,0,0,0,0,0,0,0,0,0,0,0,0,0,0
0,0,0,0,0,0,0,0,0,0,0,0,0,0,0,0,0,0,0,0,0,0,0,0,0,0,0,0,0,0
0,0,0,0,0,0,0,0,0,0,0,0,0,0,0,0,0,0,0,0,0,0,0,0,0,0,0,0,0,0
0,0,0,0,0,0,0,0,0,0,0,0,0,0,0,0,0,0,0,0,0,0,0,0,0,0,0,0,0,0
0,0,0,0,0,0,0,0,0,0,0,0,0,0,0,0,0,0,0,0,0,0,0,0,0,0,0,0,0,0
0,0,0,0,0,0,0,0,0,0,0,0,0,0,0,0,0,0,0,0,0,0,0,0,0,0,0,0,0,0
0,0,0,0,0,0,0,0,0,0,0,0,0,0,0,0,0,0,0,0,0,0,0,0,0,0,0,0,0,0
0,0,0,0,0,0,0,0,0,0,0,0,0,0,0,0,0,0,0,0,0,0,0,0,0,0,0,0,0,0
0,0,0,0,0,0,0,0,0,0,0,0,0,0,0,0,0,0,0,0,0,0,0,0,0,0,0,0,0,0
0,0,0,0,0,0,0,0,0,0,0,0,0,0,0,0,0,0,0,0,0,0,0,0,0,0,0,0,0,0
0,0,0,0,0,0,0,0,0,0,0,0,0,0,0,0,0,0,0,0,0,0,0,0,0,0,0,0,0,0
0,0,0,0,0,0,0,0,0,0,0,0,0,0,0,0,0,0,0,0,0,0,0,0,0,0,0,0,0,0
0,0,0,0,0,0,0,0,0,0,0,0,0,0,0,0,0,0,0,0,0,0,0,0,0,0,0,0,0,0
0,0,0,0,0,0,0,0,0,0,0,0,0,0,0,0,0,0,0,0,0,0,0,0,0,0,0,0,0,0
0,0,0,0,0,0,0,0,0,0,0,0,0,0,0,0,0,0,0,0,0,0,0,0,0,0,0,0,0,0
0,0,0,0,0,0,0,0,0,0,0,0,0,0,0,0,0,0,0,0,0,0,0,0,0,0,0,0,0,0
0,0,0,0,0,0,0,0,0,0,0,0,0,0,0,0,0,0,0,20,20,20,0,0,0,0,0,0,0,0
0,0,0,0,0,0,0,0,0,0,0,0,0,0,0,0,0,0,0,45,51,43,0,0,0,0,0,0,0,0
0,0,0,0,0,0,0,0,0,0,0,0,0,0,0,0,0,0,0,45,48,43,0,0,0,0,0,0,0,0
0,0,0,0,0,0,0,0,0,0,0,0,0,0,0,0,0,0,0,0,0,0,0,0,0,0,0,0,0,0
0,0,0,0,0,0,0,0,0,0,0,0,0,0,0,0,0,0,0,0,0,0,0,0,0,0,0,0,0,0
endlayer

layer
0,0,0,0,0,0,0,0,0,0,0,0,0,0,0,0,0,0,0,0,0,0,0,0,0,0,0,0,0,0
0,0,0,0,0,0,0,0,0,0,0,0,0,0,0,0,0,0,0,0,0,0,0,0,0,0,0,0,0,0
0,0,0,0,0,0,0,0,0,0,0,0,0,0,0,0,0,0,0,0,0,0,0,0,0,0,0,0,0,0
0,0,0,0,0,0,0,0,0,0,0,0,0,0,0,0,0,0,0,0,0,0,0,0,0,0,0,0,0,0
0,0,0,0,0,0,0,0,0,0,0,0,0,0,0,0,0,0,0,0,0,0,0,0,0,0,0,0,0,0
0,0,0,0,0,0,0,0,0,0,0,0,0,0,0,0,0,0,0,0,0,0,0,0,0,0,0,0,0,0
0,0,0,0,0,0,0,0,0,0,0,0,0,0,0,0,0,0,0,0,0,0,0,0,0,0,0,0,0,0
0,0,0,0,0,0,0,0,0,0,0,0,0,0,0,0,0,0,0,0,0,0,0,0,0,0,0,0,0,0
0,0,0,0,0,0,0,0,0,0,0,0,0,0,0,0,0,0,0,0,0,0,0,0,0,0,0,0,0,0
0,0,0,0,0,0,0,0,0,0,0,0,0,0,0,0,0,0,0,0,0,0,0,0,0,0,0,0,0,0
0,0,0,0,0,0,0,0,0,0,0,0,0,0,0,0,0,0,0,0,0,0,0,0,0,0,0,0,0,0
0,0,0,0,0,0,0,0,0,0,0,0,0,0,0,0,0,0,0,0,0,0,0,0,0,0,0,0,0,0
0,0,0,0,0,0,0,0,0,0,0,0,0,0,0,0,0,0,0,0,0,0,0,0,0,0,0,0,0,0
0,0,0,0,0,0,0,0,0,0,0,0,0,0,0,0,0,0,0,0,0,0,0,0,0,0,0,0,0,0
0,0,0,0,0,0,0,0,0,0,0,0,0,0,0,0,0,0,0,0,0,0,0,0,0,0,0,0,0,0
0,0,0,0,0,0,0,0,0,0,0,0,0,0,0,0,0,0,0,0,0,0,0,0,0,0,0,0,0,0
0,0,0,0,0,0,0,0,0,0,0,0,0,0,0,0,0,0,0,0,0,0,0,0,0,0,0,0,0,0
0,0,0,0,0,0,0,0,0,0,0,0,0,0,0,0,0,0,0,0,0,0,0,0,0,0,0,0,0,0
0,0,0,0,0,0,0,0,0,0,0,0,0,0,0,0,0,0,0,0,0,0,0,0,0,0,0,0,0,0
0,0,0,0,0,0,0,0,0,0,0,0,0,0,0,0,0,0,0,0,0,0,0,0,0,0,0,0,0,0
0,0,0,0,0,0,0,0,0,0,0,0,0,0,0,0,0,0,0,0,0,0,0,0,0,0,0,0,0,0
0,0,0,0,0,0,0,0,0,0,0,0,0,0,0,0,0,0,0,0,0,0,0,0,0,0,0,0,0,0
0,0,0,0,0,0,0,0,0,0,0,0,0,0,0,0,0,0,0,0,0,0,0,0,0,0,0,0,0,0
0,0,0,0,0,0,0,0,0,0,0,0,0,0,0,0,0,0,0,0,0,0,0,0,0,0,0,0,0,0
0,0,0,0,0,0,0,0,0,0,0,0,0,0,0,0,0,0,0,0,0,0,0,0,0,0,0,0,0,0
0,0,0,0,0,0,0,0,0,0,0,0,0,0,0,0,0,0,0,0,0,0,0,0,0,0,0,0,0,0
0,0,0,0,0,0,0,0,0,0,0,0,0,0,0,0,0,0,0,0,13,0,0,0,0,0,0,0,0,0
0,0,0,0,0,0,0,0,0,0,0,0,0,0,0,0,0,0,0,0,0,0,0,0,0,0,0,0,0,0
0,0,0,0,0,0,0,0,0,0,0,0,0,0,0,0,0,0,0,0,0,0,0,0,0,0,0,0,0,0
0,0,0,0,0,0,0,0,0,0,0,0,0,0,0,0,0,0,0,0,0,0,0,0,0,0,0,0,0,0
endlayer

layer
0,0,0,0,0,0,0,0,0,0,0,0,0,0,0,0,0,0,0,0,0,0,0,0,0,0,0,0,0,0
0,0,0,0,0,0,0,0,0,0,0,0,0,0,0,0,0,0,0,0,0,0,0,0,0,0,0,0,0,0
0,0,0,0,0,0,0,0,0,0,0,0,0,0,0,0,0,0,0,0,0,0,0,0,0,0,0,0,0,0
0,0,0,0,0,0,0,0,0,0,0,0,0,0,0,0,0,0,0,0,0,0,0,0,0,0,0,0,0,0
0,0,0,0,0,0,0,0,0,0,0,0,0,0,0,0,0,0,0,0,0,0,0,0,0,0,0,0,0,0
0,0,0,0,0,0,0,0,0,0,0,0,0,0,0,0,0,0,0,0,0,0,0,0,0,0,0,0,0,0
0,0,0,0,0,0,0,0,0,0,0,0,0,0,0,0,0,0,0,0,0,0,0,0,0,0,0,0,0,0
0,0,0,0,0,0,0,0,0,0,0,0,0,0,0,0,0,0,0,0,0,0,0,0,0,0,0,0,0,0
0,0,0,0,0,0,0,0,0,0,0,0,0,0,0,0,0,0,0,0,0,0,0,0,0,0,0,0,0,0
0,0,0,0,0,0,0,0,0,0,0,0,0,0,0,0,0,0,0,0,0,0,0,0,0,0,0,0,0,0
0,0,0,0,0,0,0,0,0,0,0,0,0,0,0,0,0,0,0,0,0,0,0,0,0,0,0,0,0,0
0,0,0,0,0,0,0,0,0,0,0,0,0,0,0,0,0,0,0,0,0,0,0,0,0,0,0,0,0,0
0,0,0,0,0,0,0,0,0,0,0,0,0,0,0,0,0,0,0,0,0,0,0,0,0,0,0,0,0,0
0,0,0,0,0,0,0,0,0,0,0,0,0,0,0,0,0,0,0,0,0,0,0,0,0,0,0,0,0,0
0,0,0,0,0,0,0,0,0,0,0,0,0,0,0,0,0,0,0,0,0,0,0,0,0,0,0,0,0,0
0,0,0,0,0,0,0,0,0,0,0,0,0,0,0,0,0,0,0,0,0,0,0,0,0,0,0,0,0,0
0,0,0,0,0,0,0,0,0,0,0,0,0,0,0,0,0,0,0,0,0,0,0,0,0,0,0,0,0,0
0,0,0,0,0,0,0,0,0,0,0,0,0,0,0,0,0,0,0,0,0,0,0,0,0,0,0,0,0,0
0,0,0,0,0,0,0,0,0,0,0,0,0,0,0,0,0,0,0,0,0,0,0,0,0,0,0,0,0,0
0,0,0,0,0,0,0,0,0,0,0,0,0,0,0,0,0,0,0,0,0,0,0,0,0,0,0,0,0,0
0,0,0,0,0,0,0,0,0,0,0,0,0,0,0,0,0,0,0,0,0,0,0,0,0,0,0,0,0,0
0,0,0,0,0,0,0,0,0,0,0,0,0,0,0,0,0,0,0,0,0,0,0,0,0,0,0,0,0,0
0,0,0,0,0,0,0,0,0,0,0,0,0,0,0,0,0,0,0,0,0,0,0,0,0,0,0,0,0,0
0,0,0,0,0,0,0,0,0,0,0,0,0,0,0,0,0,0,0,0,0,0,0,0,0,0,0,0,0,0
0,0,0,0,0,0,0,0,0,0,0,0,0,0,0,0,0,0,0,0,0,0,0,0,0,0,0,0,0,0
0,0,0,0,0,0,0,0,0,0,0,0,0,0,0,0,0,0,0,0,0,0,0,0,0,0,0,0,0,0
0,0,0,0,0,0,0,0,0,0,0,0,0,0,0,0,0,0,0,0,11,0,0,0,0,0,0,0,0,0
0,0,0,0,0,0,0,0,0,0,0,0,0,0,0,0,0,0,0,0,0,0,0,0,0,0,0,0,0,0
0,0,0,0,0,0,0,0,0,0,0,0,0,0,0,0,0,0,0,0,0,0,0,0,0,0,0,0,0,0
0,0,0,0,0,0,0,0,0,0,0,0,0,0,0,0,0,0,0,0,0,0,0,0,0,0,0,0,0,0
endlayer

layer
0,0,0,0,0,0,0,0,0,0,0,0,0,0,0,0,0,0,0,0,0,0,0,0,0,0,0,0,0,0
0,0,0,0,0,0,0,0,0,0,0,0,0,0,0,0,0,0,0,0,0,0,0,0,0,0,0,0,0,0
0,0,0,0,0,0,0,0,0,0,0,0,0,0,0,0,0,0,0,0,0,0,0,0,0,0,0,0,0,0
0,0,0,0,0,0,0,0,0,0,0,0,0,0,0,0,0,0,0,0,0,0,0,0,0,0,0,0,0,0
0,0,0,0,0,0,0,0,0,0,0,0,0,0,0,0,0,0,0,0,0,0,0,0,0,0,0,0,0,0
0,0,0,0,0,0,0,0,0,0,0,0,0,0,0,0,0,0,0,0,0,0,0,0,0,0,0,0,0,0
0,0,0,0,0,0,0,0,0,0,0,0,0,0,0,0,0,0,0,0,0,0,0,0,0,0,0,0,0,0
0,0,0,0,0,0,0,0,0,0,0,0,0,0,0,0,0,0,0,0,0,0,0,0,0,0,0,0,0,0
0,0,0,0,0,0,0,0,0,0,0,0,0,0,0,0,0,0,0,0,0,0,0,0,0,0,0,0,0,0
0,0,0,0,0,0,0,0,0,0,0,0,0,0,0,0,0,0,0,0,0,0,0,0,0,0,0,0,0,0
0,0,0,0,0,0,0,0,0,0,0,0,0,0,0,0,0,0,0,0,0,0,0,0,0,0,0,0,0,0
0,0,0,0,0,0,0,0,0,0,0,0,0,0,0,0,0,0,0,0,0,0,0,0,0,0,0,0,0,0
0,0,0,0,0,0,0,0,0,0,0,0,0,0,0,0,0,0,0,0,0,0,0,0,0,0,0,0,0,0
0,0,0,0,0,0,0,0,0,0,0,0,0,0,0,0,0,0,0,0,0,0,0,0,0,0,0,0,0,0
0,0,0,0,0,0,0,0,0,0,0,0,0,0,0,0,0,0,0,0,0,0,0,0,0,0,0,0,0,0
0,0,0,0,0,0,0,0,0,0,0,0,0,0,0,0,0,0,0,0,0,0,0,0,0,0,0,0,0,0
0,0,0,0,0,0,0,0,0,0,0,0,0,0,0,0,0,0,0,0,0,0,0,0,0,0,0,0,0,0
0,0,0,0,0,0,0,0,0,0,0,0,0,0,0,0,0,0,0,0,0,0,0,0,0,0,0,0,0,0
0,0,0,0,0,0,0,0,0,0,0,0,0,0,0,0,0,0,0,0,0,0,0,0,0,0,0,0,0,0
0,0,0,0,0,0,0,0,0,0,0,0,0,0,0,0,0,0,0,0,0,0,0,0,0,0,0,0,0,0
0,0,0,0,0,0,0,0,0,0,0,0,0,0,0,0,0,0,0,0,0,0,0,0,0,0,0,0,0,0
0,0,0,0,0,0,0,0,0,0,0,0,0,0,0,0,0,0,0,0,0,0,0,0,0,0,0,0,0,0
0,0,0,0,0,0,0,0,0,0,0,0,0,0,0,0,0,0,0,0,0,0,0,0,0,0,0,0,0,0
0,0,0,0,0,0,0,0,0,0,0,0,0,0,0,0,0,0,0,0,0,0,0,0,0,0,0,0,0,0
0,0,0,0,0,0,0,0,0,0,0,0,0,0,0,0,0,0,0,0,0,0,0,0,0,0,0,0,0,0
0,0,0,0,0,0,0,0,0,0,0,0,0,0,0,0,0,0,0,0,0,0,0,0,0,0,0,0,0,0
0,0,0,0,0,0,0,0,0,0,0,0,0,0,0,0,0,0,0,0,14,0,0,0,0,0,0,0,0,0
0,0,0,0,0,0,0,0,0,0,0,0,0,0,0,0,0,0,0,0,0,0,0,0,0,0,0,0,0,0
0,0,0,0,0,0,0,0,0,0,0,0,0,0,0,0,0,0,0,0,0,0,0,0,0,0,0,0,0,0
0,0,0,0,0,0,0,0,0,0,0,0,0,0,0,0,0,0,0,0,0,0,0,0,0,0,0,0,0,0
endlayer

