
# Created by Ruins mod version 14.4 Ingame Parser
# authoring Player: Mikhaila666

weight=1
embed_into_distance=0
acceptable_target_blocks=
unacceptable_target_blocks=flowing_water,water,flowing_lava,lava
dimensions=21,21,21
allowable_overhang=0
max_leveling=2
leveling_buffer=0
preserve_water=0
preserve_lava=0

rule1=0,100,Railcraft:tile.railcraft.residual.heat-0
rule2=0,100,minecraft:grass-0
rule3=0,100,minecraft:stonebrick-0
rule4=0,100,minecraft:dirt-0
rule5=0,100,minecraft:ladder-4
rule6=0,100,minecraft:ladder-5
rule7=0,100,minecraft:stonebrick-2
rule8=0,100,IInventory;minecraft:chest;minecraft:record_13#1#0#4+minecraft:name_tag#1#0#7+harvestcraft:heartybreakfastItem#1#0#10+minecraft:redstone#1#0#14+minecraft:record_13#1#0#17-3
rule9=0,100,MobSpawner:Spider
rule10=0,100,minecraft:stonebrick-1
rule11=0,100,minecraft:ladder-3
rule12=2,100,minecraft:torch-3
rule13=2,100,minecraft:torch-4
rule14=0,100,IInventory;minecraft:chest;minecraft:redstone#3#0#10+minecraft:iron_horse_armor#1#0#23+TConstruct:heartCanister#1#1#25+harvestcraft:deluxecheeseburgerItem#1#0#26-2
rule15=2,100,minecraft:torch-2
rule16=0,100,MobSpawner:Zombie
rule17=0,100,minecraft:stonebrick-3
rule18=0,100,minecraft:leaves-0
rule19=0,100,IInventory;minecraft:chest;TConstruct:heartCanister#1#1#1+minecraft:rotten_flesh#6#0#16-5
rule20=0,100,minecraft:log-0
rule21=0,100,minecraft:leaves-4
rule22=0,100,minecraft:leaves-12
rule23=0,100,IInventory;minecraft:chest;minecraft:enchanted_book#1#0#9+minecraft:saddle#1#0#10+minecraft:bone#4#0#18-4
rule24=0,100,minecraft:wooden_door-2
rule25=0,100,minecraft:glass_pane-0
rule26=0,100,minecraft:wooden_door-8
rule27=0,100,minecraft:stone_slab-13
rule28=0,100,minecraft:stone_brick_stairs-4
rule29=0,100,minecraft:stone_brick_stairs-6
rule30=0,100,minecraft:stone_brick_stairs-7
rule31=0,100,minecraft:log-8
rule32=0,100,minecraft:log-4
rule33=0,100,minecraft:stone_brick_stairs-5
rule34=0,100,minecraft:stone_slab-5
rule35=0,100,minecraft:stone_brick_stairs-2
rule36=0,100,minecraft:stone_brick_stairs-3
rule37=0,100,minecraft:stone_brick_stairs-0
rule38=0,100,minecraft:stone_brick_stairs-1

layer
0,0,0,0,0,0,0,0,0,0,0,0,0,0,1,0,0,0,0,0,0
0,0,0,0,0,0,0,0,0,0,0,0,0,0,0,0,0,0,0,0,0
0,0,0,0,0,0,0,0,0,0,0,0,0,0,0,0,0,0,0,0,0
0,0,0,0,0,0,2,2,2,2,2,2,2,2,0,0,0,0,0,0,0
0,0,0,0,0,2,2,3,3,3,3,3,3,2,2,0,0,0,0,0,0
0,0,0,0,2,2,3,3,0,0,0,0,3,3,2,2,0,0,0,0,1
0,0,0,2,2,3,3,3,3,3,3,4,0,3,3,2,2,0,0,0,0
0,0,0,2,3,3,3,3,3,3,3,3,3,0,3,3,2,0,0,0,0
0,1,1,2,3,4,4,4,4,4,3,3,3,0,0,3,2,0,0,0,0
0,0,0,2,3,3,4,4,4,4,3,3,3,0,0,3,2,0,0,0,0
0,0,0,2,3,3,3,4,4,3,3,3,3,3,0,3,2,0,4,0,0
0,0,0,2,3,3,4,4,3,3,3,3,3,3,0,3,2,0,0,0,0
0,1,0,2,3,3,3,4,3,3,3,3,3,3,3,3,2,0,0,0,0
0,1,0,2,2,3,3,3,4,4,4,4,3,3,3,2,2,0,0,0,0
0,0,0,0,2,2,3,3,0,0,0,0,3,3,2,2,1,1,0,0,0
0,0,0,0,1,2,2,3,3,3,3,3,3,2,2,0,0,0,0,0,0
0,0,1,1,0,0,3,4,4,4,4,4,2,2,0,0,0,1,0,0,0
0,0,0,0,0,0,1,0,0,0,0,0,0,0,0,0,0,1,0,0,0
0,0,0,0,0,0,0,0,0,0,0,0,0,0,0,0,0,0,0,0,0
0,0,0,0,0,0,0,0,0,0,0,0,0,0,0,0,0,0,0,0,0
0,0,0,0,0,0,0,0,0,0,0,0,0,0,0,0,0,0,0,0,0
endlayer

layer
0,0,0,0,0,1,0,0,1,1,0,0,0,0,0,0,0,0,0,0,0
0,0,0,0,0,1,1,0,0,0,0,0,0,0,0,0,0,0,0,0,0
0,0,0,0,0,0,0,1,0,0,0,1,1,0,1,1,0,0,0,0,0
0,1,0,0,0,1,1,0,0,0,0,0,0,1,0,1,1,0,0,0,0
0,1,0,1,1,0,1,3,3,3,3,3,3,0,1,0,0,1,0,0,0
0,1,0,0,0,0,3,3,0,0,0,0,3,3,1,0,0,0,1,0,0
0,1,0,0,0,3,3,3,3,3,3,3,0,3,3,1,0,0,1,0,0
0,0,0,0,3,3,0,5,0,0,0,0,3,0,3,3,0,0,0,0,0
1,0,0,0,3,3,3,3,3,3,0,0,3,0,0,3,0,0,0,0,0
0,0,0,0,3,1,3,4,4,3,0,0,3,0,1,3,0,0,0,1,0
1,0,1,0,3,1,3,3,7,6,0,0,0,3,0,3,0,1,1,1,0
0,0,0,0,3,0,3,3,9,0,0,0,8,3,0,3,0,1,0,0,0
0,0,0,0,3,0,0,3,10,0,0,0,0,3,3,3,0,0,1,0,0
0,1,0,0,0,3,0,11,3,3,3,3,3,3,3,0,0,0,0,0,0
0,0,0,0,0,0,3,3,0,0,0,0,3,3,0,0,1,1,0,0,0
0,0,0,1,0,0,0,3,3,3,3,3,3,0,0,0,0,1,0,0,0
0,1,0,0,1,0,0,3,3,3,3,3,0,0,0,0,1,1,0,1,0
1,0,0,0,0,0,1,1,0,1,1,0,1,0,1,1,0,0,1,0,0
1,0,0,0,0,0,1,1,1,0,1,0,0,1,0,0,0,0,0,0,0
0,0,0,0,0,0,0,0,0,1,0,0,0,1,0,0,0,0,0,0,0
0,0,0,0,0,0,0,0,0,1,0,0,0,0,0,0,0,0,0,0,1
endlayer

layer
0,0,0,0,0,0,0,0,0,0,0,0,0,0,1,1,0,0,0,0,0
0,0,0,0,0,0,0,0,0,0,0,0,0,0,0,0,0,0,0,0,0
0,0,0,0,0,0,0,0,0,0,0,0,0,0,0,0,0,1,0,0,0
0,0,0,0,0,0,0,0,0,0,0,0,0,0,0,0,0,0,0,0,0
0,0,0,1,0,0,0,3,3,3,3,3,3,0,0,0,0,1,0,0,0
0,0,0,0,0,0,3,3,0,0,0,0,3,3,0,0,0,1,1,0,0
0,0,0,0,0,3,3,3,3,3,3,3,0,3,3,1,0,0,0,0,0
0,0,0,0,3,3,13,5,0,0,0,12,3,0,3,3,0,1,0,0,1
0,0,1,0,3,3,3,3,3,3,0,0,3,0,0,3,0,0,0,0,0
0,0,0,0,3,0,3,2,3,3,0,0,3,0,0,3,0,0,0,0,0
0,0,0,1,3,12,3,3,0,6,0,0,0,3,0,3,0,0,0,0,1
0,1,0,0,3,0,3,3,14,0,0,0,0,3,0,3,0,0,0,0,1
0,0,0,0,3,0,0,3,0,0,15,0,0,3,3,3,0,0,0,0,0
0,0,0,0,0,3,0,11,3,3,3,3,3,3,3,0,0,0,0,0,0
0,0,0,0,0,0,3,3,0,0,0,0,3,3,0,0,0,0,0,0,0
0,0,0,0,1,0,0,3,3,3,3,3,3,0,0,0,0,0,0,0,0
0,0,0,1,0,0,0,0,3,3,3,3,0,0,0,0,0,1,0,0,0
0,1,0,0,0,0,0,0,0,0,0,0,0,0,0,0,0,0,0,0,0
0,0,0,0,0,0,0,0,0,0,0,0,0,0,0,0,0,0,0,0,0
0,0,0,0,0,0,0,0,0,0,1,0,0,0,0,0,0,0,0,0,0
0,0,0,0,0,0,0,0,1,0,0,0,0,0,0,0,0,0,0,0,0
endlayer

layer
0,0,0,0,0,0,0,0,0,0,0,0,0,0,0,0,0,0,0,0,0
0,0,0,0,0,0,0,0,0,0,0,0,0,0,0,0,0,0,0,0,0
0,0,0,1,0,0,0,1,0,1,1,0,0,0,0,0,0,0,0,0,0
0,0,1,1,0,1,0,1,1,0,0,0,0,0,0,0,0,0,0,0,0
0,0,0,1,0,0,0,3,3,3,3,3,3,0,0,0,0,0,0,0,0
0,0,1,0,0,0,3,3,0,0,7,10,3,3,0,0,0,0,0,0,0
0,0,0,0,0,3,3,3,4,4,4,0,0,3,3,0,0,0,0,0,0
0,0,1,0,3,3,0,5,3,7,3,3,0,0,3,3,0,0,0,0,0
0,0,0,1,3,3,10,3,4,4,3,3,4,0,0,3,0,0,0,0,0
0,0,1,1,3,0,7,0,4,3,3,3,3,0,0,3,0,0,0,0,1
1,0,0,0,3,0,7,7,3,6,0,0,0,3,0,3,0,0,0,0,0
1,0,0,0,3,0,10,10,3,0,0,0,0,3,0,3,0,0,0,0,0
0,0,1,0,3,0,17,17,3,0,0,0,0,16,3,3,0,0,0,0,0
0,0,0,0,0,3,16,11,3,3,3,3,3,3,3,0,0,0,0,0,0
0,0,0,0,0,0,3,3,0,0,0,0,3,3,0,0,0,0,0,0,0
0,0,0,0,0,0,0,3,3,3,3,3,3,0,0,0,0,0,0,0,0
0,0,1,0,0,0,0,0,0,3,3,3,0,0,0,0,0,0,0,0,0
0,0,0,0,0,0,0,0,0,0,0,0,0,0,0,0,0,0,0,0,0
0,0,0,0,0,0,0,0,0,1,0,0,0,0,0,0,0,0,0,0,0
0,0,0,0,0,0,0,0,0,1,0,0,0,0,0,0,0,0,0,0,0
0,0,0,0,0,0,0,0,0,0,0,0,0,0,0,0,0,0,0,0,0
endlayer

layer
0,0,0,0,0,0,0,0,0,0,0,0,0,0,0,0,0,0,0,0,0
0,0,0,0,0,0,0,0,0,0,0,0,0,0,0,0,0,0,0,0,0
0,2,0,0,0,0,0,0,0,0,0,0,0,0,0,0,0,0,0,0,0
0,0,0,0,0,0,0,0,0,0,0,0,0,0,0,0,0,0,0,0,0
0,0,0,0,0,0,0,3,3,3,3,3,3,0,0,0,0,0,0,0,0
0,0,0,0,0,0,3,3,10,7,7,10,3,3,0,0,0,0,0,0,0
0,0,0,0,0,3,3,17,10,7,7,10,4,3,3,0,0,0,0,0,0
0,0,0,0,3,3,17,10,10,7,7,10,17,17,3,3,0,0,0,0,0
0,0,1,0,3,10,10,10,7,2,2,7,10,10,10,3,2,0,2,0,0
0,0,0,0,3,7,7,7,2,4,2,2,7,7,7,3,0,0,0,0,0
0,1,0,0,3,7,7,7,2,2,2,2,7,7,7,3,0,0,0,0,0
0,0,0,0,3,10,10,10,7,3,3,7,10,10,10,3,0,0,0,0,0
0,0,1,0,3,3,17,17,10,7,7,10,17,3,3,3,0,0,0,0,0
0,0,0,0,0,3,3,7,10,7,7,10,17,3,3,0,0,0,1,0,0
0,0,0,0,0,0,3,3,10,7,7,10,3,3,2,0,0,0,0,0,0
0,0,0,0,0,0,0,3,3,3,3,3,3,0,0,0,0,0,0,0,0
0,0,0,0,0,0,0,0,0,0,3,3,0,0,0,0,0,0,0,0,0
0,0,0,0,0,0,0,1,0,1,0,0,0,1,0,0,0,0,0,0,0
0,0,0,0,0,0,0,0,0,0,0,1,0,0,0,0,0,0,0,0,0
0,0,0,0,0,0,0,0,0,1,1,0,0,0,0,0,0,0,0,0,0
0,0,0,0,0,0,0,0,0,0,0,0,0,0,0,0,0,0,0,0,0
endlayer

layer
0,0,0,0,0,0,0,0,0,0,0,0,0,0,0,0,0,0,0,0,0
0,0,0,0,0,0,0,0,1,0,0,0,0,0,0,0,0,0,0,0,0
0,0,0,0,0,0,0,1,1,0,0,0,0,0,0,0,0,0,0,0,0
0,0,0,0,0,0,1,0,0,1,0,0,0,0,0,0,0,0,0,0,0
0,0,0,0,0,0,0,3,3,3,3,3,3,0,0,0,0,0,0,0,0
0,0,0,1,0,0,3,0,0,0,18,18,18,3,0,0,0,0,0,0,0
0,0,0,0,0,3,0,0,1,1,18,18,20,19,3,0,0,0,0,0,0
0,0,0,0,3,0,0,18,18,18,18,18,18,18,18,3,0,0,0,0,0
0,0,0,0,3,0,0,21,22,18,22,21,18,18,0,3,0,0,0,0,0
0,0,0,0,3,1,21,21,22,20,18,21,21,0,0,3,0,0,0,0,0
0,0,0,0,3,0,21,21,21,18,18,22,21,1,0,3,0,0,0,0,0
0,0,1,0,3,1,0,21,21,23,18,22,21,1,0,3,0,0,1,0,0
0,0,0,0,3,0,1,21,21,22,22,22,21,0,0,3,0,0,0,0,0
0,0,0,0,0,3,0,0,21,21,21,21,1,1,3,0,0,0,0,0,0
0,0,1,0,0,0,3,0,1,0,0,0,0,3,0,0,0,0,0,0,0
0,0,1,0,0,0,0,3,3,3,24,3,3,0,0,0,0,0,0,0,0
0,0,0,0,0,0,0,0,0,0,0,0,0,0,0,0,0,0,0,0,0
0,0,0,0,0,0,0,0,0,0,0,0,0,0,0,0,0,0,0,0,0
0,0,0,0,0,0,0,0,0,1,1,0,0,0,0,0,0,0,0,0,0
0,0,0,0,0,0,0,0,0,1,1,0,0,0,0,0,0,0,0,0,0
0,0,0,0,0,0,0,0,0,0,0,0,0,0,0,0,0,0,0,0,0
endlayer

layer
0,0,0,0,0,0,0,0,0,0,0,0,0,0,0,0,0,0,0,0,0
0,0,0,0,0,0,0,0,0,0,0,1,0,1,0,0,0,0,0,0,0
0,0,0,0,0,0,0,0,0,1,0,1,0,0,1,0,0,0,0,0,0
0,0,0,0,0,0,0,0,0,0,0,0,0,0,0,0,0,0,0,0,0
0,0,0,0,0,0,0,3,3,25,25,3,3,0,0,0,0,0,0,0,0
0,0,0,0,0,0,3,0,0,0,0,18,18,3,0,0,0,0,0,0,0
0,0,0,0,0,3,0,0,0,0,0,18,18,18,3,0,0,0,0,0,0
0,1,0,0,3,0,0,0,22,0,22,21,18,18,0,3,0,0,0,0,0
0,0,0,0,3,0,0,21,22,18,22,21,21,0,0,3,0,0,0,0,0
0,1,0,0,25,0,0,21,22,18,18,21,21,0,0,25,0,1,0,0,0
1,0,1,0,25,0,0,21,21,18,0,22,21,0,0,25,0,0,1,0,0
0,0,0,0,3,0,0,21,21,22,0,22,21,0,0,3,0,0,0,0,0
0,0,0,0,3,0,0,21,21,22,22,22,21,0,0,3,0,0,0,0,0
0,0,0,0,0,3,0,0,21,21,21,0,0,0,3,0,0,0,0,0,0
0,0,0,0,0,0,3,0,0,0,0,0,0,3,0,0,0,0,0,0,0
0,0,0,0,0,0,0,3,3,3,26,3,3,0,0,0,0,0,0,0,0
0,0,0,0,0,0,0,0,0,0,0,0,0,0,0,0,0,0,0,0,0
0,0,0,0,0,0,0,0,0,0,0,0,0,0,0,0,0,0,0,0,0
0,0,0,0,0,0,0,0,0,0,0,0,0,0,0,0,0,1,0,0,0
0,0,0,0,0,0,1,0,0,0,0,0,0,0,0,0,0,0,0,0,0
0,0,0,0,0,0,0,0,0,0,0,0,0,0,0,0,0,0,0,0,0
endlayer

layer
0,0,0,0,0,0,0,0,0,0,0,0,0,0,0,0,0,0,0,0,0
0,0,0,0,0,0,0,0,0,0,0,0,0,0,0,0,0,0,0,0,0
0,0,0,0,0,0,0,0,0,0,0,0,0,0,0,0,0,0,0,0,0
0,0,0,0,0,0,0,0,0,0,0,0,0,0,0,0,0,0,0,0,0
0,0,0,0,0,0,0,7,3,25,25,3,7,0,0,0,0,0,0,0,0
0,0,0,0,0,0,3,0,27,27,27,27,0,3,0,0,0,0,0,0,0
0,0,0,0,0,3,27,0,0,0,0,0,0,27,3,0,0,0,0,0,0
0,0,0,0,7,0,0,0,22,22,22,21,21,0,0,7,0,0,0,0,0
0,0,0,0,3,27,0,21,22,22,22,21,21,0,27,3,0,0,0,0,0
0,0,0,0,25,27,0,21,22,18,0,21,21,0,27,25,0,0,0,0,0
0,0,0,0,25,27,0,21,21,0,0,22,21,0,27,25,0,0,0,0,0
0,0,0,0,3,27,0,21,21,22,22,22,21,0,27,3,0,0,0,0,0
0,0,0,0,7,0,0,0,21,22,22,22,21,0,0,7,0,0,0,0,0
0,0,0,0,0,3,27,0,0,0,0,0,0,27,3,0,0,0,0,0,0
0,0,0,0,0,0,3,0,27,27,27,27,0,3,0,0,0,0,0,0,0
0,0,0,0,0,0,0,7,3,3,3,3,7,0,0,0,0,0,0,0,0
0,0,0,0,0,0,0,0,0,0,0,0,0,0,0,0,0,0,0,0,0
0,0,0,0,0,0,0,0,0,0,0,0,0,0,0,0,0,0,0,0,0
0,0,0,0,0,0,0,0,0,0,0,0,0,0,0,0,0,0,0,0,0
0,0,0,0,0,0,0,0,0,0,0,0,0,0,0,0,0,0,0,0,0
1,0,0,0,0,0,0,0,0,0,0,0,0,0,0,0,0,0,0,0,0
endlayer

layer
0,0,0,0,0,0,0,0,0,0,0,0,0,0,0,0,0,0,0,0,0
0,0,0,0,0,0,0,0,0,0,0,0,0,0,0,0,0,0,0,0,0
0,0,0,0,0,0,0,0,0,0,0,0,0,0,0,0,0,0,0,0,0
0,0,0,0,0,0,0,0,0,0,0,0,0,0,0,0,0,0,0,0,0
0,0,0,0,0,0,0,7,7,10,10,7,7,0,0,0,0,0,0,0,0
0,0,0,0,0,0,7,0,0,0,1,0,0,7,0,0,0,0,0,0,0
0,0,0,0,0,7,0,0,0,0,0,0,0,0,7,0,0,0,0,0,0
0,0,0,0,7,0,0,0,21,0,0,0,0,0,0,7,0,0,0,0,0
0,0,0,0,7,0,0,21,21,21,21,21,0,0,1,7,0,0,0,0,0
0,0,0,0,10,0,0,0,21,0,0,21,0,0,1,10,0,0,0,0,0
0,0,0,0,10,0,0,21,21,0,0,21,0,0,0,10,0,0,0,0,0
0,0,0,0,7,0,0,21,21,21,21,21,0,0,0,7,0,0,0,0,0
0,0,0,0,7,0,0,21,21,21,21,21,0,0,0,7,0,0,0,0,0
0,0,0,0,0,7,0,0,21,21,21,0,0,0,7,0,0,0,0,0,0
0,0,0,0,0,0,7,0,0,0,0,0,0,7,0,0,0,0,0,0,0
0,0,0,0,0,0,0,7,7,10,10,7,7,0,0,0,0,0,0,0,0
0,0,0,0,0,0,0,0,0,0,0,0,0,0,0,0,0,0,0,0,0
0,0,0,0,0,0,0,0,0,0,0,0,0,0,0,0,0,0,0,0,0
0,0,0,0,0,0,0,0,0,0,0,0,0,0,0,0,0,0,0,0,0
0,0,0,0,0,0,0,0,0,0,0,0,0,0,0,0,0,0,0,0,0
0,0,0,0,0,0,0,0,0,0,0,0,0,0,0,0,0,0,0,0,0
endlayer

layer
0,0,0,0,0,0,0,0,0,0,0,0,0,0,0,0,0,0,0,0,0
0,0,0,0,0,0,0,0,0,0,0,0,0,0,0,0,0,0,0,0,0
0,0,0,0,0,0,0,0,0,0,0,0,0,0,0,0,0,0,0,0,0
0,0,0,0,0,0,0,0,0,0,0,0,0,0,0,0,0,0,0,0,0
0,0,0,0,0,0,28,7,10,10,10,10,7,28,0,0,0,0,0,0,0
0,0,0,0,0,27,3,0,0,0,0,0,0,3,27,0,0,0,0,0,0
0,0,0,0,30,3,0,21,21,21,0,0,0,0,3,29,0,0,0,0,0
0,0,0,0,7,0,21,21,21,21,21,0,0,0,0,7,0,0,0,0,0
0,0,0,0,10,0,21,21,21,21,21,21,0,0,0,10,0,0,0,0,0
0,0,0,0,10,0,21,31,21,21,32,31,21,0,0,10,0,0,0,0,0
0,0,0,0,10,0,0,21,0,0,21,21,21,0,0,10,0,0,0,0,0
0,0,0,0,10,0,0,21,32,21,21,21,21,0,0,10,0,0,0,0,0
0,0,0,0,7,0,0,0,21,21,21,21,0,0,0,7,0,0,0,0,0
0,0,0,0,30,3,0,0,0,0,0,0,0,0,3,29,0,0,0,0,0
0,0,0,0,0,27,3,0,0,0,0,0,0,3,27,0,0,0,0,0,0
0,0,0,0,0,0,33,7,10,10,10,10,7,33,0,0,0,0,0,0,0
0,0,0,0,0,0,0,0,0,0,0,0,0,0,0,0,0,0,0,0,0
0,0,0,0,0,0,0,0,0,0,0,0,0,0,0,0,0,0,0,0,0
0,0,0,0,0,0,0,0,0,0,0,0,0,0,0,0,0,0,0,0,0
0,0,0,0,0,0,0,0,0,0,0,0,0,0,0,0,0,0,0,0,0
0,0,0,0,0,0,0,0,0,0,0,0,0,0,0,0,0,0,0,0,0
endlayer

layer
0,0,0,0,0,0,0,0,0,0,0,0,0,0,0,0,0,0,0,0,0
0,0,0,0,0,0,0,0,0,0,0,0,0,0,0,0,0,0,0,0,0
0,0,0,0,0,0,0,0,0,0,0,0,0,0,0,0,0,0,0,0,0
0,0,0,0,0,0,0,28,7,10,10,7,28,0,0,0,0,0,0,0,0
0,0,0,0,0,0,3,3,0,0,0,0,3,3,0,0,0,0,0,0,0
0,0,0,0,0,3,0,0,0,0,0,0,0,0,3,0,0,0,0,0,0
0,0,0,0,3,0,0,21,0,21,0,0,0,0,0,3,0,0,0,0,0
0,0,0,30,3,0,21,21,21,21,21,21,21,0,0,3,29,0,0,0,0
0,0,0,7,0,0,21,21,21,21,21,21,31,21,0,0,7,0,0,0,0
0,0,0,10,0,21,31,21,21,21,21,21,21,0,0,0,10,0,0,0,0
0,0,0,10,0,0,21,21,21,0,21,21,21,0,0,1,10,0,0,0,0
0,0,0,7,0,0,21,21,21,21,32,21,21,0,0,0,7,0,0,0,0
0,0,0,30,3,0,21,21,21,21,21,21,0,0,0,3,29,0,0,0,0
0,0,0,0,3,0,0,21,21,21,0,0,0,0,0,3,0,0,0,0,0
0,0,0,0,0,3,0,0,0,0,0,0,0,0,3,0,0,0,0,0,0
0,0,0,0,0,0,3,3,0,0,0,0,3,3,0,0,0,0,0,0,0
0,0,0,0,0,0,0,33,7,10,10,7,33,0,0,0,0,0,0,0,0
0,0,0,0,0,0,0,0,0,0,0,0,0,0,0,0,0,0,0,0,0
0,0,0,0,0,0,0,0,0,0,0,0,0,0,0,0,0,0,0,0,0
0,0,0,0,0,0,0,0,0,0,0,0,0,0,0,0,0,0,0,0,0
0,0,0,0,0,0,0,0,0,0,0,0,0,0,0,0,0,0,0,0,0
endlayer

layer
0,0,0,0,0,0,0,0,0,0,0,0,0,0,0,0,0,0,0,0,0
0,0,0,0,0,0,0,0,0,0,0,0,0,0,0,0,0,0,0,0,0
0,0,0,0,0,0,0,0,28,17,17,28,0,0,0,0,0,0,0,0,0
0,0,0,0,0,0,0,3,3,0,0,3,3,0,0,0,0,0,0,0,0
0,0,0,0,0,34,3,0,0,0,0,0,0,3,34,0,0,0,0,0,0
0,0,0,0,34,0,0,0,0,0,0,0,0,0,0,34,0,0,0,0,0
0,0,0,0,3,0,0,0,0,0,0,21,21,21,0,3,0,0,0,0,0
0,0,0,3,0,21,21,21,21,21,21,21,21,21,21,0,3,0,0,0,0
0,0,30,3,21,21,21,21,21,21,21,21,21,21,21,0,3,29,0,0,0
0,0,17,0,21,21,21,31,21,21,21,21,21,21,21,0,0,17,0,0,0
0,0,17,0,21,21,21,21,0,0,21,21,21,21,0,0,0,17,0,0,0
0,0,30,3,0,21,21,21,21,21,21,21,0,0,0,0,3,29,0,0,0
0,0,0,3,0,0,21,21,21,21,21,32,21,0,0,0,3,0,0,0,0
0,0,0,0,3,0,0,21,21,21,0,21,0,0,1,3,0,0,0,0,0
0,0,0,0,34,0,0,0,0,0,0,0,0,0,0,34,0,0,0,0,0
0,0,0,0,0,34,3,0,0,0,0,0,0,3,34,0,0,0,0,0,0
0,0,0,0,0,0,0,3,3,0,0,3,3,0,0,0,0,0,0,0,0
0,0,0,0,0,0,0,0,33,17,17,33,0,0,0,0,0,0,0,0,0
0,0,0,0,0,0,0,0,0,0,0,0,0,0,0,0,0,0,0,0,0
0,0,0,0,0,0,0,0,0,0,0,0,0,0,0,0,0,0,0,0,0
0,0,0,0,0,0,0,0,0,0,0,0,0,0,0,0,0,0,0,0,0
endlayer

layer
0,0,0,0,0,0,0,0,0,0,0,0,0,0,0,0,0,0,0,0,0
0,0,0,0,0,0,0,0,0,0,0,0,0,0,0,0,0,0,0,0,0
0,0,0,0,0,0,0,0,3,3,3,3,0,0,0,0,0,0,0,0,0
0,0,0,0,0,0,34,3,0,0,0,0,3,34,0,0,0,0,0,0,0
0,0,0,0,0,0,0,0,0,0,0,0,0,0,0,0,0,0,0,0,0
0,0,0,0,0,0,0,0,0,0,0,0,0,0,0,0,0,0,0,0,0
0,0,0,34,0,0,0,0,0,0,0,0,21,21,0,0,34,0,0,0,0
0,0,0,3,0,0,21,21,21,0,21,21,21,21,21,0,3,0,0,0,0
0,0,3,1,0,21,21,21,21,21,21,21,21,21,21,0,0,3,0,0,0
0,0,3,1,21,21,21,21,21,21,21,21,21,21,21,0,0,3,0,0,0
0,0,3,0,0,21,21,21,21,0,21,21,21,21,0,0,0,3,0,0,0
0,0,3,1,0,0,21,21,21,21,21,21,21,21,0,0,0,3,0,0,0
0,0,3,0,0,0,0,0,21,21,21,21,21,21,0,0,3,0,0,0,0
0,0,0,34,0,0,0,0,0,21,21,21,21,21,0,0,34,0,0,0,0
0,0,0,0,0,0,0,0,0,0,21,21,21,0,0,0,0,0,0,0,0
0,0,0,0,0,0,0,0,0,0,0,0,0,0,0,0,0,0,0,0,0
0,0,0,0,0,0,34,3,0,0,0,0,3,34,0,0,0,0,0,0,0
0,0,0,0,0,0,0,0,3,3,3,3,0,0,0,0,0,0,0,0,0
0,0,0,0,0,0,0,0,0,0,0,0,0,0,0,0,0,0,0,0,0
0,0,0,0,0,0,0,0,0,0,0,0,0,0,0,0,0,0,0,0,0
0,0,0,0,0,0,0,0,0,0,0,0,0,0,0,0,0,0,0,0,0
endlayer

layer
0,0,0,0,0,0,0,0,0,0,0,0,0,0,0,0,0,0,0,0,0
0,0,0,0,0,0,0,0,3,34,34,3,0,0,0,0,0,0,0,0,0
0,0,0,0,0,0,0,34,3,0,0,3,34,0,0,0,0,0,0,0,0
0,0,0,0,0,0,0,0,0,0,0,0,0,0,0,0,0,0,0,0,0
0,0,0,0,0,0,0,0,0,0,0,0,0,0,0,0,0,0,0,0,0
0,0,0,0,0,0,0,0,0,0,0,0,0,0,0,0,0,0,0,0,0
0,0,0,0,0,0,0,0,0,0,0,0,0,0,0,0,0,0,0,0,0
0,0,34,0,0,0,0,21,0,0,0,0,21,0,0,0,0,34,0,0,0
0,3,3,0,0,0,21,21,21,21,21,21,21,21,0,0,0,3,3,0,0
0,34,0,0,0,21,21,21,21,21,21,21,21,0,0,0,0,0,34,0,0
0,34,0,0,0,0,21,21,21,21,21,21,21,0,0,0,0,0,34,0,0
0,3,3,0,0,0,0,21,21,21,21,21,21,21,0,0,0,3,3,0,0
0,0,34,0,0,0,1,0,21,21,21,21,21,21,0,0,0,34,0,0,0
0,0,0,0,0,0,0,0,0,21,21,21,21,0,0,0,0,0,0,0,0
0,0,0,0,0,0,0,0,0,0,21,21,21,0,0,0,0,0,0,0,0
0,0,0,0,0,0,0,0,0,0,0,0,0,0,0,0,0,0,0,0,0
0,0,0,0,0,0,0,0,0,0,0,0,0,0,0,0,0,0,0,0,0
0,0,0,0,0,0,0,34,3,0,0,3,34,0,0,0,0,0,0,0,0
0,0,0,0,0,0,0,0,3,34,34,3,0,0,0,0,0,0,0,0,0
0,0,0,0,0,1,0,0,0,0,0,0,0,0,0,0,0,0,0,0,0
0,0,0,0,0,0,0,0,0,0,0,0,0,0,0,0,0,0,0,0,0
endlayer

layer
0,0,0,0,0,0,0,0,0,0,0,0,0,0,0,0,0,0,0,0,0
0,0,0,0,0,0,0,0,36,29,30,35,0,0,0,0,0,0,0,0,0
0,0,0,0,0,0,0,0,0,0,0,0,0,0,0,0,0,1,0,0,0
0,0,0,0,0,0,0,0,0,0,0,0,0,0,0,0,0,0,0,0,0
0,0,0,0,0,0,0,0,0,0,0,0,0,0,0,0,0,0,0,0,0
0,0,0,0,0,0,0,0,0,0,1,0,0,0,0,0,0,0,0,0,0
0,0,0,0,0,0,0,0,0,0,0,0,0,0,0,0,0,0,0,0,0
0,0,0,0,0,1,0,0,0,0,0,0,0,0,0,0,0,0,0,0,0
0,37,0,0,0,0,0,21,0,21,0,0,0,0,0,0,0,0,37,0,0
0,33,0,0,0,0,0,21,21,21,21,0,0,0,0,0,0,0,33,0,0
0,28,0,0,0,0,0,21,21,21,21,21,0,0,0,0,0,0,28,0,0
0,38,0,0,0,0,0,0,21,21,21,21,0,0,0,0,0,0,38,0,0
0,0,0,0,0,0,0,0,0,21,21,21,21,0,0,0,0,0,0,0,0
0,0,0,0,0,0,0,0,0,0,0,21,0,0,0,0,0,0,0,0,0
0,0,0,0,0,0,0,0,0,0,0,0,0,0,0,0,0,0,0,0,0
0,0,0,0,0,0,0,0,0,0,0,0,0,0,0,0,0,0,0,0,0
0,0,0,0,0,0,0,0,0,0,0,0,0,0,0,0,0,0,0,0,0
0,0,0,0,0,0,0,0,0,0,0,0,0,0,0,0,0,0,0,0,0
0,0,0,0,0,0,0,0,36,29,30,35,0,0,0,0,0,0,0,0,0
0,0,0,0,0,0,0,0,0,0,0,0,0,0,0,0,0,0,0,0,0
0,0,0,0,0,0,0,0,0,0,0,0,0,0,0,0,0,0,0,0,0
endlayer

layer
0,0,0,0,0,0,0,0,0,0,0,0,0,0,0,0,0,0,0,0,0
0,0,0,0,0,0,0,0,0,34,34,0,0,0,0,0,0,0,0,0,0
0,0,0,0,0,0,0,0,0,0,0,0,0,0,0,0,0,0,0,0,0
0,0,0,0,0,0,0,0,0,0,0,0,0,0,0,0,0,0,0,0,0
0,0,0,0,0,0,0,0,0,0,0,0,0,0,1,0,0,0,0,0,0
0,0,0,0,0,0,0,0,0,0,0,0,0,0,0,0,0,0,0,0,0
0,0,0,0,0,0,0,0,0,0,0,0,0,0,0,0,0,0,0,0,0
0,0,0,0,0,0,0,0,0,0,0,0,0,0,0,0,0,0,0,0,0
0,0,0,0,0,0,0,0,0,0,0,0,0,0,0,0,0,0,0,0,0
0,34,0,0,0,0,0,0,0,21,0,0,0,0,0,0,0,0,34,0,0
0,34,0,0,0,0,0,0,21,21,21,0,0,0,0,0,0,0,34,0,0
0,0,0,0,0,0,0,0,0,21,0,0,0,0,0,0,0,0,0,0,0
0,0,0,0,0,0,0,0,0,0,0,0,0,0,0,0,0,0,0,0,0
0,0,0,0,0,0,0,0,0,0,0,0,0,0,0,1,0,0,0,0,0
0,0,0,0,0,0,0,0,0,0,0,0,0,0,0,0,0,0,0,0,0
0,0,0,0,0,0,0,0,0,0,0,0,0,0,0,0,1,0,0,0,0
0,0,0,0,0,0,0,0,0,0,0,0,0,0,0,0,0,0,0,0,0
0,0,0,0,0,0,0,0,0,0,0,0,0,0,0,0,0,0,0,0,0
0,0,0,0,0,0,0,0,0,34,34,0,0,0,0,0,0,0,0,0,0
0,0,0,0,0,0,0,0,0,0,0,0,0,0,0,0,0,0,0,0,0
0,0,0,0,0,0,0,0,0,0,0,0,0,0,0,0,0,1,0,0,0
endlayer

layer
0,0,0,0,0,0,0,0,0,0,0,0,0,0,0,0,0,0,0,0,0
0,0,0,0,0,0,0,0,0,0,0,0,0,0,0,0,0,0,0,0,0
0,0,0,0,0,0,0,0,0,0,0,0,0,0,0,0,0,0,0,0,0
0,0,0,0,0,0,0,0,0,0,0,0,0,0,0,0,0,0,0,0,0
0,0,0,0,0,0,0,0,0,0,0,0,0,0,0,0,0,0,0,0,0
0,0,0,0,0,0,0,0,0,0,0,0,0,0,0,0,0,0,0,0,0
0,0,0,0,0,0,0,0,0,0,0,0,0,0,0,0,0,0,0,0,0
0,0,0,0,0,0,0,0,0,0,0,0,0,0,0,0,0,0,0,0,0
0,0,0,0,0,0,0,0,0,0,0,0,0,0,0,0,0,0,0,0,0
0,0,0,0,0,0,0,0,0,0,0,0,0,0,0,0,0,0,0,0,0
0,0,0,0,0,0,0,0,0,0,0,0,0,0,0,0,0,0,0,0,0
0,0,0,0,0,0,0,0,0,0,0,0,0,0,0,0,0,0,0,0,0
0,0,0,0,0,0,0,0,0,0,0,0,0,0,0,0,0,0,0,0,0
0,0,0,0,0,0,0,0,0,0,0,0,0,0,0,0,0,0,0,0,0
0,0,0,0,0,0,0,0,0,0,0,0,0,0,0,0,0,0,0,0,0
0,0,0,0,0,0,0,0,0,0,0,0,0,0,0,0,0,0,0,0,0
0,0,0,0,0,0,0,0,0,0,0,0,0,0,0,0,0,0,0,0,0
0,0,0,0,0,0,0,0,0,0,0,0,0,0,0,0,0,0,0,0,0
0,0,0,0,0,0,0,0,0,0,0,0,0,0,0,0,0,0,0,0,0
0,0,0,0,0,0,0,0,0,0,0,0,0,0,0,0,0,0,0,0,0
0,0,0,0,0,0,0,0,0,0,0,0,0,0,0,0,0,0,0,0,0
endlayer

layer
0,0,0,0,0,0,0,0,0,0,0,0,0,0,0,0,0,0,0,0,0
0,0,0,0,0,0,0,0,0,0,0,0,0,0,0,0,0,0,0,0,0
0,0,0,0,0,0,0,0,0,0,0,0,0,0,0,0,0,0,0,0,0
0,0,0,0,0,0,0,0,0,0,0,0,0,0,0,0,0,0,0,0,0
0,0,0,0,0,0,0,0,0,0,0,0,0,0,0,0,0,0,0,0,0
0,0,0,0,0,0,0,0,0,0,0,0,0,0,0,0,0,0,0,0,0
0,0,0,0,0,0,0,0,0,0,0,0,0,0,0,0,0,0,0,0,0
0,0,0,0,0,0,0,0,0,0,0,0,0,0,0,0,0,0,0,0,0
0,0,0,0,0,0,0,0,0,0,0,0,0,0,0,0,0,0,0,0,0
0,0,0,0,0,0,0,0,0,0,0,0,0,0,0,0,0,0,0,0,0
0,0,0,0,0,0,0,0,0,0,0,0,0,0,0,0,0,0,0,0,0
0,0,0,0,0,0,0,0,0,0,0,0,0,0,0,0,0,0,0,0,0
0,0,0,0,0,0,0,0,0,0,0,0,0,0,0,0,0,0,0,0,0
0,0,0,0,0,0,0,0,0,0,0,0,0,0,0,0,0,0,0,0,0
0,0,0,0,0,0,0,0,0,0,0,0,0,0,0,0,0,0,0,0,0
0,0,0,0,0,0,0,0,0,0,0,0,0,0,0,0,0,0,0,0,0
0,0,0,0,0,0,0,0,0,0,0,0,0,0,0,0,0,0,0,0,0
0,0,0,0,0,0,0,0,0,0,0,0,0,0,0,0,0,0,0,0,0
0,0,0,0,0,0,0,0,0,0,0,0,0,0,0,0,0,0,0,0,0
0,0,0,0,0,0,0,0,0,0,0,0,0,0,0,0,0,0,0,0,0
0,0,0,0,0,0,0,0,0,0,0,0,0,0,0,0,0,0,0,0,0
endlayer

layer
0,0,0,0,0,0,0,0,0,0,0,0,0,0,0,0,0,0,0,0,0
0,0,0,0,0,0,0,0,0,0,0,0,0,0,0,0,0,0,0,0,0
0,0,0,0,0,0,0,0,0,0,0,0,0,0,0,0,0,0,0,0,0
0,0,0,0,0,0,0,0,0,0,0,0,0,0,0,0,0,0,0,0,0
0,0,0,0,0,0,0,0,0,0,0,0,0,0,0,0,0,0,0,0,0
0,0,0,0,0,0,0,0,0,0,0,0,0,0,0,0,0,0,0,0,0
0,0,0,0,0,0,0,0,0,0,0,0,0,0,0,0,0,0,0,0,0
0,0,0,0,0,0,0,0,0,0,0,0,0,0,0,0,0,0,0,0,0
0,0,0,0,0,0,0,0,0,0,0,0,0,0,0,0,0,0,0,0,0
0,0,0,0,0,0,0,0,0,0,0,0,0,0,1,0,0,0,0,0,0
0,0,0,0,0,0,0,0,0,0,0,0,0,0,0,0,0,0,0,0,0
0,0,0,0,0,0,0,0,0,0,0,0,0,0,0,0,0,0,0,0,0
0,0,0,0,0,0,0,0,0,0,0,0,0,0,0,0,0,0,0,0,0
0,0,0,0,0,0,0,0,0,0,0,0,0,0,0,0,0,0,0,0,0
0,0,0,0,0,0,0,0,0,0,0,0,0,0,0,0,0,0,0,0,0
0,0,0,0,0,1,0,0,0,0,0,0,0,0,0,0,0,0,0,0,0
0,0,0,0,0,0,0,0,0,0,0,0,0,0,0,0,0,0,0,0,0
0,0,0,0,0,0,0,0,0,0,0,0,0,0,0,0,0,0,0,0,0
0,0,0,0,0,0,0,0,0,0,0,0,0,0,0,0,0,0,0,0,0
0,0,0,0,0,0,0,0,0,0,0,0,0,0,0,0,0,0,0,0,0
0,0,0,0,0,0,0,0,0,0,0,0,0,0,0,0,0,0,0,0,0
endlayer

layer
0,0,0,0,0,0,0,0,0,0,0,0,0,0,0,0,0,0,0,0,0
0,0,0,0,0,0,0,0,0,0,0,0,0,0,0,0,0,0,0,0,0
0,0,0,0,0,0,0,0,0,0,0,0,0,0,0,0,0,0,0,0,0
0,0,0,0,0,0,0,0,0,0,0,0,0,0,0,0,0,0,0,0,0
0,0,0,0,0,0,0,0,0,0,0,0,0,0,0,0,0,0,0,0,0
0,0,0,0,0,0,0,0,0,0,0,0,0,0,0,0,0,0,0,0,0
0,0,0,0,0,0,0,0,0,0,0,0,0,0,0,0,0,0,0,0,0
0,0,0,0,0,0,0,0,0,0,0,0,0,0,0,0,0,0,0,0,0
0,0,0,0,0,0,0,0,0,0,0,0,0,0,0,0,0,0,0,0,0
0,0,0,0,0,0,0,0,0,0,0,0,0,1,0,0,0,0,0,0,0
0,0,0,0,0,0,0,0,0,0,0,0,0,0,0,0,0,0,0,0,0
0,0,0,0,0,0,0,0,0,0,0,0,0,0,0,0,0,0,0,0,0
0,0,0,0,0,0,0,0,0,0,0,0,0,0,0,0,0,0,0,0,0
0,0,0,0,0,0,0,0,0,0,0,0,0,0,0,0,0,0,0,0,0
0,0,0,0,0,0,0,0,0,0,0,0,0,0,0,0,0,0,0,0,0
0,0,0,0,0,0,0,0,0,0,0,0,0,0,0,0,0,0,0,0,0
0,0,0,0,0,0,0,0,0,0,0,0,0,0,0,0,0,0,0,0,0
0,0,0,0,0,0,0,0,0,0,0,0,0,0,0,0,0,0,0,0,0
0,0,0,0,0,0,0,0,0,0,0,0,0,0,0,0,0,0,0,0,0
0,0,0,0,0,0,0,0,0,0,0,0,0,0,0,0,0,0,0,0,0
0,0,0,0,0,0,0,0,0,0,0,0,0,0,0,0,0,0,0,0,0
endlayer

layer
0,0,0,0,0,0,0,0,0,0,0,0,0,0,0,0,0,0,0,0,0
0,0,0,0,0,0,0,0,0,0,0,0,0,0,0,0,0,0,0,0,0
0,0,0,0,0,0,0,0,0,0,0,0,0,0,0,0,0,0,0,0,0
0,0,0,0,0,0,0,0,0,0,0,0,0,0,0,0,0,0,0,0,0
0,0,0,0,0,0,0,0,0,0,0,0,0,0,0,0,0,0,0,0,0
0,0,0,0,0,0,0,0,0,0,0,0,0,0,0,0,0,0,0,0,0
0,0,0,0,0,0,0,0,0,0,0,0,0,0,0,0,0,0,0,0,0
0,0,0,0,0,0,0,0,0,0,0,0,0,0,0,0,0,0,0,0,0
0,0,0,0,0,0,0,0,0,0,0,0,0,0,0,0,0,0,0,0,0
0,0,0,0,0,0,0,0,0,0,0,0,0,0,0,0,0,0,0,0,0
0,0,0,0,0,0,0,0,0,0,0,0,0,1,0,0,0,0,0,0,0
0,0,0,0,0,0,0,0,0,0,0,0,0,0,0,0,0,0,0,0,0
0,0,0,0,0,0,0,0,0,0,0,0,0,0,0,0,0,0,0,0,0
0,0,0,0,0,0,0,0,0,0,0,0,0,0,0,0,0,0,0,0,0
0,0,0,0,0,0,0,0,0,0,0,0,0,0,0,0,0,0,0,0,0
0,0,0,0,0,0,0,0,0,0,0,0,0,0,0,0,0,0,0,0,0
0,0,0,0,0,0,0,0,0,0,0,0,0,0,0,0,0,0,0,0,0
0,0,0,0,0,0,0,0,0,0,0,0,0,0,0,0,0,0,0,0,0
0,0,0,0,0,0,0,0,0,0,0,0,0,0,0,0,0,0,0,0,0
0,0,0,0,0,0,0,0,0,0,0,0,0,0,0,0,0,0,0,0,0
0,0,0,0,0,0,0,0,0,0,0,0,0,0,0,0,0,0,0,0,0
endlayer

