
# Created by Ruins mod version 14.4 Ingame Parser
# authoring Player: Mikhaila666

weight=1
embed_into_distance=0
acceptable_target_blocks=
unacceptable_target_blocks=flowing_water,water,flowing_lava,lava
dimensions=11,24,18
allowable_overhang=0
max_leveling=2
leveling_buffer=0
preserve_water=0
preserve_lava=0

rule1=0,100,minecraft:grass-0
rule2=0,100,minecraft:dirt-0
rule3=0,100,arsmagica2:vinteumOre-0
rule4=0,100,MobSpawner:Witch
rule5=0,100,minecraft:trapped_chest-5
rule6=0,100,Railcraft:tile.railcraft.residual.heat-0
rule7=0,100,minecraft:leaves-0
rule8=0,100,arsmagica2:blueOrchid-0
rule9=0,100,minecraft:log-0
rule10=0,100,minecraft:leaves-8
rule11=0,100,Highlands:tile.hl_acaciaWood-0
rule12=0,100,minecraft:obsidian-0
rule13=0,100,minecraft:tallgrass-1
rule14=0,100,minecraft:leaves-9
rule15=0,100,minecraft:red_flower-4
rule16=0,100,minecraft:yellow_flower-0
rule17=0,100,arsmagica2:liquidEssence-0
rule18=0,100,arsmagica2:Aum-0
rule19=0,100,Highlands:tile.hl_acaciaWood-4
rule20=0,100,Highlands:tile.hl_acaciaLeaves-0

layer
0,0,0,0,0,0,0,0,0,0,0,0,0,0,0,0,0,0
0,0,0,1,1,1,1,1,1,1,1,1,1,1,1,0,0,0
0,0,1,1,1,1,1,1,1,1,1,1,1,1,1,1,0,0
0,1,1,1,1,1,1,1,1,1,1,1,1,1,1,1,1,0
0,1,1,1,1,1,1,1,1,1,1,1,1,2,1,1,1,0
0,1,1,1,1,1,1,1,1,1,1,1,1,1,1,1,1,0
0,1,1,1,1,1,1,1,1,1,1,1,1,1,1,1,1,0
0,1,1,1,1,1,1,1,1,1,1,1,1,1,1,1,1,0
0,1,1,1,1,2,2,2,2,2,2,1,2,1,1,1,1,0
0,1,1,1,1,1,2,2,2,2,2,2,1,1,1,1,1,0
0,1,1,1,1,2,2,2,3,3,2,2,2,1,1,1,1,0
0,1,1,1,1,2,2,3,5,4,3,2,2,1,1,1,1,0
0,1,1,1,1,2,2,3,4,5,3,2,2,1,1,1,1,0
0,1,1,1,1,2,2,2,3,3,2,2,2,1,1,1,1,0
0,1,1,1,1,1,2,2,2,2,2,2,1,1,1,1,1,0
0,1,1,1,1,2,1,2,2,2,2,1,2,1,1,1,1,0
0,1,1,1,1,1,1,1,1,1,1,1,1,1,1,1,1,0
0,1,1,1,1,1,1,1,1,1,1,1,1,1,1,1,1,0
0,1,1,1,1,1,1,1,1,1,2,1,1,1,1,1,1,0
0,1,1,1,1,2,1,1,1,1,1,1,1,1,1,1,1,0
0,1,1,1,1,1,1,1,1,1,1,1,1,1,1,1,1,0
0,0,1,1,1,1,1,1,1,1,1,1,1,1,1,1,0,0
0,0,0,1,1,1,1,1,1,1,1,1,1,1,1,0,0,0
0,0,0,0,0,0,0,0,0,0,0,0,0,0,0,0,0,0
endlayer

layer
0,0,0,0,0,0,0,0,0,0,0,6,6,6,6,6,6,6
0,0,0,0,0,6,6,0,6,6,0,0,0,0,6,6,0,0
0,0,0,0,0,0,0,0,0,6,8,7,7,7,7,6,0,0
0,0,6,0,6,0,0,0,0,0,0,7,7,7,7,7,0,6
0,0,6,0,8,0,0,0,0,0,0,7,7,9,7,7,0,0
0,0,0,0,0,0,0,0,0,8,0,7,7,7,7,7,0,0
0,0,0,0,0,10,7,7,0,0,0,7,7,7,7,7,0,0
0,0,0,0,0,7,7,7,7,0,0,0,0,0,0,0,0,6
0,0,0,0,0,11,9,1,1,2,1,0,11,0,8,0,0,0
0,0,0,8,0,7,1,1,2,2,1,1,0,0,0,6,0,0
0,6,0,0,0,1,1,2,12,12,2,1,1,0,0,0,0,0
0,0,6,0,6,1,2,12,12,12,12,2,1,0,0,0,0,6
0,0,0,0,0,1,2,12,12,12,12,2,1,0,0,8,6,0
0,0,0,0,6,1,1,2,12,12,2,1,2,13,0,0,0,0
0,0,6,0,0,0,1,1,2,2,1,1,14,0,0,0,0,0
0,6,0,0,8,11,13,1,1,1,1,15,11,0,0,0,0,6
0,0,8,0,6,0,0,16,0,7,7,7,0,8,0,0,0,6
0,0,6,7,7,7,7,7,7,7,7,7,7,0,0,0,0,0
0,0,0,7,7,7,7,7,7,7,9,7,7,0,0,0,0,0
0,0,0,7,7,9,7,7,7,7,7,7,7,6,8,0,0,0
0,6,0,7,7,7,7,7,7,7,7,7,7,6,0,0,0,0
0,0,6,7,7,7,7,0,0,0,0,0,0,0,0,0,0,0
0,0,0,6,0,6,0,0,0,0,0,0,0,0,0,6,0,0
0,0,0,0,0,0,0,0,0,0,0,0,6,0,6,0,0,6
endlayer

layer
0,0,0,0,6,0,0,0,0,0,0,6,0,0,0,0,0,0
0,0,0,0,0,0,0,0,0,0,0,0,0,0,0,0,0,0
0,0,0,0,0,0,0,6,0,0,0,6,0,0,0,0,0,0
0,0,0,0,0,0,0,0,0,0,0,0,0,7,0,6,0,6
0,6,0,0,6,6,0,0,0,0,0,0,7,7,7,6,0,0
0,0,6,0,0,0,0,6,0,0,6,0,7,7,6,0,0,0
0,0,0,0,0,0,0,0,7,7,7,0,6,0,6,0,0,0
0,0,6,0,0,7,7,7,7,7,7,7,0,0,0,0,0,0
0,0,0,0,0,11,7,7,7,9,7,7,11,0,6,0,0,0
0,0,0,0,0,0,0,7,1,1,7,7,0,0,0,0,0,0
0,0,0,0,0,0,0,1,17,17,1,7,0,0,6,0,0,0
6,6,0,6,0,0,1,17,17,17,17,1,7,7,7,0,6,6
0,0,0,6,0,0,1,17,17,17,17,1,7,10,7,0,0,0
0,0,0,0,0,0,0,1,17,17,1,7,9,7,7,0,0,0
0,0,6,0,6,0,0,0,1,1,10,7,7,7,7,6,0,6
0,0,0,0,0,11,0,0,13,0,7,7,11,10,0,0,6,6
0,6,6,6,0,0,0,0,0,0,0,0,0,0,0,0,0,0
0,0,0,0,6,6,0,0,0,7,7,0,0,0,0,0,0,0
0,0,0,0,7,7,7,0,0,7,7,7,6,0,0,0,6,0
0,0,0,0,7,7,7,0,0,7,7,0,0,0,0,0,0,0
0,0,0,0,7,7,7,0,0,0,0,0,0,0,0,0,0,0
0,0,0,0,0,0,0,0,0,0,0,0,0,0,0,0,0,0
0,0,0,0,0,0,0,0,0,0,0,0,0,0,0,0,0,0
0,0,0,0,0,0,0,0,0,0,0,0,0,0,0,0,0,0
endlayer

layer
0,0,0,0,0,0,0,0,0,0,0,0,0,6,0,0,0,0
0,0,0,0,0,0,0,0,0,0,0,0,0,6,0,0,0,0
0,0,0,0,0,0,0,0,0,0,0,0,0,0,0,0,0,0
0,0,0,0,0,0,0,0,0,0,6,0,0,0,0,0,0,0
0,0,0,0,0,0,0,0,0,0,0,0,0,7,0,0,0,0
0,0,0,0,0,6,0,0,0,0,0,0,0,0,0,0,0,0
0,0,0,0,0,0,0,6,0,0,0,0,0,0,6,0,0,0
0,0,0,0,0,0,0,0,0,7,7,0,0,0,0,0,0,0
0,0,0,0,0,11,0,0,7,7,7,0,11,0,0,6,0,0
0,6,0,6,0,0,6,0,7,7,7,0,0,0,0,0,0,6
0,0,6,0,0,0,0,18,0,0,0,0,0,0,0,0,0,0
0,0,0,0,0,0,0,0,0,0,0,18,0,0,0,0,0,6
0,0,0,0,0,6,0,6,6,0,6,0,7,7,0,6,0,0
0,0,0,0,0,0,0,18,6,0,0,7,10,7,0,0,6,0
0,0,0,0,0,0,0,0,0,0,0,0,7,7,0,0,6,0
0,0,0,0,0,11,0,0,0,6,0,0,11,0,0,6,6,6
0,0,0,0,0,0,0,6,0,6,0,0,0,0,0,6,0,0
0,0,0,0,0,0,6,6,6,0,0,0,6,0,0,0,0,0
0,0,0,0,0,0,0,0,0,0,0,0,0,0,0,6,6,0
0,0,0,0,0,7,0,6,0,6,0,0,0,0,0,6,0,0
0,0,0,0,0,0,6,6,0,6,6,0,6,0,0,0,0,0
0,0,0,0,0,0,0,0,6,0,0,0,0,0,0,0,0,6
0,0,0,0,0,0,0,0,0,0,0,0,0,0,0,0,0,0
0,0,0,0,0,0,0,0,0,0,0,0,0,0,0,0,0,0
endlayer

layer
0,0,0,6,0,0,0,0,0,0,0,0,0,0,0,0,0,0
0,0,0,0,0,0,0,0,0,0,0,0,0,0,0,0,0,0
0,0,0,0,0,0,0,0,0,0,0,0,0,0,0,0,0,0
0,0,0,0,0,0,0,0,0,0,0,0,0,0,0,0,0,0
0,0,0,0,0,0,0,0,0,0,0,0,0,0,0,0,0,0
0,0,0,0,0,0,0,0,0,0,0,0,0,0,0,0,0,0
0,0,0,0,0,0,0,0,0,0,0,0,0,0,0,0,0,0
0,0,0,0,0,0,0,0,0,0,0,0,19,0,0,0,0,0
0,0,0,0,0,11,0,0,0,7,0,0,11,0,0,0,0,0
0,0,0,0,0,0,0,0,0,0,0,0,0,0,0,0,0,0
0,0,0,0,0,0,0,6,0,0,0,0,0,0,0,0,0,0
0,0,6,0,0,0,6,6,0,0,0,0,6,6,0,0,0,0
0,0,0,0,6,0,0,0,0,0,6,0,0,0,0,0,0,0
0,0,0,0,0,0,0,0,0,0,0,0,7,0,0,0,0,0
0,0,0,0,0,0,0,0,0,0,6,0,0,0,0,0,0,0
0,0,0,0,0,11,0,0,0,0,0,0,11,0,0,0,0,0
0,0,0,0,0,19,0,0,0,0,0,0,0,0,0,0,0,0
0,0,0,0,0,0,0,0,0,0,0,0,0,0,0,0,0,0
0,0,0,0,0,0,0,0,0,0,0,0,0,0,0,0,0,0
0,0,0,0,0,0,0,0,0,0,0,0,0,0,0,0,0,0
0,0,0,0,0,0,0,0,0,0,0,0,0,0,0,0,0,0
0,0,0,0,0,0,0,0,0,0,0,0,0,0,0,0,0,0
0,0,0,0,0,0,0,0,0,0,0,0,0,0,0,0,0,0
0,0,0,0,0,0,0,0,0,0,0,0,0,0,0,0,0,0
endlayer

layer
0,0,0,0,0,0,0,0,0,0,0,0,0,0,0,0,0,0
0,0,0,0,0,0,0,0,0,0,0,0,0,0,0,0,0,0
0,0,0,0,0,0,0,0,0,0,0,0,0,0,0,0,0,0
0,0,0,0,0,0,0,0,0,0,0,0,0,0,0,0,0,0
0,0,0,0,0,0,0,0,0,0,0,0,0,0,0,0,0,0
0,0,0,0,0,0,0,0,0,0,0,0,0,0,0,0,0,0
0,0,0,0,0,0,0,0,0,0,0,0,19,0,0,0,0,0
0,0,0,0,0,0,0,0,0,0,0,0,0,0,0,0,0,0
0,0,0,0,0,11,0,0,0,0,0,0,11,0,0,0,0,0
0,0,0,0,0,19,0,6,0,0,0,0,0,0,0,0,0,0
0,0,0,0,0,0,0,0,0,0,0,0,0,0,0,0,0,0
0,0,0,0,0,0,0,0,0,0,0,0,0,0,0,0,0,0
0,0,0,0,0,0,0,0,0,0,0,0,0,0,0,0,0,0
0,0,0,0,0,0,0,0,0,0,0,0,0,0,0,0,0,0
0,0,0,0,0,0,0,0,0,0,0,0,0,0,0,0,0,0
0,0,0,0,0,11,0,0,0,0,0,0,11,0,0,0,0,0
0,0,0,0,0,0,0,0,0,0,0,0,19,0,0,0,0,0
0,0,0,0,0,19,0,0,0,0,0,0,0,0,0,0,0,0
0,0,0,0,0,0,0,0,0,0,0,0,0,0,0,0,0,0
0,0,0,0,0,0,0,0,0,0,0,0,0,0,0,0,0,0
0,0,0,0,0,0,0,0,0,0,0,0,0,0,0,0,0,0
0,0,0,0,0,0,0,0,0,0,0,0,0,0,0,0,0,0
0,0,0,0,0,0,0,0,0,0,0,0,0,0,0,0,0,0
0,0,0,0,0,0,0,0,0,0,0,0,0,0,0,0,0,0
endlayer

layer
0,0,0,0,0,0,0,0,0,0,0,0,0,0,0,0,0,0
0,0,0,0,0,0,0,0,0,0,0,0,0,0,0,0,0,0
0,0,0,0,0,0,0,0,0,0,0,0,0,0,0,0,0,0
0,0,0,0,0,0,0,0,0,0,0,0,0,0,0,0,0,0
0,0,0,0,0,0,0,0,0,0,0,0,0,0,0,0,0,0
0,0,0,0,0,0,0,0,0,0,0,0,19,0,0,0,0,0
0,0,0,0,0,0,0,0,0,0,0,0,0,0,0,0,0,0
0,0,0,0,0,0,0,0,0,0,0,0,0,0,0,0,0,0
0,0,0,0,0,11,0,0,0,0,0,0,11,0,0,0,0,0
0,0,0,0,0,0,0,0,0,0,0,0,0,0,0,0,0,0
0,0,0,0,0,19,0,0,0,0,0,0,0,0,0,0,0,0
0,0,0,0,0,0,0,0,0,0,0,0,0,0,0,0,0,0
0,0,0,0,0,0,0,0,0,0,0,0,0,0,0,0,0,0
0,0,0,0,0,0,0,0,0,0,0,0,0,0,0,0,0,0
0,0,0,0,0,0,0,0,0,0,0,0,0,0,0,0,0,0
0,0,0,0,0,11,0,0,0,0,0,0,11,0,0,0,0,0
0,0,0,0,0,0,0,0,0,0,0,0,0,0,0,0,0,0
0,0,0,0,0,0,0,0,0,0,0,0,19,0,0,0,0,0
0,0,0,0,0,19,0,0,0,0,0,0,0,0,0,0,0,0
0,0,0,0,0,0,0,0,0,0,0,0,0,0,0,0,0,0
0,0,0,0,0,0,0,0,0,0,0,0,0,6,0,0,0,0
0,0,0,0,0,0,0,0,0,0,0,0,0,0,0,0,0,0
0,0,0,0,0,0,0,0,0,0,0,0,0,0,0,0,0,0
0,0,0,0,0,0,0,0,0,0,0,0,0,0,0,0,0,0
endlayer

layer
0,0,0,0,0,0,0,0,0,0,20,20,20,20,20,0,0,0
0,0,0,0,0,0,0,0,0,20,20,20,20,20,20,20,0,0
0,0,0,0,0,0,0,0,20,20,20,20,20,20,20,20,20,0
0,0,0,0,0,0,0,0,20,20,20,20,20,20,20,20,20,0
0,0,0,0,0,0,0,0,20,20,20,20,19,20,20,20,20,0
0,0,0,0,0,0,0,0,20,20,20,20,20,20,20,20,20,0
0,0,0,0,0,0,0,0,20,20,20,20,20,20,20,20,20,0
0,0,0,0,0,0,0,0,0,20,20,20,20,20,20,20,0,0
0,0,0,0,0,11,0,0,0,0,20,20,11,20,20,0,0,0
0,0,0,0,0,0,0,0,0,0,0,0,0,0,0,0,0,0
0,0,0,0,0,0,0,0,0,0,0,0,0,0,0,0,0,0
0,0,0,0,0,19,0,0,0,0,0,0,0,0,0,0,0,0
0,0,0,0,0,0,0,0,0,0,0,0,0,0,0,0,0,0
0,0,0,0,0,0,0,0,0,0,0,0,0,0,0,0,0,0
0,0,0,0,0,0,0,0,0,0,0,0,0,0,0,0,0,0
0,0,0,20,20,11,20,20,0,0,0,0,11,0,0,0,0,0
0,0,20,20,20,20,20,20,20,0,0,0,0,0,0,0,0,0
0,20,20,20,20,20,20,20,20,20,0,0,0,0,0,0,0,0
0,20,20,20,20,20,20,20,20,20,0,0,19,0,0,0,0,0
0,20,20,20,20,19,20,20,20,20,0,0,0,0,0,0,0,0
0,20,20,20,20,20,20,20,20,20,0,0,0,0,0,0,0,0
0,20,20,20,20,20,20,20,20,20,0,0,0,0,0,0,0,0
0,0,20,20,20,20,20,20,20,0,0,0,0,0,0,0,0,0
0,0,0,20,20,20,20,20,0,0,0,0,0,0,0,0,0,0
endlayer

layer
0,0,0,0,0,0,0,0,0,0,0,0,0,0,0,0,0,0
0,0,0,0,0,0,0,0,0,0,0,20,20,20,0,0,0,0
0,0,0,0,0,0,0,0,0,0,20,20,20,20,20,0,0,0
0,0,0,0,0,0,0,0,0,20,20,20,20,20,20,20,0,0
0,0,0,0,0,0,0,0,0,20,20,20,20,20,20,20,0,0
0,0,0,0,0,0,0,0,20,20,20,20,20,20,20,20,20,0
0,0,0,0,0,0,0,20,20,20,20,20,20,20,20,20,20,20
0,0,0,0,0,0,0,20,20,20,20,20,20,20,20,20,20,20
0,0,0,20,20,11,20,20,20,20,20,20,11,20,20,20,20,20
0,0,20,20,20,20,20,20,20,20,20,20,20,20,20,20,20,20
0,20,20,20,20,20,20,20,20,20,20,20,20,20,20,20,20,20
0,20,20,20,20,20,20,20,20,20,20,20,20,20,20,20,20,0
0,20,20,20,20,20,20,20,20,20,20,20,20,20,20,20,0,0
20,20,20,20,20,20,20,20,20,20,20,20,20,20,20,0,0,0
20,20,20,20,20,20,20,20,20,20,20,0,0,0,0,0,0,0
20,20,20,20,20,11,20,20,20,20,20,20,11,20,20,0,0,0
20,20,20,20,20,20,20,20,20,20,20,20,20,20,20,20,0,0
20,20,20,20,20,20,20,20,20,20,20,20,20,20,20,20,20,0
0,20,20,20,20,20,20,20,20,20,20,20,20,20,20,20,20,0
0,0,20,20,20,20,20,20,20,20,20,20,19,20,20,20,20,0
0,0,20,20,20,20,20,20,20,20,20,20,20,20,20,20,20,0
0,0,0,20,20,20,20,20,20,20,20,20,20,20,20,20,20,0
0,0,0,0,20,20,20,0,0,20,20,20,20,20,20,20,0,0
0,0,0,0,0,0,0,0,0,0,20,20,20,20,20,0,0,0
endlayer

layer
0,0,0,0,0,0,0,0,0,0,0,0,0,0,0,0,0,0
0,0,0,0,0,0,0,0,0,0,0,0,0,0,0,0,0,0
0,0,0,0,0,0,0,0,0,0,0,0,0,0,0,0,0,0
0,0,0,20,20,20,20,20,0,0,0,0,0,0,0,0,0,0
0,0,20,20,20,20,20,20,20,0,20,20,20,20,20,0,0,0
0,20,20,20,20,20,20,20,20,20,20,20,20,20,20,20,0,0
20,20,20,20,20,20,20,20,20,20,20,20,20,20,20,20,20,0
20,20,20,20,20,20,20,20,20,20,20,20,20,20,20,20,20,0
20,20,20,20,20,11,20,20,20,20,20,20,20,20,20,20,20,0
20,20,20,20,20,20,20,20,20,20,20,20,20,20,20,20,20,0
20,20,20,20,20,20,20,20,20,20,20,20,20,20,20,20,20,0
0,20,20,20,20,20,20,20,20,20,20,20,20,20,20,20,0,0
0,0,20,20,20,20,20,20,20,20,20,20,20,20,20,20,20,0
6,20,20,20,20,20,20,20,20,20,20,20,20,20,20,20,20,20
0,20,20,20,20,20,20,20,20,20,20,20,20,20,20,20,20,20
0,20,20,20,20,20,20,20,20,20,20,20,11,20,20,20,20,20
0,20,20,20,20,20,20,20,20,20,20,20,20,20,20,20,20,20
0,20,20,20,20,20,20,20,20,20,20,20,20,20,20,20,20,20
0,0,20,20,20,20,20,20,20,20,20,20,20,20,20,20,20,0
0,0,0,20,20,20,20,20,0,20,20,20,20,20,20,20,0,0
0,0,0,0,0,0,0,0,0,20,20,20,20,20,20,20,0,0
0,0,0,0,0,0,0,0,0,0,20,20,20,20,20,0,0,0
0,0,0,0,0,0,0,0,0,0,0,20,20,20,0,0,0,0
0,0,0,0,0,0,0,0,0,0,0,0,0,0,0,0,0,0
endlayer

layer
0,0,0,0,0,0,0,0,0,0,0,0,0,0,0,0,0,0
0,0,0,0,0,0,0,0,0,0,0,0,0,0,0,0,0,0
0,0,0,0,0,0,0,0,0,0,0,0,0,0,0,0,0,0
0,0,0,0,0,0,0,0,0,0,0,0,0,0,0,0,0,0
0,0,0,20,20,20,20,20,0,0,0,0,0,0,0,0,0,0
0,0,20,20,20,20,20,20,20,0,0,0,0,0,0,0,0,0
0,20,20,20,20,20,20,20,20,20,0,0,0,0,0,0,0,0
0,20,20,20,20,20,20,20,20,20,0,0,0,0,0,0,0,0
0,20,20,20,20,20,20,20,20,20,0,0,0,0,0,0,0,0
0,20,20,20,20,20,20,20,20,20,0,0,0,0,0,0,0,0
0,20,20,20,20,20,20,20,20,20,0,0,0,0,0,0,0,0
0,0,20,20,20,20,20,20,20,0,20,20,20,20,20,0,0,0
0,0,0,20,20,20,20,20,0,20,20,20,20,20,20,20,0,0
6,0,0,0,0,0,0,0,20,20,20,20,20,20,20,20,20,0
0,0,0,0,0,0,0,0,20,20,20,20,20,20,20,20,20,0
0,0,0,0,0,0,0,0,20,20,20,20,20,20,20,20,20,0
0,0,0,0,0,0,0,0,20,20,20,20,20,20,20,20,20,0
0,0,0,0,0,0,0,0,20,20,20,20,20,20,20,20,20,0
0,0,0,0,0,0,0,0,0,20,20,20,20,20,20,20,0,0
0,0,0,0,0,0,0,0,0,0,20,20,20,20,20,0,0,0
0,0,0,0,0,0,0,0,0,0,0,0,0,0,0,0,0,0
0,0,0,0,0,0,0,0,0,0,0,0,0,0,0,0,0,0
0,0,0,0,0,0,0,0,0,0,0,0,0,0,0,0,0,0
0,0,0,0,0,0,0,0,0,0,0,0,0,0,0,0,0,0
endlayer

