
# Created by Ruins mod version 14.4 Ingame Parser
# authoring Player: Mikhaila666

weight=1
embed_into_distance=0
acceptable_target_blocks=
unacceptable_target_blocks=flowing_water,water,flowing_lava,lava
dimensions=14,12,14
allowable_overhang=0
max_leveling=2
leveling_buffer=0
preserve_water=0
preserve_lava=0

rule1=0,100,minecraft:grass-0
rule2=0,100,minecraft:gravel-0
rule3=0,100,minecraft:planks-1
rule4=0,100,minecraft:dirt-0
rule5=0,100,minecraft:stone_brick_stairs-0
rule6=0,100,minecraft:stone_brick_stairs-2
rule7=0,100,minecraft:cobblestone-0
rule8=0,100,minecraft:log-0
rule9=0,100,minecraft:wooden_door-0
rule10=0,100,minecraft:stone_brick_stairs-3
rule11=0,100,minecraft:crafting_table-0
rule12=0,100,minecraft:ladder-5
rule13=0,100,ChestGenHook:dungeonChest:5-2
rule14=0,100,minecraft:wooden_slab-8
rule15=0,100,minecraft:oak_stairs-2
rule16=0,100,minecraft:furnace-2
rule17=0,100,minecraft:stone_slab-11
rule18=0,100,minecraft:wool-8
rule19=0,100,minecraft:red_flower-0
rule20=0,100,minecraft:leaves-1
rule21=0,100,minecraft:stone_brick_stairs-1
rule22=0,100,minecraft:stonebrick-0
rule23=0,100,minecraft:wooden_door-8
rule24=0,100,minecraft:stone_pressure_plate-0
rule25=0,100,Railcraft:tile.railcraft.residual.heat-0
rule26=0,100,minecraft:cobblestone_wall-0
rule27=0,100,minecraft:fence-0
rule28=2,100,minecraft:torch-2
rule29=0,100,minecraft:stone_stairs-4
rule30=0,100,minecraft:wooden_slab-9
rule31=0,100,minecraft:stone_stairs-6
rule32=0,100,minecraft:stone_stairs-7
rule33=0,100,minecraft:stone_brick_stairs-4
rule34=0,100,minecraft:double_wooden_slab-0
rule35=0,100,minecraft:stone_brick_stairs-6
rule36=0,100,minecraft:stone_brick_stairs-5
rule37=0,100,minecraft:stone_stairs-5
rule38=0,100,minecraft:oak_stairs-0
rule39=0,100,minecraft:bed-9
rule40=0,100,minecraft:oak_stairs-3
rule41=0,100,minecraft:bed-1
rule42=0,100,minecraft:glass_pane-0
rule43=0,100,minecraft:oak_stairs-1
rule44=0,100,minecraft:bed-3
rule45=0,100,ChestGenHook:dungeonChest:5-3
rule46=0,100,minecraft:bed-11
rule47=0,100,minecraft:oak_stairs-4
rule48=0,100,minecraft:oak_stairs-6
rule49=0,100,minecraft:oak_stairs-7
rule50=0,100,minecraft:oak_stairs-5
rule51=0,100,minecraft:wooden_slab-0
rule52=0,100,minecraft:log-8
rule53=0,100,minecraft:log-4
rule54=0,100,minecraft:tnt-0
rule55=0,100,MobSpawner:Zombie
rule56=0,100,ChestGenHook:dungeonChest:5-4
rule57=0,100,minecraft:spruce_stairs-2
rule58=2,100,minecraft:torch-1
rule59=0,100,minecraft:spruce_stairs-5
rule60=0,100,minecraft:spruce_stairs-3
rule61=0,100,minecraft:spruce_stairs-4
rule62=0,100,minecraft:spruce_stairs-0
rule63=0,100,minecraft:planks-0
rule64=0,100,minecraft:spruce_stairs-1

layer
1,1,1,1,3,1,3,1,3,1,1,1,2,1
1,1,3,3,3,3,3,3,3,3,1,2,2,2
1,1,3,3,3,3,3,3,3,2,2,2,2,2
1,3,3,3,3,3,3,3,3,3,4,4,2,2
1,1,3,3,3,3,3,3,3,2,2,4,2,2
1,3,3,3,3,3,3,3,3,3,2,4,2,2
1,1,3,3,3,3,3,3,3,2,2,4,2,2
1,3,3,3,3,3,3,3,3,3,4,4,2,2
1,1,3,3,3,3,3,3,3,2,2,2,2,2
1,3,3,3,3,2,3,3,3,3,2,2,2,2
1,1,3,1,3,2,3,2,3,1,1,1,1,1
1,1,1,1,1,1,1,1,1,1,1,1,1,1
endlayer

layer
0,0,5,0,5,0,5,0,5,0,0,0,0,0
0,10,7,7,8,9,8,7,7,6,0,0,0,0
0,0,7,13,0,0,12,11,7,0,0,5,0,0
0,10,7,16,0,0,15,14,7,7,7,7,6,0
0,0,7,17,0,0,0,0,0,0,0,7,0,0
0,10,7,16,0,0,0,0,0,0,0,7,0,0
19,0,7,18,0,0,0,0,0,0,0,7,0,0
20,10,7,18,18,0,0,14,7,7,7,7,6,0
20,0,7,18,0,0,15,14,7,0,0,21,0,0
20,10,7,7,7,9,7,7,7,6,0,0,0,0
19,0,21,0,21,0,21,0,21,0,0,0,0,0
20,20,20,0,19,0,0,0,0,0,0,0,0,0
endlayer

layer
0,0,0,0,0,0,0,0,0,0,0,0,0,0
0,0,22,22,8,23,8,22,22,0,0,0,0,0
0,0,22,0,0,0,12,0,22,0,0,0,0,0
0,0,22,26,25,0,0,24,22,22,22,22,0,0
0,0,27,0,0,0,0,0,0,0,0,22,0,0
0,0,22,26,0,0,0,0,0,0,0,22,0,0
0,0,27,0,0,0,0,0,0,0,0,22,0,0
0,0,22,18,0,0,0,0,22,22,22,22,0,0
0,0,22,0,28,0,0,24,22,0,0,0,0,0
0,0,22,27,22,23,22,27,22,0,0,0,25,0
0,25,0,0,0,0,0,0,0,0,0,0,0,0
0,0,0,0,0,0,0,0,0,0,0,0,0,0
endlayer

layer
0,0,29,30,29,30,29,30,29,0,0,0,0,0
0,32,22,22,8,22,8,22,22,31,0,0,0,0
0,30,22,34,14,14,12,14,22,30,30,33,0,0
0,32,22,34,14,14,14,14,22,22,22,22,35,0
0,30,22,34,14,14,14,14,0,0,0,22,30,0
0,32,22,34,14,14,14,14,0,0,0,22,30,0
0,30,22,34,14,14,14,14,0,0,0,22,30,0
0,32,22,34,14,14,14,14,22,22,22,22,35,0
0,30,22,34,14,14,14,14,22,30,30,36,0,0
0,32,22,22,22,22,22,22,22,31,0,0,0,0
0,0,37,30,37,30,37,30,37,0,0,0,0,0
0,0,0,0,0,0,0,0,0,0,0,0,0,0
endlayer

layer
0,0,26,0,26,0,26,0,26,0,0,0,0,0
0,26,8,38,8,38,8,38,8,26,0,0,0,0
0,0,40,13,39,0,12,0,15,0,0,26,0,0
0,26,8,0,41,0,0,0,8,38,38,8,26,0
0,0,40,0,39,0,0,0,0,0,0,15,0,0
0,26,8,0,41,0,0,0,0,0,0,15,0,0
0,0,42,13,39,0,0,0,0,0,0,15,0,0
0,26,8,0,41,0,44,0,8,43,43,8,26,0
0,0,40,27,0,0,46,45,15,0,0,26,0,0
0,26,8,43,8,43,8,43,8,26,0,0,0,0
0,0,26,0,26,0,26,0,26,0,0,0,0,0
0,0,0,0,0,0,0,0,0,0,0,0,0,0
endlayer

layer
0,0,26,0,26,0,26,0,26,0,0,0,0,0
0,26,8,47,8,47,8,47,8,26,0,0,0,0
0,0,49,0,0,0,12,0,48,0,0,26,0,0
0,26,8,0,0,0,0,0,8,47,47,8,26,0
0,25,49,0,0,0,0,0,0,0,0,48,0,0
0,26,8,0,0,0,0,0,0,0,0,48,0,0
0,0,42,0,0,0,0,0,0,0,0,48,0,0
0,26,8,0,0,0,0,0,8,50,50,8,26,0
25,0,49,27,0,0,0,0,48,0,0,26,0,0
0,26,8,50,8,50,8,50,8,26,0,0,0,0
0,0,26,0,26,0,26,0,26,0,0,0,0,0
0,0,0,0,0,0,0,0,0,0,0,0,0,0
endlayer

layer
0,0,38,51,38,51,38,51,38,0,25,25,0,0
25,40,8,52,52,52,52,52,8,15,0,0,0,0
0,51,53,3,3,3,3,3,53,51,51,38,0,0
0,40,8,3,3,3,3,3,8,52,52,8,15,0
0,51,53,3,3,3,3,3,53,0,0,53,51,25
0,40,53,3,3,3,3,3,53,0,0,53,51,0
0,51,53,3,3,3,3,3,53,0,0,53,51,0
0,40,53,3,3,3,3,3,53,52,52,8,15,0
25,51,53,3,3,3,3,3,53,51,51,43,0,0
0,40,8,52,52,52,52,52,8,15,25,0,0,0
0,0,43,51,43,51,43,51,43,0,25,0,0,0
0,0,0,25,25,0,25,25,0,0,0,0,0,0
endlayer

layer
0,0,0,0,0,0,0,0,0,0,0,0,0,0
0,0,8,3,8,3,8,3,8,0,0,0,0,0
0,0,3,11,0,0,54,54,3,0,0,0,0,0
0,0,8,7,11,55,24,45,8,3,3,8,0,0
0,0,27,11,0,25,25,54,0,0,0,3,0,0
0,0,8,13,0,25,0,24,54,0,0,3,0,0
0,0,27,24,0,25,0,24,54,0,0,3,0,0
0,0,8,54,24,0,0,54,8,3,3,8,0,0
0,0,3,54,54,55,56,54,3,0,0,0,0,0
0,0,8,3,8,3,8,3,8,0,0,0,0,0
0,0,0,0,0,0,0,0,0,0,0,0,0,0
0,0,0,0,0,0,0,0,0,0,0,0,0,0
endlayer

layer
0,40,48,0,0,0,0,0,49,15,0,0,0,0
0,40,8,3,8,3,8,3,8,57,0,0,0,0
0,40,27,0,0,0,58,0,27,38,38,38,38,0
0,60,8,11,0,0,0,0,8,59,59,8,59,0
0,40,27,0,0,0,0,0,0,0,0,27,0,0
0,60,8,0,0,0,0,0,0,0,0,27,0,0
0,40,27,0,0,0,0,0,0,0,0,27,0,0
0,60,8,56,0,0,0,0,8,61,61,8,61,0
0,40,27,0,0,0,0,0,27,15,43,43,43,0
0,60,8,27,8,27,8,27,8,57,0,0,0,0
0,40,48,0,0,0,0,0,49,15,0,0,0,0
0,0,0,0,0,0,0,0,0,0,0,0,0,0
endlayer

layer
0,0,40,48,0,0,0,49,15,0,0,0,0,0
0,0,60,52,8,52,8,52,57,0,0,0,0,0
0,0,40,48,0,0,0,49,15,0,0,0,0,0
0,0,60,48,0,0,0,49,57,62,62,62,62,0
0,0,40,48,0,0,0,49,63,63,63,63,63,0
0,0,60,48,0,25,0,49,3,3,3,3,3,0
0,0,40,48,0,0,0,49,63,63,63,63,63,0
0,0,60,48,0,0,0,49,57,64,64,64,64,0
0,0,40,48,0,0,0,49,15,0,0,0,0,0
0,0,60,52,8,52,8,52,57,0,0,0,0,0
0,0,40,48,0,0,0,49,15,0,0,0,0,0
0,0,0,0,0,0,0,0,0,0,0,0,0,0
endlayer

layer
0,0,0,40,34,34,34,15,0,0,0,0,0,0
0,0,0,60,3,3,3,57,0,0,0,0,0,0
0,0,0,40,48,14,49,15,0,0,0,0,0,0
0,0,0,7,3,3,3,57,0,0,0,0,0,0
0,0,0,40,48,14,49,15,0,0,0,0,0,0
0,0,0,60,3,3,3,57,0,0,0,0,0,0
0,0,0,40,48,3,3,15,0,0,0,0,0,0
0,0,0,60,3,3,3,57,0,0,0,0,0,0
0,0,0,40,48,14,49,15,0,0,0,0,0,0
0,0,0,60,3,3,3,57,0,0,0,0,0,0
0,0,0,40,34,34,34,15,0,0,0,0,0,0
0,0,0,0,0,0,0,0,0,0,0,0,0,0
endlayer

layer
0,0,0,0,0,0,0,0,0,0,0,0,0,0
0,0,0,0,0,0,0,0,0,0,0,0,0,0
0,0,0,0,0,0,0,0,0,0,0,0,0,0
0,0,0,7,0,0,0,0,0,0,0,0,0,0
0,0,0,0,0,0,0,0,0,0,0,0,0,0
0,0,0,0,0,0,0,0,0,0,0,0,0,0
0,0,0,0,0,0,25,25,25,0,0,0,0,0
0,0,0,0,0,0,0,0,0,0,0,0,0,0
0,0,0,0,0,0,0,0,0,0,0,0,0,0
0,0,0,0,0,0,0,0,0,0,0,0,0,0
0,0,0,0,0,0,0,0,0,0,0,0,0,0
0,0,0,0,0,0,0,0,0,0,0,0,0,0
endlayer

layer
0,0,0,0,0,0,0,0,0,0,0,0,0,0
0,0,0,0,0,0,0,0,0,0,0,0,0,0
0,0,0,0,0,0,0,0,0,0,0,0,0,0
0,0,0,26,0,0,0,0,0,0,0,0,0,0
0,0,0,0,0,0,0,0,0,0,0,0,0,0
0,0,0,0,0,0,0,0,0,0,0,0,0,0
0,0,0,0,0,0,0,0,0,0,0,0,0,0
0,0,0,0,0,0,0,0,0,0,0,0,0,0
0,0,0,0,0,0,0,0,0,0,0,0,25,0
0,0,0,0,0,0,0,0,0,0,0,0,0,0
0,0,0,0,0,0,0,0,0,0,0,0,0,0
0,0,0,0,0,0,0,0,0,0,0,0,0,0
endlayer

layer
0,0,0,0,0,0,0,0,0,0,0,0,0,0
0,0,0,0,0,0,0,0,0,0,0,0,0,0
0,0,0,0,0,0,0,0,0,0,0,0,0,0
0,0,0,0,0,0,0,0,0,0,0,0,0,0
0,0,0,0,0,0,0,0,0,0,0,0,0,0
0,0,0,0,0,0,0,0,0,0,0,0,0,0
0,0,0,0,0,0,25,25,0,0,0,0,0,0
0,0,0,0,0,0,0,0,0,0,0,0,0,0
0,0,0,0,0,0,0,0,0,0,0,0,0,0
0,0,0,0,0,0,0,0,0,0,0,0,0,0
0,0,0,0,0,0,0,0,0,0,0,0,0,0
0,0,0,0,0,0,0,0,0,0,0,0,0,0
endlayer

