
# Created by Ruins mod version 14.4 Ingame Parser
# authoring Player: Mikhaila666

weight=1
embed_into_distance=0
acceptable_target_blocks=
unacceptable_target_blocks=flowing_water,water,flowing_lava,lava
dimensions=38,30,32
allowable_overhang=0
max_leveling=2
leveling_buffer=0
preserve_water=0
preserve_lava=0

rule1=0,100,minecraft:grass-0
rule2=0,100,minecraft:dirt-0
rule3=0,100,minecraft:cobblestone-0
rule4=0,100,minecraft:wooden_slab-1
rule5=0,100,minecraft:log-0
rule6=0,100,minecraft:double_wooden_slab-1
rule7=0,100,minecraft:spruce_stairs-3
rule8=0,100,minecraft:spruce_stairs-2
rule9=0,100,minecraft:log-8
rule10=0,100,minecraft:leaves-1
rule11=0,100,minecraft:red_flower-0
rule12=0,100,minecraft:yellow_flower-0
rule13=0,100,Railcraft:tile.railcraft.residual.heat-0
rule14=0,100,minecraft:fence-0
rule15=0,100,minecraft:fence_gate-2
rule16=0,100,minecraft:ladder-3
rule17=0,100,minecraft:fence_gate-1
rule18=0,100,minecraft:iron_bars-0
rule19=2,100,minecraft:torch-1
rule20=2,100,minecraft:torch-3
rule21=2,100,minecraft:torch-4
rule22=0,100,minecraft:cobblestone_wall-0
rule23=0,100,minecraft:wooden_slab-9
rule24=0,100,minecraft:stonebrick-0
rule25=2,100,minecraft:torch-2
rule26=0,100,minecraft:double_stone_slab-3
rule27=0,100,minecraft:stone_stairs-4
rule28=0,100,minecraft:stone_slab-11
rule29=0,100,minecraft:stone_slab-13
rule30=0,100,minecraft:stone_stairs-6
rule31=0,100,minecraft:planks-1
rule32=0,100,minecraft:stone_stairs-7
rule33=0,100,minecraft:log-4
rule34=0,100,minecraft:oak_stairs-7
rule35=0,100,minecraft:oak_stairs-6
rule36=0,100,minecraft:oak_stairs-4
rule37=0,100,minecraft:stone_stairs-0
rule38=0,100,minecraft:stone_stairs-2
rule39=0,100,minecraft:stone_brick_stairs-0
rule40=0,100,minecraft:stone_stairs-3
rule41=0,100,minecraft:stone_stairs-1
rule42=0,100,minecraft:wooden_door-2
rule43=0,100,minecraft:wooden_door-1
rule44=0,100,minecraft:wooden_door-3
rule45=0,100,minecraft:wooden_door-5
rule46=0,100,minecraft:wooden_door-7
rule47=0,100,minecraft:wooden_door-8
rule48=0,100,minecraft:stone_brick_stairs-7
rule49=0,100,minecraft:stone_brick_stairs-6
rule50=0,100,minecraft:spruce_stairs-0
rule51=0,100,minecraft:spruce_stairs-5
rule52=0,100,minecraft:spruce_stairs-6
rule53=0,100,minecraft:spruce_stairs-4
rule54=0,100,minecraft:stone_stairs-5
rule55=0,100,minecraft:spruce_stairs-7
rule56=0,100,ChestGenHook:dungeonChest:5-2
rule57=0,100,minecraft:ladder-4
rule58=0,100,minecraft:wooden_pressure_plate-0
rule59=0,100,minecraft:stone_brick_stairs-5
rule60=0,100,minecraft:wooden_door-0
rule61=0,100,minecraft:stone_pressure_plate-0
rule62=0,100,minecraft:stone_slab-5
rule63=0,100,minecraft:planks-0
rule64=0,100,minecraft:stone_brick_stairs-4
rule65=0,100,minecraft:stonebrick-1
rule66=0,100,minecraft:trapdoor-6
rule67=0,100,minecraft:trapdoor-4
rule68=0,100,minecraft:stained_hardened_clay-14
rule69=0,100,minecraft:trapdoor-5
rule70=0,100,minecraft:stained_hardened_clay-8
rule71=0,100,minecraft:trapdoor-7

layer
0,0,1,1,1,1,1,1,1,1,1,1,1,1,1,1,1,1,1,1,1,1,1,1,1,1,1,1,1,1,1,1
0,0,1,1,1,1,1,1,1,1,1,1,1,1,1,1,1,1,1,1,1,1,1,1,1,1,1,1,1,1,1,1
0,0,1,1,1,1,1,1,1,1,1,1,1,1,1,1,1,1,1,1,1,1,1,1,1,1,1,1,1,1,1,1
0,0,1,1,1,1,1,1,1,1,2,2,2,2,2,1,1,1,1,1,1,1,2,2,2,2,2,1,1,1,1,1
0,0,1,1,1,1,1,1,1,1,3,3,3,3,3,2,1,1,1,1,1,2,3,3,3,3,3,1,1,1,1,1
0,0,1,1,1,1,1,1,1,3,4,4,4,4,4,3,2,2,2,2,2,3,4,4,4,4,4,3,1,1,1,1
0,0,1,1,1,1,1,1,3,4,4,4,4,4,4,4,3,3,3,3,3,4,4,4,4,4,4,4,3,1,1,1
0,0,1,1,1,1,1,1,3,4,4,4,4,4,4,4,4,4,4,4,4,4,4,4,4,4,4,4,3,1,1,1
0,0,1,1,2,1,1,1,3,4,4,4,5,4,4,5,4,4,4,4,4,5,4,4,5,4,4,4,3,1,1,1
0,0,1,1,1,1,1,1,3,6,4,4,4,4,4,4,4,4,4,4,4,4,4,4,4,4,4,4,3,1,1,1
0,0,1,1,1,1,1,1,3,6,4,4,4,4,4,4,4,4,4,4,4,4,8,6,7,4,4,4,3,1,1,1
0,0,1,1,1,1,1,1,1,3,4,4,4,4,4,4,4,4,4,4,4,4,4,6,4,4,4,3,1,1,1,1
0,0,1,1,1,1,1,1,1,1,3,4,4,4,4,4,4,4,4,4,4,4,8,6,7,4,3,1,1,1,1,1
0,0,1,1,1,1,1,1,1,1,3,4,4,4,4,4,4,4,4,4,4,4,4,4,4,4,3,1,1,1,1,1
0,0,1,1,1,1,1,1,1,1,3,4,5,4,4,5,4,4,4,4,4,5,4,4,5,4,3,1,1,1,1,1
0,0,1,1,1,1,1,1,1,1,3,4,4,4,4,3,5,4,4,4,5,3,4,4,4,4,3,1,1,1,1,1
0,0,1,1,1,1,1,1,1,1,3,4,4,4,4,3,4,4,4,4,4,3,4,4,4,4,3,1,1,1,1,1
0,0,1,1,1,1,1,1,1,3,4,4,4,4,4,3,4,4,4,4,4,3,4,4,4,4,4,3,1,1,1,1
0,0,1,1,1,1,1,1,3,4,4,4,4,4,4,3,4,4,4,4,4,3,4,4,4,4,4,4,3,1,1,1
0,0,1,1,2,1,1,1,3,4,4,4,5,4,4,3,3,4,4,4,3,3,4,4,5,4,4,4,3,1,1,1
0,0,1,1,1,1,1,1,3,4,4,4,4,4,4,3,3,9,9,9,3,3,4,4,4,4,4,4,3,1,1,1
0,0,1,1,1,1,1,1,3,4,4,4,4,4,4,3,3,1,1,1,3,3,4,4,4,4,4,4,3,1,1,1
0,0,1,1,1,1,1,1,1,3,4,4,4,4,3,1,1,1,1,1,1,1,3,4,4,4,4,3,1,1,1,1
0,0,1,1,1,1,1,1,1,1,3,3,3,3,1,1,1,1,1,1,1,1,1,3,3,3,3,1,1,1,1,1
0,0,1,1,1,1,1,1,1,1,1,1,1,1,1,1,1,1,1,1,1,1,1,1,1,1,1,1,1,1,1,1
0,0,1,1,1,1,1,1,1,1,1,1,1,1,1,1,1,1,1,1,1,1,1,1,1,1,1,1,1,1,1,1
0,0,1,1,1,1,1,1,1,1,1,1,1,1,1,1,1,1,1,1,1,1,1,1,1,1,1,1,1,1,1,1
0,0,0,0,0,0,0,0,0,0,0,0,0,0,0,0,0,0,0,0,0,0,0,0,0,0,0,0,0,0,0,0
0,0,0,0,0,0,0,0,0,0,0,0,0,0,0,0,0,0,0,0,0,0,0,0,0,0,0,0,0,0,0,0
0,0,0,0,0,0,0,0,0,0,0,0,0,0,0,0,0,0,0,0,0,0,0,0,0,0,0,0,0,0,0,0
endlayer

layer
0,0,0,0,0,0,0,0,0,0,0,0,0,0,0,0,0,0,0,0,0,0,0,0,0,0,0,0,0,0,0,0
0,0,0,0,0,10,0,10,10,10,10,10,0,0,0,10,10,10,10,0,0,10,0,0,0,10,0,10,10,10,0,0
0,0,0,0,0,10,10,10,10,10,12,0,0,0,0,10,10,10,10,11,10,0,0,0,0,0,0,10,10,10,0,0
0,0,0,0,10,10,10,10,10,0,3,3,3,3,3,10,10,10,10,0,10,0,3,3,3,3,3,10,10,0,0,0
0,0,0,0,10,12,10,0,10,0,3,3,3,3,3,3,0,0,0,10,0,3,3,3,3,3,3,10,10,10,0,0
0,13,0,0,0,11,10,10,10,3,0,0,0,0,0,3,3,3,3,3,3,3,0,0,0,0,0,3,0,0,0,0
0,13,0,0,0,10,0,10,3,0,0,0,0,0,0,0,3,3,3,3,3,0,0,0,0,0,0,0,3,0,0,0
0,13,0,0,0,0,0,0,3,0,0,0,0,0,0,0,0,0,0,0,0,0,0,0,0,0,0,0,3,0,0,0
0,0,0,0,5,14,14,14,3,0,0,0,5,0,0,5,0,0,0,0,0,5,0,0,5,0,0,0,3,0,0,0
0,0,0,0,14,0,0,0,3,0,0,0,0,0,0,0,0,0,0,0,0,0,0,0,0,0,0,0,3,0,0,0
0,0,0,0,14,0,0,0,3,0,0,0,0,0,0,0,0,0,0,0,0,0,0,0,0,0,0,0,3,0,0,0
0,0,0,0,14,0,0,0,14,3,0,0,0,0,0,0,0,0,0,0,0,0,0,0,0,0,0,3,0,0,0,0
0,0,0,0,14,0,0,0,0,0,3,0,0,0,0,0,0,0,0,0,0,0,0,0,0,0,3,0,12,11,0,0
0,0,0,0,15,0,0,0,0,0,3,0,0,0,0,0,0,0,0,0,0,0,0,0,0,0,3,0,0,0,0,0
0,0,0,0,14,14,17,14,14,14,3,0,5,0,0,5,0,0,0,0,16,5,0,0,5,0,3,0,0,0,0,0
0,0,0,0,14,0,0,0,0,0,0,0,0,0,0,3,5,0,0,0,5,3,0,0,0,0,3,0,0,0,0,0
0,13,0,0,15,0,0,0,0,0,3,0,0,0,0,3,0,0,0,0,0,3,0,0,0,0,3,0,0,0,0,0
0,13,0,0,14,0,0,0,14,3,0,0,0,0,0,3,0,0,0,0,13,3,0,0,0,0,0,3,0,0,0,0
0,0,0,0,14,0,0,0,3,0,0,0,0,0,0,3,0,0,0,0,0,3,0,0,0,0,0,0,3,0,0,0
0,0,0,0,5,14,14,14,3,0,0,0,5,0,0,3,3,0,0,0,3,3,0,0,5,0,0,0,3,0,0,0
0,0,0,0,0,0,0,0,3,0,0,0,0,0,0,3,3,0,0,0,3,3,0,0,0,0,0,0,3,0,0,0
0,0,0,0,0,10,0,0,3,0,0,0,0,0,0,3,3,0,0,0,3,3,0,0,0,0,0,0,3,0,0,0
0,0,0,0,10,0,10,10,10,3,0,0,0,0,3,0,0,0,0,0,0,0,3,0,0,0,0,3,0,0,0,0
13,0,0,0,0,10,10,10,0,0,3,3,3,3,0,0,0,0,0,0,0,0,0,3,3,3,3,0,0,0,0,0
0,0,0,0,0,10,10,10,10,0,0,0,10,10,0,0,0,0,0,0,0,0,0,0,0,0,0,0,0,0,0,0
0,0,0,0,0,0,0,0,0,0,0,0,0,0,0,0,0,0,0,0,0,0,0,0,0,0,0,0,0,0,0,0
13,0,0,0,13,0,0,0,0,0,0,0,0,0,0,0,0,0,0,0,0,0,0,0,0,0,0,0,0,0,0,0
0,0,0,13,0,0,0,0,0,0,0,0,0,0,0,0,0,0,0,0,0,0,0,0,0,0,0,0,0,0,0,0
0,0,13,0,0,0,0,0,0,0,0,0,0,0,0,0,0,0,0,0,0,0,0,0,0,0,0,0,0,0,0,0
0,0,0,0,0,0,0,0,0,0,0,0,0,0,0,0,0,0,0,0,0,0,0,0,0,0,0,0,0,0,0,0
endlayer

layer
0,0,0,0,0,0,0,0,0,0,0,0,0,0,0,0,0,0,0,0,0,0,0,0,0,0,0,0,0,0,0,0
0,0,0,0,0,0,0,0,0,0,0,0,0,0,0,0,0,0,0,0,0,0,0,0,0,0,0,0,0,0,0,0
0,0,0,0,0,0,0,0,0,0,0,0,0,0,0,0,0,0,0,0,0,0,0,0,0,0,0,0,0,0,0,0
0,0,0,0,0,0,0,0,0,0,3,3,3,3,3,0,0,0,0,0,0,0,3,3,3,3,3,0,0,0,0,0
0,0,0,0,0,0,0,0,0,0,3,3,3,3,3,3,0,0,0,0,0,3,3,3,3,3,3,0,0,0,0,0
0,0,0,0,0,0,0,0,0,3,0,0,0,0,0,3,3,3,18,3,3,3,0,0,0,0,0,3,0,0,0,0
0,0,0,0,0,0,0,0,3,0,0,0,0,0,0,0,3,3,0,3,3,0,0,0,0,0,0,0,3,0,0,0
0,0,0,0,0,0,0,0,3,0,0,0,0,0,0,0,0,0,0,0,0,0,0,0,0,0,0,0,3,0,0,0
0,0,0,0,5,0,0,0,3,0,0,0,5,0,0,5,0,0,0,0,0,5,0,0,5,0,0,0,3,0,0,0
0,0,0,0,0,0,0,0,3,0,0,0,0,0,0,0,0,0,0,0,0,0,0,0,19,0,0,0,3,0,0,0
0,0,0,0,0,0,0,0,3,0,0,0,0,0,0,0,0,0,0,0,0,0,0,0,0,0,0,0,3,0,0,0
0,0,0,0,0,0,0,0,0,3,0,0,0,0,0,0,0,0,0,0,0,0,0,0,0,0,0,3,0,0,0,0
0,0,0,0,0,0,0,0,0,0,3,0,0,0,0,0,0,0,0,0,0,0,0,0,0,0,3,0,0,0,0,0
0,0,0,0,0,0,0,0,0,0,3,0,0,0,0,0,0,0,0,0,0,0,0,0,0,0,3,0,0,0,0,0
0,0,0,13,0,0,0,0,0,0,3,0,5,0,0,5,0,0,0,0,16,5,0,0,5,0,3,0,0,0,0,0
0,0,0,0,0,0,0,0,0,0,0,0,0,0,0,3,5,0,0,0,5,3,0,0,0,0,3,0,0,0,0,0
0,0,0,0,0,0,0,0,0,0,3,0,0,0,0,3,0,0,0,0,0,3,0,0,0,0,3,0,0,0,0,0
0,0,0,0,0,0,0,0,0,3,0,0,0,0,0,3,0,0,0,0,0,3,0,0,0,0,0,3,0,0,0,0
0,0,0,0,0,0,0,0,3,0,0,0,0,0,0,3,21,0,0,0,20,3,0,0,0,0,0,0,3,0,0,0
0,0,0,0,5,0,0,0,3,0,0,0,5,0,0,3,22,0,0,0,22,3,0,0,5,0,0,0,3,0,0,0
0,0,0,0,0,0,0,0,3,0,0,0,0,0,0,3,3,0,0,0,3,3,0,0,0,0,0,0,3,0,0,0
0,13,0,0,0,0,0,0,3,0,0,0,0,0,0,3,22,0,0,0,22,3,0,0,0,0,0,0,3,0,0,0
0,0,0,0,0,0,0,0,0,3,0,0,0,0,3,0,0,0,0,0,0,0,3,0,0,0,0,3,0,0,0,0
0,0,0,0,0,0,0,0,0,0,3,3,3,3,0,0,0,0,0,0,0,0,0,3,3,3,3,0,0,0,0,0
0,0,0,0,0,0,0,0,0,0,0,0,0,0,0,0,0,0,0,0,0,0,0,0,0,0,0,0,0,0,0,0
0,0,0,0,0,0,0,0,0,0,0,0,0,0,0,0,0,0,0,0,0,0,0,0,0,0,0,0,0,0,0,0
0,0,0,0,0,0,0,0,0,0,0,0,0,0,0,0,0,0,0,0,0,0,0,0,0,0,0,0,0,0,0,0
0,0,0,0,0,0,0,0,0,0,0,0,0,0,0,0,0,0,0,0,0,0,0,0,0,0,0,0,0,0,0,0
0,0,13,0,0,0,0,0,0,0,0,13,0,0,0,0,0,0,0,0,0,0,0,0,0,0,0,0,0,0,0,0
0,0,0,0,0,0,0,0,0,13,0,0,0,0,0,0,0,0,0,0,0,0,0,0,0,0,0,0,0,0,0,0
endlayer

layer
0,0,0,0,0,0,0,0,0,0,0,0,0,0,0,0,0,0,0,0,0,0,0,0,0,0,0,0,0,0,0,0
0,0,0,0,0,0,0,0,0,0,0,0,0,0,0,0,0,0,0,0,0,0,0,0,0,0,0,0,0,0,0,0
0,0,0,0,0,0,0,0,0,0,0,0,0,0,0,0,0,0,0,0,0,0,0,0,0,0,0,0,0,0,0,0
0,0,0,0,0,0,0,0,0,0,3,3,18,3,3,0,0,0,0,0,0,0,3,3,18,3,3,0,0,0,0,0
0,0,0,0,0,0,0,0,0,0,3,3,0,3,3,3,0,0,0,0,0,3,3,3,0,3,3,0,0,0,0,0
0,0,0,0,0,0,0,0,0,3,0,0,0,0,0,3,3,3,18,3,3,3,0,0,0,0,0,3,0,0,0,0
0,0,0,0,0,0,0,0,3,0,0,0,0,0,0,0,3,3,0,3,3,0,0,0,0,0,0,0,3,0,0,0
0,0,0,0,4,23,0,0,3,0,0,0,0,0,0,0,0,0,0,0,0,0,0,0,0,0,0,0,3,0,0,0
0,0,0,0,4,23,0,0,3,0,0,0,5,0,0,5,0,0,0,0,0,5,0,0,5,0,0,0,3,0,0,0
0,0,0,0,4,23,0,0,3,0,0,0,0,0,0,0,0,0,0,0,0,0,0,0,0,0,0,0,3,0,0,0
0,0,0,0,4,23,0,0,3,0,0,0,0,0,0,0,0,0,0,0,0,0,0,0,0,0,0,0,3,0,0,0
0,0,0,0,4,23,0,0,0,3,0,0,0,0,0,0,0,0,0,0,0,0,0,0,0,0,0,3,0,0,0,0
0,0,0,0,4,23,0,0,0,0,3,0,0,0,0,0,0,0,0,0,0,0,0,0,0,0,3,0,0,0,0,0
0,0,0,0,4,23,0,0,0,0,3,0,0,0,0,0,0,0,0,0,0,0,0,0,0,0,3,0,0,0,0,0
0,0,0,0,4,23,0,0,0,0,3,0,5,0,0,5,0,0,0,0,16,5,0,0,5,0,3,0,0,0,0,0
0,0,0,0,4,23,0,0,0,0,3,0,0,0,0,3,5,0,0,0,5,3,0,0,0,0,3,0,0,0,0,0
0,0,0,0,4,23,0,0,0,0,3,0,0,0,0,3,0,0,0,0,0,3,0,0,0,0,3,0,0,0,0,0
0,0,0,0,4,23,0,0,0,3,0,0,0,0,0,3,0,0,0,0,0,3,0,0,0,0,0,3,0,0,0,0
0,0,0,0,4,23,0,0,3,0,0,0,0,0,0,3,0,0,0,0,0,3,0,0,0,0,0,0,3,0,0,0
0,0,0,0,4,23,0,0,3,0,0,0,5,0,0,3,22,0,0,0,22,3,0,0,5,0,0,0,3,0,0,0
0,0,0,0,4,23,0,0,3,0,0,0,0,0,0,3,3,0,0,0,3,3,0,0,0,0,0,0,3,0,0,0
0,0,0,0,0,0,0,0,3,0,0,0,0,0,0,3,22,0,0,0,22,3,0,0,0,0,0,0,3,0,0,0
0,0,0,0,0,0,0,0,0,3,0,0,0,0,3,0,0,0,0,0,0,0,3,0,0,0,0,3,0,0,0,0
0,0,0,0,0,0,0,0,0,0,3,3,3,3,0,0,0,0,0,0,0,0,0,3,3,3,3,0,0,0,0,0
0,0,0,0,0,0,0,0,0,0,0,0,0,0,0,0,0,0,0,0,0,0,0,0,0,0,0,0,0,0,0,0
0,0,0,0,0,0,0,0,0,0,0,0,0,0,0,0,0,0,0,0,0,0,0,0,0,0,0,0,0,0,0,0
0,0,0,0,0,0,0,0,0,0,0,0,0,0,0,0,0,0,0,0,0,0,0,0,0,0,0,0,0,0,0,0
0,0,0,0,0,0,0,0,0,0,0,0,0,0,0,0,0,0,0,0,0,0,0,0,0,0,0,0,0,0,0,0
0,13,0,0,0,0,0,0,0,0,0,0,0,0,0,0,0,0,0,0,0,0,0,0,0,0,0,0,0,0,0,0
0,0,0,0,0,0,0,0,0,0,0,0,0,0,0,0,0,0,0,0,0,0,0,0,0,0,0,0,0,0,13,0
endlayer

layer
0,0,0,0,0,0,0,0,0,0,0,0,0,0,0,0,0,0,0,0,0,0,0,0,0,0,0,0,0,0,0,0
0,0,0,0,0,0,0,0,0,0,0,0,0,0,0,0,0,0,0,0,0,0,0,0,0,0,0,0,0,0,0,0
0,0,0,0,0,0,0,0,0,0,0,0,0,0,0,0,0,0,0,0,0,0,0,0,0,0,0,0,0,0,0,0
0,0,0,0,0,0,0,0,0,0,24,24,24,24,24,0,0,0,0,0,0,0,24,24,24,24,24,0,0,0,0,0
0,0,0,0,0,0,0,0,0,0,24,0,0,0,0,24,0,0,0,0,0,24,3,0,0,0,24,0,0,0,0,0
0,0,0,0,0,0,0,0,0,24,0,0,0,0,0,0,24,24,24,24,24,0,0,0,0,0,0,24,0,0,0,0
0,0,0,0,0,0,0,0,24,0,0,0,0,0,0,0,0,0,0,0,0,0,0,0,0,0,0,0,24,0,0,0
0,0,0,0,0,0,4,23,24,0,0,0,25,0,0,0,0,0,0,0,0,0,0,0,0,0,0,0,24,0,0,0
0,0,0,0,0,0,4,23,24,0,0,0,5,0,0,5,0,0,0,0,0,5,0,0,5,0,0,0,24,0,0,0
0,0,0,0,0,0,4,23,24,0,0,0,0,0,0,0,0,0,0,0,0,0,0,0,0,0,0,0,24,0,0,0
0,0,0,0,0,0,4,23,24,0,0,0,0,0,0,0,0,0,0,0,0,0,0,0,0,0,0,0,24,0,0,0
0,0,0,0,0,0,4,23,0,24,0,0,0,0,0,0,0,0,0,0,0,0,0,0,0,0,0,24,0,0,0,0
0,0,0,0,0,0,4,23,0,0,24,0,0,0,0,0,0,0,0,0,0,0,0,0,0,0,24,0,0,0,0,0
0,0,0,0,0,0,4,23,0,0,24,0,0,0,0,0,0,0,0,0,0,0,0,0,0,0,24,0,0,0,0,0
0,0,0,0,0,0,4,23,0,0,24,0,5,0,0,5,0,0,0,0,16,5,0,0,5,0,24,0,0,0,0,0
0,0,0,0,0,0,4,23,0,0,24,0,0,0,0,0,5,0,0,0,5,0,0,0,0,0,24,0,0,0,0,0
0,0,0,0,0,0,4,23,0,0,24,0,0,0,0,0,0,0,0,0,0,0,0,0,0,0,24,0,0,0,0,0
0,0,0,0,0,0,4,23,0,24,0,0,0,0,0,0,0,0,0,0,0,0,0,0,0,0,0,24,0,0,0,0
0,0,0,0,0,0,4,23,24,0,0,0,0,0,0,0,0,0,0,0,0,0,0,0,0,0,0,0,24,0,0,0
0,0,0,0,0,0,4,23,24,0,0,0,5,0,0,3,22,0,0,0,22,3,0,0,5,0,0,0,24,0,0,0
0,0,0,0,0,0,4,23,24,0,0,0,19,0,0,3,24,18,18,18,24,3,0,0,0,0,0,0,24,0,0,0
0,0,0,0,0,0,0,0,24,0,0,0,0,0,0,24,22,0,0,0,22,24,0,0,0,0,0,0,24,0,0,0
0,0,0,0,0,0,0,0,0,24,0,0,0,0,24,0,0,0,0,0,0,0,24,0,0,0,0,24,0,0,0,0
0,0,0,0,0,0,0,0,0,0,24,24,24,24,0,0,0,0,0,0,0,0,0,24,24,24,24,0,0,0,0,0
0,0,0,0,0,0,0,0,0,0,0,0,0,0,0,0,0,0,0,0,0,0,0,0,0,0,0,0,0,0,0,0
0,0,0,0,0,0,0,0,0,0,0,0,0,0,0,0,0,0,0,0,0,0,0,0,0,0,0,0,0,0,0,0
0,0,0,0,0,0,0,0,0,0,0,0,0,0,0,0,0,0,0,0,0,0,0,0,0,0,0,0,0,0,0,0
0,0,0,0,0,0,0,0,0,0,0,0,0,0,0,0,0,0,0,0,0,0,0,0,0,0,0,0,0,0,0,0
0,0,0,0,0,0,0,0,0,0,0,0,0,0,0,0,0,0,0,0,0,0,0,0,0,0,0,0,0,0,0,0
0,0,0,0,0,0,0,0,0,0,0,0,0,0,0,0,0,0,0,0,0,0,0,0,0,0,0,0,0,0,0,0
endlayer

layer
0,0,0,0,0,0,0,0,0,0,0,0,0,0,0,0,0,0,0,0,0,0,0,0,0,0,0,0,0,0,0,0
0,0,0,0,0,0,0,0,0,0,0,0,0,0,0,0,0,0,0,0,0,0,0,0,0,0,0,0,0,0,0,0
0,13,0,0,0,0,0,0,0,0,0,0,0,0,0,0,0,0,0,0,0,0,0,0,0,0,0,0,0,0,0,0
0,0,0,0,0,0,0,0,0,0,3,3,3,3,3,0,0,0,0,0,0,0,3,3,3,3,3,0,0,0,0,0
0,0,0,0,0,0,0,0,0,0,3,3,3,3,3,3,0,0,0,0,0,3,3,3,3,3,3,0,0,0,0,0
0,0,0,0,0,0,0,0,0,3,0,0,0,0,0,3,3,3,3,3,3,3,0,0,0,0,0,3,0,0,0,0
0,0,0,0,0,0,0,0,3,0,0,0,0,0,0,0,3,3,3,3,3,0,0,0,0,0,0,0,3,0,0,0
0,0,0,0,0,0,0,0,3,0,0,0,0,0,0,0,0,0,0,0,0,0,0,0,0,0,0,0,3,0,0,0
0,0,0,0,0,0,0,0,18,0,0,0,5,0,0,5,0,0,0,0,0,5,0,0,5,0,0,0,18,0,0,0
0,0,0,0,0,0,0,0,3,0,0,0,13,0,0,0,0,0,0,0,0,0,0,0,0,0,0,0,3,0,0,0
0,0,0,0,0,0,0,0,3,0,0,0,0,0,0,0,0,0,0,0,0,0,0,0,0,0,0,0,3,0,0,0
0,0,0,0,0,0,0,0,4,3,0,0,0,0,0,0,0,0,0,0,0,0,0,0,0,0,0,3,0,0,0,0
0,0,0,0,0,0,0,0,4,23,3,0,0,0,0,0,0,0,0,0,0,0,0,0,0,0,3,0,0,0,0,0
0,0,0,0,0,0,0,0,4,23,3,0,0,0,0,0,0,0,0,0,0,0,0,0,0,0,3,0,0,0,0,0
0,0,0,0,0,0,0,0,4,23,3,0,5,0,0,5,0,0,0,0,16,5,0,0,5,0,18,0,0,0,0,0
0,0,0,0,0,0,0,0,4,23,3,0,0,0,0,0,5,0,0,0,5,0,0,0,0,0,3,0,0,0,0,0
0,0,0,0,0,0,0,0,4,23,3,0,0,0,0,0,0,0,0,0,0,0,0,0,0,0,3,0,0,0,0,0
0,13,0,0,0,0,0,0,4,3,0,0,0,0,0,0,0,0,0,0,0,0,0,0,0,0,0,3,0,0,0,0
0,0,0,0,0,0,0,0,3,0,0,0,0,0,0,0,0,0,0,0,0,0,0,0,0,0,0,0,3,0,0,0
0,0,0,0,0,0,0,0,3,0,0,0,5,0,0,3,3,0,0,0,3,3,0,0,5,0,0,0,3,0,0,0
0,0,0,0,0,0,0,0,3,0,0,0,0,0,0,3,3,18,18,18,3,3,0,0,0,0,0,0,18,0,0,0
0,0,0,0,0,0,0,0,3,0,0,0,0,0,0,3,26,0,0,0,26,3,0,0,0,0,0,0,3,0,0,0
0,0,0,0,0,0,0,0,0,3,0,13,0,0,3,0,0,0,0,0,0,0,3,0,0,0,0,3,0,0,0,0
0,0,0,0,0,0,0,0,0,0,3,3,18,3,0,0,0,0,0,0,0,0,0,3,18,3,3,0,0,0,0,0
0,0,0,0,0,0,0,0,0,0,0,0,0,0,0,0,0,0,0,0,0,0,0,0,0,0,0,0,0,0,0,0
0,0,0,0,0,0,0,0,0,0,0,0,0,0,0,0,0,0,0,0,0,0,0,0,0,0,0,0,0,0,0,0
0,0,0,0,0,0,0,0,0,0,0,0,0,0,0,0,0,0,0,0,0,0,0,0,0,0,0,0,0,0,0,0
0,0,0,0,0,0,0,0,0,0,0,0,0,0,0,0,0,0,0,0,0,0,0,0,0,0,0,0,0,0,0,0
0,0,0,0,0,0,0,0,0,0,0,0,0,0,0,0,0,0,0,0,0,0,0,0,0,0,0,0,0,0,0,0
0,13,0,0,13,0,0,0,0,0,0,0,0,0,0,0,0,0,0,0,0,0,0,0,0,13,0,0,0,0,0,0
endlayer

layer
0,0,0,0,0,0,0,0,0,0,0,0,0,0,0,0,0,0,0,0,0,0,0,0,0,0,0,0,0,0,0,0
0,0,0,0,0,0,0,0,0,0,0,0,0,0,0,0,0,0,0,0,0,0,0,0,0,0,0,0,0,0,0,0
0,0,0,0,0,0,0,0,0,0,27,0,27,0,27,0,0,0,0,0,0,0,27,0,27,0,27,0,0,0,0,0
0,0,0,0,0,0,0,0,0,0,3,24,24,24,24,27,0,0,0,0,0,27,3,24,24,24,3,0,0,0,0,0
0,0,0,0,0,0,0,0,0,0,3,3,3,3,3,24,27,0,27,0,27,24,3,3,3,3,3,0,0,0,0,0
0,0,0,0,0,0,0,0,0,3,0,0,0,0,0,3,24,24,24,24,24,3,0,0,0,0,0,3,0,0,0,0
0,0,0,0,0,0,0,0,3,0,0,0,0,0,0,0,3,3,3,3,3,0,0,0,0,0,0,0,3,0,0,0
0,0,0,0,0,0,0,0,3,0,0,0,0,0,0,0,0,0,0,0,0,0,0,0,0,0,0,0,3,0,0,0
0,0,0,0,0,0,0,0,3,0,0,0,5,0,0,5,0,0,0,0,0,5,0,0,5,0,0,0,3,0,0,0
0,0,0,0,0,0,0,0,3,0,0,0,0,0,0,0,0,0,0,0,0,0,0,0,0,0,0,0,3,0,0,0
0,0,0,0,0,0,0,0,3,0,0,0,0,0,0,0,0,0,0,0,0,0,0,0,0,0,0,0,3,0,0,0
0,0,0,0,0,0,0,0,0,3,0,0,0,0,0,0,0,0,0,0,0,0,0,0,0,0,0,3,0,0,0,0
0,0,0,0,0,0,0,0,0,0,3,0,0,0,0,0,0,0,0,0,0,0,0,0,0,0,3,0,0,0,0,0
0,0,0,0,0,0,0,0,0,0,3,0,0,0,0,0,0,0,0,0,0,0,0,0,0,0,3,0,0,0,0,0
0,0,0,0,0,0,0,0,0,0,3,0,5,0,0,5,0,0,0,0,16,5,0,0,5,0,3,0,0,0,0,0
0,0,0,0,0,0,0,0,0,0,3,0,0,0,0,0,5,0,0,0,5,0,0,0,0,0,3,0,0,0,0,0
0,0,0,0,0,0,0,0,0,0,3,0,0,0,0,0,0,0,0,0,0,0,0,0,0,0,3,0,0,0,0,0
0,0,0,0,0,0,0,0,0,3,0,0,0,0,0,0,0,0,0,0,0,0,0,0,0,0,0,3,0,0,0,0
0,0,0,0,0,0,0,0,3,0,0,0,0,0,0,0,0,0,0,0,0,0,0,0,0,0,0,0,3,0,0,0
0,0,0,0,0,0,0,0,3,0,0,0,5,0,0,3,3,3,28,3,3,3,0,0,5,0,0,0,3,0,0,0
0,0,0,0,0,0,0,0,3,0,0,0,0,0,0,3,3,18,18,18,3,3,0,0,0,0,0,0,3,0,0,0
0,0,0,0,0,0,0,0,3,0,0,0,0,0,0,3,3,3,28,3,3,3,0,0,0,0,0,0,3,0,0,0
0,0,0,0,0,0,0,0,0,3,0,0,0,0,3,0,0,0,0,0,0,0,3,0,0,0,0,3,0,0,0,0
0,0,0,0,0,0,0,0,0,0,3,3,3,3,0,0,0,0,0,0,0,0,0,3,3,3,3,0,0,0,0,0
0,0,0,0,0,0,0,0,0,0,0,0,0,0,0,0,0,0,0,0,0,0,0,0,0,0,0,0,0,0,0,0
0,0,0,0,0,0,0,0,0,0,0,0,0,0,0,0,0,0,0,0,0,0,0,0,0,0,0,0,0,0,0,0
0,0,0,0,0,0,0,0,0,0,0,0,0,0,0,0,0,0,0,0,0,0,0,0,0,0,0,0,0,0,0,0
0,0,0,0,0,0,0,0,0,0,0,0,0,0,0,0,0,0,0,0,0,0,0,0,0,0,0,0,0,0,0,0
0,0,0,0,0,0,0,0,0,0,0,0,0,0,0,0,0,0,0,0,0,0,0,0,0,0,0,0,0,0,0,0
0,0,0,0,0,0,0,0,0,0,0,0,0,0,0,0,0,0,0,0,0,0,0,0,0,0,0,0,0,0,0,0
endlayer

layer
0,0,0,0,0,0,0,0,0,0,0,0,0,0,0,0,0,0,0,0,0,0,0,0,0,0,0,0,0,0,0,0
0,0,0,0,0,0,0,0,0,0,27,29,27,29,27,0,0,0,0,0,0,0,27,29,27,29,27,0,0,0,0,0
0,0,0,0,0,0,0,0,0,32,31,31,31,31,31,27,0,0,0,0,0,27,31,31,31,31,31,30,0,0,0,0
0,0,0,0,0,0,0,0,0,29,31,31,31,31,31,31,27,29,27,29,27,31,31,31,31,31,31,29,0,0,0,0
0,0,0,0,0,0,0,0,0,32,3,3,3,3,3,31,31,31,31,31,31,31,3,3,3,3,3,30,0,0,0,0
0,0,0,0,0,0,0,0,0,3,0,0,33,0,0,3,31,31,31,31,31,3,0,0,33,0,0,3,0,0,0,0
0,0,0,0,0,0,0,0,3,0,0,0,33,0,0,33,3,3,3,3,3,0,0,0,33,0,0,0,3,0,0,0
0,0,0,0,0,0,0,0,3,0,0,0,33,0,0,33,0,0,0,0,0,0,0,0,33,0,0,0,3,0,0,0
0,0,0,0,0,0,0,0,3,9,9,9,5,9,9,9,9,9,9,9,9,9,9,9,5,9,9,9,3,0,0,0
0,0,0,0,0,0,0,0,3,0,0,0,33,0,0,33,0,0,0,0,0,33,0,0,33,0,0,0,3,0,0,0
0,0,0,0,0,0,0,0,3,0,0,0,33,0,0,33,0,0,0,0,0,33,0,0,33,0,0,0,3,0,0,0
0,0,0,0,0,0,0,0,0,3,0,0,33,0,0,33,0,0,0,0,0,33,0,0,33,0,0,3,0,0,0,0
0,0,0,0,0,0,0,0,0,0,3,0,33,0,0,33,0,0,0,0,0,33,0,0,33,0,3,0,0,0,0,0
0,0,0,0,0,0,0,0,0,0,3,0,33,0,0,33,0,0,0,0,0,33,0,0,33,0,3,0,0,0,0,0
0,0,0,0,0,0,0,0,0,0,3,9,33,9,9,33,0,0,0,0,16,33,9,9,33,9,3,0,0,0,0,0
0,0,0,0,0,0,0,0,0,0,3,0,33,0,0,33,5,0,0,0,5,33,0,0,33,0,3,0,0,0,0,0
0,0,0,0,0,0,0,0,0,0,3,0,33,0,0,33,35,0,0,0,34,33,0,0,33,0,3,0,0,0,0,0
0,0,0,0,0,0,0,0,0,3,0,0,33,0,0,33,35,0,0,0,34,33,0,0,33,0,0,3,0,0,0,0
0,0,0,0,0,0,0,0,3,0,0,0,33,0,0,33,35,36,36,36,34,33,0,0,33,0,0,0,3,0,0,0
0,0,0,0,0,0,0,0,3,9,9,9,33,9,9,9,9,9,9,9,9,9,9,9,33,9,9,9,3,0,0,0
0,0,0,0,0,0,0,0,3,0,0,0,33,0,0,3,3,3,3,3,3,3,0,0,33,0,0,0,3,0,0,0
0,0,0,0,0,0,0,0,3,0,0,0,33,0,0,3,3,3,3,3,3,3,0,0,33,0,0,0,3,0,0,0
0,0,0,0,0,0,0,0,0,3,0,0,33,0,3,0,0,0,0,0,0,0,3,0,33,0,0,3,0,0,0,0
0,0,0,0,0,0,0,0,0,0,3,3,3,3,0,0,0,0,0,0,0,0,0,3,3,3,3,0,0,0,0,0
0,0,0,0,0,0,0,0,0,0,0,0,0,0,0,0,0,0,0,0,0,0,0,0,0,0,0,0,0,0,0,0
0,0,0,0,0,0,0,0,0,0,0,0,0,0,0,0,0,0,0,0,0,0,0,0,0,0,0,0,0,0,0,0
0,0,0,0,0,0,0,0,0,0,0,0,0,0,0,0,0,0,0,0,0,0,0,0,0,0,0,0,0,0,0,0
0,0,0,0,0,0,0,0,0,0,0,0,0,0,0,0,0,0,0,0,0,0,0,0,0,0,0,0,0,0,0,0
0,0,0,0,0,0,0,0,0,0,0,0,0,0,0,0,0,0,0,0,0,0,0,0,0,0,0,0,0,0,0,0
0,0,0,0,0,0,0,0,0,0,0,0,0,0,0,0,0,0,0,0,0,0,0,0,0,0,0,0,0,0,0,0
endlayer

layer
0,0,0,0,0,0,0,0,0,0,0,0,0,0,0,0,0,0,0,0,0,0,0,0,0,0,0,0,0,0,0,0
0,0,0,0,0,0,0,0,0,0,24,22,24,22,24,0,0,0,0,0,0,0,24,22,24,22,24,0,0,0,0,0
0,0,0,0,0,0,0,0,0,24,0,0,0,0,0,24,0,0,0,0,0,24,0,0,0,0,0,24,0,0,0,0
0,0,0,0,0,0,0,0,0,22,0,0,0,0,0,0,24,22,24,22,24,0,0,0,0,0,0,22,0,0,0,0
0,0,0,0,0,0,0,0,0,24,3,37,37,37,3,0,0,0,0,0,0,0,3,37,37,37,3,24,0,0,0,0
0,0,0,0,0,0,0,0,0,3,24,24,24,24,24,3,0,0,0,0,0,3,24,24,24,24,24,3,0,0,0,0
0,0,0,0,0,0,0,0,40,24,24,24,24,24,24,24,3,39,39,39,3,24,24,24,24,24,24,24,38,0,0,0
0,0,0,0,0,0,0,0,4,24,24,24,24,24,24,24,24,24,24,24,24,24,24,24,24,24,24,24,4,0,0,0
0,0,0,0,0,0,0,0,40,24,24,24,5,24,24,24,24,24,24,24,24,24,24,24,5,24,24,24,38,0,0,0
0,0,0,0,0,0,0,0,4,24,24,24,24,24,24,24,24,24,24,24,24,24,24,24,24,24,24,24,4,0,0,0
0,0,0,0,0,0,0,0,40,24,24,24,24,24,24,24,24,24,24,24,24,24,24,24,24,24,24,24,38,0,0,0
0,0,0,0,0,0,0,0,0,40,24,24,24,24,24,24,24,24,24,24,24,24,24,24,24,24,24,38,0,0,0,0
0,0,0,0,0,0,0,0,0,0,40,24,24,24,24,24,24,24,24,24,24,24,24,24,24,24,38,0,0,0,0,0
0,0,0,0,0,0,0,0,0,0,4,24,24,24,24,24,24,24,24,24,24,24,24,24,24,24,4,0,0,0,0,0
0,0,0,0,0,0,0,0,0,0,40,24,24,24,24,24,24,24,24,24,16,24,24,24,24,24,38,0,0,0,0,0
0,0,0,0,0,0,0,0,0,0,4,24,24,24,24,24,24,24,24,24,24,24,24,24,24,24,4,0,0,0,0,0
0,0,0,0,0,0,0,0,0,0,40,24,24,24,24,24,24,24,24,24,24,24,24,24,24,24,38,0,0,0,0,0
0,0,0,0,0,0,0,0,0,40,24,24,24,24,24,24,24,24,24,24,24,24,24,24,24,24,24,38,0,0,0,0
0,0,0,0,0,0,0,0,40,24,24,24,24,24,24,24,24,24,24,24,24,24,24,24,24,24,24,24,38,0,0,0
0,0,0,0,0,0,0,0,4,24,24,24,24,24,24,24,24,24,24,24,24,24,24,24,24,24,24,24,4,0,0,0
0,0,0,0,0,0,0,0,4,24,24,24,24,24,24,24,24,24,24,24,24,24,24,24,24,24,24,24,4,0,0,0
0,0,0,0,0,0,0,0,40,24,24,24,24,24,24,41,4,41,4,41,4,41,24,24,24,24,24,24,38,0,0,0
0,0,0,0,0,0,0,0,0,40,24,24,24,24,38,0,0,0,0,0,0,0,41,24,24,24,24,38,0,0,0,0
0,0,0,0,0,0,0,0,0,0,41,4,4,41,0,0,0,0,0,0,0,0,0,41,4,4,41,0,0,0,0,0
0,0,0,0,0,0,0,0,0,0,0,0,0,0,0,0,0,0,0,0,0,0,0,0,0,0,0,0,0,0,0,0
0,0,0,0,0,0,0,0,0,0,0,0,0,0,0,0,0,0,0,0,0,0,0,0,0,0,0,0,0,0,0,0
0,0,0,0,0,0,0,0,0,0,0,0,0,0,0,0,0,0,0,0,0,0,0,0,0,0,0,0,0,0,0,0
0,0,0,0,0,0,0,0,0,0,0,0,0,0,0,0,0,0,0,0,0,0,0,0,0,0,0,0,0,0,0,0
0,0,0,0,0,0,0,0,0,0,0,0,0,0,0,0,0,0,0,0,0,0,0,0,0,0,0,0,0,0,0,0
0,0,0,0,0,0,0,0,0,0,0,0,0,0,0,0,0,0,0,0,0,0,0,0,0,0,0,0,0,0,0,0
endlayer

layer
0,0,0,0,0,0,0,0,0,0,0,0,0,0,0,0,0,0,0,0,0,0,0,0,0,0,0,0,0,0,0,0
0,0,0,0,0,0,0,0,0,0,22,0,22,0,22,0,0,0,0,0,0,0,22,0,22,0,22,0,0,0,0,0
0,0,0,0,0,0,0,0,0,22,0,0,0,0,0,22,0,0,0,0,0,22,0,0,0,0,0,22,0,0,0,0
0,0,0,0,0,0,0,0,0,0,0,0,0,0,0,0,22,0,22,0,22,0,0,0,0,0,0,0,0,0,0,0
0,0,0,0,0,0,0,0,0,22,3,0,0,0,3,0,0,0,0,0,0,0,3,0,0,0,3,22,0,0,0,0
0,0,0,0,0,0,0,0,0,3,24,24,24,24,24,3,0,0,0,0,0,3,24,24,24,24,24,3,0,0,0,0
0,0,0,0,0,0,0,0,0,24,0,0,0,0,0,24,3,0,0,0,3,24,0,0,0,0,0,24,0,0,0,0
0,0,0,0,0,0,0,0,0,24,0,0,0,0,0,0,24,24,42,24,24,0,0,0,0,0,0,24,0,0,0,0
0,0,0,0,0,0,0,0,0,24,0,0,5,0,0,0,3,0,0,0,3,0,0,0,5,0,0,24,0,0,0,0
0,0,0,0,0,0,0,0,0,24,0,0,0,0,0,0,44,0,0,0,43,0,0,0,0,0,0,24,0,0,0,0
0,0,0,0,0,0,0,0,0,24,0,0,0,0,0,0,3,0,0,0,3,0,0,0,0,0,0,24,0,0,0,0
0,0,0,0,0,0,0,0,0,0,24,0,0,0,0,3,0,0,0,0,5,3,0,0,0,0,24,0,0,0,0,0
0,0,0,0,0,0,0,0,0,0,0,24,0,0,3,0,0,0,0,7,6,6,3,0,0,24,0,0,0,0,0,0
0,0,0,0,0,0,0,0,0,0,0,24,0,0,3,0,0,0,0,0,5,6,3,0,0,24,0,0,0,0,0,0
0,0,0,0,0,0,0,0,0,0,0,24,0,0,3,0,0,0,0,0,0,0,3,0,0,24,0,0,0,0,0,0
0,0,0,0,0,0,0,0,0,0,0,24,0,0,0,3,0,0,0,0,0,3,0,0,0,24,0,0,0,0,0,0
0,0,0,0,0,0,0,0,0,0,0,24,0,0,0,0,3,0,0,0,3,0,0,0,0,24,0,0,0,0,0,0
0,0,0,0,0,0,0,0,0,0,24,0,0,0,0,0,46,0,0,0,45,0,0,0,0,0,24,0,0,0,0,0
0,0,0,0,0,0,0,0,0,24,0,0,0,0,0,0,3,0,0,0,3,0,0,0,0,0,0,24,0,0,0,0
0,0,0,0,0,0,0,0,0,24,0,0,0,0,0,0,5,0,0,0,5,0,0,0,0,0,0,24,0,0,0,0
0,0,0,0,0,0,0,0,0,24,0,0,0,0,0,24,24,24,24,24,24,24,0,0,0,0,0,24,0,0,0,0
0,0,0,0,0,0,0,0,0,24,0,0,0,0,24,0,0,0,0,0,0,0,24,0,0,0,0,24,0,0,0,0
0,0,0,0,0,0,0,0,0,0,24,24,24,24,0,0,0,0,0,0,0,0,0,24,24,24,24,0,0,0,0,0
0,0,0,0,0,0,0,0,0,0,0,0,0,0,0,0,0,0,0,0,0,0,0,0,0,0,0,0,0,0,0,0
0,0,0,0,0,0,0,0,0,0,0,0,0,0,0,0,0,0,0,0,0,0,0,0,0,0,0,0,0,0,0,0
0,0,0,0,0,0,0,0,0,0,0,0,0,0,0,0,0,0,0,0,0,0,0,0,0,0,0,0,0,0,0,0
0,0,0,0,0,0,0,0,0,0,0,0,0,0,0,0,0,0,0,0,0,0,0,0,0,0,0,0,0,0,0,0
0,0,0,0,0,0,0,0,0,0,0,0,0,0,0,0,0,0,0,0,0,0,0,0,0,0,0,0,0,0,0,0
0,0,0,0,0,0,0,0,0,0,0,0,0,0,0,0,0,0,0,0,0,0,0,0,0,0,0,0,0,0,0,0
0,0,0,0,0,0,0,0,0,0,0,0,0,0,0,0,0,0,0,0,0,0,0,0,0,0,0,0,0,0,0,0
endlayer

layer
0,0,0,0,0,0,0,0,0,0,0,0,0,0,0,0,0,0,0,0,0,0,0,0,0,0,0,0,0,0,0,0
0,0,0,0,0,0,0,0,0,0,14,0,14,0,14,0,0,0,0,0,0,0,14,0,14,0,14,0,0,0,0,0
0,0,0,0,0,0,0,0,0,14,0,0,0,0,0,14,0,0,0,0,0,14,0,0,0,0,0,14,0,0,0,0
0,0,0,0,0,0,0,0,0,0,0,0,0,0,0,0,14,0,14,0,14,0,0,0,0,0,0,0,0,0,0,0
0,0,0,0,0,0,0,0,0,14,3,0,0,0,3,0,0,0,0,0,0,0,3,0,0,0,3,14,0,0,0,0
0,0,0,0,0,0,0,0,0,3,24,24,24,24,24,3,0,0,0,0,0,3,24,24,24,24,24,3,0,0,0,0
0,0,0,0,0,0,0,0,0,24,0,19,0,0,0,24,3,0,0,0,3,24,0,0,19,0,0,24,0,0,0,0
0,0,0,0,0,0,0,0,0,24,0,0,0,0,0,0,24,24,47,24,24,0,0,0,0,0,0,24,0,0,0,0
0,0,0,0,0,0,0,0,0,24,0,0,5,0,0,20,3,21,0,0,3,0,0,0,5,0,0,24,0,0,0,0
0,0,0,0,0,0,0,0,0,24,21,0,0,0,0,0,47,0,0,0,47,0,0,0,0,0,20,24,0,0,0,0
0,0,0,0,0,0,0,0,0,24,0,0,0,0,0,0,3,0,0,0,3,0,0,0,0,0,0,24,0,0,0,0
0,0,0,0,0,0,0,0,0,0,24,0,0,0,0,3,0,0,0,0,5,3,0,0,0,0,24,0,0,0,0,0
0,0,0,0,0,0,0,0,0,0,0,24,0,0,3,0,0,0,0,0,7,6,3,0,0,24,0,0,0,0,0,0
0,0,0,0,0,0,0,0,0,0,0,24,0,0,3,21,0,0,0,0,5,6,3,21,0,24,0,0,0,0,0,0
0,0,0,0,0,0,0,0,0,0,0,24,21,0,3,0,0,0,0,0,0,0,3,0,0,24,0,0,0,0,0,0
0,0,0,0,0,0,0,0,0,0,0,24,0,0,0,3,0,0,0,0,0,3,0,0,0,24,0,0,0,0,0,0
0,0,0,0,0,0,0,0,0,0,0,24,0,0,0,0,3,0,0,0,3,0,0,0,0,24,0,0,0,0,0,0
0,0,0,0,0,0,0,0,0,0,24,0,0,0,0,0,47,0,0,0,47,0,0,0,0,0,24,0,0,0,0,0
0,0,0,0,0,0,0,0,0,24,0,0,0,0,0,0,3,21,0,20,3,21,0,0,0,0,0,24,0,0,0,0
0,0,0,0,0,0,0,0,0,24,0,0,0,0,0,0,5,0,0,0,5,0,0,0,0,0,20,24,0,0,0,0
0,0,0,0,0,0,0,0,0,24,21,0,0,0,0,24,24,18,24,24,24,24,0,0,0,0,0,24,0,0,0,0
0,0,0,0,0,0,0,0,0,24,0,0,0,0,24,0,0,0,0,0,0,0,24,0,25,0,0,24,0,0,0,0
0,0,0,0,0,0,0,0,0,0,24,18,24,24,0,0,0,0,0,0,0,0,0,24,24,24,24,0,0,0,0,0
0,0,0,0,0,0,0,0,0,0,0,0,0,0,0,0,0,0,0,0,0,0,0,0,0,0,0,0,0,0,0,0
0,0,0,0,0,0,0,0,0,0,0,0,0,0,0,0,0,0,0,0,0,0,0,0,0,0,0,0,0,0,0,0
0,0,0,0,0,0,0,0,0,0,0,0,0,0,0,0,0,0,0,0,0,0,0,0,0,0,0,0,0,0,0,0
0,0,0,0,0,0,0,0,0,0,0,0,0,0,0,0,0,0,0,0,0,0,0,0,0,0,0,0,0,0,0,0
0,0,0,0,0,0,0,0,0,0,0,0,0,0,0,0,0,0,0,0,0,0,0,0,0,0,0,0,0,0,0,0
0,0,0,0,0,0,0,0,0,0,0,0,0,0,0,0,0,0,0,0,0,0,0,0,0,0,0,0,0,0,0,0
0,0,0,0,0,0,0,0,0,0,0,0,0,0,0,0,0,0,0,0,0,0,0,0,0,0,0,0,0,0,0,0
endlayer

layer
0,0,0,0,0,0,0,0,0,0,0,0,0,0,0,0,0,0,0,0,0,0,0,0,0,0,0,0,0,0,0,0
0,0,0,0,0,0,0,0,0,0,14,0,14,0,14,0,0,0,0,0,0,0,14,0,14,0,14,0,0,0,0,0
0,0,0,0,0,0,0,0,0,14,0,0,0,0,0,14,0,0,0,0,0,14,0,0,0,0,0,14,0,0,0,0
0,0,0,0,0,0,0,0,0,0,0,0,0,0,0,0,14,0,14,0,14,0,0,0,0,0,0,0,0,0,0,0
0,0,0,0,0,0,0,0,0,14,3,0,0,0,3,0,0,0,0,0,0,0,3,0,0,0,3,14,0,0,0,0
0,0,0,0,0,0,0,0,0,3,24,24,24,24,24,3,0,0,0,0,0,3,24,24,24,24,24,3,0,0,0,0
0,0,0,0,0,0,0,0,0,24,0,0,0,0,0,24,3,49,0,48,3,24,0,0,0,0,0,24,0,0,0,0
0,0,0,0,0,0,0,0,0,24,0,0,0,0,0,0,24,24,24,24,24,0,0,0,0,0,0,24,0,0,13,0
0,0,0,0,0,0,0,0,0,24,0,0,5,0,0,0,3,0,0,0,3,0,0,0,5,0,0,24,0,0,0,0
0,0,0,0,0,0,0,0,0,24,0,0,0,0,0,0,3,0,0,0,3,0,0,0,0,0,0,24,0,0,0,0
0,0,0,0,0,0,0,0,0,24,0,0,0,0,0,0,3,0,0,0,3,0,0,0,0,0,0,24,0,0,0,0
0,0,0,0,0,0,0,0,0,0,24,0,0,0,0,3,0,0,0,0,5,3,0,0,0,0,24,0,0,0,0,0
0,0,0,0,0,0,0,0,0,0,0,24,0,0,3,0,0,0,0,0,0,0,3,0,0,24,0,0,0,0,0,0
0,0,0,0,0,0,0,0,0,0,0,24,0,0,3,0,0,0,0,0,5,50,3,0,0,24,0,0,0,0,0,0
0,0,0,0,0,0,0,0,0,0,0,24,0,0,3,0,0,0,0,0,0,0,3,0,0,24,0,0,0,0,0,0
0,0,0,0,0,0,0,0,0,0,0,24,0,0,0,3,0,0,0,0,0,3,0,0,0,24,0,0,0,0,0,0
0,0,0,0,0,0,0,0,0,0,0,24,0,0,0,0,3,0,0,0,3,0,0,0,0,24,0,0,0,0,0,0
0,0,0,0,0,0,0,0,0,0,24,0,0,0,0,0,3,0,0,0,3,0,0,0,0,0,24,0,0,0,0,0
0,0,0,0,0,0,0,0,0,24,0,0,0,0,0,0,3,0,0,0,3,0,0,0,0,0,0,24,0,0,0,0
0,0,0,0,0,0,0,0,0,24,0,0,0,0,0,0,5,0,0,0,5,0,0,0,0,0,0,24,0,0,0,0
0,0,0,0,0,0,0,0,0,24,0,0,0,0,0,24,24,24,24,24,24,24,0,0,0,0,0,24,0,0,0,0
0,0,0,0,0,0,0,0,0,24,0,0,0,0,24,0,0,0,0,0,0,0,24,0,0,0,0,24,0,0,0,0
0,0,0,0,0,0,0,0,0,0,24,24,24,24,0,0,0,0,0,0,0,0,0,24,24,24,24,0,0,0,0,0
0,0,0,0,0,0,0,0,0,0,0,0,0,0,0,0,0,0,0,0,0,0,0,0,0,0,0,0,0,0,0,0
0,0,0,0,0,0,0,0,0,0,0,0,0,0,0,0,0,0,0,0,0,0,0,0,0,0,0,0,0,0,0,0
0,0,0,0,0,0,0,0,0,0,0,0,0,0,0,0,0,0,0,0,0,0,0,0,0,0,0,0,0,0,0,0
0,0,0,0,0,0,0,0,0,0,0,0,0,0,0,0,0,0,0,0,0,0,0,0,0,0,0,0,0,0,0,0
0,0,0,0,0,0,0,0,0,0,0,0,0,0,0,0,0,0,0,0,0,0,0,0,0,0,0,0,0,0,0,0
0,0,0,0,0,0,0,0,0,0,0,0,0,0,0,0,0,0,0,0,0,0,0,0,0,0,0,0,0,0,0,0
0,0,0,0,0,0,0,0,0,0,0,0,0,0,0,0,0,0,0,0,0,0,0,0,0,0,0,0,0,0,0,0
endlayer

layer
0,0,0,0,0,0,0,0,0,0,0,0,0,0,0,0,0,0,0,0,0,0,0,0,0,0,0,0,0,0,0,0
0,0,0,0,0,0,0,0,0,0,4,4,4,4,4,0,0,0,0,0,0,0,4,4,4,4,4,0,0,0,0,0
0,0,0,0,0,0,0,0,0,4,6,6,6,6,6,4,0,0,0,0,0,4,6,6,6,6,6,4,0,0,0,0
0,0,0,0,0,0,0,0,4,6,6,6,6,6,6,6,4,4,4,4,4,6,6,6,6,6,6,6,4,0,0,0
0,0,0,0,0,0,0,0,4,6,3,6,6,6,3,6,6,6,6,6,6,6,3,6,6,6,3,6,4,0,0,0
0,0,0,0,0,0,0,0,4,3,24,24,24,24,24,3,6,6,6,6,6,3,24,24,24,24,24,3,4,0,0,0
0,0,0,0,0,0,0,0,32,24,0,0,0,0,0,24,3,6,6,6,3,24,0,0,0,0,0,24,30,0,0,0
0,0,0,0,0,0,0,0,32,24,0,0,0,0,0,0,24,9,9,9,24,0,0,0,0,0,0,24,30,0,13,0
0,0,0,0,0,0,0,0,32,24,0,0,5,0,0,0,3,6,6,6,3,0,0,0,5,0,0,24,30,0,0,0
0,0,0,0,0,0,0,0,32,24,0,0,0,0,0,0,3,6,6,6,3,0,0,0,0,0,0,24,30,0,0,0
0,0,0,0,0,0,0,0,32,24,0,0,0,0,0,0,3,6,6,6,3,0,0,0,0,0,0,24,30,0,0,0
0,0,0,0,0,0,0,0,0,32,24,0,0,0,0,3,6,6,52,51,5,3,0,0,0,0,24,30,0,0,0,0
0,0,0,0,0,0,0,0,0,0,32,24,0,0,3,6,6,6,52,0,0,0,3,0,0,24,30,0,0,0,0,0
0,0,0,0,0,0,0,0,0,0,32,24,0,0,3,6,6,6,53,53,5,0,3,0,0,24,30,0,0,0,0,0
0,0,0,0,0,0,0,0,0,0,32,24,0,0,3,6,6,6,6,6,6,4,3,0,0,24,30,0,0,0,0,0
0,0,0,0,0,0,0,0,0,0,32,24,0,0,0,3,6,6,6,6,6,3,0,0,0,24,30,0,0,0,0,0
0,0,0,0,0,0,0,0,0,0,32,24,0,0,0,0,3,6,6,6,3,0,0,0,0,24,30,0,0,0,0,0
0,0,0,0,0,0,0,0,0,32,24,0,0,0,0,0,3,31,31,31,3,0,0,0,0,0,24,30,0,0,0,0
0,0,0,0,0,0,0,0,32,24,0,0,0,0,0,0,3,0,0,0,3,0,0,0,0,0,0,24,30,0,0,0
0,0,0,0,0,0,0,0,32,24,0,0,0,0,0,0,5,0,0,0,5,0,0,0,0,0,0,24,30,0,0,0
0,0,0,0,0,0,0,0,32,24,0,0,0,0,0,24,24,24,24,24,24,24,0,0,0,0,0,24,30,0,0,0
0,0,0,0,0,0,0,0,32,24,0,0,0,0,24,54,54,54,54,54,54,54,24,0,0,0,0,24,30,0,0,0
0,0,0,0,0,0,0,0,0,32,24,24,24,24,30,0,0,0,0,0,0,0,32,24,24,24,24,30,0,0,0,0
0,0,0,0,0,0,0,0,0,0,54,54,54,54,0,0,0,0,0,0,0,0,0,54,54,54,54,0,0,0,0,0
0,0,0,0,0,0,0,0,0,0,0,0,0,0,0,0,0,0,0,0,0,0,0,0,0,0,0,0,0,0,0,0
0,0,0,0,0,0,0,0,0,0,0,0,0,0,0,0,0,0,0,0,0,0,0,0,0,0,0,0,0,0,0,0
0,0,0,0,0,0,0,0,0,0,0,0,0,0,0,0,0,0,0,0,0,0,0,0,0,0,0,0,0,0,0,0
0,0,0,0,0,0,0,0,0,0,0,0,0,0,0,0,0,0,0,0,0,0,0,0,0,0,0,0,0,0,0,0
0,0,0,0,0,0,0,0,0,0,0,0,0,0,0,0,0,0,0,0,0,0,0,0,0,0,0,0,0,0,0,0
0,0,0,0,0,0,0,0,0,0,0,0,0,0,0,0,0,0,0,0,0,0,0,0,0,0,0,0,0,0,0,0
endlayer

layer
0,0,0,0,0,0,0,0,0,0,0,0,0,0,0,0,0,0,0,0,0,0,0,0,0,0,0,0,0,0,0,0
0,0,0,0,0,0,0,0,0,0,0,0,0,0,0,0,0,0,0,0,0,0,0,0,0,0,0,0,0,0,0,0
0,0,0,0,0,0,0,0,0,0,0,0,0,0,0,0,0,0,0,0,0,0,0,0,0,0,0,0,0,0,0,0
0,0,0,0,0,0,0,0,0,0,4,4,4,4,4,0,0,0,0,0,0,0,4,4,4,4,4,0,0,0,0,0
0,0,0,0,0,0,0,0,0,0,3,3,3,3,3,4,0,0,0,0,0,4,3,3,3,3,3,0,0,0,0,0
0,0,0,0,0,0,0,0,0,3,31,31,31,31,31,3,4,4,4,4,4,3,31,31,31,31,31,3,0,0,0,0
0,0,0,0,0,0,0,0,3,31,31,31,31,31,31,31,3,3,22,3,3,31,31,31,31,31,31,31,3,0,0,0
0,0,0,0,0,0,0,0,3,31,31,31,31,31,31,31,3,0,0,0,3,31,31,31,31,31,31,31,3,0,0,0
0,0,0,0,0,0,0,0,3,31,31,31,5,31,31,31,8,0,0,0,7,55,31,31,5,31,31,31,3,0,0,0
0,0,0,0,0,0,0,0,3,31,31,31,31,31,31,31,3,0,0,0,3,31,31,31,31,31,31,31,3,0,0,0
0,0,0,0,0,0,0,0,3,31,31,31,31,31,31,31,3,0,0,0,3,31,31,31,31,31,31,31,3,0,0,0
0,0,0,0,0,0,0,0,0,3,31,31,31,31,31,3,0,0,14,14,5,3,31,31,31,31,31,3,0,0,0,0
0,0,0,0,0,0,0,0,0,0,3,31,31,31,3,0,0,0,14,0,0,0,3,31,31,3,3,0,0,0,0,0
0,0,0,0,0,0,0,0,0,0,3,31,31,31,3,0,0,0,14,14,5,0,3,31,31,31,3,0,0,0,0,0
0,0,0,0,0,0,0,0,0,0,3,31,31,31,3,0,0,0,0,0,0,0,3,31,31,31,3,0,0,0,0,0
0,0,0,0,0,0,0,0,0,0,3,31,31,31,31,3,0,0,0,0,0,3,31,31,31,31,3,0,0,0,0,0
0,0,0,0,0,0,0,0,0,0,3,31,31,31,31,31,3,0,0,0,3,31,31,31,31,31,3,0,0,0,0,0
0,0,0,0,0,0,0,0,0,3,31,31,31,31,31,31,3,50,50,50,3,31,31,31,31,31,31,3,0,0,0,0
0,0,0,0,0,0,0,0,3,31,31,31,31,31,31,31,3,31,31,31,3,31,31,31,31,31,31,31,3,0,0,0
0,0,0,0,0,0,0,0,3,31,31,31,31,31,31,31,5,31,31,31,5,31,31,31,31,31,31,31,3,0,0,0
0,0,0,0,0,0,0,0,3,31,31,31,31,31,31,31,31,31,31,31,31,31,31,31,31,31,31,31,3,0,0,0
0,0,0,0,0,0,0,0,3,31,31,31,31,31,31,3,3,3,3,3,3,3,31,31,31,31,31,31,3,0,0,0
0,0,0,0,0,0,0,0,0,3,31,31,31,31,3,0,0,0,0,0,0,0,3,31,31,31,31,3,0,0,0,0
0,0,0,0,0,0,0,0,0,0,3,3,3,3,0,0,0,0,0,0,0,0,0,3,3,3,3,0,0,0,0,0
0,0,0,0,0,0,0,0,0,0,0,0,0,0,0,0,0,0,0,0,0,0,0,0,0,0,0,0,0,0,0,0
0,0,0,0,0,0,0,0,0,0,0,0,0,0,0,0,0,0,0,0,0,0,0,0,0,0,0,0,0,0,0,0
0,0,0,0,0,0,0,0,0,0,0,0,0,0,0,0,0,0,0,0,0,0,0,0,0,0,0,0,0,0,0,0
0,0,0,0,0,0,0,0,0,0,0,0,0,0,0,0,0,0,0,0,0,0,0,0,0,0,0,0,0,0,0,0
0,0,0,0,0,0,0,0,0,0,0,0,0,0,0,0,0,0,0,0,0,0,0,0,0,0,0,0,0,0,0,0
0,0,0,0,0,0,0,0,0,0,0,0,0,0,0,0,0,0,0,0,0,0,0,0,0,0,0,0,0,0,0,0
endlayer

layer
0,0,0,0,0,0,0,0,0,0,0,0,0,0,0,0,0,0,0,0,0,0,0,0,0,0,0,0,0,0,0,0
0,0,0,0,0,0,0,0,0,0,0,0,0,0,0,0,0,0,0,0,0,0,0,0,0,0,0,0,0,0,0,0
0,0,0,0,0,0,0,0,0,0,0,0,0,0,0,0,0,0,0,0,0,0,0,0,0,0,0,0,0,0,0,0
0,0,0,0,0,0,0,0,0,0,0,0,0,0,0,0,0,0,0,0,0,0,0,0,0,0,0,0,0,0,0,0
0,0,0,0,0,0,0,0,0,0,3,3,3,3,3,0,0,0,0,0,0,0,3,3,3,3,3,0,0,0,0,0
0,0,0,0,0,0,0,0,0,3,0,0,0,0,0,3,0,0,0,0,0,3,0,0,0,0,0,3,0,0,0,0
0,0,0,0,0,0,0,0,3,0,0,0,0,0,0,0,3,22,0,22,3,56,0,0,0,0,0,0,3,0,0,0
0,0,0,0,0,0,0,0,3,0,0,0,57,0,0,3,3,0,0,0,3,56,0,0,0,0,0,0,3,0,0,0
0,0,0,0,0,0,0,0,3,0,0,0,5,0,0,45,0,0,0,0,0,0,0,0,5,0,0,0,3,0,0,0
0,0,0,0,0,0,0,0,3,0,0,0,0,0,0,3,3,0,0,0,3,46,0,0,0,0,0,0,3,0,0,0
0,0,0,0,0,0,0,0,3,0,0,0,0,0,0,0,3,0,0,20,3,3,0,0,37,0,0,0,3,0,0,0
0,0,0,0,0,0,0,0,0,3,0,0,0,0,0,3,0,0,0,0,58,3,3,3,0,3,0,3,0,0,0,0
0,0,0,0,0,0,0,0,0,32,3,3,3,3,3,0,0,0,0,0,0,0,3,3,3,3,3,30,0,0,0,0
0,0,0,0,0,0,0,0,0,23,3,0,0,0,3,21,0,0,0,0,58,0,3,0,0,0,3,23,0,0,0,0
0,0,0,0,0,0,0,0,0,32,3,0,0,0,3,0,0,0,0,0,0,0,3,0,0,0,3,30,0,0,0,0
0,0,0,0,0,0,0,0,0,23,3,0,0,0,0,3,0,0,0,0,0,3,0,0,0,0,3,23,0,0,0,0
0,0,0,0,0,0,0,0,0,27,3,0,0,0,0,0,3,0,0,0,3,0,0,0,0,0,3,27,0,0,0,0
0,0,0,0,0,0,0,0,32,3,0,0,0,0,0,0,3,0,0,0,3,0,0,0,0,0,0,3,30,0,0,0
0,0,0,0,0,0,0,32,3,0,0,0,0,0,0,0,3,50,50,50,3,0,0,0,0,0,0,0,3,30,0,0
0,0,0,0,0,0,0,23,3,0,0,0,0,0,0,0,5,0,31,31,5,0,0,0,0,0,0,0,3,23,0,0
0,0,0,0,0,0,0,23,3,0,0,0,0,0,0,0,0,0,0,0,0,0,0,0,0,0,0,0,3,23,0,0
0,0,0,0,0,0,0,32,3,0,0,0,0,0,0,3,3,3,3,3,3,3,0,0,0,0,0,0,3,30,0,0
0,0,0,0,0,0,0,0,32,3,0,0,0,0,3,30,23,54,23,54,23,32,3,0,0,0,0,3,30,0,0,0
0,0,0,0,0,0,0,0,0,54,3,3,3,3,54,0,0,0,0,0,0,0,54,3,3,3,3,54,0,0,0,0
0,0,0,0,0,0,0,0,0,0,54,23,23,54,0,0,0,0,0,0,0,0,0,54,23,23,54,0,0,0,0,0
0,0,0,0,0,0,0,0,0,0,0,0,0,0,0,0,0,0,0,0,0,0,0,0,0,0,0,0,0,0,0,0
0,0,0,0,0,0,0,0,0,0,0,0,0,0,0,0,0,0,0,0,0,0,0,0,0,0,0,0,0,0,0,0
0,0,0,0,0,0,0,0,0,0,0,0,0,0,0,0,0,0,0,0,0,0,0,0,0,0,0,0,0,0,0,0
0,0,0,0,0,0,0,0,0,0,0,0,0,0,0,0,0,0,0,0,0,0,0,0,0,0,0,0,0,0,0,0
0,0,0,0,0,0,0,0,0,0,0,0,0,0,0,0,0,0,0,0,0,0,0,0,0,0,0,0,0,0,0,0
endlayer

layer
0,0,0,0,0,0,0,0,0,0,0,0,0,0,0,0,0,0,0,0,0,0,0,0,0,0,0,0,0,0,0,0
0,0,0,0,0,0,0,0,0,0,0,0,0,0,0,0,0,0,0,0,0,0,0,0,0,0,0,0,0,0,0,0
0,0,0,0,0,0,0,0,0,0,0,0,0,0,0,0,0,0,0,0,0,0,0,0,0,0,0,0,0,0,0,0
0,0,0,0,0,0,0,0,0,0,0,0,0,0,0,0,0,0,0,0,0,0,0,0,0,0,0,0,0,0,0,0
0,0,0,0,0,0,0,0,0,0,3,3,18,3,3,0,0,0,0,0,0,0,3,3,18,3,3,0,0,0,0,0
0,0,0,0,0,0,0,0,0,3,0,0,0,0,0,3,0,0,0,0,0,3,0,0,0,0,0,3,0,0,0,0
0,0,0,0,0,0,0,0,3,0,0,0,0,0,0,0,3,22,0,22,3,0,0,0,0,0,0,0,3,0,0,0
0,0,0,0,0,0,0,0,3,0,0,0,57,0,0,3,3,0,0,0,3,0,0,0,25,0,0,0,3,0,0,0
0,0,0,0,0,0,0,0,18,0,0,20,5,0,0,47,0,0,0,0,0,0,0,0,5,21,0,0,18,0,0,0
0,0,0,0,0,0,0,0,3,0,0,0,0,0,0,3,3,0,0,0,3,47,0,0,0,0,0,0,3,0,0,0
0,0,0,0,0,0,0,0,3,0,0,0,0,0,0,0,3,0,0,0,3,3,0,0,0,0,0,0,3,0,0,0
0,0,0,0,0,0,0,0,0,3,0,0,0,0,0,3,0,0,0,0,0,3,3,3,37,3,0,3,0,0,0,0
0,0,0,0,0,0,0,0,0,3,3,3,3,3,3,0,0,0,0,0,0,0,3,3,3,3,3,3,0,0,0,0
0,0,0,0,0,0,0,0,0,48,31,31,31,31,3,0,0,0,0,0,0,0,3,31,31,31,31,49,0,0,0,0
0,0,0,0,0,0,0,0,0,3,31,31,31,31,3,0,0,0,0,0,0,0,3,31,31,31,31,3,0,0,0,0
0,0,0,0,0,0,0,0,0,48,31,31,31,31,31,3,0,0,0,0,0,3,31,31,31,31,31,49,0,0,0,0
0,0,0,0,0,0,0,0,0,3,31,31,31,31,31,31,3,0,0,0,3,31,31,31,31,31,31,3,0,0,0,0
0,0,0,0,0,0,0,0,3,31,31,31,31,31,31,31,30,0,0,0,32,31,31,31,31,31,31,31,3,0,0,0
0,0,0,0,0,0,0,3,31,31,31,31,31,31,31,31,30,0,0,0,32,31,31,31,31,31,31,31,31,3,0,0
0,0,0,0,0,0,0,48,31,31,31,31,31,31,31,31,24,50,50,50,24,31,31,31,31,31,31,31,31,49,0,0
0,0,0,0,0,0,0,48,31,31,31,31,31,31,31,31,31,31,31,31,31,31,31,31,31,31,6,31,31,49,0,0
0,0,0,0,0,0,0,3,31,31,31,31,31,31,31,31,31,31,31,31,31,31,31,31,31,31,31,31,31,3,0,0
0,0,0,0,0,0,0,0,3,31,31,31,31,31,31,3,59,3,59,3,59,3,31,31,31,31,31,31,3,0,0,0
0,0,0,0,0,0,0,0,0,3,31,31,31,31,3,0,0,0,0,0,0,0,3,31,31,31,31,3,0,0,0,0
0,0,0,0,0,0,0,0,0,0,3,59,59,3,0,0,0,0,0,0,0,0,0,3,59,59,3,0,0,0,0,0
0,0,0,0,0,0,0,0,0,0,0,0,0,0,0,0,0,0,0,0,0,0,0,0,0,0,0,0,0,0,0,0
0,0,0,0,0,0,0,0,0,0,0,0,0,0,0,0,0,0,0,0,0,0,0,0,0,0,0,0,0,0,0,0
0,0,0,0,0,0,0,0,0,0,0,0,0,0,0,0,0,0,0,0,0,0,0,0,0,0,0,0,0,0,0,0
0,0,0,0,0,0,0,0,0,0,0,0,0,0,0,0,0,0,0,0,0,0,0,0,0,0,0,0,0,0,0,0
0,0,0,0,0,0,0,0,0,0,0,0,0,0,0,0,0,0,0,0,0,0,0,0,0,0,0,0,0,0,0,0
endlayer

layer
0,0,0,0,0,0,0,0,0,0,0,0,0,0,0,0,0,0,0,0,0,0,0,0,0,0,0,0,0,0,0,0
0,0,0,0,0,0,0,0,0,0,0,0,0,0,0,0,0,0,0,0,0,0,0,0,0,0,0,0,0,0,0,0
0,0,0,0,0,0,0,0,0,0,0,0,0,0,0,0,0,0,0,0,0,0,0,0,0,0,0,0,0,0,0,0
0,0,0,0,0,0,0,0,0,0,0,0,0,0,0,0,0,0,0,0,0,0,0,0,0,0,0,0,0,0,0,0
0,0,0,0,0,0,0,0,0,0,3,3,3,3,3,0,0,0,0,0,0,0,3,3,3,3,3,0,0,0,0,0
0,0,0,0,0,0,0,0,0,3,54,54,54,54,54,3,0,0,0,0,0,3,54,54,54,54,54,3,0,0,0,0
0,0,0,0,0,0,0,0,3,30,0,0,0,0,0,32,3,22,0,22,3,30,0,0,0,0,0,32,3,0,0,0
0,0,0,0,0,0,0,0,3,30,0,0,57,0,0,3,3,0,0,0,3,30,0,0,0,0,0,32,3,0,0,0
0,0,0,0,0,0,0,0,3,30,0,0,5,0,0,32,3,0,0,0,3,3,0,0,5,0,0,32,3,0,0,0
0,0,0,0,0,0,0,0,3,30,0,0,0,0,0,3,3,0,0,0,3,30,0,0,0,0,0,32,3,0,0,0
0,0,0,0,0,0,0,0,3,30,0,0,0,0,0,32,3,0,0,0,3,3,0,0,0,0,0,32,3,0,0,0
0,0,0,0,0,0,0,0,0,3,27,27,27,27,27,3,0,0,0,0,0,3,3,3,0,3,27,3,0,0,0,0
0,0,0,0,0,0,0,0,0,3,3,3,3,3,3,30,0,0,0,0,0,32,3,3,60,3,3,3,0,0,0,0
0,0,0,0,0,0,0,0,0,22,0,3,0,0,3,30,0,0,0,0,0,32,3,0,0,0,0,22,0,0,0,0
0,0,0,0,0,0,0,0,0,3,0,0,0,0,3,30,0,0,0,0,0,32,3,0,0,0,0,3,0,0,0,0
0,0,0,0,0,0,0,0,0,22,0,0,0,0,0,3,30,0,0,0,32,3,0,0,0,0,0,22,0,0,0,0
0,0,0,0,0,0,0,0,0,3,0,0,0,0,0,0,3,30,0,32,3,3,0,0,0,0,0,3,0,0,0,0
0,0,0,0,0,0,0,0,3,0,0,0,0,0,0,0,22,0,0,0,22,0,0,0,0,0,0,0,3,0,0,0
0,0,0,0,0,0,0,3,0,0,0,0,0,0,0,0,22,0,0,0,22,0,0,0,0,0,0,0,0,3,0,0
0,0,0,0,0,0,0,22,0,0,0,0,0,0,0,0,24,0,0,0,24,0,0,0,0,0,0,0,0,22,0,0
0,0,0,0,0,0,0,22,0,0,0,0,0,0,0,0,0,0,0,0,0,0,0,0,0,0,0,0,0,22,0,0
0,0,0,0,0,0,0,3,0,0,0,0,0,0,0,0,0,0,0,0,0,0,0,0,0,0,0,0,0,3,0,0
0,0,0,0,0,0,0,0,3,0,0,0,0,0,0,3,22,3,22,3,22,3,0,0,0,0,0,0,3,0,0,0
0,0,0,0,0,0,0,0,0,3,0,0,0,0,3,0,0,0,0,0,0,0,3,0,0,0,0,3,0,0,0,0
0,0,0,0,0,0,0,0,0,0,3,22,22,3,0,0,0,0,0,0,0,0,0,3,22,22,3,0,0,0,0,0
0,0,0,0,0,0,0,0,0,0,0,0,0,0,0,0,0,0,0,0,0,0,0,0,0,0,0,0,0,0,0,0
0,0,0,0,0,0,0,0,0,0,0,0,0,0,0,0,0,0,0,0,0,0,0,0,0,0,0,0,0,0,0,0
0,0,0,0,0,0,0,0,0,0,0,0,0,0,0,0,0,0,0,0,0,0,0,0,0,0,0,0,0,0,0,0
0,0,0,0,0,0,0,0,0,0,0,0,0,0,0,0,0,0,0,0,0,0,0,0,0,0,0,0,0,0,0,0
0,0,0,0,0,0,0,0,0,0,0,0,0,0,0,0,0,0,0,0,0,0,0,0,0,0,0,0,0,0,0,0
endlayer

layer
0,0,0,0,0,0,0,0,0,0,0,0,0,0,0,0,0,0,0,0,0,0,0,0,0,0,0,0,0,0,0,0
0,0,0,0,0,0,0,0,0,0,0,0,0,0,0,0,0,0,0,0,0,0,0,0,0,0,0,0,0,0,0,0
0,0,0,0,0,0,0,0,0,0,0,0,0,0,0,0,0,0,0,0,0,0,0,0,0,0,0,0,0,0,0,0
0,0,0,0,0,0,0,0,0,0,0,0,0,0,0,0,0,0,0,0,0,0,0,0,0,0,0,0,0,0,0,0
0,0,0,0,0,0,0,0,0,0,3,3,3,3,3,0,0,0,0,0,0,0,37,37,37,37,37,0,0,0,0,0
0,0,0,0,0,0,0,0,0,3,3,3,3,3,3,38,0,0,0,0,0,40,3,3,3,3,3,38,0,0,0,0
0,0,0,0,0,0,0,0,3,3,0,0,0,0,0,3,0,22,0,22,0,3,0,0,0,0,0,3,38,0,0,0
0,0,0,0,0,0,0,0,3,3,0,0,57,0,0,3,0,0,0,0,0,3,0,0,0,0,0,3,38,0,0,0
0,0,0,0,0,0,0,0,3,3,0,0,5,0,0,3,0,0,0,0,0,3,0,0,5,0,0,3,38,0,0,0
0,0,0,0,0,0,0,0,3,3,0,0,0,0,0,3,0,0,0,0,0,3,0,0,0,0,0,3,38,0,0,0
0,0,0,0,0,0,0,0,3,3,0,0,0,0,0,3,0,0,0,0,0,3,0,0,0,0,0,3,38,0,0,0
0,0,0,0,0,0,0,0,0,3,3,3,3,3,3,3,0,0,0,0,0,3,3,3,0,3,3,38,0,0,0,0
0,0,0,0,0,0,0,0,0,0,3,3,41,41,41,3,0,0,0,0,0,3,38,41,47,41,41,14,0,0,0,0
0,0,0,0,0,0,0,0,0,0,0,3,0,0,40,3,0,0,0,0,0,3,38,0,0,0,0,0,0,0,0,0
0,0,0,0,0,0,0,0,0,0,0,0,0,0,40,3,0,0,0,0,0,3,38,0,0,0,0,14,0,0,0,0
0,0,0,0,0,0,0,0,0,0,0,0,0,0,0,40,3,3,3,3,3,38,0,0,0,0,0,0,0,0,0,0
0,0,0,0,0,0,0,0,0,0,0,0,0,0,0,0,41,3,41,3,41,14,0,0,0,0,0,14,0,0,0,0
0,0,0,0,0,0,0,0,0,0,0,0,0,0,0,0,0,0,0,0,0,0,0,0,0,0,0,0,0,0,0,0
0,0,0,0,0,0,0,0,0,0,0,0,0,0,0,0,0,0,0,0,0,0,0,0,0,0,0,0,0,0,0,0
0,0,0,0,0,0,0,0,0,0,0,0,0,0,0,0,61,0,0,0,61,0,0,0,0,0,0,0,0,0,0,0
0,0,0,0,0,0,0,0,0,0,0,0,0,0,0,0,0,0,0,0,0,0,0,0,0,0,0,0,0,0,0,0
0,0,0,0,0,0,0,0,0,0,0,0,0,0,0,0,0,0,0,0,0,0,0,0,0,0,0,0,0,0,0,0
0,0,0,0,0,0,0,0,0,0,0,0,0,0,0,0,0,0,0,0,0,0,0,0,0,0,0,0,0,0,0,0
0,0,0,0,0,0,0,0,0,0,0,0,0,0,0,0,0,0,0,0,0,0,0,0,0,0,0,0,0,0,0,0
0,0,0,0,0,0,0,0,0,0,0,0,0,0,0,0,0,0,0,0,0,0,0,0,0,0,0,0,0,0,0,0
0,0,0,0,0,0,0,0,0,0,0,0,0,0,0,0,0,0,0,0,0,0,0,0,0,0,0,0,0,0,0,0
0,0,0,0,0,0,0,0,0,0,0,0,0,0,0,0,0,0,0,0,0,0,0,0,0,0,0,0,0,0,0,0
0,0,0,0,0,0,0,0,0,0,0,0,0,0,0,0,0,0,0,0,0,0,0,0,0,0,0,0,0,0,0,0
0,0,0,0,0,0,0,0,0,0,0,0,0,0,0,0,0,0,0,0,0,0,0,0,0,0,0,0,0,0,0,0
0,0,0,0,0,0,0,0,0,0,0,0,0,0,0,0,0,0,0,0,0,0,0,0,0,0,0,0,0,0,0,0
endlayer

layer
0,0,0,0,0,0,0,0,0,0,0,0,0,0,0,0,0,0,0,0,0,0,0,0,0,0,0,0,0,0,0,0
0,0,0,0,0,0,0,0,0,0,0,0,0,0,0,0,0,0,0,0,0,0,0,0,0,0,0,0,0,0,0,0
0,0,0,0,0,0,0,0,0,0,0,0,0,0,0,0,0,0,0,0,0,0,0,0,0,0,0,0,0,0,0,0
0,0,0,0,0,0,0,0,0,28,0,27,0,27,0,28,0,0,0,0,0,0,0,0,0,0,0,0,0,0,0,0
0,0,0,0,0,0,0,0,0,28,3,3,3,3,3,28,0,0,0,0,0,0,27,27,27,27,27,0,0,0,0,0
0,0,0,0,0,0,0,28,28,3,3,3,3,3,3,3,28,28,0,0,0,32,3,3,3,3,3,30,0,0,0,0
0,0,0,0,0,0,0,0,3,3,0,0,0,0,0,3,0,3,27,3,0,3,0,0,0,0,0,3,30,0,0,0
0,0,0,0,0,0,0,32,3,3,0,0,57,0,0,3,0,31,31,31,0,3,0,0,0,0,0,3,30,0,0,0
0,0,0,0,0,0,0,0,3,3,0,0,5,0,0,3,0,31,31,31,0,3,0,0,5,0,0,3,30,0,0,0
0,0,0,0,0,0,0,32,3,3,0,0,0,0,0,3,0,31,31,31,0,3,0,0,0,0,0,3,30,0,0,0
0,0,0,0,0,0,0,0,3,3,0,0,0,0,0,3,0,31,31,31,0,3,0,0,0,0,0,3,30,0,0,0
0,0,0,0,0,0,0,28,28,3,3,3,3,3,3,3,31,31,31,31,31,3,3,3,3,3,3,30,0,0,0,0
0,0,0,0,0,0,0,0,0,28,3,3,54,54,54,0,31,31,31,31,31,0,54,54,54,54,54,14,0,0,0,0
0,0,0,0,0,0,0,0,0,28,0,3,0,0,32,0,31,31,31,31,31,0,30,0,0,0,0,0,0,0,0,0
0,0,0,0,0,0,0,0,0,0,0,0,0,0,32,0,31,31,31,31,31,0,30,0,0,0,0,14,0,0,0,0
0,0,0,0,0,0,0,0,0,0,0,0,0,0,0,32,0,0,0,0,0,3,23,23,23,23,23,23,0,0,0,0
0,0,0,0,0,0,0,0,0,0,0,0,0,0,0,0,54,24,54,24,54,4,4,4,4,4,4,4,0,0,0,0
0,0,0,0,0,0,0,0,0,0,0,0,0,0,0,0,0,0,0,0,0,0,0,0,0,0,0,0,0,0,0,0
0,0,0,0,0,0,0,0,0,0,0,0,0,0,0,0,0,0,0,0,0,0,0,0,0,0,0,0,0,0,0,0
0,0,0,0,0,0,0,0,0,0,0,0,0,0,0,0,0,0,0,0,0,0,0,0,0,0,0,0,0,0,0,0
0,0,0,0,0,0,0,0,0,0,0,0,0,0,0,0,0,0,0,0,0,0,0,0,0,0,0,0,0,0,0,0
0,0,0,0,0,0,0,0,0,0,0,0,0,0,0,0,0,0,0,0,0,0,0,0,0,0,0,0,0,0,0,0
0,0,0,0,0,0,0,0,0,0,0,0,0,0,0,0,0,0,0,0,0,0,0,0,0,0,0,0,0,0,0,0
0,0,0,0,0,0,0,0,0,0,0,0,0,0,0,0,0,0,0,0,0,0,0,0,0,0,0,0,0,0,0,0
0,0,0,0,0,0,0,0,0,0,0,0,0,0,0,0,0,0,0,0,0,0,0,0,0,0,0,0,0,0,0,0
0,0,0,0,0,0,0,0,0,0,0,0,0,0,0,0,0,0,0,0,0,0,0,0,0,0,0,0,0,0,0,0
0,0,0,0,0,0,0,0,0,0,0,0,0,0,0,0,0,0,0,0,0,0,0,0,0,0,0,0,0,0,0,0
0,0,0,0,0,0,0,0,0,0,0,0,0,0,0,0,0,0,0,0,0,0,0,0,0,0,0,0,0,0,0,0
0,0,0,0,0,0,0,0,0,0,0,0,0,0,0,0,0,0,0,0,0,0,0,0,0,0,0,0,0,0,0,0
0,0,0,0,0,0,0,0,0,0,0,0,0,0,0,0,0,0,0,0,0,0,0,0,0,0,0,0,0,0,0,0
endlayer

layer
0,0,0,0,0,0,0,0,0,0,0,0,0,0,0,0,0,0,0,0,0,0,0,0,0,0,0,0,0,0,0,0
0,0,0,0,0,0,0,0,0,0,0,0,0,0,0,0,0,0,0,0,0,0,0,0,0,0,0,0,0,0,0,0
0,0,0,0,0,0,0,0,0,27,23,27,23,27,23,27,0,0,0,0,0,0,0,0,0,0,0,0,0,0,0,0
0,0,0,0,0,0,0,0,27,31,31,31,31,31,31,31,27,0,0,0,0,0,0,0,0,0,0,0,0,0,0,0
0,0,0,0,0,0,0,32,31,31,3,3,3,3,3,31,31,30,0,0,0,0,3,3,3,3,3,0,0,0,0,0
0,0,0,0,0,0,32,31,31,3,0,0,0,0,0,3,31,4,30,27,27,3,3,3,3,3,3,3,0,0,0,0
0,0,0,0,0,0,23,31,3,0,0,0,0,0,0,0,3,4,4,4,3,3,0,0,0,0,0,3,3,0,0,0
0,0,0,0,0,0,32,31,3,0,0,0,57,0,0,0,3,0,0,0,3,3,0,0,0,0,0,3,3,0,0,0
0,0,0,0,0,0,23,31,3,0,0,0,5,0,0,0,0,0,0,0,0,0,0,0,5,0,0,3,3,0,0,0
0,0,0,0,0,0,32,31,3,0,0,0,0,0,0,0,3,0,0,0,3,3,0,0,0,0,0,3,3,0,0,0
0,0,0,0,0,0,23,31,3,0,0,0,0,0,0,0,3,0,0,0,3,3,0,0,0,0,0,3,3,0,0,0
0,0,0,0,0,0,32,31,31,3,0,0,0,0,0,3,0,0,0,0,0,3,3,3,3,3,3,3,0,0,0,0
0,0,0,0,0,0,0,32,31,31,3,3,3,3,3,62,0,0,0,0,0,62,3,3,3,3,3,14,0,0,0,0
0,0,0,0,0,0,0,0,54,31,31,31,31,31,31,4,0,0,0,0,0,62,3,23,23,23,23,23,0,0,0,0
0,0,0,0,0,0,0,0,0,54,23,54,23,32,24,62,0,0,0,0,0,62,0,4,4,4,4,4,0,0,0,0
0,0,0,0,0,0,0,0,0,0,0,0,0,0,32,24,62,62,62,62,62,24,30,0,0,0,0,0,0,0,0,0
0,0,0,0,0,0,0,0,0,0,0,0,0,0,0,54,24,24,0,0,0,54,0,0,0,0,0,0,0,0,0,0
0,0,0,0,0,0,0,0,0,0,0,0,0,0,0,0,54,23,54,23,54,0,0,0,0,0,0,0,0,0,0,0
0,0,0,0,0,0,0,0,0,0,0,0,0,0,0,0,0,0,0,0,0,0,0,0,0,0,0,0,0,0,0,0
0,0,0,0,0,0,0,0,0,0,0,0,0,0,0,0,0,0,0,0,0,0,0,0,0,0,0,0,0,0,0,0
0,0,0,0,0,0,0,0,0,0,0,0,0,0,0,0,0,0,0,0,0,0,0,0,0,0,0,0,0,0,0,0
0,0,0,0,0,0,0,0,0,0,0,0,0,0,0,0,0,0,0,0,0,0,0,0,0,0,0,0,0,0,0,0
0,0,0,0,0,0,0,0,0,0,0,0,0,0,0,0,0,0,0,0,0,0,0,0,0,0,0,0,0,0,0,0
0,0,0,0,0,0,0,0,0,0,0,0,0,0,0,0,0,0,0,0,0,0,0,0,0,0,0,0,0,0,0,0
0,0,0,0,0,0,0,0,0,0,0,0,0,0,0,0,0,0,0,0,0,0,0,0,0,0,0,0,0,0,0,0
0,0,0,0,0,0,0,0,0,0,0,0,0,0,0,0,0,0,0,0,0,0,0,0,0,0,0,0,0,0,0,0
0,0,0,0,0,0,0,0,0,0,0,0,0,0,0,0,0,0,0,0,0,0,0,0,0,0,0,0,0,0,0,0
0,0,0,0,0,0,0,0,0,0,0,0,0,0,0,0,0,0,0,0,0,0,0,0,0,0,0,0,0,0,0,0
0,0,0,0,0,0,0,0,0,0,0,0,0,0,0,0,0,0,0,0,0,0,0,0,0,0,0,0,0,0,0,0
0,0,0,0,0,0,0,0,0,0,0,0,0,0,0,0,0,0,0,0,0,0,0,0,0,0,0,0,0,0,0,0
endlayer

layer
0,0,0,0,0,0,0,0,0,0,0,0,0,0,0,0,0,0,0,0,0,0,0,0,0,0,0,0,0,0,0,0
0,0,0,0,0,0,0,0,0,0,0,0,0,0,0,0,0,0,0,0,0,0,0,0,0,0,0,0,0,0,0,0
0,0,0,0,0,0,0,0,0,3,22,3,22,3,22,3,0,0,0,0,0,0,0,0,0,0,0,0,0,0,0,0
0,0,0,0,0,0,0,0,3,0,0,0,0,0,0,0,3,0,0,0,0,0,0,0,0,0,0,0,0,0,0,0
0,0,0,0,0,0,0,3,0,0,3,3,3,3,3,0,0,3,0,0,0,0,3,3,3,3,3,0,0,0,0,0
0,0,0,0,0,0,3,0,0,3,0,0,0,0,0,3,0,0,3,22,3,3,63,63,63,63,63,3,0,0,0,0
0,0,0,0,0,0,22,0,3,0,0,0,0,0,0,0,3,0,0,0,3,63,63,63,63,63,63,63,3,0,0,0
0,0,0,0,0,0,3,0,3,0,0,0,57,0,0,0,3,0,0,0,3,63,63,63,63,63,63,63,3,0,0,0
0,0,0,0,0,0,22,0,3,0,0,0,5,0,0,0,0,0,0,0,0,0,0,0,5,63,63,63,3,0,0,0
0,0,0,0,0,0,3,0,3,0,0,0,0,0,0,0,3,0,0,0,3,63,63,63,63,63,63,63,3,0,0,0
0,0,0,0,0,0,22,0,3,0,0,0,0,0,0,0,3,0,0,0,3,63,63,63,63,63,63,63,3,0,0,0
0,0,0,0,0,0,3,0,0,3,0,0,0,0,0,3,0,0,0,0,0,3,63,63,3,3,3,3,0,0,0,0
0,0,0,0,0,0,0,3,0,0,3,3,3,3,3,0,0,0,0,0,0,0,3,3,41,3,3,4,0,0,0,0
0,0,0,0,0,0,0,0,3,0,0,0,0,0,0,0,0,0,0,0,0,0,0,22,0,0,0,0,0,0,0,0
0,0,0,0,0,0,0,0,0,3,22,3,22,3,0,0,0,0,0,0,0,0,0,3,0,0,0,0,0,0,0,0
0,0,0,0,0,0,0,0,0,0,0,0,0,0,3,0,0,0,0,0,0,0,3,0,0,0,0,0,0,0,0,0
0,0,0,0,0,0,0,0,0,0,0,0,0,0,0,3,0,0,0,0,0,3,0,0,0,0,0,0,0,0,0,0
0,0,0,0,0,0,0,0,0,0,0,0,0,0,0,0,3,22,3,22,3,0,0,0,0,0,0,0,0,0,0,0
0,0,0,0,0,0,0,0,0,0,0,0,0,0,0,0,0,0,0,0,0,0,0,0,0,0,0,0,0,0,0,0
0,0,0,0,0,0,0,0,0,0,0,0,0,0,0,0,0,0,0,0,0,0,0,0,0,0,0,0,0,0,0,0
0,0,0,0,0,0,0,0,0,0,0,0,0,0,0,0,0,0,0,0,0,0,0,0,0,0,0,0,0,0,0,0
0,0,0,0,0,0,0,0,0,0,0,0,0,0,0,0,0,0,0,0,0,0,0,0,0,0,0,0,0,0,0,0
0,0,0,0,0,0,0,0,0,0,0,0,13,0,0,0,0,0,0,0,0,0,0,0,0,0,0,0,13,0,0,0
0,0,0,0,0,0,0,0,0,0,0,0,0,0,0,0,0,0,0,0,0,0,0,0,0,0,0,0,0,0,0,0
0,0,0,0,0,0,0,0,0,0,0,0,0,0,0,0,0,0,0,0,0,0,0,0,0,0,0,0,0,0,0,0
0,0,0,0,0,0,0,0,0,0,0,0,0,0,0,0,0,0,0,0,0,0,0,0,0,0,0,0,0,0,0,0
0,0,0,0,0,0,0,0,0,0,0,0,0,0,0,0,0,0,0,0,0,0,0,0,0,0,0,13,0,0,0,0
0,0,0,0,0,0,0,0,0,0,0,0,0,0,0,0,0,0,0,0,0,0,0,0,0,0,0,0,0,0,0,0
0,0,0,0,0,0,0,0,0,0,0,0,0,0,0,0,0,0,0,0,0,0,0,0,0,0,0,0,0,0,0,0
0,0,0,0,0,0,0,0,0,0,0,0,13,0,0,0,0,0,0,0,0,0,0,0,0,0,0,0,0,0,0,0
endlayer

layer
0,0,0,0,0,0,0,0,0,0,0,0,0,0,0,0,0,0,0,0,0,0,0,0,0,0,0,0,0,0,0,0
0,0,0,0,0,0,0,0,0,0,0,0,0,0,0,0,0,0,0,0,0,0,0,0,0,0,0,0,0,0,0,0
0,0,0,0,0,0,0,0,0,0,0,0,0,0,0,0,0,0,0,0,0,0,0,0,0,0,0,0,0,0,0,0
0,0,0,0,0,0,0,0,0,0,0,0,0,0,0,0,0,0,0,0,0,0,0,0,0,0,0,0,0,0,0,0
0,0,0,0,0,0,0,0,0,0,3,3,3,3,3,0,0,0,0,0,0,0,37,37,37,37,37,0,0,0,0,0
0,0,0,0,0,0,0,0,0,3,63,63,63,63,63,3,0,0,0,0,0,40,3,3,3,3,3,38,0,0,0,0
0,0,0,0,0,0,0,0,3,63,63,63,63,63,63,63,3,0,0,0,40,3,0,0,0,0,0,3,38,0,0,0
0,0,0,0,0,0,0,0,3,63,63,63,57,63,63,63,3,30,28,32,3,0,0,0,0,0,0,3,38,0,0,0
0,0,0,0,0,0,0,0,3,63,63,63,5,63,63,63,0,30,28,32,38,0,0,16,5,0,0,3,38,0,0,0
0,0,0,0,0,0,0,0,3,63,63,63,63,63,63,63,3,30,28,32,3,0,0,0,0,0,0,3,38,0,0,0
0,0,0,0,0,0,0,0,3,63,63,63,63,63,63,63,3,0,0,0,40,3,0,0,0,0,0,3,38,0,0,0
0,0,0,0,0,0,0,0,0,3,63,63,63,63,63,3,0,0,0,0,0,41,3,3,18,3,3,38,0,0,0,0
0,0,0,0,0,0,0,0,0,0,3,3,3,3,3,0,0,0,0,0,0,0,41,41,0,41,41,0,0,0,0,0
0,0,0,0,0,0,0,0,0,0,0,0,0,0,0,0,0,0,0,0,0,0,0,0,0,0,0,0,0,0,0,0
0,0,0,0,0,0,0,0,0,0,0,0,0,0,0,0,0,0,0,0,0,0,0,0,0,0,0,0,0,0,0,0
0,0,0,0,0,0,0,0,0,0,0,0,0,0,0,0,0,0,0,0,0,0,0,0,0,0,0,0,0,0,0,0
0,0,0,0,0,0,0,0,0,0,0,0,0,0,0,0,0,0,0,0,0,0,0,0,0,0,0,0,0,0,0,0
0,0,0,0,0,0,0,0,0,0,0,0,0,0,0,0,0,0,0,0,0,0,0,0,0,0,0,0,0,0,0,0
0,0,0,0,0,0,0,0,0,0,0,0,0,0,0,0,0,0,0,0,0,0,0,0,0,0,0,0,0,0,0,0
0,0,0,0,0,0,0,0,0,0,0,0,0,0,0,0,0,0,0,0,0,0,0,0,0,0,0,0,0,0,0,0
0,0,0,0,0,0,0,0,0,0,0,0,0,0,0,0,0,0,0,0,0,0,0,0,0,0,0,0,0,0,0,0
0,0,0,0,0,0,0,0,0,0,0,0,0,0,0,0,0,0,0,0,0,0,0,0,0,0,0,0,0,0,0,0
0,0,0,0,0,0,0,0,0,0,0,0,0,0,0,0,0,0,0,0,0,0,0,0,0,0,0,0,0,0,0,0
0,0,0,0,0,0,0,0,0,0,0,0,0,0,0,0,0,0,0,0,0,0,0,0,0,0,0,0,0,0,0,0
0,0,0,0,0,0,0,0,0,0,0,0,0,0,0,0,0,0,0,0,0,0,0,0,0,0,0,0,0,0,0,0
0,0,0,0,0,0,0,0,0,0,0,0,0,0,0,0,0,0,0,0,0,0,0,0,0,0,0,0,0,0,0,0
0,0,0,0,0,0,0,0,0,0,0,0,0,0,0,0,0,0,0,0,0,0,0,0,0,0,0,0,0,0,0,0
0,0,0,0,0,0,0,0,0,0,0,0,0,0,0,0,0,0,0,0,0,0,0,0,0,0,0,0,0,0,0,0
0,0,0,0,0,0,0,0,0,0,0,0,0,0,0,0,0,0,0,0,0,0,0,0,0,0,0,0,0,0,0,0
0,0,0,0,0,0,0,0,0,0,0,0,0,0,0,0,0,0,0,0,0,0,0,0,0,0,0,0,0,0,0,0
endlayer

layer
0,0,0,0,0,0,0,0,0,0,0,0,0,0,0,0,0,0,0,0,0,0,0,0,0,0,0,0,0,0,0,0
0,0,0,0,0,0,0,0,0,0,0,0,0,0,0,0,0,0,0,0,0,0,0,0,0,0,0,0,0,0,0,0
0,0,0,0,0,0,0,0,0,0,0,0,0,0,0,0,0,0,0,0,0,0,0,0,0,0,0,0,0,0,0,0
0,0,0,0,0,0,0,0,0,0,0,0,0,0,0,0,0,0,0,0,0,0,0,0,0,0,0,0,0,0,0,0
0,0,0,0,0,0,0,0,0,0,3,3,3,3,3,0,0,0,0,0,0,0,27,27,27,27,27,0,0,0,0,0
0,0,0,0,0,0,0,0,0,3,0,0,0,0,0,3,0,0,0,0,0,32,3,3,3,3,3,30,0,0,0,0
0,0,0,0,0,0,0,0,3,0,0,0,0,0,0,0,3,0,0,0,32,3,0,0,0,0,0,3,30,0,0,0
0,0,0,0,0,0,0,0,3,0,0,0,57,0,0,0,26,22,22,22,26,0,0,0,0,0,0,3,30,0,0,0
0,0,0,0,0,0,0,0,3,0,0,16,5,0,0,0,0,0,0,0,0,0,0,16,5,0,0,3,30,0,0,0
0,0,0,0,0,0,0,0,3,0,0,0,0,0,0,0,26,22,22,22,26,0,0,0,0,0,0,3,30,0,0,0
0,0,0,0,0,0,0,0,3,0,0,0,0,0,0,3,3,0,0,0,32,3,0,0,0,0,0,3,30,0,0,0
0,0,0,0,0,0,0,0,0,3,0,3,0,3,0,3,0,0,0,0,0,54,3,3,18,3,3,30,0,0,0,0
0,0,0,0,0,0,0,0,0,0,3,41,0,41,3,0,0,0,0,0,0,0,54,54,0,54,54,0,0,0,0,0
0,0,0,0,0,0,0,0,0,0,0,0,0,0,0,0,0,0,0,0,0,0,0,0,0,0,0,0,0,0,0,0
0,0,0,0,0,0,0,0,0,0,0,0,0,0,0,0,0,0,0,0,0,0,0,0,0,0,0,0,0,0,0,0
0,0,0,0,0,0,0,0,0,0,0,0,0,0,0,0,0,0,0,0,0,0,0,0,0,0,0,0,0,0,0,0
0,0,0,0,0,0,0,0,0,0,0,0,0,0,0,0,0,0,0,0,0,0,0,0,0,0,0,0,0,0,0,0
0,0,0,0,0,0,0,0,0,0,0,0,0,0,0,0,0,0,0,0,0,0,0,0,0,0,0,0,0,0,0,0
0,0,0,0,0,0,0,0,0,0,0,0,0,0,0,0,0,0,0,0,0,0,0,0,0,0,0,0,0,0,0,0
0,0,0,0,0,0,0,0,0,0,0,0,0,0,0,0,0,0,0,0,0,0,0,0,0,0,0,0,0,0,0,0
0,0,0,0,0,0,0,0,0,0,0,0,0,0,0,0,0,0,0,0,0,0,0,0,0,0,0,0,0,0,0,0
0,0,0,0,0,0,0,0,0,0,0,0,0,0,0,0,0,0,0,0,0,0,0,0,0,0,0,0,0,0,0,0
0,0,0,0,0,0,0,0,0,0,0,0,0,0,0,0,0,0,0,0,0,0,0,0,0,0,0,0,0,0,0,0
0,0,0,0,0,0,0,0,0,0,0,0,0,0,0,0,0,0,0,0,0,0,0,0,0,0,0,0,0,0,0,0
0,0,0,0,0,0,0,0,0,0,0,0,0,0,0,0,0,0,0,0,0,0,0,0,0,0,0,0,0,0,0,0
0,0,0,0,0,0,0,0,0,0,0,0,0,0,0,0,0,0,0,0,0,0,0,0,0,0,0,0,0,0,0,0
0,0,0,0,0,0,0,0,0,0,0,0,0,0,0,0,0,0,0,0,0,0,0,0,0,0,0,0,0,0,0,0
0,0,0,0,0,0,0,0,0,0,0,0,0,0,0,0,0,0,0,0,0,0,0,0,0,0,0,0,0,0,0,0
0,0,0,0,0,0,0,0,0,0,0,0,0,0,0,0,0,0,0,0,0,0,0,0,0,0,0,0,0,0,0,0
0,0,0,0,0,0,0,0,0,0,0,0,0,0,0,0,0,0,0,0,0,0,0,0,0,0,0,0,0,0,0,0
endlayer

layer
0,0,0,0,0,0,0,0,0,0,0,0,0,0,0,0,0,0,0,0,0,0,0,0,0,0,0,0,0,0,0,0
0,0,0,0,0,0,0,0,0,0,0,0,0,0,0,0,0,0,0,0,0,0,0,0,0,0,0,0,0,0,0,0
0,0,0,0,0,0,0,0,0,0,0,0,0,0,0,0,0,0,0,0,0,0,0,0,0,0,0,0,0,0,0,0
0,0,0,0,0,0,0,0,0,0,0,0,0,0,0,0,0,0,0,0,0,0,0,0,0,0,0,0,0,0,0,0
0,0,0,0,0,0,0,0,0,0,37,37,37,37,37,0,0,0,0,0,0,0,3,3,3,3,3,0,0,0,0,0
0,0,0,0,0,0,0,0,0,40,0,0,0,0,0,38,0,0,0,0,0,3,3,3,3,3,3,3,0,0,0,0
0,0,0,0,0,0,0,0,40,0,0,0,0,0,0,0,38,0,0,0,3,3,0,0,0,0,0,3,3,0,0,0
0,0,0,0,0,0,0,0,40,0,0,0,57,0,0,0,0,0,0,0,22,0,0,0,0,0,0,3,3,0,13,0
0,0,0,0,0,0,0,0,40,0,0,16,5,0,0,0,0,0,0,0,0,0,0,16,5,0,0,3,3,0,0,0
0,0,0,0,0,0,0,0,40,0,0,0,0,0,0,0,0,0,0,0,22,0,0,0,0,0,20,3,3,0,0,0
0,0,0,0,0,0,0,0,40,0,0,0,0,0,0,0,38,0,0,0,3,3,0,0,0,0,0,3,3,0,0,0
0,0,0,0,0,0,0,0,0,40,0,18,0,18,0,38,0,0,0,0,0,3,3,3,3,3,3,3,0,0,0,0
0,0,0,0,0,0,0,0,0,0,41,0,41,0,41,0,0,0,0,0,0,0,3,3,54,3,3,0,0,0,0,0
0,0,0,0,0,0,0,0,0,0,0,0,0,0,0,0,0,0,0,0,0,0,0,0,0,0,0,0,0,0,0,0
0,0,0,0,0,0,0,0,0,0,0,0,0,0,0,0,0,0,0,0,0,0,0,0,0,0,0,0,0,0,0,0
0,0,0,0,0,0,0,0,0,0,0,0,0,0,0,0,0,0,0,0,0,0,0,0,0,0,0,0,0,0,0,0
0,0,0,0,0,0,0,0,0,0,0,0,0,0,0,0,0,0,0,0,0,0,0,0,0,0,0,0,0,0,0,0
0,0,0,0,0,0,0,0,0,0,0,0,0,0,0,0,0,0,0,0,0,0,0,0,0,0,0,0,0,0,0,0
0,0,0,0,0,0,0,0,0,0,0,0,0,0,0,0,0,0,0,0,0,0,0,0,0,0,0,0,0,0,0,0
0,0,0,0,0,0,0,0,0,0,0,0,0,0,0,0,0,0,0,0,0,0,0,0,0,0,0,0,0,0,0,0
0,0,0,0,0,0,0,0,0,0,0,0,0,0,0,0,0,0,0,0,0,0,0,0,0,0,0,0,0,0,0,0
0,0,0,0,0,0,0,0,0,0,0,0,0,0,0,0,0,0,0,0,0,0,0,0,0,0,0,0,0,0,0,0
0,0,0,0,0,0,0,0,0,0,0,0,0,0,0,0,0,0,0,0,0,0,0,0,0,0,0,0,0,0,0,0
0,0,0,0,0,0,0,0,0,0,0,0,0,0,0,0,0,0,0,0,0,0,0,0,0,0,0,0,0,0,0,0
0,0,0,0,0,0,0,0,0,0,0,0,0,0,0,0,0,0,0,0,0,0,0,0,0,0,0,0,0,0,0,0
0,0,0,0,0,0,0,0,0,0,0,0,0,0,0,0,0,0,0,0,0,0,0,0,0,0,0,0,0,0,0,0
0,0,0,0,0,0,0,0,0,0,0,0,0,0,0,0,0,0,0,0,0,0,0,0,0,0,0,0,0,0,0,0
0,0,0,0,0,0,0,0,0,0,0,0,0,0,0,0,0,0,0,0,0,0,0,0,0,0,0,0,0,0,0,0
0,0,0,0,0,0,0,0,0,0,0,0,0,0,0,0,0,0,0,0,0,0,0,0,0,0,0,0,0,0,0,0
0,0,0,0,0,0,0,0,0,0,0,0,0,0,0,0,0,0,0,0,0,0,0,0,0,0,0,0,0,0,0,13
endlayer

layer
0,0,0,0,0,0,0,0,0,0,0,0,0,0,0,0,0,0,0,0,0,0,0,0,0,0,0,0,0,0,0,0
0,0,0,0,0,0,0,0,0,0,0,0,0,0,0,0,0,0,0,0,0,0,0,0,0,0,0,0,0,0,0,0
0,0,0,0,0,0,0,0,0,0,0,0,0,0,0,0,0,0,0,0,0,0,0,0,0,0,0,0,0,0,0,0
0,0,0,0,0,0,0,0,0,0,0,0,0,0,0,0,0,0,0,0,0,0,27,23,27,23,27,0,0,0,0,0
0,0,0,0,0,0,0,0,0,0,27,27,27,27,27,0,0,0,0,0,0,27,3,3,3,3,3,27,0,0,0,0
0,0,0,0,0,0,0,0,0,32,0,0,0,0,0,30,0,0,0,0,32,3,3,3,3,3,3,3,30,0,0,0
0,0,0,0,0,0,0,0,32,0,0,0,0,0,0,0,30,0,0,32,3,3,0,0,0,0,0,3,3,30,13,0
0,0,0,0,0,0,0,0,32,0,0,0,0,0,0,0,0,0,0,23,3,0,0,0,0,0,0,3,3,23,13,0
0,0,0,0,0,0,0,0,32,0,0,16,5,0,0,0,30,0,0,32,3,0,0,16,5,0,0,3,3,30,0,0
0,0,0,0,0,0,0,0,32,0,0,0,0,0,0,0,0,0,0,23,3,0,0,0,0,0,0,3,3,23,0,0
0,0,0,0,0,0,0,0,32,0,0,0,0,0,0,0,30,0,0,32,3,3,0,0,0,0,0,3,3,30,0,0
0,0,0,0,0,0,0,0,0,32,0,18,0,18,0,30,0,0,0,0,32,3,3,3,3,3,3,3,30,0,0,0
0,0,0,0,0,0,0,0,0,0,54,0,54,0,54,0,0,0,0,0,0,54,3,3,3,3,3,54,0,0,0,0
0,0,0,0,0,0,0,0,0,0,0,0,0,0,0,0,0,0,0,0,0,0,54,23,54,23,54,0,0,0,0,0
0,0,0,0,0,0,0,0,0,0,0,0,0,0,0,0,0,0,0,0,0,0,0,0,0,0,0,0,0,0,0,0
0,0,0,0,0,0,0,0,0,0,0,0,0,0,0,0,0,0,0,0,0,0,0,0,0,0,0,0,0,0,0,0
0,0,0,0,0,0,0,0,0,0,0,0,0,0,0,0,0,0,0,0,0,0,0,0,0,0,0,0,0,0,0,0
0,0,0,0,0,0,0,0,0,0,0,0,0,0,0,0,0,0,0,0,0,0,0,0,0,0,0,0,0,0,0,0
0,0,0,0,0,0,0,0,0,0,0,0,0,0,0,0,0,0,0,0,0,0,0,0,0,0,0,0,0,0,0,0
0,0,0,0,0,0,0,0,0,0,0,0,0,0,0,0,0,0,0,0,0,0,0,0,0,0,0,0,0,0,0,0
0,0,0,0,0,0,0,0,0,0,0,0,0,0,0,0,0,0,0,0,0,0,0,0,0,0,0,0,0,0,0,0
0,0,0,0,0,0,0,0,0,0,0,0,0,0,0,0,0,0,0,0,0,0,0,0,0,0,0,0,0,0,0,0
0,0,0,0,0,0,0,0,0,0,0,0,0,0,0,0,0,0,0,0,0,0,0,0,0,0,0,0,0,0,0,0
0,0,0,0,0,0,0,0,0,0,0,0,0,0,0,0,0,0,0,0,0,0,0,0,0,0,0,0,0,0,0,0
0,0,0,0,0,0,0,0,0,0,0,0,0,0,0,0,0,0,0,0,0,0,0,0,0,0,0,0,0,0,0,0
0,0,0,0,0,0,0,0,0,0,0,0,0,0,0,0,0,0,0,0,0,0,0,0,0,0,0,0,0,0,0,0
0,0,0,0,0,0,0,0,0,0,0,0,0,0,0,0,0,0,0,0,0,0,0,0,0,0,0,0,0,0,0,0
0,0,0,0,0,0,0,0,0,0,0,0,0,0,0,0,0,0,0,0,0,0,0,0,0,0,0,0,0,0,0,0
0,0,0,0,0,0,0,0,0,0,0,0,0,0,0,0,0,0,0,0,0,0,0,0,0,0,0,0,0,0,0,0
0,0,0,0,0,0,0,0,0,0,0,0,0,0,0,0,0,0,0,0,0,0,0,0,0,0,0,0,0,0,0,0
endlayer

layer
0,0,0,0,0,0,0,0,0,0,0,0,0,0,0,0,0,0,0,0,0,0,0,0,0,0,0,0,0,0,0,0
0,0,0,0,0,0,0,0,0,0,0,0,0,0,0,0,0,0,0,0,0,0,0,0,0,0,0,0,0,0,0,0
0,0,0,0,0,0,0,0,0,0,0,0,0,0,0,0,0,0,0,0,0,0,0,0,0,0,0,0,0,0,0,0
0,0,0,0,0,0,0,0,0,0,0,0,0,0,0,0,0,0,0,0,0,0,3,64,3,64,3,0,0,0,0,0
0,0,0,0,0,0,0,0,0,0,3,3,3,3,3,0,0,0,0,0,0,3,31,31,31,31,31,3,0,0,0,0
0,0,0,0,0,0,0,0,0,3,3,0,0,0,3,3,0,0,0,0,3,31,31,31,31,31,31,31,3,0,0,0
0,0,0,0,0,0,0,0,3,3,0,0,0,0,0,3,3,0,0,3,31,31,31,31,31,31,31,31,31,3,0,0
0,0,0,0,0,0,0,0,3,0,0,0,0,0,0,0,3,0,0,48,31,31,31,31,31,31,31,31,31,49,0,0
0,0,0,0,0,0,0,0,3,0,0,16,5,0,0,20,3,0,0,3,31,31,31,16,6,31,31,31,31,3,0,0
0,0,0,0,0,0,0,0,3,0,0,0,0,0,0,0,3,0,0,48,31,31,31,31,31,31,31,31,31,49,0,0
0,0,0,0,0,0,0,0,3,3,0,0,0,0,0,3,3,0,0,3,31,31,31,31,31,31,31,31,31,3,0,0
0,0,0,0,0,0,0,0,0,3,3,3,3,3,3,3,0,0,0,0,3,31,31,31,31,31,31,31,3,0,0,0
0,0,0,0,0,0,0,0,0,0,3,54,0,54,0,0,0,0,0,0,0,3,31,31,31,31,31,3,0,0,0,0
0,0,0,0,0,0,0,0,0,0,0,0,0,0,0,0,0,0,0,0,0,0,3,59,3,59,3,0,0,0,0,0
0,0,0,0,0,0,0,0,0,0,0,0,0,0,0,0,0,0,0,0,0,0,0,0,0,0,0,0,0,0,0,0
0,0,0,0,0,0,0,0,0,0,0,0,0,0,0,0,0,0,0,0,0,0,0,0,0,0,0,0,0,0,0,0
0,0,0,0,0,0,0,0,0,0,0,0,0,0,0,0,0,0,0,0,0,0,0,0,0,0,0,0,0,0,0,0
0,0,0,0,0,0,0,0,0,0,0,0,0,0,0,0,0,0,0,0,0,0,0,0,0,0,0,0,0,0,0,0
0,0,0,0,0,0,0,0,0,0,0,0,0,0,0,0,0,0,0,0,0,0,13,0,0,0,0,0,0,0,0,0
0,0,0,0,0,0,0,0,0,0,0,0,0,0,0,0,0,0,0,0,0,0,0,0,0,0,0,0,0,0,0,0
0,0,0,0,0,0,0,0,0,0,0,0,0,0,0,0,0,0,0,0,0,0,0,0,0,0,0,0,0,0,0,0
0,0,0,0,0,0,0,0,0,0,0,0,0,0,0,0,0,0,0,0,0,0,0,0,0,0,0,0,0,0,0,0
0,0,0,0,0,0,0,0,0,0,0,0,0,0,0,0,0,0,0,0,0,0,0,0,0,0,0,0,0,0,0,0
0,0,0,0,0,0,0,0,0,0,0,0,0,0,0,0,0,0,0,0,0,0,0,0,0,0,0,0,0,0,0,0
0,0,0,0,0,0,0,0,0,0,0,0,0,0,0,0,0,0,0,0,0,0,0,0,0,0,0,0,0,0,0,0
0,0,0,0,0,0,0,0,0,0,0,0,0,0,0,0,0,0,0,0,0,0,0,0,0,0,0,0,0,0,0,0
0,0,0,0,0,0,0,0,0,0,0,0,0,0,0,0,0,0,0,0,0,0,0,0,0,0,0,0,0,0,0,0
0,0,0,0,0,0,0,0,0,0,0,0,0,0,0,0,0,0,0,0,0,0,0,0,0,0,0,0,0,0,0,0
0,0,0,0,0,0,0,0,0,0,0,0,0,0,0,0,0,0,0,0,0,0,0,0,0,0,0,0,0,0,0,0
0,0,0,0,0,0,0,0,0,0,0,0,0,0,0,0,0,0,0,0,0,0,0,0,0,0,0,0,0,0,0,0
endlayer

layer
0,0,0,0,0,0,0,0,0,0,0,0,0,0,0,0,0,0,0,0,0,0,0,0,0,0,0,0,0,0,0,0
0,0,0,0,0,0,0,0,0,0,0,0,0,0,0,0,0,0,0,0,0,0,0,0,0,0,0,0,0,0,0,0
0,0,0,0,0,0,0,0,0,0,0,0,0,0,0,0,0,0,0,0,0,0,0,0,0,0,0,0,0,0,0,0
0,0,0,0,0,0,0,0,0,0,0,0,0,0,0,0,0,0,0,0,0,0,3,22,3,22,3,0,0,0,0,0
0,0,0,0,0,0,0,0,0,0,3,3,3,3,3,0,0,0,0,0,0,3,0,0,0,0,0,3,0,0,0,0
0,0,0,0,0,0,0,0,0,3,3,0,0,0,3,3,0,0,0,0,3,0,0,0,0,0,0,0,3,0,0,0
0,0,0,0,0,0,0,0,3,3,0,0,0,0,0,3,3,0,0,3,0,0,0,0,0,0,0,0,0,3,0,0
0,0,0,0,0,0,0,0,3,0,0,0,0,0,0,0,3,0,0,22,0,0,0,0,0,0,0,0,0,22,13,0
0,0,0,0,0,0,0,0,3,0,0,16,5,0,0,0,3,0,0,3,0,0,0,0,0,0,13,0,0,3,0,0
0,0,0,0,0,0,0,0,3,0,0,0,0,0,0,0,3,0,0,22,0,0,0,0,0,0,0,0,0,22,0,0
0,0,0,0,0,0,0,0,3,3,0,0,0,0,0,3,3,0,0,3,0,0,0,0,0,0,0,0,0,3,0,0
0,0,0,0,0,0,0,0,0,3,3,3,3,3,3,3,0,0,0,0,3,0,0,0,0,0,0,0,3,0,0,0
0,0,0,0,0,0,0,0,0,0,3,3,3,3,3,0,0,0,0,0,0,3,0,0,0,0,0,3,0,0,0,0
0,0,0,0,0,0,0,0,0,0,0,0,0,0,0,0,0,0,0,0,0,0,3,22,3,22,3,0,0,0,0,0
0,0,0,0,0,0,0,0,0,0,0,0,0,0,0,0,0,0,0,0,0,0,0,0,0,0,0,0,0,0,0,0
0,0,0,0,0,0,0,0,0,0,0,0,0,0,0,0,0,0,0,0,0,0,0,0,0,0,0,0,0,0,0,0
0,0,0,0,0,0,0,0,0,0,0,0,0,0,0,0,0,0,0,0,0,0,0,0,0,0,0,0,0,0,0,0
0,0,0,0,0,0,0,0,0,0,0,0,0,0,0,0,0,0,0,0,0,0,0,0,0,0,0,0,0,0,0,0
0,0,0,0,0,0,0,0,0,0,0,0,0,0,0,0,0,0,0,0,0,0,0,0,0,0,0,0,0,0,0,0
0,0,0,0,0,0,0,0,0,0,0,0,0,0,0,0,0,0,0,0,0,0,0,0,0,0,0,0,0,0,0,0
0,0,0,0,0,0,0,0,0,0,0,0,0,0,0,0,0,0,0,0,0,0,0,0,0,0,0,0,0,0,0,0
0,0,0,0,0,0,0,0,0,0,0,0,0,0,0,13,0,0,0,0,0,0,0,0,0,0,0,0,0,0,0,0
0,0,0,0,0,0,0,0,0,0,0,0,0,0,0,0,0,0,0,0,0,0,0,0,0,0,0,0,0,0,0,0
0,0,0,0,0,0,0,0,0,0,0,0,0,0,0,0,0,0,0,0,0,0,0,0,0,0,0,0,0,0,0,0
0,0,0,0,0,0,0,0,0,0,0,0,0,0,0,0,0,0,0,0,0,0,0,0,0,0,0,0,0,0,13,0
0,0,0,0,0,0,0,0,0,0,0,0,0,0,0,0,0,0,0,0,0,0,0,0,0,0,0,0,0,0,0,0
0,0,0,0,0,0,0,0,0,0,0,0,0,0,0,0,0,0,0,0,0,0,0,0,0,0,0,0,0,0,0,0
0,0,0,0,0,0,0,0,0,0,0,0,0,0,0,0,0,0,0,0,0,0,0,0,0,0,0,0,0,0,0,0
0,0,0,0,0,0,0,0,0,0,0,0,0,0,0,0,0,0,0,0,0,0,0,0,0,0,0,0,0,0,0,0
0,0,0,0,0,0,0,0,0,0,0,0,0,0,0,0,0,0,0,0,0,0,0,0,0,0,0,0,0,0,0,0
endlayer

layer
0,0,0,0,0,0,0,0,0,0,0,0,0,0,0,0,0,0,0,0,0,0,0,0,0,0,0,0,0,0,0,0
0,0,0,0,0,0,0,0,0,0,0,0,0,0,0,0,0,0,0,0,0,0,0,0,0,0,13,0,0,0,0,0
0,0,0,0,0,0,0,0,0,0,0,0,0,0,0,0,0,0,0,0,0,0,0,13,0,0,0,0,0,0,0,0
0,0,0,0,0,0,0,0,0,0,27,0,27,0,27,0,0,0,0,0,0,0,65,65,65,65,65,0,0,0,0,0
0,0,0,0,0,0,0,0,0,27,3,3,3,3,3,27,0,0,0,0,0,65,0,0,0,0,0,65,0,0,0,0
0,0,0,0,0,0,0,0,32,3,3,0,0,0,3,3,30,0,0,0,65,0,0,0,0,0,0,0,65,13,0,13
0,0,0,0,0,0,0,32,3,3,0,0,0,0,0,3,3,30,0,65,0,0,0,0,0,0,0,0,0,65,0,13
0,0,0,0,0,0,0,0,3,0,0,0,0,0,0,0,3,0,0,65,0,0,0,0,0,0,0,0,0,65,0,0
0,0,0,0,0,0,0,32,3,0,0,16,5,0,0,0,3,30,0,65,0,0,0,0,0,0,0,0,0,65,0,13
0,0,0,0,0,0,0,0,3,0,0,0,0,0,0,0,3,0,0,65,0,0,0,0,0,0,0,0,0,65,0,0
0,0,0,0,0,0,0,32,3,3,0,0,0,0,0,3,3,30,0,65,0,0,0,0,0,0,0,0,0,65,0,0
0,0,0,0,0,0,0,0,32,3,3,3,3,3,3,3,30,0,0,0,65,0,0,0,0,0,0,0,65,0,0,0
0,0,0,0,0,0,0,0,0,54,3,3,3,3,3,54,0,0,0,0,0,65,0,0,0,0,0,65,0,0,0,0
0,0,0,0,0,0,0,0,0,0,54,0,54,0,54,0,0,0,0,0,0,0,65,65,65,65,65,0,13,0,0,0
0,0,0,0,0,0,0,0,0,0,0,0,0,0,0,0,0,0,0,0,0,0,0,0,0,0,0,0,0,0,0,0
0,0,0,0,0,0,0,0,0,0,0,0,0,0,0,0,0,0,0,0,0,0,13,0,0,0,13,0,0,0,0,0
0,0,0,0,0,0,0,0,0,0,0,0,0,0,0,0,0,0,0,0,0,0,0,0,0,0,0,0,0,0,0,0
0,0,0,0,0,0,0,0,0,0,0,0,0,0,0,0,0,0,0,0,0,0,0,0,0,0,0,0,0,0,0,0
0,0,0,0,0,0,0,0,0,0,0,0,0,0,0,0,0,0,0,0,0,0,0,0,0,0,0,0,0,0,0,0
0,0,0,0,0,0,0,0,0,0,0,0,0,0,0,0,0,0,0,0,0,0,0,0,0,0,0,0,0,0,0,0
0,0,0,0,0,0,0,0,0,0,0,0,0,0,0,0,0,0,0,0,0,0,0,0,0,0,0,0,0,0,0,0
0,0,0,0,0,0,0,0,0,0,0,0,0,0,0,0,0,0,0,0,0,0,0,13,0,0,0,0,0,0,0,0
0,0,0,0,0,0,0,0,0,0,0,0,0,0,0,0,0,0,0,0,0,0,0,0,0,0,0,0,0,0,0,0
0,0,0,0,0,0,0,0,0,0,0,0,0,0,0,0,0,0,0,0,0,0,0,0,0,0,13,0,0,0,0,0
0,0,0,0,0,0,0,0,0,0,0,0,0,0,0,0,0,0,0,0,0,0,0,0,0,0,0,0,0,0,0,0
0,0,0,0,0,0,0,0,0,0,0,0,0,0,0,0,0,0,0,0,0,0,0,0,0,0,0,0,0,0,0,0
0,0,0,0,0,0,0,0,0,0,0,0,0,0,0,0,0,0,0,0,0,0,0,0,0,0,0,0,0,0,0,0
0,0,0,0,0,0,0,0,0,0,0,0,0,0,0,0,0,0,0,0,0,0,0,0,0,0,0,0,0,0,0,0
0,0,0,0,0,0,0,0,0,0,0,0,0,0,0,0,0,0,0,0,0,0,0,0,0,0,0,0,0,0,0,0
0,0,0,0,0,0,0,0,0,0,0,0,0,0,0,0,0,0,0,0,0,0,0,0,0,0,0,0,0,0,0,0
endlayer

layer
0,0,0,0,0,0,0,0,0,0,0,0,0,0,0,0,0,0,0,0,0,0,0,0,0,0,0,0,0,0,0,0
0,0,0,0,0,0,0,0,0,0,0,0,0,0,0,0,0,0,0,0,0,0,0,0,0,0,0,0,0,0,0,0
0,0,0,0,0,0,0,0,0,0,27,23,27,23,27,0,0,0,0,0,0,13,0,0,0,0,0,0,0,0,0,0
0,0,0,0,0,0,0,0,0,27,3,64,3,64,3,27,0,0,0,0,0,0,65,0,65,0,65,0,0,0,0,0
0,0,0,0,0,0,0,0,27,3,31,31,31,31,31,3,30,0,0,0,0,13,0,0,0,0,0,0,0,0,0,0
0,0,0,0,0,0,0,32,3,31,31,31,31,31,31,31,3,30,0,0,0,0,0,0,0,0,0,0,0,0,0,0
0,0,0,0,0,0,32,3,31,31,31,31,31,31,31,31,31,3,30,65,0,13,0,0,0,0,0,0,0,65,0,0
0,0,0,0,0,0,23,48,31,31,31,31,31,31,31,31,31,3,23,0,0,0,0,0,0,0,0,0,0,0,0,0
0,0,0,0,0,0,32,3,31,31,31,16,31,31,31,31,31,3,30,65,0,0,0,0,0,0,0,0,0,65,0,0
0,0,0,0,0,0,23,48,31,31,31,31,31,31,31,31,31,3,23,0,0,0,13,0,0,0,0,0,0,0,0,0
0,0,0,0,0,0,32,3,31,31,31,31,31,31,31,31,31,3,30,65,0,0,13,13,0,0,0,0,0,65,0,0
0,0,0,0,0,0,0,32,3,31,31,31,31,31,31,31,3,30,0,0,0,0,0,0,0,0,0,0,0,0,0,0
0,0,0,0,0,0,0,0,54,3,31,31,31,31,31,3,54,0,0,0,0,0,0,0,0,0,0,0,0,0,0,0
0,0,0,0,0,0,0,0,0,54,3,3,3,3,3,54,0,0,0,0,0,0,65,0,65,0,65,0,0,0,0,0
0,0,0,0,0,0,0,0,0,0,54,23,54,23,54,0,0,0,0,0,0,0,0,0,0,0,0,0,0,0,0,0
0,0,0,0,0,0,0,0,0,0,0,0,0,0,0,0,0,0,0,0,0,0,0,0,0,0,0,0,0,0,0,0
0,0,0,0,0,0,0,0,0,0,0,0,0,0,0,0,0,0,0,0,0,0,0,0,0,0,0,0,0,0,0,0
0,0,0,0,0,0,0,0,0,0,0,0,0,0,0,0,0,0,0,0,0,0,0,0,0,0,0,0,0,0,0,0
0,0,0,0,0,0,0,0,0,0,0,0,0,0,0,0,0,0,0,0,0,0,0,0,0,0,0,0,0,0,0,0
0,0,0,0,0,0,0,0,0,0,0,0,0,0,0,0,0,0,0,0,0,0,0,0,0,0,0,0,0,0,0,0
0,0,0,0,0,0,0,0,0,0,0,0,0,0,0,0,0,0,0,0,0,0,0,0,0,0,0,0,0,0,0,0
0,0,0,0,0,0,0,0,0,0,0,0,0,0,0,0,0,0,0,0,0,0,0,0,0,0,0,0,0,0,0,0
0,0,0,0,0,0,0,0,0,0,0,0,0,0,0,0,0,0,0,0,0,0,0,0,0,0,0,0,0,0,0,0
0,0,0,0,0,0,0,0,0,0,0,0,0,0,0,0,0,0,0,0,0,0,0,0,0,0,0,0,0,0,0,0
0,0,0,0,0,0,0,0,0,0,0,0,0,0,0,0,0,0,0,0,0,0,0,0,0,0,0,0,0,0,0,0
0,0,0,0,0,0,0,0,0,0,0,0,0,0,0,0,0,0,0,0,0,0,0,0,0,0,0,0,0,0,0,0
0,0,0,0,0,0,0,0,0,0,0,0,0,0,0,0,0,0,0,0,0,0,0,0,0,0,0,0,0,0,0,0
0,0,0,0,0,0,0,0,0,0,0,0,0,0,0,0,0,0,0,0,0,0,0,0,0,0,0,0,0,0,0,0
0,0,0,0,0,0,0,0,0,0,0,0,0,0,0,0,0,0,0,0,0,0,0,0,0,0,0,0,0,0,0,0
0,0,0,0,0,0,0,0,0,0,0,0,0,0,0,0,0,0,0,0,0,0,0,0,0,0,0,0,0,0,0,0
endlayer

layer
0,0,0,0,0,0,0,0,0,13,0,0,0,0,13,0,0,0,0,0,0,0,0,0,0,13,0,0,0,0,0,0
0,0,0,0,0,0,0,0,0,0,0,0,0,0,0,0,0,13,0,0,0,0,0,13,0,0,0,0,0,0,0,0
0,0,0,0,0,0,0,13,0,0,65,64,3,64,65,0,0,0,0,0,0,0,0,0,0,0,0,0,0,0,0,0
0,0,0,0,0,0,0,0,0,65,31,31,31,31,31,65,0,0,0,0,0,0,0,0,0,0,0,0,0,0,0,0
0,0,0,0,0,0,0,13,65,31,31,31,31,31,31,31,65,0,0,0,0,0,0,0,0,0,0,0,0,0,13,0
0,0,0,0,0,0,0,65,31,31,31,31,31,31,31,31,31,65,0,13,0,0,0,0,0,0,0,0,0,0,0,0
0,0,0,0,13,0,65,31,31,31,31,31,31,31,31,31,31,31,65,13,0,13,0,0,0,0,0,0,0,0,0,0
0,0,0,0,0,0,48,31,31,31,31,31,31,31,31,31,31,31,49,0,0,0,0,0,0,0,0,0,0,0,13,0
0,0,0,0,0,0,65,31,31,31,31,16,31,31,31,31,31,31,65,0,0,13,0,0,0,0,0,0,0,0,0,0
0,0,0,0,0,0,48,31,31,31,31,6,31,31,31,31,31,31,49,0,13,0,0,0,0,0,0,0,0,0,0,0
0,0,0,13,0,0,65,31,31,31,31,31,31,31,31,31,31,31,65,0,0,0,0,0,0,0,0,0,0,0,0,0
0,0,0,0,0,0,0,65,31,31,31,31,31,31,31,31,31,65,0,0,0,0,0,0,0,0,0,0,0,0,0,0
0,0,0,0,0,0,0,0,65,31,31,31,31,31,31,31,65,0,0,0,0,0,0,0,0,0,0,0,0,0,13,0
0,0,0,0,0,0,0,0,0,65,31,31,31,31,31,65,0,0,13,0,0,0,0,0,0,0,0,0,0,0,0,0
0,0,0,0,0,13,0,0,0,0,65,59,65,59,65,0,0,13,0,0,0,0,0,0,0,0,0,0,13,0,0,0
0,0,0,0,0,0,0,13,0,13,0,0,0,0,0,0,13,0,0,0,0,0,0,0,13,13,0,0,0,0,0,0
0,0,0,0,0,0,0,0,0,0,0,0,0,13,13,13,0,0,0,0,0,0,0,0,0,0,0,0,0,0,0,0
0,0,0,0,0,0,0,0,0,0,0,0,0,0,0,0,0,0,0,0,0,0,0,0,0,0,0,13,0,0,0,0
0,0,0,0,0,0,0,0,0,0,0,0,0,0,0,0,0,0,0,0,0,0,0,0,0,0,0,0,0,0,0,0
0,0,0,0,0,0,0,0,0,0,0,0,0,0,0,0,0,0,0,0,0,0,0,0,0,0,0,0,0,0,0,0
0,0,0,0,0,0,0,0,0,0,0,0,0,0,0,0,0,0,0,0,0,0,0,0,0,0,0,0,0,0,0,0
0,0,0,0,0,0,0,0,0,0,0,0,0,0,0,0,0,0,0,0,0,0,0,0,0,0,0,0,0,0,0,0
0,0,0,0,0,0,0,0,0,0,0,0,0,0,0,0,0,0,0,0,0,0,0,0,0,0,0,0,0,0,0,0
0,0,0,0,0,0,0,0,0,0,0,0,0,0,0,0,0,0,0,0,0,0,0,0,0,0,0,0,0,0,0,0
0,0,0,0,0,0,0,0,0,0,0,0,0,0,0,0,0,0,0,0,0,0,0,0,0,0,0,0,0,0,0,0
0,0,0,0,0,0,0,0,0,0,0,0,0,0,0,0,0,0,0,0,0,0,0,0,0,0,0,0,0,0,0,0
0,0,0,0,0,0,0,0,0,0,0,0,0,0,0,0,0,0,0,0,0,0,0,0,0,0,0,0,0,0,0,0
0,0,0,0,0,0,0,0,0,0,0,0,0,0,0,0,0,0,0,0,0,0,0,0,0,0,0,0,0,0,0,0
0,0,0,0,0,0,0,0,0,0,0,0,0,0,0,0,0,0,0,0,0,0,0,0,0,0,0,0,0,0,0,0
0,0,0,0,0,0,0,0,0,0,0,0,0,0,0,0,0,0,0,0,0,0,0,0,0,0,0,0,0,0,0,0
endlayer

layer
0,0,0,0,0,0,0,0,0,0,0,0,0,0,0,0,0,0,0,0,0,0,0,0,0,0,0,0,0,0,0,0
0,0,0,0,0,0,0,0,0,0,0,0,0,0,0,0,0,0,0,0,0,0,0,0,0,0,0,0,0,0,0,0
0,0,0,0,0,0,0,0,0,0,65,22,65,22,65,0,0,0,0,0,0,0,0,0,0,0,0,0,0,0,0,0
0,0,0,0,0,0,0,0,0,65,0,0,0,0,0,65,0,0,0,0,0,0,0,0,0,0,0,0,0,0,0,0
0,0,0,0,0,0,0,0,65,0,0,0,0,0,0,0,65,0,0,0,0,0,0,0,0,0,0,0,0,0,0,0
0,0,0,0,0,0,0,65,0,0,0,0,0,0,0,0,0,65,0,0,0,0,13,0,0,0,0,0,0,0,0,0
0,0,0,0,0,0,65,0,0,0,6,0,0,0,0,0,0,0,65,0,0,0,0,0,0,0,0,0,0,0,0,0
0,0,0,0,0,0,22,0,0,0,0,0,0,0,0,0,0,0,22,0,0,0,0,0,0,0,0,0,0,0,0,0
0,0,0,0,0,0,65,0,0,0,0,0,0,0,0,0,0,0,65,0,0,13,0,0,0,0,0,0,0,0,0,0
0,0,0,0,0,0,22,0,0,0,0,0,0,0,0,0,0,0,22,0,0,0,0,0,0,0,0,0,0,0,0,0
0,0,0,0,0,0,65,0,0,0,0,0,0,0,0,0,0,0,65,0,0,0,0,0,0,0,0,0,0,0,0,0
0,0,0,0,0,0,0,65,0,0,0,0,0,0,0,0,0,65,0,0,0,0,0,0,0,0,0,0,0,0,0,0
0,0,0,0,0,0,0,0,65,0,0,0,0,0,0,0,65,0,0,0,0,0,0,0,0,0,0,0,0,0,0,0
0,0,0,0,0,0,0,0,0,65,0,0,0,0,0,65,0,0,0,0,0,0,0,0,0,0,0,0,0,0,0,0
0,0,0,0,0,0,0,0,0,0,65,22,65,22,65,0,0,0,0,0,0,0,0,0,0,0,0,0,0,0,0,0
0,0,0,0,0,0,0,0,0,0,0,0,0,0,0,0,0,0,0,0,0,0,0,0,0,0,0,0,0,0,0,0
0,0,0,0,0,0,0,0,0,0,0,0,0,0,0,0,0,0,0,0,0,0,0,0,0,0,0,0,0,0,0,0
0,0,0,0,0,0,0,0,0,0,0,0,0,0,0,0,0,0,0,0,0,0,0,0,0,0,0,13,0,0,0,0
0,0,0,0,0,0,0,0,0,0,0,0,0,0,0,0,0,0,0,0,0,0,0,0,0,0,0,0,0,0,0,0
0,0,0,0,0,0,0,0,0,0,0,0,0,0,0,0,0,0,0,0,0,0,0,0,0,0,0,0,0,0,0,0
0,0,0,0,0,0,0,0,0,0,0,0,0,0,0,0,0,0,0,0,0,0,0,0,0,0,0,0,0,0,0,0
0,0,0,0,0,0,0,0,0,0,0,0,0,0,0,0,0,0,0,0,0,0,0,0,0,0,0,0,0,0,0,0
0,0,0,0,0,0,0,0,0,0,0,0,0,0,0,0,0,0,0,0,0,0,0,0,0,0,0,0,0,0,0,0
0,0,0,0,0,0,0,0,0,0,0,0,0,0,0,0,0,0,0,0,0,0,0,0,0,0,0,0,0,0,0,0
0,0,0,0,0,0,0,0,0,0,0,0,0,0,0,0,0,0,0,0,0,0,0,0,0,0,0,0,0,0,0,0
0,0,0,0,0,0,0,0,0,0,0,0,0,0,0,0,0,0,0,0,0,0,0,0,0,0,0,0,0,0,0,0
0,0,0,0,0,0,0,0,0,0,0,0,0,0,0,0,0,0,0,0,0,0,0,0,0,0,0,0,0,0,0,0
0,0,0,0,0,0,0,0,0,0,0,0,0,0,0,0,0,0,0,0,0,0,0,0,0,0,0,0,0,0,0,0
0,0,0,0,0,0,0,0,0,0,0,0,0,0,0,0,0,0,0,0,0,0,0,0,0,0,0,0,0,0,0,0
0,0,0,0,0,0,0,0,0,0,0,0,0,0,0,0,0,0,0,0,0,0,0,0,0,0,0,0,0,0,0,0
endlayer

layer
0,0,0,0,0,0,0,0,13,13,0,0,0,0,0,0,0,0,0,0,0,0,0,0,0,0,0,0,0,0,0,0
0,0,0,0,0,0,0,0,0,0,0,0,0,0,0,0,0,0,0,0,0,0,0,0,0,0,0,0,0,0,0,0
0,0,0,0,0,0,0,0,0,0,65,0,65,0,65,0,0,0,0,0,0,0,0,0,0,0,0,0,0,0,0,0
0,0,0,0,0,0,0,0,0,0,0,0,0,0,0,0,0,0,0,0,0,0,0,0,0,0,0,0,0,0,0,0
0,0,0,0,0,0,0,0,65,0,0,0,0,0,0,0,65,0,0,0,0,0,0,0,0,0,0,0,0,0,0,0
0,0,0,0,0,0,0,0,0,0,0,0,0,0,0,0,0,0,0,0,0,0,0,0,0,0,0,13,0,0,0,0
0,0,0,0,0,0,65,0,0,0,14,0,0,0,0,0,0,0,65,0,0,0,0,0,0,0,0,0,0,0,0,0
0,0,0,0,0,0,0,0,0,0,0,0,0,0,0,0,0,0,0,0,0,0,0,0,0,0,0,0,0,0,0,0
0,0,0,0,0,0,65,0,0,0,0,0,0,0,0,0,0,0,65,0,0,0,0,0,0,0,0,0,0,0,0,0
0,0,0,0,0,0,0,0,0,0,0,0,0,0,0,0,0,0,0,0,0,0,0,0,0,0,0,0,0,0,0,0
0,0,0,0,0,0,65,0,0,0,0,0,0,0,0,0,0,0,65,0,0,0,0,0,0,0,0,0,0,0,0,0
0,0,0,0,0,0,0,0,0,0,0,0,0,0,0,0,0,0,0,0,0,0,0,0,0,0,0,0,0,0,0,0
0,0,0,0,0,0,0,0,65,0,0,0,0,0,0,0,65,0,0,0,0,0,0,0,0,0,0,13,0,0,0,0
0,0,0,0,0,0,0,0,0,0,0,0,0,0,0,0,0,0,0,0,0,0,0,0,0,0,0,0,0,0,0,0
0,0,0,0,0,0,0,0,0,0,65,0,65,0,65,0,0,0,0,0,0,0,0,0,0,0,0,0,0,0,0,0
0,0,0,0,0,0,0,0,0,0,0,0,0,0,0,0,0,0,0,0,0,0,0,0,0,0,0,0,0,0,0,0
0,0,0,0,0,0,0,0,0,0,0,0,0,0,0,0,0,0,0,0,0,0,0,0,0,0,0,0,0,0,0,0
0,0,0,0,0,0,0,0,0,0,0,0,0,0,0,0,0,0,0,0,0,0,0,0,0,0,0,0,0,0,0,0
0,0,0,0,0,0,0,0,0,0,0,0,0,0,0,0,0,0,0,0,0,0,0,0,0,0,0,0,0,0,0,0
0,0,0,0,0,0,0,0,0,0,0,0,0,0,0,0,0,0,0,0,0,0,0,0,0,0,0,0,0,0,0,0
0,0,0,0,0,0,0,0,0,0,0,0,0,0,0,0,0,0,0,0,0,0,0,0,0,0,0,0,0,0,0,0
0,0,0,0,0,0,0,0,0,0,0,0,0,0,0,0,0,0,0,0,0,0,0,0,0,0,0,0,0,0,0,0
0,0,0,0,0,0,0,0,0,0,0,0,0,0,0,0,0,0,0,0,0,0,0,0,0,0,0,0,0,0,0,0
0,0,0,0,0,0,0,0,0,0,0,0,0,0,0,0,0,0,0,0,0,0,0,0,0,0,0,0,0,0,0,0
0,0,0,0,0,0,0,0,0,0,0,0,0,0,0,0,0,0,0,0,0,0,0,0,0,0,0,0,0,0,0,0
0,0,0,0,0,0,0,0,0,0,0,0,0,0,0,0,0,0,0,0,0,0,0,0,0,0,0,0,0,0,0,0
0,0,0,0,0,0,0,0,0,0,0,0,0,0,0,0,0,0,0,0,0,0,0,0,0,0,0,0,0,0,0,0
0,0,0,0,0,0,0,0,0,0,0,0,0,0,0,0,0,0,0,0,0,0,0,0,0,0,0,0,0,0,0,0
0,0,0,0,0,0,0,0,0,0,0,0,0,0,0,0,0,0,0,0,0,0,0,0,0,0,0,0,0,0,0,0
0,0,0,0,0,0,0,0,0,0,0,0,0,0,0,0,0,0,0,0,0,0,0,0,0,0,0,0,0,0,0,0
endlayer

layer
0,0,0,0,0,0,0,0,0,0,0,0,0,0,0,0,0,0,0,0,0,0,0,0,0,0,0,0,0,0,0,0
0,0,0,0,0,0,0,0,0,0,0,0,0,0,0,0,0,0,0,0,0,0,0,0,0,0,0,0,0,0,0,0
0,0,0,0,0,0,0,0,0,0,0,0,0,0,0,0,0,0,0,0,0,0,0,0,0,0,0,0,0,0,0,0
0,0,0,0,0,0,0,0,0,0,0,0,0,0,0,0,0,0,0,0,0,0,0,0,0,0,0,0,0,0,0,0
0,0,0,0,0,0,0,0,0,0,0,13,13,0,0,0,0,0,0,0,0,0,0,0,0,0,0,0,0,0,0,0
0,0,0,0,0,0,0,0,0,0,0,0,0,0,0,0,0,0,13,0,0,0,0,0,0,0,0,0,0,0,0,0
0,0,0,0,0,0,0,0,13,0,14,0,0,0,0,0,0,0,0,0,0,0,0,0,0,0,0,0,0,0,0,0
0,0,0,0,0,0,0,0,0,0,0,0,0,0,0,0,0,0,0,0,0,0,0,0,0,0,0,0,0,0,0,0
0,0,0,0,0,0,0,0,0,0,0,0,0,0,0,0,0,0,0,0,0,0,0,0,0,0,0,0,0,0,0,0
0,0,0,0,0,0,0,0,13,0,0,0,0,0,0,13,0,0,0,0,0,0,0,0,0,0,0,0,0,0,0,0
0,0,0,0,0,0,0,0,0,13,0,0,0,0,0,0,0,0,0,0,0,0,0,0,0,0,0,0,0,0,0,0
0,0,0,0,0,0,0,0,0,0,0,0,0,13,0,0,0,0,0,0,0,0,0,0,0,0,0,0,0,0,0,0
0,0,0,0,0,0,0,0,0,0,0,0,0,0,0,0,0,0,0,0,0,0,0,0,0,0,0,0,0,0,0,0
0,0,0,0,0,0,0,0,0,0,0,0,0,0,0,0,0,0,0,0,0,0,0,0,0,0,0,0,0,0,0,0
0,0,0,0,0,0,0,0,0,0,0,0,0,0,0,0,0,0,0,0,0,0,0,0,0,0,0,0,0,0,0,0
0,0,0,0,0,0,0,0,0,0,0,0,0,0,0,0,0,0,0,0,0,0,0,0,0,0,0,0,0,0,0,0
0,0,0,0,0,0,0,0,0,0,0,0,0,0,0,0,0,0,0,0,0,0,0,0,0,0,0,0,0,0,0,0
0,0,0,0,0,0,0,0,0,0,0,0,0,0,0,0,0,0,0,0,0,0,0,0,0,0,0,0,0,0,0,0
0,0,0,0,0,0,0,0,0,0,0,0,0,0,0,0,0,0,0,0,0,0,0,0,0,0,0,0,0,0,0,0
0,0,0,0,0,0,0,0,0,0,0,0,0,0,0,0,0,0,0,0,0,0,0,0,0,0,0,0,0,0,0,0
0,0,0,0,0,0,0,0,0,0,0,0,0,0,0,0,0,0,0,0,0,0,0,0,0,0,0,0,0,0,0,0
0,0,0,0,0,0,0,0,0,0,0,0,0,0,0,0,0,0,0,0,0,0,0,0,0,0,0,0,0,0,0,0
0,0,0,0,0,0,0,0,0,0,0,0,0,0,0,0,0,0,0,0,0,0,0,0,0,0,0,0,0,0,0,0
0,0,0,0,0,0,0,0,0,0,0,0,0,0,0,0,0,0,0,0,0,0,0,0,0,0,0,0,0,0,0,0
0,0,0,0,0,0,0,0,0,0,0,0,0,0,0,0,0,0,0,0,0,0,0,0,0,0,0,0,0,0,0,0
0,0,0,0,0,0,0,0,0,0,0,0,0,0,0,0,0,0,0,0,0,0,0,0,0,0,0,0,0,0,0,0
0,0,0,0,0,0,0,0,0,0,0,0,0,0,0,0,0,0,0,0,0,0,0,0,0,0,0,0,0,0,0,0
0,0,0,0,0,0,0,0,0,0,0,0,0,0,0,0,0,0,0,0,0,0,0,0,0,0,0,0,0,0,0,0
0,0,0,0,0,0,0,0,0,0,0,0,0,0,0,0,0,0,0,0,0,0,0,0,0,0,0,0,0,0,0,0
0,0,0,0,0,0,0,0,0,0,0,0,0,0,0,0,0,0,0,0,0,0,0,0,0,0,0,0,0,0,0,0
endlayer

layer
0,0,0,0,0,0,0,0,0,0,0,0,0,0,0,0,0,0,0,0,0,0,0,0,0,0,0,0,0,0,0,0
0,0,0,0,0,0,0,0,0,0,0,0,0,0,0,0,0,0,0,0,0,0,0,0,0,0,0,0,0,0,0,0
0,0,0,0,0,0,0,0,0,0,0,0,0,0,0,0,0,0,0,0,0,0,0,0,0,0,0,0,0,0,0,0
0,0,0,0,0,13,0,0,0,0,0,0,0,0,0,0,0,0,0,0,0,0,0,0,0,0,0,0,0,0,0,0
0,0,0,0,0,0,0,0,0,0,0,0,0,0,0,0,0,0,0,0,0,0,0,0,0,0,0,0,0,0,0,0
0,0,0,0,0,0,0,0,0,0,0,0,0,0,0,0,0,0,0,0,0,0,0,0,0,0,0,0,0,0,0,0
0,0,0,0,0,0,0,0,0,0,14,0,0,0,0,0,0,0,0,0,0,0,0,0,0,0,0,0,0,0,0,0
0,0,0,0,0,0,0,0,0,0,0,0,0,0,0,0,0,0,0,0,0,0,0,0,0,0,0,0,0,0,0,0
0,0,0,0,0,0,0,0,0,0,0,0,0,0,0,0,0,0,0,0,0,0,0,0,0,0,0,0,0,0,0,0
0,0,0,0,0,0,0,0,0,0,0,0,0,0,0,0,0,0,0,0,0,0,0,0,0,0,0,0,0,0,0,0
0,0,0,0,0,0,0,0,0,0,0,0,0,0,0,0,0,0,0,0,0,0,0,0,0,0,0,0,0,0,0,0
0,0,0,0,0,0,0,0,0,0,0,0,0,0,0,0,0,0,0,0,0,0,0,0,0,0,0,0,0,0,0,0
0,0,0,0,0,0,0,0,0,0,0,0,0,0,0,0,0,0,0,0,0,0,0,0,0,0,0,0,0,0,0,0
0,0,0,0,0,0,0,0,0,0,0,0,0,0,0,0,0,0,0,0,0,0,0,0,0,0,0,0,0,0,0,0
0,0,0,0,0,0,0,0,0,0,0,0,0,0,0,0,0,0,0,0,0,0,0,0,0,0,0,0,0,0,0,0
0,0,0,0,0,0,0,0,0,0,0,0,0,0,0,0,0,0,0,0,0,0,0,0,0,0,0,0,0,0,0,0
0,0,0,0,0,0,0,0,0,0,0,0,0,0,0,0,0,0,0,0,0,0,0,0,0,0,0,0,0,0,0,0
0,0,0,0,0,0,0,0,0,0,0,0,0,0,0,0,0,0,0,0,0,0,0,0,0,0,0,0,0,0,0,0
0,0,0,0,0,0,0,0,0,0,0,0,0,0,0,0,0,0,0,0,0,0,0,0,0,0,0,0,0,0,0,0
0,0,0,0,0,0,0,0,0,0,0,0,0,0,0,0,0,0,0,0,0,0,0,0,0,0,0,0,0,0,0,0
0,0,0,0,0,0,0,0,0,0,0,0,0,0,0,0,0,0,0,0,0,0,0,0,0,0,0,0,0,0,0,0
0,0,0,0,0,0,0,0,0,0,0,0,0,0,0,0,0,0,0,0,0,0,0,0,0,0,0,0,0,0,0,0
0,0,0,0,0,0,0,0,0,0,0,0,0,0,0,0,0,0,0,0,0,0,0,0,0,0,0,0,0,0,0,0
0,0,0,0,0,0,0,0,0,0,0,0,0,0,0,0,0,0,0,0,0,0,0,0,0,0,0,0,0,0,0,0
0,0,0,0,0,0,0,0,0,0,0,0,0,0,0,0,0,0,0,0,0,0,0,0,0,0,0,0,0,0,0,0
0,0,0,0,0,0,0,0,0,0,0,0,0,0,0,0,0,0,0,0,0,0,0,0,0,0,0,0,0,0,0,0
0,0,0,0,0,0,0,0,0,0,0,0,0,0,0,0,0,0,0,0,0,0,0,0,0,0,0,0,0,0,0,0
0,0,0,0,0,0,0,0,0,0,0,0,0,0,0,0,0,0,0,0,0,0,0,0,0,0,0,0,0,0,0,0
0,0,0,0,0,0,0,0,0,0,0,0,0,0,0,0,0,0,0,0,0,0,0,0,0,0,0,0,0,0,0,0
0,0,0,0,0,0,0,0,0,0,0,0,0,0,0,0,0,0,0,0,0,0,0,0,0,0,0,0,0,0,0,0
endlayer

layer
0,0,0,0,0,0,0,0,0,0,0,0,0,0,0,0,0,0,0,0,0,0,0,0,0,0,0,0,0,0,0,0
0,0,0,0,0,0,0,0,0,0,0,0,0,0,0,0,0,0,0,0,0,0,0,0,0,0,0,0,0,0,0,0
0,0,0,0,0,0,0,0,0,0,0,0,0,0,0,0,0,0,0,0,0,0,0,0,0,0,0,0,0,0,0,0
0,0,0,0,0,0,0,0,0,0,0,0,0,0,0,0,0,0,0,0,0,0,0,0,0,0,0,0,0,0,0,0
0,0,0,0,0,0,0,0,0,0,0,0,0,0,0,0,0,0,0,0,0,0,0,0,0,0,0,0,0,0,0,0
0,0,0,0,0,0,0,0,0,0,0,0,0,0,0,0,0,0,0,0,0,0,0,0,0,0,0,0,0,0,0,0
0,0,0,0,0,0,0,0,0,0,14,0,0,0,0,0,0,0,0,0,0,0,0,0,0,0,0,0,0,0,0,0
0,0,0,0,0,0,0,0,0,0,0,0,0,0,0,0,13,0,0,0,0,0,0,0,0,0,0,0,0,0,0,0
0,0,0,0,0,0,0,0,0,0,0,0,0,0,0,0,0,0,0,0,0,0,0,0,0,0,0,0,0,0,0,0
0,0,0,0,0,0,0,0,0,0,0,0,0,0,0,0,0,0,0,0,0,0,13,0,0,0,0,0,0,0,0,0
0,0,0,0,0,0,0,0,0,0,0,0,0,0,0,0,0,0,0,0,0,0,0,0,0,0,0,0,0,0,0,0
0,0,0,0,0,0,0,0,13,0,0,0,0,0,0,0,0,0,0,0,0,0,0,0,0,0,0,0,0,0,0,0
0,0,0,0,0,0,0,0,0,0,0,0,0,0,0,0,0,0,0,0,0,0,0,0,0,0,0,0,0,0,0,0
0,0,0,0,0,0,0,0,0,0,0,0,0,0,0,0,0,0,0,0,0,0,0,0,0,0,0,0,0,0,0,0
0,0,0,0,0,0,0,0,0,0,0,0,0,0,0,0,0,0,0,0,0,0,0,0,0,0,0,0,0,0,0,0
0,0,0,0,0,0,0,0,0,0,0,0,0,0,0,0,0,0,0,0,0,0,0,0,0,0,0,0,0,0,0,0
0,0,0,0,0,0,0,0,0,0,0,0,0,0,0,0,0,0,0,0,0,0,0,0,0,0,0,0,0,0,0,0
0,0,0,0,0,0,0,0,0,0,0,0,0,0,0,0,0,0,0,0,0,0,0,0,0,0,0,0,0,0,0,0
0,0,0,0,0,0,0,0,0,0,0,0,0,0,0,0,0,0,0,0,0,0,0,0,0,0,0,0,0,0,0,0
0,0,0,0,0,0,0,0,0,0,0,0,0,0,0,0,0,0,0,0,0,0,0,0,0,0,0,0,0,0,0,0
0,0,0,0,0,0,0,0,0,0,0,0,0,0,0,0,0,0,0,0,0,0,0,0,0,0,0,0,0,0,0,0
0,0,0,0,0,0,0,0,0,0,0,0,0,0,0,0,0,0,0,0,0,0,0,0,0,0,0,0,0,0,0,0
0,0,0,0,0,0,0,0,0,0,0,0,0,0,0,0,0,0,0,0,0,0,0,0,0,0,0,0,0,0,0,0
0,0,0,0,0,0,0,0,0,0,0,0,0,0,0,0,0,0,0,0,0,0,0,0,0,0,0,0,0,0,0,0
0,0,0,0,0,0,0,0,0,0,0,0,0,0,0,0,0,0,0,0,0,0,0,0,0,0,0,0,0,0,0,0
0,0,0,0,0,0,0,0,0,0,0,0,0,0,0,0,0,0,0,0,0,0,0,0,0,0,0,0,0,0,0,0
0,0,0,0,0,0,0,0,0,0,0,0,0,0,0,0,0,0,0,0,0,0,0,0,0,0,0,0,0,0,0,0
0,0,0,0,0,0,0,0,0,0,0,0,0,0,0,0,0,0,0,0,0,0,0,0,0,0,0,0,0,0,0,0
0,0,0,0,0,0,0,0,0,0,0,0,0,0,0,0,0,0,0,0,0,0,0,0,0,0,0,0,0,0,0,0
0,0,0,0,0,0,0,0,0,0,0,0,0,0,0,0,0,0,0,0,0,0,0,0,0,0,0,0,0,0,0,0
endlayer

layer
0,0,0,0,0,0,0,0,0,0,0,0,0,0,0,0,0,0,0,0,0,0,0,0,0,0,0,0,0,0,0,0
0,0,0,0,0,0,0,0,0,0,0,0,0,0,0,0,0,0,0,0,0,0,0,0,0,0,0,0,0,0,0,0
0,0,0,0,0,0,0,0,0,0,0,0,0,0,0,0,0,0,0,0,0,0,0,0,0,0,0,0,0,0,0,0
0,0,0,0,0,0,0,0,0,0,0,0,0,0,0,0,0,0,0,0,0,0,0,0,0,0,0,0,0,0,0,0
0,0,0,0,0,0,0,0,0,0,0,0,0,0,0,0,0,0,0,0,0,0,0,0,0,0,0,0,0,0,0,0
0,0,0,0,0,0,0,0,0,0,0,0,0,0,0,0,0,0,0,0,0,0,0,0,0,0,0,0,0,0,0,0
0,0,0,0,0,0,0,0,0,0,14,0,0,0,0,0,0,0,0,0,0,0,0,0,0,0,0,0,0,0,0,0
0,0,0,0,0,0,0,0,0,0,0,0,0,0,0,0,0,0,0,0,0,0,0,0,0,0,0,0,0,0,0,0
0,0,0,0,0,0,0,0,0,0,0,0,0,0,0,0,0,0,0,0,0,0,0,0,0,0,0,0,0,0,0,0
0,0,0,0,0,0,0,0,0,0,0,0,0,0,0,0,0,0,0,0,0,0,0,0,0,0,0,0,0,0,13,0
0,0,0,0,0,0,0,0,0,0,0,0,0,0,0,0,0,0,0,0,0,0,0,0,0,0,0,0,0,0,0,0
0,0,0,0,0,0,0,0,0,0,0,0,0,0,0,0,0,0,0,0,0,0,0,0,0,0,0,0,0,0,0,0
0,0,0,0,0,0,0,0,0,0,0,0,0,0,0,0,0,0,0,0,0,0,0,0,0,0,0,0,0,0,0,0
0,0,0,0,0,0,0,0,0,0,0,0,0,0,0,0,0,0,0,0,0,0,0,0,0,0,0,0,0,0,0,0
0,0,0,0,0,0,0,0,0,0,0,0,0,0,0,0,0,0,0,0,0,0,0,0,0,0,0,0,0,0,0,0
0,0,0,0,0,0,0,0,0,0,0,0,0,0,0,0,0,0,0,0,0,0,0,0,0,0,0,0,0,0,0,0
0,0,0,0,0,0,0,0,0,0,0,0,0,0,0,0,0,0,0,0,0,0,0,0,0,0,0,0,0,0,0,0
0,0,0,0,0,0,0,0,0,0,0,0,0,0,0,0,0,0,0,0,0,0,0,0,0,0,0,0,0,0,0,0
0,0,0,0,0,0,0,0,0,0,0,0,0,0,0,0,0,0,0,0,0,0,0,0,0,0,0,0,0,0,0,0
0,0,0,0,0,0,0,0,0,0,0,0,0,0,0,0,0,0,0,0,0,0,0,0,0,0,0,0,0,0,0,0
0,0,0,0,0,0,0,0,0,0,0,0,0,0,0,0,0,0,0,0,0,0,0,0,0,0,0,0,0,0,0,0
0,0,0,0,0,0,0,0,0,0,0,0,0,0,0,0,0,0,0,0,0,0,0,0,0,0,0,0,0,0,0,0
0,0,0,0,0,0,0,0,0,0,0,0,0,0,0,0,0,0,0,0,0,0,0,0,0,0,0,0,0,0,0,0
0,0,0,0,0,0,0,0,0,0,0,0,0,0,0,0,0,0,0,0,0,0,0,0,0,0,0,0,0,0,0,0
0,0,0,0,0,0,0,0,0,0,0,0,0,0,0,0,0,0,0,0,0,0,0,0,0,0,0,0,0,0,0,0
0,0,0,0,0,0,0,0,0,0,0,0,0,0,0,0,0,0,0,0,0,0,0,0,0,0,0,0,0,0,0,0
0,0,0,0,0,0,0,0,0,0,0,0,0,0,0,0,0,0,0,0,0,0,0,0,0,0,0,0,0,0,0,0
0,0,0,0,0,0,0,0,0,0,0,0,0,0,0,0,0,0,0,0,0,0,0,0,0,0,0,0,0,0,0,0
0,0,0,0,0,0,0,0,0,0,0,0,0,0,0,0,0,0,0,0,0,0,0,0,0,0,0,0,0,0,0,0
0,0,0,0,0,0,0,0,0,0,0,0,0,0,0,0,0,0,0,0,0,0,0,0,0,0,0,0,0,0,0,0
endlayer

layer
0,0,0,0,0,0,0,0,0,0,0,0,0,0,0,0,0,0,0,0,0,0,0,0,0,0,0,0,0,0,0,0
0,0,0,0,0,0,0,0,0,0,0,0,0,0,0,0,0,0,0,0,0,0,0,0,0,0,0,0,0,0,0,0
0,0,0,0,0,0,0,0,0,0,0,0,0,0,0,0,0,0,0,0,0,0,0,0,0,0,0,0,0,0,0,0
0,0,0,0,0,0,0,0,0,0,0,0,0,0,0,0,0,0,0,0,0,0,0,0,0,0,0,0,0,0,0,0
0,0,0,0,0,0,0,0,0,0,0,0,0,0,0,0,0,0,0,0,0,0,0,0,0,0,0,0,0,0,0,0
0,0,0,0,0,0,0,0,0,0,66,0,0,0,0,0,0,0,0,0,0,0,0,0,0,0,0,0,0,0,0,0
0,0,0,0,0,0,0,0,0,69,68,67,0,0,0,0,0,0,0,0,0,0,0,0,0,0,0,0,0,0,0,0
0,0,0,0,0,0,0,0,0,0,71,70,68,0,0,0,0,0,0,0,0,0,0,0,0,0,0,0,0,0,0,0
0,0,0,0,0,0,0,0,0,0,0,0,0,70,68,0,0,0,0,0,0,0,0,0,0,0,0,0,0,0,0,0
0,0,0,0,0,0,0,0,0,0,0,0,0,0,0,0,0,0,0,0,0,0,0,0,0,0,0,0,0,0,0,0
0,0,0,0,0,0,0,0,0,0,0,0,0,0,0,0,0,0,0,0,0,0,0,0,0,0,0,0,0,0,0,0
0,0,0,0,0,0,0,0,0,0,0,0,0,0,0,0,0,0,0,0,0,0,0,0,0,0,0,0,0,0,0,0
0,0,0,0,0,0,0,0,0,0,0,0,0,0,0,0,0,0,0,0,0,0,0,0,0,0,0,0,0,0,0,0
0,0,0,0,0,0,0,0,0,0,0,0,0,0,0,0,0,0,0,0,0,0,0,0,0,0,0,0,0,0,0,0
0,0,0,0,0,0,0,0,0,0,0,0,0,0,0,0,0,0,0,0,0,0,0,0,0,0,0,0,0,0,0,0
0,0,0,0,0,0,0,0,0,0,0,0,0,0,0,0,0,0,0,0,0,0,0,0,0,0,0,0,0,0,0,0
0,0,0,0,0,0,0,0,0,0,0,0,0,0,0,0,0,0,0,0,0,0,0,0,0,0,0,0,0,0,0,0
0,0,0,0,0,0,0,0,0,0,0,0,0,0,0,0,0,0,0,0,0,0,0,0,0,0,0,0,0,0,0,0
0,0,0,0,0,0,0,0,0,0,0,0,0,0,0,0,0,0,0,0,0,0,0,0,0,0,0,0,0,0,0,0
0,0,0,0,0,0,0,0,0,0,0,0,0,0,0,0,0,0,0,0,0,0,0,0,0,0,0,0,0,0,0,0
0,0,0,0,0,0,0,0,0,0,0,0,0,0,0,0,0,0,0,0,0,0,0,0,0,0,0,0,0,0,0,0
0,0,0,0,0,0,0,0,0,0,0,0,0,0,0,0,0,0,0,0,0,0,0,0,0,0,0,0,0,0,0,0
0,0,0,0,0,0,0,0,0,0,0,0,0,0,0,0,0,0,0,0,0,0,0,0,0,0,0,0,0,0,0,0
0,0,0,0,0,0,0,0,0,0,0,0,0,0,0,0,0,0,0,0,0,0,0,0,0,0,0,0,0,0,0,0
0,0,0,0,0,0,0,0,0,0,0,0,0,0,0,0,0,0,0,0,0,0,0,0,0,0,0,0,0,0,0,0
0,0,0,0,0,0,0,0,0,0,0,0,0,0,0,0,0,0,0,0,0,0,0,0,0,0,0,0,0,0,0,0
0,0,0,0,0,0,0,0,0,0,0,0,0,0,0,0,0,0,0,0,0,0,0,0,0,0,0,0,0,0,0,0
0,0,0,0,0,0,0,0,0,0,0,0,0,0,0,0,0,0,0,0,0,0,0,0,0,0,0,0,0,0,0,0
0,0,0,0,0,0,0,0,0,0,0,0,0,0,0,0,0,0,0,0,0,0,0,0,0,0,0,0,0,0,0,0
0,0,0,0,0,0,0,0,0,0,0,0,0,0,0,0,0,0,0,0,0,0,0,0,0,0,0,0,0,0,0,0
endlayer

layer
0,0,0,0,0,0,0,0,0,0,0,0,0,0,0,0,0,0,0,0,0,0,0,0,0,0,0,0,0,0,0,0
0,0,0,0,0,0,0,0,0,0,0,0,0,0,0,0,0,0,0,0,0,0,0,0,0,0,0,0,0,0,0,0
0,0,0,0,0,0,0,0,0,0,0,0,0,0,0,0,0,0,0,0,0,0,0,0,0,0,0,0,0,0,0,0
0,0,0,0,0,0,0,0,0,0,0,0,0,0,0,0,0,0,0,0,0,0,0,0,0,0,0,0,0,0,0,0
0,0,0,0,0,0,0,0,0,0,0,0,0,0,0,0,0,0,0,0,0,0,0,0,0,0,0,0,0,0,0,0
0,0,0,0,0,0,0,0,0,0,0,0,0,0,0,0,0,0,0,0,0,0,0,0,0,0,0,0,0,0,0,0
0,0,0,0,0,0,0,0,0,0,58,0,0,0,0,0,0,0,0,0,0,0,0,0,0,0,0,0,0,0,0,0
0,0,0,0,0,0,0,0,0,0,0,0,0,0,0,0,0,0,0,0,0,0,0,0,0,0,0,0,0,0,0,0
0,0,0,0,0,0,0,0,0,0,0,0,0,0,0,0,0,0,0,0,0,0,0,0,0,0,0,0,0,0,0,0
0,0,0,0,0,0,0,0,0,0,0,0,0,0,0,0,0,0,0,0,0,0,0,0,0,0,0,0,0,0,0,0
0,0,0,0,0,0,0,0,0,0,0,0,0,0,0,0,0,0,0,0,0,0,0,0,0,0,0,0,0,0,0,0
0,0,0,0,0,0,0,0,0,0,0,0,0,0,0,0,0,0,0,0,0,0,0,0,0,0,0,0,0,0,0,0
0,0,0,0,0,0,0,0,0,0,0,0,0,0,0,0,0,0,0,0,0,0,0,0,0,0,0,0,0,0,0,0
0,0,0,0,0,0,0,0,0,0,0,0,0,0,0,0,0,0,0,0,0,0,0,0,0,0,0,0,0,0,0,0
0,0,0,0,0,0,0,0,0,0,0,0,0,0,0,0,0,0,0,0,0,0,0,0,0,0,0,0,0,0,0,0
0,0,0,0,0,0,0,0,0,0,0,0,0,0,0,0,0,0,0,0,0,0,0,0,0,0,0,0,0,0,0,0
0,0,0,0,0,0,0,0,0,0,0,0,0,0,0,0,0,0,0,0,0,0,0,0,0,0,0,0,0,0,0,0
0,0,0,0,0,0,0,0,0,0,0,0,0,0,0,0,0,0,0,0,0,0,0,0,0,0,0,0,0,0,0,0
0,0,0,0,0,0,0,0,0,0,0,0,0,0,0,0,0,0,0,0,0,0,0,0,0,0,0,0,0,0,0,0
0,0,0,0,0,0,0,0,0,0,0,0,0,0,0,0,0,0,0,0,0,0,0,0,0,0,0,0,0,0,0,0
0,0,0,0,0,0,0,0,0,0,0,0,0,0,0,0,0,0,0,0,0,0,0,0,0,0,0,0,0,0,0,0
0,0,0,0,0,0,0,0,0,0,0,0,0,0,0,0,0,0,0,0,0,0,0,0,0,0,0,0,0,0,0,0
0,0,0,0,0,0,0,0,0,0,0,0,0,0,0,0,0,0,0,0,0,0,0,0,0,0,0,0,0,0,0,0
0,0,0,0,0,0,0,0,0,0,0,0,0,0,0,0,0,0,0,0,0,0,0,0,0,0,0,0,0,0,0,0
0,0,0,0,0,0,0,0,0,0,0,0,0,0,0,0,0,0,0,0,0,0,0,0,0,0,0,0,0,0,0,0
0,0,0,0,0,0,0,0,0,0,0,0,0,0,0,0,0,0,0,0,0,0,0,0,0,0,0,0,0,0,0,0
0,0,0,0,0,0,0,0,0,0,0,0,0,0,0,0,0,0,0,0,0,0,0,0,0,0,0,0,0,0,0,0
0,0,0,0,0,0,0,0,0,0,0,0,0,0,0,0,0,0,0,0,0,0,0,0,0,0,0,0,0,0,0,0
0,0,0,0,0,0,0,0,0,0,0,0,0,0,0,0,0,0,0,0,0,0,0,0,0,0,0,0,0,0,0,0
0,0,0,0,0,0,0,0,0,0,0,0,0,0,0,0,0,0,0,0,0,0,0,0,0,0,0,0,0,0,0,0
endlayer

