
# Created by Ruins mod version 14.4 Ingame Parser
# authoring Player: Mikhaila666

weight=1
embed_into_distance=0
acceptable_target_blocks=
unacceptable_target_blocks=flowing_water,water,flowing_lava,lava
dimensions=26,9,11
allowable_overhang=0
max_leveling=2
leveling_buffer=0
preserve_water=0
preserve_lava=0

rule1=0,100,minecraft:stone-0
rule2=0,100,minecraft:dirt-0
rule3=0,100,minecraft:monster_egg-0
rule4=0,100,minecraft:grass-0
rule5=0,100,minecraft:bookshelf-0
rule6=0,100,Railcraft:tile.railcraft.residual.heat-0
rule7=0,100,minecraft:enchanting_table-0
rule8=0,100,IInventory;minecraft:chest;Metallurgy:metallurgy.tartarite.boots#1#0#0+Metallurgy:metallurgy.tartarite.leggings#1#0#1+Metallurgy:metallurgy.tartarite.helmet#1#0#2+TConstruct:heartCanister#5#6#3+TConstruct:heartCanister#5#2#4+TConstruct:heartCanister#5#4#5+TConstruct:pickaxe#1#0#6+TConstruct:broadsword#1#0#7+Metallurgy:metallurgy.tartarite.chestplate#1#0#8+TwilightForest:item.venisonCooked#16#0#9+TwilightForest:item.meefSteak#16#0#10+minecraft:cooked_beef#16#0#11+minecraft:golden_apple#16#0#12+enviromine:coldWaterBottle#1#0#13+enviromine:coldWaterBottle#1#0#14+enviromine:coldWaterBottle#1#0#15+Metallurgy:metallurgy.tartarite.chestplate#1#0#16+Metallurgy:metallurgy.tartarite.chestplate#1#0#17+Metallurgy:metallurgy.tartarite.chestplate#1#0#18+minecraft:water_bucket#1#0#19+minecraft:water_bucket#1#0#20+minecraft:water_bucket#1#0#21+minecraft:water_bucket#1#0#22+minecraft:water_bucket#1#0#23+minecraft:water_bucket#1#0#24-2

layer
0,0,0,1,1,1,1,1,1,1,1
0,0,1,1,1,1,1,1,1,1,1
0,0,1,1,1,1,1,1,1,1,1
0,1,1,1,1,1,1,1,1,1,1
0,2,1,1,1,1,1,1,1,1,1
0,2,1,1,1,1,1,1,1,1,1
0,2,2,1,1,1,1,1,1,1,1
0,2,2,1,1,1,1,1,1,1,1
0,2,2,2,2,1,1,1,3,1,1
endlayer

layer
0,0,0,0,1,1,1,1,1,1,1
0,0,0,1,1,1,1,1,1,1,1
0,0,1,1,1,1,1,1,1,1,1
0,1,1,1,1,1,1,1,1,1,1
4,2,1,1,1,1,1,1,1,1,1
4,2,2,1,1,1,1,1,1,1,1
4,2,2,1,1,1,1,1,1,3,1
4,4,2,2,1,1,1,1,3,1,1
4,4,2,2,2,1,3,1,1,1,1
endlayer

layer
0,0,0,0,1,1,1,1,1,1,1
0,0,0,1,1,1,1,1,1,1,1
0,0,0,1,1,1,1,1,1,1,1
0,0,1,1,1,1,3,1,1,1,1
0,4,1,1,1,1,3,3,1,1,1
0,4,2,2,1,1,3,3,1,3,1
0,4,2,2,1,1,1,1,3,1,1
0,0,2,2,2,1,3,3,3,1,1
0,0,2,2,2,3,3,3,3,1,1
endlayer

layer
0,0,0,0,1,1,1,1,1,1,1
0,0,0,1,1,1,1,1,1,1,1
0,0,1,1,1,1,3,1,1,1,1
0,0,1,1,1,5,5,5,5,5,1
0,0,1,1,1,5,0,0,0,0,3
0,0,2,2,1,5,6,7,6,6,1
0,0,2,2,1,5,0,0,6,6,1
0,0,2,2,2,5,0,0,0,6,1
0,0,1,1,2,3,3,3,3,1,1
endlayer

layer
0,0,0,0,1,1,1,1,1,1,1
0,0,1,1,1,1,1,1,1,1,1
0,0,1,1,1,1,1,1,1,1,1
0,0,1,1,1,5,5,5,5,5,1
0,0,1,1,1,5,0,0,0,0,1
0,0,2,2,1,5,0,0,0,6,1
0,0,1,2,1,5,0,0,6,0,1
0,0,1,2,2,5,0,0,0,6,1
0,0,1,1,1,1,3,3,3,1,1
endlayer

layer
0,0,1,1,1,1,1,1,1,1,1
0,0,1,1,1,1,1,1,1,1,1
0,0,1,1,1,1,1,1,1,1,1
0,0,1,1,1,5,5,5,5,5,1
0,0,1,1,1,5,1,1,1,1,1
0,0,1,4,1,5,1,0,1,1,1
0,0,1,4,1,5,1,1,1,1,1
0,0,1,1,4,5,1,1,1,1,1
0,0,1,1,1,1,3,3,3,1,1
endlayer

layer
0,0,1,1,1,1,1,1,1,1,1
0,0,1,6,0,0,6,6,0,0,1
0,0,1,0,6,6,0,6,6,0,1
0,0,1,0,6,6,6,6,6,0,1
0,0,1,8,0,6,6,6,6,0,1
0,0,1,6,0,6,6,6,6,0,1
0,0,1,0,0,6,6,0,6,0,1
0,0,1,0,0,6,0,0,0,0,1
0,0,1,1,1,1,1,1,1,1,1
endlayer

layer
0,0,0,0,0,0,0,0,0,0,0
0,0,0,0,0,0,0,0,0,0,0
0,0,0,0,0,0,0,0,0,0,0
0,0,0,0,0,6,0,0,0,0,0
0,0,0,0,0,0,0,0,0,0,0
0,0,0,0,0,0,0,0,0,0,0
0,0,0,0,0,0,0,0,0,0,0
0,0,0,0,0,0,0,0,0,0,0
0,0,0,0,0,0,0,0,0,0,0
endlayer

layer
0,0,0,0,0,0,0,0,0,0,0
0,0,0,0,0,0,0,0,0,0,0
0,0,0,0,0,0,0,0,0,0,6
0,0,0,0,0,0,0,0,0,0,0
0,0,0,0,0,0,0,0,0,0,0
0,0,0,0,0,0,0,0,6,6,0
0,0,0,0,0,0,0,0,0,0,0
0,0,0,0,0,0,0,0,0,6,0
0,0,0,0,0,0,0,0,0,0,0
endlayer

layer
0,0,0,0,0,0,0,0,0,0,0
0,0,0,0,0,0,0,0,0,0,0
0,0,6,0,0,0,0,0,6,0,0
0,0,0,0,0,0,0,6,0,0,0
0,0,0,0,0,0,0,0,6,0,0
0,0,0,0,0,0,0,0,0,0,0
0,0,0,0,0,0,0,0,0,0,0
0,0,0,0,0,0,0,0,0,0,0
0,0,0,0,0,0,0,0,0,0,0
endlayer

layer
0,0,0,0,0,0,0,0,0,0,0
0,0,0,0,0,0,0,0,0,0,0
0,0,0,0,0,0,0,0,0,0,0
0,0,0,0,0,6,0,0,0,0,0
0,0,0,0,0,0,0,0,0,0,0
0,0,0,0,0,0,0,0,0,0,0
0,0,0,0,0,6,0,0,0,0,0
0,0,0,0,0,0,0,0,0,0,0
0,0,0,0,0,0,0,0,0,0,0
endlayer

layer
0,0,0,0,0,0,0,0,0,0,0
0,0,0,0,0,0,0,0,0,0,0
0,0,0,0,0,0,0,0,0,0,0
0,0,0,0,0,0,0,0,0,0,0
0,0,0,0,0,0,0,0,0,0,0
0,0,0,0,0,0,0,0,0,0,0
0,0,0,0,0,0,0,0,0,0,0
0,0,0,0,0,0,0,0,0,0,0
0,0,0,0,0,0,0,0,0,0,0
endlayer

layer
0,0,0,0,0,0,0,0,0,0,0
0,0,0,0,0,0,0,0,0,0,0
0,0,0,0,0,0,0,0,0,0,0
0,0,0,0,0,0,0,0,0,0,0
0,0,0,0,0,0,0,0,0,0,0
0,0,0,0,0,0,0,0,0,0,0
0,0,0,0,0,0,0,0,0,0,0
0,0,0,0,0,0,0,0,0,0,0
0,0,0,0,0,0,0,0,0,0,0
endlayer

layer
0,0,0,0,0,0,0,0,0,0,0
0,0,0,0,0,0,0,0,0,0,0
0,0,0,0,0,0,0,0,0,0,0
0,0,0,0,0,0,0,0,0,0,0
0,0,0,0,0,0,0,0,0,0,0
0,0,0,0,0,0,0,0,0,0,0
0,0,0,0,0,0,0,0,0,0,0
0,0,0,0,0,0,0,0,0,0,0
0,0,0,0,0,0,0,0,0,0,0
endlayer

layer
0,0,0,0,0,0,0,0,0,0,0
0,0,0,0,0,0,0,0,0,0,0
0,0,0,0,0,0,0,0,0,0,0
0,0,0,0,0,0,0,0,0,0,0
0,0,0,0,0,0,0,0,0,0,0
0,0,0,0,0,0,0,0,0,0,0
0,0,0,0,0,0,0,0,0,0,0
0,0,0,0,0,0,0,0,0,0,0
0,0,0,0,0,0,0,0,0,0,0
endlayer

layer
0,0,0,0,0,0,0,0,0,0,0
0,0,0,0,0,0,0,0,0,0,0
0,0,0,0,0,0,0,0,0,0,0
0,0,0,0,0,0,0,0,0,0,0
0,0,0,0,0,0,0,0,0,0,0
0,0,0,0,0,0,0,0,0,0,0
0,0,0,0,0,0,0,0,0,0,0
0,0,0,0,0,0,0,0,0,0,0
0,0,0,0,0,0,0,0,0,0,0
endlayer

layer
0,0,0,0,0,0,0,0,0,0,0
0,0,0,0,0,0,0,0,0,0,0
0,0,0,0,0,0,0,0,0,0,0
0,0,0,0,0,0,0,0,0,0,0
0,0,0,0,0,0,0,0,0,0,0
0,0,0,0,0,0,0,0,0,0,0
0,0,0,0,0,0,0,0,0,0,0
0,0,0,0,0,0,0,0,0,0,0
0,0,0,0,0,0,0,0,0,0,0
endlayer

layer
0,0,0,0,0,0,0,0,0,0,0
0,0,0,0,0,0,0,0,0,0,0
0,0,0,0,0,0,0,0,0,0,0
0,0,0,0,0,0,0,0,0,0,0
0,0,0,0,0,0,0,0,0,0,0
0,0,0,0,0,0,0,0,0,0,0
0,0,0,0,0,0,0,0,0,0,0
0,0,0,0,0,0,0,0,0,0,0
0,0,0,0,0,0,0,0,0,0,0
endlayer

layer
0,0,0,0,0,0,0,0,0,0,0
0,0,0,0,0,0,0,0,0,0,0
0,0,0,0,0,0,0,0,0,0,0
0,0,0,0,0,0,0,0,0,0,0
0,0,0,0,0,0,0,0,0,0,0
0,0,0,0,0,0,0,0,0,0,0
0,0,0,0,0,0,0,0,0,0,0
0,0,0,0,0,0,0,0,0,0,0
0,0,0,0,0,0,0,0,0,0,0
endlayer

layer
0,0,0,0,0,0,0,0,0,0,0
0,0,0,0,0,0,0,0,0,0,0
0,0,0,0,0,0,0,0,0,0,0
0,0,0,0,0,0,0,0,0,0,0
0,0,0,0,0,0,0,0,0,0,0
0,0,0,0,0,0,0,0,0,0,0
0,0,0,0,0,0,0,0,0,0,0
0,0,0,0,0,0,0,0,0,0,0
0,0,0,0,0,0,0,0,0,0,0
endlayer

layer
0,0,0,0,0,0,0,0,0,0,0
0,0,0,0,0,0,0,0,0,0,0
0,0,0,0,0,0,0,0,0,0,0
0,0,0,0,0,0,0,0,0,0,0
0,0,0,0,0,0,0,0,0,0,0
0,0,0,0,0,0,0,0,0,0,0
0,0,0,0,0,0,0,0,0,0,0
0,0,0,0,0,0,0,0,0,0,0
0,0,0,0,0,0,0,0,0,0,0
endlayer

layer
0,0,0,0,0,0,0,0,0,0,0
0,0,0,0,0,0,0,0,0,0,0
0,0,0,0,0,0,0,0,0,0,0
0,0,0,0,0,0,0,0,0,0,0
0,0,0,0,0,0,0,0,0,0,0
0,0,0,0,0,0,0,0,0,0,0
0,0,0,0,0,0,0,0,0,0,0
0,0,0,0,0,0,0,0,0,0,0
0,0,0,0,0,0,0,0,0,0,0
endlayer

layer
0,0,0,0,0,0,0,0,0,0,0
0,0,0,0,0,0,0,0,0,0,0
0,0,0,0,0,0,0,0,0,0,0
0,0,0,0,0,0,0,0,0,0,0
0,0,0,0,0,0,0,0,0,0,0
0,0,0,0,0,0,0,0,0,0,0
0,0,0,0,0,0,0,0,0,0,0
0,0,0,0,0,0,0,0,0,0,0
0,0,0,0,0,0,0,0,0,0,0
endlayer

layer
0,0,0,0,0,0,0,0,0,0,0
0,0,0,0,0,0,0,0,0,0,0
0,0,0,0,0,0,0,0,0,0,0
0,0,0,0,0,0,0,0,0,0,0
0,0,0,0,0,0,0,0,0,0,0
0,0,0,0,0,0,0,0,0,0,0
0,0,0,0,0,0,0,0,0,0,0
0,0,0,0,0,0,0,0,0,0,0
0,0,0,0,0,0,0,0,0,0,0
endlayer

layer
0,0,0,0,0,0,0,0,0,0,0
0,0,0,0,0,0,0,0,0,0,0
0,0,0,0,0,0,0,0,0,0,0
0,0,0,0,0,0,0,0,0,0,0
0,0,0,0,0,0,0,0,0,0,0
0,0,0,0,0,0,0,0,0,0,0
0,0,0,0,0,0,0,0,0,0,0
0,0,0,0,0,0,0,0,0,0,0
0,0,0,0,0,0,0,0,0,0,0
endlayer

layer
0,0,0,0,0,0,0,0,0,0,0
0,0,0,0,0,0,0,0,0,0,0
0,0,0,0,0,0,0,0,0,0,0
0,0,0,0,0,0,0,0,0,0,0
0,0,0,0,0,6,0,0,0,0,0
0,0,0,0,0,6,0,0,0,0,0
0,0,0,0,0,0,0,0,0,0,0
0,0,0,0,0,0,0,0,0,0,0
0,0,0,0,0,0,0,0,0,0,0
endlayer

