
# Created by Ruins mod version 14.4 Ingame Parser
# authoring Player: Mikhaila666

weight=1
embed_into_distance=0
acceptable_target_blocks=
unacceptable_target_blocks=flowing_water,water,flowing_lava,lava
dimensions=33,19,25
allowable_overhang=0
max_leveling=2
leveling_buffer=0
preserve_water=0
preserve_lava=0

rule1=0,100,Railcraft:tile.railcraft.residual.heat-0
rule2=0,100,minecraft:stonebrick-2
rule3=0,100,minecraft:stone-0
rule4=0,100,minecraft:stonebrick-0
rule5=0,100,minecraft:double_stone_slab-0
rule6=0,100,minecraft:quartz_block-0
rule7=2,100,minecraft:torch-1
rule8=2,100,minecraft:torch-3
rule9=2,100,minecraft:torch-4
rule10=2,100,minecraft:torch-2
rule11=0,100,minecraft:quartz_stairs-0
rule12=0,100,minecraft:quartz_stairs-2
rule13=0,100,minecraft:quartz_stairs-3
rule14=0,100,minecraft:quartz_stairs-4
rule15=0,100,minecraft:quartz_stairs-6
rule16=0,100,minecraft:quartz_stairs-7
rule17=0,100,minecraft:quartz_stairs-5
rule18=0,100,minecraft:quartz_stairs-1
rule19=0,100,minecraft:quartz_block-2
rule20=0,100,minecraft:stone_slab-15
rule21=0,100,minecraft:stone_slab-7
rule22=0,100,minecraft:cobblestone-0
rule23=0,100,minecraft:stone_stairs-0
rule24=0,100,minecraft:stone_stairs-2
rule25=0,100,minecraft:stone_stairs-3
rule26=0,100,minecraft:stone_stairs-1

layer
0,0,0,0,1,0,0,0,0,0,0,0,0,0,0,0,0,0,0,0,0,0,0,0,0
0,0,0,0,0,0,0,0,2,4,4,4,4,3,4,4,4,3,3,3,3,2,3,2,0
0,0,0,0,0,0,0,0,4,4,3,4,3,4,4,4,4,3,3,3,3,3,3,3,0
0,0,0,0,0,0,0,0,4,4,4,4,4,4,4,4,4,3,3,3,3,3,3,3,0
0,0,0,0,0,0,1,0,4,4,4,4,4,4,4,4,4,3,3,3,2,3,3,3,0
0,0,0,0,0,0,1,0,5,4,4,4,4,4,4,4,3,3,3,3,3,3,3,2,0
0,0,0,0,0,0,0,0,4,4,4,4,4,4,4,3,3,3,3,3,3,3,3,3,0
0,0,0,0,0,1,0,0,4,4,4,4,3,3,3,3,3,3,3,3,3,3,3,3,0
0,0,0,0,1,0,1,0,4,4,4,4,3,3,3,3,3,3,3,3,3,3,3,3,0
0,0,0,0,0,0,0,0,4,4,4,4,3,3,3,3,3,3,3,3,3,3,3,3,0
0,0,0,0,0,0,0,0,4,4,4,4,3,3,3,3,3,3,3,3,3,2,3,3,0
0,0,0,0,0,0,0,0,4,4,4,4,3,3,3,3,3,3,3,3,3,3,5,3,0
0,0,0,0,1,0,0,0,4,4,4,4,4,3,3,3,3,3,3,3,3,3,3,3,0
0,0,0,0,0,1,0,0,4,4,4,4,4,4,4,3,3,3,3,3,3,2,2,3,0
0,0,0,0,0,0,1,0,4,2,4,4,4,4,4,4,4,4,4,4,4,4,4,4,0
0,0,0,0,0,0,0,0,4,4,4,4,2,4,4,4,4,4,4,4,4,4,2,4,0
0,0,0,0,0,0,0,0,4,4,4,4,4,4,4,4,4,4,4,4,4,5,4,4,0
0,0,0,0,0,0,0,1,0,0,0,0,0,0,0,0,0,0,0,0,0,0,0,0,0
0,0,0,0,0,0,0,0,0,0,0,0,0,0,0,0,0,0,0,0,0,0,0,0,0
endlayer

layer
0,0,0,0,0,0,0,0,0,0,0,0,0,0,0,0,0,0,0,0,0,0,0,0,0
0,0,0,0,0,0,0,0,0,0,0,0,0,0,0,0,0,0,0,0,0,0,0,0,0
0,0,0,0,0,0,0,0,0,0,6,6,0,0,0,6,0,0,0,6,6,0,0,0,0
0,0,0,0,0,0,0,0,0,6,6,6,0,0,0,6,0,0,0,6,6,6,0,0,0
0,0,0,0,0,0,0,0,6,6,6,6,0,0,0,6,0,0,0,6,6,6,6,0,0
0,0,0,0,0,0,0,0,6,6,6,6,6,0,6,6,6,0,6,6,6,6,6,0,0
0,0,0,0,0,0,0,0,0,0,0,6,0,0,0,0,0,0,0,6,0,0,0,0,0
0,0,0,0,0,0,0,0,0,0,0,0,0,0,0,0,0,0,0,0,0,0,0,0,0
0,0,0,0,0,0,0,0,0,0,0,6,0,0,0,0,0,0,0,6,0,0,0,0,0
0,0,0,0,0,0,0,0,6,6,6,6,0,0,0,0,0,0,0,6,6,6,6,0,0
0,0,0,0,0,0,0,0,0,0,0,6,0,0,0,0,0,0,0,6,0,0,0,0,0
0,0,0,0,0,0,0,0,0,0,0,0,0,0,0,0,0,0,0,0,0,0,0,0,0
0,0,0,0,0,0,0,0,0,0,0,6,0,0,0,0,0,0,0,6,0,0,0,0,0
0,0,0,0,0,0,0,0,6,6,6,6,6,0,6,6,6,0,6,6,6,6,6,0,0
0,0,0,0,0,0,0,0,6,6,6,6,0,0,0,6,0,0,0,6,6,6,6,0,0
0,0,0,0,0,0,0,0,0,6,6,6,0,0,0,6,0,0,0,6,6,6,0,0,0
0,0,0,0,0,0,0,0,0,0,6,6,0,0,0,6,0,0,0,6,6,0,0,0,0
0,0,0,0,0,0,0,0,0,0,0,0,0,0,0,0,0,0,0,0,0,0,0,0,0
0,0,0,0,0,0,0,0,0,0,0,0,0,0,0,0,0,0,0,0,0,0,0,0,0
endlayer

layer
0,0,0,0,0,0,0,0,0,0,0,0,0,0,0,0,0,0,0,0,0,0,0,0,0
0,0,0,0,0,0,0,0,0,0,0,0,0,0,0,0,0,0,0,0,0,0,0,0,0
0,0,0,0,0,0,0,0,0,0,6,6,0,0,0,6,0,0,0,6,6,0,0,0,0
0,0,0,1,0,0,0,0,0,6,0,6,0,0,0,6,0,0,0,6,0,6,0,0,0
0,0,0,0,0,0,0,0,6,0,0,6,0,0,0,6,0,0,0,6,0,0,6,0,0
0,0,0,0,0,0,0,0,6,6,6,0,6,0,6,6,6,0,6,0,6,6,6,0,0
0,0,0,0,0,0,0,0,0,0,0,6,0,0,0,0,0,0,0,6,0,0,0,0,0
0,0,0,0,0,0,0,0,0,0,0,0,0,0,0,0,0,0,0,0,0,0,0,0,0
0,0,0,0,0,0,0,0,0,0,0,6,0,0,0,0,0,0,0,6,0,0,0,0,0
0,0,0,0,0,0,0,0,6,6,6,6,0,0,0,0,0,0,0,6,6,6,6,0,0
0,1,0,0,0,0,0,0,0,0,0,6,0,0,0,0,0,0,0,6,0,0,0,0,0
0,0,0,0,0,0,0,0,0,0,0,0,0,0,0,0,0,0,0,0,0,0,0,0,0
0,0,0,0,0,0,0,0,0,0,0,6,0,0,0,0,0,0,0,6,0,0,0,0,0
0,0,0,0,0,0,0,0,6,6,6,0,6,0,6,6,6,0,6,0,6,6,6,0,0
0,0,0,0,0,0,0,0,6,0,0,6,0,0,0,6,0,0,0,6,0,0,6,0,0
0,0,0,0,0,0,0,0,0,6,0,6,0,0,0,6,0,0,0,6,0,6,0,0,0
0,0,0,0,0,0,0,0,0,0,6,6,0,0,0,6,0,0,0,6,6,0,0,0,0
0,0,0,0,0,0,0,0,0,0,0,0,0,0,0,0,0,0,0,0,0,0,0,0,0
0,0,0,0,0,0,0,0,0,1,0,0,0,0,0,0,0,0,0,0,0,0,0,0,0
endlayer

layer
0,0,0,0,0,0,0,0,0,0,0,0,0,0,0,0,0,0,0,0,0,0,0,0,0
0,0,0,0,0,0,0,0,0,0,0,0,0,0,0,0,0,0,0,0,0,0,0,0,0
0,0,0,0,0,0,0,0,0,0,6,6,0,0,0,6,0,0,0,6,6,0,0,0,0
0,0,0,0,0,0,0,0,0,6,0,6,0,0,0,6,0,0,0,6,0,6,0,0,0
0,0,0,0,0,0,0,0,6,0,0,6,0,0,0,6,0,0,0,6,0,0,6,0,0
0,0,0,0,0,0,0,0,6,6,6,0,6,0,6,6,6,0,6,0,6,6,6,0,0
0,0,0,0,0,0,0,0,0,0,0,6,0,0,0,7,0,0,0,6,0,0,0,0,0
0,0,0,0,0,0,0,0,0,0,0,0,0,0,0,0,0,0,0,0,0,0,0,0,0
0,0,0,0,0,0,0,0,0,0,0,6,0,0,0,0,0,0,0,6,0,0,0,0,0
0,0,0,0,0,0,0,0,6,6,6,6,9,0,0,0,0,0,8,6,6,6,6,0,0
0,0,0,0,0,0,0,0,0,0,0,6,0,0,0,0,0,0,0,6,0,0,0,0,0
0,0,0,0,0,0,0,0,0,0,0,0,0,0,0,0,0,0,0,0,0,0,0,0,0
0,0,0,0,0,0,0,0,0,0,0,6,0,0,0,10,0,0,0,6,0,0,0,0,0
0,0,0,0,0,0,0,0,6,6,6,0,6,0,6,6,6,0,6,0,6,6,6,0,0
0,0,0,0,0,0,0,0,6,0,0,6,0,0,0,6,0,0,0,6,0,0,6,0,0
0,0,0,0,0,0,0,0,0,6,0,6,0,0,0,6,0,0,0,6,0,6,0,0,0
0,0,0,0,0,0,0,0,0,0,6,6,0,0,0,6,0,0,0,6,6,0,0,0,0
0,0,0,0,0,0,0,0,0,0,0,0,0,0,0,0,0,0,0,0,0,0,0,0,0
0,0,0,0,0,0,0,0,0,0,0,0,0,0,0,0,0,0,0,0,0,0,0,0,0
endlayer

layer
0,0,0,0,0,0,0,0,0,0,0,0,0,0,0,0,0,0,0,0,0,0,0,0,0
0,0,0,0,0,0,0,0,0,0,0,0,0,0,0,0,0,0,0,0,0,0,0,0,0
0,0,0,0,0,0,0,0,0,0,11,11,0,0,0,11,0,0,0,11,11,0,0,0,0
0,0,0,0,0,0,0,0,0,6,6,6,0,0,0,6,0,0,0,6,6,6,0,0,0
0,0,0,0,0,0,0,0,13,6,0,6,0,0,0,6,0,0,0,6,0,6,12,0,0
0,0,0,0,0,0,0,0,13,6,6,0,6,14,6,6,6,14,6,0,6,6,12,0,0
0,0,0,0,0,0,0,0,0,0,0,6,0,0,0,0,0,0,0,6,0,0,0,0,0
0,0,0,0,0,0,0,0,0,0,0,16,0,0,0,0,0,0,0,15,0,0,0,0,0
0,0,0,0,0,0,0,0,0,0,0,6,0,0,0,0,0,0,0,6,0,0,0,0,0
0,0,0,0,0,0,0,0,13,6,6,6,0,0,0,0,0,0,0,6,6,6,12,0,0
0,0,0,0,0,0,0,0,0,0,0,6,0,0,0,0,0,0,0,6,0,0,0,0,0
0,0,0,0,0,0,0,0,0,0,0,16,0,0,0,0,0,0,0,15,0,0,0,0,0
0,0,0,0,0,0,0,0,0,0,0,6,0,0,0,0,0,0,0,6,0,0,0,0,0
0,0,0,0,0,0,0,0,13,6,6,0,6,17,6,6,6,17,6,0,6,6,12,0,0
0,0,0,0,0,0,0,0,13,6,0,6,0,0,0,6,0,0,0,6,0,6,12,0,0
0,0,0,0,0,0,0,0,0,6,6,6,0,0,0,6,0,0,0,6,6,6,0,0,0
0,0,0,0,0,0,0,0,0,0,18,18,0,0,0,18,0,0,0,18,18,0,0,0,0
0,0,0,0,0,0,0,0,0,0,0,0,0,0,0,0,0,0,0,0,0,0,0,0,0
0,0,0,0,0,0,0,0,0,0,0,0,0,0,0,0,0,0,0,0,0,0,0,0,0
endlayer

layer
0,0,0,0,0,0,0,0,0,0,0,0,0,0,0,0,0,0,0,0,0,0,0,0,0
0,0,0,0,0,0,0,0,0,0,0,0,0,0,0,0,0,0,0,0,0,0,0,0,0
0,0,0,0,0,0,0,0,0,0,0,0,0,0,0,0,0,0,0,0,0,0,0,0,0
0,0,0,0,0,0,0,0,0,0,6,6,0,0,0,6,0,0,0,6,6,0,0,0,0
0,0,0,0,0,0,0,0,0,6,0,6,15,0,16,6,15,0,16,6,0,6,0,0,0
0,0,0,0,0,0,0,0,0,6,6,6,6,6,6,6,6,6,6,6,6,6,0,0,0
0,0,0,0,0,0,0,0,0,0,17,6,0,0,0,0,0,0,0,6,17,0,0,0,0
0,0,0,0,0,0,0,0,0,0,0,6,0,0,0,0,0,0,0,6,0,0,0,0,0
0,0,0,0,0,0,0,0,0,0,14,6,0,0,0,0,0,0,0,6,14,0,0,0,0
0,0,0,0,0,0,0,0,0,6,6,6,0,0,0,0,0,0,0,6,6,6,0,0,0
0,0,0,0,0,0,0,0,0,0,17,6,0,0,0,0,0,0,0,6,17,0,0,0,0
0,0,0,0,0,0,0,0,0,0,0,6,0,0,0,0,0,0,0,6,0,0,0,0,0
0,0,0,0,0,0,0,0,0,0,14,6,0,0,0,0,0,0,0,6,14,0,0,0,0
0,0,0,0,0,0,0,0,0,6,6,6,6,6,6,6,6,6,6,6,6,6,0,0,0
0,0,0,0,0,0,0,0,0,6,0,6,15,0,16,6,15,0,16,6,0,6,0,0,0
0,0,0,0,0,0,0,0,0,0,6,6,0,0,0,6,0,0,0,6,6,0,0,0,0
0,0,0,0,0,0,0,0,0,0,0,0,0,0,0,0,0,0,0,0,0,0,0,0,0
0,0,0,0,0,0,0,0,0,0,0,0,0,0,0,0,0,0,0,0,0,0,0,0,0
0,0,0,0,0,0,0,0,0,0,0,0,0,0,0,0,0,0,0,0,0,0,0,0,0
endlayer

layer
0,0,0,0,0,0,0,0,0,0,0,0,0,0,0,0,0,0,0,0,0,0,0,0,0
0,0,0,0,0,0,0,0,0,0,0,0,0,0,0,0,0,0,0,0,0,0,0,0,0
0,0,0,0,0,0,0,0,0,0,0,0,0,0,0,0,0,0,0,0,0,0,0,0,0
0,0,0,0,0,0,0,0,0,0,6,6,0,0,0,6,0,0,0,6,6,0,0,0,0
0,0,0,0,0,0,0,0,0,6,0,6,6,6,6,6,6,6,6,6,0,6,0,0,0
0,0,0,0,0,0,0,0,0,6,6,0,0,0,0,0,0,0,0,0,6,6,0,0,0
0,0,0,0,0,0,0,0,0,0,6,0,0,0,0,0,0,0,0,0,6,0,0,0,0
0,0,0,0,0,0,0,0,0,0,6,0,0,0,0,0,0,0,0,0,6,0,0,0,0
0,0,0,0,0,0,0,0,0,0,6,0,0,0,0,0,0,0,0,0,6,0,0,0,0
0,0,0,0,0,0,0,0,0,6,6,0,0,0,0,0,0,0,0,0,6,6,0,0,0
0,0,0,0,0,0,0,0,0,0,6,0,0,0,0,0,0,0,0,0,6,0,0,0,0
0,0,0,0,0,0,0,0,0,0,6,0,0,0,0,0,0,0,0,0,6,0,0,0,0
0,0,0,0,0,0,0,0,0,0,6,0,0,0,0,0,0,0,0,0,6,0,0,0,0
0,0,0,0,0,0,0,0,0,6,6,0,0,0,0,0,0,0,0,0,6,6,0,0,0
0,0,0,0,0,0,0,0,0,6,0,6,6,6,6,6,6,6,6,6,0,6,0,0,0
0,0,0,0,0,0,0,0,0,0,6,6,0,0,0,6,0,0,0,6,6,0,0,0,0
0,0,0,0,0,0,0,0,0,0,0,0,0,0,0,0,0,0,0,0,0,0,0,0,0
0,0,0,0,0,0,0,0,0,0,0,0,0,0,0,0,0,0,0,0,0,0,0,0,0
0,0,0,0,0,0,0,0,0,0,0,0,0,0,0,0,0,0,0,0,0,0,0,0,0
endlayer

layer
0,0,0,0,0,0,0,0,0,0,0,0,0,0,0,0,0,0,0,0,0,0,0,0,0
0,0,0,0,0,0,0,0,0,0,0,0,0,0,0,0,0,0,0,0,0,0,0,0,0
0,0,0,0,0,0,0,0,0,0,0,0,0,0,0,0,0,0,0,0,0,0,0,0,0
0,0,0,0,0,0,0,0,0,0,6,6,0,0,0,6,0,0,0,6,6,0,0,0,0
0,0,0,0,0,0,0,0,0,6,0,6,6,6,6,6,6,6,6,6,0,6,0,0,0
0,0,0,0,0,0,0,0,0,6,6,0,0,0,0,0,0,0,0,0,6,6,0,0,0
0,0,0,0,0,0,0,0,0,0,6,0,0,0,0,0,0,0,0,0,6,0,0,0,0
0,0,0,0,0,0,0,0,0,0,6,0,0,0,0,0,0,0,0,0,6,0,0,0,0
0,0,0,0,0,0,0,0,0,0,6,0,0,0,0,0,0,0,0,0,6,0,0,0,0
0,0,0,0,0,0,0,0,0,6,6,0,0,0,0,0,0,0,0,0,6,6,0,0,0
0,0,0,0,0,0,0,0,0,0,6,0,0,0,0,0,0,0,0,0,6,0,0,0,0
0,0,0,0,0,0,0,0,0,0,6,0,0,0,0,0,0,0,0,0,6,0,0,0,0
0,0,0,0,0,0,0,0,0,0,6,0,0,0,0,0,0,0,0,0,6,0,0,0,0
0,0,0,0,0,0,0,0,0,6,6,0,0,0,0,0,0,0,0,0,6,6,0,0,0
0,0,0,0,0,0,0,0,0,6,0,6,6,6,6,6,6,6,6,6,0,6,0,0,0
0,0,0,0,0,0,0,0,0,0,6,6,0,0,0,6,0,0,0,6,6,0,0,0,0
0,0,0,0,0,0,0,0,0,0,0,0,0,0,0,0,0,0,0,0,0,0,0,0,0
0,0,0,0,0,0,0,0,0,0,0,0,0,0,0,0,0,0,0,0,0,0,0,0,0
0,0,0,0,0,0,0,0,0,0,0,0,0,0,0,0,0,0,0,0,0,0,0,0,0
endlayer

layer
0,0,0,0,0,0,0,0,0,0,0,0,0,0,0,0,0,0,0,0,0,0,0,0,0
0,0,0,0,0,0,0,0,0,0,0,0,0,0,0,0,0,0,0,0,0,0,0,0,0
0,0,0,0,0,0,0,0,0,0,0,0,0,0,0,0,0,0,0,0,0,0,0,0,0
0,0,0,0,0,0,0,0,0,0,6,6,0,0,0,6,0,0,0,6,6,0,0,0,0
0,0,0,0,0,0,0,0,0,6,0,6,6,6,6,6,6,6,6,6,0,6,0,0,0
0,0,0,0,0,0,0,0,0,6,6,0,0,0,0,0,0,0,0,0,6,6,0,0,0
0,0,0,0,0,0,0,0,0,0,6,0,0,0,0,0,0,0,0,0,6,0,0,0,0
0,0,0,0,0,0,0,0,0,0,6,0,0,0,0,0,0,0,0,0,6,0,0,0,0
0,0,0,0,0,0,0,0,0,0,6,0,0,0,0,0,0,0,0,0,6,0,0,0,0
0,0,0,0,0,0,0,0,0,6,6,0,0,0,0,0,0,0,0,0,6,6,0,0,0
0,0,0,0,0,0,0,0,0,0,6,0,0,0,0,0,0,0,0,0,6,0,0,0,0
0,0,0,0,0,0,0,0,0,0,6,0,0,0,0,0,0,0,0,0,6,0,0,0,0
0,0,0,0,0,0,0,0,0,0,6,0,0,0,0,0,0,0,0,0,6,0,0,0,0
0,0,0,0,0,0,0,0,0,6,6,0,0,0,0,0,0,0,0,0,6,6,0,0,0
0,0,0,0,0,0,0,0,0,6,0,6,6,6,6,6,6,6,6,6,0,6,0,0,0
0,0,0,0,0,0,0,0,0,0,6,6,0,0,0,6,0,0,0,6,6,0,0,0,0
0,0,0,0,0,0,0,0,0,0,0,0,0,0,0,0,0,0,0,0,0,0,0,0,0
0,0,0,0,0,0,0,0,0,0,0,0,0,0,0,0,0,0,0,0,0,0,0,0,0
0,0,0,0,0,0,0,0,0,0,0,0,0,0,0,0,0,0,0,0,0,0,0,0,0
endlayer

layer
0,0,0,0,0,0,0,0,0,0,0,0,0,0,0,0,0,0,0,0,0,0,0,0,0
0,0,0,0,0,0,0,0,0,0,0,0,0,0,0,0,0,0,0,0,0,0,0,0,0
0,0,0,0,0,0,0,0,0,0,0,0,0,0,0,0,0,0,0,0,0,0,0,0,0
0,0,0,0,0,0,0,0,0,0,6,6,0,0,0,6,0,0,0,6,6,0,0,0,0
0,0,0,0,0,0,0,0,0,6,0,6,6,6,6,6,6,6,6,6,0,6,0,0,0
0,0,0,0,0,0,0,0,0,6,6,0,0,0,0,0,0,0,0,0,6,6,0,0,0
0,0,0,0,0,0,0,0,0,0,6,0,0,0,0,0,0,0,0,0,6,0,0,0,0
0,0,0,0,0,0,0,0,0,0,6,0,0,0,0,0,0,0,0,0,6,0,0,0,0
0,0,0,0,0,0,0,0,0,0,6,0,0,0,0,0,0,0,0,0,6,0,0,0,0
0,0,0,0,0,0,0,0,0,6,6,0,0,0,0,0,0,0,0,0,6,6,0,0,0
0,0,0,0,0,0,0,0,0,0,6,0,0,0,0,0,0,0,0,0,6,0,0,0,0
0,0,0,0,0,0,0,0,0,0,6,0,0,0,0,0,0,0,0,0,6,0,0,0,0
0,0,0,0,0,0,0,0,0,0,6,0,0,0,0,0,0,0,0,0,6,0,0,0,0
0,0,0,0,0,0,0,0,0,6,6,0,0,0,0,0,0,0,0,0,6,6,0,0,0
0,0,0,0,0,0,0,0,0,6,0,6,6,6,6,6,6,6,6,6,0,6,0,0,0
0,0,0,0,0,0,0,0,0,0,6,6,0,0,0,6,0,0,0,6,6,0,0,0,0
0,0,0,0,0,0,0,0,0,0,0,0,0,0,0,0,0,0,0,0,0,0,0,0,0
0,0,0,0,0,0,0,0,0,0,0,0,0,0,0,0,0,0,0,0,0,0,0,0,0
0,0,0,0,0,0,0,0,0,0,0,0,0,0,0,0,0,0,0,0,0,0,0,0,0
endlayer

layer
0,0,0,0,0,0,0,0,0,0,0,0,0,0,0,0,0,0,0,0,0,0,0,0,0
0,0,0,0,0,0,0,0,0,0,0,0,0,0,0,0,0,0,0,0,0,0,0,0,0
0,0,0,0,0,0,0,0,0,0,0,0,0,0,0,0,0,0,0,0,0,0,0,0,0
0,0,0,0,0,0,0,0,0,0,6,6,14,14,14,6,14,14,14,6,6,0,0,0,0
0,0,0,0,0,0,0,0,0,6,0,6,6,6,6,6,6,6,6,6,0,6,0,0,0
0,0,0,0,0,0,0,0,0,6,6,0,0,0,0,0,0,0,0,0,6,6,0,0,0
0,0,0,0,0,0,0,0,0,16,6,0,0,0,0,0,0,0,0,0,6,15,0,0,0
0,0,0,0,0,0,0,0,0,16,6,0,0,0,0,0,0,0,0,0,6,15,0,0,0
0,0,0,0,0,0,0,0,0,16,6,0,0,0,0,0,0,0,0,0,6,15,0,0,0
0,0,0,0,0,0,0,0,0,6,6,0,0,0,0,0,0,0,0,0,6,6,0,0,0
0,0,0,0,0,0,0,0,0,16,6,0,0,0,0,0,0,0,0,0,6,15,0,0,0
0,0,0,0,0,0,0,0,0,16,6,0,0,0,0,0,0,0,0,0,6,15,0,0,0
0,0,0,0,0,0,0,0,0,16,6,0,0,0,0,0,0,0,0,0,6,15,0,0,0
0,0,0,0,0,0,0,0,0,6,6,0,0,0,0,0,0,0,0,0,6,6,0,0,0
0,0,0,0,0,0,0,0,0,6,0,6,6,6,6,6,6,6,6,6,0,6,0,0,0
0,0,0,0,0,0,0,0,0,0,6,6,17,17,17,6,17,17,17,6,6,0,0,0,0
0,0,0,0,0,0,0,0,0,0,0,0,0,0,0,0,0,0,0,0,0,0,0,0,0
0,0,0,0,0,0,0,0,0,0,0,0,0,0,0,0,0,0,0,0,0,0,0,0,0
0,0,0,0,0,0,0,0,0,0,0,0,0,0,0,0,0,0,0,0,0,0,0,0,0
endlayer

layer
0,0,0,0,0,0,0,0,0,0,0,0,0,0,0,0,0,0,0,0,0,0,0,0,0
0,0,0,0,0,0,0,0,0,0,0,0,0,0,0,0,0,0,0,0,0,0,0,0,0
0,0,0,0,0,0,0,0,0,0,0,0,0,0,0,0,0,0,0,0,0,0,0,0,0
0,0,0,0,0,0,0,0,0,0,11,11,0,0,0,11,0,0,0,11,11,0,0,0,0
0,0,0,0,0,0,0,0,0,13,6,6,11,11,11,6,11,11,11,6,6,12,0,0,0
0,0,0,0,0,0,0,0,0,13,6,6,6,6,6,6,6,6,6,6,6,12,0,0,0
0,0,0,0,0,0,0,0,0,0,13,6,0,0,0,0,0,0,0,6,12,0,0,0,0
0,0,0,0,0,0,0,0,0,0,13,6,0,0,0,0,0,0,0,6,12,0,0,0,0
0,0,0,0,0,0,0,0,0,0,13,6,0,0,0,0,0,0,0,6,12,0,0,0,0
0,0,0,0,0,0,0,0,0,13,6,6,0,0,0,0,0,0,0,6,6,12,0,0,0
0,0,0,0,0,0,0,0,0,0,13,6,0,0,0,0,0,0,0,6,12,0,0,0,0
0,0,0,0,0,0,0,0,0,0,13,6,0,0,0,0,0,0,0,6,12,0,0,0,0
0,0,0,0,0,0,0,0,0,0,13,6,0,0,0,0,0,0,0,6,12,0,0,0,0
0,0,0,0,0,0,0,0,0,13,6,6,6,6,6,6,6,6,6,6,6,12,0,0,0
0,0,0,0,0,0,0,0,0,13,6,6,18,18,18,6,18,18,18,6,6,12,0,0,0
0,0,0,0,0,0,0,0,0,0,18,18,0,0,0,18,0,0,0,18,18,0,0,0,0
0,0,0,0,0,0,0,0,0,0,0,0,0,0,0,0,0,0,0,0,0,0,0,0,0
0,0,0,0,0,0,0,0,0,0,0,0,0,0,0,0,0,0,0,0,0,0,0,0,0
0,0,0,0,0,0,0,0,0,0,0,0,0,0,0,0,0,0,0,0,0,0,0,0,0
endlayer

layer
0,0,0,0,0,0,0,0,0,0,0,0,0,0,0,0,0,0,0,0,0,0,0,0,0
0,0,0,0,0,0,0,0,0,0,0,0,0,0,0,0,0,0,0,0,0,0,0,0,0
0,0,0,0,0,0,0,0,0,0,0,0,0,0,0,0,0,0,0,0,0,0,0,0,0
0,0,0,0,0,0,0,0,0,0,0,0,0,0,0,0,0,0,0,0,0,0,0,0,0
0,0,0,0,0,0,0,0,0,0,16,14,14,14,14,14,14,14,14,14,15,0,0,0,0
0,0,0,0,0,0,0,0,0,0,16,6,6,6,6,6,6,6,6,6,15,0,0,0,0
0,0,0,0,0,0,0,0,0,0,16,6,0,0,0,0,0,0,0,6,15,0,0,0,0
0,0,0,0,0,0,0,0,0,0,16,6,0,0,0,0,0,0,0,6,15,0,0,0,0
0,0,0,0,0,0,0,0,0,0,16,6,0,0,0,0,0,0,0,6,15,0,0,0,0
0,0,0,0,0,0,0,0,0,0,16,6,0,0,0,0,0,0,0,6,15,0,0,0,0
0,0,0,0,0,0,0,0,0,0,16,6,0,0,0,0,0,0,0,6,15,0,0,0,0
0,0,0,0,0,0,0,0,0,0,16,6,0,0,0,0,0,0,0,6,15,0,0,0,0
0,0,0,0,0,0,0,0,0,0,16,6,0,0,0,0,0,0,0,6,15,0,0,0,0
0,0,0,0,0,0,0,0,0,0,16,6,6,6,6,6,6,6,6,6,15,0,0,0,0
0,0,0,0,0,0,0,0,0,0,16,17,17,17,17,17,17,17,17,17,15,0,0,0,0
0,0,0,0,0,0,0,0,0,0,0,0,0,0,0,0,0,0,0,0,0,0,0,0,0
0,0,0,0,0,0,0,0,0,0,0,0,0,0,0,0,0,0,0,0,0,0,0,0,0
0,0,0,0,0,0,0,0,0,0,0,0,0,0,0,0,0,0,0,0,0,0,0,0,0
0,0,0,0,0,0,0,0,0,0,0,0,0,0,0,0,0,0,0,0,0,0,0,0,0
endlayer

layer
0,0,0,0,0,0,0,0,0,0,0,0,0,0,0,0,0,0,0,0,0,0,0,0,0
0,0,0,0,0,0,0,0,0,0,0,0,0,0,0,0,0,0,0,0,0,0,0,0,0
0,0,0,0,0,0,0,0,0,0,0,0,0,0,0,0,0,0,0,0,0,0,0,0,0
0,0,0,0,0,0,0,0,0,0,0,0,0,0,0,0,0,0,0,0,0,0,0,0,0
0,0,0,0,0,0,0,0,0,0,0,0,0,0,0,0,0,0,0,0,0,0,0,0,0
0,0,0,0,0,0,0,0,0,0,0,6,6,11,11,6,11,11,6,6,0,0,0,0,0
0,0,0,0,0,0,0,0,0,0,0,6,0,0,0,0,0,0,0,6,0,0,0,0,0
0,0,0,0,0,0,0,0,0,0,0,13,0,0,0,0,0,0,0,12,0,0,0,0,0
0,0,0,0,0,0,0,0,0,0,0,13,0,0,0,0,0,0,0,12,0,0,0,0,0
0,0,0,0,0,0,0,0,0,0,0,6,0,0,0,0,0,0,0,6,0,0,0,0,0
0,0,0,0,0,0,0,0,0,0,0,13,0,0,0,0,0,0,0,12,0,0,0,0,0
0,0,0,0,0,0,0,0,0,0,0,13,0,0,0,0,0,0,0,12,0,0,0,0,0
0,0,0,0,0,0,0,0,0,0,0,6,0,0,0,0,0,0,0,6,0,0,0,0,0
0,0,0,0,0,0,0,0,0,0,0,6,6,18,18,6,18,18,6,6,0,0,0,0,0
0,0,0,0,0,0,0,0,0,0,0,0,0,0,0,0,0,0,0,0,0,0,0,0,0
0,0,0,0,0,0,0,0,0,0,0,0,0,0,0,0,0,0,0,0,0,0,0,0,0
0,0,0,0,0,0,0,0,0,0,0,0,0,0,0,0,0,0,0,0,0,0,0,0,0
0,0,0,0,0,0,0,0,0,0,0,0,0,0,0,0,0,0,0,0,0,0,0,0,0
0,0,0,0,0,0,0,0,0,0,0,0,0,0,0,0,0,0,0,0,0,0,0,0,0
endlayer

layer
0,0,0,0,0,0,0,0,0,0,0,0,0,0,0,0,0,0,0,0,0,0,0,0,0
0,0,0,0,0,0,0,0,0,0,0,0,0,0,0,0,0,0,0,0,0,0,0,0,0
0,0,0,0,0,0,0,0,0,0,0,0,0,0,0,0,0,0,0,0,0,0,0,0,0
0,0,0,0,0,0,0,0,0,0,0,0,0,0,0,0,0,0,0,0,0,0,0,0,0
0,0,0,0,0,0,0,0,0,0,0,0,0,0,0,0,0,0,0,0,0,0,0,0,0
0,0,0,0,0,0,0,0,0,0,0,6,19,0,0,19,0,0,19,6,0,0,0,0,0
0,0,0,0,0,0,0,0,0,0,0,19,0,0,0,0,0,0,0,19,0,0,0,0,0
0,0,0,0,0,0,0,0,0,0,0,0,0,0,0,0,0,0,0,0,0,0,0,0,0
0,0,0,0,0,0,0,0,0,0,0,0,0,0,0,0,0,0,0,0,0,0,0,0,0
0,0,0,0,0,0,0,0,0,0,0,19,0,0,0,0,0,0,0,19,0,0,0,0,0
0,0,0,0,0,0,0,0,0,0,0,0,0,0,0,0,0,0,0,0,0,0,0,0,0
0,0,0,0,0,0,0,0,0,0,0,0,0,0,0,0,0,0,0,0,0,0,0,0,0
0,0,0,0,0,0,0,0,0,0,0,19,0,0,0,0,0,0,0,19,0,0,0,0,0
0,0,0,0,0,0,0,0,0,0,0,6,19,0,0,19,0,0,19,6,0,0,0,0,0
0,0,0,0,0,0,0,0,0,0,0,0,0,0,0,0,0,0,0,0,0,0,0,0,0
0,0,0,0,0,0,0,0,0,0,0,0,0,0,0,0,0,0,0,0,0,0,0,0,0
0,0,0,0,0,0,0,0,0,0,0,0,0,0,0,0,0,0,0,0,0,0,0,0,0
0,0,0,0,0,0,0,0,0,0,0,0,0,0,0,0,0,0,0,0,0,0,0,0,0
0,0,0,0,0,0,0,0,0,0,0,0,0,0,0,0,0,0,0,0,0,0,0,0,0
endlayer

layer
0,0,0,0,0,0,0,0,0,0,0,0,0,0,0,0,0,0,0,0,0,0,0,0,0
0,0,0,0,0,0,0,0,0,0,0,0,0,0,0,0,0,0,0,0,0,0,0,0,0
0,0,0,0,0,0,0,0,0,0,0,0,0,0,0,0,0,0,0,0,0,0,0,0,0
0,0,0,0,0,0,0,0,0,0,0,0,0,0,0,0,0,0,0,0,0,0,0,0,0
0,0,0,0,0,0,0,0,0,0,0,0,0,0,0,0,0,0,0,0,0,0,0,0,0
0,0,0,0,0,0,0,0,0,0,0,6,19,0,0,19,0,0,19,6,0,0,0,0,0
0,0,0,0,0,0,0,0,0,0,0,19,0,0,0,0,0,0,0,19,0,0,0,0,0
0,0,0,0,0,0,0,0,0,0,0,0,0,0,0,0,0,0,0,0,0,0,0,0,0
0,0,0,0,0,0,0,0,0,0,0,0,0,0,0,0,0,0,0,0,0,0,0,0,0
0,0,0,0,0,0,0,0,0,0,0,19,0,0,0,0,0,0,0,19,0,0,0,0,0
0,0,0,0,0,0,0,0,0,0,0,0,0,0,0,0,0,0,0,0,0,0,0,0,0
0,0,0,0,0,0,0,0,0,0,0,0,0,0,0,0,0,0,0,0,0,0,0,0,0
0,0,0,0,0,0,0,0,0,0,0,19,0,0,0,0,0,0,0,19,0,0,0,0,0
0,0,0,0,0,0,0,0,0,0,0,6,19,0,0,19,0,0,19,6,0,0,0,0,0
0,0,0,0,0,0,0,0,0,0,0,0,0,0,0,0,0,0,0,0,0,0,0,0,0
0,0,0,0,0,0,0,0,0,0,0,0,0,0,0,0,0,0,0,0,0,0,0,0,0
0,0,0,0,0,0,0,0,0,0,0,0,0,0,0,0,0,0,0,0,0,0,0,0,0
0,0,0,0,0,0,0,0,0,0,0,0,0,0,0,0,0,0,0,0,0,0,0,0,0
0,0,0,0,0,0,0,0,0,0,0,0,0,0,0,0,0,0,0,0,0,0,0,0,0
endlayer

layer
0,0,0,0,0,0,0,0,0,0,0,0,0,0,0,0,0,0,0,0,0,0,0,0,0
0,0,0,0,0,0,0,0,0,0,0,0,0,0,0,0,0,0,0,0,0,0,0,0,0
0,0,0,0,0,0,0,0,0,0,0,0,0,0,0,0,0,0,0,0,0,0,0,0,0
0,0,0,0,0,0,0,0,0,0,0,0,0,0,0,0,0,0,0,0,0,0,0,0,0
0,0,0,0,0,0,0,0,0,0,0,0,0,0,0,0,0,0,0,0,0,0,0,0,0
0,0,0,0,0,0,0,0,0,0,0,6,19,0,0,19,0,0,19,6,0,0,0,0,0
0,0,0,0,0,0,0,0,0,0,0,19,0,0,0,7,0,0,0,19,0,0,0,0,0
0,0,0,0,0,0,0,0,0,0,0,0,0,0,0,0,0,0,0,0,0,0,0,0,0
0,0,0,0,0,0,0,0,0,0,0,0,0,0,0,0,0,0,0,0,0,0,0,0,0
0,0,0,0,0,0,0,0,0,0,0,19,9,0,0,0,0,0,8,19,0,0,0,0,0
0,0,0,0,0,0,0,0,0,0,0,0,0,0,0,0,0,0,0,0,0,0,0,0,0
0,0,0,0,0,0,0,0,0,0,0,0,0,0,0,0,0,0,0,0,0,0,0,0,0
0,0,0,0,0,0,0,0,0,0,0,19,0,0,0,10,0,0,0,19,0,0,0,0,0
0,0,0,0,0,0,0,0,0,0,0,6,19,0,0,19,0,0,19,6,0,0,0,0,0
0,0,0,0,0,0,0,0,0,0,0,0,0,0,0,0,0,0,0,0,0,0,0,0,0
0,0,0,0,0,0,0,0,0,0,0,0,0,0,0,0,0,0,0,0,0,0,0,0,0
0,0,0,0,0,0,0,0,0,0,0,0,0,0,0,0,0,0,0,0,0,0,0,0,0
0,0,0,0,0,0,0,0,0,0,0,0,0,0,0,0,0,0,0,0,0,0,0,0,0
0,0,0,0,0,0,0,0,0,0,0,0,0,0,0,0,0,0,0,0,0,0,0,0,0
endlayer

layer
0,0,0,0,0,0,0,0,0,0,0,0,0,0,0,0,0,0,0,0,0,0,0,0,0
0,0,0,0,0,0,0,0,0,0,0,0,0,0,0,0,0,0,0,0,0,0,0,0,0
0,0,0,0,0,0,0,0,0,0,0,0,0,0,0,0,0,0,0,0,0,0,0,0,0
0,0,0,0,0,0,0,0,0,0,0,0,0,0,0,0,0,0,0,0,0,0,0,0,0
0,0,0,0,0,0,0,0,0,0,0,0,0,0,0,0,0,0,0,0,0,0,0,0,0
0,0,0,0,0,0,0,0,0,0,0,6,19,0,0,19,0,0,19,6,0,0,0,0,0
0,0,0,0,0,0,0,0,0,0,0,19,0,0,0,0,0,0,0,19,0,0,0,0,0
0,0,0,0,0,0,0,0,0,0,0,0,0,0,0,0,0,0,0,0,0,0,0,0,0
0,0,0,0,0,0,0,0,0,0,0,0,0,0,0,0,0,0,0,0,0,0,0,0,0
0,0,0,0,0,0,0,0,0,0,0,19,0,0,0,0,0,0,0,19,0,0,0,0,0
0,0,0,0,0,0,0,0,0,0,0,0,0,0,0,0,0,0,0,0,0,0,0,0,0
0,0,0,0,0,0,0,0,0,0,0,0,0,0,0,0,0,0,0,0,0,0,0,0,0
0,0,0,0,0,0,0,0,0,0,0,19,0,0,0,0,0,0,0,19,0,0,0,0,0
0,0,0,0,0,0,0,0,0,0,0,6,19,0,0,19,0,0,19,6,0,0,0,0,0
0,0,0,0,0,0,0,0,0,0,0,0,0,0,0,0,0,0,0,0,0,0,0,0,0
0,0,0,0,0,0,0,0,0,0,0,0,0,0,0,0,0,0,0,0,0,0,0,0,0
0,0,0,0,0,0,0,0,0,0,0,0,0,0,0,0,0,0,0,0,0,0,0,0,0
0,0,0,0,0,0,0,0,0,0,0,0,0,0,0,0,0,0,0,0,0,0,0,0,0
0,0,0,0,0,0,0,0,0,0,0,0,0,0,0,0,0,0,0,0,0,0,0,0,0
endlayer

layer
0,0,0,0,0,0,0,0,0,0,0,0,0,0,0,0,0,0,0,0,0,0,0,0,0
0,0,0,0,0,0,0,0,0,0,0,0,0,0,0,0,0,0,0,0,0,0,0,0,0
0,0,0,0,0,0,0,0,0,0,0,0,0,0,0,0,0,0,0,0,0,0,0,0,0
0,0,0,0,0,0,0,0,0,0,0,0,0,0,0,0,0,0,0,0,0,0,0,0,0
0,0,0,0,0,0,0,0,0,0,20,20,14,15,16,14,15,16,14,20,20,0,0,0,0
0,0,0,0,0,0,0,0,0,0,20,6,6,15,16,6,15,16,6,6,20,0,0,0,0
0,0,0,0,0,0,0,0,0,0,16,6,0,0,0,0,0,0,0,6,15,0,0,0,0
0,0,0,0,0,0,0,0,0,0,17,17,0,0,0,0,0,0,0,17,17,0,0,0,0
0,0,0,0,0,0,0,0,0,0,14,14,0,0,0,0,0,0,0,14,15,0,0,0,0
0,0,0,0,0,0,0,0,0,0,16,6,0,0,0,0,0,0,0,6,15,0,0,0,0
0,0,0,0,0,0,0,0,0,0,16,17,0,0,0,0,0,0,0,17,17,0,0,0,0
0,0,0,0,0,0,0,0,0,0,14,14,0,0,0,0,0,0,0,14,14,0,0,0,0
0,0,0,0,0,0,0,0,0,0,16,6,0,0,0,0,0,0,0,6,15,0,0,0,0
0,0,0,0,0,0,0,0,0,0,20,6,6,15,16,6,15,16,6,6,20,0,0,0,0
0,0,0,0,0,0,0,0,0,0,20,20,17,15,16,17,15,16,17,20,20,0,0,0,0
0,0,0,0,0,0,0,0,0,0,0,0,0,0,0,0,0,0,0,0,0,0,0,0,0
0,0,0,0,0,0,0,0,0,0,0,0,0,0,0,0,0,0,0,0,0,0,0,0,0
0,0,0,0,0,0,0,0,0,0,0,0,0,0,0,0,0,0,0,0,0,0,0,0,0
0,0,0,0,0,0,0,0,0,0,0,0,0,0,0,0,0,0,0,0,0,0,0,0,0
endlayer

layer
0,0,0,0,0,0,0,0,0,0,0,0,0,0,0,0,0,0,0,0,0,0,0,0,0
0,0,0,0,0,0,0,0,0,0,0,0,0,0,0,0,0,0,0,0,0,0,0,0,0
0,0,0,0,0,0,0,0,0,0,0,0,0,0,0,0,0,0,0,0,0,0,0,0,0
0,0,0,0,0,0,0,0,0,0,0,0,0,0,0,0,0,0,0,0,0,0,0,0,0
0,0,0,0,0,0,0,0,0,0,0,0,0,13,12,0,13,12,0,0,0,0,0,0,0
0,0,0,0,0,0,0,0,0,0,0,6,6,6,6,6,6,6,6,6,0,0,0,0,0
0,0,0,0,0,0,0,0,0,0,0,6,0,0,0,0,0,0,0,6,0,0,0,0,0
0,0,0,0,0,0,0,0,0,0,11,6,0,0,0,0,0,0,0,6,11,0,0,0,0
0,0,0,0,0,0,0,0,0,0,18,6,0,0,0,0,0,0,0,6,18,0,0,0,0
0,0,0,0,0,0,0,0,0,0,0,6,0,0,0,0,0,0,0,6,0,0,0,0,0
0,0,0,0,0,0,0,0,0,0,11,6,0,0,0,0,0,0,0,6,11,0,0,0,0
0,0,0,0,0,0,0,0,0,0,18,6,0,0,0,0,0,0,0,6,18,0,0,0,0
0,0,0,0,0,0,0,0,0,0,0,6,0,0,0,0,0,0,0,6,0,0,0,0,0
0,0,0,0,0,0,0,0,0,0,0,6,6,6,6,6,6,6,6,6,0,0,0,0,0
0,0,0,0,0,0,0,0,0,0,0,0,0,13,12,0,13,12,0,0,0,0,0,0,0
0,0,0,0,0,0,0,0,0,0,0,0,0,0,0,0,0,0,0,0,0,0,0,0,0
0,0,0,0,0,0,0,0,0,0,0,0,0,0,0,0,0,0,0,0,0,0,0,0,0
0,0,0,0,0,0,0,0,0,0,0,0,0,0,0,0,0,0,0,0,0,0,0,0,0
0,0,0,0,0,0,0,0,0,0,0,0,0,0,0,0,0,0,0,0,0,0,0,0,0
endlayer

layer
0,0,0,0,0,0,0,0,0,0,0,0,0,0,0,0,0,0,0,0,0,0,0,0,0
0,0,0,0,0,0,0,0,0,0,0,0,0,0,0,0,0,0,0,0,0,0,0,0,0
0,0,0,0,0,0,0,0,0,0,0,0,0,0,0,0,0,0,0,0,0,0,0,0,0
0,0,0,0,0,0,0,0,0,0,0,0,0,0,0,0,0,0,0,0,0,0,0,0,0
0,0,0,0,0,0,0,0,0,0,20,14,14,14,14,14,14,14,14,14,20,0,0,0,0
0,0,0,0,0,0,0,0,0,0,16,6,6,6,6,6,6,6,6,6,15,0,0,0,0
0,0,0,0,0,0,0,0,0,0,16,6,0,0,0,0,0,0,0,6,15,0,0,0,0
0,0,0,0,0,0,0,0,0,0,16,6,0,0,0,0,0,0,0,6,15,0,0,0,0
0,0,0,0,0,0,0,0,0,0,16,6,0,0,0,0,0,0,0,6,15,0,0,0,0
0,0,0,0,0,0,0,0,0,0,16,6,0,0,0,0,0,0,0,6,15,0,0,0,0
0,0,0,0,0,0,0,0,0,0,16,6,0,0,0,0,0,0,0,6,15,0,0,0,0
0,0,0,0,0,0,0,0,0,0,16,6,0,0,0,0,0,0,0,6,15,0,0,0,0
0,0,0,0,0,0,0,0,0,0,16,6,0,0,0,0,0,0,0,6,15,0,0,0,0
0,0,0,0,0,0,0,0,0,0,16,6,6,6,6,6,6,6,6,6,15,0,0,0,0
0,0,0,0,0,0,0,0,0,0,20,17,17,17,17,17,17,17,17,17,20,0,0,0,0
0,0,0,0,0,0,0,0,0,0,0,0,0,0,0,0,0,0,0,0,0,0,0,0,0
0,0,0,0,0,0,0,0,0,0,0,0,0,0,0,0,0,0,0,0,0,0,0,0,0
0,0,0,0,0,0,0,0,0,0,0,0,0,0,0,0,0,0,0,0,0,0,0,0,0
0,0,0,0,0,0,0,0,0,0,0,0,0,0,0,0,0,0,0,0,0,0,0,0,0
endlayer

layer
0,0,0,0,0,0,0,0,0,0,0,0,0,0,0,0,0,0,0,0,0,0,0,0,0
0,0,0,0,0,0,0,0,0,0,0,0,0,0,0,0,0,0,0,0,0,0,0,0,0
0,0,0,0,0,0,0,0,0,0,0,0,0,0,0,0,0,0,0,0,0,0,0,0,0
0,0,0,0,0,0,0,0,0,0,0,0,0,0,0,0,0,0,0,0,0,0,0,0,0
0,0,0,0,0,0,0,0,0,0,0,0,0,0,0,0,0,0,0,0,0,0,0,0,0
0,0,0,0,0,0,0,0,0,0,0,6,6,11,11,6,11,11,6,6,0,0,0,0,0
0,0,0,0,0,0,0,0,0,0,0,6,0,0,0,0,0,0,0,6,0,0,0,0,0
0,0,0,0,0,0,0,0,0,0,0,13,0,0,0,0,0,0,0,12,0,0,0,0,0
0,0,0,0,0,0,0,0,0,0,0,13,0,0,0,0,0,0,0,12,0,0,0,0,0
0,0,0,0,0,0,0,0,0,0,0,6,0,0,0,0,0,0,0,6,0,0,0,0,0
0,0,0,0,0,0,0,0,0,0,0,13,0,0,0,0,0,0,0,12,0,0,0,0,0
0,0,0,0,0,0,0,0,0,0,0,13,0,0,0,0,0,0,0,12,0,0,0,0,0
0,0,0,0,0,0,0,0,0,0,0,6,0,0,0,0,0,0,0,6,0,0,0,0,0
0,0,0,0,0,0,0,0,0,0,0,6,6,18,18,6,18,18,6,6,0,0,0,0,0
0,0,0,0,0,0,0,0,0,0,0,0,0,0,0,0,0,0,0,0,0,0,0,0,0
0,0,0,0,0,0,0,0,0,0,0,0,0,0,0,0,0,0,0,0,0,0,0,0,0
0,0,0,0,0,0,0,0,0,0,0,0,0,0,0,0,0,0,0,0,0,0,0,0,0
0,0,0,0,0,0,0,0,0,0,0,0,0,0,0,0,0,0,0,0,0,0,0,0,0
0,0,0,0,0,0,0,0,0,0,0,0,0,0,0,0,0,0,0,0,0,0,0,0,0
endlayer

layer
0,0,0,0,0,0,0,0,0,0,0,0,0,0,0,0,0,0,0,0,0,0,0,0,0
0,0,0,0,0,0,0,0,0,0,0,0,0,0,0,0,0,0,0,0,0,0,0,0,0
0,0,0,0,0,0,0,0,0,0,0,0,0,0,0,0,0,0,0,0,0,0,0,0,0
0,0,0,0,0,0,0,0,0,0,0,0,0,0,0,0,0,0,0,0,0,0,0,0,0
0,0,0,0,0,0,0,0,0,0,0,0,0,0,0,0,0,0,0,0,0,0,0,0,0
0,0,0,0,0,0,0,0,0,0,0,6,19,0,0,19,0,0,19,6,0,0,0,0,0
0,0,0,0,0,0,0,0,0,0,0,19,0,0,0,0,0,0,0,19,0,0,0,0,0
0,0,0,0,0,0,0,0,0,0,0,0,0,0,0,0,0,0,0,0,0,0,0,0,0
0,0,0,0,0,0,0,0,0,0,0,0,0,0,0,0,0,0,0,0,0,0,0,0,0
0,0,0,0,0,0,0,0,0,0,0,19,0,0,0,0,0,0,0,19,0,0,0,0,0
0,0,0,0,0,0,0,0,0,0,0,0,0,0,0,0,0,0,0,0,0,0,0,0,0
0,0,0,0,0,0,0,0,0,0,0,0,0,0,0,0,0,0,0,0,0,0,0,0,0
0,0,0,0,0,0,0,0,0,0,0,19,0,0,0,0,0,0,0,19,0,0,0,0,0
0,0,0,0,0,0,0,0,0,0,0,6,19,0,0,19,0,0,19,6,0,0,0,0,0
0,0,0,0,0,0,0,0,0,0,0,0,0,0,0,0,0,0,0,0,0,0,0,0,0
0,0,0,0,0,0,0,0,0,0,0,0,0,0,0,0,0,0,0,0,0,0,0,0,0
0,0,0,0,0,0,0,0,0,0,0,0,0,0,0,0,0,0,0,0,0,0,0,0,0
0,0,0,0,0,0,0,0,0,0,0,0,0,0,0,0,0,0,0,0,0,0,0,0,0
0,0,0,0,0,0,0,0,0,0,0,0,0,0,0,0,0,0,0,0,0,0,0,0,0
endlayer

layer
0,0,0,0,0,0,0,0,0,0,0,0,0,0,0,0,0,0,0,0,0,0,0,0,0
0,0,0,0,0,0,0,0,0,0,0,0,0,0,0,0,0,0,0,0,0,0,0,0,0
0,0,0,0,0,0,0,0,0,0,0,0,0,0,0,0,0,0,0,0,0,0,0,0,0
0,0,0,0,0,0,0,0,0,0,0,0,0,0,0,0,0,0,0,0,0,0,0,0,0
0,0,0,0,0,0,0,0,0,0,0,0,0,0,0,0,0,0,0,0,0,0,0,0,0
0,0,0,0,0,0,0,0,0,0,0,6,19,0,0,19,0,0,19,6,0,0,0,0,0
0,0,0,0,0,0,0,0,0,0,0,19,0,0,0,7,0,0,0,19,0,0,0,0,0
0,0,0,0,0,0,0,0,0,0,0,0,0,0,0,0,0,0,0,0,0,0,0,0,0
0,0,0,0,0,0,0,0,0,0,0,0,0,0,0,0,0,0,0,0,0,0,0,0,0
0,0,0,0,0,0,0,0,0,0,0,19,9,0,0,0,0,0,8,19,0,0,0,0,0
0,0,0,0,0,0,0,0,0,0,0,0,0,0,0,0,0,0,0,0,0,0,0,0,0
0,0,0,0,0,0,0,0,0,0,0,0,0,0,0,0,0,0,0,0,0,0,0,0,0
0,0,0,0,0,0,0,0,0,0,0,19,0,0,0,10,0,0,0,19,0,0,0,0,0
0,0,0,0,0,0,0,0,0,0,0,6,19,0,0,19,0,0,19,6,0,0,0,0,0
0,0,0,0,0,0,0,0,0,0,0,0,0,0,0,0,0,0,0,0,0,0,0,0,0
0,0,0,0,0,0,0,0,0,0,0,0,0,0,0,0,0,0,0,0,0,0,0,0,0
0,0,0,0,0,0,0,0,0,0,0,0,0,0,0,0,0,0,0,0,0,0,0,0,0
0,0,0,0,0,0,0,0,0,0,0,0,0,0,0,0,0,0,0,0,0,0,0,0,0
0,0,0,0,0,0,0,0,0,0,0,0,0,0,0,0,0,0,0,0,0,0,0,0,0
endlayer

layer
0,0,0,0,0,0,0,0,0,0,0,0,0,0,0,0,0,0,0,0,0,0,0,0,0
0,0,0,0,0,0,0,0,0,0,0,0,0,0,0,0,0,0,0,0,0,0,0,0,0
0,0,0,0,0,0,0,0,0,0,0,0,0,0,0,0,0,0,0,0,0,0,0,0,0
0,0,0,0,0,0,0,0,0,0,0,0,0,0,0,0,0,0,0,0,0,0,0,0,0
0,0,0,0,0,0,0,0,0,0,0,0,0,0,0,0,0,0,0,0,0,0,0,0,0
0,0,0,0,0,0,0,0,0,0,0,6,19,0,0,19,0,0,19,6,0,0,0,0,0
0,0,0,0,0,0,0,0,0,0,0,19,0,0,0,0,0,0,0,19,0,0,0,0,0
0,0,0,0,0,0,0,0,0,0,0,0,0,0,0,0,0,0,0,0,0,0,0,0,0
0,0,0,0,0,0,0,0,0,0,0,0,0,0,0,0,0,0,0,0,0,0,0,0,0
0,0,0,0,0,0,0,0,0,0,0,19,0,0,0,0,0,0,0,19,0,0,0,0,0
0,0,0,0,0,0,0,0,0,0,0,0,0,0,0,0,0,0,0,0,0,0,0,0,0
0,0,0,0,0,0,0,0,0,0,0,0,0,0,0,0,0,0,0,0,0,0,0,0,0
0,0,0,0,0,0,0,0,0,0,0,19,0,0,0,0,0,0,0,19,0,0,0,0,0
0,0,0,0,0,0,0,0,0,0,0,6,19,0,0,19,0,0,19,6,0,0,0,0,0
0,0,0,0,0,0,0,0,0,0,0,0,0,0,0,0,0,0,0,0,0,0,0,0,0
0,0,0,0,0,0,0,0,0,0,0,0,0,0,0,0,0,0,0,0,0,0,0,0,0
0,0,0,0,0,0,0,0,0,0,0,0,0,0,0,0,0,0,0,0,0,0,0,0,0
0,0,0,0,0,0,0,0,0,0,0,0,0,0,0,0,0,0,0,0,0,0,0,0,0
0,0,0,0,0,0,0,0,0,0,0,0,0,0,0,0,0,0,0,0,0,0,0,0,0
endlayer

layer
0,0,0,0,0,0,0,0,0,0,0,0,0,0,0,0,0,0,0,0,0,0,0,0,0
0,0,0,0,0,0,0,0,0,0,0,0,0,0,0,0,0,0,0,0,0,0,0,0,0
0,0,0,0,0,0,0,0,0,0,0,0,0,0,0,0,0,0,0,0,0,0,0,0,0
0,0,0,0,0,0,0,0,0,0,0,0,0,0,0,0,0,0,0,0,0,0,0,0,0
0,0,0,0,0,0,0,0,0,0,0,0,0,0,0,0,0,0,0,0,0,0,0,0,0
0,0,0,0,0,0,0,0,0,0,0,6,6,15,16,6,15,16,6,6,0,0,0,0,0
0,0,0,0,0,0,0,0,0,0,0,6,0,0,0,0,0,0,0,6,0,0,0,0,0
0,0,0,0,0,0,0,0,0,0,0,17,0,0,0,0,0,0,0,17,0,0,0,0,0
0,0,0,0,0,0,0,0,0,0,0,14,0,0,0,0,0,0,0,14,0,0,0,0,0
0,0,0,0,0,0,0,0,0,0,0,6,0,0,0,0,0,0,0,6,0,0,0,0,0
0,0,0,0,0,0,0,0,0,0,0,17,0,0,0,0,0,0,0,17,0,0,0,0,0
0,0,0,0,0,0,0,0,0,0,0,14,0,0,0,0,0,0,0,14,0,0,0,0,0
0,0,0,0,0,0,0,0,0,0,0,6,0,0,0,0,0,0,0,6,0,0,0,0,0
0,0,0,0,0,0,0,0,0,0,0,6,6,15,16,6,15,16,6,6,0,0,0,0,0
0,0,0,0,0,0,0,0,0,0,0,0,0,0,0,0,0,0,0,0,0,0,0,0,0
0,0,0,0,0,0,0,0,0,0,0,0,0,0,0,0,0,0,0,0,0,0,0,0,0
0,0,0,0,0,0,0,0,0,0,0,0,0,0,0,0,0,0,0,0,0,0,0,0,0
0,0,0,0,0,0,0,0,0,0,0,0,0,0,0,0,0,0,0,0,0,0,0,0,0
0,0,0,0,0,0,0,0,0,0,0,0,0,0,0,0,0,0,0,0,0,0,0,0,0
endlayer

layer
0,0,0,0,0,0,0,0,0,0,0,0,0,0,0,0,0,0,0,0,0,0,0,0,0
0,0,0,0,0,0,0,0,0,0,0,0,0,0,0,0,0,0,0,0,0,0,0,0,0
0,0,0,0,0,0,0,0,0,0,0,0,0,0,0,0,0,0,0,0,0,0,0,0,0
0,0,0,0,0,0,0,0,0,0,0,0,0,0,0,0,0,0,0,0,0,0,0,0,0
0,0,0,0,0,0,0,0,0,0,20,20,14,14,14,14,14,14,14,20,20,0,0,0,0
0,0,0,0,0,0,0,0,0,0,20,6,6,6,6,6,6,6,6,6,20,0,0,0,0
0,0,0,0,0,0,0,0,0,0,16,6,6,6,0,0,0,6,6,6,15,0,0,0,0
0,0,0,0,0,0,0,0,0,0,16,6,6,0,0,0,0,0,6,6,15,0,0,0,0
0,0,0,0,0,0,0,0,0,0,16,6,0,0,0,0,0,0,0,6,15,0,0,0,0
0,0,0,0,0,0,0,0,0,0,16,6,0,0,0,0,0,0,0,6,15,0,0,0,0
0,0,0,0,0,0,0,0,0,0,16,6,0,0,0,0,0,0,0,6,15,0,0,0,0
0,0,0,0,0,0,0,0,0,0,16,6,6,0,0,0,0,0,6,6,15,0,0,0,0
0,0,0,0,0,0,0,0,0,0,16,6,6,6,0,0,0,6,6,6,15,0,0,0,0
0,0,0,0,0,0,0,0,0,0,20,6,6,6,6,6,6,6,6,6,20,0,0,0,0
0,0,0,0,0,0,0,0,0,0,20,20,17,17,17,17,17,17,17,20,20,0,0,0,0
0,0,0,0,0,0,0,0,0,0,0,0,0,0,0,0,0,0,0,0,0,0,0,0,0
0,0,0,0,0,0,0,0,0,0,0,0,0,0,0,0,0,0,0,0,0,0,0,0,0
0,0,0,0,0,0,0,0,0,0,0,0,0,0,0,0,0,0,0,0,0,0,0,0,0
0,0,0,0,0,0,0,0,0,0,0,0,0,0,0,0,0,0,0,0,0,0,0,0,0
endlayer

layer
0,0,0,0,0,0,0,0,0,0,0,0,0,0,0,0,0,0,0,0,0,0,0,0,0
0,0,0,0,0,0,0,0,0,0,0,0,0,0,0,0,0,0,0,0,0,0,0,0,0
0,0,0,0,0,0,0,0,0,0,0,0,0,0,0,0,0,0,0,0,0,0,0,0,0
0,0,0,0,0,0,0,0,0,0,0,0,0,0,0,0,0,0,0,0,0,0,0,0,0
0,0,0,0,0,0,0,0,0,0,0,0,0,0,0,0,0,0,0,0,0,0,0,0,0
0,0,0,0,0,0,0,0,0,0,0,0,21,11,11,19,11,11,21,0,0,0,0,0,0
0,0,0,0,0,0,0,0,0,0,0,21,19,6,22,22,22,6,19,21,0,0,0,0,0
0,0,0,0,0,0,0,0,0,0,0,13,6,22,0,0,0,22,6,12,0,0,0,0,0
0,0,0,0,0,0,0,0,0,0,0,13,22,0,0,0,0,0,22,12,0,0,0,0,0
0,0,0,0,0,0,0,0,0,0,0,19,22,0,0,0,0,0,22,19,0,0,0,0,0
0,0,0,0,0,0,0,0,0,0,0,13,22,0,0,0,0,0,22,12,0,0,0,0,0
0,0,0,0,0,0,0,0,0,0,0,13,6,22,0,0,0,22,6,12,0,0,0,0,0
0,0,0,0,0,0,0,0,0,0,0,21,19,6,22,22,22,6,19,21,0,0,0,0,0
0,0,0,0,0,0,0,0,0,0,0,0,21,18,18,19,18,18,21,0,0,0,0,0,0
0,0,0,0,0,0,0,0,0,0,0,0,0,0,0,0,0,0,0,0,0,0,0,0,0
0,0,0,0,0,0,0,0,0,0,0,0,0,0,0,0,0,0,0,0,0,0,0,0,0
0,0,0,0,0,0,0,0,0,0,0,0,0,0,0,0,0,0,0,0,0,0,0,0,0
0,0,0,0,0,0,0,0,0,0,0,0,0,0,0,0,0,0,0,0,0,0,0,0,0
0,0,0,0,0,0,0,0,0,0,0,0,0,0,0,0,0,0,0,0,0,0,0,0,0
endlayer

layer
0,0,0,0,0,0,0,0,0,0,0,0,0,0,0,0,0,0,0,0,0,0,0,0,0
0,0,0,0,0,0,0,0,0,0,0,0,0,0,0,0,0,0,0,0,0,0,0,0,0
0,0,0,0,0,0,0,0,0,0,0,0,0,0,0,0,0,0,0,0,0,0,0,0,0
0,0,0,0,0,0,0,0,0,0,0,0,0,0,0,0,0,0,0,0,0,0,0,0,0
0,0,0,0,0,0,0,0,0,0,0,0,0,0,0,0,0,0,0,0,0,0,0,0,0
0,0,0,0,0,0,0,0,0,0,0,0,0,14,14,19,14,14,0,0,0,0,0,0,0
0,0,0,0,0,0,0,0,0,0,0,0,19,22,22,22,22,22,19,0,0,0,0,0,0
0,0,0,0,0,0,0,0,0,0,0,16,22,22,0,0,0,22,22,15,0,0,0,0,0
0,0,0,0,0,0,0,0,0,0,0,16,22,0,0,0,0,0,22,15,0,0,0,0,0
0,0,0,0,0,0,0,0,0,0,0,19,22,0,0,0,0,0,22,19,0,0,0,0,0
0,0,0,0,0,0,0,0,0,0,0,16,22,0,0,0,0,0,22,15,0,0,0,0,0
0,0,0,0,0,0,0,0,0,0,0,16,22,22,0,0,0,22,22,15,0,0,0,0,0
0,0,0,0,0,0,0,0,0,0,0,0,19,22,22,22,22,22,19,0,0,0,0,0,0
0,0,0,0,0,0,0,0,0,0,0,0,0,17,17,19,17,17,0,0,0,0,0,0,0
0,0,0,0,0,0,0,0,0,0,0,0,0,0,0,0,0,0,0,0,0,0,0,0,0
0,0,0,0,0,0,0,0,0,0,0,0,0,0,0,0,0,0,0,0,0,0,0,0,0
0,0,0,0,0,0,0,0,0,0,0,0,0,0,0,0,0,0,0,0,0,0,0,0,0
0,0,0,0,0,0,0,0,0,0,0,0,0,0,0,0,0,0,0,0,0,0,0,0,0
0,0,0,0,0,0,0,0,0,0,0,0,0,0,0,0,0,0,0,0,0,0,0,0,0
endlayer

layer
0,0,0,0,0,0,0,0,0,0,0,0,0,0,0,0,0,0,0,0,0,0,0,0,0
0,0,0,0,0,0,0,0,0,0,0,0,0,0,0,0,0,0,0,0,0,0,0,0,0
0,0,0,0,0,0,0,0,0,0,0,0,0,0,0,0,0,0,0,0,0,0,0,0,0
0,0,0,0,0,0,0,0,0,0,0,0,0,0,0,0,0,0,0,0,0,0,0,0,0
0,0,0,0,0,0,0,0,0,0,0,0,0,0,0,0,0,0,0,0,0,0,0,0,0
0,0,0,0,0,0,0,0,0,0,0,0,21,11,11,11,11,11,21,0,0,0,0,0,0
0,0,0,0,0,0,0,0,0,0,0,21,6,22,22,22,22,22,6,21,0,0,0,0,0
0,0,0,0,0,0,0,0,0,0,0,13,22,22,0,0,0,22,22,12,0,0,0,0,0
0,0,0,0,0,0,0,0,0,0,0,13,22,22,0,0,0,22,22,12,0,0,0,0,0
0,0,0,0,0,0,0,0,0,0,0,13,22,22,0,0,0,22,22,12,0,0,0,0,0
0,0,0,0,0,0,0,0,0,0,0,13,22,22,0,0,0,22,22,12,0,0,0,0,0
0,0,0,0,0,0,0,0,0,0,0,13,22,22,0,0,0,22,22,12,0,0,0,0,0
0,0,0,0,0,0,0,0,0,0,0,21,6,22,22,22,22,22,6,21,0,0,0,0,0
0,0,0,0,0,0,0,0,0,0,0,0,21,18,18,18,18,18,21,0,0,0,0,0,0
0,0,0,0,0,0,0,0,0,0,0,0,0,0,0,0,0,0,0,0,0,0,0,0,0
0,0,0,0,0,0,0,0,0,0,0,0,0,0,0,0,0,0,0,0,0,0,0,0,0
0,0,0,0,0,0,0,0,0,0,0,0,0,0,0,0,0,0,0,0,0,0,0,0,0
0,0,0,0,0,0,0,0,0,0,0,0,0,0,0,0,0,0,0,0,0,0,0,0,0
0,0,0,0,0,0,0,0,0,0,0,0,0,0,0,0,0,0,0,0,0,0,0,0,0
endlayer

layer
0,0,0,0,0,0,0,0,0,0,0,0,0,0,0,0,0,0,0,0,0,0,0,0,0
0,0,0,0,0,0,0,0,0,0,0,0,0,0,0,0,0,0,0,0,0,0,0,0,0
0,0,0,0,0,0,0,0,0,0,0,0,0,0,0,0,0,0,0,0,0,0,0,0,0
0,0,0,0,0,0,0,0,0,0,0,0,0,0,0,0,0,0,0,0,0,0,0,0,0
0,0,0,0,0,0,0,0,0,0,0,0,0,0,0,0,0,0,0,0,0,0,0,0,0
0,0,0,0,0,0,0,0,0,0,0,0,0,0,0,0,0,0,0,0,0,0,0,0,0
0,0,0,0,0,0,0,0,0,0,0,0,0,22,22,22,22,22,0,0,0,0,0,0,0
0,0,0,0,0,0,0,0,0,0,0,0,22,0,22,22,22,0,22,0,0,0,0,0,0
0,0,0,0,0,0,0,0,0,0,0,0,22,22,0,0,0,22,22,0,0,0,0,0,0
0,0,0,0,0,0,0,0,0,0,0,0,22,22,0,0,0,22,22,0,0,0,0,0,0
0,0,0,0,0,0,0,0,0,0,0,0,22,22,0,0,0,22,22,0,0,0,0,0,0
0,0,0,0,0,0,0,0,0,0,0,0,22,0,22,22,22,0,22,0,0,0,0,0,0
0,0,0,0,0,0,0,0,0,0,0,0,0,22,22,22,22,22,0,0,0,0,0,0,0
0,0,0,0,0,0,0,0,0,0,0,0,0,0,0,0,0,0,0,0,0,0,0,0,0
0,0,0,0,0,0,0,0,0,0,0,0,0,0,0,0,0,0,0,0,0,0,0,0,0
0,0,0,0,0,0,0,0,0,0,0,0,0,0,0,0,0,0,0,0,0,0,0,0,0
0,0,0,0,0,0,0,0,0,0,0,0,0,0,0,0,0,0,0,0,0,0,0,0,0
0,0,0,0,0,0,0,0,0,0,0,0,0,0,0,0,0,0,0,0,0,0,0,0,0
0,0,0,0,0,0,0,0,0,0,0,0,0,0,0,0,0,0,0,0,0,0,0,0,0
endlayer

layer
0,0,0,0,0,0,0,0,0,0,0,0,0,0,0,0,0,0,0,0,0,0,0,0,0
0,0,0,0,0,0,0,0,0,0,0,0,0,0,0,0,0,0,0,0,0,0,0,0,0
0,0,0,0,0,0,0,0,0,0,0,0,0,0,0,0,0,0,0,0,0,0,0,0,0
0,0,0,0,0,0,0,0,0,0,0,0,0,0,0,0,0,0,0,0,0,0,0,0,0
0,0,0,0,0,0,0,0,0,0,0,0,0,0,0,0,0,0,0,0,0,0,0,0,0
0,0,0,0,0,0,0,0,0,0,0,0,0,0,0,0,0,0,0,0,0,0,0,0,0
0,0,0,0,0,0,0,0,0,0,0,0,0,23,23,23,23,23,0,0,0,0,0,0,0
0,0,0,0,0,0,0,0,0,0,0,0,25,22,22,22,22,22,24,0,0,0,0,0,0
0,0,0,0,0,0,0,0,0,0,0,0,25,22,0,0,0,22,24,0,0,0,0,0,0
0,0,0,0,0,0,0,0,0,0,0,0,25,22,0,0,0,22,24,0,0,0,0,0,0
0,0,0,0,0,0,0,0,0,0,0,0,25,22,0,0,0,22,24,0,0,0,0,0,0
0,0,0,0,0,0,0,0,0,0,0,0,25,22,22,22,22,22,24,0,0,0,0,0,0
0,0,0,0,0,0,0,0,0,0,0,0,0,26,26,26,26,26,0,0,0,0,0,0,0
0,0,0,0,0,0,0,0,0,0,0,0,0,0,0,0,0,0,0,0,0,0,0,0,0
0,0,0,0,0,0,0,0,0,0,0,0,0,0,0,0,0,0,0,0,0,0,0,0,0
0,0,0,0,0,0,0,0,0,0,0,0,0,0,0,0,0,0,0,0,0,0,0,0,0
0,0,0,0,0,0,0,0,0,0,0,0,0,0,0,0,0,0,0,0,0,0,0,0,0
0,0,0,0,0,0,0,0,0,0,0,0,0,0,0,0,0,0,0,0,0,0,0,0,0
0,0,0,0,0,0,0,0,0,0,0,0,0,0,0,0,0,0,0,0,0,0,0,0,0
endlayer

layer
0,0,0,0,0,0,0,0,0,0,0,0,0,0,0,0,0,0,0,0,0,0,0,0,0
0,0,0,0,0,0,0,0,0,0,0,0,0,0,0,0,0,0,0,0,0,0,0,0,0
0,0,0,0,0,0,0,0,0,0,0,0,0,0,0,0,0,0,0,0,0,0,0,0,0
0,0,0,0,0,0,0,0,0,0,0,0,0,0,0,0,0,0,0,0,0,0,0,0,0
0,0,0,0,0,0,0,0,0,0,0,0,0,0,0,0,0,0,0,0,0,0,0,0,0
0,0,0,0,0,0,0,0,0,0,0,0,0,0,0,0,0,0,0,0,0,0,0,0,0
0,0,0,0,0,0,0,0,0,0,0,0,0,0,0,0,0,0,0,0,0,0,0,0,0
0,0,0,0,0,0,0,0,0,0,0,0,0,25,23,23,23,24,0,0,0,0,0,0,0
0,0,0,0,0,0,0,0,0,0,0,0,0,25,22,22,22,24,0,0,0,0,0,0,0
0,0,0,0,0,0,0,0,0,0,0,0,0,25,22,22,22,24,0,0,0,0,0,0,0
0,0,0,0,0,0,0,0,0,0,0,0,0,25,22,22,22,24,0,0,0,0,0,0,0
0,0,0,0,0,0,0,0,0,0,0,0,0,25,26,26,26,24,0,0,0,0,0,0,0
0,0,0,0,0,0,0,0,0,0,0,0,0,0,0,0,0,0,0,0,0,0,0,0,0
0,0,0,0,0,0,0,0,0,0,0,0,0,0,0,0,0,0,0,0,0,0,0,0,0
0,0,0,0,0,0,0,0,0,0,0,0,0,0,0,0,0,0,0,0,0,0,0,0,0
0,0,0,0,0,0,0,0,0,0,0,0,0,0,0,0,0,0,0,0,0,0,0,0,0
0,0,0,0,0,0,0,0,0,0,0,0,0,0,0,0,0,0,0,0,0,0,0,0,0
0,0,0,0,0,0,0,0,0,0,0,0,0,0,0,0,0,0,0,0,0,0,0,0,0
0,0,0,0,0,0,0,0,0,0,0,0,0,0,0,0,0,0,0,0,0,0,0,0,0
endlayer

