
# Created by Ruins mod version 14.4 Ingame Parser
# authoring Player: Mikhaila666

weight=1
embed_into_distance=0
acceptable_target_blocks=
unacceptable_target_blocks=flowing_water,water,flowing_lava,lava
dimensions=20,35,35
allowable_overhang=0
max_leveling=2
leveling_buffer=0
preserve_water=0
preserve_lava=0

rule1=0,100,Railcraft:tile.railcraft.residual.heat-0
rule2=0,100,minecraft:grass-0
rule3=0,100,minecraft:gravel-0
rule4=0,100,minecraft:cobblestone-0
rule5=0,100,minecraft:dirt-0
rule6=0,100,minecraft:coal_ore-0
rule7=0,100,minecraft:netherrack-0
rule8=0,100,minecraft:tallgrass-1
rule9=0,100,minecraft:tallgrass-2
rule10=0,100,minecraft:cobblestone_wall-0
rule11=0,100,minecraft:log-0
rule12=0,100,minecraft:stone_stairs-0
rule13=0,100,minecraft:stonebrick-2
rule14=0,100,minecraft:fence-0
rule15=0,100,minecraft:stone_stairs-1
rule16=0,100,minecraft:stone_stairs-3
rule17=0,100,minecraft:stone_stairs-2
rule18=0,100,minecraft:ladder-4
rule19=0,100,minecraft:spruce_stairs-3
rule20=0,100,minecraft:wooden_slab-1
rule21=0,100,minecraft:spruce_stairs-2
rule22=0,100,minecraft:stone_slab-3
rule23=0,100,minecraft:log-3
rule24=0,100,minecraft:cauldron-0
rule25=0,100,ChestGenHook:dungeonChest:5-5
rule26=0,100,minecraft:fence_gate-3
rule27=0,100,minecraft:piston-1
rule28=0,100,minecraft:furnace-4
rule29=0,100,minecraft:crafting_table-0
rule30=0,100,minecraft:fence_gate-1
rule31=0,100,minecraft:birch_stairs-7
rule32=0,100,minecraft:birch_stairs-6
rule33=0,100,minecraft:birch_stairs-5
rule34=0,100,minecraft:spruce_stairs-0
rule35=0,100,minecraft:wooden_slab-10
rule36=0,100,minecraft:carpet-7
rule37=0,100,minecraft:birch_stairs-4
rule38=2,100,WallSign:null:null:null:null-4
rule39=2,100,WallSign:null:null:null:null-2
rule40=0,100,minecraft:spruce_stairs-1
rule41=2,100,WallSign:null:null:null:null-3
rule42=0,100,minecraft:spruce_stairs-6
rule43=0,100,minecraft:spruce_stairs-4
rule44=2,100,WallSign:null:null:null:null-5
rule45=0,100,minecraft:spruce_stairs-5
rule46=0,100,minecraft:spruce_stairs-7
rule47=0,100,minecraft:carpet-14
rule48=0,100,minecraft:iron_bars-0
rule49=0,100,minecraft:cauldron-2
rule50=0,100,minecraft:stained_hardened_clay-14
rule51=0,100,minecraft:ladder-5
rule52=0,100,minecraft:wooden_slab-9
rule53=0,100,minecraft:ladder-2
rule54=0,100,minecraft:ladder-3
rule55=0,100,minecraft:brewing_stand-0
rule56=2,100,minecraft:torch-1
rule57=2,100,minecraft:torch-3
rule58=2,100,minecraft:torch-4
rule59=0,100,minecraft:hay_block-0
rule60=0,100,minecraft:wool-13
rule61=0,100,minecraft:planks-1
rule62=0,100,minecraft:wooden_slab-2
rule63=0,100,minecraft:double_wooden_slab-1

layer
0,0,0,0,0,0,0,0,1,0,0,0,0,0,0,0,0,0,0,0,0,0,0,0,0,0,0,0,0,0,0,0,0,0,0
0,0,0,0,0,0,0,0,0,0,0,0,0,1,0,0,0,0,0,0,0,0,0,0,0,0,0,0,0,0,0,0,0,0,0
0,0,0,0,0,0,0,0,0,0,0,0,0,0,0,0,1,0,0,0,0,0,0,0,0,0,0,0,0,0,0,0,0,0,0
0,1,0,0,3,2,2,2,2,2,2,2,2,2,2,2,2,2,2,2,2,2,2,2,2,2,2,2,2,2,2,0,0,0,0
0,0,0,0,4,2,2,2,2,2,2,2,2,2,2,2,2,2,2,2,2,2,2,2,2,2,2,2,2,2,2,2,2,0,0
0,0,0,0,4,2,2,0,4,0,4,0,5,5,0,5,2,2,2,0,2,2,2,0,5,0,5,0,5,5,5,0,2,2,0
0,0,0,0,3,2,2,2,0,0,0,0,5,0,5,0,0,0,0,0,0,0,0,5,0,5,5,5,0,0,0,2,2,2,0
0,0,0,0,2,2,2,2,0,0,0,0,0,5,0,0,0,0,0,0,0,0,5,0,5,0,0,0,5,5,5,2,2,2,0
0,0,0,0,4,2,2,2,0,0,0,0,0,0,0,0,0,0,0,0,5,5,5,0,0,0,0,0,0,0,5,2,2,2,0
0,0,0,0,2,2,2,0,0,0,0,0,0,0,0,0,0,0,0,5,0,0,0,0,0,0,0,0,0,0,5,5,2,2,0
0,0,0,0,3,2,0,0,0,0,0,0,0,0,0,0,0,0,0,5,0,0,0,0,0,0,0,0,0,0,0,5,5,2,0
0,0,0,0,2,2,2,0,0,0,0,0,0,0,0,0,0,0,0,5,0,0,0,0,0,0,0,0,0,0,0,5,2,2,0
0,0,0,0,2,2,2,0,0,0,0,0,0,0,0,0,0,0,0,5,0,0,0,0,0,0,0,0,0,0,0,0,2,2,0
0,0,0,0,2,2,2,0,0,0,0,0,0,0,0,0,0,0,0,0,5,0,0,0,0,0,0,0,0,0,0,0,2,2,0
0,0,0,0,2,2,0,0,0,0,0,0,0,0,0,0,0,0,0,0,5,0,0,0,0,0,0,0,0,0,0,5,5,2,0
1,0,0,0,2,2,2,0,0,0,0,0,0,0,0,0,0,0,0,5,0,0,0,0,0,0,0,0,0,0,0,5,2,2,0
0,0,0,0,2,2,2,0,0,0,0,0,0,0,0,0,0,0,2,5,0,0,0,0,0,0,0,0,0,0,0,5,2,2,0
0,0,0,0,2,2,2,0,0,0,0,0,0,0,0,0,0,2,0,6,6,6,0,0,0,0,0,0,0,0,0,5,2,2,0
0,0,0,0,4,2,0,0,0,0,0,0,0,0,0,0,0,5,6,7,6,0,0,0,0,0,0,0,0,0,0,5,5,2,0
0,0,0,0,3,2,2,0,0,0,0,0,0,0,0,0,0,5,5,6,0,0,0,0,0,0,0,0,0,0,0,5,2,2,0
0,0,0,0,2,2,2,0,0,0,0,0,0,0,0,0,0,0,5,6,0,0,0,0,0,0,0,0,0,0,0,5,2,2,0
0,0,0,0,3,2,2,0,0,0,0,0,0,0,0,0,0,5,0,5,0,8,0,0,0,0,0,0,0,0,0,0,2,2,0
0,0,0,0,3,2,0,0,0,0,0,0,0,0,0,0,0,0,5,0,8,0,0,0,0,0,0,0,0,0,0,0,5,2,0
0,1,0,0,3,2,2,0,0,0,0,0,0,0,0,0,0,5,0,0,0,0,0,0,0,0,0,0,0,0,0,5,2,2,0
0,0,0,0,3,2,2,0,0,0,0,0,0,0,0,0,0,0,5,0,0,0,0,0,0,0,0,0,0,0,0,5,2,2,0
0,0,0,0,3,2,2,0,0,0,0,0,0,0,0,0,0,0,5,0,0,0,0,0,0,0,0,0,0,0,5,0,2,2,0
0,0,0,0,3,2,0,0,0,0,0,0,0,0,0,0,0,0,5,8,0,0,0,0,0,0,0,0,0,0,5,0,0,2,0
0,0,0,0,3,2,2,0,0,0,0,0,0,0,0,0,2,2,2,5,0,0,0,0,0,0,0,0,0,5,0,0,2,2,0
0,0,0,0,3,2,2,2,0,0,0,0,0,0,0,2,2,2,2,2,0,9,0,0,0,0,0,0,0,5,0,2,2,2,0
0,0,0,0,3,2,2,2,0,0,0,0,0,0,0,2,2,2,2,2,2,2,2,2,0,0,0,0,0,5,0,2,2,2,0
0,0,0,0,3,2,2,2,0,5,5,0,0,0,0,2,2,2,2,2,2,2,2,2,3,3,3,5,5,0,5,2,2,2,0
0,0,0,0,2,2,2,0,2,3,0,2,2,0,2,0,2,2,2,2,2,2,2,0,2,0,2,2,2,3,2,0,2,2,0
0,0,0,0,2,2,2,2,2,2,4,3,4,2,2,2,2,2,2,2,2,2,2,2,2,2,3,3,2,2,2,2,2,2,0
0,0,0,0,3,2,2,2,2,2,2,4,3,2,2,2,2,2,2,2,2,2,2,2,2,2,4,3,4,2,2,2,2,2,0
0,0,0,0,0,0,0,0,0,0,0,0,0,0,0,0,0,0,0,0,0,0,0,0,0,0,0,0,0,0,0,0,0,0,0
endlayer

layer
0,0,0,0,0,0,0,0,0,0,0,0,0,0,0,0,0,0,0,0,0,0,0,0,0,0,0,0,0,0,0,0,0,0,0
0,0,0,0,0,1,0,0,0,0,0,0,0,0,0,0,0,0,0,0,0,0,0,0,0,0,0,0,0,0,0,0,0,0,0
0,0,0,0,0,0,0,0,0,0,0,0,0,0,0,0,0,0,0,0,0,0,0,0,0,0,0,0,0,0,0,0,0,0,0
0,0,0,0,0,0,8,9,9,8,8,8,0,0,0,0,0,0,0,0,8,8,8,8,8,8,8,8,8,0,8,0,0,0,0
0,0,0,0,0,8,8,10,9,8,8,10,8,8,8,10,8,0,0,10,0,0,0,10,8,8,0,10,0,0,0,10,8,0,0
0,0,0,0,0,0,0,11,12,13,12,11,12,13,12,11,10,14,10,11,10,14,10,11,12,13,12,11,12,13,12,11,8,8,0
0,0,0,0,0,8,0,10,4,0,4,4,4,4,4,4,4,4,4,4,4,4,4,4,4,0,4,4,4,0,4,10,8,0,0
0,0,0,0,8,8,0,14,4,13,13,13,13,13,4,13,13,13,13,13,13,13,13,13,4,13,13,13,13,13,4,14,0,8,0
0,0,0,0,0,8,8,10,4,13,13,13,13,13,4,13,13,13,13,13,13,13,13,13,4,13,13,13,13,13,4,10,8,8,0
0,0,0,0,8,0,0,11,4,13,13,13,13,13,4,13,13,13,13,13,13,13,13,13,4,13,13,13,13,13,4,11,0,8,0
0,0,0,0,0,0,11,0,0,0,0,0,0,0,0,4,0,13,13,13,13,13,4,4,4,13,13,13,13,13,4,0,11,0,0
0,0,0,0,0,0,10,4,13,13,13,13,13,13,13,13,13,13,13,13,13,13,13,13,13,13,13,13,13,13,13,4,10,8,0
0,0,0,0,0,0,14,4,13,13,13,13,13,13,13,13,13,13,13,13,13,13,13,13,13,13,13,13,13,13,13,4,14,0,0
0,0,0,0,0,8,10,4,13,13,13,13,13,13,13,13,13,13,13,13,13,13,13,13,13,13,13,13,13,13,13,4,10,8,0
0,0,0,0,0,8,11,4,13,13,13,13,13,13,13,13,13,13,13,13,13,13,13,13,13,13,13,13,13,13,13,4,11,0,0
0,0,0,0,8,8,10,4,13,13,13,13,13,13,13,13,13,13,13,13,13,13,13,13,13,13,13,13,13,13,13,4,10,8,0
0,0,0,0,8,0,14,4,13,13,13,13,13,13,13,13,13,13,15,15,15,13,13,13,13,13,13,13,13,13,13,4,14,8,0
0,0,0,0,8,8,10,4,13,13,13,13,13,13,13,13,13,15,17,10,16,15,13,13,13,13,13,13,13,13,13,4,10,8,0
0,0,0,0,0,0,11,4,0,0,13,13,13,13,13,13,13,17,10,0,10,16,13,13,13,13,13,13,13,13,13,4,11,8,0
0,0,0,0,0,0,10,4,13,13,13,13,13,13,13,13,13,12,17,10,16,12,13,13,13,13,13,13,13,13,13,4,10,8,0
0,0,0,0,0,0,14,4,13,13,13,13,13,13,13,13,13,13,12,12,12,13,13,13,13,13,13,13,13,13,13,4,14,8,0
0,0,0,0,0,0,10,4,13,13,13,13,13,13,13,13,13,13,13,13,13,13,13,13,13,13,13,13,13,13,13,4,10,0,0
0,0,0,0,0,8,11,4,13,13,13,13,13,13,13,13,13,13,13,13,13,13,13,13,13,13,13,13,13,13,13,4,11,8,0
0,0,0,0,0,8,10,4,13,13,13,13,13,13,13,13,13,13,13,13,13,13,13,13,13,13,13,13,13,13,13,4,10,0,0
0,0,0,0,0,8,14,4,13,13,13,13,13,13,13,13,13,13,13,13,13,13,13,13,13,13,13,13,13,13,13,4,14,8,0
0,0,0,0,0,8,10,4,13,13,13,13,13,13,13,13,13,13,13,13,13,13,13,13,13,13,13,13,13,13,13,4,10,8,0
0,0,0,0,0,0,11,0,0,13,13,13,13,13,0,4,4,4,4,4,4,4,4,4,4,13,13,13,13,13,0,0,11,8,0
0,0,0,0,0,8,8,11,4,13,13,13,13,13,4,11,10,14,10,11,10,14,10,11,4,13,13,13,13,13,4,11,8,0,0
0,0,0,0,0,8,8,10,4,13,13,13,13,13,4,10,0,0,0,0,0,0,0,10,4,13,13,13,13,13,4,10,8,0,0
0,0,0,0,0,8,8,14,4,13,13,13,13,13,4,14,0,0,0,0,0,8,8,14,4,13,13,13,13,13,4,14,0,8,0
0,0,0,0,0,0,8,10,4,0,4,4,4,0,4,10,0,8,8,8,8,0,8,10,4,4,4,4,4,4,4,10,8,8,0
0,0,0,0,0,8,8,11,8,13,15,15,15,13,0,11,8,0,0,8,8,9,9,11,8,13,15,15,15,13,8,11,8,8,0
0,0,0,0,8,0,8,10,8,8,0,1,0,8,8,10,8,8,8,8,9,9,9,10,9,8,0,0,0,8,0,10,8,8,0
0,0,0,0,0,8,8,8,0,0,0,0,0,0,0,8,8,8,0,0,0,8,0,8,9,8,0,0,0,8,8,0,8,8,0
0,0,0,0,0,0,0,0,0,0,0,0,0,0,0,0,0,0,0,0,0,0,0,0,0,0,0,0,0,0,0,0,0,0,0
endlayer

layer
0,0,0,0,0,0,0,0,0,0,0,0,0,0,0,0,0,0,0,0,0,0,0,0,0,0,0,0,0,0,0,0,0,0,0
0,0,0,0,0,0,0,0,0,0,0,0,0,0,0,0,0,0,0,0,0,0,0,0,0,0,0,0,0,0,0,0,0,0,0
0,0,0,0,0,0,0,0,0,0,0,0,0,0,0,0,0,0,0,0,0,0,0,0,0,0,0,0,0,0,0,0,0,0,0
0,0,0,0,0,0,0,0,0,0,0,0,0,0,0,0,0,0,0,0,0,0,0,0,0,0,0,0,0,0,0,0,0,0,0
0,0,0,0,0,0,0,14,0,0,0,14,0,0,0,14,0,0,0,14,0,0,0,14,0,0,0,14,0,0,0,14,0,0,0
0,0,0,0,0,0,0,11,18,10,18,11,18,10,18,11,21,20,19,11,21,20,19,11,18,10,18,11,18,10,18,11,0,0,0
0,0,0,0,0,0,0,22,23,13,23,0,23,13,23,0,23,13,23,24,23,13,23,0,23,13,23,0,23,13,23,22,0,0,0
0,0,0,0,0,0,0,22,13,0,0,0,0,0,10,0,0,25,25,0,25,25,0,0,10,0,0,0,0,0,13,22,0,0,0
0,0,0,0,0,0,0,22,23,0,0,0,0,0,0,0,0,0,0,0,0,0,0,0,0,0,0,0,0,0,23,22,0,0,0
0,0,0,1,0,0,0,11,0,0,0,0,0,0,10,0,0,0,0,0,0,0,0,0,10,0,0,0,0,0,0,11,0,0,0
0,0,0,0,0,0,11,0,23,11,11,11,11,11,23,30,23,29,28,27,27,27,23,26,23,11,11,11,11,11,23,0,11,0,0
0,0,0,0,0,0,22,23,33,0,10,0,10,0,0,0,10,0,0,0,0,0,10,0,0,0,10,0,10,32,31,23,22,0,0
0,0,0,0,0,0,22,13,35,0,0,0,0,0,0,0,0,34,0,34,0,34,0,0,0,0,0,0,0,0,0,13,22,0,0
0,0,0,0,0,0,22,23,37,0,0,0,0,0,0,0,0,0,0,0,36,36,36,36,0,0,0,0,0,0,0,23,22,0,0
0,0,0,0,0,0,11,21,0,0,38,0,0,0,0,0,0,0,0,0,0,36,36,0,0,0,41,40,39,38,0,19,11,0,0
0,0,0,0,0,0,22,23,10,0,21,0,0,0,10,0,36,0,0,10,0,36,36,36,10,38,43,43,42,19,10,23,22,0,0
0,1,0,0,0,0,22,13,0,0,44,47,0,0,0,36,36,0,0,1,0,36,0,36,0,21,46,45,45,44,0,13,22,0,0
0,0,0,0,0,0,22,23,34,34,21,47,47,1,0,36,36,0,0,48,0,0,1,0,0,44,41,34,39,0,0,23,22,0,0
0,0,0,0,0,0,11,21,50,50,20,47,47,1,0,36,36,0,48,49,48,0,0,0,1,0,0,0,0,0,0,19,11,0,0
0,0,0,0,0,0,22,23,40,40,21,47,47,0,36,36,36,0,0,48,0,0,0,0,0,38,41,40,39,0,0,23,22,0,0
0,0,0,0,0,0,22,13,0,0,38,47,0,0,36,36,0,0,0,1,0,0,0,0,0,21,46,43,42,38,0,13,22,0,0
0,0,0,0,0,0,22,23,10,0,21,0,0,0,10,0,0,0,0,10,0,0,0,0,10,44,46,45,45,19,10,23,22,0,0
0,0,0,0,0,0,11,21,0,0,44,0,1,0,38,41,40,39,0,0,38,41,40,39,38,0,41,34,39,44,0,19,11,0,0
0,0,0,0,0,0,22,23,33,0,0,1,36,0,21,43,43,42,38,0,21,46,43,42,19,0,0,0,36,36,0,23,22,0,0
0,0,0,0,0,0,22,13,35,0,0,36,36,0,44,46,45,45,19,0,44,45,45,45,44,0,36,36,36,0,0,13,22,0,0
0,0,0,0,0,0,22,23,37,0,36,36,36,0,0,41,34,39,44,0,0,41,34,39,0,36,36,36,36,0,0,23,22,0,0
0,0,0,0,0,0,11,0,23,0,36,36,36,1,23,34,23,13,23,34,23,13,23,34,23,0,0,36,36,36,23,0,11,0,0
0,0,0,0,0,0,0,11,21,0,36,36,36,0,0,11,22,22,22,11,22,22,22,11,21,0,0,0,0,0,19,11,0,0,0
0,0,0,0,0,0,0,22,23,0,0,0,36,0,23,22,0,0,0,0,0,0,0,22,23,0,0,0,0,0,23,22,0,0,0
0,0,0,0,0,0,0,22,13,0,0,0,0,0,13,22,0,0,0,0,0,0,0,22,13,0,0,0,0,0,13,22,0,0,0
0,0,0,0,0,0,0,22,23,13,10,1,10,13,23,22,0,0,0,0,0,0,0,22,23,13,10,0,10,13,23,22,0,0,0
0,0,0,0,0,0,0,11,51,10,0,0,0,10,51,11,0,0,0,0,0,0,0,11,51,10,0,0,0,10,51,11,0,0,0
0,0,0,0,0,0,0,14,0,0,0,0,0,0,0,14,0,0,0,0,0,0,0,14,0,0,0,0,0,0,0,14,0,0,0
0,0,0,0,0,0,0,0,0,1,0,0,0,0,0,0,0,0,0,0,0,0,0,0,0,0,0,0,0,0,0,0,0,0,0
0,0,0,0,0,0,0,0,0,0,0,0,0,0,0,0,0,0,0,0,0,0,0,0,0,0,0,0,0,0,0,0,0,0,0
endlayer

layer
0,0,0,0,0,0,0,0,0,0,0,0,0,0,0,0,0,0,0,0,0,0,0,0,0,0,0,0,0,0,0,0,0,0,0
0,0,0,0,0,0,0,0,0,0,0,0,0,0,0,0,0,0,0,0,0,0,0,0,0,0,0,0,0,0,0,0,0,0,0
0,0,0,0,0,0,0,0,0,0,0,0,0,0,0,0,0,0,0,0,0,0,0,0,0,0,0,0,0,0,0,0,0,0,0
0,0,0,0,0,0,0,0,0,0,0,0,0,0,0,0,0,0,0,0,0,0,0,0,0,0,0,0,0,0,0,0,0,0,0
0,0,0,0,0,52,0,10,0,0,0,14,0,0,0,10,0,0,0,14,0,0,0,10,0,0,0,14,0,0,0,10,0,52,0
0,0,0,0,0,52,0,11,18,10,18,11,18,10,18,11,0,0,0,11,0,0,0,11,18,10,18,11,18,10,18,11,0,52,0
0,0,0,0,0,52,0,54,23,14,23,0,23,14,23,0,23,14,23,0,23,14,23,0,23,14,23,0,23,14,23,53,0,52,0
0,0,0,0,0,52,0,0,14,0,0,0,0,0,14,0,0,0,0,0,0,0,0,0,14,0,0,0,0,0,14,0,0,52,0
0,0,0,0,0,52,0,54,23,0,0,0,0,0,0,0,0,0,0,0,0,0,0,0,0,0,0,0,0,0,23,53,0,52,0
0,0,0,0,0,52,0,11,0,0,0,0,0,0,14,0,0,0,0,0,0,0,0,0,14,0,0,0,0,0,0,11,0,52,0
0,0,0,0,0,0,11,0,23,11,11,11,11,11,23,0,23,0,0,0,0,55,23,0,23,11,11,11,11,11,23,0,11,0,0
0,0,0,0,0,0,54,23,0,0,14,0,14,0,56,0,14,0,0,0,0,0,14,0,56,0,14,0,14,0,0,23,53,0,0
0,0,0,0,0,0,0,14,0,0,0,0,0,0,0,0,0,0,0,0,0,0,0,0,0,0,0,0,0,0,0,14,0,0,0
0,0,0,0,0,0,54,23,0,0,0,0,0,0,0,0,0,0,0,0,0,0,0,0,0,0,0,0,0,0,0,23,53,0,0
0,0,0,0,0,0,11,0,0,0,0,0,0,0,0,0,0,0,0,0,0,0,0,0,0,0,0,0,0,0,0,0,11,0,0
0,0,0,0,0,0,54,23,14,0,0,0,0,0,14,0,0,0,0,14,0,0,0,0,14,0,0,0,0,0,14,23,53,0,0
0,0,0,0,0,0,0,14,0,0,0,0,0,0,0,0,0,0,0,0,0,0,0,0,0,0,0,0,0,0,0,14,0,0,0
0,0,0,0,0,0,54,23,43,42,0,0,0,0,0,0,0,0,0,0,0,0,0,0,0,0,0,0,0,0,0,23,53,0,0
0,0,0,0,0,0,11,0,50,0,0,0,0,0,0,0,0,0,0,1,0,0,0,0,0,0,0,0,0,0,0,0,11,0,0
0,0,0,0,0,0,54,23,45,42,0,0,0,0,1,0,0,0,0,0,0,0,0,0,0,0,0,0,0,0,0,23,53,0,0
0,0,0,0,0,0,0,14,0,0,0,0,0,0,0,0,0,0,0,0,0,0,0,0,0,0,0,0,0,0,0,14,0,0,0
0,0,0,0,0,0,54,23,14,0,0,0,0,0,14,0,0,0,0,14,0,0,0,0,14,0,0,0,0,0,14,23,53,0,0
0,0,0,0,0,0,11,0,0,0,0,0,0,0,0,0,0,0,0,0,0,0,0,0,0,0,0,0,0,0,0,0,11,0,0
0,0,0,0,0,0,54,23,0,0,0,0,0,0,0,0,0,0,0,0,0,0,0,0,0,0,0,0,0,0,0,23,53,0,0
0,0,0,0,0,0,0,14,0,0,0,1,0,0,0,0,0,0,0,0,0,0,0,0,0,0,0,0,0,0,0,14,0,0,0
0,0,0,0,0,0,54,23,0,0,0,1,0,0,0,0,0,0,0,0,0,0,0,0,0,0,0,0,0,0,0,23,53,0,0
0,0,0,0,0,0,11,0,23,0,0,0,0,0,23,0,23,14,23,0,23,14,23,0,23,0,0,0,0,0,23,0,11,0,0
0,0,0,0,0,52,0,11,0,0,0,0,0,0,0,11,0,0,0,11,0,0,0,11,0,0,0,0,0,0,0,11,0,52,0
0,0,0,0,0,52,0,54,23,58,0,0,0,57,23,0,0,0,0,0,0,0,0,0,23,58,0,0,0,57,23,53,0,52,0
0,0,0,0,0,52,0,0,14,0,0,0,0,0,14,0,0,0,0,0,0,0,0,0,14,0,0,0,0,0,14,0,0,52,0
0,0,0,0,0,52,0,54,23,14,10,0,10,14,23,0,0,0,0,0,0,0,0,0,23,14,10,0,10,14,23,53,0,52,0
0,0,0,0,0,52,0,11,51,10,0,0,0,10,51,11,0,0,0,0,0,0,0,11,51,10,0,0,0,10,51,11,0,52,0
0,0,0,0,0,52,0,10,0,0,0,0,0,0,0,10,0,0,0,0,0,0,0,10,0,0,0,0,0,0,0,10,0,52,0
0,0,0,0,0,0,0,0,0,0,0,0,0,0,0,0,0,0,0,0,0,0,0,0,0,0,0,0,0,0,0,0,0,0,0
0,0,0,0,0,0,0,0,0,0,0,0,0,0,0,0,0,0,0,0,0,0,0,0,0,0,0,0,0,0,0,0,0,0,0
endlayer

layer
0,0,0,0,0,0,0,0,0,0,0,0,0,0,0,0,0,0,0,0,0,0,0,0,0,0,0,0,0,0,0,0,0,0,0
0,0,0,0,0,0,0,0,0,0,0,0,0,0,0,0,0,0,0,0,0,0,0,0,0,0,0,0,0,0,0,0,0,0,0
0,0,0,0,0,0,0,0,0,0,0,0,0,0,0,0,0,0,0,0,0,0,0,0,0,0,0,0,0,0,0,0,0,0,0
0,0,0,0,0,0,0,0,0,0,0,0,0,0,0,0,0,0,0,0,0,0,0,0,0,0,0,0,0,0,0,0,0,0,0
0,0,0,0,0,0,19,42,0,0,0,14,0,0,0,46,21,0,0,10,0,0,19,42,0,0,0,14,0,0,0,46,21,0,0
0,0,0,0,0,0,59,11,42,10,0,11,0,10,46,11,42,0,46,11,42,0,46,11,42,10,0,11,0,10,46,11,59,0,0
0,0,0,0,0,0,59,45,23,14,23,0,23,14,23,0,23,14,23,0,23,14,23,0,23,14,23,0,23,14,23,45,59,0,0
0,0,0,0,0,0,59,0,14,0,0,0,0,0,45,0,0,0,0,0,0,0,0,0,45,0,0,0,0,0,14,0,59,0,0
0,0,0,0,0,0,59,43,23,0,0,0,0,0,0,0,0,0,0,0,0,0,0,0,0,0,0,0,0,0,23,43,59,0,0
0,0,0,0,0,34,59,11,42,0,0,0,0,0,43,0,0,0,0,0,0,0,0,0,43,0,0,0,0,0,46,11,59,34,0
0,0,0,0,0,45,11,0,23,11,11,11,11,11,23,14,23,14,14,14,14,14,23,14,23,11,11,11,11,11,23,0,11,45,0
0,0,0,0,0,35,45,23,0,45,14,45,14,45,0,0,14,0,0,0,0,0,14,0,0,45,14,45,14,45,0,23,45,35,0
0,0,0,0,0,0,0,14,0,0,0,0,0,0,0,0,0,0,0,0,0,0,0,0,0,0,0,0,0,0,0,14,0,0,0
0,0,0,0,0,0,43,23,60,0,0,0,0,0,0,0,0,0,0,0,0,0,0,0,0,0,0,0,0,0,60,23,43,0,0
0,0,0,0,0,0,11,42,0,0,0,0,0,0,0,0,0,0,0,0,0,0,0,0,0,0,0,0,0,0,0,46,11,0,0
0,0,0,0,0,0,45,23,14,0,0,0,0,0,14,0,0,0,0,14,0,0,0,0,14,0,0,0,0,0,14,23,45,0,0
0,0,0,0,0,0,0,14,0,0,0,0,0,0,0,0,0,0,0,0,0,0,0,0,0,0,0,0,0,0,0,14,0,0,0
0,0,0,0,0,0,43,23,34,0,0,0,0,0,0,0,0,0,0,0,0,0,0,0,0,0,0,0,0,0,0,23,43,0,0
0,0,0,0,0,0,11,42,61,0,0,0,0,0,0,1,0,0,0,0,0,0,0,0,0,0,0,0,0,0,0,46,11,0,0
0,0,0,0,0,0,45,23,40,0,0,0,0,0,0,0,0,0,0,0,0,0,0,0,0,0,0,0,0,0,0,23,45,0,0
0,0,0,0,0,0,0,14,0,0,0,0,0,0,0,0,0,0,0,0,0,0,0,0,0,0,0,0,0,0,0,14,0,0,0
0,0,0,0,0,0,43,23,14,0,0,0,0,0,14,0,0,0,0,14,0,0,0,0,14,0,0,0,0,0,14,23,43,0,0
0,0,0,0,0,0,11,42,0,0,0,0,0,0,0,0,0,0,0,0,0,0,0,0,0,0,0,0,0,0,0,46,11,0,0
0,0,0,0,0,0,45,23,60,0,0,0,0,0,0,0,0,0,0,0,0,0,0,0,0,0,0,0,0,0,60,23,45,0,0
0,0,0,0,0,0,0,14,0,0,0,0,0,0,0,0,0,0,0,0,0,0,0,0,0,0,0,0,0,0,0,14,0,0,0
0,0,0,0,0,35,43,23,0,0,0,0,0,0,0,0,0,0,0,0,0,0,0,0,0,0,0,0,0,0,0,23,43,35,0
0,0,0,0,0,43,11,0,23,0,0,0,0,0,23,43,23,14,23,0,23,14,23,43,23,0,0,0,0,0,23,0,11,43,0
0,0,0,0,0,40,59,11,42,0,0,0,0,0,46,11,42,0,46,11,42,0,46,11,42,0,0,0,0,0,46,11,59,40,0
0,0,0,0,0,0,59,45,23,0,0,0,0,0,23,45,52,0,0,0,0,0,52,45,23,0,0,0,0,0,23,45,59,0,0
0,0,0,0,0,0,59,0,14,0,0,0,0,0,14,0,52,0,0,0,0,0,52,0,14,0,0,0,0,0,14,0,59,0,0
0,0,0,0,0,0,59,43,23,14,32,0,31,14,23,0,52,0,0,0,0,0,52,0,23,14,32,0,31,14,23,43,59,0,0
0,0,0,0,0,0,59,11,42,10,0,0,0,10,46,11,52,0,0,0,0,0,52,11,42,10,0,0,0,10,46,11,59,0,0
0,0,0,0,0,0,19,42,0,0,0,0,0,0,0,46,21,0,0,0,0,0,19,42,0,0,0,0,0,0,0,46,21,0,0
0,0,0,0,0,0,0,0,0,0,0,0,0,0,0,0,0,0,0,0,0,0,0,0,0,0,0,0,0,0,0,0,0,0,0
0,0,0,0,0,0,0,0,0,0,0,0,0,0,0,0,0,0,0,0,0,0,0,0,0,0,0,0,0,0,0,0,0,0,0
endlayer

layer
0,0,0,0,0,0,0,0,0,0,0,0,0,0,0,0,0,0,0,0,0,0,0,0,0,0,0,0,0,0,0,0,0,0,0
0,0,0,0,0,0,0,0,0,0,0,0,0,0,1,1,0,0,0,0,0,0,0,0,0,0,0,0,0,0,0,0,0,0,0
0,0,0,0,0,0,0,0,0,0,0,0,0,0,0,0,0,0,0,0,0,0,0,0,0,0,0,0,0,0,0,0,0,0,1
0,0,0,0,0,0,0,0,0,0,0,0,0,0,0,0,0,0,0,0,0,0,0,0,0,0,0,0,0,0,0,0,0,0,0
0,0,0,0,0,0,0,19,42,0,0,14,0,0,46,21,20,20,20,20,20,20,20,19,42,0,0,14,0,0,46,21,0,0,0
0,0,0,0,0,0,0,59,11,32,14,11,14,31,11,59,59,59,59,59,59,59,59,59,11,32,14,11,14,31,11,59,0,0,0
0,0,0,0,0,0,0,59,0,11,11,62,11,11,0,59,59,59,59,59,59,59,59,59,0,11,11,62,11,11,0,59,0,0,0
0,0,0,0,0,0,0,59,11,32,0,0,0,31,11,59,42,0,0,0,0,0,46,59,11,32,0,0,0,31,11,59,0,0,0
0,0,0,0,0,0,0,59,11,0,0,0,0,0,61,59,42,0,0,0,0,0,46,59,61,0,0,0,0,0,11,59,0,0,0
0,0,0,0,0,0,0,59,11,0,0,0,0,0,11,59,42,0,0,0,0,0,46,59,11,0,0,0,0,0,11,59,0,0,0
0,0,0,0,0,34,59,59,11,21,11,14,11,19,11,59,23,42,52,52,52,46,23,59,11,21,11,14,11,19,11,59,59,34,0
0,0,0,0,0,45,0,11,33,0,14,0,14,0,33,0,10,0,0,0,0,0,10,0,33,0,14,0,14,0,33,11,0,45,0
0,0,0,0,0,62,0,11,0,0,0,0,0,0,0,0,0,0,0,0,0,0,0,0,0,0,0,0,0,0,0,11,0,62,0
0,0,0,0,0,62,0,11,60,0,0,0,0,0,0,0,0,0,0,0,0,0,0,0,0,0,0,0,0,0,60,11,0,62,0
0,0,0,0,33,35,11,21,0,0,0,0,0,0,0,0,0,0,0,0,0,0,0,0,0,0,0,0,0,0,0,19,11,35,0
0,0,0,0,0,35,0,11,14,0,0,0,0,0,14,0,0,0,0,14,0,0,0,0,14,0,0,0,0,0,14,11,0,35,0
0,0,0,0,0,0,0,11,60,0,0,0,0,0,0,0,0,0,0,0,0,0,0,0,0,0,0,0,0,0,60,11,0,0,0
0,0,0,0,0,0,0,11,0,0,0,0,0,0,0,0,0,0,0,0,0,0,0,0,0,0,0,0,0,0,0,11,0,0,0
0,0,0,0,0,0,11,21,60,0,0,0,0,0,0,0,0,0,0,0,0,0,0,0,0,0,0,0,0,0,60,19,11,0,0
0,0,0,0,0,0,0,11,0,0,0,0,0,0,0,0,0,0,0,0,0,0,0,0,0,0,0,0,0,0,0,11,0,0,0
0,0,0,0,0,0,0,11,60,0,0,0,0,0,0,0,0,0,0,0,0,0,0,0,0,0,0,0,0,0,60,11,0,0,0
0,0,0,0,0,35,0,11,14,0,0,0,0,0,14,0,0,0,0,14,0,0,0,0,14,0,0,0,0,0,14,11,0,35,0
0,0,0,0,0,35,11,0,0,0,0,0,0,0,0,0,0,0,0,0,0,0,0,0,0,0,0,0,0,0,0,0,11,35,0
0,0,0,0,0,62,0,11,60,0,0,0,0,0,0,0,0,0,0,0,0,0,0,0,0,0,0,0,0,0,60,11,0,62,0
0,0,0,0,0,62,0,11,0,0,0,0,0,0,0,0,0,0,0,0,0,0,0,0,0,0,0,0,0,0,0,11,0,62,0
0,0,0,0,0,43,0,11,37,0,0,0,0,0,37,0,0,0,0,0,0,0,0,0,37,0,0,0,0,0,37,11,0,43,0
0,0,0,0,0,40,59,59,11,0,0,0,0,0,11,59,59,11,11,43,11,11,59,59,11,0,0,0,0,0,11,59,59,40,0
0,0,0,0,0,0,0,59,11,0,0,0,0,0,11,59,11,20,10,20,10,20,11,59,11,0,0,0,0,0,11,59,0,0,0
0,0,0,0,0,0,0,59,11,0,0,0,0,0,11,59,0,0,0,0,0,0,0,59,11,0,0,0,0,0,11,59,0,0,0
0,0,0,0,0,0,0,59,11,32,0,0,0,31,11,59,0,0,0,0,0,0,0,59,11,32,0,0,0,31,11,59,0,0,0
0,0,0,0,0,0,0,59,0,11,11,62,11,11,0,59,0,0,0,0,0,0,0,59,0,11,11,62,11,11,0,59,0,0,0
0,0,0,0,0,0,0,59,11,32,14,14,14,31,11,59,0,0,0,0,0,0,0,59,11,32,14,14,14,31,11,59,0,0,0
0,0,0,0,0,0,0,19,42,0,0,0,0,0,46,21,0,0,0,0,0,0,0,19,42,0,0,0,0,0,46,21,0,0,0
0,0,0,0,0,0,0,0,0,0,0,0,0,0,0,0,0,0,0,0,0,0,0,0,0,0,0,0,0,0,0,0,0,0,0
0,0,0,0,0,0,0,0,0,0,0,0,0,0,0,0,0,0,0,0,0,0,0,0,0,0,0,0,0,0,0,0,0,0,0
endlayer

layer
0,0,0,0,0,0,0,0,0,0,0,0,0,0,0,0,0,0,0,0,0,0,0,0,0,0,0,0,0,0,0,0,0,0,0
0,0,0,0,0,0,0,0,0,0,0,0,0,0,0,0,0,0,0,0,0,0,0,0,0,0,0,0,0,0,0,0,0,0,0
0,0,0,0,0,0,0,0,0,0,0,0,0,0,0,0,0,0,0,0,0,0,0,0,0,0,0,0,0,0,0,0,0,0,0
0,0,0,0,0,0,0,0,0,0,0,0,0,0,0,0,0,0,0,0,0,0,0,0,0,0,0,0,0,0,0,0,0,0,0
0,0,0,0,0,0,0,0,19,42,0,10,0,46,21,0,0,0,0,0,0,0,0,0,19,42,0,10,0,46,21,0,0,0,0
0,0,0,0,0,0,0,0,59,11,32,11,31,11,59,0,0,0,0,0,0,0,0,0,59,11,32,11,31,11,59,0,0,0,0
0,0,0,0,0,0,0,0,59,11,11,0,11,11,59,20,20,20,20,20,20,20,20,20,59,11,11,0,11,11,59,0,0,0,0
0,0,0,0,0,0,0,0,59,0,62,35,62,0,59,59,59,59,59,59,59,59,59,59,59,0,62,35,62,0,59,0,0,0,0
0,0,0,0,0,0,0,0,59,0,0,0,0,0,59,59,59,59,59,59,59,59,59,59,59,0,0,0,0,0,59,0,0,0,0
0,0,0,0,0,0,0,0,59,0,0,0,0,0,59,0,19,42,10,0,10,46,21,0,59,0,0,0,0,0,59,0,0,0,0
0,0,0,0,0,0,0,0,59,42,11,14,11,46,59,0,59,11,11,14,11,11,59,0,59,42,11,14,11,46,59,0,0,0,0
0,0,0,0,0,34,59,59,59,0,14,0,14,0,59,59,59,0,0,0,0,0,59,59,59,0,14,0,14,0,59,59,59,34,0
0,0,0,0,0,45,0,11,33,0,0,0,0,0,33,0,0,0,0,0,0,0,0,0,33,0,0,0,0,0,33,11,0,45,0
0,0,0,0,0,0,0,11,14,0,0,0,0,0,0,0,0,0,0,0,0,0,0,0,0,0,0,0,0,0,14,11,0,0,0
0,0,0,0,0,0,11,0,0,0,0,0,0,0,0,0,0,0,0,0,0,0,0,0,0,0,0,0,0,0,0,0,11,0,0
0,0,0,0,0,0,0,11,14,0,0,0,0,0,14,0,0,0,0,14,0,0,0,0,14,0,0,0,0,0,14,11,0,0,0
0,0,0,0,0,62,0,11,60,0,0,0,0,0,0,0,0,0,0,0,0,0,0,0,0,0,0,0,0,0,60,11,0,62,0
0,0,0,0,0,62,0,11,0,0,0,0,0,0,0,0,0,0,0,0,0,0,0,0,0,0,0,0,0,0,0,11,0,62,0
0,0,0,0,0,62,11,0,60,0,0,0,0,0,0,0,0,0,0,0,0,0,0,0,0,0,0,0,0,0,60,0,11,62,0
0,0,0,0,0,62,0,11,0,0,0,0,0,0,0,0,0,0,0,0,0,0,0,0,0,0,0,0,0,0,0,11,0,62,0
0,0,0,0,0,62,0,11,60,0,0,0,0,0,0,0,0,0,0,0,0,0,0,0,0,0,0,0,0,0,60,11,0,62,0
0,0,0,0,0,0,0,11,14,0,0,0,0,0,14,0,0,0,0,14,0,0,0,0,14,0,0,0,0,0,14,11,0,0,0
0,0,0,0,0,0,11,0,0,0,0,0,0,0,0,0,0,0,0,0,0,0,0,0,0,0,0,0,0,0,0,0,11,0,0
0,0,0,0,0,0,0,11,14,0,0,0,0,0,0,0,0,0,0,0,0,0,0,0,0,0,0,0,0,0,14,11,0,0,0
0,0,0,0,0,43,0,11,37,0,0,0,0,0,37,0,0,0,0,0,0,0,0,0,37,0,0,0,0,0,37,11,0,43,0
0,0,0,0,0,40,59,59,59,0,0,0,0,0,59,59,59,0,0,0,0,0,59,59,59,0,0,0,0,0,59,59,59,40,0
0,0,0,0,0,0,0,0,59,0,0,0,0,0,59,0,59,11,11,14,11,11,59,0,59,0,0,0,0,0,59,0,0,0,0
0,0,0,0,0,0,0,0,59,0,0,0,0,0,59,0,19,42,10,0,10,46,21,0,59,0,0,0,0,0,59,0,0,0,0
0,0,0,0,0,0,0,0,59,0,0,0,0,0,59,0,0,0,0,0,0,0,0,0,59,0,0,0,0,0,59,0,0,0,0
0,0,0,0,0,0,0,0,59,0,62,35,62,0,59,0,0,0,0,0,0,0,0,0,59,0,62,35,62,0,59,0,0,0,0
0,0,0,0,0,0,0,0,59,11,11,0,11,11,59,0,0,0,0,0,0,0,0,0,59,11,11,0,11,11,59,0,0,0,0
0,0,0,0,0,0,0,0,59,11,32,14,31,11,59,0,0,0,0,0,0,0,0,0,59,11,32,14,31,11,59,0,0,0,0
0,0,0,0,0,0,0,0,19,42,0,0,0,46,21,0,0,0,0,0,0,0,0,0,19,42,0,0,0,46,21,0,0,0,0
0,0,0,0,0,0,0,0,0,0,0,0,0,0,0,0,0,0,0,0,0,0,0,0,0,0,0,0,0,0,0,0,0,0,0
0,0,0,0,0,0,0,0,0,0,0,0,0,0,0,0,0,0,0,0,0,0,0,0,0,0,0,0,0,0,0,0,0,0,0
endlayer

layer
0,0,0,0,0,0,0,0,0,0,0,0,0,0,0,0,0,0,0,0,0,0,0,0,0,0,0,0,0,0,0,0,0,0,0
0,0,0,0,0,0,0,0,0,0,0,0,0,0,0,0,0,0,0,0,0,0,0,0,0,0,0,0,0,0,0,0,0,0,0
0,0,0,0,0,0,0,0,0,0,0,0,0,0,0,0,0,0,0,0,0,0,0,0,0,0,0,0,0,0,0,0,0,0,0
0,0,0,0,0,0,0,0,0,0,0,0,0,0,0,0,0,0,0,0,0,0,0,0,0,0,0,0,0,0,0,0,0,0,0
0,0,0,0,0,0,0,0,0,19,42,62,46,21,0,0,0,0,0,0,0,0,0,0,0,19,42,62,46,21,0,0,0,0,0
0,0,0,0,0,0,0,0,0,59,11,11,11,59,0,0,0,0,0,0,0,0,0,0,0,59,11,11,11,59,0,0,0,0,0
0,0,0,0,0,0,0,0,0,59,11,33,11,59,0,0,0,0,0,0,0,0,0,0,0,59,11,33,11,59,0,0,0,0,0
0,0,0,0,0,0,0,0,0,59,0,0,0,59,0,0,0,0,0,0,0,0,0,0,0,59,0,0,0,59,0,0,0,0,0
0,0,0,0,0,0,0,0,0,59,0,0,0,59,20,20,20,20,20,20,20,20,20,20,20,59,0,0,0,59,0,0,0,0,0
0,0,0,0,0,0,0,0,0,59,0,0,0,59,59,59,59,19,42,0,46,21,59,59,59,59,0,0,0,59,0,0,0,0,0
0,0,0,0,0,0,0,0,0,59,11,11,11,59,59,59,59,59,11,14,11,59,59,59,59,59,11,11,11,59,0,0,0,0,0
0,0,0,0,0,0,0,0,0,59,10,45,10,59,0,0,0,59,0,0,0,59,0,0,0,59,10,45,10,59,0,0,0,0,0
0,0,0,0,0,34,59,59,59,59,0,0,0,59,59,59,59,59,0,0,0,59,59,59,59,59,0,0,0,59,59,59,59,34,0
0,0,0,0,0,45,37,11,33,0,0,0,0,0,33,0,0,0,0,0,0,0,0,0,33,0,0,0,0,0,33,11,37,45,0
0,0,0,0,0,0,11,0,35,0,0,0,0,0,35,0,0,0,0,35,0,0,0,0,35,0,0,0,0,0,35,0,11,0,0
0,0,0,0,0,0,0,11,10,0,0,0,0,0,10,0,0,0,0,10,0,0,0,0,10,0,0,0,0,0,10,11,0,0,0
0,0,0,0,0,0,0,11,14,0,0,0,0,0,0,0,0,0,0,0,0,0,0,0,0,0,0,0,0,0,14,11,0,0,0
0,0,0,0,0,0,0,11,0,0,0,0,0,0,0,0,0,0,0,0,0,0,0,0,0,0,0,0,0,0,0,11,0,0,0
0,0,0,0,0,0,11,14,14,0,0,0,0,0,0,0,0,0,0,0,0,0,0,0,0,0,0,0,0,0,14,14,11,0,0
0,0,0,0,0,0,0,11,0,0,0,0,0,0,0,0,0,0,0,0,0,0,0,0,0,0,0,0,0,0,0,11,0,0,0
0,0,0,0,0,0,0,11,14,0,0,0,0,0,0,0,0,0,0,0,0,0,0,0,0,0,0,0,0,0,14,11,0,0,0
0,0,0,0,0,0,0,11,10,0,0,0,0,0,10,0,0,0,0,10,0,0,0,0,10,0,0,0,0,0,10,11,0,0,0
0,0,0,0,0,0,11,0,35,0,0,0,0,0,35,0,0,0,0,35,0,0,0,0,35,0,0,0,0,0,35,0,11,0,0
0,0,0,0,0,43,33,11,37,0,0,0,0,0,37,0,0,0,0,0,0,0,0,0,37,0,0,0,0,0,37,11,33,43,0
0,0,0,0,0,40,59,59,59,59,0,0,0,59,59,59,59,59,0,0,0,59,59,59,59,59,0,0,0,59,59,59,59,40,0
0,0,0,0,0,0,0,0,0,59,0,0,0,59,0,0,0,59,0,0,0,59,0,0,0,59,0,0,0,59,0,0,0,0,0
0,0,0,0,0,0,0,0,0,59,0,0,0,59,0,0,0,59,11,14,11,59,0,0,0,59,0,0,0,59,0,0,0,0,0
0,0,0,0,0,0,0,0,0,59,0,0,0,59,0,0,0,19,42,0,46,21,0,0,0,59,0,0,0,59,0,0,0,0,0
0,0,0,0,0,0,0,0,0,59,0,0,0,59,0,0,0,0,0,0,0,0,0,0,0,59,0,0,0,59,0,0,0,0,0
0,0,0,0,0,0,0,0,0,59,0,0,0,59,0,0,0,0,0,0,0,0,0,0,0,59,0,0,0,59,0,0,0,0,0
0,0,0,0,0,0,0,0,0,59,11,37,11,59,0,0,0,0,0,0,0,0,0,0,0,59,11,37,11,59,0,0,0,0,0
0,0,0,0,0,0,0,0,0,59,11,11,11,59,0,0,0,0,0,0,0,0,0,0,0,59,11,11,11,59,0,0,0,0,0
0,0,0,0,0,0,0,0,0,19,42,62,46,21,0,0,0,0,0,0,0,0,0,0,0,19,42,62,46,21,0,0,0,0,0
0,0,0,0,0,0,0,0,0,0,0,0,0,0,0,0,0,0,0,0,0,0,0,0,0,0,0,0,0,0,0,0,0,0,0
0,0,0,0,0,0,0,0,0,0,0,0,0,0,0,0,0,0,0,0,0,0,0,0,0,0,0,0,0,0,0,0,0,0,0
endlayer

layer
0,0,0,0,0,0,0,0,0,0,0,0,0,0,0,0,0,0,0,0,0,0,0,0,0,0,0,0,0,0,0,0,0,0,0
0,0,0,0,0,0,0,0,0,0,0,0,0,0,0,0,0,0,0,0,0,0,0,0,0,0,0,0,0,0,0,0,0,0,0
0,0,0,0,0,0,0,0,0,0,0,0,0,0,0,0,0,0,0,0,0,0,0,0,0,0,0,0,0,0,0,0,0,0,0
0,0,0,0,0,0,0,0,0,0,0,0,0,0,0,0,0,0,0,0,0,0,0,0,0,0,0,0,0,0,0,0,0,0,0
0,0,0,0,0,0,0,0,0,0,19,43,21,0,0,0,0,0,0,0,0,0,0,0,0,0,19,43,21,0,0,0,0,0,0
0,0,0,0,0,0,0,0,0,0,59,11,59,0,0,0,0,0,0,0,0,0,0,0,0,0,59,11,59,0,0,0,0,0,0
0,0,0,0,0,0,0,0,0,0,59,63,59,0,0,0,0,0,0,0,0,0,0,0,0,0,59,63,59,0,0,0,0,0,0
0,0,0,0,0,0,0,0,0,0,59,52,59,0,0,0,0,0,0,0,0,0,0,0,0,0,59,52,59,0,0,0,0,0,0
0,0,0,0,0,0,0,0,0,0,59,52,59,0,0,0,0,0,0,0,0,0,0,0,0,0,59,52,59,0,0,0,0,0,0
0,0,0,0,0,0,0,0,0,0,59,52,59,0,0,0,0,0,19,43,21,0,0,0,0,0,59,52,59,0,0,0,0,0,0
0,0,0,0,0,0,0,0,0,0,59,52,59,20,20,20,20,20,59,11,59,20,20,20,20,20,59,52,59,0,0,0,0,0,0
0,0,0,0,0,0,0,0,0,0,59,52,59,59,59,59,59,59,59,0,59,59,59,59,59,59,59,52,59,0,0,0,0,0,0
0,0,0,0,0,0,0,0,0,0,59,52,59,59,59,59,59,59,59,0,59,59,59,59,59,59,59,52,59,0,0,0,0,0,0
0,0,0,0,0,34,59,59,59,59,59,52,59,59,59,59,59,59,59,0,59,59,59,59,59,59,59,52,59,59,59,59,59,34,0
0,0,0,0,0,46,11,52,52,52,52,52,52,52,52,52,52,52,52,52,52,52,52,52,52,52,52,52,52,52,52,52,11,42,0
0,0,0,0,0,0,33,11,62,0,0,0,0,0,62,0,0,0,0,11,0,0,0,0,62,0,0,0,0,0,62,11,33,0,0
0,0,0,0,0,0,0,11,62,0,0,0,0,0,62,0,0,0,0,0,0,0,0,0,62,0,0,0,0,0,62,11,0,0,0
0,0,0,0,0,0,0,11,35,0,0,0,0,0,35,0,0,0,0,0,0,0,0,0,35,0,0,0,0,0,35,11,0,0,0
0,0,0,0,0,0,11,0,35,0,0,0,0,0,35,0,0,0,0,0,0,0,0,0,35,0,0,0,0,0,35,0,11,0,0
0,0,0,0,0,0,0,11,35,0,0,0,0,0,35,0,0,0,0,0,0,0,0,0,35,0,0,0,0,0,35,11,0,0,0
0,0,0,0,0,0,0,11,62,0,0,0,0,0,62,0,0,0,0,0,0,0,0,0,62,0,0,0,0,0,62,11,0,0,0
0,0,0,0,0,0,37,11,62,0,0,0,0,0,62,0,0,0,0,11,0,0,0,0,62,0,0,0,0,0,62,11,37,0,0
0,0,0,0,0,46,11,52,52,52,52,52,52,52,52,52,52,52,52,52,52,52,52,52,52,52,52,52,52,52,52,52,11,42,0
0,0,0,0,0,40,59,59,59,59,59,52,59,59,59,59,59,59,59,0,59,59,59,59,59,59,59,52,59,59,59,59,59,40,0
0,0,0,0,0,0,0,0,0,0,59,52,59,0,0,0,0,0,59,0,59,0,0,0,0,0,59,52,59,0,0,0,0,0,0
0,0,0,0,0,0,0,0,0,0,59,52,59,0,0,0,0,0,59,0,59,0,0,0,0,0,59,52,59,0,0,0,0,0,0
0,0,0,0,0,0,0,0,0,0,59,52,59,0,0,0,0,0,59,11,59,0,0,0,0,0,59,52,59,0,0,0,0,0,0
0,0,0,0,0,0,0,0,0,0,59,52,59,0,0,0,0,0,19,45,21,0,0,0,0,0,59,52,59,0,0,0,0,0,0
0,0,0,0,0,0,0,0,0,0,59,52,59,0,0,0,0,0,0,0,0,0,0,0,0,0,59,52,59,0,0,0,0,0,0
0,0,0,0,0,0,0,0,0,0,59,52,59,0,0,0,0,0,0,0,0,0,0,0,0,0,59,52,59,0,0,0,0,0,0
0,0,0,0,0,0,0,0,0,0,59,63,59,0,0,0,0,0,0,0,0,0,0,0,0,0,59,63,59,0,0,0,0,0,0
0,0,0,0,0,0,0,0,0,0,59,11,59,0,0,0,0,0,0,0,0,0,0,0,0,0,59,11,59,0,0,0,0,0,0
0,0,0,0,0,0,0,0,0,0,19,45,21,0,0,0,0,0,0,0,0,0,0,0,0,0,19,45,21,0,0,0,0,0,0
0,0,0,0,0,0,0,0,0,0,0,0,0,0,0,0,0,0,0,0,0,0,0,0,0,0,0,0,0,0,0,0,0,0,0
0,0,0,0,0,0,0,0,0,0,0,0,0,0,0,0,0,0,0,0,0,0,0,0,0,0,0,0,0,0,0,0,0,0,0
endlayer

layer
0,0,0,0,0,0,0,0,0,0,0,0,0,0,0,0,0,0,0,0,0,0,0,0,0,0,0,0,0,0,0,0,0,0,0
0,0,0,0,0,0,0,0,0,0,0,0,0,0,0,0,0,0,0,0,0,0,0,0,0,0,0,0,0,0,0,0,0,0,0
0,0,0,0,0,0,0,0,0,0,0,0,0,0,0,0,0,0,0,0,0,0,0,0,0,0,0,0,0,0,0,0,0,0,0
0,0,0,0,0,0,0,0,0,0,46,37,42,0,0,0,0,0,0,0,0,0,0,0,0,0,46,37,42,0,0,0,0,0,0
0,0,0,0,0,0,0,0,0,0,0,34,0,0,0,0,0,0,0,0,0,0,0,0,0,0,0,34,0,0,0,0,0,0,0
0,0,0,0,0,0,0,0,0,0,0,59,0,0,0,0,0,0,0,0,0,0,0,0,0,0,0,59,0,0,0,0,0,0,0
0,0,0,0,0,0,0,0,0,0,0,59,0,0,0,0,0,0,0,0,0,0,0,0,0,0,0,59,0,0,0,0,0,0,0
0,0,0,0,0,0,0,0,0,0,0,59,0,0,0,0,0,0,0,0,0,0,0,0,0,0,0,59,0,0,0,0,0,0,0
0,0,0,0,0,0,0,0,0,0,0,59,0,0,0,0,0,0,0,0,0,0,0,0,0,0,0,59,0,0,0,0,0,0,0
0,0,0,0,0,0,0,0,0,0,0,59,0,0,0,0,0,0,0,34,0,0,0,0,0,0,0,59,0,0,0,0,0,0,0
0,0,0,0,0,0,0,0,0,0,0,59,0,0,0,0,0,0,0,59,0,0,0,0,0,0,0,59,0,0,0,0,0,0,0
0,0,0,0,0,0,0,0,0,0,0,59,0,0,0,0,0,0,0,59,0,0,0,0,0,0,0,59,0,0,0,0,0,0,0
0,0,0,0,0,0,0,0,0,0,0,59,0,0,0,0,0,0,0,59,0,0,0,0,0,0,0,59,0,0,0,0,0,0,0
0,0,0,0,0,0,0,0,0,0,0,59,20,20,20,20,20,20,20,59,20,20,20,20,20,20,20,59,0,0,0,0,0,0,0
0,0,0,0,0,20,59,59,59,59,59,59,59,59,59,59,59,59,59,59,59,59,59,59,59,59,59,59,59,59,59,59,59,20,0
0,0,0,0,0,63,59,59,59,59,59,59,59,59,59,59,59,59,59,59,59,59,59,59,59,59,59,59,59,59,59,59,59,63,0
0,0,0,0,0,52,62,11,52,52,52,52,52,52,52,52,52,52,52,52,52,52,52,52,52,52,52,52,52,52,52,11,62,52,0
0,0,0,0,0,0,35,11,0,0,0,0,0,0,0,0,0,0,0,0,0,0,0,0,0,0,0,0,0,0,0,11,35,0,0
0,0,0,0,0,0,11,0,10,0,0,0,0,0,10,0,0,0,0,0,0,0,0,0,10,0,0,0,0,0,10,0,11,0,0
0,0,0,0,0,0,35,11,0,0,0,0,0,0,0,0,0,0,0,0,0,0,0,0,0,0,0,0,0,0,0,11,35,0,0
0,0,0,0,0,52,62,11,52,52,52,52,52,52,52,52,52,52,52,52,52,52,52,52,52,52,52,52,52,52,52,11,62,52,0
0,0,0,0,0,63,59,59,59,59,59,59,59,59,59,59,59,59,59,59,59,59,59,59,59,59,59,59,59,59,59,59,59,63,0
0,0,0,0,0,20,59,59,59,59,59,59,59,59,59,59,59,59,59,59,59,59,59,59,59,59,59,59,59,59,59,59,59,20,0
0,0,0,0,0,0,0,0,0,0,0,59,0,0,0,0,0,0,0,59,0,0,0,0,0,0,0,59,0,0,0,0,0,0,0
0,0,0,0,0,0,0,0,0,0,0,59,0,0,0,0,0,0,0,59,0,0,0,0,0,0,0,59,0,0,0,0,0,0,0
0,0,0,0,0,0,0,0,0,0,0,59,0,0,0,0,0,0,0,59,0,0,0,0,0,0,0,59,0,0,0,0,0,0,0
0,0,0,0,0,0,0,0,0,0,0,59,0,0,0,0,0,0,0,59,0,0,0,0,0,0,0,59,0,0,0,0,0,0,0
0,0,0,0,0,0,0,0,0,0,0,59,0,0,0,0,0,0,0,40,0,0,0,0,0,0,0,59,0,0,0,0,0,0,0
0,0,0,0,0,0,0,0,0,0,0,59,0,0,0,0,0,0,46,33,42,0,0,0,0,0,0,59,0,0,0,0,0,0,0
0,0,0,0,0,0,0,0,0,0,0,59,0,0,0,0,0,0,0,0,0,0,0,0,0,0,0,59,0,0,0,0,0,0,0
0,0,0,0,0,0,0,0,0,0,0,59,0,0,0,0,0,0,0,0,0,0,0,0,0,0,0,59,0,0,0,0,0,0,0
0,0,0,0,0,0,0,0,0,0,0,59,0,0,0,0,0,0,0,0,0,0,0,0,0,0,0,59,0,0,0,0,0,0,0
0,0,0,0,0,0,0,0,0,0,0,40,0,0,0,0,0,0,0,0,0,0,0,0,0,0,0,40,0,0,0,0,0,0,0
0,0,0,0,0,0,0,0,0,0,46,33,42,0,0,0,0,0,0,0,0,0,0,0,0,0,46,33,42,0,0,0,0,0,0
0,0,0,0,0,0,0,0,0,0,0,0,0,0,0,0,0,0,0,0,0,0,0,0,0,0,0,0,0,0,0,0,0,0,0
endlayer

layer
0,0,0,0,0,0,0,0,0,0,0,0,0,0,0,0,0,0,0,0,0,0,0,0,0,0,0,0,0,0,0,0,0,0,0
0,0,0,0,0,0,0,0,0,0,0,0,0,0,0,0,0,0,0,0,0,0,0,0,0,0,0,0,0,0,0,0,0,0,0
0,0,0,0,0,0,0,0,0,0,0,0,0,0,0,0,0,0,0,0,0,0,0,0,0,0,0,0,0,0,0,0,0,0,0
0,0,0,0,0,0,0,0,0,0,19,0,21,0,0,0,0,0,0,0,0,0,0,0,0,0,19,0,21,0,0,0,0,0,0
0,0,0,0,0,0,0,0,0,0,0,0,0,0,0,0,0,0,0,0,0,0,0,0,0,0,0,0,0,0,0,0,0,0,0
0,0,0,0,0,0,0,0,0,0,0,0,0,0,0,0,0,0,0,0,0,0,0,0,0,0,0,0,0,0,0,0,0,0,0
0,0,0,0,0,0,0,0,0,0,0,0,0,0,0,0,0,0,0,0,0,0,0,0,0,0,0,0,0,0,0,0,0,0,0
0,0,0,0,0,0,0,0,0,0,0,0,0,0,0,0,0,0,0,0,0,0,0,0,0,0,0,0,0,0,0,0,0,0,0
0,0,0,0,0,0,0,0,0,0,0,0,0,0,0,0,0,0,0,0,0,0,0,0,0,0,0,0,0,0,0,0,0,0,0
0,0,0,0,0,0,0,0,0,0,0,0,0,0,0,0,0,0,0,0,0,0,0,0,0,0,0,0,0,0,0,0,0,0,0
0,0,0,0,0,0,0,0,0,0,0,0,0,0,0,0,0,0,0,0,0,0,0,0,0,0,0,0,0,0,0,0,0,0,0
0,0,0,0,0,0,0,0,0,0,0,0,0,0,0,0,0,0,0,0,0,0,0,0,0,0,0,0,0,0,0,0,0,0,0
0,0,0,0,0,0,0,0,0,0,0,0,0,0,0,0,0,0,0,0,0,0,0,0,0,0,0,0,0,0,0,0,0,0,0
0,0,0,0,0,0,0,0,0,0,0,0,0,0,0,0,0,0,0,0,0,0,0,0,0,0,0,0,0,0,0,0,0,0,0
0,0,0,0,0,0,0,0,0,0,0,0,0,0,0,0,11,34,34,34,34,34,11,0,0,0,0,0,0,0,0,0,0,0,0
0,0,0,0,0,0,20,20,20,20,20,20,20,20,20,11,0,63,20,20,20,63,0,11,20,20,20,20,20,20,20,20,20,0,0
0,0,0,0,0,20,59,59,59,59,59,59,59,59,59,59,59,52,0,0,0,52,59,59,59,59,59,59,59,59,59,59,59,20,0
0,0,0,0,0,63,59,59,59,59,59,59,59,59,59,59,59,52,0,0,0,52,59,59,59,59,59,59,59,59,59,59,59,63,0
0,0,0,0,0,52,11,0,14,0,0,0,0,0,14,0,0,52,1,1,0,52,0,0,14,0,0,0,0,0,14,0,11,52,0
0,0,0,0,0,63,59,59,59,59,59,59,59,59,59,59,59,52,0,0,0,52,59,59,59,59,59,59,59,59,59,59,59,63,0
0,0,0,0,0,20,59,59,59,59,59,59,59,59,59,59,59,52,0,0,0,52,59,59,59,59,59,59,59,59,59,59,59,20,0
0,0,0,0,0,0,20,20,20,20,20,20,20,20,20,11,0,63,20,20,20,63,0,11,20,20,20,20,20,20,20,20,20,0,0
0,0,0,0,0,0,0,0,0,0,0,0,0,0,0,0,11,40,40,40,40,40,11,0,0,0,0,0,0,0,0,0,0,0,0
0,0,0,0,0,0,0,0,0,0,0,0,0,0,0,0,0,0,0,0,0,0,0,0,0,0,0,0,0,0,0,0,0,0,0
0,0,0,0,0,0,0,0,0,0,0,0,0,0,0,0,0,0,0,0,0,0,0,0,0,0,0,0,0,0,0,0,0,0,0
0,0,0,0,0,0,0,0,0,0,0,0,0,0,0,0,0,0,0,0,0,0,0,0,0,0,0,0,0,0,0,0,0,0,0
0,0,0,0,0,0,0,0,0,0,0,0,0,0,0,0,0,0,0,0,0,0,0,0,0,0,0,0,0,0,0,0,0,0,0
0,0,0,0,0,0,0,0,0,0,0,0,0,0,0,0,0,0,0,0,0,0,0,0,0,0,0,0,0,0,0,0,0,0,0
0,0,0,0,0,0,0,0,0,0,0,0,0,0,0,0,0,0,19,0,21,0,0,0,0,0,0,0,0,0,0,0,0,0,0
0,0,0,0,0,0,0,0,0,0,0,0,0,0,0,0,0,0,0,0,0,0,0,0,0,0,0,0,0,0,0,0,0,0,0
0,0,0,0,0,0,0,0,0,0,0,0,0,0,0,0,0,0,0,0,0,0,0,0,0,0,0,0,0,0,0,0,0,0,0
0,0,0,0,0,0,0,0,0,0,0,0,0,0,0,0,0,0,0,0,0,0,0,0,0,0,0,0,0,0,0,0,0,0,0
0,0,0,0,0,0,0,0,0,0,0,0,0,0,0,0,0,0,0,0,0,0,0,0,0,0,0,0,0,0,0,0,0,0,0
0,0,0,0,0,0,0,0,0,0,19,0,21,0,0,0,0,0,0,0,0,0,0,0,0,0,19,0,21,0,0,0,0,0,0
0,0,0,0,0,0,0,0,0,0,0,0,0,0,0,0,0,0,0,0,0,0,0,0,0,0,0,0,0,0,0,0,0,0,0
endlayer

layer
0,0,0,0,0,0,0,0,0,0,0,0,0,0,0,0,0,0,0,0,0,0,0,0,0,0,0,0,0,0,0,0,0,0,0
0,0,0,0,0,0,0,0,0,0,0,0,0,0,0,0,0,0,0,0,0,0,0,0,0,0,0,0,0,0,0,0,0,0,0
0,0,0,0,0,0,0,0,0,0,0,0,0,0,0,0,0,0,0,0,0,0,0,0,0,0,0,0,0,0,0,0,0,0,0
0,0,0,0,0,0,0,0,0,0,0,0,0,0,0,0,0,0,0,0,0,0,0,0,0,0,0,0,0,0,0,0,0,0,0
0,0,0,0,0,0,0,0,0,0,0,0,0,0,0,0,0,0,0,0,0,0,0,0,0,0,0,0,0,0,0,0,0,0,0
0,0,0,0,0,0,0,0,0,0,0,0,0,0,0,0,0,0,0,0,0,0,0,0,0,0,0,0,0,0,0,0,0,0,0
0,0,0,0,0,0,0,0,0,0,0,0,0,0,0,0,0,0,0,0,0,0,0,0,0,0,0,0,0,0,0,0,0,0,0
0,0,0,0,0,0,0,0,0,0,0,0,0,0,0,0,0,0,0,0,0,0,0,0,0,0,0,0,0,0,0,0,0,0,0
0,0,0,0,0,0,0,0,0,0,0,0,0,0,0,0,0,0,0,0,0,0,0,0,0,0,0,0,0,0,0,0,0,0,0
0,0,0,0,0,0,0,0,0,0,0,0,0,0,0,0,0,0,0,0,0,0,0,0,0,0,0,0,0,0,0,0,0,0,0
0,0,0,0,0,0,0,0,0,0,0,0,0,0,0,0,0,0,0,0,0,0,0,0,0,0,0,0,0,0,0,0,0,0,0
0,0,0,0,0,0,0,0,0,0,0,0,0,0,0,0,0,0,0,0,0,0,0,0,0,0,0,0,0,0,0,0,0,0,0
0,0,0,0,0,0,0,0,0,0,0,0,0,0,0,0,0,0,0,0,0,0,0,0,0,0,0,0,0,0,0,0,0,0,0
0,0,0,0,0,0,0,0,0,0,0,0,0,0,0,0,0,0,0,0,0,0,0,0,0,0,0,0,0,0,0,0,0,0,0
0,0,0,0,0,0,0,0,0,0,0,0,0,0,0,0,19,42,0,0,0,46,21,0,0,0,0,0,0,0,0,0,0,0,0
0,0,0,0,0,0,0,0,0,0,0,0,0,0,0,34,59,0,14,14,14,0,59,34,0,0,0,0,0,0,0,0,0,0,0
0,0,0,0,0,0,0,0,0,0,0,0,0,0,0,45,0,14,0,0,0,14,0,45,0,0,0,0,0,0,0,0,0,0,0
0,0,0,0,43,0,20,20,20,20,20,20,20,20,20,20,20,14,0,0,0,14,20,20,20,20,20,20,20,20,20,20,20,0,43
0,0,0,0,31,19,59,59,59,59,59,59,59,59,59,59,59,14,0,0,0,14,59,59,59,59,59,59,59,59,59,59,59,21,32
0,0,0,0,45,0,20,20,20,20,20,20,20,20,20,20,20,14,0,0,0,14,20,20,20,20,20,20,20,20,20,20,20,0,45
0,0,0,0,0,0,0,0,0,0,0,0,0,0,0,43,0,14,0,0,0,14,0,43,0,0,0,0,0,0,0,0,0,0,0
0,0,0,0,0,0,0,0,0,0,0,0,0,0,0,40,59,0,14,14,14,0,59,40,0,0,0,0,0,0,0,0,0,0,0
0,0,0,0,0,0,0,0,0,0,0,0,0,0,0,0,19,42,0,0,0,46,21,0,0,0,0,0,0,0,0,0,0,0,0
0,0,0,0,0,0,0,0,0,0,0,0,0,0,0,0,0,0,0,0,0,0,0,0,0,0,0,0,0,0,0,0,0,0,0
0,0,0,0,0,0,0,0,0,0,0,0,0,0,0,0,0,0,0,0,0,0,0,0,0,0,0,0,0,0,0,0,0,0,0
0,0,0,0,0,0,0,0,0,0,0,0,0,0,0,0,0,0,0,0,0,0,0,0,0,0,0,0,0,0,0,0,0,0,0
0,0,0,0,0,0,0,0,0,0,0,0,0,0,0,0,0,0,0,0,0,0,0,0,0,0,0,0,0,0,0,0,0,0,0
0,0,0,0,0,0,0,0,0,0,0,0,0,0,0,0,0,0,0,0,0,0,0,0,0,0,0,0,0,0,0,0,0,0,0
0,0,0,0,0,0,0,0,0,0,0,0,0,0,0,0,0,0,0,0,0,0,0,0,0,0,0,0,0,0,0,0,0,0,0
0,0,0,0,0,0,0,0,0,0,0,0,0,0,0,0,0,0,0,0,0,0,0,0,0,0,0,0,0,0,0,0,0,0,0
0,0,0,0,0,0,0,0,0,0,0,0,0,0,0,0,0,0,0,0,0,0,0,0,0,0,0,0,0,0,0,0,0,0,0
0,0,0,0,0,0,0,0,0,0,0,0,0,0,0,0,0,0,0,0,0,0,0,0,0,0,0,0,0,0,0,0,0,0,0
0,0,0,0,0,0,0,0,0,0,0,0,0,0,0,0,0,0,0,0,0,0,0,0,0,0,0,0,0,0,0,0,0,0,0
0,0,0,0,0,0,0,0,0,0,0,0,0,0,0,0,0,0,0,0,0,0,0,0,0,0,0,0,0,0,0,0,0,0,0
0,0,0,0,0,0,0,0,0,0,0,0,0,0,0,0,0,0,0,0,0,0,0,0,0,0,0,0,0,0,0,0,0,0,0
endlayer

layer
0,0,0,0,0,0,0,0,0,0,0,0,0,0,0,0,0,0,0,0,0,0,0,0,0,0,0,0,0,0,0,0,0,0,0
0,0,0,0,0,0,0,0,0,0,0,0,0,0,0,0,0,0,0,0,0,0,0,0,0,0,0,0,0,0,0,0,0,0,0
0,0,0,0,0,0,0,0,0,0,0,0,0,0,0,0,0,0,0,0,0,0,0,0,0,0,0,0,0,0,0,0,0,0,0
0,0,0,0,0,0,0,0,0,0,0,0,0,0,0,0,0,0,0,0,0,0,0,0,0,0,0,0,0,0,0,0,0,0,0
0,0,0,0,0,0,0,0,0,0,0,0,0,0,0,0,0,0,0,0,0,0,0,0,0,0,0,0,0,0,0,0,0,0,0
0,0,0,0,0,0,0,0,0,0,0,0,0,0,0,0,0,0,0,0,0,0,0,0,0,0,0,0,0,0,0,0,0,0,0
0,0,0,0,0,0,0,0,0,0,0,0,0,0,0,0,0,0,0,0,0,0,0,0,0,0,0,0,0,0,0,0,0,0,0
0,0,0,0,0,0,0,0,0,0,0,0,0,0,0,0,0,0,0,0,0,0,0,0,0,0,0,0,0,0,0,0,0,0,0
0,0,0,0,0,0,0,0,0,0,0,0,0,0,0,0,0,0,0,0,0,0,0,0,0,0,0,0,0,0,0,0,0,0,0
0,0,0,0,0,0,0,0,0,0,0,0,0,0,0,0,0,0,0,0,0,0,0,0,0,0,0,0,0,0,0,0,0,0,0
0,0,0,0,0,0,0,0,0,0,0,0,0,0,0,0,0,0,0,0,0,0,0,0,0,0,0,0,0,0,0,0,0,0,0
0,0,0,0,0,0,0,0,0,0,0,0,0,0,0,0,0,0,0,0,0,0,0,0,0,0,0,0,0,0,0,0,0,0,0
0,0,0,0,0,0,0,0,0,0,0,0,0,0,0,0,0,0,0,0,0,0,0,0,0,0,0,0,0,0,0,0,0,0,0
0,0,0,0,0,0,0,0,0,0,0,0,0,0,0,0,0,0,0,0,0,0,0,0,0,0,0,0,0,0,0,0,0,0,0
0,0,0,0,0,0,0,0,0,0,0,0,0,0,0,0,0,19,42,0,46,21,0,0,0,0,0,0,0,0,0,0,0,0,0
0,0,0,0,0,0,0,0,0,0,0,0,0,0,0,0,0,59,0,14,0,59,0,0,0,0,0,0,0,0,0,0,0,0,0
0,0,0,0,0,0,0,0,0,0,0,0,0,0,0,34,59,59,0,0,0,59,59,34,0,0,0,0,0,0,0,0,0,0,0
0,0,0,0,34,0,0,0,0,0,0,0,0,0,0,45,45,14,45,0,45,14,45,45,0,0,0,0,0,0,0,0,0,0,34
0,0,0,0,0,0,0,0,0,0,0,0,0,0,0,0,0,14,0,0,0,14,0,0,0,0,0,0,0,0,0,0,0,0,0
0,0,0,0,40,0,0,0,0,0,0,0,0,0,0,43,43,14,43,0,43,14,43,43,0,0,0,0,0,0,0,0,0,0,40
0,0,0,0,0,0,0,0,0,0,0,0,0,0,0,40,59,59,0,0,0,59,59,40,0,0,0,0,0,0,0,0,0,0,0
0,0,0,0,0,0,0,0,0,0,0,0,0,0,0,0,0,59,0,14,0,59,0,0,0,0,0,0,0,0,0,0,0,0,0
0,0,0,0,0,0,0,0,0,0,0,0,0,0,0,0,0,19,42,0,46,21,0,0,0,0,0,0,0,0,0,0,0,0,0
0,0,0,0,0,0,0,0,0,0,0,0,0,0,0,0,0,0,0,0,0,0,0,0,0,0,0,0,0,0,0,0,0,0,0
0,0,0,0,0,0,0,0,0,0,0,0,0,0,0,0,0,0,0,0,0,0,0,0,0,0,0,0,0,0,0,0,0,0,0
0,0,0,0,0,0,0,0,0,0,0,0,0,0,0,0,0,0,0,0,0,0,0,0,0,0,0,0,0,0,0,0,0,0,0
0,0,0,0,0,0,0,0,0,0,0,0,0,0,0,0,0,0,0,0,0,0,0,0,0,0,0,0,0,0,0,0,0,0,0
0,0,0,0,0,0,0,0,0,0,0,0,0,0,0,0,0,0,0,0,0,0,0,0,0,0,0,0,0,0,0,0,0,0,0
0,0,0,0,0,0,0,0,0,0,0,0,0,0,0,0,0,0,0,0,0,0,0,0,0,0,0,0,0,0,0,0,0,0,0
0,0,0,0,0,0,0,0,0,0,0,0,0,0,0,0,0,0,0,0,0,0,0,0,0,0,0,0,0,0,0,0,0,0,0
0,0,0,0,0,0,0,0,0,0,0,0,0,0,0,0,0,0,0,0,0,0,0,0,0,0,0,0,0,0,0,0,0,0,0
0,0,0,0,0,0,0,0,0,0,0,0,0,0,0,0,0,0,0,0,0,0,0,0,0,0,0,0,0,0,0,0,0,0,0
0,0,0,0,0,0,0,0,0,0,0,0,0,0,0,0,0,0,0,0,0,0,0,0,0,0,0,0,0,0,0,0,0,0,0
0,0,0,0,0,0,0,0,0,0,0,0,0,0,0,0,0,0,0,0,0,0,0,0,0,0,0,0,0,0,0,0,0,0,0
0,0,0,0,0,0,0,0,0,0,0,0,0,0,0,0,0,0,0,0,0,0,0,0,0,0,0,0,0,0,0,0,0,0,0
endlayer

layer
0,0,0,0,0,0,0,0,0,0,0,0,0,0,0,0,0,0,0,0,0,0,0,0,0,0,0,0,0,0,0,0,0,0,0
0,0,0,0,0,0,0,0,0,0,0,0,0,0,0,0,0,0,0,0,0,0,0,0,0,0,0,0,0,0,0,0,0,0,0
0,0,0,0,0,0,0,0,0,0,0,0,0,0,0,0,0,0,0,0,0,0,0,0,0,0,0,0,0,0,0,0,0,0,0
0,0,0,0,0,0,0,0,0,0,0,0,0,0,0,0,0,0,0,0,0,0,0,0,0,0,0,0,0,0,0,0,0,0,0
0,0,0,0,0,0,0,0,0,0,0,0,0,0,0,0,0,0,0,0,0,0,0,0,0,0,0,0,0,0,0,0,0,0,0
0,0,0,0,0,0,0,0,0,0,0,0,0,0,0,0,0,0,0,0,0,0,0,0,0,0,0,0,0,0,0,0,0,0,0
0,0,0,0,0,0,0,0,0,0,0,0,0,0,0,0,0,0,0,0,0,0,0,0,0,0,0,0,0,0,0,0,0,0,0
0,0,0,0,0,0,0,0,0,0,0,0,0,0,0,0,0,0,0,0,0,0,0,0,0,0,0,0,0,0,0,0,0,0,0
0,0,0,0,0,0,0,0,0,0,0,0,0,0,0,0,0,0,0,0,0,0,0,0,0,0,0,0,0,0,0,0,0,0,0
0,0,0,0,0,0,0,0,0,0,0,0,0,0,0,0,0,0,0,0,0,0,0,0,0,0,0,0,0,0,0,0,0,0,0
0,0,0,0,0,0,0,0,0,0,0,0,0,0,0,0,0,0,0,0,0,0,0,0,0,0,0,0,0,0,0,0,0,0,0
0,0,0,0,0,0,0,0,0,0,0,0,0,0,0,0,0,0,0,0,0,0,0,0,0,0,0,0,0,0,0,0,0,0,0
0,0,0,0,0,0,0,0,0,0,0,0,0,0,0,0,0,0,0,0,0,0,0,0,0,0,0,0,0,0,0,0,0,0,0
0,0,0,0,0,0,0,0,0,0,0,0,0,0,0,0,0,0,0,0,0,0,0,0,0,0,0,0,0,0,0,0,0,0,0
0,0,0,0,0,0,0,0,0,0,0,0,0,0,0,0,0,0,19,43,21,0,0,0,0,0,0,0,0,0,0,0,0,0,0
0,0,0,0,0,0,0,0,0,0,0,0,0,0,0,0,0,0,59,59,59,0,0,0,0,0,0,0,0,0,0,0,0,0,0
0,0,0,0,0,0,0,0,0,0,0,0,0,0,0,0,0,0,59,59,59,0,0,0,0,0,0,0,0,0,0,0,0,0,0
0,0,0,0,0,0,0,0,0,0,0,0,0,0,0,34,59,59,11,59,11,59,59,34,0,0,0,0,0,0,0,0,0,0,0
0,0,0,0,0,0,0,0,0,0,0,0,0,0,0,46,59,11,0,0,0,11,59,42,0,0,0,0,0,0,0,0,0,0,0
0,0,0,0,0,0,0,0,0,0,0,0,0,0,0,40,59,59,11,59,11,59,59,40,0,0,0,0,0,0,0,0,0,0,0
0,0,0,0,0,0,0,0,0,0,0,0,0,0,0,0,0,0,59,59,59,0,0,0,0,0,0,0,0,0,0,0,0,0,0
0,0,0,0,0,0,0,0,0,0,0,0,0,0,0,0,0,0,59,59,59,0,0,0,0,0,0,0,0,0,0,0,0,0,0
0,0,0,0,0,0,0,0,0,0,0,0,0,0,0,0,0,0,19,45,21,0,0,0,0,0,0,0,0,0,0,0,0,0,0
0,0,0,0,0,0,0,0,0,0,0,0,0,0,0,0,0,0,0,0,0,0,0,0,0,0,0,0,0,0,0,0,0,0,0
0,0,0,0,0,0,0,0,0,0,0,0,0,0,0,0,0,0,0,0,0,0,0,0,0,0,0,0,0,0,0,0,0,0,0
0,0,0,0,0,0,0,0,0,0,0,0,0,0,0,0,0,0,0,0,0,0,0,0,0,0,0,0,0,0,0,0,0,0,0
0,0,0,0,0,0,0,0,0,0,0,0,0,0,0,0,0,0,0,0,0,0,0,0,0,0,0,0,0,0,0,0,0,0,0
0,0,0,0,0,0,0,0,0,0,0,0,0,0,0,0,0,0,0,0,0,0,0,0,0,0,0,0,0,0,0,0,0,0,0
0,0,0,0,0,0,0,0,0,0,0,0,0,0,0,0,0,0,0,0,0,0,0,0,0,0,0,0,0,0,0,0,0,0,0
0,0,0,0,0,0,0,0,0,0,0,0,0,0,0,0,0,0,0,0,0,0,0,0,0,0,0,0,0,0,0,0,0,0,0
0,0,0,0,0,0,0,0,0,0,0,0,0,0,0,0,0,0,0,0,0,0,0,0,0,0,0,0,0,0,0,0,0,0,0
0,0,0,0,0,0,0,0,0,0,0,0,0,0,0,0,0,0,0,0,0,0,0,0,0,0,0,0,0,0,0,0,0,0,0
0,0,0,0,0,0,0,0,0,0,0,0,0,0,0,0,0,0,0,0,0,0,0,0,0,0,0,0,0,0,0,0,0,0,0
0,0,0,0,0,0,0,0,0,0,0,0,0,0,0,0,0,0,0,0,0,0,0,0,0,0,0,0,0,0,0,0,0,0,0
0,0,0,0,0,0,0,0,0,0,0,0,0,0,0,0,0,0,0,0,0,0,0,0,0,0,0,0,0,0,0,0,0,0,0
endlayer

layer
0,0,0,0,0,0,0,0,0,0,0,0,0,0,0,0,0,0,0,0,0,0,0,0,0,0,0,0,0,0,0,0,0,0,0
0,0,0,0,0,0,0,0,0,0,0,0,0,0,0,0,0,0,0,0,0,0,0,0,0,0,0,0,0,0,0,0,0,0,0
0,0,0,0,0,0,0,0,0,0,0,0,0,0,0,0,0,0,0,0,0,0,0,0,0,0,0,0,0,0,0,0,0,0,0
0,0,0,0,0,0,0,0,0,0,0,0,0,0,0,0,0,0,0,0,0,0,0,0,0,0,0,0,0,0,0,0,0,0,0
0,0,0,0,0,0,0,0,0,0,0,0,0,0,0,0,0,0,0,0,0,0,0,0,0,0,0,0,0,0,0,0,0,0,0
0,0,0,0,0,0,0,0,0,0,0,0,0,0,0,0,0,0,0,0,0,0,0,0,0,0,0,0,0,0,0,0,0,0,0
0,0,0,0,0,0,0,0,0,0,0,0,0,0,0,0,0,0,0,0,0,0,0,0,0,0,0,0,0,0,0,0,0,0,0
0,0,0,0,0,0,0,0,0,0,0,0,0,0,0,0,0,0,0,0,0,0,0,0,0,0,0,0,0,0,0,0,0,0,0
0,0,0,0,0,0,0,0,0,0,0,0,0,0,0,0,0,0,0,0,0,0,0,0,0,0,0,0,0,0,0,0,0,0,0
0,0,0,0,0,0,0,0,0,0,0,0,0,0,0,0,0,0,0,0,0,0,0,0,0,0,0,0,0,0,0,0,0,0,0
0,0,0,0,0,0,0,0,0,0,0,0,0,0,0,0,0,0,0,0,0,0,0,0,0,0,0,0,0,0,0,0,0,0,0
0,0,0,0,0,0,0,0,0,0,0,0,0,0,0,0,0,0,0,0,0,0,0,0,0,0,0,0,0,0,0,0,0,0,0
0,0,0,0,0,0,0,0,0,0,0,0,0,0,0,0,0,0,0,0,0,0,0,0,0,0,0,0,0,0,0,0,0,0,0
0,0,0,0,0,0,0,0,0,0,0,0,0,0,0,0,0,0,0,37,0,0,0,0,0,0,0,0,0,0,0,0,0,0,0
0,0,0,0,0,0,0,0,0,0,0,0,0,0,0,0,0,0,0,34,0,0,0,0,0,0,0,0,0,0,0,0,0,0,0
0,0,0,0,0,0,0,0,0,0,0,0,0,0,0,0,0,0,0,0,0,0,0,0,0,0,0,0,0,0,0,0,0,0,0
0,0,0,0,0,0,0,0,0,0,0,0,0,0,0,0,0,0,34,14,34,0,0,0,0,0,0,0,0,0,0,0,0,0,0
0,0,0,0,0,0,0,0,0,0,0,0,0,0,0,0,0,19,10,0,10,21,0,0,0,0,0,0,0,0,0,0,0,0,0
0,0,0,0,0,0,0,0,0,0,0,0,0,0,31,19,0,14,0,0,0,14,0,21,32,0,0,0,0,0,0,0,0,0,0
0,0,0,0,0,0,0,0,0,0,0,0,0,0,0,0,0,19,10,0,10,21,0,0,0,0,0,0,0,0,0,0,0,0,0
0,0,0,0,0,0,0,0,0,0,0,0,0,0,0,0,0,0,40,14,40,0,0,0,0,0,0,0,0,0,0,0,0,0,0
0,0,0,0,0,0,0,0,0,0,0,0,0,0,0,0,0,0,0,0,0,0,0,0,0,0,0,0,0,0,0,0,0,0,0
0,0,0,0,0,0,0,0,0,0,0,0,0,0,0,0,0,0,0,40,0,0,0,0,0,0,0,0,0,0,0,0,0,0,0
0,0,0,0,0,0,0,0,0,0,0,0,0,0,0,0,0,0,0,33,0,0,0,0,0,0,0,0,0,0,0,0,0,0,0
0,0,0,0,0,0,0,0,0,0,0,0,0,0,0,0,0,0,0,0,0,0,0,0,0,0,0,0,0,0,0,0,0,0,0
0,0,0,0,0,0,0,0,0,0,0,0,0,0,0,0,0,0,0,0,0,0,0,0,0,0,0,0,0,0,0,0,0,0,0
0,0,0,0,0,0,0,0,0,0,0,0,0,0,0,0,0,0,0,0,0,0,0,0,0,0,0,0,0,0,0,0,0,0,0
0,0,0,0,0,0,0,0,0,0,0,0,0,0,0,0,0,0,0,0,0,0,0,0,0,0,0,0,0,0,0,0,0,0,0
0,0,0,0,0,0,0,0,0,0,0,0,0,0,0,0,0,0,0,0,0,0,0,0,0,0,0,0,0,0,0,0,0,0,0
0,0,0,0,0,0,0,0,0,0,0,0,0,0,0,0,0,0,0,0,0,0,0,0,0,0,0,0,0,0,0,0,0,0,0
0,0,0,0,0,0,0,0,0,0,0,0,0,0,0,0,0,0,0,0,0,0,0,0,0,0,0,0,0,0,0,0,0,0,0
0,0,0,0,0,0,0,0,0,0,0,0,0,0,0,0,0,0,0,0,0,0,0,0,0,0,0,0,0,0,0,0,0,0,0
0,0,0,0,0,0,0,0,0,0,0,0,0,0,0,0,0,0,0,0,0,0,0,0,0,0,0,0,0,0,0,0,0,0,0
0,0,0,0,0,0,0,0,0,0,0,0,0,0,0,0,0,0,0,0,0,0,0,0,0,0,0,0,0,0,0,0,0,0,0
0,0,0,0,0,0,0,0,0,0,0,0,0,0,0,0,0,0,0,0,0,0,0,0,0,0,0,0,0,0,0,0,0,0,0
endlayer

layer
0,0,0,0,0,0,0,0,0,0,0,0,0,0,0,0,0,0,0,0,0,0,0,0,0,0,0,0,0,0,0,0,0,0,0
0,0,0,0,0,0,0,0,0,0,0,0,0,0,0,0,0,0,0,0,0,0,0,0,0,0,0,0,0,0,0,0,0,0,0
0,0,0,0,0,0,0,0,0,0,0,0,0,0,0,0,0,0,0,0,0,0,0,0,0,0,0,0,0,0,0,0,0,0,0
0,0,0,0,0,0,0,0,0,0,0,0,0,0,0,0,0,0,0,0,0,0,0,0,0,0,0,0,0,0,0,0,0,0,0
0,0,0,0,0,0,0,0,0,0,0,0,0,0,0,0,0,0,0,0,0,0,0,0,0,0,0,0,0,0,0,0,0,0,0
0,0,0,0,0,0,0,0,0,0,0,0,0,0,0,0,0,0,0,0,0,0,0,0,0,0,0,0,0,0,0,0,0,0,0
0,0,0,0,0,0,0,0,0,0,0,0,0,0,0,0,0,0,0,0,0,0,0,0,0,0,0,0,0,0,0,0,0,0,0
0,0,0,0,0,0,0,0,0,0,0,0,0,0,0,0,0,0,0,0,0,0,0,0,0,0,0,0,0,0,0,0,0,0,0
0,0,0,0,0,0,0,0,0,0,0,0,0,0,0,0,0,0,0,0,0,0,0,0,0,0,0,0,0,0,0,0,0,0,0
0,0,0,0,0,0,0,0,0,0,0,0,0,0,0,0,0,0,0,0,0,0,0,0,0,0,0,0,0,0,0,0,0,0,0
0,0,0,0,0,0,0,0,0,0,0,0,0,0,0,0,0,0,0,0,0,0,0,0,0,0,0,0,0,0,0,0,0,0,0
0,0,0,0,0,0,0,0,0,0,0,0,0,0,0,0,0,0,0,0,0,0,0,0,0,0,0,0,0,0,0,0,0,0,0
0,0,0,0,0,0,0,0,0,0,0,0,0,0,0,0,0,0,0,0,0,0,0,0,0,0,0,0,0,0,0,0,0,0,0
0,0,0,0,0,0,0,0,0,0,0,0,0,0,0,0,0,0,0,0,0,0,0,0,0,0,0,0,0,0,0,0,0,0,0
0,0,0,0,0,0,0,0,0,0,0,0,0,0,0,0,0,0,0,0,0,0,0,0,0,0,0,0,0,0,0,0,0,0,0
0,0,0,0,0,0,0,0,0,0,0,0,0,0,0,0,0,0,0,0,0,0,0,0,0,0,0,0,0,0,0,0,0,0,0
0,0,0,0,0,0,0,0,0,0,0,0,0,0,0,0,0,0,52,14,52,0,0,0,0,0,0,0,0,0,0,0,0,0,0
0,0,0,0,0,0,0,0,0,0,0,0,0,0,0,0,0,52,14,0,14,52,0,0,0,0,0,0,0,0,0,0,0,0,0
0,0,0,0,0,0,0,0,0,0,0,0,0,0,0,0,0,14,0,0,0,14,0,0,0,0,0,0,0,0,0,0,0,0,0
0,0,0,0,0,0,0,0,0,0,0,0,0,0,0,0,0,52,14,0,14,52,0,0,0,0,0,0,0,0,0,0,0,0,0
0,0,0,0,0,0,0,0,0,0,0,0,0,0,0,0,0,0,52,14,52,0,0,0,0,0,0,0,0,0,0,0,0,0,0
0,0,0,0,0,0,0,0,0,0,0,0,0,0,0,0,0,0,0,0,0,0,0,0,0,0,0,0,0,0,0,0,0,0,0
0,0,0,0,0,0,0,0,0,0,0,0,0,0,0,0,0,0,0,0,0,0,0,0,0,0,0,0,0,0,0,0,0,0,0
0,0,0,0,0,0,0,0,0,0,0,0,0,0,0,0,0,0,0,0,0,0,0,0,0,0,0,0,0,0,0,0,0,0,0
0,0,0,0,0,0,0,0,0,0,0,0,0,0,0,0,0,0,0,0,0,0,0,0,0,0,0,0,0,0,0,0,0,0,0
0,0,0,0,0,0,0,0,0,0,0,0,0,0,0,0,0,0,0,0,0,0,0,0,0,0,0,0,0,0,0,0,0,0,0
0,0,0,0,0,0,0,0,0,0,0,0,0,0,0,0,0,0,0,0,0,0,0,0,0,0,0,0,0,0,0,0,0,0,0
0,0,0,0,0,0,0,0,0,0,0,0,0,0,0,0,0,0,0,0,0,0,0,0,0,0,0,0,0,0,0,0,0,0,0
0,0,0,0,0,0,0,0,0,0,0,0,0,0,0,0,0,0,0,0,0,0,0,0,0,0,0,0,0,0,0,0,0,0,0
0,0,0,0,0,0,0,0,0,0,0,0,0,0,0,0,0,0,0,0,0,0,0,0,0,0,0,0,0,0,0,0,0,0,0
0,0,0,0,0,0,0,0,0,0,0,0,0,0,0,0,0,0,0,0,0,0,0,0,0,0,0,0,0,0,0,0,0,0,0
0,0,0,0,0,0,0,0,0,0,0,0,0,0,0,0,0,0,0,0,0,0,0,0,0,0,0,0,0,0,0,0,0,0,0
0,0,0,0,0,0,0,0,0,0,0,0,0,0,0,0,0,0,0,0,0,0,0,0,0,0,0,0,0,0,0,0,0,0,0
0,0,0,0,0,0,0,0,0,0,0,0,0,0,0,0,0,0,0,0,0,0,0,0,0,0,0,0,0,0,0,0,0,0,0
0,0,0,0,0,0,0,0,0,0,0,0,0,0,0,0,0,0,0,0,0,0,0,0,0,0,0,0,0,0,0,0,0,0,0
endlayer

layer
0,0,0,0,0,0,0,0,0,0,0,0,0,0,0,0,0,0,0,0,0,0,0,0,0,0,0,0,0,0,0,0,0,0,0
0,0,0,0,0,0,0,0,0,0,0,0,0,0,0,0,0,0,0,0,0,0,0,0,0,0,0,0,0,0,0,0,0,0,0
0,0,0,0,0,0,0,0,0,0,0,0,0,0,0,0,0,0,0,0,0,0,0,0,0,0,0,0,0,0,0,0,0,0,0
0,0,0,0,0,0,0,0,0,0,0,0,0,0,0,0,0,0,0,0,0,0,0,0,0,0,0,0,0,0,0,0,0,0,0
0,0,0,0,0,0,0,0,0,0,0,0,0,0,0,0,0,0,0,0,0,0,0,0,0,0,0,0,0,0,0,0,0,0,0
0,0,0,0,0,0,0,0,0,0,0,0,0,0,0,0,0,0,0,0,0,0,0,0,0,0,0,0,0,0,0,0,0,0,0
0,0,0,0,0,0,0,0,0,0,0,0,0,0,0,0,0,0,0,0,0,0,0,0,0,0,0,0,0,0,0,0,0,0,0
0,0,0,0,0,0,0,0,0,0,0,0,0,0,0,0,0,0,0,0,0,0,0,0,0,0,0,0,0,0,0,0,0,0,0
0,0,0,0,0,0,0,0,0,0,0,0,0,0,0,0,0,0,0,0,0,0,0,0,0,0,0,0,0,0,0,0,0,0,0
0,0,0,0,0,0,0,0,0,0,0,0,0,0,0,0,0,0,0,0,0,0,0,0,0,0,0,0,0,0,0,0,0,0,0
0,0,0,0,0,0,0,0,0,0,0,0,0,0,0,0,0,0,0,0,0,0,0,0,0,0,0,0,0,0,0,0,0,0,0
0,0,0,0,0,0,0,0,0,0,0,0,0,0,0,0,0,0,0,0,0,0,0,0,0,0,0,0,0,0,0,0,0,0,0
0,0,0,0,0,0,0,0,0,0,0,0,0,0,0,0,0,0,0,0,0,0,0,0,0,0,0,0,0,0,0,0,0,0,0
0,0,0,0,0,0,0,0,0,0,0,0,0,0,0,0,0,0,0,0,0,0,0,0,0,0,0,0,0,0,0,0,0,0,0
0,0,0,0,0,0,0,0,0,0,0,0,0,0,0,0,0,0,0,0,0,0,0,0,0,0,0,0,0,0,0,0,0,0,0
0,0,0,0,0,0,0,0,0,0,0,0,0,0,0,0,0,0,0,37,0,0,0,0,0,0,0,0,0,0,0,0,0,0,0
0,0,0,0,0,0,0,0,0,0,0,0,0,0,0,0,0,0,0,34,0,0,0,0,0,0,0,0,0,0,0,0,0,0,0
0,0,0,0,0,0,0,0,0,0,0,0,0,0,0,0,0,0,59,59,59,0,0,0,0,0,0,0,0,0,0,0,0,0,0
0,0,0,0,0,0,0,0,0,0,0,0,0,0,0,0,31,19,59,0,59,21,32,0,0,0,0,0,0,0,0,0,0,0,0
0,0,0,0,0,0,0,0,0,0,0,0,0,0,0,0,0,0,59,59,59,0,0,0,0,0,0,0,0,0,0,0,0,0,0
0,0,0,0,0,0,0,0,0,0,0,0,0,0,0,0,0,0,0,40,0,0,0,0,0,0,0,0,0,0,0,0,0,0,0
0,0,0,0,0,0,0,0,0,0,0,0,0,0,0,0,0,0,0,33,0,0,0,0,0,0,0,0,0,0,0,0,0,0,0
0,0,0,0,0,0,0,0,0,0,0,0,0,0,0,0,0,0,0,0,0,0,0,0,0,0,0,0,0,0,0,0,0,0,0
0,0,0,0,0,0,0,0,0,0,0,0,0,0,0,0,0,0,0,0,0,0,0,0,0,0,0,0,0,0,0,0,0,0,0
0,0,0,0,0,0,0,0,0,0,0,0,0,0,0,0,0,0,0,0,0,0,0,0,0,0,0,0,0,0,0,0,0,0,0
0,0,0,0,0,0,0,0,0,0,0,0,0,0,0,0,0,0,0,0,0,0,0,0,0,0,0,0,0,0,0,0,0,0,0
0,0,0,0,0,0,0,0,0,0,0,0,0,0,0,0,0,0,0,0,0,0,0,0,0,0,0,0,0,0,0,0,0,0,0
0,0,0,0,0,0,0,0,0,0,0,0,0,0,0,0,0,0,0,0,0,0,0,0,0,0,0,0,0,0,0,0,0,0,0
0,0,0,0,0,0,0,0,0,0,0,0,0,0,0,0,0,0,0,0,0,0,0,0,0,0,0,0,0,0,0,0,0,0,0
0,0,0,0,0,0,0,0,0,0,0,0,0,0,0,0,0,0,0,0,0,0,0,0,0,0,0,0,0,0,0,0,0,0,0
0,0,0,0,0,0,0,0,0,0,0,0,0,0,0,0,0,0,0,0,0,0,0,0,0,0,0,0,0,0,0,0,0,0,0
0,0,0,0,0,0,0,0,0,0,0,0,0,0,0,0,0,0,0,0,0,0,0,0,0,0,0,0,0,0,0,0,0,0,0
0,0,0,0,0,0,0,0,0,0,0,0,0,0,0,0,0,0,0,0,0,0,0,0,0,0,0,0,0,0,0,0,0,0,0
0,0,0,0,0,0,0,0,0,0,0,0,0,0,0,0,0,0,0,0,0,0,0,0,0,0,0,0,0,0,0,0,0,0,0
0,0,0,0,0,0,0,0,0,0,0,0,0,0,0,0,0,0,0,0,0,0,0,0,0,0,0,0,0,0,0,0,0,0,0
endlayer

layer
0,0,0,0,0,0,0,0,0,0,0,0,0,0,0,0,0,0,0,0,0,0,0,0,0,0,0,0,0,0,0,0,0,0,0
0,0,0,0,0,0,0,0,0,0,0,0,0,0,0,0,0,0,0,0,0,0,0,0,0,0,0,0,0,0,0,0,0,0,0
0,0,0,0,0,0,0,0,0,0,0,0,0,0,0,0,0,0,0,0,0,0,0,0,0,0,0,0,0,0,0,0,0,0,0
0,0,0,0,0,0,0,0,0,0,0,0,0,0,0,0,0,0,0,0,0,0,0,0,0,0,0,0,0,0,0,0,0,0,0
0,0,0,0,0,0,0,0,0,0,0,0,0,0,0,0,0,0,0,0,0,0,0,0,0,0,0,0,0,0,0,0,0,0,0
0,0,0,0,0,0,0,0,0,0,0,0,0,0,0,0,0,0,0,0,0,0,0,0,0,0,0,0,0,0,0,0,0,0,0
0,0,0,0,0,0,0,0,0,0,0,0,0,0,0,0,0,0,0,0,0,0,0,0,0,0,0,0,0,0,0,0,0,0,0
0,0,0,0,0,0,0,0,0,0,0,0,0,0,0,0,0,0,0,0,0,0,0,0,0,0,0,0,0,0,0,0,0,0,0
0,0,0,0,0,0,0,0,0,0,0,0,0,0,0,0,0,0,0,0,0,0,0,0,0,0,0,0,0,0,0,0,0,0,0
0,0,0,0,0,0,0,0,0,0,0,0,0,0,0,0,0,0,0,0,0,0,0,0,0,0,0,0,0,0,0,0,0,0,0
0,0,0,0,0,0,0,0,0,0,0,0,0,0,0,0,0,0,0,0,0,0,0,0,0,0,0,0,0,0,0,0,0,0,0
0,0,0,0,0,0,0,0,0,0,0,0,0,0,0,0,0,0,0,0,0,0,0,0,0,0,0,0,0,0,0,0,0,0,0
0,0,0,0,0,0,0,0,0,0,0,0,0,0,0,0,0,0,0,0,0,0,0,0,0,0,0,0,0,0,0,0,0,0,0
0,0,0,0,0,0,0,0,0,0,0,0,0,0,0,0,0,0,0,0,0,0,0,0,0,0,0,0,0,0,0,0,0,0,0
0,0,0,0,0,0,0,0,0,0,0,0,0,0,0,0,0,0,0,0,0,0,0,0,0,0,0,0,0,0,0,0,0,0,0
0,0,0,0,0,0,0,0,0,0,0,0,0,0,0,0,0,0,0,0,0,0,0,0,0,0,0,0,0,0,0,0,0,0,0
0,0,0,0,0,0,0,0,0,0,0,0,0,0,0,0,0,0,0,37,0,0,0,0,0,0,0,0,0,0,0,0,0,0,0
0,0,0,0,0,0,0,0,0,0,0,0,0,0,0,0,0,0,0,34,0,0,0,0,0,0,0,0,0,0,0,0,0,0,0
0,0,0,0,0,0,0,0,0,0,0,0,0,0,0,0,0,31,19,59,21,32,0,0,0,0,0,0,0,0,0,0,0,0,0
0,0,0,0,0,0,0,0,0,0,0,0,0,0,0,0,0,0,0,40,0,0,0,0,0,0,0,0,0,0,0,0,0,0,0
0,0,0,0,0,0,0,0,0,0,0,0,0,0,0,0,0,0,0,33,0,0,0,0,0,0,0,0,0,0,0,0,0,0,0
0,0,0,0,0,0,0,0,0,0,0,0,0,0,0,0,0,0,0,0,0,0,0,0,0,0,0,0,0,0,0,0,0,0,0
0,0,0,0,0,0,0,0,0,0,0,0,0,0,0,0,0,0,0,0,0,0,0,0,0,0,0,0,0,0,0,0,0,0,0
0,0,0,0,0,0,0,0,0,0,0,0,0,0,0,0,0,0,0,0,0,0,0,0,0,0,0,0,0,0,0,0,0,0,0
0,0,0,0,0,0,0,0,0,0,0,0,0,0,0,0,0,0,0,0,0,0,0,0,0,0,0,0,0,0,0,0,0,0,0
0,0,0,0,0,0,0,0,0,0,0,0,0,0,0,0,0,0,0,0,0,0,0,0,0,0,0,0,0,0,0,0,0,0,0
0,0,0,0,0,0,0,0,0,0,0,0,0,0,0,0,0,0,0,0,0,0,0,0,0,0,0,0,0,0,0,0,0,0,0
0,0,0,0,0,0,0,0,0,0,0,0,0,0,0,0,0,0,0,0,0,0,0,0,0,0,0,0,0,0,0,0,0,0,0
0,0,0,0,0,0,0,0,0,0,0,0,0,0,0,0,0,0,0,0,0,0,0,0,0,0,0,0,0,0,0,0,0,0,0
0,0,0,0,0,0,0,0,0,0,0,0,0,0,0,0,0,0,0,0,0,0,0,0,0,0,0,0,0,0,0,0,0,0,0
0,0,0,0,0,0,0,0,0,0,0,0,0,0,0,0,0,0,0,0,0,0,0,0,0,0,0,0,0,0,0,0,0,0,0
0,0,0,0,0,0,0,0,0,0,0,0,0,0,0,0,0,0,0,0,0,0,0,0,0,0,0,0,0,0,0,0,0,0,0
0,0,0,0,0,0,0,0,0,0,0,0,0,0,0,0,0,0,0,0,0,0,0,0,0,0,0,0,0,0,0,0,0,0,0
0,0,0,0,0,0,0,0,0,0,0,0,0,0,0,0,0,0,0,0,0,0,0,0,0,0,0,0,0,0,0,0,0,0,0
0,0,0,0,0,0,0,0,0,0,0,0,0,0,0,0,0,0,0,0,0,0,0,0,0,0,0,0,0,0,0,0,0,0,0
endlayer

layer
0,0,0,0,0,0,0,0,0,0,0,0,0,0,0,0,0,0,0,0,0,0,0,0,0,0,0,0,0,0,0,0,0,0,0
0,0,0,0,0,0,0,0,0,0,0,0,0,0,0,0,0,0,0,0,0,0,0,0,0,0,0,0,0,0,0,0,0,0,0
0,0,0,0,0,0,0,0,0,0,0,0,0,0,0,0,0,0,0,0,0,0,0,0,0,0,0,0,0,0,0,0,0,0,0
0,0,0,0,0,0,0,0,0,0,0,0,0,0,0,0,0,0,0,0,0,0,0,0,0,0,0,0,0,0,0,0,0,0,0
0,0,0,0,0,0,0,0,0,0,0,0,0,0,0,0,0,0,0,0,0,0,0,0,0,0,0,0,0,0,0,0,0,0,0
0,0,0,0,0,0,0,0,0,0,0,0,0,0,0,0,0,0,0,0,0,0,0,0,0,0,0,0,0,0,0,0,0,0,0
0,0,0,0,0,0,0,0,0,0,0,0,0,0,0,0,0,0,0,0,0,0,0,0,0,0,0,0,0,0,0,0,0,0,0
0,0,0,0,0,0,0,0,0,0,0,0,0,0,0,0,0,0,0,0,0,0,0,0,0,0,0,0,0,0,0,0,0,0,0
0,0,0,0,0,0,0,0,0,0,0,0,0,0,0,0,0,0,0,0,0,0,0,0,0,0,0,0,0,0,0,0,0,0,0
0,0,0,0,0,0,0,0,0,0,0,0,0,0,0,0,0,0,0,0,0,0,0,0,0,0,0,0,0,0,0,0,0,0,0
0,0,0,0,0,0,0,0,0,0,0,0,0,0,0,0,0,0,0,0,0,0,0,0,0,0,0,0,0,0,0,0,0,0,0
0,0,0,0,0,0,0,0,0,0,0,0,0,0,0,0,0,0,0,0,0,0,0,0,0,0,0,0,0,0,0,0,0,0,0
0,0,0,0,0,0,0,0,0,0,0,0,0,0,0,0,0,0,0,0,0,0,0,0,0,0,0,0,0,0,0,0,0,0,0
0,0,0,0,0,0,0,0,0,0,0,0,0,0,0,0,0,0,0,0,0,0,0,0,0,0,0,0,0,0,0,0,0,0,0
0,0,0,0,0,0,0,0,0,0,0,0,0,0,0,0,0,0,0,0,0,0,0,0,0,0,0,0,0,0,0,0,0,0,0
0,0,0,0,0,0,0,0,0,0,0,0,0,0,0,0,0,0,0,0,0,0,0,0,0,0,0,0,0,0,0,0,0,0,0
0,0,0,0,0,0,0,0,0,0,0,0,0,0,0,0,0,0,0,0,0,0,0,0,0,0,0,0,0,0,0,0,0,0,0
0,0,0,0,0,0,0,0,0,0,0,0,0,0,0,0,0,0,0,0,0,0,0,0,0,0,0,0,0,0,0,0,0,0,0
0,0,0,0,0,0,0,0,0,0,0,0,0,0,0,0,0,0,0,10,0,0,0,0,0,0,0,0,0,0,0,0,0,0,0
0,0,0,0,0,0,0,0,0,0,0,0,0,0,0,0,0,0,0,0,0,0,0,0,0,0,0,0,0,0,0,0,0,0,0
0,0,0,0,0,0,0,0,0,0,0,0,0,0,0,0,0,0,0,0,0,0,0,0,0,0,0,0,0,0,0,0,0,0,0
0,0,0,0,0,0,0,0,0,0,0,0,0,0,0,0,0,0,0,0,0,0,0,0,0,0,0,0,0,0,0,0,0,0,0
0,0,0,0,0,0,0,0,0,0,0,0,0,0,0,0,0,0,0,0,0,0,0,0,0,0,0,0,0,0,0,0,0,0,0
0,0,0,0,0,0,0,0,0,0,0,0,0,0,0,0,0,0,0,0,0,0,0,0,0,0,0,0,0,0,0,0,0,0,0
0,0,0,0,0,0,0,0,0,0,0,0,0,0,0,0,0,0,0,0,0,0,0,0,0,0,0,0,0,0,0,0,0,0,0
0,0,0,0,0,0,0,0,0,0,0,0,0,0,0,0,0,0,0,0,0,0,0,0,0,0,0,0,0,0,0,0,0,0,0
0,0,0,0,0,0,0,0,0,0,0,0,0,0,0,0,0,0,0,0,0,0,0,0,0,0,0,0,0,0,0,0,0,0,0
0,0,0,0,0,0,0,0,0,0,0,0,0,0,0,0,0,0,0,0,0,0,0,0,0,0,0,0,0,0,0,0,0,0,0
0,0,0,0,0,0,0,0,0,0,0,0,0,0,0,0,0,0,0,0,0,0,0,0,0,0,0,0,0,0,0,0,0,0,0
0,0,0,0,0,0,0,0,0,0,0,0,0,0,0,0,0,0,0,0,0,0,0,0,0,0,0,0,0,0,0,0,0,0,0
0,0,0,0,0,0,0,0,0,0,0,0,0,0,0,0,0,0,0,0,0,0,0,0,0,0,0,0,0,0,0,0,0,0,0
0,0,0,0,0,0,0,0,0,0,0,0,0,0,0,0,0,0,0,0,0,0,0,0,0,0,0,0,0,0,0,0,0,0,0
0,0,0,0,0,0,0,0,0,0,0,0,0,0,0,0,0,0,0,0,0,0,0,0,0,0,0,0,0,0,0,0,0,0,0
0,0,0,0,0,0,0,0,0,0,0,0,0,0,0,0,0,0,0,0,0,0,0,0,0,0,0,0,0,0,0,0,0,0,0
0,0,0,0,0,0,0,0,0,0,0,0,0,0,0,0,0,0,0,0,0,0,0,0,0,0,0,0,0,0,0,0,0,0,0
endlayer

layer
0,0,0,0,0,0,0,0,0,0,0,0,0,0,0,0,0,0,0,0,0,0,0,0,0,0,0,0,0,0,0,0,0,0,0
0,0,0,0,0,0,0,0,0,0,0,0,0,0,0,0,0,0,0,0,0,0,0,0,0,0,0,0,0,0,0,0,0,0,0
0,0,0,0,0,0,0,0,0,0,0,0,0,0,0,0,0,0,0,0,0,0,0,0,0,0,0,0,0,0,0,0,0,0,0
0,0,0,0,0,0,0,0,0,0,0,0,0,0,0,0,0,0,0,0,0,0,0,0,0,0,0,0,0,0,0,0,0,0,0
0,0,0,0,0,0,0,0,0,0,0,0,0,0,0,0,0,0,0,0,0,0,0,0,0,0,0,0,0,0,0,0,0,0,0
0,0,0,0,0,0,0,0,0,0,0,0,0,0,0,0,0,0,0,0,0,0,0,0,0,0,0,0,0,0,0,0,0,0,0
0,0,0,0,0,0,0,0,0,0,0,0,0,0,0,0,0,0,0,0,0,0,0,0,0,0,0,0,0,0,0,0,0,0,0
0,0,0,0,0,0,0,0,0,0,0,0,0,0,0,0,0,0,0,0,0,0,0,0,0,0,0,0,0,0,0,0,0,0,0
0,0,0,0,0,0,0,0,0,0,0,0,0,0,0,0,0,0,0,0,0,0,0,0,0,0,0,0,0,0,0,0,0,0,0
0,0,0,0,0,0,0,0,0,0,0,0,0,0,0,0,0,0,0,0,0,0,0,0,0,0,0,0,0,0,0,0,0,0,0
0,0,0,0,0,0,0,0,0,0,0,0,0,0,0,0,0,0,0,0,0,0,0,0,0,0,0,0,0,0,0,0,0,0,0
0,0,0,0,0,0,0,0,0,0,0,0,0,0,0,0,0,0,0,0,0,0,0,0,0,0,0,0,0,0,0,0,0,0,0
0,0,0,0,0,0,0,0,0,0,0,0,0,0,0,0,0,0,0,0,0,0,0,0,0,0,0,0,0,0,0,0,0,0,0
0,0,0,0,0,0,0,0,0,0,0,0,0,0,0,0,0,0,0,0,0,0,0,0,0,0,0,0,0,0,0,0,0,0,0
0,0,0,0,0,0,0,0,0,0,0,0,0,0,0,0,0,0,0,0,0,0,0,0,0,0,0,0,0,0,0,0,0,0,0
0,0,0,0,0,0,0,0,0,0,0,0,0,0,0,0,0,0,0,0,0,0,0,0,0,0,0,0,0,0,0,0,0,0,0
0,0,0,0,0,0,0,0,0,0,0,0,0,0,0,0,0,0,0,0,0,0,0,0,0,0,0,0,0,0,0,0,0,0,0
0,0,0,0,0,0,0,0,0,0,0,0,0,0,0,0,0,0,0,0,0,0,0,0,0,0,0,0,0,0,0,0,0,0,0
0,0,0,0,0,0,0,0,0,0,0,0,0,0,0,0,0,0,0,14,0,0,0,0,0,0,0,0,0,0,0,0,0,0,0
0,0,0,0,0,0,0,0,0,0,0,0,0,0,0,0,0,0,0,0,0,0,0,0,0,0,0,0,0,0,0,0,0,0,0
0,0,0,0,0,0,0,0,0,0,0,0,0,0,0,0,0,0,0,0,0,0,0,0,0,0,0,0,0,0,0,0,0,0,0
0,0,0,0,0,0,0,0,0,0,0,0,0,0,0,0,0,0,0,0,0,0,0,0,0,0,0,0,0,0,0,0,0,0,0
0,0,0,0,0,0,0,0,0,0,0,0,0,0,0,0,0,0,0,0,0,0,0,0,0,0,0,0,0,0,0,0,0,0,0
0,0,0,0,0,0,0,0,0,0,0,0,0,0,0,0,0,0,0,0,0,0,0,0,0,0,0,0,0,0,0,0,0,0,0
0,0,0,0,0,0,0,0,0,0,0,0,0,0,0,0,0,0,0,0,0,0,0,0,0,0,0,0,0,0,0,0,0,0,0
0,0,0,0,0,0,0,0,0,0,0,0,0,0,0,0,0,0,0,0,0,0,0,0,0,0,0,0,0,0,0,0,0,0,0
0,0,0,0,0,0,0,0,0,0,0,0,0,0,0,0,0,0,0,0,0,0,0,0,0,0,0,0,0,0,0,0,0,0,0
0,0,0,0,0,0,0,0,0,0,0,0,0,0,0,0,0,0,0,0,0,0,0,0,0,0,0,0,0,0,0,0,0,0,0
0,0,0,0,0,0,0,0,0,0,0,0,0,0,0,0,0,0,0,0,0,0,0,0,0,0,0,0,0,0,0,0,0,0,0
0,0,0,0,0,0,0,0,0,0,0,0,0,0,0,0,0,0,0,0,0,0,0,0,0,0,0,0,0,0,0,0,0,0,0
0,0,0,0,0,0,0,0,0,0,0,0,0,0,0,0,0,0,0,0,0,0,0,0,0,0,0,0,0,0,0,0,0,0,0
0,0,0,0,0,0,0,0,0,0,0,0,0,0,0,0,0,0,0,0,0,0,0,0,0,0,0,0,0,0,0,0,0,0,0
0,0,0,0,0,0,0,0,0,0,0,0,0,0,0,0,0,0,0,0,0,0,0,0,0,0,0,0,0,0,0,0,0,0,0
0,0,0,0,0,0,0,0,0,0,0,0,0,0,0,0,0,0,0,0,0,0,0,0,0,0,0,0,0,0,0,0,0,0,0
0,0,0,0,0,0,0,0,0,0,0,0,0,0,0,0,0,0,0,0,0,0,0,0,0,0,0,0,0,0,0,0,0,0,0
endlayer

