
# Created by Ruins mod version 14.4 Ingame Parser
# authoring Player: Mikhaila666

weight=1
embed_into_distance=0
acceptable_target_blocks=
unacceptable_target_blocks=flowing_water,water,flowing_lava,lava
dimensions=8,14,14
allowable_overhang=0
max_leveling=2
leveling_buffer=0
preserve_water=0
preserve_lava=0

rule1=0,100,Railcraft:tile.railcraft.stair-0
rule2=0,100,Railcraft:tile.railcraft.stair-2
rule3=0,100,minecraft:grass-0
rule4=0,100,Railcraft:tile.railcraft.stair-3
rule5=0,100,Railcraft:tile.railcraft.stair-1
rule6=0,100,arsmagica2:liquidEssence-0
rule7=0,100,TConstruct:GlassBlock.StainedClear-9
rule8=0,100,Railcraft:tile.railcraft.residual.heat-0
rule9=0,100,arsmagica2:liquidEssence-1
rule10=0,100,Railcraft:tile.railcraft.lantern.stone-6

layer
0,1,1,1,1,1,1,1,1,1,1,1,1,0
1,4,3,3,3,3,3,3,3,3,3,3,2,1
4,3,3,3,3,3,3,3,3,3,3,3,3,2
4,3,3,3,5,5,5,5,5,5,3,3,3,2
4,3,3,5,2,6,6,6,6,4,5,3,3,2
4,3,3,2,6,7,6,6,7,6,4,3,3,2
4,3,3,2,6,6,6,6,6,6,4,3,3,2
4,3,3,2,6,6,6,6,6,6,4,3,3,2
4,3,3,2,6,7,6,6,7,6,4,3,3,2
4,3,3,2,1,6,6,6,6,1,4,3,3,2
4,3,3,3,2,1,1,1,1,4,3,3,3,2
4,3,3,3,3,3,3,3,3,3,3,3,3,2
4,5,3,3,3,3,3,3,3,3,3,3,5,2
0,4,5,5,5,5,5,5,5,5,5,5,2,0
endlayer

layer
0,0,0,0,0,0,8,8,0,0,0,0,0,0
0,0,0,0,8,0,0,0,0,0,0,0,0,0
0,0,0,0,0,0,0,8,0,0,0,0,0,0
0,0,8,8,0,8,8,0,0,0,0,0,0,0
0,0,0,8,8,8,8,8,0,0,0,0,0,0
0,8,8,8,8,7,9,9,7,8,8,8,0,0
0,0,8,8,8,9,9,9,9,8,0,0,0,0
8,0,0,8,8,9,9,9,9,8,8,0,0,0
0,0,8,8,8,7,9,9,7,8,8,0,0,0
0,0,0,8,8,0,8,8,8,8,0,0,0,0
8,8,0,8,8,8,8,8,8,0,0,0,0,0
0,8,0,8,8,8,0,0,8,0,0,0,0,0
0,0,0,0,8,0,0,0,0,0,0,0,0,0
8,0,0,0,0,0,0,0,0,0,0,0,0,8
endlayer

layer
0,0,0,0,8,0,0,0,0,0,8,8,0,0
8,8,0,8,8,8,0,8,8,0,0,0,0,0
8,8,0,8,0,8,0,0,0,0,8,8,0,0
8,0,8,8,0,0,0,0,0,8,0,0,0,0
0,8,0,0,0,0,8,8,0,0,0,0,0,0
0,0,0,0,0,7,9,9,7,0,0,0,8,0
0,8,0,0,0,9,9,9,9,0,0,0,0,0
0,8,0,0,0,9,9,9,9,0,0,8,0,8
8,0,0,0,0,7,9,9,7,8,0,0,0,0
0,0,0,0,0,0,0,8,0,0,8,0,0,0
0,8,8,0,0,0,8,8,0,0,0,0,0,0
0,8,0,8,8,0,0,0,0,0,0,8,0,0
0,8,0,0,0,0,8,0,8,0,0,0,8,0
0,0,0,0,0,0,8,0,8,0,0,8,0,0
endlayer

layer
0,0,8,0,0,0,0,0,0,0,8,0,0,0
0,0,0,0,0,0,0,0,0,0,0,0,8,0
0,0,0,8,0,0,8,0,0,0,0,8,0,0
0,0,0,0,0,0,8,0,0,0,0,8,0,0
0,0,0,0,0,0,0,0,0,0,0,0,0,0
8,8,8,0,0,10,9,9,10,0,8,0,0,0
0,8,0,0,8,9,9,9,9,0,0,0,0,0
8,0,0,0,0,9,9,9,9,0,0,0,0,0
0,0,0,0,0,10,9,9,10,0,0,8,0,0
0,0,0,0,0,0,8,0,0,0,0,0,0,0
0,0,0,0,8,0,8,0,8,0,0,0,0,0
0,0,0,0,0,0,0,0,0,0,0,0,0,0
8,0,0,0,0,0,0,0,8,0,0,0,0,0
0,0,0,0,0,0,0,0,0,0,0,0,0,0
endlayer

layer
0,0,0,0,0,0,0,0,0,0,0,0,0,0
0,0,0,0,0,0,0,0,0,0,0,0,0,0
0,0,0,0,0,0,0,0,0,0,0,0,0,0
0,0,0,0,0,0,0,0,0,0,0,0,0,0
0,0,0,0,0,0,0,0,0,0,0,0,0,0
0,0,0,0,0,0,9,9,0,0,0,0,0,0
0,0,0,0,0,9,6,6,9,0,0,0,0,0
0,0,0,0,0,9,6,6,9,8,8,0,8,0
0,0,0,0,0,0,9,9,0,0,0,0,0,0
0,0,0,0,0,0,0,0,0,0,0,0,0,0
0,0,0,0,0,0,0,0,0,0,0,0,0,0
0,0,0,0,0,0,0,0,0,0,0,0,0,0
0,0,0,0,0,0,0,0,0,0,0,0,0,0
0,0,0,0,0,0,0,0,0,0,0,0,0,0
endlayer

layer
0,0,0,0,0,0,0,0,0,0,0,0,0,0
0,0,0,0,0,0,0,0,0,0,0,0,0,0
0,0,0,0,0,0,0,0,0,0,0,0,0,0
0,0,0,0,0,0,0,0,0,0,0,0,0,0
0,0,0,0,0,0,0,0,0,0,0,0,0,0
0,0,0,0,0,0,0,0,0,0,0,0,0,0
0,0,0,0,8,8,0,0,0,0,0,0,0,0
0,0,0,0,0,0,0,0,0,0,8,0,0,0
0,0,0,0,0,0,0,0,0,0,0,0,0,0
0,0,0,0,0,0,0,0,0,0,0,0,0,0
0,0,0,0,0,0,0,0,0,0,0,0,0,0
0,0,0,0,0,0,0,0,0,0,0,0,0,0
0,0,0,0,0,0,0,0,0,0,0,0,0,0
0,0,0,0,0,0,0,0,0,0,0,0,0,0
endlayer

layer
0,0,0,0,0,0,0,0,0,0,0,0,0,0
0,0,0,0,0,0,0,0,0,0,0,0,0,0
0,0,0,0,0,0,0,0,8,0,0,0,0,0
0,0,0,0,0,0,0,0,0,0,0,0,0,0
0,0,0,0,0,0,0,0,0,0,0,0,0,0
0,0,0,0,0,8,0,0,0,0,0,0,0,0
0,0,0,0,0,0,0,0,0,0,0,0,0,0
0,0,0,0,0,0,0,0,0,0,0,0,0,0
0,0,0,0,0,0,0,0,0,0,0,0,0,0
0,0,0,0,0,0,0,0,0,0,0,0,0,0
0,0,0,0,0,0,0,0,0,0,0,0,8,0
0,0,0,0,0,0,0,0,0,0,0,0,0,0
0,0,0,8,0,0,0,0,0,0,0,0,0,0
0,0,0,0,0,0,0,0,0,0,0,0,0,0
endlayer

layer
0,0,0,0,0,0,0,0,0,0,0,0,0,0
0,0,0,0,0,0,0,0,0,0,0,0,0,0
0,0,0,0,0,0,0,0,0,0,0,0,0,0
0,0,0,0,0,0,0,0,0,0,0,0,0,0
0,0,0,0,0,0,0,0,0,0,0,0,0,0
0,0,0,0,0,0,0,0,0,0,0,0,0,0
0,0,0,0,0,0,8,8,0,0,0,0,0,0
0,0,0,0,0,0,0,0,8,0,0,0,0,0
0,0,0,0,0,0,0,0,0,0,0,0,0,0
0,0,0,0,0,0,0,0,0,0,0,0,0,0
0,0,0,0,0,0,0,0,0,0,0,0,0,0
0,0,0,0,0,0,0,0,0,0,0,0,0,0
0,0,0,0,0,0,0,0,0,0,0,0,0,0
0,0,0,0,0,0,0,0,0,0,0,0,0,0
endlayer

