
# Created by Ruins mod version 14.4 Ingame Parser
# authoring Player: Mikhaila666

weight=1
embed_into_distance=0
acceptable_target_blocks=
unacceptable_target_blocks=flowing_water,water,flowing_lava,lava
dimensions=13,14,12
allowable_overhang=0
max_leveling=2
leveling_buffer=0
preserve_water=0
preserve_lava=0

rule1=0,100,minecraft:grass-0
rule2=0,100,minecraft:planks-1
rule3=0,100,minecraft:gravel-0
rule4=0,100,minecraft:dirt-0
rule5=0,100,minecraft:red_flower-0
rule6=0,100,minecraft:leaves-1
rule7=0,100,minecraft:stone_brick_stairs-0
rule8=0,100,minecraft:stone_brick_stairs-2
rule9=0,100,minecraft:cobblestone-0
rule10=0,100,minecraft:stone_brick_stairs-3
rule11=0,100,ChestGenHook:dungeonChest:5-5
rule12=0,100,minecraft:furnace-5
rule13=0,100,minecraft:stone_slab-11
rule14=0,100,minecraft:wool-8
rule15=0,100,minecraft:log-0
rule16=0,100,minecraft:wooden_door-1
rule17=0,100,minecraft:ladder-3
rule18=0,100,minecraft:oak_stairs-1
rule19=0,100,minecraft:crafting_table-0
rule20=0,100,minecraft:wooden_slab-8
rule21=0,100,minecraft:stone_brick_stairs-1
rule22=0,100,minecraft:stonebrick-0
rule23=0,100,minecraft:fence-0
rule24=0,100,minecraft:cobblestone_wall-0
rule25=2,100,minecraft:torch-4
rule26=0,100,minecraft:wooden_door-8
rule27=0,100,Railcraft:tile.railcraft.residual.heat-0
rule28=0,100,minecraft:stone_pressure_plate-0
rule29=0,100,minecraft:stone_stairs-4
rule30=0,100,minecraft:wooden_slab-9
rule31=0,100,minecraft:stone_stairs-6
rule32=0,100,minecraft:stone_stairs-7
rule33=0,100,minecraft:double_wooden_slab-0
rule34=0,100,minecraft:stone_stairs-5
rule35=0,100,minecraft:stone_brick_stairs-6
rule36=0,100,minecraft:stone_brick_stairs-7
rule37=0,100,minecraft:stone_brick_stairs-5
rule38=0,100,minecraft:oak_stairs-0
rule39=0,100,minecraft:glass_pane-0
rule40=0,100,minecraft:oak_stairs-2
rule41=0,100,minecraft:oak_stairs-3
rule42=0,100,minecraft:bed-10
rule43=0,100,minecraft:bed-2
rule44=0,100,minecraft:bed-0
rule45=0,100,minecraft:bed-8
rule46=0,100,ChestGenHook:dungeonChest:5-4
rule47=0,100,minecraft:oak_stairs-4
rule48=0,100,minecraft:oak_stairs-6
rule49=0,100,minecraft:oak_stairs-7
rule50=0,100,minecraft:oak_stairs-5
rule51=0,100,minecraft:wooden_slab-0
rule52=0,100,minecraft:log-8
rule53=0,100,minecraft:log-4
rule54=0,100,ChestGenHook:dungeonChest:5-2
rule55=0,100,minecraft:spruce_stairs-0
rule56=2,100,minecraft:torch-3
rule57=0,100,minecraft:spruce_stairs-1
rule58=0,100,minecraft:spruce_stairs-7
rule59=0,100,minecraft:spruce_stairs-6
rule60=0,100,minecraft:planks-0
rule61=0,100,minecraft:spruce_stairs-2
rule62=0,100,minecraft:spruce_stairs-3

layer
1,1,1,1,1,1,1,1,1,1,1,1
1,1,2,1,2,1,2,1,2,1,1,1
1,2,2,2,2,2,2,2,2,2,2,1
1,1,2,2,2,2,2,2,2,2,2,1
1,2,2,2,2,2,2,2,2,2,2,2
1,3,3,2,2,2,2,2,2,2,2,1
1,2,2,2,2,2,2,2,2,2,2,2
1,3,2,2,2,2,2,2,2,2,2,1
1,2,2,2,2,2,2,2,2,2,2,2
1,1,2,3,2,3,2,3,2,3,2,1
1,1,3,3,4,3,3,3,4,3,1,1
1,1,3,3,4,4,4,4,4,3,3,1
1,1,3,3,3,3,3,3,3,3,3,3
1,1,3,3,3,3,3,3,3,3,3,1
endlayer

layer
6,5,6,6,6,5,0,0,0,0,0,0
6,0,7,0,7,0,7,0,7,0,7,0
6,10,9,9,9,9,9,9,9,9,9,8
0,0,9,14,14,14,12,13,12,11,9,0
5,10,9,0,14,0,0,0,0,0,15,8
0,0,16,0,0,0,0,0,0,0,16,0
0,10,9,18,0,0,0,0,18,17,15,8
0,0,9,20,20,0,0,0,20,19,9,0
0,10,9,9,9,0,0,0,9,9,9,8
0,0,21,0,9,0,0,0,9,0,21,0
0,0,0,0,9,0,0,0,9,0,0,0
0,0,0,10,9,9,9,9,9,8,0,0
0,0,0,0,21,0,0,0,21,0,0,0
0,0,0,0,0,0,0,0,0,0,0,0
endlayer

layer
0,0,0,0,0,0,0,0,0,0,0,0
0,0,0,0,0,0,0,0,0,0,0,0
0,0,22,22,22,23,22,23,22,22,22,0
0,0,23,0,14,0,24,0,24,0,22,0
0,0,22,25,0,0,0,0,0,0,15,0
0,0,26,0,0,0,0,0,0,0,26,0
0,27,22,0,0,0,0,0,0,17,15,0
0,0,23,28,0,0,0,0,28,0,22,0
0,0,22,22,22,0,0,0,22,22,22,0
0,0,0,0,22,0,0,0,22,0,0,0
0,0,0,0,22,0,0,0,22,0,0,0
0,0,0,0,22,22,22,22,22,0,0,0
0,0,0,0,0,0,0,0,0,0,0,0
0,0,0,0,0,0,0,0,0,0,0,27
endlayer

layer
0,0,0,0,0,0,0,0,0,0,0,0
0,0,29,30,29,30,29,30,29,30,29,0
0,32,22,22,22,22,22,22,22,22,22,31
0,30,22,33,33,33,33,33,33,33,22,30
0,32,22,20,20,20,20,20,20,20,15,31
0,30,22,20,20,20,20,20,20,20,22,30
0,32,22,20,20,20,20,20,20,17,15,31
0,30,22,20,20,20,20,20,20,20,22,30
0,32,22,22,22,0,0,0,22,22,22,31
0,0,34,30,22,0,0,0,22,30,34,0
0,0,0,30,22,0,0,0,22,30,0,0
0,0,0,36,22,22,22,22,22,35,0,0
0,0,0,0,37,30,30,30,37,0,0,0
0,0,0,0,0,0,0,0,0,0,0,0
endlayer

layer
0,0,0,0,0,0,0,0,0,0,0,0
0,0,24,0,24,0,24,0,24,0,24,0
0,24,15,38,15,39,15,38,15,38,15,24
0,0,41,23,0,11,0,0,0,11,40,0
0,24,15,0,43,42,43,42,43,42,15,24
0,0,41,0,0,0,0,0,0,0,40,0
0,24,15,45,44,0,0,0,0,17,15,24
0,0,41,46,0,0,0,0,0,0,40,0
0,24,15,18,15,0,0,0,15,18,15,24
0,0,24,0,41,0,0,0,40,0,24,0
0,0,0,0,41,0,0,0,40,0,0,0
0,0,0,24,15,18,18,18,15,24,0,0
0,0,0,0,24,0,0,0,24,0,0,0
0,0,0,0,0,0,0,0,0,0,0,0
endlayer

layer
0,0,0,0,0,0,0,0,0,0,0,0
0,0,24,0,24,0,24,0,24,0,24,0
0,24,15,47,15,39,15,47,15,47,15,24
0,0,49,23,0,0,0,0,0,0,48,0
0,24,15,0,0,0,0,0,0,0,15,24
0,0,49,0,0,0,0,0,0,0,48,0
0,24,15,0,0,0,0,0,0,17,15,24
0,0,49,0,0,0,0,0,0,0,48,27
0,24,15,50,15,0,0,0,15,50,15,24
0,0,24,0,49,0,0,0,48,0,24,0
0,0,0,0,49,0,0,0,48,0,0,0
0,0,0,24,15,50,50,50,15,24,0,0
0,0,0,0,24,0,0,0,24,0,0,0
0,0,0,0,0,0,0,0,0,0,0,0
endlayer

layer
0,0,0,0,0,0,0,0,0,0,0,0
0,0,38,51,38,51,38,51,38,51,38,0
0,41,15,52,52,52,52,52,15,52,15,40
0,51,53,2,2,2,2,2,2,2,53,51
0,41,53,2,2,2,2,2,2,2,53,40
0,51,53,2,2,2,2,2,2,2,53,51
0,41,53,2,2,2,2,2,2,2,53,40
0,51,53,2,2,2,2,2,2,2,53,51
0,41,15,52,52,52,52,52,15,52,15,40
0,0,18,51,53,0,0,0,53,51,18,0
0,0,0,51,53,0,0,0,53,51,0,0
0,0,0,41,15,52,52,52,15,40,0,0
0,0,0,0,18,51,51,51,18,0,0,0
0,0,0,0,0,0,0,0,0,0,0,0
endlayer

layer
0,0,0,0,0,0,0,0,0,0,0,0
0,0,0,0,0,0,0,0,0,0,0,0
0,0,15,23,15,23,15,23,15,23,15,0
0,0,23,14,14,0,11,19,9,19,23,0
0,0,15,14,0,0,0,0,19,0,15,0
0,0,23,0,0,0,0,0,0,0,0,0
0,0,15,54,0,0,0,0,0,0,15,0
0,0,23,0,0,0,0,0,46,0,23,0
0,0,15,23,15,0,0,0,15,23,15,0
0,0,0,0,23,0,0,0,23,0,0,0
0,0,0,0,23,0,0,0,23,0,0,0
0,0,0,0,15,23,23,23,15,0,0,0
0,0,0,0,0,0,0,0,0,0,0,0
0,0,0,0,0,0,0,0,0,0,0,0
endlayer

layer
0,0,0,0,0,0,0,0,0,0,0,0
0,38,55,38,55,38,55,38,55,38,38,38
0,50,15,23,15,23,15,23,15,23,15,50
0,0,23,14,54,0,0,0,19,0,23,0
0,0,15,0,0,0,0,0,0,0,15,0
0,0,23,0,0,0,0,0,0,0,0,0
0,0,15,0,0,0,0,0,0,56,15,0
0,0,23,0,0,0,0,0,0,0,23,0
0,47,15,23,15,0,0,0,15,23,15,47
0,18,57,18,59,0,0,0,58,40,57,18
0,0,0,41,59,0,0,0,58,40,0,0
0,0,0,41,15,23,23,23,15,40,0,0
0,0,0,41,59,0,0,0,58,40,0,0
0,0,0,0,0,0,0,0,0,0,0,0
endlayer

layer
0,0,0,0,0,0,0,0,0,0,0,0
0,0,0,0,0,0,0,0,0,0,0,0
0,38,55,38,55,38,55,38,55,38,55,38
0,50,53,50,50,50,50,50,50,50,53,50
0,0,15,0,0,0,0,0,0,0,15,0
0,0,53,0,0,0,0,0,0,0,53,0
0,0,15,0,0,0,0,0,0,0,15,0
0,47,53,47,47,47,47,47,47,47,53,47
0,18,57,18,57,60,2,60,57,18,57,18
0,0,0,0,62,60,2,60,61,0,0,0
0,0,0,0,62,60,2,60,61,0,0,0
0,0,0,0,62,60,2,60,61,0,0,0
0,0,0,0,62,60,2,60,61,0,0,0
0,0,0,0,0,0,0,0,0,0,0,0
endlayer

layer
0,0,0,0,0,0,0,0,0,0,0,0
0,0,0,0,0,0,0,0,0,0,0,0
0,0,0,0,0,0,0,0,0,0,0,0
0,38,55,38,55,38,55,38,9,38,55,38
0,33,2,50,2,50,2,50,2,50,2,33
0,33,2,20,2,20,2,20,2,20,2,33
0,33,2,47,2,47,2,47,2,47,2,33
0,18,57,18,57,18,57,18,57,18,57,18
0,0,0,0,0,0,0,0,0,0,0,0
0,0,0,0,0,0,0,0,0,0,0,0
0,0,0,0,0,0,0,0,0,0,0,0
0,0,0,0,0,0,0,0,0,0,0,0
0,0,0,0,0,0,0,0,0,0,0,0
0,0,0,0,0,0,0,0,0,0,0,0
endlayer

layer
0,0,0,0,0,0,0,0,0,0,0,0
0,0,0,0,0,0,0,0,0,0,0,0
0,0,0,0,0,0,0,0,0,0,0,0
0,0,0,0,0,0,0,0,9,0,0,0
0,0,0,0,0,0,0,0,0,0,0,0
0,0,0,0,0,0,0,0,0,0,0,0
0,0,0,0,0,0,0,0,0,0,0,0
0,0,0,0,0,0,0,0,0,0,0,0
0,0,0,0,0,0,0,0,0,0,0,0
0,0,0,0,0,0,0,0,0,0,0,0
0,0,0,0,0,0,0,0,0,0,0,0
0,0,0,0,0,0,0,0,0,0,0,0
0,0,0,0,0,0,0,0,0,0,0,0
0,0,0,0,0,0,0,0,0,0,0,0
endlayer

layer
0,0,0,0,0,0,0,0,0,0,0,0
0,0,0,0,0,0,0,0,0,0,0,0
0,0,0,0,0,0,0,0,0,0,0,0
0,0,0,0,0,0,0,0,24,0,0,0
0,0,0,0,0,0,0,0,0,0,0,0
0,0,0,0,0,0,0,0,0,0,0,0
0,0,0,0,0,0,0,0,0,0,0,0
0,0,0,0,0,0,0,0,0,0,0,0
0,0,0,0,0,0,0,0,0,0,0,0
0,0,0,0,0,0,0,0,0,0,0,0
0,0,0,0,0,0,0,0,0,0,0,0
0,0,0,0,0,0,0,0,0,0,0,0
0,0,0,0,0,0,0,0,0,0,0,0
0,0,0,0,0,0,0,0,0,0,0,0
endlayer

