
# Created by Ruins mod version 14.4 Ingame Parser
# authoring Player: Mikhaila666

weight=1
embed_into_distance=0
acceptable_target_blocks=
unacceptable_target_blocks=flowing_water,water,flowing_lava,lava
dimensions=16,19,20
allowable_overhang=0
max_leveling=2
leveling_buffer=0
preserve_water=0
preserve_lava=0

rule1=0,100,minecraft:wooden_slab-0
rule2=0,100,minecraft:planks-0
rule3=0,100,minecraft:wool-14
rule4=0,100,minecraft:wool-11
rule5=0,100,MobSpawner:Spider
rule6=0,100,MobSpawner:Zombie
rule7=0,100,minecraft:stonebrick-0
rule8=0,100,minecraft:stonebrick-2
rule9=0,100,minecraft:double_stone_slab-0
rule10=0,100,minecraft:bookshelf-0
rule11=0,100,minecraft:stonebrick-1
rule12=0,100,Railcraft:tile.railcraft.residual.heat-0
rule13=0,100,minecraft:stone_slab-0
rule14=0,100,minecraft:web-0
rule15=2,100,minecraft:torch-2
rule16=2,100,minecraft:torch-4
rule17=2,100,minecraft:torch-3
rule18=2,100,minecraft:torch-1
rule19=0,100,minecraft:stonebrick-3
rule20=0,100,minecraft:fence-0
rule21=0,100,minecraft:iron_bars-0
rule22=0,100,IInventory;minecraft:chest;minecraft:iron_helmet#1#0#2+minecraft:apple#1#0#8-4
rule23=0,100,IInventory;minecraft:chest;minecraft:iron_pickaxe#1#0#5+Railcraft:fuel.coke#9#0#20-4
rule24=0,100,minecraft:wool-0
rule25=0,100,minecraft:wool-10
rule26=0,100,minecraft:glowstone-0

layer
0,0,0,0,0,0,0,0,0,0,0,0,0,0,0,0,0,0,0,0
0,0,0,0,0,0,0,0,0,0,0,0,0,0,0,0,0,0,0,0
0,0,0,0,0,0,0,0,0,1,1,0,0,0,0,0,0,0,0,0
0,0,0,0,0,0,0,0,1,2,2,1,0,0,0,0,0,0,0,0
0,0,0,0,0,0,0,0,2,2,2,2,0,0,0,0,0,0,0,0
0,0,0,0,0,0,0,2,2,3,3,2,2,0,0,0,0,0,0,0
0,0,0,0,0,0,2,2,4,3,3,4,2,2,0,0,0,0,0,0
0,0,0,0,0,2,5,2,2,3,3,2,4,2,2,0,0,0,0,0
0,0,0,1,2,2,4,2,2,3,3,2,2,4,2,2,1,0,0,0
0,0,1,2,2,3,3,3,3,4,4,3,3,3,3,2,2,1,0,0
0,0,1,2,2,3,3,3,3,4,4,3,3,3,3,2,2,1,0,0
0,0,0,1,2,2,4,2,2,3,3,2,2,4,2,2,1,0,0,0
0,0,0,0,0,2,2,4,2,3,3,2,2,6,2,0,0,0,0,0
0,0,0,0,0,0,2,2,4,3,3,4,2,2,0,0,0,0,0,0
0,0,0,0,0,0,0,2,2,3,3,2,2,0,0,0,0,0,0,0
0,0,0,0,0,0,0,0,2,2,2,2,0,0,0,0,0,0,0,0
0,0,0,0,0,0,0,0,1,2,2,1,0,0,0,0,0,0,0,0
0,0,0,0,0,0,0,0,0,1,1,0,0,0,0,0,0,0,0,0
0,0,0,0,0,0,0,0,0,0,0,0,0,0,0,0,0,0,0,0
endlayer

layer
0,0,0,0,0,0,0,0,0,0,0,0,0,0,0,0,0,0,0,0
0,0,0,0,0,0,0,0,0,0,0,0,0,0,0,0,0,0,0,0
0,0,0,0,0,0,0,0,0,0,0,0,0,0,0,0,0,0,0,0
0,0,0,0,0,0,0,0,0,0,0,0,0,0,0,0,0,0,0,0
0,0,0,0,0,0,0,0,8,0,0,7,0,0,0,0,0,0,0,0
0,0,0,0,0,0,0,11,10,0,0,9,7,0,0,0,0,0,0,0
0,0,0,0,0,0,8,10,0,0,0,9,9,11,0,0,0,0,0,0
0,0,0,0,0,7,10,0,0,12,0,2,9,9,7,0,0,0,0,0
0,0,0,0,11,10,0,0,12,0,0,0,2,9,13,11,0,0,0,0
0,0,0,0,0,0,0,0,0,12,0,0,0,0,0,0,0,0,0,0
0,0,0,0,0,0,0,0,0,12,12,12,0,0,0,0,0,0,0,0
0,0,0,0,8,10,0,0,12,12,12,0,0,14,10,11,0,0,0,0
0,0,0,0,0,11,10,14,0,0,0,0,0,10,8,0,0,0,0,0
0,0,0,0,0,0,7,10,0,0,0,0,10,7,0,0,0,0,0,0
0,0,0,0,0,0,0,7,10,0,0,10,7,0,0,0,0,0,0,0
0,0,0,0,0,0,0,0,8,0,0,11,0,0,0,0,0,0,0,0
0,0,0,0,0,0,0,0,0,0,0,0,0,0,0,0,0,0,0,0
0,0,0,0,0,0,0,0,0,0,0,0,0,0,0,0,0,0,0,0
0,0,0,0,0,0,0,0,0,0,0,0,0,0,0,0,0,0,0,0
endlayer

layer
0,0,0,0,0,0,0,0,0,0,0,0,0,0,0,0,0,0,0,0
0,0,0,0,0,0,0,0,0,0,0,0,0,0,0,0,0,0,0,0
0,0,0,0,0,0,0,0,0,0,0,0,0,0,0,0,0,0,0,0
0,0,0,0,0,0,0,0,15,0,0,15,0,0,0,0,0,0,0,0
0,0,0,0,0,0,0,0,7,0,0,11,0,0,0,0,0,0,0,0
0,0,0,0,0,0,0,8,10,0,0,9,7,0,0,0,0,0,0,0
0,0,0,0,0,0,8,10,0,0,0,9,9,8,0,0,0,0,0,0
12,0,0,0,0,11,10,0,0,0,0,2,9,13,11,0,0,0,0,0
0,0,0,17,11,10,0,0,0,0,0,0,2,12,0,7,16,0,0,0
0,0,0,0,0,0,0,0,0,0,0,0,0,0,0,0,0,0,0,0
0,0,0,0,0,0,0,0,0,0,0,0,0,0,0,0,0,0,0,0
0,0,0,17,8,10,14,0,0,0,0,0,0,0,10,8,16,0,0,0
0,0,0,0,0,7,10,0,0,0,0,0,0,10,11,0,0,0,0,0
0,0,0,0,0,0,11,10,0,0,0,0,10,8,0,0,0,0,0,0
0,0,0,0,0,0,0,8,10,0,0,10,7,0,0,0,0,0,0,0
0,0,0,0,0,0,0,0,7,0,0,11,0,0,0,0,0,0,0,0
0,0,0,0,0,0,0,0,18,0,0,18,0,0,0,0,0,0,0,0
0,0,0,0,0,0,0,0,0,0,0,0,0,0,0,0,0,0,0,0
0,0,0,0,0,0,0,0,0,0,0,0,0,0,0,0,0,0,0,0
endlayer

layer
0,0,0,0,0,0,0,0,0,0,0,0,0,0,0,0,0,0,0,0
0,0,0,0,0,0,0,0,0,0,0,0,0,0,0,0,0,0,0,0
0,0,0,0,0,0,0,0,0,0,0,0,0,0,0,0,0,0,0,0
0,0,0,0,0,0,0,0,0,0,0,0,0,0,0,0,0,0,0,0
0,0,0,0,0,0,0,0,8,19,19,7,0,0,0,0,0,0,0,0
0,0,0,0,0,0,0,11,10,18,18,9,11,0,0,0,0,0,0,0
0,0,0,0,0,0,7,10,0,0,0,9,13,11,0,0,0,0,0,0
0,0,0,0,0,8,10,14,0,0,14,2,0,0,7,0,0,0,0,0
0,0,0,0,7,10,0,0,0,0,0,0,2,0,0,8,0,0,0,0
0,0,0,0,19,16,0,0,0,0,0,0,0,0,17,19,0,0,0,0
0,0,0,0,19,16,0,0,0,0,0,0,0,0,17,19,0,0,0,0
0,0,0,0,11,10,0,0,0,0,0,0,0,0,10,11,0,0,0,0
0,0,0,0,0,7,10,0,0,0,0,0,14,10,8,0,0,0,0,0
0,0,0,0,0,0,8,10,14,0,0,0,10,7,0,0,0,0,0,0
0,0,0,0,0,0,0,8,10,15,15,10,11,0,0,0,0,0,0,0
0,0,0,0,0,0,0,0,11,19,19,7,0,0,0,0,0,0,0,0
0,0,0,0,0,0,0,0,0,0,0,0,0,0,0,0,0,0,0,0
0,0,0,0,0,0,0,0,0,0,0,0,0,0,0,0,0,0,0,0
0,0,0,0,0,0,0,0,0,0,0,0,0,0,0,0,0,0,0,0
endlayer

layer
0,0,0,0,0,0,0,0,0,0,0,0,0,0,0,0,0,0,0,0
0,0,0,0,0,0,0,0,2,2,2,2,0,0,0,0,0,0,0,0
0,0,0,0,0,0,0,0,2,2,2,2,0,0,0,0,0,0,0,0
0,0,0,0,0,0,0,0,2,2,2,2,0,0,0,0,0,0,0,0
0,0,0,0,0,0,0,0,8,11,11,7,0,0,0,0,0,0,0,0
0,0,0,0,0,0,0,11,10,10,2,13,11,0,0,0,0,0,0,0
0,0,0,0,0,0,8,10,2,2,2,0,0,7,0,0,0,0,0,0
0,0,0,0,0,7,10,2,2,2,2,2,0,0,8,0,0,0,0,0
0,2,2,2,11,10,2,2,2,2,2,2,2,0,2,11,2,2,2,0
0,2,2,2,8,2,2,2,2,2,2,2,2,2,2,11,2,2,2,0
0,2,2,2,11,2,2,2,2,2,2,2,2,2,2,11,2,2,2,0
0,2,2,2,7,10,2,2,2,2,2,2,2,2,10,7,2,2,2,0
0,0,0,0,0,8,10,2,2,2,2,2,2,10,11,0,0,0,0,0
0,0,0,0,0,0,11,10,2,2,2,2,10,7,0,0,0,0,0,0
0,0,0,0,0,0,0,8,10,2,2,10,8,0,0,0,0,0,0,0
0,0,0,0,0,0,0,0,7,7,11,11,0,0,0,0,0,0,0,0
0,0,0,0,0,0,0,0,2,2,2,2,0,0,0,0,0,0,0,0
0,0,0,0,0,0,0,0,2,2,2,2,0,0,0,0,0,0,0,0
0,0,0,0,0,0,0,0,2,2,2,2,0,0,0,0,0,0,0,0
endlayer

layer
0,0,0,0,0,0,0,0,0,0,0,0,0,0,0,0,0,0,0,0
0,0,0,0,0,0,0,0,20,20,20,20,0,0,0,0,0,0,0,0
0,0,0,0,0,0,0,0,20,0,0,20,0,0,0,0,0,0,0,0
0,0,0,0,0,0,0,0,20,0,0,20,0,0,0,0,0,0,0,0
0,0,0,0,0,0,0,0,11,0,0,11,0,0,0,0,0,0,0,0
0,0,0,0,0,0,0,7,0,0,0,0,8,0,0,0,0,0,0,0
0,0,0,0,0,0,11,14,0,0,12,0,0,7,0,0,0,0,0,0
0,0,0,0,0,7,0,0,0,0,0,0,0,0,11,0,0,0,0,0
0,20,20,20,11,14,0,0,21,21,21,0,0,0,0,8,20,20,20,0
0,20,12,0,12,12,12,0,21,22,19,0,12,0,0,0,0,0,20,0
0,20,12,0,0,12,12,12,21,19,0,0,0,0,0,0,0,14,20,0
0,20,20,20,11,0,0,0,0,0,0,12,12,0,0,11,20,20,20,0
0,0,0,0,0,7,0,0,12,12,0,0,0,0,8,0,0,0,0,0
0,0,0,0,0,0,11,0,0,0,0,0,0,7,0,0,0,0,0,0
0,0,0,0,0,0,0,8,14,12,0,0,11,0,0,0,0,0,0,0
0,0,0,0,0,0,0,0,8,0,0,8,0,0,0,0,0,0,0,0
0,0,0,0,0,0,0,0,20,0,0,20,0,0,0,0,0,0,0,0
0,0,0,0,0,0,0,0,20,0,0,20,0,0,0,0,0,0,0,0
0,0,0,0,0,0,0,0,20,20,20,20,0,0,0,0,0,0,0,0
endlayer

layer
0,0,0,0,0,0,0,0,0,0,0,0,0,0,0,0,0,0,0,0
0,0,0,0,0,0,0,0,0,0,0,0,0,0,0,0,0,0,0,0
0,0,0,0,0,0,0,0,0,0,0,0,0,0,0,0,0,0,0,0
0,0,0,0,0,0,0,0,0,0,0,0,0,0,0,0,0,0,0,0
0,0,0,0,0,0,0,0,7,0,0,8,0,0,0,0,0,0,0,0
0,0,0,0,0,0,0,8,0,0,0,0,7,0,0,0,0,0,0,0
0,0,0,0,0,0,8,0,0,0,0,0,14,11,0,0,0,0,0,0
0,0,0,0,0,11,0,0,0,0,0,0,0,0,8,0,0,0,0,0
0,0,0,0,8,0,0,0,21,21,21,21,0,0,0,11,0,0,0,0
0,0,0,0,0,0,0,0,21,19,19,21,0,0,0,0,0,0,0,0
0,0,0,0,0,0,12,12,21,19,19,21,0,0,0,0,0,0,0,0
0,0,0,0,7,0,0,0,0,0,0,0,0,0,0,8,0,0,0,0
0,0,0,0,0,11,14,0,0,0,0,0,0,0,7,0,0,0,0,0
0,0,0,0,0,0,7,0,0,0,0,0,14,11,0,0,0,0,0,0
0,0,0,0,0,0,0,11,0,0,0,0,8,0,0,0,0,0,0,0
0,0,0,0,0,0,0,0,7,0,0,11,0,0,0,0,0,0,0,0
0,0,0,0,0,0,0,0,0,0,0,0,0,0,0,0,0,0,0,0
0,0,0,0,0,0,0,0,0,0,0,0,0,0,0,0,0,0,0,0
0,0,0,0,0,0,0,0,0,0,0,0,0,0,0,0,0,0,0,0
endlayer

layer
0,0,0,0,0,0,0,0,0,0,0,0,0,0,0,0,0,0,0,0
0,0,0,0,0,0,0,0,0,0,0,0,0,0,0,0,0,0,0,0
0,0,0,0,0,0,0,0,0,0,0,0,0,0,0,0,0,0,0,0
0,0,0,0,0,0,0,0,15,0,0,15,0,0,0,0,0,0,0,0
0,0,0,0,0,0,0,0,8,0,0,11,0,0,0,0,0,0,0,0
0,0,0,0,0,0,0,7,0,0,0,14,11,0,0,0,0,0,0,0
0,0,0,0,0,0,11,0,0,0,0,0,0,8,0,0,0,0,0,0
0,0,0,0,0,7,0,0,0,0,0,0,0,0,11,0,0,0,0,0
0,0,0,17,7,0,0,0,0,21,21,21,0,0,0,11,16,0,0,0
0,0,0,0,0,0,0,0,0,19,23,21,0,0,0,0,0,0,0,0
0,0,0,0,0,0,0,0,0,0,19,21,0,0,0,14,0,0,0,0
0,0,0,17,8,0,0,0,0,0,0,0,0,0,0,7,16,0,0,0
0,0,0,0,0,11,0,0,0,0,0,0,0,0,8,0,0,0,0,0
0,0,0,0,0,0,7,0,0,0,0,0,0,7,0,0,0,0,0,0
0,0,0,0,0,0,0,8,0,0,0,0,11,0,0,0,0,0,0,0
0,0,0,0,0,0,0,0,11,0,0,8,0,0,0,0,0,0,0,0
0,0,0,0,0,0,0,0,18,0,0,18,0,0,0,0,0,0,0,0
0,0,0,0,0,0,0,0,0,0,0,0,0,0,0,0,0,0,0,0
0,0,0,0,0,0,0,0,0,0,0,0,0,0,0,0,0,0,0,0
endlayer

layer
0,0,0,0,0,0,0,0,0,0,0,0,0,0,0,0,0,0,0,0
0,0,0,0,0,0,0,0,0,0,0,0,0,0,0,0,0,0,0,0
0,0,0,0,0,0,0,0,0,0,0,0,0,0,0,0,0,0,0,0
0,0,0,0,0,0,0,0,0,0,0,0,0,0,0,0,0,0,0,0
0,0,0,0,0,0,0,0,7,19,19,8,0,0,0,0,0,0,0,0
0,0,0,0,0,0,0,7,0,0,0,0,8,0,0,0,0,0,0,0
0,0,0,0,0,0,8,0,0,0,0,0,0,7,0,0,0,0,0,0
0,0,0,0,0,8,0,0,0,0,0,0,0,0,11,0,0,0,0,0
0,0,0,0,11,0,0,0,0,21,21,21,0,0,0,7,0,0,0,0
0,0,0,0,19,0,0,12,0,19,19,21,0,0,0,19,0,0,0,0
0,0,0,0,19,0,0,0,0,19,19,21,0,0,0,19,0,0,0,0
0,0,0,0,11,0,0,0,0,0,0,0,0,0,0,8,0,0,0,0
0,0,0,0,0,8,0,0,0,0,0,0,0,0,11,0,0,0,0,0
0,0,0,0,0,0,11,0,0,0,0,0,0,11,0,0,0,0,0,0
0,0,0,0,0,0,0,7,0,0,0,0,8,0,0,0,0,0,0,0
0,0,0,0,0,0,0,0,7,19,19,7,0,0,0,0,0,0,0,0
0,0,0,0,0,0,0,0,0,0,0,0,0,0,0,0,0,0,0,0
0,0,0,0,0,0,0,0,0,0,0,0,0,0,0,0,0,0,0,0
0,0,0,0,0,0,0,0,0,0,0,0,0,0,0,0,0,0,0,0
endlayer

layer
0,0,0,0,0,0,0,0,0,0,0,0,0,0,0,0,0,0,0,0
0,0,0,0,0,0,0,0,0,0,0,0,0,0,0,0,0,0,0,0
0,0,0,0,0,0,0,0,0,0,0,0,0,0,0,0,0,0,0,0
0,0,0,0,0,0,0,0,4,4,4,4,0,0,0,0,0,0,0,0
0,0,0,0,0,0,0,4,24,24,24,24,4,0,0,0,0,0,0,0
0,0,0,0,0,0,4,24,24,24,24,24,24,4,0,0,0,0,0,0
0,0,0,0,0,4,24,24,24,24,24,24,24,24,4,0,0,0,0,0
0,0,0,0,4,24,24,24,24,24,24,24,24,24,24,4,0,0,0,0
0,0,0,4,24,24,24,24,24,24,24,24,24,24,24,24,4,0,0,0
0,0,0,4,24,24,24,24,24,5,24,24,24,24,24,24,4,0,0,0
0,0,0,4,24,24,24,24,24,24,24,24,24,24,24,24,4,0,0,0
0,0,0,4,24,24,24,24,24,24,24,24,24,24,24,24,4,0,0,0
0,0,0,0,4,24,24,24,24,24,24,24,24,24,24,4,0,0,0,0
0,0,0,0,0,4,24,24,24,24,24,24,24,24,4,0,0,0,0,0
0,0,0,0,0,0,4,24,24,24,24,24,24,4,0,0,0,0,0,0
0,0,0,0,0,0,0,4,24,24,24,24,4,0,0,0,0,0,0,0
0,0,0,0,0,0,0,0,4,4,4,4,0,0,0,0,0,0,0,0
0,0,0,0,0,0,0,0,0,0,0,0,0,0,0,0,0,0,0,0
0,0,0,0,0,0,0,0,0,0,0,0,0,0,0,0,0,0,0,0
endlayer

layer
0,0,0,0,0,0,0,0,0,0,0,0,0,0,0,0,0,0,0,0
0,0,0,0,0,0,0,0,0,0,0,0,0,0,0,0,0,0,0,0
0,0,0,0,0,0,0,0,0,0,0,0,0,0,0,0,0,0,0,0
0,0,0,0,0,0,0,0,0,0,0,0,0,0,0,0,0,0,0,0
0,0,0,0,0,0,0,0,25,4,4,25,0,0,0,0,0,0,0,0
0,0,0,0,0,0,0,25,4,4,4,4,4,0,0,0,0,0,0,0
0,0,0,0,0,0,4,4,4,4,4,4,4,25,0,0,0,0,0,0
0,0,0,0,0,4,4,4,4,4,4,4,4,4,4,0,0,0,0,0
0,0,0,0,4,4,4,4,4,4,4,4,4,4,4,4,0,0,0,0
0,0,0,0,25,4,4,26,4,4,4,4,4,4,4,25,0,0,0,0
0,0,0,0,25,4,4,4,4,4,4,4,4,4,4,4,0,0,0,0
0,0,0,0,4,4,4,26,4,4,4,4,4,4,4,4,0,0,0,0
0,0,0,0,0,4,4,4,4,26,4,26,4,4,25,0,0,0,0,0
0,0,0,0,0,0,25,4,4,4,4,4,4,4,0,0,0,0,0,0
0,0,0,0,0,0,0,4,4,4,4,4,4,0,0,0,0,0,0,0
0,0,0,0,0,0,0,0,4,4,25,4,0,0,0,0,0,0,0,0
0,0,0,0,0,0,0,0,0,0,0,0,0,0,0,0,0,0,0,0
0,0,0,0,0,0,0,0,0,0,0,0,0,0,0,0,0,0,0,0
0,0,0,0,0,0,0,0,0,0,0,0,0,0,0,0,0,0,0,0
endlayer

layer
0,0,0,0,0,0,0,0,0,0,0,0,0,0,0,0,0,0,0,0
0,0,0,0,0,0,0,0,0,0,0,0,0,0,0,0,0,0,0,0
0,0,0,0,0,0,0,0,0,0,0,0,0,0,0,0,0,0,0,0
0,0,0,0,0,0,0,0,0,0,0,0,0,0,0,0,0,0,0,0
0,0,0,0,0,0,0,0,0,0,0,0,0,0,0,0,0,0,0,0
0,0,0,0,0,0,0,0,4,4,4,25,0,0,0,0,0,0,0,0
0,0,0,0,0,0,0,25,4,4,4,4,4,0,0,0,0,0,0,0
0,0,0,0,0,0,4,4,4,4,4,4,4,4,0,0,0,0,0,0
0,0,0,0,0,4,4,4,4,4,4,4,4,4,25,0,0,0,0,0
0,0,0,0,0,25,4,4,4,4,4,4,4,4,4,0,0,0,0,0
0,0,0,0,0,4,4,4,4,4,4,4,4,4,4,0,0,0,0,0
0,0,0,0,0,4,4,4,4,4,4,4,4,4,25,0,0,0,0,0
0,0,0,0,0,0,4,4,4,4,4,4,4,4,0,0,0,0,0,0
0,0,0,0,0,0,0,25,4,4,4,4,4,0,0,0,0,0,0,0
0,0,0,0,0,0,0,0,4,4,4,25,0,0,0,0,0,0,0,0
0,0,0,0,0,0,0,0,0,0,0,0,0,0,0,0,0,0,0,0
0,0,0,0,0,0,0,0,0,0,0,0,0,0,0,0,0,0,0,0
0,0,0,0,0,0,0,0,0,0,0,0,0,0,0,0,0,0,0,0
0,0,0,0,0,0,0,0,0,0,0,0,0,0,0,0,0,0,0,0
endlayer

layer
0,0,0,0,0,0,0,0,0,0,0,0,0,0,0,0,0,0,0,0
0,0,0,0,0,0,0,0,0,0,0,0,0,0,0,0,0,0,0,0
0,0,0,0,0,0,0,0,0,0,0,0,0,0,0,0,0,0,0,0
0,0,0,0,0,0,0,0,0,0,0,0,0,0,0,0,0,0,0,0
0,0,0,0,0,0,0,0,0,0,0,0,0,0,0,0,0,0,0,0
0,0,0,0,0,0,0,0,0,0,0,0,0,0,0,0,0,0,0,0
0,0,0,0,0,0,0,0,25,4,4,4,0,0,0,0,0,0,0,0
0,0,0,0,0,0,0,4,4,4,4,4,25,0,0,0,0,0,0,0
0,0,0,0,0,0,25,4,4,4,4,4,4,4,0,0,0,0,0,0
0,0,0,0,0,0,4,4,4,4,4,4,4,4,0,0,0,0,0,0
0,0,0,0,0,0,4,4,4,4,4,4,4,4,0,0,0,0,0,0
0,0,0,0,0,0,4,4,4,4,4,4,4,25,0,0,0,0,0,0
0,0,0,0,0,0,0,25,4,4,4,4,4,0,0,0,0,0,0,0
0,0,0,0,0,0,0,0,4,4,25,4,0,0,0,0,0,0,0,0
0,0,0,0,0,0,0,0,0,0,0,0,0,0,0,0,0,0,0,0
0,0,0,0,0,0,0,0,0,0,0,0,0,0,0,0,0,0,0,0
0,0,0,0,0,0,0,0,0,0,0,0,0,0,0,0,0,0,0,0
0,0,0,0,0,0,0,0,0,0,0,0,0,0,0,0,0,0,0,0
0,0,0,0,0,0,0,0,0,0,0,0,0,0,0,0,0,0,0,0
endlayer

layer
0,0,0,0,0,0,0,0,0,0,0,0,0,0,0,0,0,0,0,0
0,0,0,0,0,0,0,0,0,0,0,0,0,0,0,0,0,0,0,0
0,0,0,0,0,0,0,0,0,0,0,0,0,0,0,0,0,0,0,0
0,0,0,0,0,0,0,0,0,0,0,0,0,0,0,0,0,0,0,0
0,0,0,0,0,0,0,0,0,0,0,0,0,0,0,0,0,0,0,0
0,0,0,0,0,0,0,0,0,0,0,0,0,0,0,0,0,0,0,0
0,0,0,0,0,0,0,0,0,0,0,0,0,0,0,0,0,0,0,0
0,0,0,0,0,0,0,0,4,4,25,4,0,0,0,0,0,0,0,0
0,0,0,0,0,0,0,25,4,4,4,4,25,0,0,0,0,0,0,0
0,0,0,0,0,0,0,4,4,4,4,4,4,0,0,0,0,0,0,0
0,0,0,0,0,0,0,4,4,4,4,4,4,0,0,0,0,0,0,0
0,0,0,0,0,0,0,4,4,4,4,4,25,0,0,0,0,0,0,0
0,0,0,0,0,0,0,0,4,4,25,25,0,0,0,0,0,0,0,0
0,0,0,0,0,0,0,0,0,0,0,0,0,0,0,0,0,0,0,0
0,0,0,0,0,0,0,0,0,0,0,0,0,0,0,0,0,0,0,0
0,0,0,0,0,0,0,0,0,0,0,0,0,0,0,0,0,0,0,0
0,0,0,0,0,0,0,0,0,0,0,0,0,0,0,0,0,0,0,0
0,0,0,0,0,0,0,0,0,0,0,0,0,0,0,0,0,0,0,0
0,0,0,0,0,0,0,0,0,0,0,0,0,0,0,0,0,0,0,0
endlayer

layer
0,0,0,0,0,0,0,0,0,0,0,0,0,0,0,0,0,0,0,0
0,0,0,0,0,0,0,0,0,0,0,0,0,0,0,0,0,0,0,0
0,0,0,0,0,0,0,0,0,0,0,0,0,0,0,0,0,0,0,0
0,0,0,0,0,0,0,0,0,0,0,0,0,0,0,0,0,0,0,0
0,0,0,0,0,0,0,0,0,0,0,0,0,0,0,0,0,0,0,0
0,0,0,0,0,0,0,0,0,0,0,0,0,0,0,0,0,0,0,0
0,0,0,0,0,0,0,0,0,0,0,0,0,0,0,0,0,0,0,0
0,0,0,0,0,0,0,0,0,0,0,0,0,0,0,0,0,0,0,0
0,0,0,0,0,0,0,0,4,4,25,25,0,0,0,0,0,0,0,0
0,0,0,0,0,0,0,0,4,4,4,4,0,0,0,0,0,0,0,0
0,0,0,0,0,0,0,0,25,4,4,4,0,0,0,0,0,0,0,0
0,0,0,0,0,0,0,0,4,4,4,25,0,0,0,0,0,0,0,0
0,0,0,0,0,0,0,0,0,0,0,0,0,0,0,0,0,0,0,0
0,0,0,0,0,0,0,0,0,0,0,0,0,0,0,0,0,0,0,0
0,0,0,0,0,0,0,0,0,0,0,0,0,0,0,0,0,0,0,0
0,0,0,0,0,0,0,0,0,0,0,0,0,0,0,0,0,0,0,0
0,0,0,0,0,0,0,0,0,0,0,0,0,0,0,0,0,0,0,0
0,0,0,0,0,0,0,0,0,0,0,0,0,0,0,0,0,0,0,0
0,0,0,0,0,0,0,0,0,0,0,0,0,0,0,0,0,0,0,0
endlayer

layer
0,0,0,0,0,0,0,0,0,0,0,0,0,0,0,0,0,0,0,0
0,0,0,0,0,0,0,0,0,0,0,0,0,0,0,0,0,0,0,0
0,0,0,0,0,0,0,0,0,0,0,0,0,0,0,0,0,0,0,0
0,0,0,0,0,0,0,0,0,0,0,0,0,0,0,0,0,0,0,0
0,0,0,0,0,0,0,0,0,0,0,0,0,0,0,0,0,0,0,0
0,0,0,0,0,0,0,0,0,0,0,0,0,0,0,0,0,0,0,0
0,0,0,0,0,0,0,0,0,0,0,0,0,0,0,0,0,0,0,0
0,0,0,0,0,0,0,0,0,0,0,0,0,0,0,0,0,0,0,0
0,0,0,0,0,0,0,0,0,0,0,0,0,0,0,0,0,0,0,0
0,0,0,0,0,0,0,0,0,4,25,0,0,0,0,0,0,0,0,0
0,0,0,0,0,0,0,0,0,4,4,0,0,0,0,0,0,0,0,0
0,0,0,0,0,0,0,0,0,0,0,0,0,0,0,0,0,0,0,0
0,0,0,0,0,0,0,0,0,0,0,0,0,0,0,0,0,0,0,0
0,0,0,0,0,0,0,0,0,0,0,0,0,0,0,0,0,0,0,0
0,0,0,0,0,0,0,0,0,0,0,0,0,0,0,0,0,0,0,0
0,0,0,0,0,0,0,0,0,0,0,0,0,0,0,0,0,0,0,0
0,0,0,0,0,0,0,0,0,0,0,0,0,0,0,0,0,0,0,0
0,0,0,0,0,0,0,0,0,0,0,0,0,0,0,0,0,0,0,0
0,0,0,0,0,0,0,0,0,0,0,0,0,0,0,0,0,0,0,0
endlayer

