
# Created by Ruins mod version 14.4 Ingame Parser
# authoring Player: Mikhaila666

weight=1
embed_into_distance=0
acceptable_target_blocks=
unacceptable_target_blocks=flowing_water,water,flowing_lava,lava
dimensions=14,13,14
allowable_overhang=0
max_leveling=2
leveling_buffer=0
preserve_water=0
preserve_lava=0

rule1=0,100,Railcraft:tile.railcraft.residual.heat-0
rule2=0,100,minecraft:stonebrick-3
rule3=0,100,minecraft:stone_brick_stairs-0
rule4=0,100,arsmagica2:liquidEssence-0
rule5=0,100,minecraft:stonebrick-0
rule6=0,100,minecraft:stone_brick_stairs-2
rule7=0,100,minecraft:stonebrick-2
rule8=0,100,minecraft:stone_brick_stairs-3
rule9=0,100,minecraft:stone_brick_stairs-1
rule10=0,100,minecraft:ladder-3
rule11=0,100,arsmagica2:InscriptionTable-12
rule12=0,100,minecraft:wooden_door-3
rule13=0,100,arsmagica2:InscriptionTable-4
rule14=0,100,minecraft:web-0
rule15=0,100,minecraft:glass_pane-0
rule16=0,100,minecraft:stained_glass_pane-15
rule17=0,100,minecraft:wooden_door-8
rule18=0,100,minecraft:wool-14
rule19=0,100,minecraft:tnt-0
rule20=0,100,minecraft:trapped_chest-2
rule21=0,100,minecraft:stonebrick-1
rule22=0,100,minecraft:stone_slab-0
rule23=0,100,minecraft:stone_slab-8
rule24=0,100,MobSpawner:Spider

layer
0,0,0,0,1,1,0,0,0,0,0,0,0,0
1,0,0,0,0,0,0,0,0,0,0,0,0,0
0,0,0,0,0,2,3,3,3,2,0,0,0,0
0,0,0,0,2,2,2,4,2,2,0,0,0,0
0,0,0,2,2,5,5,5,5,5,2,2,0,0
0,0,0,0,3,5,5,7,5,5,2,6,0,0
1,1,1,1,8,5,7,7,5,5,4,6,0,0
0,1,0,0,9,5,5,5,5,5,2,6,0,0
0,1,0,2,2,5,5,5,5,5,2,2,0,0
1,0,1,0,2,2,2,4,2,2,2,0,0,0
0,0,0,0,0,2,9,9,9,2,0,0,0,0
0,0,0,0,1,0,0,0,0,0,0,0,0,0
0,0,0,0,0,0,0,0,0,0,0,0,0,0
endlayer

layer
0,0,0,1,1,1,0,1,0,0,1,0,0,0
0,0,0,1,1,0,0,1,1,0,1,1,0,0
0,1,0,1,0,2,0,0,0,2,0,0,1,0
0,1,0,0,2,2,2,0,2,2,0,0,1,0
0,1,1,2,2,5,5,5,5,5,2,2,1,0
0,0,0,0,0,5,1,1,10,5,2,0,0,0
0,0,0,0,1,12,1,0,11,5,0,0,1,1
0,0,0,0,0,5,14,0,13,5,2,0,0,1
1,1,1,2,2,5,5,5,5,5,2,2,0,1
0,1,0,0,2,2,2,0,2,2,2,0,1,1
0,0,0,0,0,2,0,0,0,2,0,0,0,0
1,0,0,1,1,0,1,0,1,1,0,1,0,0
0,0,0,1,0,0,0,1,1,1,0,1,0,0
endlayer

layer
0,0,0,0,0,0,0,0,0,0,1,0,0,0
0,0,0,0,0,0,0,1,0,0,0,0,0,0
0,0,0,0,0,0,0,0,0,0,0,0,0,0
0,0,0,0,0,2,0,0,0,2,0,0,0,0
0,0,0,0,2,5,7,15,5,5,2,0,0,0
0,0,0,0,0,5,0,1,10,5,0,0,0,0
0,0,0,0,0,17,0,1,0,16,0,1,0,0
0,0,0,0,0,7,0,0,0,7,0,0,0,1
1,0,0,0,2,5,5,15,5,5,2,0,0,0
0,0,0,0,0,2,0,0,0,2,0,0,0,0
0,0,0,0,0,0,0,1,0,0,0,0,1,0
0,0,0,0,0,0,0,0,0,0,0,0,0,0
0,0,0,0,0,0,0,1,0,0,0,0,0,0
endlayer

layer
0,0,0,0,0,0,0,0,0,0,0,0,0,0
0,0,0,0,0,0,0,0,0,0,0,0,0,0
0,0,0,0,0,0,0,0,0,0,0,0,0,0
0,0,0,0,0,0,0,0,0,0,0,0,0,0
0,0,0,0,0,2,7,0,5,2,0,0,0,0
0,0,0,0,0,7,0,0,10,5,0,0,0,0
0,0,0,0,0,5,0,1,0,15,0,0,0,0
0,0,0,0,0,5,0,0,0,7,0,0,0,0
0,0,0,0,0,2,7,1,5,2,0,0,0,0
0,0,0,0,0,0,0,0,0,0,0,0,0,0
0,0,0,0,0,0,0,0,0,0,0,0,0,0
0,0,0,0,0,0,0,0,0,0,0,0,0,0
0,0,0,0,0,0,0,0,0,0,0,0,0,0
endlayer

layer
0,0,0,0,0,0,0,0,0,0,0,0,0,0
0,0,0,0,0,0,0,0,0,0,0,0,0,0
0,0,0,0,0,0,0,0,0,0,0,0,0,0
0,0,0,0,0,0,0,0,0,0,0,0,0,0
0,0,0,0,0,0,5,15,5,0,0,0,0,0
0,0,0,0,0,7,0,0,10,5,0,0,0,0
0,0,0,0,0,5,0,0,0,15,0,0,1,0
0,0,0,0,0,5,0,0,0,5,0,0,0,0
0,0,0,0,0,0,7,0,5,0,0,0,0,0
0,0,0,0,0,0,0,0,0,0,0,0,0,0
0,0,0,0,0,0,0,0,0,0,0,0,0,0
0,0,0,0,0,0,0,0,0,0,0,0,0,0
0,0,0,0,0,0,0,0,0,0,0,0,0,0
endlayer

layer
0,0,0,0,0,0,0,0,0,0,0,0,0,0
0,0,0,0,0,0,0,0,0,0,0,0,0,0
0,0,0,0,0,0,0,0,0,0,0,0,0,0
0,0,0,0,0,0,0,0,0,0,0,0,0,0
0,0,0,0,0,0,5,5,5,0,0,0,0,0
0,0,0,0,0,5,0,1,10,5,0,0,0,0
0,0,0,0,0,7,0,0,0,5,0,0,0,0
0,0,0,0,0,5,0,0,0,5,0,0,0,0
0,0,0,0,0,0,7,5,5,0,0,0,0,0
0,0,0,0,0,0,0,0,0,0,0,0,0,0
0,0,0,0,0,0,0,0,0,0,0,0,0,0
0,0,0,0,0,0,0,0,0,0,0,0,0,0
0,0,0,0,0,0,0,1,0,0,0,0,0,0
endlayer

layer
0,0,0,0,0,0,0,0,0,0,0,0,0,0
0,0,0,0,0,0,0,0,0,0,0,0,0,0
0,0,0,0,0,0,0,0,0,0,0,0,0,0
0,0,0,0,0,0,0,0,0,0,0,0,0,0
0,0,0,0,0,5,5,5,5,5,0,0,0,0
0,0,0,0,0,5,5,5,10,5,0,0,0,0
0,0,0,0,0,5,7,7,5,5,0,0,0,0
0,0,0,0,0,5,7,7,7,5,0,0,0,0
0,0,0,0,0,5,5,5,5,5,0,0,0,0
0,0,0,0,0,0,0,0,0,0,0,0,0,0
0,0,0,0,0,0,0,0,0,0,0,0,0,0
0,0,0,0,0,0,0,0,0,0,0,0,0,0
0,0,0,0,0,0,0,0,0,0,0,0,0,0
endlayer

layer
0,0,0,0,0,0,0,0,0,0,0,0,0,0
0,0,0,0,0,0,0,0,0,0,0,0,0,0
0,0,0,0,0,0,0,0,0,0,0,0,0,0
0,0,0,0,0,5,5,5,5,5,0,0,0,0
0,0,0,0,5,5,0,0,0,0,5,0,0,0
0,0,0,0,5,18,6,0,1,0,7,0,0,0
0,0,0,0,5,19,6,1,1,0,5,0,0,0
0,0,0,0,5,18,6,0,1,0,5,0,0,0
0,0,0,0,5,5,0,0,0,0,5,0,0,0
0,0,0,0,0,5,5,5,5,5,0,0,0,0
0,0,0,0,0,0,0,0,0,0,0,0,0,0
0,0,0,0,0,0,0,0,0,0,0,0,0,0
0,0,0,0,0,0,0,0,0,0,0,0,0,0
endlayer

layer
0,0,0,0,0,0,0,0,0,0,0,0,0,0
0,0,0,0,0,0,0,0,0,0,0,0,0,0
0,0,0,0,0,0,0,0,0,0,0,0,0,0
0,0,0,0,0,5,5,5,5,5,0,0,0,0
0,0,0,0,5,0,0,0,0,0,5,0,0,0
0,0,0,0,5,0,0,0,1,0,7,0,0,0
0,0,1,0,5,20,0,0,1,0,5,0,0,0
0,0,0,0,5,0,0,0,0,0,5,0,0,0
0,0,0,0,5,0,0,0,0,0,5,0,0,0
0,0,0,0,0,5,5,5,5,5,0,0,0,0
0,0,0,0,0,0,0,0,0,0,0,0,0,0
0,0,0,0,0,0,0,0,0,0,0,0,0,0
0,0,0,0,0,0,0,0,0,0,0,0,0,0
endlayer

layer
0,0,0,0,0,0,0,1,0,0,0,0,0,0
0,0,0,0,0,0,0,0,0,0,0,0,0,0
0,0,1,0,0,0,0,0,0,0,0,0,0,0
0,0,0,0,0,5,15,16,15,5,0,0,0,0
0,0,0,0,5,0,0,0,0,0,5,0,0,0
0,1,0,0,16,0,0,0,0,0,15,0,0,0
0,0,0,0,15,0,0,0,0,0,16,0,0,0
0,0,0,0,15,0,0,0,0,0,15,0,0,0
0,0,0,0,5,0,0,0,0,0,5,0,0,0
0,0,1,0,0,5,15,15,15,5,0,0,0,0
0,0,0,0,0,0,0,0,0,0,0,0,0,0
0,0,0,0,0,1,0,0,0,0,0,1,0,0
0,0,0,0,0,0,1,0,0,0,0,0,0,0
endlayer

layer
0,0,0,0,1,0,0,0,0,0,0,0,0,0
0,0,0,0,0,0,0,0,0,0,0,0,0,0
0,0,0,0,0,0,0,0,0,0,0,0,0,0
0,0,0,0,2,5,15,15,16,5,2,0,0,0
0,0,0,0,5,0,0,0,0,0,5,0,0,0
0,0,0,0,15,0,0,0,0,0,15,0,0,0
0,0,0,0,15,0,0,0,0,0,15,0,0,0
0,0,0,0,15,0,0,0,0,0,15,0,0,0
0,0,0,0,21,0,0,0,0,0,7,0,0,0
0,0,0,0,2,5,15,15,16,5,2,0,0,0
0,0,0,0,0,0,0,0,0,0,0,0,0,1
0,0,0,0,0,0,0,0,0,0,0,1,0,0
0,0,0,0,0,0,0,0,0,0,0,0,0,0
endlayer

layer
0,0,0,0,1,0,0,0,0,0,0,0,0,0
0,0,0,0,0,0,0,0,0,0,0,0,0,0
0,0,0,0,0,0,0,0,0,0,0,0,0,1
0,0,0,0,2,5,5,7,7,5,2,0,0,0
0,0,0,0,7,0,0,0,0,0,5,0,0,0
0,0,0,0,5,0,0,0,0,0,5,0,0,0
0,0,0,0,5,0,0,0,0,0,5,0,0,0
0,0,0,0,5,0,0,0,0,0,5,0,0,0
0,0,0,0,21,0,0,0,0,0,7,0,0,0
0,0,0,0,2,5,5,5,5,5,2,0,0,0
0,0,0,0,0,0,0,0,0,0,0,0,0,0
0,0,0,0,0,1,0,0,0,0,0,1,0,0
0,0,0,0,0,0,1,0,0,0,0,0,0,0
endlayer

layer
0,0,0,0,0,0,0,0,0,0,0,0,0,0
0,0,0,0,0,0,0,0,0,0,0,0,0,0
0,0,0,0,0,0,0,0,0,0,0,0,0,0
0,0,0,0,2,0,0,0,0,0,2,0,0,0
0,0,0,0,0,22,22,22,22,22,0,0,0,0
0,0,0,0,0,22,23,23,23,22,0,0,0,0
0,0,0,0,0,22,23,24,23,22,0,0,0,0
0,0,0,0,0,22,23,23,23,22,0,0,0,0
0,0,0,0,0,22,22,22,22,22,0,0,0,0
0,0,0,0,2,0,0,0,0,0,2,0,0,0
0,0,0,0,0,0,0,0,0,0,0,0,0,0
0,0,0,0,0,0,0,0,0,0,0,0,0,0
0,0,0,0,0,0,0,0,0,0,0,0,0,0
endlayer

layer
0,0,0,0,0,0,0,0,0,0,0,0,0,0
0,0,0,0,0,0,0,0,0,0,0,0,0,0
0,0,0,0,0,0,0,0,0,0,0,0,0,0
0,0,0,0,0,0,0,0,0,0,0,0,0,0
0,0,0,0,0,0,0,0,0,0,0,0,0,0
0,0,0,0,0,0,0,0,0,0,0,0,0,0
0,0,0,0,0,0,0,22,0,0,0,0,0,0
0,0,0,0,0,0,0,0,0,0,0,0,0,0
0,0,0,0,0,0,0,0,0,0,0,0,0,0
0,0,0,0,0,0,0,0,0,0,0,0,0,0
0,0,0,0,0,0,0,0,0,0,0,0,0,0
0,0,0,0,0,0,0,0,0,0,0,0,0,0
0,0,0,0,0,0,0,0,0,0,0,0,0,0
endlayer

