
# Created by Ruins mod version 14.4 Ingame Parser
# authoring Player: Mikhaila666

weight=1
embed_into_distance=0
acceptable_target_blocks=
unacceptable_target_blocks=flowing_water,water,flowing_lava,lava
dimensions=16,14,18
allowable_overhang=0
max_leveling=2
leveling_buffer=0
preserve_water=0
preserve_lava=0

rule1=0,100,Railcraft:tile.railcraft.residual.heat-0
rule2=0,100,minecraft:oak_stairs-2
rule3=0,100,minecraft:oak_stairs-0
rule4=0,100,minecraft:oak_stairs-3
rule5=0,100,minecraft:stonebrick-0
rule6=0,100,minecraft:stone-0
rule7=0,100,minecraft:redstone_wire-0
rule8=0,100,minecraft:monster_egg-0
rule9=0,100,MobSpawner:Zombie
rule10=0,100,minecraft:oak_stairs-1
rule11=0,100,minecraft:wooden_door-0
rule12=0,100,minecraft:ladder-5
rule13=0,100,minecraft:bookshelf-0
rule14=0,100,minecraft:tripwire-0
rule15=0,100,minecraft:tripwire-1
rule16=0,100,arsmagica2:InscriptionTable-11
rule17=0,100,arsmagica2:InscriptionTable-3
rule18=0,100,minecraft:ladder-4
rule19=0,100,minecraft:web-0
rule20=0,100,IInventory;minecraft:chest;HardcoreEnderExpansion:temple_caller#1#0#0+Forestry:beeDroneGE#1#0#4+minecraft:bread#1#0#10+TConstruct:broadsword#1#0#15+minecraft:wheat#2#0#20-4
rule21=0,100,minecraft:glass_pane-0
rule22=0,100,minecraft:wooden_door-8
rule23=2,100,minecraft:torch-4
rule24=0,100,IInventory;minecraft:dispenser;minecraft:arrow#63#0#0-3
rule25=0,100,IInventory;minecraft:dispenser;minecraft:arrow#63#0#0+minecraft:arrow#1#0#1-3
rule26=2,100,minecraft:torch-2
rule27=2,100,minecraft:torch-1
rule28=0,100,minecraft:planks-0
rule29=0,100,minecraft:log-0
rule30=0,100,IInventory;minecraft:chest;minecraft:record_cat#1#0#4+minecraft:string#4#0#7+minecraft:name_tag#1#0#9+harvestcraft:deluxecheeseburgerItem#1#0#17+minecraft:iron_horse_armor#1#0#25-2
rule31=0,100,IInventory;minecraft:chest;HardcoreEnderExpansion:knowledge_note#1#0#0+harvestcraft:deluxecheeseburgerItem#0#0#4+minecraft:name_tag#1#0#18+harvestcraft:baconmushroomburgerItem#0#0#20-2
rule32=0,100,minecraft:wooden_slab-8
rule33=0,100,minecraft:wooden_slab-0

layer
0,1,0,0,1,0,0,0,0,0,0,0,0,0,0,0,0,0
0,0,0,4,3,2,0,0,0,0,0,0,0,0,0,0,0,0
0,5,5,6,6,6,5,5,0,0,0,0,0,0,0,0,0,0
0,5,6,6,6,6,6,5,5,5,5,5,5,5,5,5,5,0
0,6,6,6,6,6,6,6,7,7,7,7,7,7,7,7,5,0
0,6,6,6,6,6,6,6,6,6,6,6,6,6,6,5,5,0
0,5,6,6,6,6,6,6,6,6,6,6,6,6,6,5,5,0
0,5,6,6,6,6,6,6,6,6,6,6,6,6,6,5,5,0
0,6,6,6,6,6,6,6,6,6,6,5,6,6,6,5,5,0
0,6,6,6,6,6,6,6,7,7,7,7,7,7,7,7,5,0
0,5,9,8,6,6,6,5,5,5,5,5,5,5,5,5,5,0
0,5,5,6,6,6,5,5,0,0,0,0,0,0,0,0,0,0
0,0,0,4,10,2,0,0,0,0,0,0,0,0,0,0,0,0
0,0,1,0,0,0,0,0,0,0,0,0,0,0,0,0,0,0
endlayer

layer
0,0,0,0,0,0,0,0,0,0,0,0,0,0,0,0,0,0
0,0,0,0,1,0,0,0,0,0,0,0,0,0,0,0,0,0
0,5,6,6,11,6,6,5,0,0,0,0,0,0,0,0,0,0
0,6,0,1,1,0,0,6,5,5,5,5,5,5,5,5,5,0
0,6,0,0,1,0,0,8,9,6,5,5,6,6,6,0,5,0
0,6,0,0,1,1,0,13,0,6,6,6,1,12,6,7,5,0
0,6,0,0,1,1,0,13,14,1,0,0,1,0,0,5,6,0
0,6,17,16,1,1,0,13,15,1,0,1,1,0,0,5,6,0
0,6,0,1,1,1,1,13,0,6,6,6,0,18,6,7,5,0
0,6,0,0,1,0,1,8,9,6,5,5,6,6,6,0,5,0
0,6,20,0,0,0,19,6,5,5,5,5,5,5,5,5,5,0
0,5,6,6,0,6,6,5,0,0,0,0,0,0,0,0,0,0
0,0,0,0,0,0,0,0,0,0,0,0,0,0,0,0,0,0
0,0,0,0,0,0,0,0,0,0,0,0,0,0,0,0,0,0
endlayer

layer
0,0,0,0,0,0,0,0,0,0,0,0,0,0,0,0,0,0
0,0,0,0,0,0,0,0,0,0,0,0,0,0,0,0,0,0
0,6,21,6,22,6,21,6,0,0,0,0,0,0,0,0,0,0
1,6,0,0,0,0,0,6,0,0,0,0,0,0,0,0,0,0
0,6,23,0,0,0,0,6,6,6,5,5,6,6,6,5,0,0
0,21,0,0,0,0,0,13,0,6,6,6,0,12,0,6,0,0
0,21,0,0,0,0,0,13,0,0,0,0,0,0,0,24,6,0
0,21,0,0,0,0,0,13,1,0,0,0,0,0,0,25,6,0
0,21,0,0,0,0,0,13,26,6,6,6,0,18,0,6,0,0
0,6,0,0,0,0,0,6,6,6,5,5,6,6,6,5,0,0
0,6,0,0,0,0,0,6,0,0,0,0,0,0,0,0,0,0
0,6,21,6,0,6,21,6,0,0,0,0,0,0,0,0,0,0
0,0,0,0,0,0,0,0,0,0,0,0,0,0,0,0,0,0
0,0,0,0,0,0,0,0,0,0,0,0,0,0,0,0,0,0
endlayer

layer
0,0,0,0,0,0,0,0,0,0,0,0,0,0,0,0,0,0
0,0,0,0,0,0,0,0,0,0,0,0,0,0,0,0,0,0
0,5,21,6,6,6,21,6,0,0,0,0,0,0,0,0,0,0
0,6,19,0,0,0,19,6,0,0,0,0,0,0,0,0,0,0
0,6,0,0,0,0,0,6,6,6,5,5,6,6,6,0,0,0
0,21,0,0,0,0,0,13,0,6,6,6,0,12,0,6,0,0
0,21,0,0,0,0,0,13,0,0,0,0,0,0,0,0,6,0
0,21,0,0,0,0,0,13,0,0,0,0,0,0,0,0,6,0
0,21,0,0,0,0,0,13,0,6,6,6,1,18,0,6,0,0
0,6,0,0,0,0,0,6,6,6,5,5,6,6,6,0,0,0
0,6,0,0,0,0,0,6,0,0,0,0,0,0,0,0,0,0
0,5,21,6,6,6,21,6,0,0,0,0,0,0,0,0,0,0
0,0,0,0,0,0,0,0,0,0,0,0,0,0,0,0,0,0
0,0,0,0,0,0,0,0,0,0,0,0,0,0,0,0,0,0
endlayer

layer
0,0,0,0,0,0,0,0,0,0,0,0,0,0,0,0,0,0
0,0,0,0,0,0,0,0,0,0,0,0,0,0,0,0,0,0
0,5,5,6,6,6,5,5,0,0,0,0,0,0,0,0,0,0
0,5,6,6,6,6,6,5,0,0,0,0,0,0,0,0,0,0
0,6,6,6,6,6,6,6,6,5,5,5,6,6,6,0,0,0
0,6,6,6,6,6,6,6,6,6,6,6,0,12,1,6,0,0
0,6,6,6,6,6,6,6,6,6,6,0,0,0,0,0,6,0
0,6,6,6,6,6,6,6,6,6,6,0,0,0,0,0,6,0
0,6,6,6,6,6,6,6,6,6,6,6,0,18,0,6,0,0
0,6,6,6,6,6,6,6,6,5,5,5,6,6,6,0,0,0
0,5,6,6,6,6,6,5,0,0,0,0,0,0,0,0,0,0
0,5,5,6,6,6,5,5,0,0,0,0,0,0,0,0,0,0
0,0,0,0,0,0,0,0,0,0,0,0,0,0,0,0,0,0
0,0,0,0,0,0,0,0,0,0,0,0,0,0,0,0,0,0
endlayer

layer
0,0,0,0,0,0,0,0,0,0,0,0,0,0,0,0,0,0
0,0,0,0,0,0,0,0,0,0,0,0,0,0,0,0,0,0
0,0,0,0,0,0,0,0,0,0,0,0,0,0,0,0,0,0
0,0,0,0,0,0,0,0,0,0,0,0,0,0,0,0,0,0
0,0,0,0,0,0,0,0,0,0,0,0,6,6,6,0,0,0
0,0,0,0,0,0,0,0,0,0,0,6,27,12,27,6,0,0
0,0,0,0,0,0,0,0,0,0,6,0,0,0,0,0,6,0
0,0,0,0,0,0,0,0,0,0,6,0,0,0,0,0,6,0
0,0,0,0,0,0,0,0,0,0,0,6,26,18,0,6,0,0
0,0,0,0,0,0,0,0,0,0,0,0,6,6,6,0,0,0
0,0,0,0,0,0,0,0,0,0,0,0,0,0,0,0,0,0
0,0,0,0,0,0,0,0,0,0,0,0,0,0,0,0,0,0
0,0,0,0,0,0,0,0,0,0,0,0,0,0,0,0,0,0
0,0,0,0,0,0,0,0,0,0,0,0,0,0,0,0,0,0
endlayer

layer
0,0,0,0,0,0,0,0,0,0,0,0,0,0,0,0,0,0
0,0,0,0,0,0,0,0,0,0,0,0,0,0,0,0,0,0
0,0,0,0,0,0,0,0,0,0,0,0,0,0,0,0,0,0
0,0,0,0,0,0,0,0,0,0,0,0,0,0,0,0,0,0
0,0,0,0,0,0,0,0,0,0,0,0,5,5,5,0,0,0
0,0,0,0,0,0,0,0,0,0,0,5,0,12,0,5,0,0
0,0,0,0,0,0,0,0,0,0,5,0,0,0,0,0,5,0
0,0,0,0,0,0,0,0,0,0,5,0,0,1,0,0,5,0
0,0,0,0,0,0,0,0,0,0,0,5,0,18,0,5,0,0
0,0,0,0,0,0,0,0,0,0,0,0,5,5,5,0,0,0
0,0,0,0,0,0,0,0,0,0,0,0,0,0,0,0,0,0
0,0,0,0,0,0,0,0,0,0,0,0,0,0,0,0,0,0
0,0,0,0,0,0,0,0,0,0,0,0,0,0,0,0,0,0
0,0,0,0,0,0,0,0,0,0,0,0,0,0,0,0,0,0
endlayer

layer
0,0,0,0,0,0,0,0,0,0,0,0,0,0,0,0,0,0
0,0,0,0,0,0,0,0,0,0,0,0,0,0,0,0,0,0
0,0,0,0,0,0,0,0,0,0,0,0,0,0,0,0,0,0
0,0,0,0,0,0,0,0,0,0,0,0,0,0,0,0,0,0
0,0,0,0,0,0,0,0,0,0,0,0,6,6,6,0,0,0
0,0,0,0,0,0,0,0,0,0,0,6,0,12,0,6,0,0
0,0,0,0,0,0,0,0,0,0,6,0,0,0,0,0,6,0
0,0,0,0,0,0,0,0,0,0,6,0,0,0,0,0,6,0
0,0,0,0,0,0,0,0,0,0,0,6,1,18,0,6,0,0
0,0,0,0,0,0,0,0,0,0,0,0,6,6,6,0,0,0
0,0,0,0,0,0,0,0,0,0,0,0,0,0,0,0,0,0
0,0,0,0,0,0,0,0,0,0,0,0,0,0,0,0,0,0
0,0,0,0,0,0,0,0,0,0,0,0,0,0,0,0,0,0
0,0,0,0,0,0,0,0,0,0,0,0,0,0,0,0,0,0
endlayer

layer
0,0,0,0,0,0,0,0,0,0,0,0,0,0,0,0,0,0
0,0,0,0,0,0,0,0,0,0,0,0,0,0,0,0,0,0
0,0,0,0,0,0,0,0,0,0,0,0,0,0,0,0,0,0
0,0,0,0,0,0,0,0,0,0,0,0,0,0,0,0,0,0
0,0,0,0,0,0,0,0,0,0,0,0,6,6,6,0,0,0
0,0,0,0,0,0,0,0,0,0,0,6,1,12,0,6,0,0
0,0,0,0,0,0,0,0,0,0,6,0,0,0,0,0,6,0
0,0,0,0,0,0,0,0,0,0,6,0,0,0,0,0,6,0
0,0,0,0,0,0,0,0,0,0,0,6,0,18,0,6,0,0
0,0,0,0,0,0,0,0,0,0,0,0,6,6,6,0,0,0
0,0,0,0,0,0,0,0,0,0,0,0,0,0,0,0,0,0
0,0,0,0,0,0,0,0,0,0,0,0,0,0,0,0,0,0
0,0,0,0,0,0,0,0,0,0,0,0,0,0,0,0,0,0
0,0,0,0,0,0,0,0,0,0,0,0,0,0,0,0,0,0
endlayer

layer
0,0,0,0,0,0,0,0,0,0,0,0,0,0,0,0,0,0
0,0,0,0,0,0,0,0,0,0,0,0,0,0,0,0,0,0
0,0,0,0,0,0,0,0,0,0,0,0,0,0,0,0,0,0
0,0,0,0,0,0,0,0,0,0,0,0,0,0,0,0,0,0
0,0,0,0,0,0,0,0,0,0,0,0,6,6,6,0,0,0
0,0,0,0,0,0,0,0,0,0,0,6,6,12,6,6,0,0
0,0,0,0,0,0,0,0,0,0,6,6,6,6,6,6,6,0
0,0,0,0,0,0,0,0,0,0,6,6,6,6,6,6,6,0
0,0,0,0,0,0,0,0,0,0,0,6,6,18,6,6,0,0
0,0,0,0,0,0,0,0,0,0,0,0,6,6,6,0,0,0
0,0,0,0,0,0,0,0,0,0,0,0,0,0,0,0,0,0
0,0,0,0,0,0,0,0,0,0,0,0,0,0,0,0,0,0
0,0,0,0,0,0,0,0,0,0,0,0,0,0,0,0,0,0
0,0,0,0,0,0,0,0,0,0,0,0,0,0,0,0,0,0
endlayer

layer
0,0,0,0,0,0,0,0,0,0,0,0,0,0,0,0,0,0
0,0,0,0,0,0,0,0,0,0,0,0,0,0,0,0,0,0
0,0,0,0,0,0,0,0,0,0,0,0,0,0,0,0,0,0
0,0,0,0,0,0,0,0,0,0,0,0,0,0,0,0,0,0
0,0,0,0,0,0,0,0,0,0,0,0,28,28,28,0,0,0
0,0,0,0,0,0,0,0,0,0,0,29,1,12,0,29,0,0
0,0,0,0,0,0,0,0,0,0,28,30,0,1,0,9,28,0
0,0,0,0,0,0,0,0,0,0,28,31,0,1,0,0,28,0
0,0,0,0,0,0,0,0,0,0,0,29,0,18,0,29,0,0
0,0,0,0,0,0,0,0,0,0,0,0,28,28,28,0,0,0
0,0,0,0,0,0,0,0,0,0,0,0,0,0,0,0,0,0
0,0,0,0,0,0,0,0,0,0,0,0,0,0,0,0,0,0
0,0,0,0,0,0,0,0,0,0,0,0,0,0,0,0,0,0
0,0,0,0,0,0,0,0,0,0,0,0,0,0,0,0,0,0
endlayer

layer
0,0,0,0,0,0,0,0,0,0,0,0,0,0,0,0,0,0
0,0,0,0,0,0,0,0,0,0,0,0,0,0,0,0,0,0
0,0,0,0,0,0,0,0,0,0,0,0,0,0,0,0,0,0
0,0,0,0,0,0,0,0,0,0,0,0,0,0,0,0,0,0
0,0,0,0,0,0,0,0,0,0,0,0,28,21,28,0,0,0
0,0,0,0,0,0,0,0,0,0,0,29,0,0,0,29,0,0
0,0,0,0,0,0,0,0,0,0,28,0,0,0,0,0,28,0
0,0,0,0,0,0,0,0,0,0,28,0,0,0,0,0,28,0
0,0,0,0,0,0,0,0,0,0,0,29,0,0,1,29,0,0
0,0,0,0,0,0,0,0,0,0,0,0,28,21,28,0,0,0
0,0,0,0,0,0,0,0,0,0,0,0,0,0,0,0,0,0
0,0,0,0,0,0,0,0,0,0,0,0,0,0,0,0,0,0
0,0,0,0,0,0,0,0,0,0,0,0,0,0,0,0,0,0
0,0,0,0,0,0,0,0,0,0,0,0,0,0,0,0,0,0
endlayer

layer
0,0,0,0,0,0,0,0,0,0,0,0,0,0,0,0,0,0
0,0,0,0,0,0,0,0,0,0,0,0,0,0,0,0,0,0
0,0,0,0,0,0,0,0,0,0,0,0,0,0,0,0,0,0
0,0,0,0,0,0,0,0,0,0,0,0,32,32,32,0,0,0
0,0,0,0,0,0,0,0,0,0,0,32,28,28,28,32,0,0
0,0,0,0,0,0,0,0,0,0,32,29,0,0,0,29,32,0
0,0,0,0,0,0,0,0,0,32,28,0,0,1,0,0,28,0
0,0,0,0,0,0,0,0,0,32,28,0,0,0,0,0,28,0
0,0,0,0,0,0,0,0,0,0,32,29,0,0,0,29,32,0
0,0,0,0,0,0,0,0,0,0,0,32,28,28,28,32,0,0
0,0,0,0,0,0,0,0,0,0,0,0,32,32,32,0,0,0
0,0,0,0,0,0,0,0,0,0,0,0,0,0,0,0,0,0
0,0,0,0,0,0,0,0,0,0,0,0,0,0,0,0,0,0
0,0,0,0,0,0,0,0,0,0,0,0,0,0,0,0,0,0
endlayer

layer
0,0,0,0,0,0,0,0,0,0,0,0,0,0,0,0,0,0
0,0,0,0,0,0,0,0,0,0,0,0,0,0,0,0,0,0
0,0,0,0,0,0,0,0,0,0,0,0,0,0,0,0,0,0
0,0,0,0,0,0,0,0,0,0,0,0,0,0,0,0,0,0
0,0,0,0,0,0,0,0,0,0,0,0,0,0,0,0,0,0
0,0,0,0,0,0,0,0,0,0,0,33,33,33,33,33,0,0
0,0,0,0,0,0,0,0,0,0,0,33,32,0,32,33,0,0
0,0,0,0,0,0,0,0,0,0,0,33,32,32,32,33,0,0
0,0,0,0,0,0,0,0,0,0,0,33,33,33,33,0,0,0
0,0,0,0,0,0,0,0,0,0,0,0,0,0,0,0,0,0
0,0,0,0,0,0,0,0,0,0,0,0,0,0,0,0,0,0
0,0,0,0,0,0,0,0,0,0,0,0,0,0,0,0,0,0
0,0,0,0,0,0,0,0,0,0,0,0,0,0,0,0,0,0
0,0,0,0,0,0,0,0,0,0,0,0,0,0,0,0,0,0
endlayer

layer
0,0,0,0,0,0,0,0,0,0,0,0,0,0,0,0,0,0
0,0,0,0,0,0,0,0,0,0,0,0,0,0,0,0,0,0
0,0,0,0,0,0,0,0,0,0,0,0,0,0,0,0,0,0
0,0,0,0,0,0,0,0,0,0,0,0,0,0,0,0,0,0
0,0,0,0,0,0,0,0,0,0,0,0,0,0,0,0,0,0
0,0,0,0,0,0,0,0,0,0,0,0,0,0,0,0,0,0
0,0,0,0,0,0,0,0,0,0,0,0,0,0,0,0,0,0
0,0,0,0,0,0,0,0,0,0,0,0,0,0,0,0,0,0
0,0,0,0,0,0,0,0,0,0,0,0,0,0,0,0,0,0
0,0,0,0,0,0,0,0,0,0,0,0,0,0,0,0,0,0
0,0,0,0,0,0,0,0,0,0,0,0,0,0,0,0,0,0
0,0,0,0,0,0,0,0,0,0,0,0,0,0,0,0,0,0
0,0,0,0,0,0,0,0,0,0,0,0,0,0,0,0,0,0
0,0,0,0,0,0,0,0,0,0,0,0,0,0,0,0,0,0
endlayer

layer
0,0,0,0,0,0,0,0,0,0,0,0,0,0,0,0,0,0
0,0,0,0,0,0,0,0,0,0,0,0,0,0,0,1,0,0
0,0,0,0,0,0,0,0,0,0,0,0,0,0,0,0,0,0
0,0,0,0,0,0,0,0,0,0,0,0,0,0,0,0,0,0
0,0,0,0,0,0,0,0,0,0,0,0,0,0,0,0,0,0
0,0,0,0,0,0,0,0,0,0,0,0,0,0,0,0,0,0
0,0,0,0,0,0,0,0,0,0,0,0,0,0,0,0,0,0
0,0,0,0,0,0,0,0,0,0,0,0,0,0,0,0,0,0
0,0,0,0,0,0,0,0,0,0,0,0,0,0,0,0,0,0
0,0,0,0,0,0,0,0,0,0,0,0,0,0,0,0,0,0
0,0,0,0,0,0,0,0,0,0,0,0,0,0,0,0,0,0
0,0,0,0,0,0,0,0,0,0,0,0,0,0,0,0,0,0
0,0,0,0,0,0,0,0,0,0,0,0,0,0,0,0,0,0
0,0,0,0,0,0,0,0,0,0,0,0,0,0,0,0,0,0
endlayer

