
# Created by Ruins mod version 14.4 Ingame Parser
# authoring Player: Mikhaila666

weight=1
embed_into_distance=0
acceptable_target_blocks=
unacceptable_target_blocks=flowing_water,water,flowing_lava,lava
dimensions=14,26,29
allowable_overhang=0
max_leveling=2
leveling_buffer=0
preserve_water=0
preserve_lava=0

rule1=0,100,Railcraft:tile.railcraft.residual.heat-0
rule2=0,100,minecraft:vine-1
rule3=0,100,minecraft:mossy_cobblestone-0
rule4=0,100,minecraft:vine-8
rule5=0,100,minecraft:vine-4
rule6=0,100,minecraft:soul_sand-0
rule7=0,100,minecraft:vine-12
rule8=0,100,minecraft:sandstone-0
rule9=0,100,minecraft:netherrack-0
rule10=0,100,minecraft:vine-6
rule11=0,100,minecraft:vine-2
rule12=0,100,minecraft:vine-3
rule13=0,100,minecraft:stonebrick-0
rule14=0,100,minecraft:red_mushroom-0
rule15=0,100,minecraft:nether_wart-3
rule16=0,100,minecraft:nether_wart-1
rule17=0,100,MobSpawner:Skeleton
rule18=0,100,minecraft:log-3
rule19=0,100,minecraft:stonebrick-1
rule20=0,100,minecraft:vine-9
rule21=0,100,minecraft:nether_wart-2
rule22=0,100,minecraft:nether_brick_fence-0
rule23=0,100,minecraft:iron_bars-0
rule24=0,100,minecraft:bedrock-0
rule25=0,100,minecraft:nether_wart-0
rule26=0,100,minecraft:nether_brick-0
rule27=0,100,minecraft:iron_door-0
rule28=0,100,IInventory;minecraft:chest;minecraft:name_tag#1#0#1+harvestcraft:supremepizzaItem#0#0#6+harvestcraft:curryItem#2#0#7+HardcoreEnderExpansion:knowledge_note#1#0#11+harvestcraft:deluxecheeseburgerItem#2#0#21+minecraft:bucket#1#0#22+harvestcraft:baconmushroomburgerItem#0#0#26-5
rule29=0,100,IInventory;minecraft:chest;minecraft:name_tag#1#0#2+harvestcraft:baconmushroomburgerItem#0#0#6+minecraft:wheat#4#0#9+harvestcraft:heartybreakfastItem#1#0#10+minecraft:record_13#1#0#14+minecraft:redstone#3#0#18+minecraft:iron_horse_armor#1#0#21+minecraft:record_cat#1#0#22-5
rule30=0,100,IInventory;minecraft:chest;minecraft:string#4#0#0+minecraft:bread#1#0#5+HardcoreEnderExpansion:knowledge_note#1#0#10+minecraft:gunpowder#2#0#15+minecraft:record_cat#1#0#21+Forestry:beeDroneGE#1#0#23-5
rule31=0,100,minecraft:iron_door-2
rule32=0,100,IInventory;minecraft:chest;minecraft:record_13#1#0#1+HardcoreEnderExpansion:knowledge_note#1#0#2+harvestcraft:spagettiandmeatballsItem#0#0#4+minecraft:name_tag#1#0#8+minecraft:bucket#1#0#10+minecraft:bucket#1#0#13-5
rule33=0,100,IInventory;minecraft:chest;minecraft:bread#1#0#1+harvestcraft:deluxecheeseburgerItem#2#0#12+minecraft:record_13#1#0#14+minecraft:bread#1#0#16+minecraft:iron_ingot#2#0#21+harvestcraft:curryItem#1#0#25-5
rule34=0,100,minecraft:stonebrick-2
rule35=0,100,minecraft:stonebrick-3
rule36=2,100,minecraft:redstone_torch-3
rule37=2,100,minecraft:redstone_torch-4
rule38=0,100,MobSpawner:Blaze
rule39=0,100,minecraft:iron_door-8
rule40=2,100,minecraft:redstone_torch-1
rule41=2,100,minecraft:redstone_torch-2
rule42=0,100,minecraft:vine-0
rule43=0,100,minecraft:cauldron-0
rule44=0,100,minecraft:brewing_stand-0

layer
1,0,0,0,0,0,0,0,0,0,0,0,0,0,0,0,0,0,0,0,0,0,0,0,0,0,0,0,0
1,1,0,0,0,0,0,0,0,0,0,0,0,0,0,0,0,0,0,0,0,0,0,1,0,0,0,0,0
0,0,0,0,5,5,3,4,0,3,0,0,0,3,4,0,3,0,2,0,0,0,0,0,0,0,0,0,0
0,0,0,0,5,0,0,6,6,6,6,6,6,6,6,6,0,0,2,0,0,0,0,0,1,0,0,1,0
0,0,0,0,0,0,0,6,6,6,6,6,6,6,6,6,4,0,2,0,0,0,0,1,0,0,0,0,0
0,0,0,0,5,5,3,6,6,6,6,6,6,6,6,6,3,0,2,0,0,0,0,0,1,0,0,0,0
0,0,0,0,0,0,0,6,6,6,6,6,6,6,6,6,0,0,2,0,0,0,0,0,0,0,0,0,0
0,0,0,0,5,0,5,6,6,6,6,6,6,6,6,6,2,0,2,0,0,0,0,0,0,0,0,0,0
0,0,0,0,0,5,3,6,6,6,6,6,6,6,6,6,3,2,2,0,0,0,0,0,0,0,0,0,0
0,0,0,0,0,0,7,6,6,6,6,6,6,6,6,6,0,0,4,4,0,0,0,0,0,0,0,0,0
0,0,0,0,0,0,6,6,6,6,6,6,6,6,6,6,6,0,4,0,4,4,4,0,0,0,0,0,0
0,0,0,0,5,4,6,6,6,6,6,6,6,6,6,6,6,6,6,6,2,0,4,0,2,4,0,0,0
0,0,0,5,0,6,6,6,6,6,6,6,6,6,6,6,6,6,6,6,8,8,8,8,0,0,4,0,0
0,0,5,0,6,6,6,6,6,6,6,6,6,6,6,6,6,6,6,6,6,6,6,6,8,8,3,0,0
0,0,0,7,6,9,9,6,6,6,6,6,6,6,6,6,6,6,6,6,6,6,3,6,6,6,3,0,0
0,0,5,6,9,9,9,9,6,6,6,6,6,6,6,6,6,6,6,6,6,6,6,6,6,6,3,3,0
0,5,6,9,9,9,9,9,9,6,6,6,6,6,6,6,6,6,6,6,6,6,6,6,6,6,6,3,0
0,0,10,6,9,9,9,9,6,6,6,6,6,6,6,6,6,6,6,6,6,6,6,6,6,6,3,3,1
0,0,0,5,6,9,9,6,6,6,6,6,6,6,6,6,6,6,6,6,6,6,3,6,6,6,3,0,0
0,0,0,5,6,6,6,6,6,6,6,6,6,6,6,6,6,6,6,6,6,6,6,6,8,8,3,2,0
0,0,0,0,0,6,6,6,6,6,6,6,6,6,6,6,6,6,6,6,8,8,1,8,11,0,2,0,0
0,0,0,0,0,5,6,6,6,6,6,6,6,6,6,6,6,6,6,6,0,0,0,0,11,11,0,0,0
0,0,0,0,0,0,6,6,6,6,6,6,6,6,6,6,6,12,0,0,0,11,11,0,0,0,0,0,0
0,0,0,0,0,0,0,11,11,0,0,0,0,0,11,11,0,11,0,11,0,0,0,0,0,0,0,0,0
0,0,0,0,0,0,11,11,11,11,0,11,0,0,11,0,11,0,0,0,0,0,0,0,0,0,0,0,0
0,0,0,0,0,0,0,0,0,0,0,0,0,0,0,0,0,0,0,0,0,0,0,0,0,0,0,0,0
endlayer

layer
0,0,0,0,0,0,0,0,0,0,0,0,0,0,0,0,0,0,0,0,0,0,0,0,0,0,0,0,0
0,0,0,0,0,0,0,0,0,0,0,0,0,0,0,0,0,0,0,0,0,0,0,0,0,0,0,0,0
0,0,0,0,5,5,3,4,4,3,4,4,4,3,4,4,3,0,2,0,0,0,0,0,0,0,0,0,0
0,0,0,0,5,0,0,13,13,14,13,13,13,0,13,13,2,0,2,0,0,0,0,0,0,0,0,0,0
0,0,0,0,0,0,5,13,0,0,14,1,14,0,0,13,4,0,2,0,0,0,0,0,0,0,0,0,0
0,0,0,0,5,5,3,13,1,0,0,14,0,1,0,13,3,0,2,0,0,0,0,0,0,0,0,0,0
0,0,0,0,0,0,11,13,0,1,15,0,14,1,1,13,0,0,2,0,0,0,0,0,0,0,0,0,0
1,0,0,0,5,0,5,13,0,16,0,0,0,0,1,13,2,0,2,0,0,0,0,0,0,0,0,0,0
0,0,0,0,0,5,3,17,0,0,0,1,16,1,0,13,3,2,2,0,0,0,0,0,0,0,0,0,0
0,0,0,0,0,0,7,13,0,14,0,1,1,1,0,13,0,0,4,4,0,0,0,0,0,0,0,0,0
0,0,0,0,0,0,18,19,19,19,18,0,1,0,18,18,18,0,4,4,4,4,4,0,0,0,0,0,0
0,0,0,0,5,7,18,0,14,0,0,21,0,1,0,0,0,18,18,18,20,0,4,4,2,4,0,0,0
0,0,0,5,7,19,14,14,0,0,0,1,1,16,0,0,21,0,0,0,18,18,18,18,2,0,4,0,0
0,0,5,5,19,1,1,1,0,24,1,14,3,1,1,1,1,0,21,0,23,0,1,0,18,18,22,0,0
0,0,0,7,19,26,26,1,1,1,0,1,1,25,1,3,0,0,1,1,23,0,3,0,0,0,22,2,0
0,0,5,19,29,28,26,27,26,0,14,1,1,1,0,1,1,0,1,0,23,0,0,21,0,0,0,0,0
0,5,18,30,0,0,0,0,26,1,1,1,0,1,1,1,0,0,1,14,0,1,0,1,1,1,1,0,1
0,0,10,19,33,32,26,31,26,1,0,0,1,25,1,14,0,14,1,25,23,0,0,0,0,0,0,1,0
0,0,0,5,19,26,26,1,1,1,15,0,0,14,0,3,0,1,1,0,23,0,3,1,1,0,22,2,0
0,0,0,5,19,1,1,0,1,3,1,0,3,0,1,0,0,0,0,14,23,0,1,1,18,18,22,2,0
0,0,0,0,5,19,0,0,1,1,0,14,0,1,0,1,1,0,14,0,18,18,18,18,12,0,2,0,0
0,0,0,0,0,10,18,6,6,6,6,6,6,6,6,6,6,18,18,18,11,11,11,11,11,11,0,0,0
0,0,0,0,0,5,18,18,19,19,18,18,19,19,18,18,18,12,11,11,0,11,11,0,0,0,0,0,0
0,0,0,0,0,0,11,11,11,0,11,0,0,11,11,11,11,11,0,11,0,0,0,0,0,0,0,0,0
0,0,0,0,0,0,11,11,11,11,0,11,0,0,11,0,11,0,0,0,0,0,0,0,0,0,0,0,0
0,0,0,0,0,0,0,0,0,0,0,0,0,0,0,0,0,0,0,0,0,0,0,0,0,0,0,0,0
endlayer

layer
0,1,0,0,0,0,0,0,0,0,0,0,0,0,0,0,0,0,0,0,0,0,0,0,0,0,0,0,0
0,0,0,0,0,0,0,0,0,0,0,0,0,0,0,0,0,0,0,0,0,0,0,0,0,0,0,0,0
0,0,0,0,5,5,3,4,4,3,4,4,4,3,4,4,3,0,2,0,0,0,0,0,0,0,0,0,0
0,0,0,0,5,0,0,13,13,0,13,23,34,0,13,13,2,0,2,0,0,0,0,0,1,0,0,0,0
0,0,0,0,0,0,5,13,0,0,0,0,0,0,0,13,4,0,2,0,0,0,0,0,0,0,0,0,0
0,0,0,0,5,5,3,13,0,0,0,0,0,0,0,13,3,0,2,0,0,0,0,0,0,0,0,0,0
0,0,0,0,0,0,11,13,0,0,0,0,0,0,0,13,0,0,2,0,0,0,0,0,0,0,0,0,0
0,0,0,0,5,0,5,13,0,0,0,0,0,0,0,13,2,0,2,0,0,0,0,0,0,0,0,0,0
0,0,0,0,0,5,3,13,0,0,0,0,0,0,0,13,3,2,2,0,0,0,0,0,0,0,0,0,0
0,0,0,0,0,0,7,13,0,0,0,0,0,0,0,13,0,0,4,4,0,0,0,0,0,0,0,0,0
0,0,0,0,0,0,35,35,19,19,35,37,0,36,35,35,35,0,4,4,4,4,4,0,0,0,0,0,0
0,0,0,0,5,7,35,0,0,0,0,0,0,0,0,0,0,35,35,35,20,0,4,4,2,4,0,0,0
0,0,0,5,7,19,0,0,0,0,0,0,0,0,0,0,0,0,0,0,35,35,35,35,2,0,4,0,0
0,0,5,5,19,0,0,0,0,38,0,0,3,0,0,0,0,0,0,0,23,0,0,0,35,35,2,0,0
0,0,0,7,19,26,26,0,0,0,0,0,0,0,0,3,0,0,0,0,23,0,3,0,0,0,22,2,0
0,0,5,19,0,0,26,39,26,0,0,0,0,0,0,0,0,0,0,0,0,0,0,0,0,0,0,0,0
0,5,35,0,0,0,0,0,26,0,0,0,0,0,0,0,0,0,0,0,0,0,0,0,0,0,0,0,0
0,0,10,19,0,0,26,39,26,0,0,0,0,0,0,0,0,0,0,0,0,0,0,0,0,1,0,0,0
0,0,0,5,19,26,26,0,0,0,0,0,0,0,0,3,0,0,0,0,23,0,3,0,0,0,22,2,0
0,0,0,5,19,0,0,0,0,38,0,0,24,0,0,0,0,0,0,0,23,0,0,0,35,35,2,2,0
0,0,0,0,5,19,0,0,0,0,0,0,0,0,0,0,1,0,0,0,35,35,35,35,12,0,2,0,0
0,0,0,0,0,10,35,0,6,6,6,6,6,6,6,6,25,35,35,35,11,11,0,11,11,11,0,0,0
0,0,0,0,0,5,35,35,19,19,35,35,19,19,35,35,35,11,11,11,0,11,11,0,0,0,0,0,0
0,0,0,0,0,0,11,11,11,0,11,0,0,11,11,11,11,11,0,11,0,0,0,0,0,0,0,0,0
0,0,0,0,0,0,11,11,11,11,0,11,0,0,11,0,11,0,0,0,0,0,0,0,0,0,0,0,0
0,0,0,0,0,0,0,0,0,0,0,0,0,0,0,0,0,0,0,0,0,0,0,0,0,0,0,0,0
endlayer

layer
0,0,0,0,0,0,0,0,0,0,0,0,0,0,0,0,0,0,0,0,0,0,0,0,0,0,0,0,0
0,0,0,0,0,0,0,0,0,0,0,0,0,0,0,0,0,0,0,0,0,0,0,0,0,0,0,0,0
0,0,0,0,5,0,3,4,4,3,4,4,4,3,4,4,3,0,2,0,0,0,0,0,0,0,0,0,0
0,0,0,0,5,0,0,34,13,0,34,23,13,0,13,34,0,0,2,0,0,0,0,0,0,0,0,0,0
0,0,0,0,0,0,5,13,13,13,13,13,13,13,13,13,0,0,2,0,0,0,0,0,0,0,0,0,0
0,0,0,0,5,5,3,13,13,13,13,13,13,13,13,13,3,0,2,0,0,0,0,0,0,0,0,0,0
0,0,0,0,0,0,11,13,13,13,13,13,13,13,13,13,0,0,2,0,0,0,0,0,0,0,0,0,0
0,0,0,0,5,0,5,13,13,13,13,13,13,13,13,13,2,0,2,0,0,0,0,0,0,0,0,0,0
0,0,0,0,0,5,3,13,13,13,13,13,13,13,13,13,3,2,2,0,0,0,0,0,0,0,0,0,0
0,0,0,0,0,0,7,13,13,13,13,0,0,13,13,13,0,0,4,4,0,0,0,0,0,0,0,0,0
0,0,0,0,0,0,35,18,13,13,18,0,0,13,18,18,35,0,4,4,4,4,4,0,0,0,0,0,0
0,0,0,0,5,7,18,13,13,13,13,13,13,13,13,13,13,18,18,18,20,0,4,4,2,4,0,0,0
0,0,0,5,7,18,13,13,13,13,13,13,13,13,13,13,13,13,13,13,35,18,18,35,2,0,4,0,0
0,0,5,5,18,13,13,13,13,3,13,13,3,13,13,13,13,13,13,13,23,13,13,13,18,18,2,0,0
0,0,0,4,18,26,26,13,13,40,13,13,40,13,13,3,13,13,13,13,13,13,3,13,13,35,22,2,0
0,0,5,18,0,0,26,0,26,13,13,13,13,13,13,13,13,13,13,13,13,13,13,13,13,13,22,0,0
0,5,35,0,0,1,0,0,26,13,13,13,13,13,13,13,13,13,13,13,13,13,13,13,13,13,0,0,0
0,0,10,18,0,0,26,0,26,13,13,13,13,13,13,41,13,13,13,13,13,13,13,13,13,13,22,0,0
0,0,0,5,18,26,26,13,13,41,13,13,41,1,0,3,13,13,13,13,13,13,3,13,13,35,22,2,0
0,0,0,5,18,13,13,13,13,3,13,13,3,13,13,13,13,13,13,13,23,13,13,13,18,18,2,2,0
0,0,0,0,5,18,13,13,13,13,13,13,0,0,0,0,0,13,13,13,35,18,18,35,11,0,2,0,0
0,0,0,0,0,5,18,0,21,6,6,6,6,6,6,21,1,18,18,18,11,11,0,11,11,11,0,0,0
0,0,0,0,0,5,35,18,18,18,35,35,18,18,18,18,35,11,11,11,0,11,11,0,0,0,0,0,0
0,0,0,0,0,0,11,11,11,0,11,0,0,11,11,11,11,11,0,11,0,0,0,0,0,0,0,0,0
0,0,0,0,0,0,11,11,11,11,0,11,0,0,11,0,11,0,0,0,0,0,0,0,0,0,0,0,0
0,0,0,0,0,0,0,0,0,0,0,0,0,0,0,0,0,0,0,0,0,0,0,0,0,0,0,0,0
endlayer

layer
0,0,0,0,0,0,0,0,0,0,0,0,0,0,0,0,0,0,0,0,0,0,0,0,0,0,0,0,0
0,0,0,0,0,0,0,0,0,0,0,0,0,0,0,0,0,0,0,0,0,0,0,0,0,0,0,0,0
0,0,0,0,5,0,3,4,4,3,4,4,4,3,4,4,3,0,2,0,0,0,0,0,0,0,0,0,0
0,0,0,0,5,0,42,34,13,6,13,13,34,6,34,13,0,0,2,0,0,0,0,0,0,0,0,0,0
0,0,0,0,0,0,5,13,6,6,6,6,6,6,6,13,0,0,2,0,0,0,0,0,0,0,0,0,0
0,0,0,0,5,0,3,6,6,6,6,6,6,6,6,6,3,0,2,0,0,0,0,0,0,0,0,0,0
0,0,0,0,0,0,11,13,6,6,6,6,6,6,6,13,0,0,2,0,0,0,0,0,0,0,0,0,0
0,0,0,0,5,0,0,13,6,6,6,6,6,6,6,13,2,0,2,0,0,0,0,0,0,0,0,0,0
0,0,0,0,0,0,3,6,6,6,6,6,6,6,6,6,3,0,2,0,0,0,0,0,0,0,0,0,0
0,0,0,0,0,0,4,13,6,6,6,0,0,6,6,13,0,0,4,4,0,0,0,0,0,0,0,0,0
0,0,0,0,0,0,35,6,6,6,6,1,0,6,6,6,35,0,0,0,4,4,4,0,0,0,0,0,0
0,0,0,0,5,5,18,6,6,6,6,6,6,6,6,6,6,18,18,18,4,0,4,0,2,4,0,0,0
0,0,0,5,5,18,6,6,6,6,6,6,6,6,6,6,6,6,6,6,35,18,18,35,0,0,4,0,0
0,0,5,5,18,6,6,6,6,3,6,6,3,6,6,13,6,6,6,6,6,6,6,6,18,18,2,0,0
0,0,0,4,18,6,6,6,6,6,6,6,6,6,13,24,13,6,6,6,6,6,3,6,6,18,0,2,0
0,0,0,18,6,6,6,6,6,6,6,6,6,6,6,13,6,6,6,6,6,6,6,6,6,35,22,0,0
0,0,35,6,6,6,6,6,6,6,6,6,6,6,6,6,6,6,6,6,6,6,6,6,6,6,22,0,0
0,0,11,18,6,6,6,6,6,6,6,6,6,6,6,6,6,6,6,6,6,6,6,6,6,35,22,0,0
0,0,0,0,18,6,6,6,6,6,6,6,6,6,6,3,6,6,6,6,6,6,3,6,6,18,2,2,0
0,0,0,0,18,6,6,6,6,3,6,6,3,6,6,6,6,6,6,6,6,6,6,6,18,18,2,2,0
0,0,0,0,0,18,6,6,6,6,6,6,6,6,6,6,6,6,6,6,35,18,18,35,0,0,2,0,0
0,0,0,0,0,5,18,0,0,0,6,6,6,6,0,1,0,18,18,18,11,11,0,11,11,11,0,0,0
0,0,0,0,0,0,35,18,18,18,35,35,18,18,18,18,35,11,0,11,0,11,11,0,0,0,0,0,0
0,0,0,0,0,0,0,11,11,0,11,0,0,0,11,11,11,11,0,11,0,0,0,0,0,0,0,0,0
0,0,0,0,0,0,11,11,11,11,0,11,0,0,11,0,11,0,0,0,0,0,0,0,0,0,0,0,0
0,0,0,0,0,0,0,0,0,0,0,0,0,0,0,0,0,0,0,0,0,0,0,0,0,0,0,0,0
endlayer

layer
0,0,0,0,0,0,0,0,0,0,0,0,0,0,0,0,0,0,0,0,0,0,0,0,0,0,0,0,0
0,0,0,0,0,0,0,0,0,0,0,0,0,0,0,0,0,0,0,0,0,0,0,0,0,0,0,0,0
0,0,0,0,5,19,3,4,4,3,4,4,4,3,4,4,3,19,2,0,0,0,0,0,0,0,0,0,0
0,0,0,0,5,19,19,13,34,6,34,13,13,6,13,34,19,19,2,0,0,0,0,0,0,0,0,0,0
0,0,0,0,0,19,19,13,6,0,43,1,43,0,6,13,19,19,2,0,0,0,0,0,0,0,0,0,0
0,0,0,0,5,19,3,6,44,0,0,0,0,0,44,6,3,19,2,0,0,0,0,0,0,0,0,0,0
0,0,0,0,0,19,19,6,44,0,0,0,0,0,44,6,19,19,2,0,0,0,0,0,0,0,0,0,0
0,0,0,0,5,19,19,6,0,16,1,1,0,0,0,6,19,19,2,0,0,0,0,0,0,0,0,0,0
0,0,0,0,0,19,3,6,0,0,1,1,0,16,0,6,3,19,2,0,0,0,0,0,0,0,0,0,0
0,0,0,0,0,19,19,6,0,0,0,0,0,0,0,6,19,19,4,4,0,0,0,0,0,0,0,0,0
0,0,0,0,0,19,19,0,0,0,25,1,1,0,0,0,6,19,19,19,4,4,4,0,0,0,0,0,0
0,0,0,0,5,19,19,0,0,0,0,1,1,1,25,0,0,6,6,6,19,19,19,19,2,4,0,0,0
0,0,0,5,19,19,0,0,0,1,1,0,0,1,1,0,0,0,0,0,6,6,6,6,19,19,4,0,0
0,0,5,19,19,0,16,0,0,3,1,1,3,0,1,0,1,1,0,0,0,0,0,0,6,6,19,0,0
0,0,0,19,6,0,0,0,0,0,0,0,0,1,0,17,0,0,25,1,0,0,3,0,0,6,19,2,0
0,0,19,6,0,0,1,0,0,0,0,21,1,25,1,1,1,0,0,0,1,0,25,21,0,6,19,19,0
0,19,6,0,0,0,0,21,1,0,0,0,0,0,0,0,15,0,0,15,0,21,0,0,6,35,26,19,0
0,0,19,6,0,0,0,0,0,0,0,0,0,21,1,0,1,0,0,1,0,0,15,16,0,6,19,19,0
0,0,0,19,6,0,0,0,0,0,0,16,0,0,0,3,0,21,0,0,0,0,3,0,0,6,19,2,0
0,0,0,19,6,0,0,0,0,17,0,0,3,0,0,0,0,0,0,0,0,0,0,0,6,6,19,2,0
0,0,0,0,19,6,0,0,0,0,0,0,0,0,1,0,0,0,0,0,6,6,6,6,19,19,2,0,0
0,0,0,0,0,19,6,0,0,0,0,0,16,0,0,0,0,6,6,6,19,19,19,19,11,11,0,0,0
0,0,0,0,0,19,6,6,6,6,6,6,6,6,6,6,6,19,19,19,0,11,11,0,0,0,0,0,0
0,0,0,0,0,0,19,19,19,19,19,19,19,19,19,19,19,11,0,11,0,0,0,0,0,0,0,0,0
0,0,0,0,0,0,11,11,11,11,0,11,0,0,11,0,11,0,0,0,0,0,0,0,0,0,0,0,0
0,0,0,0,0,0,0,0,0,0,0,0,0,0,0,0,0,0,0,0,0,0,0,0,0,0,0,0,0
endlayer

layer
0,0,0,0,0,0,0,0,0,0,0,0,0,0,0,0,0,0,0,0,0,0,0,0,0,0,0,0,0
0,0,0,0,0,0,0,0,0,0,0,0,0,0,0,0,0,0,0,0,0,0,0,0,0,0,0,0,0
0,0,0,0,0,0,19,4,4,3,4,4,4,3,4,4,19,0,0,0,0,0,0,0,0,0,0,0,0
0,0,0,0,0,0,19,13,13,13,13,6,13,13,13,13,19,0,0,0,0,0,0,0,0,0,0,0,0
0,0,0,0,0,0,19,6,0,0,0,0,0,0,0,6,19,0,0,0,0,0,0,0,0,0,0,0,0
0,0,0,0,0,0,19,0,0,0,0,0,0,0,0,0,19,0,0,0,0,0,0,0,0,0,0,0,0
0,0,0,0,0,0,19,0,0,0,0,0,0,0,0,0,19,0,0,0,0,0,0,0,0,0,0,0,0
0,0,0,0,0,0,19,0,0,0,0,0,0,0,0,0,19,0,0,0,0,0,0,0,0,0,0,0,0
0,0,0,0,0,0,19,0,0,0,0,0,0,0,0,0,19,0,0,0,0,0,0,0,0,0,0,0,0
0,0,0,0,0,0,19,0,0,0,0,0,0,0,0,0,19,0,0,0,0,0,0,0,0,0,0,0,0
0,0,0,0,0,0,19,0,0,0,0,0,0,0,0,0,19,0,0,0,0,0,0,0,0,0,0,0,0
0,0,0,0,0,0,19,0,0,0,0,0,0,0,0,0,0,19,19,19,0,0,0,0,0,0,0,0,0
0,0,0,0,0,19,0,0,1,0,0,0,0,0,0,0,0,0,0,0,19,19,19,19,0,0,0,0,0
0,0,0,0,19,0,0,0,0,3,0,0,3,0,0,0,0,0,0,0,0,0,0,0,19,19,0,0,0
0,0,0,0,19,0,0,0,0,0,0,0,40,0,0,3,37,0,0,0,0,0,3,0,0,19,0,0,0
0,0,0,19,0,0,0,0,0,0,0,0,0,0,0,0,0,0,0,0,0,0,0,0,0,19,19,0,0
0,0,19,19,0,0,0,0,0,0,0,0,0,0,0,0,0,0,0,0,0,0,0,0,0,19,19,0,0
0,0,0,19,0,0,0,0,0,0,0,0,0,0,0,0,0,0,0,0,0,0,0,0,0,19,19,0,0
0,0,0,0,19,0,0,0,0,0,0,0,0,0,0,3,0,0,0,0,0,0,3,0,0,19,0,0,0
0,0,0,0,19,0,0,0,0,3,0,0,3,0,0,0,0,0,0,0,0,0,0,0,19,19,0,0,0
0,0,0,0,0,19,0,0,0,0,0,0,0,0,0,0,0,0,0,0,19,19,19,19,0,0,0,0,0
0,0,0,0,0,0,19,0,0,0,0,0,0,0,0,0,0,19,19,19,0,0,0,0,0,0,0,0,0
0,0,0,0,0,0,19,19,19,19,19,19,19,19,19,19,19,0,0,0,0,0,0,0,0,0,0,0,0
0,0,0,0,0,0,0,0,0,0,0,0,0,0,0,0,0,0,0,0,0,0,0,0,0,0,0,0,0
0,0,0,0,0,0,0,0,0,0,0,0,0,0,0,0,0,0,0,0,0,0,0,0,0,0,0,0,0
0,0,0,0,0,0,0,0,0,0,0,0,0,0,0,0,0,0,0,0,0,0,0,0,0,0,0,0,0
endlayer

layer
0,0,0,0,0,0,0,0,0,0,0,0,0,0,0,0,0,0,0,0,0,0,0,0,0,0,0,0,0
0,0,0,0,0,0,0,0,0,0,0,0,0,0,0,0,0,0,0,0,0,0,0,0,0,0,0,0,0
0,0,0,0,0,0,0,19,4,3,4,4,4,3,4,19,0,0,0,0,0,0,0,0,0,0,0,0,0
0,0,0,0,0,0,0,19,34,13,6,23,6,13,34,19,0,0,0,0,0,0,0,0,0,0,0,0,0
0,0,0,0,0,0,0,19,0,0,0,0,0,0,0,19,0,0,0,0,0,0,0,0,0,0,0,0,0
0,0,0,0,0,0,0,19,0,0,0,0,0,0,0,19,0,0,0,0,0,0,0,0,0,0,0,0,0
0,0,0,0,0,0,0,19,0,0,0,0,0,0,0,19,0,0,0,0,0,0,0,0,0,0,0,0,0
0,0,0,0,0,0,0,19,0,0,0,0,0,0,0,19,0,0,0,0,0,0,0,0,0,0,0,0,0
0,0,0,0,0,0,0,19,0,0,0,0,0,0,0,19,0,0,0,0,0,0,0,0,0,0,0,0,0
0,0,0,0,0,0,0,19,0,0,0,0,0,0,0,19,0,0,0,0,0,0,0,0,0,0,0,0,0
0,0,0,0,0,0,0,19,0,0,0,0,0,0,0,19,0,0,0,0,0,0,0,0,0,0,0,0,0
0,0,0,0,0,0,0,19,0,0,0,0,0,0,0,0,19,0,0,0,0,0,0,0,0,0,0,0,0
0,0,0,0,0,0,19,0,0,0,0,0,0,0,0,0,0,19,19,19,0,0,0,0,0,0,0,0,0
0,0,0,0,0,19,0,0,0,3,0,0,3,0,0,0,0,0,0,0,19,19,19,19,0,0,0,0,0
0,0,0,0,0,19,0,0,0,0,0,0,0,0,0,3,0,0,0,0,0,0,3,0,19,0,0,0,0
0,0,0,0,19,0,0,0,0,0,0,0,0,0,0,0,0,0,0,0,0,0,0,0,19,19,0,0,0
0,0,0,19,19,0,0,0,0,0,0,0,0,0,0,0,0,0,0,0,0,0,0,0,19,19,0,0,0
0,0,0,0,19,0,0,0,0,0,0,0,0,0,0,0,0,0,0,0,0,0,0,0,19,19,0,0,0
0,0,0,0,0,19,0,0,0,0,0,0,0,0,0,3,0,0,0,0,0,0,3,0,19,0,0,0,0
0,0,0,0,0,19,0,0,0,3,0,0,3,0,0,0,0,0,0,0,19,19,19,19,0,0,0,0,0
0,0,0,0,0,0,19,0,0,0,0,0,0,0,0,0,0,19,19,19,0,0,0,0,0,0,0,0,0
0,0,0,0,0,0,0,19,19,19,19,19,19,19,19,19,19,0,0,0,0,0,0,0,0,0,0,0,0
0,0,0,0,0,0,0,0,0,0,0,0,0,0,0,0,0,0,0,0,0,0,0,0,0,0,0,0,0
0,0,0,0,0,0,0,0,0,0,0,0,0,0,0,0,0,0,0,0,0,0,0,0,0,0,0,0,0
0,0,0,0,0,0,0,0,0,0,0,0,0,0,0,0,0,0,0,0,0,0,0,0,0,0,0,0,0
0,0,0,0,0,0,0,0,0,0,0,0,0,0,0,0,0,0,0,0,0,0,0,0,0,0,0,0,0
endlayer

layer
0,0,0,0,0,0,0,0,0,0,0,0,0,0,0,0,0,0,0,0,0,0,0,0,0,0,0,0,0
0,0,0,0,0,0,0,0,0,0,0,0,0,0,0,0,0,0,0,0,0,0,0,0,0,0,0,0,0
0,0,0,0,0,0,0,0,19,3,4,4,0,3,19,0,0,0,0,0,0,0,0,0,0,0,0,0,0
0,0,0,0,0,0,0,0,19,34,34,6,13,34,19,0,0,0,0,0,0,0,0,0,0,0,0,0,0
0,0,0,0,0,0,0,0,19,0,0,0,0,0,19,0,0,0,0,0,0,0,0,0,0,0,0,0,0
0,0,0,0,0,0,0,0,19,0,0,0,0,0,19,0,0,0,0,0,0,0,0,0,0,0,0,0,0
0,0,0,0,0,0,0,0,19,0,0,0,0,0,19,0,0,0,0,0,0,0,0,0,0,0,0,0,0
0,0,0,0,0,0,0,0,19,0,0,0,0,0,19,0,0,0,0,0,0,0,0,0,0,0,0,0,0
0,0,0,0,0,0,0,0,19,0,0,0,0,0,19,0,0,0,0,0,0,0,0,0,0,0,0,0,0
0,0,0,0,0,0,0,0,19,0,0,0,0,0,19,0,0,0,0,0,0,0,0,0,0,0,0,0,0
0,0,0,0,0,0,0,0,19,0,0,0,0,0,19,0,0,0,0,0,0,0,0,0,0,0,0,0,0
0,0,0,0,0,0,0,0,19,0,0,0,0,0,0,19,0,0,0,0,0,0,0,0,0,0,0,0,0
0,0,0,0,0,0,0,19,0,0,0,0,0,0,0,0,19,0,0,0,0,0,0,0,0,0,0,0,0
0,0,0,0,0,0,19,0,0,3,0,0,3,0,0,0,0,19,19,19,0,0,0,0,0,0,0,0,0
0,0,0,0,0,0,19,0,0,0,0,0,0,0,0,3,0,0,0,0,19,19,19,19,0,0,0,0,0
0,0,0,0,0,19,0,0,0,0,0,0,0,0,0,0,0,0,0,0,0,0,0,19,19,0,0,0,0
0,0,0,0,19,19,0,0,0,0,0,0,0,0,0,0,0,0,0,0,0,0,0,19,19,0,0,0,0
0,0,0,0,0,19,0,0,0,0,0,0,0,0,0,0,0,0,0,0,0,0,0,19,19,0,0,0,0
0,0,0,0,0,0,19,0,0,0,0,0,0,0,0,3,0,0,0,0,19,19,19,19,0,0,0,0,0
0,0,0,0,0,0,19,0,0,3,0,0,3,0,0,0,0,19,19,19,0,0,0,0,0,0,0,0,0
0,0,0,0,0,0,0,19,19,19,19,19,19,19,19,19,19,0,0,0,0,0,0,0,0,0,0,0,0
0,0,0,0,0,0,0,0,0,0,0,0,0,0,0,0,0,0,0,0,0,0,0,0,0,0,0,0,0
0,0,0,0,0,0,0,0,0,0,0,0,0,0,0,0,0,0,0,0,0,0,0,0,0,0,0,0,0
0,0,0,0,0,0,0,0,0,0,0,0,0,0,0,0,0,0,0,0,0,0,0,0,0,0,0,0,0
0,0,0,0,0,0,0,0,0,0,0,0,0,0,0,0,0,0,0,0,0,0,0,0,0,0,0,0,0
0,0,0,0,0,0,0,0,0,0,0,0,0,0,0,0,0,0,0,0,0,0,0,0,0,0,0,0,0
endlayer

layer
0,0,0,0,0,0,0,0,0,0,0,0,0,0,0,0,0,0,0,0,0,0,0,0,0,0,0,0,0
0,0,0,0,0,0,0,0,0,0,0,0,0,0,0,0,0,0,0,0,0,0,0,0,0,0,0,0,0
0,0,0,0,0,0,0,0,0,19,4,4,42,19,0,0,0,0,0,0,0,0,0,0,0,0,0,0,0
0,0,0,0,0,0,0,0,0,19,13,13,13,19,0,0,0,0,0,0,0,0,0,0,0,0,0,0,0
0,0,0,0,0,0,0,0,0,19,0,0,0,19,0,0,0,0,0,0,0,0,0,0,0,0,0,0,0
0,0,0,0,0,0,0,0,0,19,0,0,0,19,0,0,0,0,0,0,0,0,0,0,1,0,0,0,0
0,0,0,0,0,0,0,0,0,19,0,0,0,19,0,0,0,0,0,0,0,0,0,0,0,0,0,0,0
0,0,0,0,0,0,0,0,0,19,0,0,0,19,0,0,0,0,0,0,0,0,0,0,0,0,0,0,0
0,0,0,0,0,0,0,0,0,19,0,0,0,19,0,0,0,0,0,0,0,0,0,0,0,0,0,0,0
0,0,0,0,0,0,0,0,0,19,0,0,0,19,0,0,0,0,0,0,0,0,0,0,0,0,0,0,0
0,0,0,0,0,0,0,0,0,19,0,0,0,19,0,0,0,0,0,0,0,0,0,0,0,0,0,0,0
0,0,0,0,0,0,0,0,0,19,0,0,0,0,19,0,0,0,0,0,0,0,0,0,0,0,0,0,0
0,0,0,0,0,0,0,0,19,0,0,0,0,0,0,19,0,0,0,0,0,0,0,0,0,0,0,0,0
0,0,0,0,0,0,0,19,0,3,0,0,3,0,0,0,19,0,0,0,0,0,0,0,0,0,0,0,0
0,0,0,0,0,0,0,19,0,0,0,0,0,0,0,3,0,19,19,19,0,0,0,0,0,0,0,0,0
0,0,0,0,0,0,19,0,0,0,0,0,0,0,0,0,0,0,0,0,19,19,19,19,0,0,0,0,0
0,0,0,0,0,19,19,0,0,0,0,0,0,0,0,0,0,0,0,0,0,0,19,19,0,0,0,0,0
0,0,0,0,0,0,19,0,0,0,0,0,0,0,0,0,0,0,0,0,19,19,19,19,0,0,0,0,0
0,0,0,0,0,0,0,19,0,0,0,0,0,0,0,3,0,19,19,19,0,0,0,0,0,0,0,0,0
0,0,0,0,0,0,0,19,19,19,19,19,19,19,19,19,19,0,0,0,0,0,0,0,0,0,0,0,0
0,0,0,0,0,0,0,0,0,0,0,0,0,0,0,0,0,0,0,0,0,0,0,0,0,0,0,0,0
0,0,0,0,0,0,0,0,0,0,0,0,0,0,0,0,0,0,0,0,0,0,0,0,0,0,0,0,0
0,0,0,0,0,0,0,0,0,0,0,0,0,0,0,0,0,0,0,0,0,0,0,0,0,0,0,0,0
0,0,0,0,0,0,0,0,0,0,0,0,0,0,0,0,0,0,0,0,0,0,0,0,0,0,0,0,0
0,0,0,0,0,0,0,0,0,0,0,0,0,0,0,0,0,0,0,0,0,0,0,0,0,0,0,0,0
0,0,0,0,0,0,0,0,0,0,0,0,0,0,0,0,0,0,0,0,0,0,0,0,0,0,0,0,0
endlayer

layer
0,0,0,0,0,0,0,0,0,0,0,0,0,0,0,0,0,0,0,0,0,0,0,0,0,0,0,0,0
0,0,0,0,0,0,0,0,0,0,0,0,0,0,0,0,0,0,0,0,0,0,0,0,0,0,0,0,0
0,0,0,0,0,0,0,0,0,0,19,0,19,0,0,0,0,0,0,0,0,0,0,0,0,0,0,0,0
0,0,0,0,0,0,0,0,0,0,19,6,19,0,0,0,0,0,0,0,0,0,0,0,0,0,0,0,0
0,0,0,0,0,0,0,0,0,0,19,0,19,0,0,0,0,0,0,0,0,0,0,0,0,0,0,0,0
0,0,0,0,0,0,0,0,0,0,19,0,19,0,0,0,0,0,0,0,0,0,0,0,0,0,0,0,0
0,0,0,0,0,0,0,0,0,0,19,0,19,0,0,0,0,0,0,0,0,0,0,0,0,0,0,0,0
0,0,0,0,0,0,0,0,0,0,19,0,19,0,0,0,0,0,0,0,0,0,0,0,0,0,0,0,0
0,0,0,0,0,0,0,0,0,0,19,0,19,0,0,0,0,0,0,0,0,0,0,0,0,0,0,0,0
0,0,0,0,0,0,0,0,0,0,19,0,19,0,0,0,0,0,0,0,0,0,0,0,0,0,0,0,0
0,0,0,0,0,0,0,0,0,0,19,0,19,0,0,0,0,0,0,0,0,0,0,0,0,0,0,0,0
0,0,0,0,0,0,0,0,0,0,19,0,19,19,0,0,0,0,0,0,0,0,0,0,0,0,0,0,0
0,0,0,0,0,0,0,0,0,19,0,0,0,0,19,0,0,0,0,0,0,0,0,0,0,0,0,0,0
0,0,0,0,0,0,0,0,19,0,0,0,3,0,0,19,0,0,0,0,0,0,0,0,0,0,0,0,0
0,0,0,0,0,0,0,0,19,0,0,0,0,0,0,3,19,0,0,0,0,0,0,0,0,0,0,0,0
0,0,0,0,0,0,0,19,0,0,0,0,0,0,0,0,19,19,19,19,0,0,0,0,0,0,0,0,0
0,0,0,0,0,0,0,19,0,0,0,0,0,0,0,0,0,0,0,0,19,19,19,0,0,0,0,0,0
0,0,0,0,0,0,0,19,0,0,0,0,0,0,0,0,19,19,19,19,0,0,0,0,0,0,0,0,0
0,0,0,0,0,0,0,0,19,19,19,19,19,19,19,19,19,0,0,0,0,0,0,0,0,0,0,0,0
0,0,0,0,0,0,0,0,0,0,0,0,0,0,0,0,0,0,0,0,0,0,0,0,0,0,0,0,0
0,0,0,0,0,0,0,0,0,0,0,0,0,0,0,0,0,0,0,0,0,0,0,0,0,0,0,0,0
0,0,0,0,0,0,0,0,0,0,0,0,0,0,0,0,0,0,0,0,0,0,0,0,0,0,0,0,0
0,0,0,0,0,0,0,0,0,0,0,0,0,0,0,0,0,0,0,0,0,0,0,0,0,0,0,0,0
0,0,0,0,0,0,0,0,0,0,0,0,0,0,0,0,0,0,0,0,0,0,0,0,0,0,0,0,0
0,0,0,0,0,0,0,0,0,0,0,0,0,0,0,0,0,0,0,0,0,0,0,0,0,0,0,0,0
0,0,0,0,0,0,0,0,0,0,0,0,0,0,0,0,0,0,0,0,0,0,0,0,0,0,0,0,0
endlayer

layer
0,0,0,0,0,0,0,0,0,0,0,0,0,0,0,0,0,0,0,0,0,0,0,0,0,0,0,0,0
0,0,0,0,0,0,0,0,0,0,0,0,0,0,0,0,0,0,0,0,0,0,0,0,0,0,0,0,0
0,0,0,0,0,0,0,0,0,0,0,19,0,0,0,0,0,0,0,0,0,0,0,0,0,0,0,0,0
0,0,0,0,0,0,0,0,0,0,0,19,0,0,0,0,0,0,0,0,0,0,0,0,0,0,0,0,0
0,0,0,0,0,0,0,0,0,0,0,19,0,0,0,0,0,0,0,0,0,0,0,0,0,0,0,0,0
0,0,0,0,0,0,0,0,0,0,0,19,0,0,0,0,0,0,0,0,0,0,0,0,0,0,0,0,0
0,0,0,0,0,1,0,0,0,0,0,19,0,0,0,0,0,0,0,0,0,0,0,0,0,0,0,0,0
0,0,0,0,0,0,0,0,0,0,0,19,0,0,0,0,0,0,0,0,0,0,0,0,0,0,0,0,0
0,0,0,0,0,0,0,0,0,0,0,19,0,0,0,0,0,0,0,0,0,0,0,0,0,0,0,0,0
0,0,0,0,0,0,0,0,1,0,0,19,0,0,0,0,0,0,0,0,0,0,0,0,0,0,0,0,0
0,0,0,0,0,0,0,0,0,0,0,19,0,0,0,0,0,0,0,0,0,0,0,0,0,0,0,0,0
0,0,0,0,0,0,0,0,0,0,0,19,0,0,0,0,0,0,0,0,0,0,0,0,0,0,0,0,0
0,0,0,0,0,0,0,0,0,0,19,19,19,19,0,0,0,0,0,0,0,0,0,0,0,0,0,0,0
0,0,0,0,0,0,0,0,0,19,19,19,19,19,19,0,0,0,0,0,0,0,0,0,0,0,0,0,0
0,0,0,0,0,0,0,0,0,19,19,19,19,19,19,19,0,0,0,0,0,0,0,0,0,0,0,0,0
0,0,0,0,0,0,0,0,19,19,19,19,19,19,19,19,0,0,0,0,0,0,0,0,0,0,0,0,0
0,0,0,0,0,0,0,0,19,19,19,19,19,19,19,19,19,19,19,19,0,0,0,0,0,0,0,0,0
0,0,0,0,0,0,0,0,19,19,19,19,19,19,19,19,0,0,0,0,0,0,0,0,0,0,0,0,0
0,0,0,0,0,0,0,0,0,0,0,0,0,0,0,0,0,0,0,0,0,0,0,0,0,0,0,0,0
0,0,0,0,0,0,0,0,0,0,0,0,0,0,0,0,0,0,0,0,0,0,0,0,0,0,0,0,0
0,0,0,0,0,0,0,0,0,0,0,0,0,0,0,0,0,0,0,0,0,0,0,0,0,0,0,0,0
0,0,0,0,0,0,0,0,0,0,0,0,0,0,0,0,0,0,0,0,0,0,0,0,0,0,0,0,0
0,0,0,0,0,0,0,0,0,0,0,0,0,0,0,0,0,0,0,0,0,0,0,0,0,0,0,0,0
0,0,0,0,0,0,0,0,0,0,0,0,0,0,0,0,0,0,0,0,0,0,0,0,0,0,0,0,0
0,0,0,0,0,0,0,0,0,0,0,0,0,0,0,0,0,0,0,0,0,0,0,0,0,0,0,0,0
0,0,0,0,0,0,0,0,0,0,0,0,0,0,0,0,0,0,0,0,0,0,0,0,0,0,0,0,0
endlayer

layer
0,0,0,0,0,0,0,0,0,0,0,0,0,0,0,0,0,0,0,0,0,0,0,0,0,0,0,0,0
0,0,0,0,0,0,0,0,0,0,0,0,0,0,0,0,0,0,0,0,0,0,0,0,0,0,0,0,0
0,0,0,0,0,0,0,0,0,0,0,0,0,0,0,0,0,0,0,0,0,0,0,0,0,0,0,0,0
0,0,0,0,0,0,0,0,0,0,0,0,0,0,0,0,0,0,0,0,0,0,0,0,0,0,0,0,0
0,0,0,0,0,0,0,0,0,0,0,0,0,0,0,0,0,0,0,0,0,0,0,0,0,0,0,0,0
0,0,0,0,0,0,0,0,0,0,0,0,0,0,0,0,0,0,0,0,0,0,0,0,0,0,0,0,0
0,0,1,0,0,0,0,0,0,0,0,0,0,0,0,0,0,0,0,0,0,0,0,0,0,0,0,0,0
0,0,0,0,0,0,0,0,0,0,0,0,0,0,0,0,0,0,0,0,0,0,0,0,0,0,0,0,0
0,0,0,0,0,0,0,0,0,0,0,0,0,0,0,0,0,0,0,0,0,0,0,0,0,0,0,0,0
0,0,0,0,0,0,0,0,0,0,0,1,0,0,0,0,0,0,0,0,0,0,0,0,0,0,0,0,0
0,0,0,0,0,0,0,0,0,0,0,0,0,0,0,0,0,0,0,0,0,0,0,0,0,0,0,0,0
0,0,0,0,0,0,0,0,0,0,0,0,0,0,0,0,0,0,0,0,0,0,0,0,0,0,0,0,0
0,0,0,0,0,0,0,0,0,0,0,19,0,0,0,0,0,0,0,0,0,0,0,0,0,0,0,0,0
0,0,0,0,0,0,0,0,0,0,19,19,19,19,0,0,0,0,0,0,0,0,0,0,0,0,0,0,0
0,0,0,0,0,0,0,0,0,0,19,13,13,19,19,0,0,0,0,0,0,0,0,0,0,0,0,0,0
0,0,0,0,0,0,0,0,0,0,19,19,13,19,19,0,0,0,0,0,0,0,0,0,0,0,0,0,0
0,0,0,0,0,0,0,0,0,0,19,19,19,19,19,19,0,0,0,0,0,0,0,0,0,0,0,0,0
0,0,0,0,0,0,0,0,0,0,0,0,0,0,0,0,0,0,0,0,0,0,0,0,0,0,0,0,0
0,0,0,0,0,0,0,0,0,0,0,0,0,0,0,0,0,0,0,0,0,0,0,0,0,0,0,0,0
0,0,0,0,0,0,0,0,0,0,0,0,0,0,0,0,0,0,0,0,0,0,0,0,0,0,0,0,0
0,0,1,0,0,0,0,0,0,0,0,0,0,0,0,0,0,0,0,0,0,0,0,0,0,0,0,0,0
0,0,0,0,0,0,0,0,0,0,0,0,0,0,0,0,0,0,0,0,0,0,0,0,0,0,0,0,0
0,0,0,0,0,0,0,0,0,0,0,0,0,0,0,0,0,0,0,0,0,0,0,0,0,0,0,0,0
0,0,0,0,0,0,0,0,0,0,0,0,0,0,0,0,0,0,0,0,0,0,0,0,0,0,0,0,0
0,0,0,0,0,0,0,0,0,0,0,0,0,0,0,0,0,0,0,0,0,0,0,0,0,0,0,0,0
0,0,0,0,0,0,0,0,0,0,0,0,0,0,0,0,0,0,0,0,0,0,0,0,0,0,0,0,0
endlayer

layer
0,0,0,0,0,0,0,0,0,0,0,0,0,0,0,0,0,0,0,0,0,0,0,0,0,0,0,0,0
0,0,0,0,0,0,0,0,0,0,0,0,0,0,0,0,0,0,0,0,0,0,0,0,0,0,0,0,0
0,0,0,0,0,0,0,0,0,0,0,0,0,0,0,0,0,0,0,0,0,0,0,0,0,0,0,0,0
0,0,0,0,0,0,0,0,0,0,0,0,0,0,0,0,0,0,0,0,0,0,0,0,0,0,0,0,0
0,0,0,0,0,0,0,0,0,0,0,0,0,0,0,0,0,0,0,0,0,0,0,0,0,0,0,0,0
0,0,0,0,0,0,0,0,0,0,0,0,0,0,0,0,0,0,0,0,0,0,0,0,0,0,0,0,0
0,0,0,1,0,0,0,0,0,0,0,0,0,0,0,0,0,0,0,0,0,0,0,0,0,0,0,0,0
0,0,0,0,0,0,0,0,0,0,0,0,0,0,0,0,0,0,0,0,0,0,0,0,0,0,0,0,0
0,0,0,0,0,0,0,0,0,0,0,0,0,0,0,0,0,0,0,0,0,0,0,0,0,0,0,0,0
0,0,0,0,0,0,0,0,0,1,0,0,0,0,0,0,0,0,0,0,0,0,0,0,0,0,0,0,0
0,0,0,0,0,0,0,0,0,0,0,0,0,0,0,0,0,0,0,0,0,0,0,0,0,0,0,0,0
0,0,0,0,0,0,0,0,1,0,0,0,0,0,0,0,0,0,0,0,0,0,0,0,0,0,0,0,0
0,0,0,0,0,0,0,0,0,0,0,0,0,0,0,0,0,0,0,0,0,0,0,0,0,0,0,0,0
0,0,0,0,0,0,0,0,0,0,0,0,0,0,0,0,0,0,0,0,0,0,0,0,0,0,0,0,0
0,0,0,0,0,0,0,0,0,0,0,19,19,19,0,0,0,0,0,0,0,0,0,0,0,0,0,0,0
0,0,0,0,0,0,0,0,0,0,0,19,13,19,0,0,0,0,0,0,0,0,0,0,0,0,0,0,0
0,0,0,0,0,0,0,0,0,0,0,0,0,0,0,0,0,0,0,0,0,0,0,0,0,0,0,0,0
0,0,0,0,0,0,0,0,0,0,0,0,0,0,0,0,0,0,0,0,0,0,0,0,0,0,0,0,0
0,0,0,0,0,0,0,0,0,0,0,0,0,0,0,0,0,0,0,0,0,0,0,0,0,0,0,0,0
0,0,0,0,0,0,0,0,0,0,0,0,0,0,0,0,0,0,0,0,0,0,0,0,0,0,0,0,0
0,0,0,0,0,0,0,0,0,0,0,0,0,0,0,0,0,0,0,0,0,0,0,0,0,0,0,0,0
0,0,0,0,0,0,0,0,0,0,0,0,0,0,0,0,0,0,0,0,0,0,0,0,0,0,0,0,0
0,0,0,0,0,0,0,0,0,0,0,0,0,0,0,0,0,0,0,0,0,0,0,0,0,0,0,0,0
0,0,0,0,0,0,0,0,0,0,0,0,0,0,0,0,0,0,0,0,0,0,0,0,0,0,0,0,0
0,0,0,0,0,0,0,0,0,0,0,0,0,0,0,0,0,0,0,0,0,0,0,0,0,0,0,0,0
0,0,0,0,0,0,0,0,0,0,0,0,0,0,0,0,0,0,0,0,0,0,0,0,0,0,0,0,0
endlayer

