
# Created by Ruins mod version 14.4 Ingame Parser
# authoring Player: Mikhaila666

weight=1
embed_into_distance=0
acceptable_target_blocks=
unacceptable_target_blocks=flowing_water,water,flowing_lava,lava
dimensions=6,10,10
allowable_overhang=0
max_leveling=2
leveling_buffer=0
preserve_water=0
preserve_lava=0

rule1=0,100,minecraft:grass-0
rule2=0,100,minecraft:dirt-0
rule3=0,100,minecraft:stonebrick-1
rule4=0,100,arsmagica2:vinteumOre-2
rule5=0,100,Railcraft:tile.railcraft.residual.heat-0
rule6=0,100,minecraft:monster_egg-3
rule7=0,100,arsmagica2:vinteumOre-3
rule8=0,100,minecraft:stone_brick_stairs-2
rule9=0,100,minecraft:stone_brick_stairs-0
rule10=0,100,arsmagica2:liquidEssence-1
rule11=0,100,arsmagica2:liquidEssence-0
rule12=0,100,arsmagica2:liquidEssence-2
rule13=0,100,minecraft:stone_brick_stairs-3
rule14=0,100,minecraft:stone_brick_stairs-1
rule15=0,100,minecraft:stone_brick_stairs-7
rule16=0,100,minecraft:stone_brick_stairs-6
rule17=0,100,minecraft:stone_brick_stairs-5
rule18=0,100,minecraft:stone_brick_stairs-4

layer
0,1,2,1,1,2,1,1,0,0
0,1,1,1,1,1,1,1,0,0
2,1,2,2,2,2,2,1,1,0
1,1,2,2,2,2,2,1,1,1
1,1,2,2,2,2,2,3,1,1
2,1,2,2,2,3,3,2,1,1
1,1,2,2,2,3,3,3,3,1
0,1,1,1,3,2,3,4,3,1
0,0,1,1,1,1,3,3,3,1
0,0,0,0,1,1,1,1,1,1
endlayer

layer
0,0,3,0,0,3,0,0,0,0
0,0,0,0,0,0,0,5,0,0
3,0,6,3,3,3,3,0,5,0
0,0,3,3,3,3,3,0,0,0
0,5,3,3,7,3,3,5,5,0
3,5,3,3,3,10,10,3,9,8
0,0,3,3,3,10,12,10,11,8
0,0,5,0,5,3,12,10,11,8
0,0,5,0,0,13,10,11,11,8
0,0,0,0,0,14,14,14,14,8
endlayer

layer
0,0,3,0,0,3,5,0,0,5
0,0,0,0,0,5,5,0,0,0
3,5,9,9,9,9,9,5,0,0
5,0,13,11,11,11,8,0,5,5
5,0,13,11,10,11,8,0,0,0
3,0,13,11,11,10,5,5,0,0
0,0,13,14,14,0,5,5,5,5
0,0,0,0,0,0,0,5,5,5
0,0,5,0,5,0,5,5,5,0
0,0,0,5,0,0,0,0,0,5
endlayer

layer
0,5,3,5,0,3,0,0,0,0
0,0,0,0,0,5,0,0,0,0
3,0,0,0,0,0,0,0,5,0
0,0,0,0,0,5,0,5,0,0
0,0,0,0,0,5,0,0,5,0
3,0,0,0,0,0,0,0,5,5
0,0,0,0,0,0,0,5,5,0
0,0,0,0,0,0,0,0,0,0
0,0,0,5,0,0,5,0,0,0
0,0,0,0,0,0,0,5,0,0
endlayer

layer
0,0,3,16,15,3,0,0,0,0
0,0,0,0,5,5,5,5,5,0
3,0,0,5,0,0,5,0,5,0
17,0,0,0,0,0,0,0,0,0
18,0,0,0,0,0,0,0,0,0
3,0,0,0,0,0,0,0,0,0
0,0,0,0,0,5,5,0,5,0
0,5,0,0,0,0,0,0,0,0
0,0,0,0,0,0,0,0,0,0
0,0,5,0,0,0,0,5,0,0
endlayer

layer
0,0,13,3,3,8,5,0,0,5
0,0,0,0,0,0,0,0,0,5
9,0,0,0,0,0,0,0,0,0
3,0,0,0,0,0,0,0,0,0
3,0,0,0,0,0,0,0,0,0
14,0,0,0,0,0,0,0,0,0
0,0,0,0,0,0,0,0,0,0
0,0,0,0,0,0,0,5,0,0
0,0,0,0,0,0,0,0,0,0
0,0,0,0,0,0,0,0,0,0
endlayer

