
# Created by Ruins mod version 14.4 Ingame Parser
# authoring Player: Mikhaila666

weight=1
embed_into_distance=0
acceptable_target_blocks=
unacceptable_target_blocks=flowing_water,water,flowing_lava,lava
dimensions=10,15,15
allowable_overhang=0
max_leveling=2
leveling_buffer=0
preserve_water=0
preserve_lava=0

rule1=0,100,minecraft:grass-0
rule2=0,100,minecraft:dirt-0
rule3=0,100,minecraft:stonebrick-1
rule4=0,100,minecraft:stonebrick-0
rule5=0,100,minecraft:stonebrick-2
rule6=0,100,Railcraft:tile.railcraft.residual.heat-0
rule7=0,100,arsmagica2:vinteumOre-0
rule8=0,100,arsmagica2:liquidEssence-0
rule9=0,100,arsmagica2:liquidEssence-1
rule10=0,100,minecraft:stonebrick-3

layer
0,0,1,1,1,1,1,1,1,1,1,1,1,0,0
0,1,1,2,1,1,1,1,1,1,1,2,1,1,0
1,1,1,1,1,2,1,1,1,2,1,1,1,1,1
1,2,1,5,4,4,5,4,3,5,4,3,1,2,1
1,1,1,3,4,4,3,4,5,4,4,4,1,1,1
1,1,2,4,5,2,2,2,2,2,4,5,2,1,1
1,1,1,3,4,2,2,1,2,2,3,4,1,1,1
1,1,1,5,5,2,1,1,1,2,5,4,2,1,1
1,1,1,4,4,2,2,1,2,2,4,5,1,1,1
1,1,2,5,3,2,2,2,2,2,4,4,2,1,1
1,1,1,4,5,4,5,3,4,5,3,4,1,1,1
1,2,1,3,4,3,4,5,4,4,5,4,1,2,1
1,1,1,1,1,2,1,1,1,2,1,1,2,1,1
0,1,1,2,1,1,1,1,1,1,1,2,1,1,0
0,0,1,1,1,1,1,1,1,1,1,1,1,0,0
endlayer

layer
0,0,0,0,0,0,0,0,0,0,0,0,0,0,0
0,0,0,3,0,6,0,6,0,0,0,3,0,0,0
0,0,0,0,0,3,0,6,0,3,0,0,0,0,0
0,3,0,0,6,6,6,0,0,6,6,0,0,3,0
0,0,0,6,6,6,6,6,6,6,6,6,0,0,0
0,0,3,0,6,3,3,3,3,3,0,6,3,0,0
0,0,0,0,6,3,7,8,7,3,6,0,0,0,0
0,0,6,6,6,3,8,8,8,3,6,6,0,0,0
0,0,0,6,0,3,7,8,7,3,6,0,0,0,0
0,0,3,0,6,3,3,3,3,3,6,6,3,6,0
0,0,0,6,6,6,6,6,6,6,6,6,0,0,0
0,3,0,6,6,0,0,6,6,6,0,0,0,3,0
0,0,0,0,0,3,0,6,6,3,0,0,0,0,0
0,0,0,3,0,0,0,6,0,0,0,3,0,0,0
0,0,0,0,0,0,0,6,0,0,0,0,0,0,0
endlayer

layer
0,0,0,0,0,0,0,0,0,0,0,0,0,0,0
0,0,0,3,0,0,0,0,0,0,0,3,0,6,6
0,0,0,0,0,3,0,0,0,3,0,0,6,0,0
0,3,0,0,6,0,0,0,0,0,6,0,0,3,0
0,0,0,0,6,6,0,0,0,0,0,0,0,0,0
0,0,3,0,0,3,0,0,0,3,0,0,3,0,0
0,0,0,0,6,6,0,9,0,0,0,0,0,0,0
0,0,0,0,0,6,9,9,9,6,0,0,0,0,0
0,0,0,0,6,6,6,9,6,6,0,0,0,0,0
0,0,3,6,6,3,0,0,6,3,0,0,3,0,0
0,0,0,0,0,6,0,0,6,0,0,6,0,0,0
0,3,0,0,0,6,0,0,0,6,0,6,0,3,0
0,0,0,0,0,3,0,0,0,3,0,6,0,0,0
0,0,0,3,0,0,0,0,0,0,0,3,0,6,0
0,0,0,0,0,0,0,6,0,0,0,0,0,6,6
endlayer

layer
0,0,0,0,0,0,6,6,0,0,6,0,0,0,0
6,6,6,3,0,0,0,0,0,0,0,3,0,0,0
0,0,6,6,0,3,0,0,0,3,0,0,0,0,0
6,3,0,6,0,0,0,6,0,0,0,0,6,3,0
0,0,6,6,6,6,6,0,0,0,0,6,0,0,0
0,0,3,0,0,3,0,0,0,3,0,0,3,0,0
6,0,0,0,0,6,6,9,0,6,0,6,0,0,0
0,0,6,0,0,6,9,9,9,6,0,0,6,0,6
6,6,0,6,0,0,0,9,0,0,6,6,6,0,0
0,0,3,6,6,3,0,0,0,3,0,0,3,6,0
6,0,6,6,6,6,0,0,0,0,6,0,6,0,6
6,3,6,0,0,6,0,6,6,0,6,6,6,3,6
0,6,6,6,0,3,0,0,6,3,0,0,0,0,0
0,0,0,3,0,0,0,6,0,6,0,3,0,6,6
0,0,0,6,0,0,0,0,0,0,0,0,0,0,0
endlayer

layer
6,0,0,0,0,0,0,0,0,0,0,0,0,0,6
6,6,0,3,0,0,0,0,0,0,0,3,0,0,0
0,0,0,0,3,3,6,0,0,3,3,0,6,0,0
0,3,0,0,0,0,6,0,0,6,0,0,0,3,0
0,0,3,0,0,0,0,0,0,0,0,0,3,0,0
0,0,3,0,0,3,0,0,0,3,0,0,3,0,0
0,0,0,0,0,0,0,9,0,0,0,6,0,0,0
0,0,0,0,0,0,9,9,9,0,0,0,0,0,0
0,0,0,0,0,0,6,9,0,0,0,0,0,0,0
0,0,3,0,6,3,0,0,0,3,0,0,3,0,0
0,0,3,0,0,6,0,0,0,0,0,0,0,0,6
6,3,0,0,0,0,0,0,0,0,0,0,0,3,0
6,0,0,0,3,3,0,0,0,3,3,0,0,0,0
0,6,6,3,0,0,0,0,0,0,0,3,0,0,0
0,0,0,6,0,0,0,0,0,0,0,0,0,6,0
endlayer

layer
0,0,0,0,0,6,0,0,0,0,0,6,0,0,0
6,0,0,10,0,0,0,6,0,0,0,10,0,0,0
0,0,0,0,0,3,0,0,6,3,0,0,0,0,0
0,10,0,0,0,0,6,0,0,0,0,0,0,10,0
0,0,0,0,0,0,6,6,0,0,0,0,6,0,0
0,0,3,0,0,10,0,0,0,10,0,0,3,0,0
0,0,0,0,0,0,3,9,3,0,0,0,0,0,0
0,0,0,0,6,0,9,8,9,0,0,0,0,0,0
0,0,0,6,0,0,3,9,3,0,0,0,0,0,0
0,0,3,0,0,10,0,0,0,10,0,0,3,0,0
0,0,0,0,0,0,0,0,0,0,0,0,3,0,0
0,10,0,0,0,0,0,0,0,0,0,0,0,10,0
0,0,0,0,0,3,0,0,0,3,0,0,0,0,0
0,0,0,10,0,0,0,0,0,0,0,10,0,6,0
0,0,0,6,0,0,0,0,0,0,0,0,6,0,0
endlayer

layer
0,0,0,0,0,0,6,0,0,0,0,0,0,0,0
0,0,0,0,0,0,0,0,0,0,0,0,0,0,0
0,0,0,0,0,3,3,3,3,3,0,0,0,0,0
0,0,0,0,0,0,0,6,0,0,6,6,6,0,0
0,0,0,0,0,0,0,0,0,0,0,0,0,0,0
0,0,3,0,6,10,6,0,0,10,6,0,3,0,0
6,0,3,0,6,0,0,9,6,0,0,0,3,0,6
6,0,3,0,6,0,9,3,9,6,0,0,3,0,6
0,0,3,0,0,0,0,9,0,0,0,0,3,0,0
0,0,3,0,0,10,0,0,0,10,0,0,3,0,0
6,0,0,0,0,0,0,0,0,0,6,0,0,6,0
0,6,0,0,0,0,0,6,0,0,0,0,0,0,0
0,0,0,0,0,3,3,3,3,3,0,0,0,0,0
0,0,0,0,0,0,0,0,6,6,0,0,0,0,0
0,0,0,0,0,6,0,0,6,0,0,0,0,0,0
endlayer

layer
0,0,0,0,0,0,0,0,0,0,0,0,0,0,0
0,0,0,0,0,0,0,0,0,0,0,0,0,0,0
0,0,0,0,0,0,0,0,0,0,0,0,0,0,0
0,0,0,0,0,0,0,0,0,0,0,0,0,0,0
0,0,0,0,0,0,0,0,0,0,0,0,0,0,0
0,0,0,0,0,0,0,0,0,0,0,0,0,0,0
0,0,0,0,0,0,0,9,0,0,6,0,0,0,0
0,0,0,0,0,0,9,8,9,0,0,0,0,0,0
0,0,0,0,0,0,0,9,0,0,6,0,0,0,0
0,0,0,0,0,0,0,0,0,0,0,0,0,0,0
0,0,0,0,0,0,0,0,6,0,0,0,0,0,0
0,0,0,0,0,0,0,0,0,0,6,0,0,0,0
0,0,0,0,0,0,0,0,0,0,0,0,0,0,0
0,0,0,0,0,0,0,0,0,0,0,0,0,0,0
0,0,0,0,0,0,0,0,0,0,0,0,0,0,0
endlayer

layer
0,0,0,0,0,0,0,0,0,0,0,0,0,0,0
0,0,0,0,0,0,0,0,0,0,0,0,0,0,0
0,0,0,0,0,0,0,0,0,0,0,0,0,0,0
0,0,0,0,0,0,0,0,0,0,0,0,0,0,0
0,0,0,6,0,0,0,0,0,0,0,0,0,0,0
6,0,0,0,6,0,0,0,0,0,0,0,0,0,0
0,0,6,0,0,0,0,0,0,0,0,0,0,0,0
0,0,0,0,0,0,0,0,0,0,0,0,0,0,0
0,0,0,0,0,0,0,0,0,0,0,0,0,0,0
0,0,0,0,0,0,0,0,0,0,0,0,0,0,0
0,0,0,0,0,0,0,0,0,0,0,0,0,0,0
0,0,0,0,0,0,0,0,0,0,0,0,0,0,0
0,0,0,0,0,0,0,0,0,0,0,0,0,0,0
0,0,0,0,0,0,0,0,0,0,0,0,0,0,0
0,0,0,0,0,0,0,0,0,0,0,0,0,0,0
endlayer

layer
0,0,0,0,0,0,0,0,0,0,0,0,0,0,0
0,0,0,0,0,0,0,0,0,0,0,0,0,0,0
0,6,0,0,0,0,0,0,0,0,0,0,0,0,0
0,0,0,0,0,0,0,0,0,0,0,0,0,0,0
0,0,0,0,0,0,0,0,0,0,0,0,0,0,0
0,0,0,0,0,0,0,0,0,0,0,6,0,0,0
0,0,0,0,6,0,0,0,0,0,0,0,0,0,0
0,0,0,0,0,0,0,6,6,0,0,0,6,0,0
0,0,0,0,0,0,0,0,0,6,0,0,0,0,0
0,0,0,0,0,0,0,0,0,6,0,0,0,0,0
0,0,0,0,0,0,0,0,0,6,0,0,0,0,0
0,0,0,0,0,0,0,6,0,0,0,0,0,0,0
0,0,0,0,0,0,0,0,0,0,0,0,0,0,0
0,0,0,0,0,0,0,0,0,0,0,0,0,0,0
0,0,0,0,0,0,0,0,0,0,0,0,0,0,0
endlayer

