
# Created by Ruins mod version 14.4 Ingame Parser
# authoring Player: Mikhaila666

weight=1
embed_into_distance=0
acceptable_target_blocks=
unacceptable_target_blocks=flowing_water,water,flowing_lava,lava
dimensions=59,33,33
allowable_overhang=0
max_leveling=2
leveling_buffer=0
preserve_water=0
preserve_lava=0

rule1=0,100,minecraft:grass-0
rule2=0,100,minecraft:dirt-0
rule3=0,100,minecraft:stonebrick-0
rule4=0,100,minecraft:wool-14
rule5=0,100,minecraft:wool-1
rule6=0,100,minecraft:wool-4
rule7=0,100,minecraft:leaves-0
rule8=0,100,minecraft:log-0
rule9=0,100,Railcraft:tile.railcraft.residual.heat-0
rule10=0,100,MobSpawner:Witch
rule11=0,100,IInventory;minecraft:chest;minecraft:paper#5#0#1+HardcoreEnderExpansion:adventurers_diary#1#0#8+HardcoreEnderExpansion:knowledge_note#1#0#14+HardcoreEnderExpansion:knowledge_note#1#0#16+HardcoreEnderExpansion:adventurers_diary#1#0#17+minecraft:book#3#0#22+HardcoreEnderExpansion:adventurers_diary#1#0#26-2
rule12=0,100,minecraft:planks-0
rule13=0,100,minecraft:wooden_slab-8
rule14=0,100,minecraft:wooden_slab-0
rule15=0,100,IInventory;minecraft:chest;HardcoreEnderExpansion:adventurers_diary#1#0#2+minecraft:book#2#0#7+HardcoreEnderExpansion:knowledge_note#1#0#11+TConstruct:broadsword#1#0#12+minecraft:book#2#0#13+minecraft:map#1#0#15+minecraft:book#1#0#18+minecraft:compass#1#0#19+minecraft:book#3#0#22+minecraft:book#1#0#26-2
rule16=0,100,IInventory;minecraft:chest;minecraft:rotten_flesh#5#0#0+minecraft:diamond#3#0#1+ExtraUtilities:divisionSigil#1#0#6+harvestcraft:baconmushroomburgerItem#0#0#7+HardcoreEnderExpansion:knowledge_note#1#0#9+HardcoreEnderExpansion:knowledge_note#1#0#10+HardcoreEnderExpansion:temple_caller#1#0#12+minecraft:gold_ingot#6#0#16+ExtraUtilities:divisionSigil#1#0#21-4
rule17=0,100,IInventory;minecraft:chest;minecraft:gold_ingot#3#0#2+minecraft:iron_ingot#1#0#7+harvestcraft:heartybreakfastItem#1#0#10+TConstruct:broadsword#1#0#15+minecraft:iron_ingot#1#0#19+ExtraUtilities:divisionSigil#1#0#20+minecraft:gold_ingot#7#0#24+minecraft:gold_ingot#7#0#25-4
rule18=0,100,minecraft:double_wooden_slab-0
rule19=0,100,MobSpawner:Spider
rule20=0,100,minecraft:web-0
rule21=0,100,minecraft:monster_egg-2
rule22=0,100,IInventory;minecraft:chest;minecraft:iron_ingot#1#0#3+minecraft:bread#1#0#4+minecraft:gold_ingot#3#0#7+minecraft:iron_ingot#4#0#9+minecraft:ender_pearl#1#0#12+minecraft:gold_ingot#2#0#14+HardcoreEnderExpansion:knowledge_note#1#0#18+minecraft:apple#1#0#24-5
rule23=0,100,IInventory;minecraft:chest;minecraft:apple#1#0#3+HardcoreEnderExpansion:adventurers_diary#1#0#6+minecraft:ender_pearl#1#0#7+minecraft:iron_helmet#1#0#9+minecraft:bread#2#0#12+minecraft:bread#1#0#15+minecraft:iron_ingot#3#0#22+minecraft:diamond_horse_armor#1#0#25-5
rule24=0,100,IInventory;minecraft:chest;minecraft:paper#3#0#1+HardcoreEnderExpansion:knowledge_note#1#0#2+HardcoreEnderExpansion:adventurers_diary#1#0#6+minecraft:enchanted_book#1#0#10+minecraft:book#2#0#11+minecraft:enchanted_book#1#0#14+minecraft:enchanted_book#1#0#16+minecraft:paper#7#0#17+minecraft:book#2#0#20+minecraft:paper#3#0#24-2
rule25=0,100,IInventory;minecraft:chest;minecraft:book#2#0#2+HardcoreEnderExpansion:knowledge_note#1#0#3+minecraft:enchanted_book#1#0#4+minecraft:enchanted_book#1#0#6+minecraft:paper#6#0#7+HardcoreEnderExpansion:knowledge_note#1#0#11+minecraft:paper#7#0#13+minecraft:enchanted_book#1#0#16+HardcoreEnderExpansion:adventurers_diary#1#0#19+minecraft:enchanted_book#1#0#21+minecraft:paper#5#0#25+minecraft:enchanted_book#1#0#26-2
rule26=0,100,minecraft:tallgrass-0
rule27=0,100,minecraft:yellow_flower-0
rule28=0,100,minecraft:stone_brick_stairs-5
rule29=0,100,minecraft:stone_brick_stairs-4
rule30=0,100,minecraft:stonebrick-3
rule31=0,100,minecraft:leaves-8
rule32=0,100,minecraft:stonebrick-2
rule33=0,100,MobSpawner:Zombie
rule34=0,100,IInventory;minecraft:chest;minecraft:enchanted_book#1#0#2+minecraft:bread#3#0#5+HardcoreEnderExpansion:knowledge_note#1#0#7+HardcoreEnderExpansion:adventurers_diary#1#0#11+minecraft:ender_pearl#1#0#16+minecraft:iron_helmet#1#0#18+minecraft:bread#3#0#19+minecraft:iron_leggings#1#0#25-5
rule35=0,100,IInventory;minecraft:chest;minecraft:bread#2#0#8+minecraft:bread#1#0#9+HardcoreEnderExpansion:adventurers_diary#1#0#16+minecraft:bread#3#0#17+HardcoreEnderExpansion:adventurers_diary#1#0#18+minecraft:bread#1#0#23+minecraft:iron_ingot#3#0#25+minecraft:iron_horse_armor#1#0#26-5
rule36=0,100,IInventory;minecraft:chest;minecraft:iron_pickaxe#1#0#0+minecraft:bread#1#0#4+minecraft:bread#2#0#10+minecraft:iron_ingot#3#0#11+minecraft:bread#3#0#14+minecraft:redstone#9#0#15+HardcoreEnderExpansion:knowledge_note#1#0#17+minecraft:bread#2#0#20+minecraft:iron_chestplate#1#0#24-5
rule37=0,100,IInventory;minecraft:chest;HardcoreEnderExpansion:knowledge_note#1#0#3+HardcoreEnderExpansion:knowledge_note#1#0#5+minecraft:compass#1#0#7+minecraft:book#1#0#15+minecraft:map#1#0#23+minecraft:book#2#0#25-2
rule38=0,100,minecraft:stone_brick_stairs-3
rule39=0,100,minecraft:stone_brick_stairs-1
rule40=0,100,IInventory;minecraft:chest;harvestcraft:deluxecheeseburgerItem#2#0#1+minecraft:rotten_flesh#6#0#10+TConstruct:broadsword#1#0#11+harvestcraft:delightedmealItem#0#0#14+harvestcraft:curryItem#0#0#15+ExtraUtilities:divisionSigil#1#0#16+minecraft:iron_ingot#4#0#18+harvestcraft:heartybreakfastItem#0#0#22+minecraft:bone#5#0#25-4
rule41=0,100,IInventory;minecraft:chest;HardcoreEnderExpansion:temple_caller#1#0#3+minecraft:iron_ingot#5#0#10+minecraft:iron_ingot#5#0#11+harvestcraft:curryItem#0#0#12+harvestcraft:deluxecheeseburgerItem#2#0#18+minecraft:diamond#3#0#19+minecraft:iron_ingot#2#0#21+harvestcraft:curryItem#2#0#26-4
rule42=0,100,IInventory;minecraft:chest;minecraft:rotten_flesh#6#0#1+minecraft:bone#4#0#5+HardcoreEnderExpansion:knowledge_note#1#0#7+minecraft:bone#5#0#9+HardcoreEnderExpansion:knowledge_note#1#0#14+harvestcraft:supremepizzaItem#1#0#19+minecraft:gold_ingot#3#0#22+minecraft:saddle#1#0#26-4
rule43=0,100,IInventory;minecraft:chest;harvestcraft:delightedmealItem#0#0#0+minecraft:iron_ingot#2#0#1+minecraft:bone#4#0#3+HardcoreEnderExpansion:knowledge_note#1#0#7+minecraft:diamond#3#0#10+minecraft:rotten_flesh#3#0#16+minecraft:gold_ingot#5#0#17+minecraft:rotten_flesh#5#0#21+minecraft:gold_ingot#6#0#24+harvestcraft:rainbowcurryItem#0#0#25-4
rule44=0,100,minecraft:stone_brick_stairs-0
rule45=0,100,MobSpawner:Skeleton
rule46=0,100,minecraft:monster_egg-5
rule47=0,100,minecraft:stone_slab-8
rule48=0,100,minecraft:stone_slab-0
rule49=0,100,minecraft:cauldron-3
rule50=0,100,minecraft:double_stone_slab-0
rule51=0,100,minecraft:stone_slab-13
rule52=0,100,minecraft:stone_slab-5
rule53=0,100,minecraft:double_stone_slab-5
rule54=0,100,minecraft:stone_brick_stairs-7
rule55=0,100,minecraft:stone_brick_stairs-6
rule56=0,100,minecraft:brewing_stand-0
rule57=0,100,minecraft:stone_brick_stairs-2
rule58=0,100,minecraft:bookshelf-0
rule59=0,100,IInventory;minecraft:chest;minecraft:book#1#0#0+minecraft:paper#3#0#3+minecraft:book#1#0#4+HardcoreEnderExpansion:adventurers_diary#1#0#12+minecraft:book#1#0#13+minecraft:paper#6#0#14+minecraft:paper#4#0#16+HardcoreEnderExpansion:adventurers_diary#1#0#17+minecraft:paper#6#0#24-2
rule60=0,100,IInventory;minecraft:chest;minecraft:paper#5#0#3+minecraft:enchanted_book#1#0#7+minecraft:enchanted_book#1#0#14+minecraft:enchanted_book#1#0#19+HardcoreEnderExpansion:knowledge_note#1#0#20+minecraft:paper#4#0#21+minecraft:book#3#0#26-2
rule61=0,100,IInventory;minecraft:chest;minecraft:paper#4#0#2+HardcoreEnderExpansion:knowledge_note#1#0#3+minecraft:paper#3#0#4+HardcoreEnderExpansion:knowledge_note#1#0#9+minecraft:enchanted_book#1#0#11+minecraft:book#1#0#12+minecraft:book#1#0#13+minecraft:map#1#0#17+minecraft:enchanted_book#1#0#23+minecraft:paper#2#0#24-2
rule62=0,100,IInventory;minecraft:chest;HardcoreEnderExpansion:adventurers_diary#1#0#0+minecraft:paper#6#0#3+HardcoreEnderExpansion:temple_caller#1#0#4+minecraft:book#1#0#7+HardcoreEnderExpansion:adventurers_diary#1#0#20+minecraft:paper#5#0#22+HardcoreEnderExpansion:knowledge_note#1#0#24-2
rule63=0,100,minecraft:log2-9
rule64=0,100,minecraft:log2-5
rule65=0,100,minecraft:stonebrick-5
rule66=0,100,MobSpawner:Silverfish
rule67=0,100,minecraft:stonebrick-1
rule68=0,100,minecraft:stained_glass_pane-3
rule69=0,100,minecraft:stained_glass_pane-4
rule70=0,100,minecraft:stained_glass_pane-1
rule71=0,100,minecraft:glowstone-0

layer
0,0,0,0,0,0,0,0,0,0,0,0,0,0,0,0,0,0,0,0,0,0,0,0,0,0,0,0,0,0,0,0,0
0,0,0,0,0,0,0,0,0,0,0,0,0,0,0,0,0,0,0,0,0,0,0,0,0,0,0,0,0,0,0,0,0
0,0,1,1,1,1,1,1,1,1,1,1,1,1,1,1,1,1,1,1,1,1,1,1,1,1,1,1,1,1,1,0,0
0,0,1,1,1,1,1,1,1,1,1,1,1,1,1,1,1,1,1,1,1,1,1,1,1,1,1,1,1,1,1,0,0
0,0,1,1,1,1,1,1,1,1,1,1,1,1,1,1,1,1,1,1,1,1,1,1,1,1,1,1,1,1,1,0,0
0,0,1,1,1,1,1,1,1,1,1,1,1,1,1,1,1,1,1,1,1,1,1,2,1,1,1,1,1,1,1,0,0
0,0,1,1,1,1,1,1,1,1,1,1,1,1,1,1,1,1,1,1,1,1,1,1,1,1,1,1,1,1,1,0,0
0,0,1,1,1,1,1,2,1,1,1,1,1,1,2,2,2,2,2,1,1,1,1,1,1,1,1,1,1,1,1,0,0
0,0,1,1,1,1,1,1,2,2,1,2,2,2,2,2,2,3,3,2,2,2,1,1,1,1,1,1,1,1,1,0,0
0,0,1,1,1,1,1,1,2,2,2,4,4,4,2,2,2,3,3,3,3,3,2,2,1,2,1,1,1,1,1,0,0
0,0,1,1,1,1,1,1,1,2,4,4,4,4,2,2,2,2,2,3,3,3,3,2,1,1,1,1,1,1,1,0,0
0,0,1,1,1,1,2,1,2,4,4,4,4,4,4,4,4,4,4,2,2,2,3,2,2,1,1,1,1,1,1,0,0
0,0,1,1,1,1,1,1,2,4,4,4,4,4,4,5,5,4,4,4,4,4,4,4,2,1,2,1,1,1,1,0,0
0,0,1,1,1,1,1,1,2,4,4,4,5,5,5,4,4,5,5,5,4,4,4,4,2,1,1,1,1,1,1,0,0
0,0,1,1,1,1,1,2,4,4,4,5,4,4,4,6,4,4,4,5,5,4,4,4,4,2,1,1,1,1,1,0,0
0,0,1,1,1,1,1,1,4,4,5,4,6,6,6,6,4,6,4,4,4,5,4,4,4,2,1,1,1,1,1,0,0
0,0,1,1,1,1,1,1,4,4,5,4,6,4,4,4,6,4,6,6,4,5,4,4,4,2,1,1,1,1,1,0,0
0,0,1,1,1,1,1,1,4,4,5,4,6,6,6,6,4,6,4,4,4,5,4,4,4,2,2,1,1,1,1,0,0
0,0,1,1,1,1,1,2,4,4,4,5,4,4,4,6,4,4,4,5,5,4,4,4,4,2,1,1,1,1,1,0,0
0,0,1,1,1,2,1,1,2,4,4,4,5,5,5,4,4,5,5,4,4,4,4,4,2,1,1,1,1,1,1,0,0
0,0,1,1,1,1,1,1,2,4,4,4,4,4,4,5,5,4,4,4,4,4,4,4,2,1,2,1,1,1,1,0,0
0,0,1,1,1,1,1,1,2,4,4,4,4,4,4,4,4,4,4,2,2,2,3,2,2,1,1,1,1,1,1,0,0
0,0,1,1,1,1,1,1,1,2,4,4,4,4,2,2,2,2,2,3,3,3,3,2,1,1,1,1,1,1,1,0,0
0,0,1,1,1,1,1,1,1,1,2,4,4,4,2,2,2,3,3,3,3,3,2,2,1,1,1,1,1,1,1,0,0
0,0,1,1,1,1,1,2,1,1,1,2,2,2,2,2,2,3,3,2,2,2,2,2,1,1,1,1,1,1,1,0,0
0,0,1,1,1,1,1,1,1,1,1,1,1,1,2,2,2,2,2,1,1,1,1,1,1,1,1,1,1,1,1,0,0
0,0,1,1,1,1,1,2,2,1,1,1,1,1,1,1,1,1,1,1,1,1,1,1,1,2,1,1,1,1,1,0,0
0,0,1,1,1,1,1,2,2,1,1,1,1,1,1,1,1,1,1,1,1,1,1,1,1,1,1,1,1,1,1,0,0
0,0,1,1,1,1,1,1,1,1,2,1,1,1,1,2,1,1,1,1,1,2,1,1,1,1,1,1,1,1,1,0,0
0,0,1,1,1,1,1,1,1,1,1,1,1,1,1,1,1,1,1,1,1,1,1,1,1,1,1,1,1,1,1,0,0
0,0,1,1,1,1,1,1,1,1,1,1,1,1,1,1,1,1,1,1,1,1,1,1,1,1,1,1,1,1,1,0,0
0,0,0,0,0,0,0,0,0,0,0,0,0,0,0,0,0,0,0,0,0,0,0,0,0,0,0,0,0,0,0,0,0
0,0,0,0,0,0,0,0,0,0,0,0,0,0,0,0,0,0,0,0,0,0,0,0,0,0,0,0,0,0,0,0,0
endlayer

layer
0,0,0,0,0,0,0,0,0,0,0,0,0,0,0,0,0,0,0,0,0,0,0,0,0,0,0,0,0,0,0,0,0
0,0,0,0,0,0,0,0,0,0,0,0,0,0,0,0,0,0,0,0,0,0,0,0,0,0,0,0,0,0,0,0,0
0,0,0,0,0,0,0,0,0,0,0,0,7,7,7,7,0,0,0,0,0,0,0,0,0,0,0,0,0,0,0,0,0
0,0,0,0,0,0,0,0,0,0,0,7,7,7,7,7,0,0,7,7,7,0,7,7,7,0,0,0,0,0,0,0,0
0,0,0,0,0,0,0,0,0,0,0,7,7,8,7,7,0,7,7,7,7,7,7,7,7,7,0,0,0,0,0,0,0
0,0,0,0,0,7,7,7,7,0,7,7,7,7,7,7,0,7,7,8,7,7,7,8,7,7,0,0,0,0,0,0,0
0,0,0,0,0,7,7,7,7,7,7,7,7,7,7,0,0,7,7,7,7,7,7,7,7,7,9,0,0,0,0,0,0
0,0,0,0,0,7,7,8,7,7,7,8,7,7,3,3,3,3,3,7,7,7,7,7,7,7,7,0,0,0,0,0,0
0,0,0,0,0,7,7,7,8,8,7,3,3,3,14,13,12,11,10,3,3,3,0,7,7,7,7,7,0,0,0,0,0
0,0,0,0,0,7,7,7,8,8,3,7,7,7,14,13,12,15,9,9,0,9,8,8,7,8,7,7,0,0,0,0,0
0,0,0,0,7,7,7,7,7,3,0,0,0,0,14,18,12,12,12,17,16,9,8,8,7,7,7,7,0,0,0,0,0
0,0,0,0,7,7,8,7,3,0,0,0,0,0,9,20,20,20,19,12,12,12,12,12,3,7,7,7,7,0,0,0,0
0,0,0,0,7,7,7,7,3,0,0,0,0,9,9,9,20,20,20,0,20,0,9,0,3,7,8,7,7,0,0,0,0
0,0,0,0,7,7,7,7,3,0,0,0,0,0,9,0,20,20,0,0,0,0,0,0,3,7,7,7,7,0,0,0,0
0,0,0,7,7,7,7,3,0,20,0,0,0,0,0,0,0,0,0,0,9,20,9,0,7,3,7,7,0,0,0,0,0
0,0,0,7,7,8,7,20,20,20,9,0,0,0,0,0,0,0,0,20,0,20,0,20,20,3,7,7,0,0,0,0,0
0,0,0,7,7,7,7,20,20,20,20,0,0,0,9,0,20,0,0,0,20,0,0,0,7,3,7,7,7,0,0,0,0
0,0,0,7,7,7,7,20,20,20,9,0,9,9,0,0,0,0,9,0,9,0,20,0,20,3,8,7,7,0,0,0,0
0,0,9,7,7,7,7,3,0,0,0,0,9,9,0,0,0,0,0,0,9,20,9,0,20,3,7,7,7,0,0,0,0
0,0,0,7,7,8,7,7,3,0,0,20,20,9,9,9,0,20,0,0,0,0,0,0,3,7,7,7,7,0,0,0,0
0,0,0,7,7,7,7,7,3,0,0,0,20,20,20,0,0,0,0,20,0,0,9,0,21,7,8,7,7,0,0,0,0
0,0,0,0,7,7,7,7,3,0,0,0,20,0,0,0,0,0,0,12,12,12,12,12,3,7,7,7,7,0,0,0,0
0,0,0,0,0,7,7,7,7,3,19,20,20,0,14,18,12,12,12,23,22,9,9,3,0,7,7,7,0,0,0,0,0
0,0,0,0,0,7,7,7,7,7,3,20,0,0,14,13,12,24,0,9,9,0,8,8,0,0,0,0,0,0,0,0,0
0,0,0,0,0,7,7,8,7,7,0,3,3,3,14,13,12,25,10,3,3,3,8,8,7,7,7,0,0,0,0,0,0
0,0,0,26,0,7,7,7,7,7,0,0,0,0,3,3,3,3,3,0,0,0,0,7,7,7,7,7,0,0,0,0,0
0,0,0,0,0,7,7,8,8,7,7,7,0,7,7,7,7,7,0,0,7,7,7,7,7,8,7,7,0,0,0,0,0
0,0,0,0,0,0,0,8,8,7,7,7,7,7,7,7,7,7,0,7,7,7,7,7,7,7,7,7,0,26,26,0,0
0,0,27,0,0,0,0,0,7,7,8,7,7,7,7,8,7,7,0,7,7,8,7,7,7,7,7,7,0,26,0,0,0
0,0,27,0,26,0,0,0,7,7,7,7,7,7,7,7,7,7,0,7,7,7,7,7,0,0,0,0,0,0,0,0,0
0,0,0,0,27,27,0,0,7,7,7,7,0,0,7,7,7,0,0,0,7,7,7,0,0,0,0,26,0,0,0,0,0
0,0,0,0,0,0,0,0,0,0,0,0,0,0,0,0,0,0,0,0,0,0,0,0,0,0,0,0,0,0,0,0,0
0,0,0,9,0,9,9,0,0,9,0,0,0,9,0,0,0,9,0,0,0,9,0,0,0,0,0,0,0,0,0,0,0
endlayer

layer
0,0,0,0,0,0,0,0,0,0,0,0,0,0,0,0,0,0,0,0,0,0,0,0,0,0,0,0,0,0,0,0,0
0,0,0,0,0,0,0,0,0,0,9,9,0,0,0,0,0,0,0,0,9,0,0,0,0,0,0,9,0,0,0,0,0
0,0,0,0,0,0,0,0,0,0,0,0,0,0,0,0,0,0,0,0,0,0,0,0,0,0,0,0,0,0,0,0,0
0,0,0,0,0,0,0,0,0,0,0,9,0,7,7,0,0,0,0,0,0,0,9,0,0,0,0,0,0,0,0,0,0
0,0,0,0,0,0,0,0,0,9,0,0,7,7,7,0,9,0,0,7,7,0,7,7,0,9,0,0,0,0,0,0,0
0,0,0,0,0,9,0,0,0,9,0,0,7,7,7,0,0,0,7,7,7,0,7,7,7,0,9,0,0,0,0,0,0
0,0,0,0,0,0,7,7,7,0,0,7,0,0,0,0,0,0,0,7,7,0,0,7,7,0,9,0,0,0,0,0,0
0,0,0,0,0,9,7,7,7,0,7,7,7,0,3,3,3,3,3,0,0,0,0,0,0,0,0,0,0,0,0,0,0
0,0,0,0,0,0,7,7,8,8,7,3,3,3,0,0,14,13,0,3,3,3,0,0,7,7,0,0,0,0,0,0,0
0,0,0,0,0,0,0,0,8,8,3,0,0,0,0,0,14,13,0,0,0,0,8,8,7,7,7,0,0,0,0,0,0
0,0,0,0,0,0,7,0,0,3,0,0,0,0,0,0,14,18,12,0,0,0,8,8,7,7,0,0,0,0,0,0,0
0,0,0,0,0,7,7,7,3,0,0,0,0,0,0,0,0,20,20,12,12,12,12,12,3,7,7,0,0,0,0,0,0
0,0,0,0,9,7,7,7,3,0,0,0,0,0,0,20,20,0,0,0,0,0,20,0,3,7,7,7,0,0,0,0,0
0,0,0,0,0,0,0,0,3,0,0,0,0,0,0,20,20,0,0,0,0,0,0,20,3,0,7,7,0,0,0,0,0
0,0,0,0,0,7,7,3,0,0,0,0,0,0,0,0,0,0,0,0,0,0,0,0,0,3,0,0,0,0,0,0,9
0,0,0,0,7,7,20,20,0,0,0,0,0,0,0,0,0,0,0,0,0,0,0,0,0,3,0,0,0,0,0,0,0
0,0,0,9,0,7,20,20,0,0,0,0,0,0,0,0,0,0,20,20,20,0,0,0,0,3,7,7,0,0,0,0,0
0,0,0,0,0,0,20,0,0,0,0,0,0,0,0,0,0,0,0,0,0,0,0,0,0,3,7,7,0,0,0,0,0
0,0,0,0,0,7,0,3,0,0,0,0,0,0,0,0,0,0,0,0,0,0,0,0,20,3,7,7,0,0,0,0,0
0,9,0,0,7,7,7,0,3,0,0,20,20,0,0,0,0,20,20,0,0,20,0,0,3,7,7,7,0,0,0,0,0
0,0,0,9,7,7,0,0,3,20,20,20,20,0,20,0,0,0,20,20,20,20,0,0,3,7,7,7,0,0,0,0,0
0,0,0,9,0,9,0,0,3,20,0,0,0,0,0,0,0,0,20,12,12,12,12,12,3,7,7,7,0,0,0,0,0
0,0,0,0,0,9,0,0,0,3,20,20,0,0,0,0,14,18,12,0,0,0,0,3,0,0,0,0,0,0,0,0,0
0,0,0,0,0,0,0,7,7,0,3,20,0,0,0,0,14,13,0,0,0,0,8,8,0,0,0,0,0,0,0,0,0
0,0,0,0,0,0,7,7,7,0,0,3,3,3,0,0,14,13,0,3,3,3,8,8,0,0,9,0,0,0,0,0,0
0,0,0,0,0,0,7,7,0,0,0,0,0,0,3,3,3,3,3,0,0,0,0,0,0,7,7,0,0,0,0,0,0
0,0,0,0,0,0,0,8,8,0,0,0,0,0,0,0,0,0,0,0,0,0,0,0,7,7,7,0,0,0,0,0,0
0,0,0,0,0,0,0,8,8,0,7,0,0,0,0,7,0,0,0,0,0,7,7,9,9,7,7,0,0,9,0,0,0
0,0,0,0,0,0,0,0,0,7,7,7,0,0,7,7,7,0,0,0,7,7,7,0,0,0,0,0,0,0,0,0,0
0,0,0,0,0,0,0,0,0,7,7,7,9,0,0,7,7,0,0,0,7,7,0,0,0,0,0,0,0,0,0,0,0
0,0,0,0,0,0,0,0,0,0,0,0,0,0,0,0,0,0,0,0,0,0,0,0,0,0,0,0,0,0,0,0,0
0,0,0,0,0,0,0,0,0,0,0,0,9,0,0,0,0,0,0,0,0,0,0,0,0,0,0,0,0,0,0,0,0
0,0,0,0,0,0,0,0,0,0,0,0,0,0,0,0,0,0,0,0,0,0,0,0,0,0,0,0,0,0,0,0,0
endlayer

layer
0,0,0,0,0,0,0,0,0,0,0,0,0,0,0,0,0,0,0,0,0,0,0,0,0,0,0,0,0,0,0,0,0
0,0,0,0,0,0,0,0,0,0,0,0,0,0,0,0,0,0,0,0,0,0,0,0,0,0,0,0,0,0,0,0,0
0,0,0,0,0,0,0,0,0,0,0,0,0,0,0,0,0,0,0,0,0,0,0,0,0,0,0,0,0,0,0,0,0
0,0,0,0,0,0,0,0,0,0,0,0,0,0,0,0,0,0,0,0,0,0,0,0,0,0,0,0,0,0,0,0,0
0,0,0,0,0,0,0,0,0,0,0,0,0,0,0,0,0,0,0,0,0,0,0,0,0,0,0,0,0,0,0,0,0
0,0,0,0,0,0,0,0,0,0,0,0,0,0,0,0,0,0,0,7,0,0,0,0,0,0,0,0,0,0,0,0,0
0,0,0,0,0,0,0,0,0,0,0,0,0,0,0,0,0,0,0,0,0,0,0,0,0,0,0,0,0,0,0,0,0
0,0,0,0,0,0,0,0,0,0,0,7,0,0,3,3,3,3,3,0,0,0,0,0,0,0,0,0,0,0,0,0,0
0,0,0,0,0,0,0,0,8,8,0,3,3,3,0,0,0,0,14,3,3,3,0,0,0,0,0,0,0,0,0,0,0
0,0,0,0,0,0,0,0,8,8,3,0,0,0,0,0,0,0,14,13,0,0,8,8,0,0,0,0,0,0,0,0,0
0,0,0,0,0,0,0,0,0,3,0,0,0,0,0,0,0,0,14,13,0,0,8,8,0,0,0,0,0,0,0,0,0
0,0,0,0,0,0,0,0,3,0,0,0,0,0,0,0,0,0,0,18,12,12,12,12,3,0,0,0,0,0,0,0,0
0,0,0,0,0,0,0,0,3,0,0,0,0,0,0,0,0,0,0,0,0,0,0,0,3,0,0,0,0,0,0,0,0
0,0,0,0,0,0,0,0,3,0,0,0,0,9,9,0,0,0,0,0,0,0,0,20,3,0,0,0,0,0,0,0,0
0,0,0,0,0,0,0,3,0,0,0,0,0,0,0,0,0,0,0,0,0,0,0,0,0,3,0,0,0,0,0,0,0
0,0,0,0,0,7,0,28,0,0,0,0,0,0,0,0,0,0,0,0,0,0,0,0,20,3,0,0,0,0,0,0,0
0,0,0,0,0,0,20,20,0,0,0,0,0,0,0,0,0,0,0,0,0,0,0,0,0,3,0,0,0,0,0,0,0
0,0,0,0,0,0,0,29,0,0,0,0,0,0,0,0,0,0,0,0,9,0,0,20,20,3,7,0,0,0,0,0,0
0,0,0,0,0,0,0,3,0,0,0,0,0,0,0,0,0,0,9,0,0,0,0,0,20,3,0,0,0,0,0,0,0
0,9,0,0,0,7,0,0,3,0,0,0,20,0,0,0,0,0,0,0,0,0,0,20,3,0,9,0,0,0,0,0,0
0,0,0,0,0,0,0,0,3,0,0,0,0,0,0,0,0,0,0,0,0,0,0,20,3,0,7,0,0,0,0,0,0
0,0,0,0,0,0,0,0,3,20,0,0,0,0,0,0,0,0,0,18,12,12,12,12,3,0,0,0,0,0,0,0,0
0,0,0,0,0,0,0,0,0,3,20,0,0,0,0,0,0,20,14,13,0,0,0,3,0,0,0,0,0,0,0,0,0
0,0,0,0,0,0,0,0,0,0,3,0,0,0,0,0,0,0,14,13,0,0,8,8,0,0,0,0,0,0,0,9,0
0,0,0,0,0,0,0,0,0,0,0,3,3,3,0,0,20,0,14,3,3,3,8,8,0,0,0,0,0,0,0,0,0
0,0,0,0,0,0,0,0,0,0,0,0,0,0,3,3,3,3,3,0,0,0,0,0,0,0,0,9,0,0,0,0,0
0,0,0,0,0,0,0,8,8,0,0,0,0,0,0,0,0,0,0,0,0,0,0,0,0,9,0,0,9,0,0,0,0
0,0,0,0,0,0,0,8,8,0,0,0,0,0,0,0,0,0,0,0,0,0,0,0,0,0,0,0,0,0,0,0,0
0,0,0,0,0,0,0,0,0,0,7,0,0,0,0,7,0,0,0,0,0,7,0,0,0,0,0,0,0,0,0,0,0
0,0,0,0,0,0,0,0,0,0,0,0,0,0,0,0,9,0,9,0,0,0,9,0,0,0,0,0,0,0,0,0,0
0,0,0,0,0,0,0,0,0,9,9,9,0,0,0,0,0,0,0,0,0,0,0,0,0,0,0,0,0,0,0,0,0
0,0,0,0,0,0,0,0,0,0,0,9,0,0,0,0,0,0,0,0,0,0,0,0,0,0,0,0,0,0,0,0,0
0,0,0,0,0,0,0,0,0,0,0,0,0,0,0,0,0,0,0,0,0,0,0,9,0,0,0,0,0,0,0,0,0
endlayer

layer
0,0,0,0,0,0,0,0,0,0,0,0,0,0,0,0,0,0,0,0,0,0,0,0,0,0,0,0,0,0,0,0,0
0,0,0,0,0,0,0,0,0,0,0,0,0,0,0,0,0,0,0,0,0,0,0,0,0,0,0,0,0,0,0,0,0
0,0,0,0,0,0,0,0,0,0,0,0,0,0,0,0,0,0,0,0,0,0,0,0,0,0,0,0,0,0,0,0,0
0,0,0,0,0,0,0,0,0,0,0,0,9,0,0,0,9,0,0,0,0,0,0,0,0,0,0,0,0,0,0,0,0
0,0,0,0,0,0,0,0,0,0,0,0,0,0,0,0,0,0,0,9,0,0,9,0,0,0,0,0,0,0,0,0,0
0,0,0,0,0,0,0,0,0,0,0,0,0,0,0,0,0,0,0,0,0,0,0,0,0,0,0,0,0,0,0,0,0
0,0,0,0,0,0,0,0,0,0,0,0,0,0,0,0,0,0,0,0,0,0,0,0,9,0,0,0,0,0,0,0,0
0,0,0,0,0,0,0,0,0,0,0,0,0,0,3,3,3,3,3,0,0,0,0,0,0,0,0,0,0,0,0,0,0
0,0,0,0,0,0,0,0,8,8,0,3,3,3,0,0,0,0,0,3,3,3,0,0,0,0,0,0,0,0,0,0,0
0,0,0,0,0,0,0,0,8,8,3,0,0,0,0,0,0,0,0,0,14,13,8,8,0,0,0,0,0,0,0,0,0
0,0,0,0,0,0,0,0,0,3,0,0,0,0,0,0,0,0,9,0,14,13,8,8,0,0,0,0,0,0,0,0,0
0,0,0,0,0,0,0,0,3,0,0,0,0,0,0,0,0,0,0,0,14,18,12,12,3,0,9,0,0,0,0,0,0
0,0,0,0,0,0,0,0,3,0,0,0,0,0,0,0,0,0,0,0,0,0,0,0,3,0,0,0,0,0,0,0,0
0,0,0,0,0,0,0,0,3,0,0,0,0,0,0,0,0,0,0,0,0,0,0,0,3,0,0,0,0,0,0,0,0
0,0,0,0,0,0,0,3,0,0,0,0,0,0,0,0,0,0,0,0,0,0,0,0,0,3,9,0,0,0,0,0,0
0,0,0,0,0,0,0,3,0,0,0,0,0,0,0,9,0,0,0,0,0,0,0,0,0,3,0,0,0,0,0,0,0
0,0,0,0,0,0,0,3,0,0,0,0,9,0,0,0,0,0,0,0,0,0,0,0,20,3,0,0,0,0,0,0,0
0,0,0,0,0,0,0,3,0,0,0,0,0,0,0,0,0,0,0,0,0,0,0,0,0,3,9,0,0,0,0,0,0
0,0,0,0,0,0,0,3,20,0,0,9,0,0,0,0,0,0,0,0,0,0,0,0,0,3,0,0,0,0,0,0,0
0,0,0,0,0,0,0,0,3,0,0,0,0,0,0,0,0,0,0,0,0,0,0,0,3,0,0,0,0,0,0,0,0
0,0,0,0,0,0,0,0,3,20,0,0,0,0,0,0,0,0,0,0,0,20,0,0,3,0,0,0,0,0,0,0,0
0,0,0,0,0,0,0,0,3,0,0,0,0,0,9,0,0,0,0,0,14,18,12,12,3,0,9,0,0,0,0,0,0
0,0,0,0,0,0,0,0,0,3,0,0,0,0,0,0,0,0,20,20,14,13,0,3,0,0,0,0,0,0,0,0,0
0,0,0,0,0,0,0,0,0,0,3,0,0,0,0,0,0,0,20,20,14,13,8,8,0,0,0,0,0,0,0,0,0
0,0,0,0,0,0,0,0,0,0,0,3,3,3,0,0,0,0,0,3,3,3,8,8,0,9,9,0,0,0,0,0,0
0,0,0,0,0,0,0,0,0,0,0,0,0,0,3,3,3,3,3,0,0,0,0,0,0,0,0,0,0,0,0,0,0
0,0,0,0,0,0,0,8,8,0,0,0,0,0,0,0,0,0,0,0,0,0,0,0,0,0,0,0,0,0,0,0,0
0,0,0,0,0,0,0,8,8,0,0,0,0,0,0,0,0,0,0,0,0,0,0,0,0,0,0,0,0,0,0,0,0
0,0,0,0,0,0,0,0,0,0,0,0,0,0,0,0,0,0,0,0,0,0,0,0,0,0,0,0,0,0,0,0,0
0,0,0,0,0,0,0,0,0,0,0,0,0,0,0,0,0,0,0,0,0,0,0,0,0,0,0,0,0,0,0,0,0
0,0,0,0,0,0,0,0,0,0,0,0,0,0,0,0,0,0,0,0,0,0,0,0,0,0,0,0,0,0,0,0,0
0,0,0,0,0,0,0,0,0,0,0,0,0,0,0,0,0,0,0,0,0,0,0,0,0,0,0,0,0,0,0,0,0
0,0,0,0,0,0,0,0,0,0,0,0,0,0,0,0,0,0,0,0,0,0,0,0,0,0,0,0,0,0,0,0,0
endlayer

layer
0,0,0,0,0,0,0,0,0,0,0,0,0,0,0,0,0,0,0,0,0,0,0,0,0,0,0,0,0,0,0,0,0
0,0,0,0,0,0,0,0,0,0,0,0,0,0,0,0,0,0,0,0,0,0,0,0,0,0,0,0,0,0,0,0,0
0,0,0,0,0,0,0,0,0,0,0,0,0,0,0,0,0,0,0,0,0,0,0,0,0,0,0,0,0,0,0,0,0
0,0,0,0,0,0,0,0,0,0,0,0,0,0,0,0,0,0,0,0,0,0,0,0,0,0,0,0,0,0,0,0,0
0,0,0,0,0,0,0,0,0,0,0,0,0,0,0,0,0,0,0,0,0,0,0,0,0,0,0,0,0,0,0,0,0
0,0,0,0,0,0,0,0,0,0,0,0,0,0,0,0,0,0,0,0,0,0,0,0,0,0,0,0,0,0,0,0,0
0,0,0,0,0,0,0,0,0,0,0,0,0,0,0,0,0,0,0,0,0,0,0,0,0,0,0,0,0,0,0,0,0
0,0,0,0,0,0,0,0,0,0,0,0,0,0,0,3,3,3,0,0,0,0,0,0,0,0,0,0,0,0,0,0,0
0,0,0,0,0,0,0,0,8,8,0,0,3,3,3,0,0,0,3,3,3,0,0,0,0,0,0,0,0,0,0,0,0
0,0,0,0,0,0,0,0,8,8,3,3,0,0,0,0,0,0,0,0,0,3,8,8,0,0,0,0,0,0,0,0,0
0,0,0,0,0,0,0,0,0,3,0,0,0,0,0,0,0,0,0,0,0,0,8,8,0,0,0,0,0,0,0,0,0
0,0,0,0,0,0,0,0,0,3,0,0,0,0,0,0,0,0,0,0,0,0,14,3,0,0,0,0,0,0,0,0,0
0,0,0,0,0,0,0,0,3,0,0,0,0,0,0,0,0,0,0,0,0,14,14,13,3,0,0,0,0,0,0,0,0
9,0,0,0,0,0,0,0,3,0,0,0,0,0,0,0,0,0,0,0,0,13,13,13,3,0,0,0,0,0,0,0,0
0,0,0,0,9,0,0,0,3,0,0,0,0,0,0,0,0,0,0,0,0,13,13,13,3,0,0,0,0,0,0,0,0
0,0,0,0,0,9,0,3,0,0,0,0,0,0,0,0,0,0,0,0,0,0,0,0,0,3,0,0,0,0,0,0,0
0,0,9,9,9,0,0,30,0,9,0,9,0,0,0,0,0,0,0,0,0,0,0,0,0,3,0,0,0,0,0,0,0
0,0,0,9,0,0,0,3,0,0,0,0,0,0,9,0,0,0,0,0,0,0,0,0,0,3,0,0,0,0,0,0,0
0,0,0,0,0,0,0,0,3,0,0,0,0,0,0,0,0,0,0,0,0,13,13,13,3,0,0,0,0,0,0,0,0
0,0,0,0,0,0,0,0,3,0,0,0,0,0,0,0,0,0,0,0,0,13,13,13,3,0,0,0,0,0,0,0,0
0,0,0,0,0,0,0,0,3,0,0,0,0,0,0,0,0,0,0,0,0,14,14,13,3,0,0,0,0,0,0,0,0
0,0,0,0,0,0,0,0,0,3,0,0,0,0,0,0,0,0,0,0,0,9,14,3,0,0,0,0,0,0,0,0,0
0,0,0,0,0,0,0,0,0,3,0,0,0,0,0,9,0,0,0,20,0,0,14,3,0,0,0,0,0,0,0,0,0
0,0,0,0,0,0,0,0,0,0,3,3,0,0,0,9,0,0,0,0,0,3,8,8,0,0,0,0,0,0,0,0,0
0,0,0,0,0,0,0,0,0,0,0,0,3,3,3,0,9,0,3,3,3,0,8,8,0,0,0,0,0,0,0,0,0
0,0,0,0,0,0,0,0,0,0,0,0,0,0,0,3,3,3,0,0,0,0,0,0,0,0,0,0,0,0,0,0,0
0,0,0,0,0,0,0,8,8,0,0,0,0,0,0,0,0,0,0,0,0,0,0,0,0,0,0,0,0,0,0,0,0
0,0,0,0,0,0,0,8,8,0,0,0,0,0,0,0,0,0,0,0,0,0,0,0,0,0,0,0,0,0,0,0,0
0,0,0,0,0,0,0,0,0,0,0,0,0,0,0,0,0,0,0,0,0,0,0,0,0,0,0,0,0,0,0,0,0
0,0,0,0,0,0,0,0,0,0,0,0,0,0,0,0,0,0,0,0,0,0,0,0,0,0,0,0,0,0,0,0,0
0,0,0,0,0,0,0,0,0,0,0,0,0,0,0,0,0,0,0,0,0,0,0,0,0,0,0,0,0,0,0,0,0
0,0,0,0,0,0,0,0,0,0,0,0,0,0,0,0,0,0,0,0,0,0,0,0,0,0,0,0,0,0,0,0,0
0,0,0,0,0,0,0,0,0,0,0,0,0,0,0,0,0,0,0,0,0,0,0,0,0,0,0,0,0,0,0,0,0
endlayer

layer
0,0,0,0,0,0,0,0,0,0,0,0,0,0,0,0,0,0,0,0,0,0,0,0,0,0,0,0,0,0,0,0,0
0,0,0,0,0,0,0,0,0,0,0,0,0,0,0,0,0,0,0,0,0,0,0,0,0,0,0,0,0,0,0,0,0
0,0,0,0,0,0,0,0,0,0,0,0,0,0,0,0,0,0,0,0,0,0,0,0,0,0,0,0,0,0,0,0,0
0,0,0,0,0,0,0,0,0,0,0,0,0,0,0,0,0,0,0,0,0,0,0,0,0,0,0,0,0,0,0,0,0
0,0,0,0,0,0,0,0,0,0,0,0,0,0,0,0,0,0,0,0,0,0,0,0,0,0,0,0,0,0,0,0,0
0,0,0,0,0,0,0,0,0,0,0,7,0,0,0,0,0,0,0,0,0,0,0,0,0,0,0,0,0,0,0,0,0
0,0,0,0,0,0,0,0,8,0,7,7,7,0,0,0,0,0,0,0,0,0,7,0,0,0,0,0,0,0,0,0,0
0,0,0,0,0,0,0,0,0,8,0,7,0,0,0,3,3,3,0,0,0,7,8,7,0,0,0,0,0,0,0,0,0
0,0,0,0,0,0,0,0,8,8,0,0,3,3,3,0,0,0,3,3,3,8,8,0,0,0,0,0,0,0,0,0,0
0,0,0,0,0,0,0,0,8,8,3,3,0,9,0,0,0,0,0,0,0,3,8,8,0,0,0,0,0,0,0,0,0
0,0,0,0,0,0,0,0,0,3,0,0,0,0,0,0,9,0,0,0,0,0,8,8,0,0,0,0,0,0,0,0,0
0,0,0,0,0,0,0,0,0,3,0,0,0,0,0,0,0,0,0,0,0,0,0,3,8,0,0,0,0,0,0,0,0
0,0,0,0,0,0,0,0,3,0,0,0,9,0,0,0,0,0,0,0,0,0,0,0,3,0,0,0,0,0,0,0,0
0,0,0,0,0,0,0,0,3,0,0,0,0,0,0,0,0,0,0,0,0,0,20,0,3,0,0,0,0,0,0,0,0
0,0,0,0,0,0,0,0,3,0,0,0,0,0,0,0,0,0,0,0,0,20,0,20,3,0,0,0,0,0,0,0,0
0,0,0,0,0,0,0,3,0,0,0,0,0,0,0,0,0,0,0,0,0,13,14,14,14,3,0,0,0,0,0,0,0
0,0,0,0,0,0,0,30,9,0,0,9,0,9,0,0,0,0,0,0,0,13,14,14,14,3,0,0,0,0,0,0,0
0,0,0,0,0,0,0,3,0,0,0,0,0,0,0,0,0,0,0,0,0,13,14,14,14,3,0,0,0,0,0,0,0
0,0,0,0,0,0,0,0,3,0,0,0,0,0,0,0,0,0,0,0,0,20,20,0,3,0,0,0,0,0,0,0,0
0,0,0,0,0,0,0,0,3,0,0,0,0,0,0,0,0,0,0,0,0,20,9,0,3,0,0,0,0,0,0,0,0
0,0,0,0,0,0,0,0,3,0,0,0,0,0,0,0,0,0,0,0,0,0,9,0,3,0,0,0,0,0,0,0,0
0,0,0,0,0,0,0,0,0,3,0,0,0,0,0,0,0,0,0,0,0,0,0,3,0,0,0,0,0,0,0,0,0
0,0,0,0,0,0,0,0,0,3,0,0,0,0,0,0,0,0,0,0,0,0,0,3,0,0,0,0,0,0,0,0,0
0,0,0,0,0,0,0,0,0,31,3,3,0,0,0,0,0,0,0,0,0,3,8,8,0,0,0,0,0,0,0,0,0
0,0,0,0,0,0,0,0,7,8,7,0,3,3,3,0,0,0,3,3,3,0,8,8,8,0,0,0,0,0,0,0,0
0,0,0,0,0,0,0,0,8,8,8,7,0,0,0,3,3,3,0,0,0,0,0,0,8,0,31,0,0,0,0,0,0
0,0,0,0,0,0,0,8,8,8,7,0,0,0,0,0,0,0,0,0,0,0,0,0,0,7,7,7,0,0,0,0,0
0,0,0,0,0,7,0,8,8,0,0,0,0,0,0,0,0,0,0,0,0,0,0,0,0,0,7,0,0,0,0,0,0
0,0,0,0,7,7,31,0,8,0,0,0,0,0,0,0,0,0,0,0,0,0,0,0,0,0,0,0,0,0,0,0,0
0,0,0,0,0,7,0,0,0,8,0,0,0,0,0,0,0,0,0,0,0,0,0,0,0,0,0,0,0,0,0,0,0
0,0,0,0,0,0,0,0,0,0,0,0,0,0,0,0,0,0,0,0,0,0,0,0,0,0,0,0,0,0,0,0,0
0,0,0,0,0,0,0,0,0,0,0,0,0,0,0,0,0,0,0,0,0,0,0,0,0,0,0,0,0,0,0,0,0
0,0,0,0,0,0,0,0,0,0,0,0,0,0,0,0,0,0,0,0,0,0,0,0,0,0,0,0,0,0,0,0,0
endlayer

layer
0,0,0,0,0,0,0,0,0,0,0,0,0,0,0,0,0,0,0,0,0,0,0,0,0,0,0,0,0,0,0,0,0
0,0,0,0,0,0,0,0,0,0,0,0,0,0,0,0,0,0,0,0,0,0,0,0,0,0,0,0,0,0,0,0,0
0,0,0,0,0,0,0,0,0,0,0,0,0,0,0,0,0,0,0,0,0,0,0,0,0,0,0,0,0,0,0,0,0
0,0,0,0,0,0,0,0,7,0,0,0,0,0,0,0,0,0,0,0,0,0,0,0,0,0,0,0,0,0,0,0,0
0,0,0,0,0,0,0,7,8,7,7,7,7,0,0,0,0,0,0,0,0,0,0,0,0,0,0,0,0,0,0,0,0
0,0,0,0,0,0,0,0,8,7,8,7,7,7,0,0,0,0,0,0,0,7,7,7,0,0,0,0,0,0,0,0,0
0,0,0,0,0,0,0,0,0,8,7,7,7,7,0,0,0,0,0,7,7,7,31,7,7,0,0,0,0,0,0,0,0
0,0,0,0,0,0,0,0,0,7,8,7,7,7,0,3,3,3,7,8,7,7,7,7,8,7,0,0,0,0,0,0,0
0,0,0,0,0,0,0,8,8,8,7,7,3,3,3,0,0,0,3,3,8,7,7,8,7,8,7,0,0,0,0,0,0
0,0,0,0,0,0,31,8,8,8,3,3,0,0,0,0,0,0,0,0,0,3,8,8,8,7,0,0,0,0,0,0,0
0,0,0,0,0,0,0,7,0,3,0,0,0,0,0,0,0,0,0,0,0,0,8,8,0,0,0,0,0,0,0,0,0
0,0,0,0,0,0,0,0,0,3,0,0,0,0,0,0,0,0,0,0,0,0,0,3,0,0,0,0,0,0,0,0,0
0,0,0,0,0,0,0,0,3,0,0,0,0,0,0,0,0,0,9,0,0,0,0,0,8,0,0,0,0,0,0,0,0
0,0,0,0,0,0,0,0,3,0,0,0,0,0,0,0,0,0,0,0,0,0,0,0,3,8,0,0,0,0,0,0,0
0,0,0,0,0,0,0,0,3,0,0,0,0,0,0,0,0,0,0,0,0,0,0,20,3,0,0,0,0,0,0,0,0
0,0,0,0,0,0,0,3,0,0,0,0,0,0,0,0,0,0,0,13,14,20,0,0,0,3,0,0,0,0,0,0,0
0,0,0,0,0,0,0,30,0,0,0,0,0,0,0,0,0,0,0,13,14,0,20,20,0,32,0,0,0,0,0,0,0
0,0,0,0,0,0,0,3,0,0,0,0,0,0,0,0,0,0,0,13,14,9,0,0,0,3,0,0,0,0,0,0,0
0,0,0,0,0,0,0,0,3,0,0,0,0,0,0,0,0,0,0,0,0,20,0,0,32,0,0,0,0,0,0,0,0
0,0,0,0,0,0,0,0,3,0,0,0,0,0,0,0,0,0,0,0,0,20,0,0,3,0,0,0,0,0,0,0,0
0,0,0,0,0,0,0,0,3,0,0,0,0,0,0,0,0,0,0,0,9,0,0,0,3,0,0,0,0,0,0,0,0
0,0,0,0,0,0,0,0,0,3,0,0,0,0,0,0,0,0,0,0,0,0,0,3,0,8,0,0,0,0,0,0,0
0,0,0,0,0,0,0,0,7,3,0,0,0,0,0,0,0,0,0,0,0,0,0,3,8,0,0,0,0,0,0,0,0
0,0,0,0,0,0,0,7,7,31,3,3,0,0,0,0,0,0,0,0,0,3,8,8,0,7,0,0,0,0,0,0,0
0,0,0,0,0,0,0,7,7,7,8,7,3,3,3,0,0,0,3,3,3,0,8,8,8,8,7,7,0,0,0,0,0
0,0,0,0,0,0,8,7,7,7,7,7,31,0,0,3,3,3,0,0,0,7,8,7,8,31,7,7,7,0,0,0,0
0,0,0,0,7,7,7,8,8,7,8,8,7,0,0,0,0,0,0,0,0,0,7,0,7,8,7,7,7,0,0,0,0
0,0,0,7,7,7,31,8,8,7,7,7,0,0,0,0,0,0,0,0,0,0,0,0,7,7,7,7,7,0,0,0,0
0,0,0,7,7,7,31,7,8,0,0,0,0,0,0,0,0,0,0,0,0,0,0,0,0,7,7,7,0,0,0,0,0
0,0,0,7,7,7,7,7,0,0,0,0,0,0,0,0,0,0,0,0,0,0,0,0,0,0,0,0,0,0,0,0,0
0,0,0,0,7,7,7,0,0,8,0,0,0,0,0,0,0,0,0,0,0,0,0,0,0,0,0,0,0,0,0,0,0
0,0,0,0,0,0,0,0,7,8,7,0,0,0,0,0,0,0,0,0,0,0,0,0,0,0,0,0,0,0,0,0,0
0,0,0,0,0,0,0,0,0,7,0,0,0,0,0,0,0,0,0,0,0,0,0,0,0,0,0,0,0,0,0,0,0
endlayer

layer
0,0,0,0,0,0,0,0,0,0,0,0,0,0,0,0,0,0,0,0,0,0,0,0,0,0,0,0,0,0,0,0,0
0,0,0,0,0,0,0,0,0,0,0,0,0,0,0,0,0,0,0,0,0,0,0,0,0,0,0,0,0,0,0,0,0
0,0,0,0,0,0,0,7,7,7,7,0,0,0,0,0,0,0,0,0,0,0,0,0,0,0,0,0,0,0,0,0,0
0,0,0,0,0,0,7,7,31,7,8,7,0,0,0,0,0,0,0,0,0,0,0,0,0,0,0,0,0,0,0,0,0
0,0,0,0,0,0,7,7,7,7,8,7,7,0,0,0,0,0,0,0,0,0,0,0,0,7,0,0,0,0,0,0,0
0,0,0,0,0,0,7,7,7,7,7,7,7,7,0,0,0,0,7,7,7,7,7,7,7,8,7,0,0,0,0,0,0
0,0,0,0,0,0,0,7,7,7,7,8,7,7,0,0,0,7,7,7,7,7,7,7,8,7,31,0,0,0,0,0,0
0,0,0,0,0,0,7,7,7,8,7,7,7,7,0,3,3,3,31,7,7,7,7,7,7,7,7,7,0,0,0,0,0
0,0,0,0,0,8,8,7,8,8,7,7,3,3,3,0,0,0,3,3,3,7,7,7,7,7,7,7,0,0,0,0,0
0,0,0,0,0,7,8,7,8,8,3,3,0,0,0,0,0,0,0,0,0,3,8,8,8,31,7,7,0,0,0,0,0
0,0,0,0,0,7,7,7,7,3,0,0,0,0,0,0,0,0,0,0,0,0,8,8,8,8,7,0,0,0,0,0,0
0,0,0,0,0,0,7,7,7,3,0,0,0,0,0,0,0,0,9,9,0,0,0,3,8,0,0,0,0,0,0,0,0
0,0,0,0,0,0,0,0,3,0,0,0,0,0,0,0,0,0,0,0,0,0,0,0,3,0,0,0,0,0,0,0,0
0,0,0,0,0,0,0,0,3,0,0,0,0,0,0,0,0,0,0,0,0,0,9,0,32,7,0,0,0,0,0,0,0
0,0,0,0,0,0,0,0,3,0,0,0,0,0,0,0,0,0,0,0,0,9,0,0,3,8,7,0,0,0,0,0,0
0,0,0,0,0,0,0,3,0,0,0,0,0,0,0,0,0,13,14,0,9,0,9,0,0,3,0,0,0,0,0,0,0
0,0,0,0,0,0,0,3,0,0,0,0,0,0,0,0,0,13,14,9,0,0,0,0,0,3,0,0,0,0,0,0,0
0,0,0,0,0,0,0,3,0,0,0,0,0,0,0,0,0,13,14,0,0,0,0,0,0,3,0,0,0,0,0,0,0
0,0,0,0,0,0,0,0,3,0,0,0,0,0,0,0,0,0,0,0,0,0,0,0,32,0,0,0,0,0,0,0,0
0,0,0,0,0,0,0,0,3,0,0,0,0,0,0,0,0,0,0,0,0,0,0,0,3,0,8,0,0,0,0,0,0
0,0,0,0,0,0,0,0,3,0,0,0,0,0,0,0,0,0,0,0,0,0,0,0,3,8,0,0,0,0,0,0,0
0,0,0,0,0,0,0,0,0,3,0,0,0,0,0,0,0,0,0,0,0,0,0,3,0,0,0,0,0,0,0,0,0
0,0,0,0,0,0,0,0,7,3,0,0,0,0,0,0,0,0,0,0,0,0,0,3,8,8,7,0,0,0,0,0,0
0,0,0,0,0,0,0,7,7,7,3,3,0,0,0,0,0,0,0,0,0,3,8,8,8,8,7,7,0,0,0,0,0
0,0,0,0,8,0,0,7,7,7,7,7,3,3,3,0,0,0,3,3,3,7,8,8,7,7,7,7,0,0,0,0,0
0,0,0,0,0,8,0,7,7,7,8,7,7,7,0,3,3,3,0,0,7,7,7,7,7,7,7,7,7,0,0,0,0
0,0,0,0,7,7,7,8,8,8,8,7,8,8,7,0,0,0,0,0,7,7,31,7,31,8,7,7,7,0,0,0,0
0,0,0,7,7,7,7,8,8,7,7,7,0,7,0,0,0,0,0,0,0,7,7,7,7,7,7,7,7,0,0,0,0
0,0,0,7,7,7,7,7,7,0,0,0,0,0,0,0,0,0,0,0,0,0,0,0,7,7,7,7,0,0,0,0,0
0,0,0,7,7,7,7,7,8,7,7,0,0,0,0,0,0,0,0,0,0,0,0,0,0,0,0,0,0,0,0,0,0
0,0,0,0,7,7,7,7,7,7,7,7,0,0,0,0,0,0,0,0,0,0,0,0,0,0,0,0,0,0,0,0,0
0,0,0,0,0,0,0,7,7,7,7,7,0,0,0,0,0,0,0,0,0,0,0,0,0,0,0,0,0,0,0,0,0
0,0,0,0,0,0,0,7,7,7,7,7,0,0,0,0,0,0,0,0,0,0,0,0,0,0,0,0,0,0,0,0,0
endlayer

layer
0,0,0,0,0,0,0,0,0,0,0,0,0,0,0,0,0,0,0,0,0,0,0,0,0,0,0,0,0,0,0,0,0
0,0,0,0,0,0,0,0,0,7,7,7,0,0,0,0,0,0,0,0,0,0,0,0,0,0,0,0,0,0,0,0,0
0,0,0,0,0,0,0,7,7,7,7,7,7,0,0,0,0,0,0,0,0,0,0,0,0,0,0,0,0,0,0,0,0
0,0,0,0,0,0,7,7,7,7,7,7,7,0,0,0,0,0,0,0,0,0,0,0,7,7,7,0,0,0,0,0,0
0,0,0,0,0,0,7,7,7,7,7,7,7,0,0,0,0,0,0,0,0,0,0,7,31,7,7,7,0,0,0,0,0
0,0,0,0,0,0,7,7,7,7,8,7,7,7,0,0,0,0,7,7,7,0,0,7,7,7,7,7,0,0,0,0,0
0,0,0,0,0,0,0,8,7,8,7,7,7,7,0,0,0,7,7,7,7,7,7,7,7,7,7,7,0,0,0,0,0
0,0,0,7,0,7,7,8,8,8,7,7,7,7,0,0,3,7,31,7,7,7,7,8,7,7,7,7,0,0,0,0,0
0,0,7,8,8,7,7,8,8,8,7,7,7,3,3,3,0,3,3,3,7,8,7,8,7,7,7,7,0,0,0,0,0
0,0,0,7,7,7,7,7,8,8,0,3,3,0,0,0,0,0,0,0,3,3,8,8,7,7,7,7,0,0,0,0,0
0,0,0,0,7,7,7,7,7,7,3,0,0,0,0,0,0,0,0,0,0,0,8,8,7,7,8,8,0,0,0,0,0
0,0,0,0,0,7,7,7,7,3,0,0,0,0,0,0,0,0,0,0,0,0,0,3,0,7,0,0,0,0,0,0,0
0,0,0,0,0,0,0,0,0,3,0,0,0,0,0,0,0,0,0,0,0,0,0,3,7,8,7,0,0,0,0,0,0
0,0,0,0,0,0,0,0,3,0,0,0,0,0,0,0,0,0,0,0,0,0,0,7,3,7,7,7,0,0,0,0,0
0,0,0,0,0,0,0,0,3,0,0,0,0,0,0,0,0,0,0,0,0,0,0,7,3,7,7,7,0,0,0,0,0
0,0,0,0,0,0,0,0,3,0,0,0,0,0,0,13,14,0,0,0,0,0,0,7,3,7,7,7,0,0,0,0,0
0,0,0,0,0,0,0,3,0,0,0,0,0,0,0,13,14,0,0,0,0,0,0,0,7,3,7,0,0,0,0,0,0
0,0,0,0,0,0,0,0,3,0,0,0,0,0,0,13,14,0,0,0,0,0,0,0,3,0,0,7,0,0,0,0,0
0,0,0,0,0,0,0,0,3,0,0,0,0,0,0,0,0,0,0,0,0,0,0,0,32,0,31,8,7,0,0,0,0
0,0,0,0,0,0,0,0,3,0,0,0,0,0,0,0,0,0,0,0,0,0,0,0,3,0,0,7,0,0,0,0,0
0,0,0,0,0,0,0,0,0,3,0,0,0,0,0,0,0,0,0,0,0,0,0,3,0,7,7,0,0,0,0,0,0
0,0,0,0,0,0,0,0,0,3,0,0,0,0,0,0,0,0,0,0,0,0,0,3,7,8,8,31,0,0,0,0,0
0,0,0,0,0,0,0,0,0,31,3,0,0,0,0,0,0,0,0,0,0,0,3,7,8,8,7,7,0,0,0,0,0
0,0,0,7,0,0,0,0,7,7,7,3,3,0,0,0,0,0,0,0,3,3,8,8,7,7,7,7,0,0,0,0,0
0,0,7,8,7,0,8,0,7,7,7,7,8,3,3,3,0,3,3,3,7,7,8,8,7,7,7,7,0,0,0,0,0
0,0,0,7,0,0,0,8,7,7,7,8,7,7,7,7,3,0,0,0,7,7,7,7,7,7,7,7,0,0,0,0,0
0,0,0,0,0,0,0,8,8,7,7,7,7,7,7,7,0,0,0,0,7,7,7,7,7,7,7,7,0,0,0,0,0
0,0,0,0,0,7,8,8,8,7,7,7,7,7,7,7,0,0,0,0,0,7,7,7,7,7,7,7,0,0,0,0,0
0,0,0,0,7,7,7,7,7,8,7,7,7,7,7,0,0,0,0,0,0,0,0,0,7,7,7,0,0,0,0,0,0
0,0,0,0,0,7,7,7,7,7,7,0,0,0,0,0,0,0,0,0,0,0,0,0,0,0,0,0,0,0,0,0,0
0,0,0,0,0,0,7,7,7,7,7,7,0,0,0,0,0,0,0,0,0,0,0,0,0,0,0,0,0,0,0,0,0
0,0,0,0,0,0,0,7,7,7,7,7,0,0,0,0,0,0,0,0,0,0,0,0,0,0,0,0,0,0,0,0,0
0,0,0,0,0,0,0,7,7,7,7,7,0,0,0,0,0,0,0,0,0,0,0,0,0,0,0,0,0,0,0,0,0
endlayer

layer
0,0,0,0,0,0,0,0,0,0,0,0,0,0,0,0,0,0,0,0,0,0,0,0,0,0,0,0,0,0,0,0,0
0,0,0,0,0,0,0,0,0,7,7,7,0,0,0,0,0,0,0,0,0,0,0,0,0,0,0,0,0,0,0,0,0
0,0,0,0,0,0,0,0,7,7,7,31,7,0,0,0,0,0,0,0,0,0,0,0,0,0,0,0,0,0,0,0,0
0,0,0,0,0,0,0,0,7,7,8,7,7,0,0,0,0,0,0,0,0,0,0,0,7,7,7,0,0,0,0,0,0
0,0,0,0,0,7,0,7,7,7,8,7,7,0,0,0,0,0,0,0,0,0,0,7,31,7,7,7,0,0,0,0,0
0,0,0,0,7,8,7,0,8,31,7,7,7,7,0,0,0,0,0,0,0,0,0,7,8,7,7,7,0,0,0,0,0
0,0,7,7,7,7,8,0,0,8,7,7,7,7,0,0,0,0,0,7,7,7,7,7,8,7,7,7,0,0,0,0,0
0,7,7,7,7,7,7,7,0,7,7,7,7,7,0,0,3,0,7,7,7,7,7,7,8,7,7,0,0,0,0,0,0
0,7,7,7,7,7,8,7,8,8,8,7,7,3,3,3,0,3,3,3,31,7,7,8,8,8,31,0,0,0,0,0,0
0,7,7,7,7,7,31,7,8,8,0,3,3,0,0,0,0,0,0,0,3,3,8,8,8,31,0,0,0,0,0,0,0
0,0,7,7,7,7,7,7,7,0,3,0,0,0,0,0,0,0,0,0,7,7,8,8,7,7,7,0,0,7,0,0,0
0,0,0,0,0,7,7,7,0,3,0,0,0,0,0,0,0,0,0,0,0,0,0,3,7,31,7,7,8,8,7,0,0
0,0,0,0,0,0,0,0,0,3,0,0,0,0,0,0,0,0,0,0,0,0,0,3,7,7,7,7,0,7,0,0,0
0,0,0,0,0,0,0,0,3,0,0,0,0,0,0,0,0,0,0,0,0,0,0,7,3,7,7,7,0,0,0,0,0
0,0,0,0,0,0,0,0,3,0,0,0,0,0,9,0,0,0,0,0,0,0,0,7,3,7,7,7,0,0,0,0,0
0,0,0,0,0,0,0,0,3,0,0,0,0,13,14,0,0,0,0,0,0,0,0,7,3,7,7,7,0,0,0,0,0
0,0,0,0,0,0,0,3,0,0,0,0,0,13,14,0,9,0,0,0,0,0,0,0,7,3,7,7,7,0,0,0,0
0,0,0,0,0,0,0,0,3,0,0,0,0,13,14,0,0,0,0,0,0,0,0,0,3,7,7,7,7,7,0,0,0
0,0,0,0,0,0,0,0,3,0,0,0,0,0,0,0,0,0,0,0,0,0,0,0,3,7,7,7,7,7,0,0,0
0,0,0,0,0,0,0,0,3,0,0,0,0,0,0,0,0,0,0,0,0,0,0,0,3,7,7,7,7,31,0,0,0
0,0,0,0,0,0,0,0,0,3,0,0,0,0,0,0,0,0,0,0,0,0,0,3,7,7,7,7,7,0,0,0,0
0,0,0,0,0,7,0,0,0,3,0,0,0,0,0,0,0,0,0,0,0,0,0,32,7,7,8,8,7,0,0,0,0
0,0,7,7,7,8,7,0,0,0,3,0,0,0,0,0,0,0,0,0,0,0,3,7,7,7,7,7,7,0,0,0,0
0,7,31,7,7,8,8,0,0,0,31,3,3,0,0,0,0,0,0,0,3,3,8,8,8,31,7,7,0,0,0,0,0
0,7,7,7,7,7,8,7,0,7,7,7,7,3,3,3,0,3,3,3,0,7,8,8,31,8,7,7,0,0,0,0,0
0,7,7,7,7,7,7,0,7,7,7,7,7,7,7,7,3,0,0,0,0,7,8,7,7,7,7,7,0,0,0,0,0
0,0,7,7,7,0,0,8,8,7,7,7,31,7,7,7,0,0,0,0,0,0,7,7,7,7,7,7,0,0,0,0,0
0,0,0,0,0,0,0,8,8,8,7,7,7,7,7,7,0,0,0,0,0,0,0,7,7,7,7,7,0,0,0,0,0
0,0,0,0,8,8,7,7,7,8,7,31,7,7,7,0,0,0,0,0,0,0,0,0,7,7,7,0,0,0,0,0,0
0,0,0,0,0,0,7,7,7,31,7,7,0,0,0,0,0,0,0,0,0,0,0,0,0,0,0,0,0,0,0,0,0
0,0,0,0,0,0,7,7,7,7,7,0,0,0,0,0,0,0,0,0,0,0,0,0,0,0,0,0,0,0,0,0,0
0,0,0,0,0,0,0,7,7,7,7,0,0,0,0,0,0,0,0,0,0,0,0,0,0,0,0,0,0,0,0,0,0
0,0,0,0,0,0,0,0,0,7,0,0,0,0,0,0,0,0,0,0,0,0,0,0,0,0,0,0,0,0,0,0,0
endlayer

layer
0,0,0,0,0,0,0,0,0,0,0,0,0,0,0,0,0,0,0,0,0,0,0,0,0,0,0,0,0,0,0,0,0
0,0,0,0,0,0,0,0,0,7,7,7,0,0,0,0,0,0,0,0,0,0,0,0,0,0,0,0,0,0,0,0,0
0,0,0,0,0,0,0,0,7,7,7,7,7,0,0,0,0,0,0,0,0,0,0,0,0,0,0,0,0,0,0,0,0
0,0,0,0,7,7,7,7,8,7,31,7,7,0,0,0,0,0,0,0,0,0,0,7,7,7,0,0,0,0,0,0,0
0,0,0,7,8,7,7,7,8,7,7,7,7,0,0,0,0,0,0,0,0,0,7,7,7,7,7,0,0,0,0,0,0
0,0,0,7,7,7,7,7,0,7,7,7,0,0,0,0,0,0,0,0,0,0,7,7,7,7,7,0,0,0,0,0,0
0,0,7,7,7,7,31,7,0,0,7,7,7,0,0,0,0,0,0,0,7,7,7,7,8,31,7,0,0,0,0,0,0
0,7,7,7,7,7,7,7,7,0,0,7,8,0,0,0,3,0,0,7,7,7,8,7,7,7,7,0,0,0,0,0,0
0,7,7,7,7,7,7,7,8,8,8,8,0,3,3,3,0,3,3,3,7,7,7,8,7,8,8,7,0,0,0,0,0
0,7,7,7,7,7,7,7,8,8,0,3,3,0,0,0,0,0,0,0,3,3,8,8,8,7,7,0,7,7,7,0,0
0,0,7,7,7,7,7,7,0,0,3,0,0,0,0,0,0,0,0,0,7,7,8,8,8,8,7,7,31,7,7,7,0
0,0,0,0,0,0,0,0,0,3,0,0,0,0,0,0,0,0,0,0,0,0,0,3,7,7,31,7,7,7,7,7,0
0,0,0,0,0,0,0,0,0,3,0,0,0,0,0,0,0,0,0,0,0,0,0,32,7,7,7,7,7,7,7,7,0
0,0,0,0,0,0,0,0,3,0,0,0,0,0,0,0,0,0,0,0,0,0,0,7,3,7,7,7,7,7,7,0,0
0,0,0,0,0,0,0,0,3,0,0,0,0,0,0,0,0,0,0,0,0,0,0,0,3,7,7,0,0,0,0,0,0
0,0,0,0,0,0,0,0,3,0,0,13,14,0,0,0,0,0,0,0,0,0,0,0,3,7,0,0,0,0,0,0,0
0,0,0,0,0,0,0,3,0,0,0,13,14,0,0,0,0,0,0,0,0,0,0,0,0,3,7,7,7,0,0,0,0
0,0,0,0,0,0,0,0,3,0,9,13,14,0,0,0,0,0,0,0,0,0,0,0,3,7,7,7,7,7,0,0,0
0,0,0,0,0,0,0,0,3,0,0,0,0,0,0,0,0,0,0,0,0,0,0,0,3,7,7,7,7,7,0,0,0
0,0,0,0,0,0,0,0,3,0,0,0,0,0,0,0,0,0,0,0,0,0,0,0,3,7,7,7,7,7,0,0,0
0,0,0,0,7,7,7,0,0,3,0,0,0,0,0,0,0,0,0,0,0,0,0,3,7,7,7,7,8,7,0,0,0
0,0,0,7,7,7,7,7,0,3,0,0,0,0,0,0,0,0,0,0,0,0,0,3,7,7,7,7,7,0,0,0,0
0,0,7,7,7,7,7,7,0,0,3,0,31,0,0,0,0,0,0,0,0,0,3,7,7,7,7,7,7,0,0,0,0
0,7,7,7,7,7,31,7,7,0,31,3,3,0,0,0,0,0,0,0,3,3,8,8,7,7,7,7,0,0,0,0,0
0,7,7,7,7,7,7,8,7,0,7,31,7,3,3,3,0,3,3,3,7,7,8,8,7,7,8,7,0,0,0,0,0
0,7,7,7,7,7,7,7,8,8,7,7,7,7,7,0,3,0,0,0,7,7,7,8,7,7,7,0,0,0,0,0,0
0,0,7,7,7,7,7,8,8,7,7,7,7,7,7,0,0,0,0,0,0,7,8,7,7,7,7,0,0,0,0,0,0
0,0,0,0,0,0,0,8,8,7,7,7,0,7,0,0,0,0,0,0,0,8,0,0,0,7,0,0,0,0,0,0,0
0,0,7,0,0,0,0,7,7,7,8,7,0,0,0,0,0,0,0,0,0,0,0,0,0,0,0,0,0,0,0,0,0
0,7,8,8,0,0,0,7,7,7,8,8,0,0,0,0,0,0,0,0,0,0,0,0,0,0,0,0,0,0,0,0,0
0,0,31,0,0,0,0,0,7,7,7,8,7,0,0,0,0,0,0,0,0,0,0,0,0,0,0,0,0,0,0,0,0
0,0,0,0,0,0,0,0,0,0,0,7,0,0,0,0,0,0,0,0,0,0,0,0,0,0,0,0,0,0,0,0,0
0,0,0,0,0,0,0,0,0,0,0,0,0,0,0,0,0,0,0,0,0,0,0,0,0,0,0,0,0,0,0,0,0
endlayer

layer
0,0,0,0,0,0,0,0,0,0,0,0,0,0,0,0,0,0,0,0,0,0,0,0,0,0,0,0,0,0,0,0,0
0,0,0,0,0,0,0,7,7,7,7,7,0,0,0,0,0,0,0,0,0,0,0,0,0,0,0,0,0,0,0,0,0
0,0,0,7,7,7,7,7,7,7,7,7,7,0,0,0,0,0,0,0,0,0,0,0,0,0,0,0,0,0,0,0,0
0,0,7,7,7,7,7,7,7,7,7,31,7,0,0,0,0,0,0,0,0,0,0,7,7,7,0,0,0,0,0,0,0
0,0,7,7,7,7,7,7,7,31,7,7,7,0,0,0,0,0,0,0,0,0,7,7,7,7,7,0,0,0,0,0,0
0,0,7,7,7,7,7,7,7,7,7,31,0,0,0,0,0,0,0,0,0,0,7,7,7,7,7,0,0,0,0,0,0
0,0,0,7,7,7,7,7,0,8,8,0,0,31,7,0,0,0,0,0,0,31,8,7,31,7,7,7,0,0,0,0,0
0,0,0,7,7,7,7,7,8,8,8,0,8,8,8,7,3,0,0,0,0,7,7,7,7,7,7,7,7,0,0,0,0
0,0,7,7,7,7,7,7,8,8,0,0,0,3,3,3,0,3,3,3,31,7,7,7,7,7,7,7,7,0,0,0,0
0,0,0,7,7,7,7,7,8,8,0,3,3,0,13,13,13,13,13,0,3,3,8,8,7,7,7,7,7,7,7,0,0
0,0,0,0,0,7,7,7,0,0,3,0,13,13,13,13,13,13,13,13,13,0,8,8,31,7,7,7,7,7,7,7,0
0,0,0,0,0,0,0,0,0,3,0,13,13,13,13,13,13,13,13,13,13,13,0,3,0,7,8,7,7,7,7,7,0
0,0,0,0,0,0,0,0,0,3,13,13,13,13,13,13,13,13,13,13,13,13,13,32,7,7,7,7,7,7,7,7,0
0,0,0,0,0,0,0,0,3,0,13,13,13,13,13,13,13,13,13,13,13,13,13,0,3,7,0,0,7,7,7,0,0
0,0,0,0,0,0,0,0,3,13,13,13,13,13,13,13,13,13,13,13,13,13,13,13,3,0,0,0,0,0,0,0,0
0,0,0,0,0,0,0,0,3,13,14,0,0,0,0,0,0,13,13,13,13,13,13,13,3,0,0,0,0,0,0,0,0
0,0,0,0,0,0,0,3,0,13,14,0,0,0,0,0,0,13,13,13,13,13,13,13,0,3,0,0,0,0,0,0,0
0,0,0,0,0,0,0,0,3,13,14,0,0,0,0,0,0,13,13,13,13,13,13,13,3,0,0,7,0,0,0,0,0
0,0,0,0,0,0,0,0,3,13,13,13,13,13,13,13,13,13,13,13,13,13,13,13,3,0,7,7,7,7,0,0,0
0,0,0,0,0,0,0,0,3,0,13,13,13,13,13,13,13,13,13,13,13,13,13,0,3,0,7,7,7,31,7,0,0
0,0,0,0,7,7,7,0,0,3,13,13,13,13,13,13,13,13,13,13,13,13,13,3,0,7,7,7,7,7,7,0,0
0,0,0,7,7,7,7,7,0,3,0,13,13,13,13,13,13,13,13,13,13,13,0,3,7,7,7,31,7,7,7,0,0
0,0,0,7,7,7,8,7,0,0,3,0,13,13,13,13,13,13,13,13,13,0,3,7,8,8,7,7,7,7,0,0,0
0,0,0,7,7,7,7,8,31,0,7,3,3,0,13,13,13,13,13,0,32,3,8,8,8,7,7,7,7,0,0,0,0
0,0,7,7,7,7,31,7,7,7,8,7,31,3,3,3,33,3,3,3,7,7,8,8,8,7,31,31,7,0,0,0,0
0,0,0,7,7,7,7,7,31,0,7,0,7,0,0,0,3,0,0,0,7,7,7,7,8,8,7,7,7,0,0,0,0
0,0,0,0,0,7,7,8,8,0,0,0,0,0,0,0,0,0,0,0,0,7,7,8,0,7,7,7,0,0,0,0,0
0,7,7,7,0,0,0,8,8,7,0,0,0,0,0,0,0,0,0,0,0,7,0,0,8,0,0,0,0,0,0,0,0
7,7,7,7,31,0,0,0,7,8,31,7,7,0,0,0,0,0,0,0,7,8,7,0,0,0,0,0,0,0,0,0,0
7,7,7,7,7,0,0,0,0,7,7,7,7,7,0,0,0,0,0,0,0,7,0,0,0,0,0,0,0,0,0,0,0
7,7,7,7,7,0,0,0,0,7,7,7,8,7,0,0,0,0,0,0,0,0,0,0,0,0,0,0,0,0,0,0,0
0,7,7,7,0,0,0,0,0,7,7,7,7,7,0,0,0,0,0,0,0,0,0,0,0,0,0,0,0,0,0,0,0
0,0,0,0,0,0,0,0,0,0,7,7,7,0,0,0,0,0,0,0,0,0,0,0,0,0,0,0,0,0,0,0,0
endlayer

layer
0,0,0,0,0,0,0,0,0,0,0,0,0,0,0,0,0,0,0,0,0,0,0,0,0,0,0,0,0,0,0,0,0
0,0,0,0,0,0,0,7,7,7,0,0,0,0,0,0,0,0,0,0,0,0,0,0,0,0,0,0,0,0,0,0,0
0,0,0,7,7,7,7,7,7,7,7,0,0,0,0,0,0,0,0,0,0,0,0,0,0,0,0,0,0,0,0,0,0
0,0,7,7,7,7,7,7,7,7,31,7,0,0,0,0,0,0,0,0,0,0,0,0,0,0,0,0,0,0,0,0,0
0,0,7,7,7,7,7,7,7,8,7,8,0,0,0,0,0,0,0,0,0,7,7,7,7,7,0,0,0,0,0,0,0
0,0,7,7,7,31,8,7,31,8,7,8,7,7,7,7,0,0,0,0,7,7,7,7,7,7,7,0,0,0,0,0,0
0,0,0,7,7,7,0,8,0,0,0,7,7,7,7,7,7,0,0,0,7,7,7,7,7,7,7,31,0,0,0,0,0
0,0,0,0,0,0,7,0,0,0,0,7,7,7,7,7,7,0,0,0,7,7,7,8,7,7,7,7,7,0,0,0,0
0,0,0,0,0,7,7,7,8,8,0,7,7,7,3,3,3,3,3,0,0,7,7,8,8,8,7,7,7,0,0,0,0
0,0,0,0,0,0,7,0,8,8,0,0,3,3,37,36,0,35,34,3,3,0,8,8,7,7,7,7,7,0,0,0,0
0,0,0,0,0,0,0,0,0,0,0,3,0,0,20,20,0,0,0,0,0,3,8,8,8,8,7,7,7,7,0,0,0
0,0,0,0,0,0,0,0,0,0,3,0,0,0,0,0,20,20,0,20,0,0,3,0,7,7,7,7,7,7,7,0,0
0,0,0,0,0,0,0,0,0,3,0,0,0,20,9,0,0,0,9,0,0,0,0,3,7,7,7,7,7,7,0,0,0
0,0,0,0,0,0,0,0,0,3,0,0,0,0,20,0,0,20,9,20,20,20,0,3,0,7,7,7,0,0,0,0,0
0,0,0,0,0,0,0,0,3,0,0,0,9,0,0,0,0,20,0,0,0,14,14,14,3,0,0,0,0,0,0,0,0
0,0,0,0,0,0,0,0,3,0,0,0,0,0,0,0,0,0,20,0,0,13,13,13,3,0,0,0,0,0,0,0,0
0,0,0,0,0,0,0,0,3,0,0,0,0,0,0,0,0,0,20,0,20,0,38,10,3,0,0,0,0,0,0,0,0
0,0,0,0,0,0,0,0,3,0,0,0,0,0,0,0,0,0,9,0,0,0,39,39,3,0,0,0,0,0,0,0,0
0,0,0,0,0,0,0,0,3,0,0,0,0,0,0,0,9,0,0,9,20,0,0,0,3,0,0,7,7,7,0,0,0
0,0,0,0,0,0,0,0,0,3,9,9,20,0,0,0,9,9,9,0,9,9,0,3,0,0,7,7,7,7,7,0,0
0,0,0,0,0,0,7,0,0,3,0,0,20,0,0,9,9,9,9,9,0,0,0,3,0,0,7,7,7,7,7,0,0
0,0,0,0,0,7,8,7,0,0,3,0,0,0,0,0,20,20,0,0,0,0,3,0,0,7,8,7,7,7,7,0,0
0,0,0,0,7,7,7,0,0,7,7,3,20,20,0,0,20,0,20,20,0,3,0,0,0,7,8,7,7,7,0,0,0
0,0,0,0,7,7,7,0,7,7,7,7,3,3,43,42,0,41,40,3,3,0,8,8,7,8,7,7,7,0,0,0,0
0,0,0,0,0,7,7,8,7,7,7,7,7,0,3,3,44,3,3,0,0,7,8,8,31,7,7,7,7,0,0,0,0
0,0,0,0,0,0,7,8,7,7,7,7,7,0,0,0,0,0,0,0,0,0,7,8,31,7,7,7,7,0,0,0,0
0,0,0,0,0,0,0,8,8,7,7,7,0,0,0,0,0,0,0,0,7,7,7,7,8,8,7,7,0,0,0,0,0
0,7,7,7,0,0,0,8,8,8,7,0,0,0,0,0,0,0,0,7,7,7,7,7,7,0,8,0,0,0,0,0,0
7,7,7,7,7,0,0,0,0,8,7,7,7,7,0,0,0,0,0,7,7,31,7,31,8,0,0,0,0,0,0,0,0
7,7,7,7,7,0,0,0,7,8,31,7,7,7,7,0,0,0,0,7,7,7,7,7,8,7,0,0,0,0,0,0,0
7,7,7,7,7,0,0,0,0,31,7,7,7,7,7,0,0,0,0,0,7,7,7,0,31,0,0,0,0,0,0,0,0
0,7,7,7,0,0,0,0,0,7,7,7,7,7,7,0,0,0,0,0,0,0,0,0,0,0,0,0,0,0,0,0,0
0,0,0,0,0,0,0,0,0,0,7,7,7,7,0,0,0,0,0,0,0,0,0,0,0,0,0,0,0,0,0,0,0
endlayer

layer
0,0,0,0,0,0,0,0,0,0,0,0,0,0,0,0,0,0,0,0,0,0,0,0,0,0,0,0,0,0,0,0,0
0,0,0,0,0,0,0,0,0,0,0,0,0,0,0,0,0,0,0,0,0,0,0,0,0,0,0,0,0,0,0,0,0
0,0,0,0,0,0,0,0,7,7,7,0,7,0,0,0,0,0,0,0,0,0,0,0,0,0,0,0,0,0,0,0,0
0,0,0,0,7,31,0,7,7,7,7,7,8,7,0,0,0,0,0,0,0,0,0,0,0,0,0,0,0,0,0,0,0
0,0,0,7,7,8,7,7,7,7,7,7,7,7,0,0,0,0,0,0,0,7,7,7,0,0,0,0,0,0,0,0,0
0,0,0,0,7,7,0,7,7,7,7,7,7,7,7,7,0,0,0,0,7,7,7,7,7,0,0,7,0,0,0,0,0
0,0,0,0,0,0,0,0,7,7,8,7,7,7,7,7,7,0,0,0,7,7,7,7,7,7,7,8,7,0,0,0,0
0,0,0,0,0,0,0,0,8,8,7,7,7,7,7,7,7,0,0,0,7,7,7,8,7,7,8,7,0,0,0,0,0
0,0,0,0,0,0,0,0,8,8,0,7,7,7,3,3,3,3,3,0,0,7,7,8,8,8,7,7,0,0,0,0,0
0,0,0,0,0,0,0,0,8,8,0,0,3,3,20,7,20,20,20,3,3,0,7,8,8,7,7,7,0,0,0,0,0
0,0,0,0,0,0,0,0,0,8,0,3,0,0,0,0,0,0,0,0,0,3,0,8,8,7,7,7,7,0,0,0,0
0,0,0,0,0,0,0,0,0,0,3,0,0,0,9,20,20,20,0,20,0,0,3,7,8,8,8,8,7,0,0,0,0
0,0,0,0,0,0,0,0,0,3,0,0,0,9,0,9,0,9,9,0,0,0,0,3,7,7,7,7,7,0,0,0,0
0,0,0,0,0,0,0,0,0,3,0,0,0,0,0,0,0,0,0,0,0,0,0,3,0,7,7,7,0,0,0,0,0
0,0,0,0,0,0,0,0,3,0,0,0,0,0,0,0,0,0,0,0,0,0,0,0,3,0,0,0,0,0,0,0,0
0,0,0,0,0,0,0,0,3,0,0,0,0,0,0,0,0,0,0,0,0,9,0,0,32,0,0,0,0,0,0,0,0
0,0,0,0,0,0,0,0,3,0,0,0,0,0,0,0,0,9,0,0,0,14,14,14,3,0,0,0,0,0,0,0,0
0,0,0,0,0,0,0,0,3,0,0,0,0,0,0,0,0,0,9,0,0,13,13,13,3,0,0,0,0,0,0,0,0
0,0,0,0,0,0,0,0,3,0,0,0,0,0,0,0,0,0,0,0,20,0,0,0,3,0,0,0,0,0,0,0,0
0,0,0,0,0,7,7,7,0,3,0,0,0,0,0,20,0,0,0,20,0,0,0,3,0,7,7,7,7,0,0,0,0
0,0,0,0,7,7,7,31,7,3,20,0,0,0,0,20,20,0,20,20,0,0,0,3,7,7,31,7,7,7,0,0,0
0,0,0,0,7,7,7,7,7,0,3,0,0,0,0,20,20,20,20,0,0,0,3,0,7,7,7,7,7,0,0,0,0
0,0,0,0,7,7,8,7,7,7,7,3,0,0,0,20,20,0,20,20,0,3,0,8,7,7,7,8,8,7,0,0,0
0,0,0,0,0,7,8,7,7,7,7,7,3,3,0,20,20,0,0,3,3,0,0,8,0,7,7,7,7,0,0,0,0
0,0,0,0,0,0,7,8,7,7,31,31,7,0,3,3,3,3,3,0,0,8,8,7,7,7,7,7,0,0,0,0,0
0,0,0,0,0,7,8,7,8,7,8,7,7,0,0,0,0,0,0,0,0,0,7,7,7,7,7,0,0,0,0,0,0
0,0,0,0,0,0,7,8,8,8,7,7,0,0,0,0,0,0,0,0,7,7,7,7,7,7,7,0,0,0,0,0,0
0,0,0,0,0,0,0,8,8,7,7,7,0,0,0,0,0,0,0,7,7,7,7,7,8,7,7,31,0,0,0,0,0
0,0,7,0,0,0,7,8,8,7,7,7,7,7,0,0,0,0,0,7,7,7,7,31,8,7,7,8,7,0,0,0,0
0,7,7,7,0,0,0,7,7,7,8,31,7,7,7,0,0,0,0,7,7,7,7,7,7,7,7,7,0,0,0,0,0
0,0,7,0,0,0,0,7,7,31,7,8,7,7,7,0,0,0,0,0,7,7,7,7,7,7,7,0,0,0,0,0,0
0,0,0,0,0,0,0,0,7,7,7,7,7,7,7,0,0,0,0,0,0,0,0,7,7,7,0,0,0,0,0,0,0
0,0,0,0,0,0,0,0,0,0,0,7,7,7,0,0,0,0,0,0,0,0,0,0,0,0,0,0,0,0,0,0,0
endlayer

layer
0,0,0,0,0,0,0,0,0,0,0,0,0,0,0,0,0,0,0,0,0,0,0,0,0,0,0,0,0,0,0,0,0
0,0,0,0,0,0,0,0,0,0,0,7,7,7,0,0,0,0,0,0,0,0,0,0,0,0,0,0,0,0,0,0,0
0,0,0,0,7,7,7,0,7,7,7,7,7,7,7,0,0,0,0,0,0,0,0,0,0,0,0,0,0,0,0,0,0
0,0,0,7,7,7,7,7,7,7,7,7,7,31,7,0,0,0,0,0,0,0,0,0,0,0,0,0,0,0,0,0,0
0,0,0,7,7,7,7,7,7,7,7,7,7,7,7,0,0,0,0,0,0,0,0,0,7,0,7,7,7,0,0,0,0
0,0,0,7,7,7,7,7,7,7,7,7,7,7,0,0,0,0,0,0,0,0,7,7,8,7,7,7,7,7,0,0,0
0,0,0,0,7,7,7,7,8,7,7,7,7,7,7,0,0,0,0,0,0,7,7,8,8,7,7,7,7,7,0,0,0
0,0,0,0,0,0,0,7,8,7,7,7,7,7,7,7,0,0,0,0,0,7,7,8,8,7,7,7,7,7,0,0,0
0,0,0,0,0,0,7,8,7,8,7,7,0,7,3,3,3,3,3,0,0,7,7,7,7,7,7,7,7,0,0,0,0
0,0,0,0,0,0,0,7,0,0,8,0,3,3,20,0,0,20,20,3,3,0,7,8,7,7,7,7,7,0,0,0,0
0,0,0,0,0,0,0,0,8,7,0,3,0,0,0,0,0,20,0,0,0,3,0,7,7,7,7,7,7,7,0,0,0
0,0,0,0,0,0,0,0,7,8,3,0,0,0,0,20,20,20,0,0,0,0,3,7,31,7,7,7,7,7,0,0,0
0,0,0,0,0,0,0,0,0,3,0,0,0,0,0,0,0,0,0,0,0,0,0,3,8,7,8,7,7,7,0,0,0
0,0,0,0,0,0,0,0,0,3,0,0,0,0,0,0,0,0,0,0,0,0,0,3,7,0,7,7,7,0,0,0,0
0,0,0,0,0,0,0,0,3,0,0,0,0,0,0,0,0,0,0,0,0,0,0,0,3,0,0,0,0,0,0,0,0
0,0,0,0,0,0,0,0,3,0,0,0,0,0,0,0,9,0,0,0,0,0,0,0,32,0,0,0,0,0,0,0,0
0,0,0,0,0,0,0,0,3,0,0,0,0,0,0,9,0,0,9,0,0,0,0,0,32,0,0,0,0,0,0,0,0
0,0,0,0,0,0,0,0,3,0,0,0,0,0,0,0,9,0,9,0,0,0,0,0,3,0,0,0,0,0,0,0,0
0,0,0,0,0,0,0,0,3,0,0,0,0,0,0,0,0,0,9,0,0,14,14,14,3,0,0,0,0,0,0,0,0
0,0,0,0,0,7,7,7,0,3,0,0,0,0,0,0,0,0,0,0,13,13,13,3,0,7,7,7,0,0,0,0,0
0,0,0,0,7,7,7,7,7,3,0,0,0,0,0,0,0,0,0,0,0,0,0,3,7,7,7,7,7,7,0,0,0
0,0,0,0,7,8,7,7,7,0,3,0,0,0,0,0,0,0,0,0,0,0,3,0,7,7,7,7,7,7,7,0,0
0,0,0,0,7,7,7,8,7,0,0,3,0,0,0,0,0,0,0,0,0,3,0,8,8,7,7,7,7,7,7,0,0
0,0,0,0,0,7,7,8,0,0,7,0,3,3,0,0,0,20,20,3,3,0,8,8,7,7,7,7,7,7,7,0,0
0,0,0,0,7,7,7,7,7,7,7,7,8,7,3,3,3,3,3,7,0,0,8,7,7,7,0,7,7,7,0,0,0
0,0,0,0,7,7,7,7,7,7,7,8,7,0,0,0,0,0,7,8,8,0,7,31,7,7,7,0,0,0,0,0,0
0,0,0,0,7,7,7,7,8,7,31,7,0,0,0,0,0,0,0,7,0,0,7,7,7,7,7,7,7,0,0,0,0
0,0,0,0,0,7,7,8,8,31,7,7,0,0,0,0,0,0,0,0,0,7,7,7,7,7,7,7,7,7,0,0,0
0,0,0,0,0,7,7,7,7,7,7,7,7,0,0,0,0,0,0,0,7,7,7,7,7,7,7,7,7,7,0,0,0
0,0,0,0,0,7,7,7,7,8,7,7,7,7,0,0,0,0,0,0,0,7,7,7,7,7,7,7,31,7,0,0,0
0,0,0,0,0,0,7,7,7,8,7,7,7,7,0,0,0,0,0,0,0,0,7,7,7,7,7,7,7,0,0,0,0
0,0,0,0,0,0,0,0,7,7,7,7,7,7,0,0,0,0,0,0,0,0,0,7,7,7,0,0,0,0,0,0,0
0,0,0,0,0,0,0,0,0,0,7,7,7,0,0,0,0,0,0,0,0,0,0,0,0,0,0,0,0,0,0,0,0
endlayer

layer
0,0,0,0,0,0,0,0,0,0,0,0,0,0,0,0,0,0,0,0,0,0,0,0,0,0,0,0,0,0,0,0,0
0,0,0,0,0,0,0,0,0,0,0,7,7,7,0,0,0,0,0,0,0,0,0,0,0,0,0,0,0,0,0,0,0
0,0,0,0,7,7,7,0,0,0,7,7,7,7,7,0,0,0,0,0,0,0,0,0,0,0,0,0,0,0,0,0,0
0,0,0,7,7,7,7,7,0,7,7,7,7,7,7,0,0,0,0,0,0,0,0,7,7,7,0,0,0,0,0,0,0
0,0,0,7,7,7,7,7,7,7,7,7,7,7,7,0,0,0,0,0,0,0,7,7,7,7,7,7,7,0,0,0,0
0,0,0,7,7,7,7,7,7,7,7,7,7,7,0,0,0,0,0,0,0,0,7,8,7,7,7,7,7,7,0,0,0
0,0,0,0,7,7,7,7,31,7,7,7,7,0,0,0,0,0,0,0,0,0,7,7,7,8,7,7,7,7,0,0,0
0,0,0,0,0,7,7,8,31,7,7,7,7,0,0,0,0,0,0,0,0,0,7,7,7,7,7,7,7,7,0,0,0
0,0,0,0,0,7,7,7,7,8,7,7,0,0,3,3,3,3,3,0,0,0,0,7,7,7,7,7,7,0,0,0,0
0,0,0,0,0,7,7,7,7,7,8,7,3,3,0,20,20,0,20,3,3,0,0,8,7,7,7,7,7,0,0,0,0
0,0,0,0,0,0,7,7,7,7,7,3,0,0,0,0,20,0,0,0,0,3,0,7,7,7,7,7,7,7,0,0,0
0,0,0,0,0,0,7,8,7,7,3,0,0,0,20,20,0,0,0,0,0,0,3,7,7,7,7,7,7,7,0,0,0
0,0,0,0,0,0,0,7,7,3,0,0,0,0,0,0,0,0,0,0,0,0,7,3,7,7,7,7,7,7,0,0,0
0,0,0,0,0,0,0,0,7,3,0,0,0,0,0,0,0,0,0,0,0,0,7,3,7,7,7,7,7,0,0,0,0
0,0,0,0,0,0,0,0,3,0,0,0,0,0,0,0,0,0,0,0,0,0,0,7,3,7,7,7,0,0,0,0,0
0,0,0,0,0,0,0,0,3,0,0,0,0,0,0,0,0,0,0,0,0,0,0,0,3,0,0,0,0,0,0,0,0
0,0,0,0,0,0,0,0,3,0,0,0,0,0,0,0,0,0,0,0,0,0,0,0,32,0,0,0,0,0,0,0,0
0,0,0,0,0,0,0,0,3,0,0,0,0,0,0,0,0,0,0,0,0,0,0,0,3,0,0,0,0,0,0,0,0
0,0,0,0,0,0,0,0,3,0,0,0,0,0,0,0,0,0,0,20,0,9,0,0,3,0,0,0,0,0,0,0,0
0,0,0,0,7,7,7,0,0,3,0,0,0,0,0,0,0,0,0,20,20,20,20,3,0,0,0,0,0,0,0,0,0
0,0,0,7,7,7,7,7,7,3,0,0,0,0,0,0,0,0,0,14,14,14,14,3,31,7,7,7,7,7,0,0,0
0,0,0,7,7,7,31,7,7,7,3,0,0,0,0,0,0,0,0,13,13,13,3,8,7,7,7,7,7,7,7,0,0
0,0,0,7,7,7,7,7,7,7,0,3,7,7,0,0,0,0,0,13,0,3,7,7,7,7,7,7,7,7,7,0,0
0,0,0,0,7,7,7,7,7,7,7,7,3,3,7,0,0,0,7,3,3,7,8,8,7,7,7,7,7,7,7,0,0
0,0,0,0,7,7,7,7,7,0,7,7,7,7,3,3,32,32,3,7,7,7,8,7,7,7,0,7,7,7,0,0,0
0,0,0,0,7,7,7,7,7,0,7,7,7,7,7,0,0,7,7,7,7,7,7,0,7,0,0,0,0,0,0,0,0
0,0,0,0,7,7,7,7,8,7,0,7,7,7,0,0,0,7,7,7,7,7,0,7,7,7,7,7,7,0,0,0,0
0,0,0,0,0,7,7,31,7,7,7,0,0,0,0,0,0,0,7,7,7,0,7,7,7,7,7,7,7,7,0,0,0
0,0,0,0,0,7,7,8,8,7,7,7,7,0,0,0,0,0,0,0,0,0,7,7,7,7,7,7,7,7,0,0,0
0,0,0,0,0,7,7,7,7,31,7,7,7,7,0,0,0,0,0,0,0,0,7,7,7,7,7,7,7,7,0,0,0
0,0,0,0,0,0,7,7,7,7,7,7,7,7,0,0,0,0,0,0,0,0,0,7,7,7,7,7,7,0,0,0,0
0,0,0,0,0,0,0,0,7,8,7,7,7,7,0,0,0,0,0,0,0,0,0,0,0,0,0,0,0,0,0,0,0
0,0,0,0,0,0,0,0,0,7,7,7,7,0,0,0,0,0,0,0,0,0,0,0,0,0,0,0,0,0,0,0,0
endlayer

layer
0,0,0,0,0,0,0,0,0,0,0,0,0,0,0,0,0,0,0,0,0,0,0,0,0,0,0,0,0,0,0,0,0
0,0,0,0,0,0,0,0,0,0,0,0,0,0,0,0,0,0,0,0,0,0,0,0,0,0,0,0,0,0,0,0,0
0,0,0,0,0,0,0,0,0,0,0,0,7,0,0,0,0,0,0,0,0,0,0,0,0,0,0,0,0,0,0,0,0
0,0,0,0,0,7,0,0,0,0,0,7,7,7,0,0,0,0,0,0,0,0,7,7,7,7,0,0,0,0,0,0,0
0,0,0,0,7,7,7,7,7,7,0,0,7,0,0,0,0,0,0,0,0,7,7,7,7,7,7,0,0,0,0,0,0
0,0,0,0,0,7,7,7,7,7,7,0,0,0,0,0,0,0,0,0,0,7,7,7,7,7,7,7,0,0,0,0,0
0,0,0,0,0,7,7,7,7,7,7,7,0,0,0,0,0,0,0,0,0,7,7,7,7,7,7,7,7,0,0,0,0
0,0,0,0,0,7,7,7,7,7,7,7,0,0,0,0,0,0,0,0,0,0,7,7,7,7,31,7,0,0,0,0,0
0,0,0,0,0,7,7,7,7,8,7,7,7,0,0,3,3,3,0,0,0,0,0,7,7,7,7,0,0,0,0,0,0
0,0,0,0,0,7,7,7,7,7,7,7,7,3,3,0,0,0,3,3,0,0,7,8,7,7,0,0,0,0,0,0,0
0,0,0,0,0,7,7,7,7,7,7,3,3,0,0,0,0,0,0,0,3,3,0,7,7,7,7,7,0,0,0,0,0
0,0,0,0,0,7,7,7,7,7,3,3,0,0,0,0,0,0,0,0,0,3,3,7,7,7,7,7,7,0,0,0,0
0,0,0,0,0,7,7,7,7,7,3,0,0,0,0,0,0,0,0,0,0,0,3,3,7,7,7,7,7,0,0,0,0
0,0,0,0,0,0,7,7,7,3,31,0,0,0,0,0,0,0,0,0,0,0,7,3,7,7,7,7,7,0,0,0,0
0,0,0,0,0,0,0,0,0,3,0,0,0,0,0,0,0,0,0,0,0,0,0,3,7,7,7,7,0,0,0,0,0
0,0,0,0,0,0,0,0,3,0,0,0,0,0,0,0,0,0,0,0,0,0,0,0,3,0,0,0,0,0,0,0,0
0,0,0,0,0,0,0,0,3,0,0,0,0,0,0,0,0,0,9,0,0,0,0,0,32,0,0,0,0,0,0,0,0
0,0,0,0,0,0,0,0,3,0,0,0,0,0,0,0,0,0,0,0,0,0,0,0,3,0,0,0,0,0,0,0,0
0,0,0,0,0,0,0,0,0,3,0,0,0,0,0,0,0,0,0,0,0,0,0,3,0,0,0,0,0,0,0,0,0
0,0,0,0,7,7,7,0,0,3,0,0,0,0,0,0,0,0,0,20,20,0,7,3,7,0,0,0,0,0,0,0,0
0,0,0,7,7,7,7,7,7,0,3,0,0,0,0,0,0,0,0,0,0,7,3,7,7,7,0,0,0,0,0,0,0
0,0,0,7,7,7,7,7,7,7,3,3,0,0,0,0,0,13,14,0,0,3,3,31,31,7,7,0,7,0,0,0,0
0,0,0,7,7,7,7,7,7,7,0,3,3,7,0,0,0,13,14,0,3,3,7,7,31,7,7,7,7,7,0,0,0
0,0,0,0,7,7,7,7,7,7,7,7,7,3,3,0,0,13,3,3,7,7,7,8,7,7,7,0,7,0,0,0,0
0,0,0,0,0,0,7,7,7,0,7,7,7,7,7,3,3,3,7,7,7,7,7,7,7,7,0,0,0,0,0,0,0
0,0,0,0,0,7,7,7,7,0,7,7,7,7,7,0,0,7,7,7,7,7,7,7,7,0,0,0,0,0,0,0,0
0,0,0,0,0,0,7,7,8,7,0,7,7,7,0,0,0,7,7,7,7,7,7,7,0,0,0,0,0,0,0,0,0
0,0,0,0,0,7,7,7,7,7,7,0,0,0,0,0,0,0,7,7,7,0,0,0,7,0,0,7,0,0,0,0,0
0,0,0,0,0,7,7,7,7,7,7,0,0,0,0,0,0,0,0,0,0,0,0,7,7,7,7,7,7,0,0,0,0
0,0,0,0,0,7,7,7,7,7,7,7,0,0,0,0,0,0,0,0,0,0,0,0,7,0,0,7,0,0,0,0,0
0,0,0,0,0,0,7,7,7,7,7,7,7,0,0,0,0,0,0,0,0,0,0,0,0,0,0,0,0,0,0,0,0
0,0,0,0,0,0,0,7,7,7,7,7,0,0,0,0,0,0,0,0,0,0,0,0,0,0,0,0,0,0,0,0,0
0,0,0,0,0,0,0,7,7,31,7,7,0,0,0,0,0,0,0,0,0,0,0,0,0,0,0,0,0,0,0,0,0
endlayer

layer
0,0,0,0,0,0,0,0,0,0,0,0,0,0,0,0,0,0,0,0,0,0,0,0,0,0,0,0,0,0,0,0,0
0,0,0,0,0,0,0,0,0,0,0,0,0,0,0,0,0,0,0,0,0,0,0,0,0,0,0,0,0,0,0,0,0
0,0,0,0,0,0,0,0,0,0,0,0,0,0,0,0,0,0,0,0,0,0,0,0,0,0,0,0,0,0,0,0,0
0,0,0,0,0,0,0,0,0,0,0,0,0,0,0,0,0,0,0,0,0,0,7,7,7,0,0,0,0,0,0,0,0
0,0,0,0,0,0,0,0,0,0,0,0,0,0,0,0,0,0,0,0,0,7,7,7,7,7,7,0,0,0,0,0,0
0,0,0,0,0,0,7,7,7,0,0,0,0,0,0,0,0,0,0,0,0,7,7,7,7,7,7,7,0,0,0,0,0
0,0,0,0,0,7,7,7,7,7,7,0,0,0,0,0,0,0,0,0,0,7,7,7,7,7,7,7,0,0,0,0,0
0,0,0,0,0,7,7,7,7,7,7,7,0,0,0,0,0,0,0,0,0,0,7,7,7,7,7,7,0,0,0,0,0
0,0,0,0,0,7,7,7,7,31,7,7,7,0,0,3,3,3,0,0,0,7,7,7,7,7,7,0,0,0,0,0,0
0,0,0,0,0,0,7,7,7,7,7,7,7,3,3,0,0,0,3,3,0,7,7,7,7,7,0,0,0,0,0,0,0
0,0,0,0,0,7,7,7,7,7,7,3,3,0,0,0,0,0,0,0,3,3,31,7,7,7,0,0,0,0,0,0,0
0,0,0,0,0,7,7,7,7,7,3,3,0,0,0,0,0,0,0,0,0,3,3,7,7,0,7,0,0,0,0,0,0
0,0,0,0,0,7,7,7,7,7,3,0,0,0,0,0,0,0,0,0,0,0,3,3,7,7,7,7,0,0,0,0,0
0,0,0,0,0,0,7,7,7,3,0,0,0,0,0,0,0,0,0,0,0,0,0,3,7,0,7,0,0,0,0,0,0
0,0,0,0,0,0,0,0,0,3,0,0,0,0,0,0,0,0,0,0,0,0,0,3,0,0,0,0,0,0,0,0,0
0,0,0,0,0,0,0,0,3,0,0,0,0,0,0,0,0,0,0,0,0,0,0,0,3,0,0,0,0,0,0,0,0
0,0,0,0,0,0,0,0,3,0,0,0,0,0,0,0,0,0,0,0,0,0,0,0,32,0,0,0,0,0,0,0,0
0,0,0,0,0,0,0,0,3,0,0,0,0,0,0,0,0,0,0,0,0,0,0,0,3,0,0,0,0,0,0,0,0
0,0,0,0,0,0,0,0,0,3,0,0,0,0,0,0,0,0,0,0,0,0,0,3,0,0,0,0,0,0,0,0,0
0,0,0,0,0,0,0,0,0,3,0,0,0,0,0,0,9,9,0,0,0,0,7,3,7,0,0,0,0,0,0,0,0
0,0,0,0,0,7,0,0,0,0,3,0,0,0,0,0,0,0,20,0,0,7,3,7,7,7,0,0,0,0,0,0,0
0,0,0,0,7,7,7,7,0,0,3,3,0,0,0,13,14,0,20,0,0,3,3,7,7,7,0,0,0,0,0,0,0
0,0,0,0,0,7,7,7,7,0,0,3,3,0,0,13,14,9,20,0,3,3,7,7,7,7,0,0,0,0,0,0,0
0,0,0,0,0,0,0,7,0,0,0,0,7,32,3,13,14,0,3,3,7,7,31,7,7,7,0,0,0,0,0,0,0
0,0,0,0,0,0,0,7,7,7,0,7,7,7,0,3,3,3,0,7,7,7,7,7,7,7,0,0,0,0,0,0,0
0,0,0,0,0,0,7,7,7,7,7,0,7,0,0,0,0,0,7,7,7,7,7,7,7,0,0,0,0,0,0,0,0
0,0,0,0,0,0,7,7,31,31,7,0,0,0,0,0,0,0,0,7,0,7,7,7,0,0,0,0,0,0,0,0,0
0,0,0,0,0,7,7,7,7,7,7,0,0,0,0,0,0,0,0,0,0,0,0,0,0,0,0,0,0,0,0,0,0
0,0,0,0,0,7,7,7,7,7,7,0,0,0,0,0,0,0,0,0,0,0,0,0,0,0,0,0,0,0,0,0,0
0,0,0,0,0,7,7,7,7,7,7,0,0,0,0,0,0,0,0,0,0,0,0,0,0,0,0,0,0,0,0,0,0
0,0,0,0,0,0,7,7,7,7,7,7,0,0,0,0,0,0,0,0,0,0,0,0,0,0,0,0,0,0,0,0,0
0,0,0,0,0,0,0,7,7,7,7,7,0,0,0,0,0,0,0,0,0,0,0,0,0,0,0,0,0,0,0,0,0
0,0,0,0,0,0,0,7,7,7,7,7,0,0,0,0,0,0,0,0,0,0,0,0,0,0,0,0,0,0,0,0,0
endlayer

layer
0,0,0,0,0,0,0,0,0,0,0,0,0,0,0,0,0,0,0,0,0,0,0,0,0,0,0,0,0,0,0,0,0
0,0,0,0,0,0,0,0,0,0,0,0,0,0,0,0,0,0,0,0,0,0,0,0,0,0,0,0,0,0,0,0,0
0,0,0,0,0,0,0,0,0,0,0,0,0,0,0,0,0,0,0,0,0,0,0,0,0,0,0,0,0,0,0,0,0
0,0,0,0,0,0,0,0,0,0,0,0,0,0,0,0,0,0,0,0,0,0,0,0,0,0,0,0,0,0,0,0,0
0,0,0,0,0,0,0,0,0,0,0,0,0,0,0,0,0,0,0,0,0,0,0,7,0,0,0,0,0,0,0,0,0
0,0,0,0,0,0,0,0,0,0,0,0,0,0,0,0,0,0,0,0,0,0,7,7,7,7,0,0,0,0,0,0,0
0,0,0,0,0,0,0,7,7,7,7,0,0,0,0,0,0,0,0,0,0,0,0,7,7,7,7,0,0,0,0,0,0
0,0,0,0,0,0,7,7,7,7,7,7,0,0,0,0,0,0,0,0,0,0,7,7,7,7,0,0,0,0,0,0,0
0,0,0,0,0,0,0,7,7,7,7,7,0,0,0,3,3,3,0,0,0,7,7,7,7,7,0,0,0,0,0,0,0
0,0,0,0,0,0,0,7,7,7,7,7,0,3,3,0,0,0,3,3,0,7,7,7,7,7,0,0,0,0,0,0,0
0,0,0,0,0,0,0,7,7,7,7,3,3,0,0,0,0,0,0,0,3,3,7,7,7,7,0,0,0,0,0,0,0
0,0,0,0,0,0,7,7,7,0,3,3,0,0,0,0,0,0,0,0,0,3,3,7,7,0,0,0,0,0,0,0,0
0,0,0,0,0,0,0,7,0,0,3,0,0,0,0,0,0,0,0,0,0,0,3,3,0,0,0,0,0,0,0,0,0
0,0,0,0,0,0,0,0,0,3,0,0,0,0,0,0,0,0,0,0,0,0,0,32,0,0,0,0,0,0,0,0,0
0,0,0,0,0,0,0,0,0,3,0,0,0,0,0,0,0,0,0,0,0,0,0,3,0,0,0,0,0,0,0,0,0
0,0,0,0,0,0,0,0,3,0,0,0,0,0,0,0,0,0,0,0,0,0,0,0,3,0,0,0,0,0,0,0,0
0,0,0,0,0,0,0,0,3,0,0,0,0,0,0,0,0,0,0,0,0,0,0,0,3,0,0,0,0,0,0,0,0
0,0,0,0,0,0,0,0,3,0,0,0,0,0,0,0,0,0,0,0,0,0,0,0,3,0,0,0,0,0,0,0,0
0,0,0,0,0,0,0,0,0,3,0,0,0,0,0,0,0,0,0,0,0,0,0,3,0,0,0,0,0,0,0,0,0
0,0,0,0,0,0,0,0,0,3,0,0,0,0,0,0,0,0,0,0,0,0,0,3,0,0,0,0,0,0,0,0,0
0,0,0,0,0,0,0,0,0,0,3,0,0,13,14,0,20,20,0,0,0,0,3,7,0,0,0,0,0,0,0,0,0
0,0,0,0,0,0,0,0,0,0,3,3,13,13,14,9,20,0,0,0,0,3,3,7,7,0,0,0,0,0,0,0,0
0,0,0,0,0,0,0,0,0,0,0,3,3,13,14,0,0,0,0,0,3,3,7,7,7,7,0,0,0,0,0,0,0
0,0,0,0,0,0,0,0,0,0,0,0,0,3,3,0,0,0,3,3,0,7,7,7,7,7,0,0,0,0,0,0,0
0,0,0,0,0,0,0,7,7,7,0,0,0,0,0,3,3,3,0,0,0,7,7,7,7,7,0,0,0,0,0,0,0
0,0,0,0,0,0,7,7,7,7,7,0,0,0,0,0,0,0,0,0,0,0,7,7,7,0,0,0,0,0,0,0,0
0,0,0,0,0,0,7,7,7,7,7,0,0,0,0,0,0,0,0,0,0,0,0,0,0,0,0,0,0,0,0,0,0
0,0,0,0,0,0,7,7,7,7,7,0,0,0,0,0,0,0,0,0,0,0,0,0,0,0,0,0,0,0,0,0,0
0,0,0,0,0,0,7,7,7,7,0,0,0,0,0,0,0,0,0,0,0,0,0,0,0,0,0,0,0,0,0,0,0
0,0,0,0,0,0,0,7,7,0,0,0,0,0,0,0,0,0,0,0,0,0,0,0,0,0,0,0,0,0,0,0,0
0,0,0,0,0,0,0,0,0,7,0,0,0,0,0,0,0,0,0,0,0,0,0,0,0,0,0,0,0,0,0,0,0
0,0,0,0,0,0,0,0,7,7,7,0,0,0,0,0,0,0,0,0,0,0,0,0,0,0,0,0,0,0,0,0,0
0,0,0,0,0,0,0,0,0,7,0,0,0,0,0,0,0,0,0,0,0,0,0,0,0,0,0,0,0,0,0,0,0
endlayer

layer
0,0,0,0,0,0,0,0,0,0,0,0,0,0,0,0,0,0,0,0,0,0,0,0,0,0,0,0,0,0,0,0,0
0,0,0,0,0,0,0,0,0,0,0,0,0,0,0,0,0,0,0,0,0,0,0,0,0,0,0,0,0,0,0,0,0
0,0,0,0,0,0,0,0,0,0,0,0,0,0,0,0,0,0,0,0,0,0,0,0,0,0,0,0,0,0,0,0,0
0,0,0,0,0,0,0,0,0,0,0,0,0,0,0,0,0,0,0,0,0,0,0,0,0,0,0,0,0,0,0,0,0
0,0,0,0,0,0,0,0,0,0,0,0,0,0,0,0,0,0,0,0,0,0,0,0,0,0,0,0,0,0,0,0,0
0,0,0,0,0,0,0,0,0,0,0,0,0,0,0,0,0,0,0,0,0,0,0,0,0,0,0,0,0,0,0,0,0
0,0,0,0,0,0,0,0,0,0,0,0,0,0,0,0,0,0,0,0,0,0,0,0,0,0,0,0,0,0,0,0,0
0,0,0,0,0,0,0,0,0,7,0,0,0,0,0,0,0,0,0,0,0,0,0,0,0,0,0,0,0,0,0,0,0
0,0,0,0,0,0,0,0,7,7,7,0,0,0,0,3,3,3,0,0,0,0,0,7,0,0,0,0,0,0,0,0,0
0,0,0,0,0,0,0,0,0,7,0,0,0,3,3,0,0,0,3,3,0,0,7,7,7,0,0,0,0,0,0,0,0
0,0,0,0,0,0,0,0,0,0,0,3,3,0,0,0,0,0,0,0,3,3,0,7,0,0,0,0,0,0,0,0,0
0,0,0,0,0,0,0,0,0,0,3,3,0,0,0,0,0,0,0,0,0,3,3,0,0,0,0,0,0,0,0,0,0
0,0,0,0,0,0,0,0,0,0,3,0,0,0,0,0,0,0,0,0,0,0,3,3,0,0,0,0,0,0,0,0,0
0,0,0,0,0,0,0,0,0,3,0,0,0,0,0,0,0,0,0,0,0,0,0,3,0,0,0,0,0,0,0,0,0
0,0,0,0,0,0,0,0,0,3,0,0,0,0,0,0,0,0,0,0,0,0,0,3,0,0,0,0,0,0,0,0,0
0,0,0,0,0,0,0,0,3,0,0,0,0,0,0,0,0,0,0,0,0,0,0,0,3,0,0,0,0,0,0,0,0
0,0,0,0,0,0,0,0,3,0,0,0,0,0,0,0,0,0,0,0,0,0,0,0,3,0,0,0,0,0,0,0,0
0,0,0,0,0,0,0,0,3,0,0,0,0,0,0,0,0,9,0,0,0,0,0,0,3,0,0,0,0,0,0,0,0
0,0,0,0,0,0,0,0,0,3,0,0,0,0,0,9,0,0,0,0,0,0,0,3,0,0,0,0,0,0,0,0,0
0,0,0,0,0,0,0,0,0,3,13,13,13,0,20,0,0,0,0,0,0,0,0,3,0,0,0,0,0,0,0,0,0
0,0,0,0,0,0,0,0,0,0,3,14,14,0,20,0,0,0,0,0,0,0,3,0,0,0,0,0,0,0,0,0,0
0,0,0,0,0,0,0,0,0,0,3,3,20,0,20,0,0,0,0,0,0,3,3,0,0,0,0,0,0,0,0,0,0
0,0,0,0,0,0,0,0,0,0,0,3,3,0,0,0,0,0,0,0,3,3,0,7,0,0,0,0,0,0,0,0,0
0,0,0,0,0,0,0,0,0,0,0,0,0,3,3,0,0,0,3,3,0,0,7,7,7,0,0,0,0,0,0,0,0
0,0,0,0,0,0,0,0,0,0,0,0,0,0,0,3,3,3,0,0,0,0,0,7,0,0,0,0,0,0,0,0,0
0,0,0,0,0,0,0,0,7,0,0,0,0,0,0,0,0,0,0,0,0,0,0,0,0,0,0,0,0,0,0,0,0
0,0,0,0,0,0,0,7,7,7,0,0,0,0,0,0,0,0,0,0,0,0,0,0,0,0,0,0,0,0,0,0,0
0,0,0,0,0,0,0,0,7,0,0,0,0,0,0,0,0,0,0,0,0,0,0,0,0,0,0,0,0,0,0,0,0
0,0,0,0,0,0,0,0,0,0,0,0,0,0,0,0,0,0,0,0,0,0,0,0,0,0,0,0,0,0,0,0,0
0,0,0,0,0,0,0,0,0,0,0,0,0,0,0,0,0,0,0,0,0,0,0,0,0,0,0,0,0,0,0,0,0
0,0,0,0,0,0,0,0,0,0,0,0,0,0,0,0,0,0,0,0,0,0,0,0,0,0,0,0,0,0,0,0,0
0,0,0,0,0,0,0,0,0,0,0,0,0,0,0,0,0,0,0,0,0,0,0,0,0,0,0,0,0,0,0,0,0
0,0,0,0,0,0,0,0,0,0,0,0,0,0,0,0,0,0,0,0,0,0,0,0,0,0,0,0,0,0,0,0,0
endlayer

layer
0,0,0,0,0,0,0,0,0,0,0,0,0,0,0,0,0,0,0,0,0,0,0,0,0,0,0,0,0,0,0,0,0
0,0,0,0,0,0,0,0,0,0,0,0,0,0,0,0,0,0,0,0,0,0,0,0,0,0,0,0,0,0,0,0,0
0,0,0,0,0,0,0,0,0,0,0,0,0,0,0,0,0,0,0,0,0,0,0,0,0,0,0,0,0,0,0,0,0
0,0,0,0,0,0,0,0,0,0,0,0,0,0,0,0,0,0,0,0,0,0,0,0,0,0,0,0,0,0,0,0,0
0,0,0,0,0,0,0,0,0,0,0,0,0,0,0,0,0,0,0,0,0,0,0,0,0,0,0,0,0,0,0,0,0
0,0,0,0,0,0,0,0,0,0,0,0,0,0,0,0,0,0,0,0,0,0,0,0,0,0,0,0,0,0,0,0,0
0,0,0,0,0,0,0,0,0,0,0,0,0,0,0,0,0,0,0,0,0,0,0,0,0,0,0,0,0,0,0,0,0
0,0,0,0,0,0,0,0,0,0,0,0,0,0,0,0,0,0,0,0,0,0,0,0,0,0,0,0,0,0,0,0,0
0,0,0,0,0,0,0,0,0,0,0,0,0,0,0,0,3,0,0,0,0,0,0,0,0,0,0,0,0,0,0,0,0
0,0,0,0,0,0,0,0,0,0,0,0,0,0,3,3,0,3,3,0,0,0,0,0,0,0,0,0,0,0,0,0,0
0,0,0,0,0,0,0,0,0,0,0,0,3,3,0,0,0,0,0,3,3,0,0,0,0,0,0,0,0,0,0,0,0
0,0,0,0,0,0,0,0,0,0,0,3,0,0,0,0,0,0,0,0,0,3,0,0,0,0,0,0,0,0,0,0,0
0,0,0,0,0,0,0,0,0,0,3,0,0,0,0,0,0,0,0,0,0,0,3,0,0,0,0,0,0,0,0,0,0
0,0,0,0,0,0,0,0,0,0,3,0,0,0,0,0,0,0,0,0,0,0,3,0,0,0,0,0,0,0,0,0,0
0,0,0,0,0,0,0,0,0,3,0,0,0,0,0,0,0,0,0,0,0,0,0,3,0,0,0,0,0,0,0,0,0
0,0,0,0,0,0,0,0,0,3,0,0,0,0,0,0,0,0,0,0,0,0,0,3,0,0,0,0,0,0,0,0,0
0,0,0,0,0,0,0,0,3,0,0,0,0,0,0,0,0,0,0,0,0,0,0,0,3,0,0,0,0,0,0,0,0
0,0,0,0,0,0,0,0,0,3,13,13,13,0,0,0,0,0,0,0,0,0,0,3,0,0,0,0,0,0,0,0,0
0,0,0,0,0,0,0,0,0,3,14,14,14,0,0,0,0,0,0,0,0,0,0,3,0,0,0,0,0,0,0,0,0
0,0,0,0,0,0,0,0,0,0,3,20,20,0,0,0,0,0,0,0,0,0,3,0,0,0,0,0,0,0,0,0,0
0,0,0,0,0,0,0,0,0,0,3,0,0,9,0,0,0,0,0,0,0,0,3,0,0,0,0,0,0,0,0,0,0
0,0,0,0,0,0,0,0,0,0,0,3,0,0,0,0,0,0,0,0,0,3,0,0,0,0,0,0,0,0,0,0,0
0,0,0,0,0,0,0,0,0,0,0,0,3,3,0,0,0,0,0,3,3,0,0,0,0,0,0,0,0,0,0,0,0
0,0,0,0,0,0,0,0,0,0,0,0,0,0,3,3,0,3,3,0,0,0,0,0,0,0,0,0,0,0,0,0,0
0,0,0,0,0,0,0,0,0,0,0,0,0,0,0,0,3,0,0,0,0,0,0,0,0,0,0,0,0,0,0,0,0
0,0,0,0,0,0,0,0,0,0,0,0,0,0,0,0,0,0,0,0,0,0,0,0,0,0,0,0,0,0,0,0,0
0,0,0,0,0,0,0,0,0,0,0,0,0,0,0,0,0,0,0,0,0,0,0,0,0,0,0,0,0,0,0,0,0
0,0,0,0,0,0,0,0,0,0,0,0,0,0,0,0,0,0,0,0,0,0,0,0,0,0,0,0,0,0,0,0,0
0,0,0,0,0,0,0,0,0,0,0,0,0,0,0,0,0,0,0,0,0,0,0,0,0,0,0,0,0,0,0,0,0
0,0,0,0,0,0,0,0,0,0,0,0,0,0,0,0,0,0,0,0,0,0,0,0,0,0,0,0,0,0,0,0,0
0,0,0,0,0,0,0,0,0,0,0,0,0,0,0,0,0,0,0,0,0,0,0,0,0,0,0,0,0,0,0,0,0
0,0,0,0,0,0,0,0,0,0,0,0,0,0,0,0,0,0,0,0,0,0,0,0,0,0,0,0,0,0,0,0,0
0,0,0,0,0,0,0,0,0,0,0,0,0,0,0,0,0,0,0,0,0,0,0,0,0,0,0,0,0,0,0,0,0
endlayer

layer
0,0,0,0,0,0,0,0,0,0,0,0,0,0,0,0,0,0,0,0,0,0,0,0,0,0,0,0,0,0,0,0,0
0,0,0,0,0,0,0,0,0,0,0,0,0,0,0,0,0,0,0,0,0,0,0,0,0,0,0,0,0,0,0,0,0
0,0,0,0,0,0,0,0,0,0,0,0,0,0,0,0,0,0,0,0,0,0,0,0,0,0,0,0,0,0,0,0,0
0,0,0,0,0,0,0,0,0,0,0,0,0,0,0,0,0,0,0,0,0,0,0,0,0,0,0,0,0,0,0,0,0
0,0,0,0,0,0,0,0,0,0,0,0,0,0,0,0,0,0,0,0,0,0,0,0,0,0,0,0,0,0,0,0,0
0,0,0,0,0,0,0,0,0,0,0,0,0,0,0,0,0,0,0,0,0,0,0,0,0,0,0,0,0,0,0,0,0
0,0,0,0,0,0,0,0,0,0,0,0,0,0,0,0,0,0,0,0,0,0,0,0,0,0,0,0,0,0,0,0,0
0,0,0,0,0,0,0,0,0,0,0,0,0,0,0,0,0,0,0,0,0,0,0,0,0,0,0,0,0,0,0,0,0
0,0,0,0,0,0,0,0,0,0,0,0,0,0,0,0,3,0,0,0,0,0,0,0,0,0,0,0,0,0,0,0,0
0,0,0,0,0,0,0,0,0,0,0,0,0,0,3,3,0,3,3,0,0,0,0,0,0,0,0,0,0,0,0,0,0
0,0,0,0,0,0,0,0,0,0,0,0,3,3,0,0,0,0,0,3,3,0,0,0,0,0,0,0,0,0,0,0,0
0,0,0,0,0,0,0,0,0,0,0,3,0,0,0,0,0,0,0,0,0,3,0,0,0,0,0,0,0,0,0,0,0
0,0,0,0,0,0,0,0,0,0,3,0,0,0,0,0,0,0,0,0,0,0,3,0,0,0,0,0,0,0,0,0,0
0,0,0,0,0,0,0,0,0,0,3,0,0,0,0,0,0,0,0,0,0,0,3,0,0,0,0,0,0,0,0,0,0
0,0,0,0,0,0,0,0,0,3,0,0,0,0,0,0,0,0,0,0,0,0,0,3,0,0,0,0,0,0,0,0,0
0,0,0,0,0,0,0,0,0,3,13,13,13,0,0,0,0,0,0,0,0,0,0,3,0,0,0,0,0,0,0,0,0
0,0,0,0,0,0,0,0,3,14,14,14,14,0,0,0,0,0,0,0,0,0,0,0,3,0,0,0,0,0,0,0,0
0,0,0,0,0,0,0,0,0,3,0,9,0,0,0,0,0,0,0,0,0,0,0,3,0,0,0,0,0,0,0,0,0
0,0,0,0,0,0,0,0,0,3,0,20,0,0,0,0,0,0,0,0,0,0,0,3,0,0,0,0,0,0,0,0,0
0,0,0,0,0,0,0,0,0,0,3,20,0,0,0,0,0,0,0,0,0,0,3,0,0,0,0,0,0,0,0,0,0
0,0,0,0,0,0,0,0,0,0,3,0,0,0,0,0,0,0,0,0,0,0,3,0,0,0,0,0,0,0,0,0,0
0,0,0,0,0,0,0,0,0,0,0,32,0,0,0,0,0,0,0,0,0,3,0,0,0,0,0,0,0,0,0,0,0
0,0,0,0,0,0,0,0,0,0,0,0,3,3,0,0,0,0,0,3,3,0,0,0,0,0,0,0,0,0,0,0,0
0,0,0,0,0,0,0,0,0,0,0,0,0,0,3,3,33,3,3,0,0,0,0,0,0,0,0,0,0,0,0,0,0
0,0,0,0,0,0,0,0,0,0,0,0,0,0,0,0,3,0,0,0,0,0,0,0,0,0,0,0,0,0,0,0,0
0,0,0,0,0,0,0,0,0,0,0,0,0,0,0,0,0,0,0,0,0,0,0,0,0,0,0,0,0,0,0,0,0
0,0,0,0,0,0,0,0,0,0,0,0,0,0,0,0,0,0,0,0,0,0,0,0,0,0,0,0,0,0,0,0,0
0,0,0,0,0,0,0,0,0,0,0,0,0,0,0,0,0,0,0,0,0,0,0,0,0,0,0,0,0,0,0,0,0
0,0,0,0,0,0,0,0,0,0,0,0,0,0,0,0,0,0,0,0,0,0,0,0,0,0,0,0,0,0,0,0,0
0,0,0,0,0,0,0,0,0,0,0,0,0,0,0,0,0,0,0,0,0,0,0,0,0,0,0,0,0,0,0,0,0
0,0,0,0,0,0,0,0,0,0,0,0,0,0,0,0,0,0,0,0,0,0,0,0,0,0,0,0,0,0,0,0,0
0,0,0,0,0,0,0,0,0,0,0,0,0,0,0,0,0,0,0,0,0,0,0,0,0,0,0,0,0,0,0,0,0
0,0,0,0,0,0,0,0,0,0,0,0,0,0,0,0,0,0,0,0,0,0,0,0,0,0,0,0,0,0,0,0,0
endlayer

layer
0,0,0,0,0,0,0,0,0,0,0,0,0,0,0,0,0,0,0,0,0,0,0,0,0,0,0,0,0,0,0,0,0
0,0,0,0,0,0,0,0,0,0,0,0,0,0,0,0,0,0,0,0,0,0,0,0,0,0,0,0,0,0,0,0,0
0,0,0,0,0,0,0,0,0,0,0,0,0,0,0,0,0,0,0,0,0,0,0,0,0,0,0,0,0,0,0,0,0
0,0,0,0,0,0,0,0,0,0,0,0,0,0,0,0,0,0,0,0,0,0,0,0,0,0,0,0,0,0,0,0,0
0,0,0,0,0,0,0,0,0,0,0,0,0,0,0,0,0,0,0,0,0,0,0,0,0,0,0,0,0,0,0,0,0
0,0,0,0,0,0,0,0,0,0,0,0,0,0,0,0,0,0,0,0,0,0,0,0,0,0,0,0,0,0,0,0,0
0,0,0,0,0,0,0,0,0,0,0,0,0,0,0,0,0,0,0,0,0,0,0,0,0,0,0,0,0,0,0,0,0
0,0,0,0,0,0,0,0,0,0,0,0,0,0,0,0,0,0,0,0,0,0,0,0,0,0,0,0,0,0,0,0,0
0,0,0,0,0,0,0,0,0,0,0,0,0,0,0,0,3,0,0,0,0,0,0,0,0,0,0,0,0,0,0,0,0
0,0,0,0,0,0,0,0,0,0,0,0,0,0,3,3,0,3,3,0,0,0,0,0,0,0,0,0,0,0,0,0,0
0,0,0,0,0,0,0,0,0,0,0,0,3,3,0,0,0,0,0,3,3,0,0,0,0,0,0,0,0,0,0,0,0
0,0,0,0,0,0,0,0,0,0,0,3,0,0,0,0,0,0,0,0,0,3,0,0,0,0,0,0,0,0,0,0,0
0,0,0,0,0,0,0,0,0,0,3,0,0,0,0,0,0,0,0,0,0,0,3,0,0,0,0,0,0,0,0,0,0
0,0,0,0,0,0,0,0,0,0,3,13,13,13,20,0,0,0,0,0,0,0,3,0,0,0,0,0,0,0,0,0,0
0,0,0,0,0,0,0,0,0,3,14,14,14,0,0,9,0,0,0,0,0,0,0,32,0,0,0,0,0,0,0,0,0
0,0,0,0,0,0,0,0,0,3,0,20,20,0,0,0,0,0,0,0,0,0,0,3,0,0,0,0,0,0,0,0,0
0,0,0,0,0,0,0,0,3,0,0,0,20,0,0,0,0,0,0,0,0,0,0,0,3,0,0,0,0,0,0,0,0
0,0,0,0,0,0,0,0,0,3,0,0,0,0,0,0,0,0,0,0,0,0,0,3,0,0,0,0,0,0,0,0,0
0,0,0,0,0,0,0,0,0,3,0,0,0,0,0,0,0,0,0,0,0,0,0,3,0,0,0,0,0,0,0,0,0
0,0,0,0,0,0,0,0,0,0,3,0,0,0,0,0,0,0,0,0,0,0,3,0,0,0,0,0,0,0,0,0,0
0,0,0,0,0,0,0,0,0,0,3,0,0,0,0,0,0,0,0,0,0,0,3,0,0,0,0,0,0,0,0,0,0
0,0,0,0,0,0,0,0,0,0,0,3,0,0,0,0,0,0,0,0,0,3,0,0,0,0,0,0,0,0,0,0,0
0,0,0,0,0,0,0,0,0,0,0,0,3,3,0,0,0,0,0,3,3,0,0,0,0,0,0,0,0,0,0,0,0
0,0,0,0,0,0,0,0,0,0,0,0,0,0,3,3,0,3,3,0,0,0,0,0,0,0,0,0,0,0,0,0,0
0,0,0,0,0,0,0,0,0,0,0,0,0,0,0,0,3,0,0,0,0,0,0,0,0,0,0,0,0,0,0,0,0
0,0,0,0,0,0,0,0,0,0,0,0,0,0,0,0,0,0,0,0,0,0,0,0,0,0,0,0,0,0,0,0,0
0,0,0,0,0,0,0,0,0,0,0,0,0,0,0,0,0,0,0,0,0,0,0,0,0,0,0,0,0,0,0,0,0
0,0,0,0,0,0,0,0,0,0,0,0,0,0,0,0,0,0,0,0,0,0,0,0,0,0,0,0,0,0,0,0,0
0,0,0,0,0,0,0,0,0,0,0,0,0,0,0,0,0,0,0,0,0,0,0,0,0,0,0,0,0,0,0,0,0
0,0,0,0,0,0,0,0,0,0,0,0,0,0,0,0,0,0,0,0,0,0,0,0,0,0,0,0,0,0,0,0,0
0,0,0,0,0,0,0,0,0,0,0,0,0,0,0,0,0,0,0,0,0,0,0,0,0,0,0,0,0,0,0,0,0
0,0,0,0,0,0,0,0,0,0,0,0,0,0,0,0,0,0,0,0,0,0,0,0,0,0,0,0,0,0,0,0,0
0,0,0,0,0,0,0,0,0,0,0,0,0,0,0,0,0,0,0,0,0,0,0,0,0,0,0,0,0,0,0,0,0
endlayer

layer
0,0,0,0,0,0,0,0,0,0,0,0,0,0,0,0,0,0,0,0,0,0,0,0,0,0,0,0,0,0,0,0,0
0,0,0,0,0,0,0,0,0,0,0,0,0,0,0,0,0,0,0,0,0,0,0,0,0,0,0,0,0,0,0,0,0
0,0,0,0,0,0,0,0,0,0,0,0,0,0,0,0,0,0,0,0,0,0,0,0,0,0,0,0,0,0,0,0,0
0,0,0,0,0,0,0,0,0,0,0,0,0,0,0,0,0,0,0,0,0,0,0,0,0,0,0,0,0,0,0,0,0
0,0,0,0,0,0,0,0,0,0,0,0,0,0,0,0,0,0,0,0,0,0,0,0,0,0,0,0,0,0,0,0,0
0,0,0,0,0,0,0,0,0,0,0,0,0,0,0,0,0,0,0,0,0,0,0,0,0,0,0,0,0,0,0,0,0
0,0,0,0,0,0,0,0,0,0,0,0,0,0,0,0,0,0,0,0,0,0,0,0,0,0,0,0,0,0,0,0,0
0,0,0,0,0,0,0,0,0,0,0,0,0,0,0,0,0,0,0,0,0,0,0,0,0,0,0,0,0,0,0,0,0
0,0,0,0,0,0,0,0,0,0,0,0,0,0,0,0,3,0,0,0,0,0,0,0,0,0,0,0,0,0,0,0,0
0,0,0,0,0,0,0,0,0,0,0,0,0,0,3,3,0,3,3,0,0,0,0,0,0,0,0,0,0,0,0,0,0
0,0,0,0,0,0,0,0,0,0,0,0,3,3,13,0,0,0,0,3,3,0,0,0,0,0,0,0,0,0,0,0,0
0,0,0,0,0,0,0,0,0,0,0,3,45,14,13,0,0,0,0,0,0,3,0,0,0,0,0,0,0,0,0,0,0
0,0,0,0,0,0,0,0,0,0,3,14,14,14,13,0,0,0,0,0,0,0,3,0,0,0,0,0,0,0,0,0,0
0,0,0,0,0,0,0,0,0,0,3,0,20,20,0,0,0,0,0,0,0,0,3,0,0,0,0,0,0,0,0,0,0
0,0,0,0,0,0,0,0,0,3,0,20,20,0,0,9,0,0,0,0,0,0,0,3,0,0,0,0,0,0,0,0,0
0,0,0,0,0,0,0,0,0,3,0,0,0,0,0,0,0,0,0,0,0,0,0,3,0,0,0,0,0,0,0,0,0
0,0,0,0,0,0,0,0,3,0,0,0,0,0,0,0,0,0,0,0,0,0,0,0,3,0,0,0,0,0,0,0,0
0,0,0,0,0,0,0,0,0,3,0,0,0,0,0,0,0,0,0,0,0,0,0,3,0,0,0,0,0,0,0,0,0
0,0,0,0,0,0,0,0,0,3,0,0,0,0,0,0,0,0,0,0,0,0,0,3,0,0,0,0,0,0,0,0,0
0,0,0,0,0,0,0,0,0,0,3,0,0,0,0,0,0,0,0,0,0,0,3,0,0,0,0,0,0,0,0,0,0
0,0,0,0,0,0,0,0,0,0,3,0,0,0,0,0,0,0,0,0,0,0,3,0,0,0,0,0,0,0,0,0,0
0,0,0,0,0,0,0,0,0,0,0,3,0,0,0,0,0,0,0,0,0,3,0,0,0,0,0,0,0,0,0,0,0
0,0,0,0,0,0,0,0,0,0,0,0,3,3,0,0,0,0,0,3,3,0,0,0,0,0,0,0,0,0,0,0,0
0,0,0,0,0,0,0,0,0,0,0,0,0,0,3,3,0,3,3,0,0,0,0,0,0,0,0,0,0,0,0,0,0
0,0,0,0,0,0,0,0,0,0,0,0,0,0,0,0,3,0,0,0,0,0,0,0,0,0,0,0,0,0,0,0,0
0,0,0,0,0,0,0,0,0,0,0,0,0,0,0,0,0,0,0,0,0,0,0,0,0,0,0,0,0,0,0,0,0
0,0,0,0,0,0,0,0,0,0,0,0,0,0,0,0,0,0,0,0,0,0,0,0,0,0,0,0,0,0,0,0,0
0,0,0,0,0,0,0,0,0,0,0,0,0,0,0,0,0,0,0,0,0,0,0,0,0,0,0,0,0,0,0,0,0
0,0,0,0,0,0,0,0,0,0,0,0,0,0,0,0,0,0,0,0,0,0,0,0,0,0,0,0,0,0,0,0,0
0,0,0,0,0,0,0,0,0,0,0,0,0,0,0,0,0,0,0,0,0,0,0,0,0,0,0,0,0,0,0,0,0
0,0,0,0,0,0,0,0,0,0,0,0,0,0,0,0,0,0,0,0,0,0,0,0,0,0,0,0,0,0,0,0,0
0,0,0,0,0,0,0,0,0,0,0,0,0,0,0,0,0,0,0,0,0,0,0,0,0,0,0,0,0,0,0,0,0
0,0,0,0,0,0,0,0,0,0,0,0,0,0,0,0,0,0,0,0,0,0,0,0,0,0,0,0,0,0,0,0,0
endlayer

layer
0,0,0,0,0,0,0,0,0,0,0,0,0,0,0,0,0,0,0,0,0,0,0,0,0,0,0,0,0,0,0,0,0
0,0,0,0,0,0,0,0,0,0,0,0,0,0,0,0,0,0,0,0,0,0,0,0,0,0,0,0,0,0,0,0,0
0,0,0,0,0,0,0,0,0,0,0,0,0,0,0,0,0,0,0,0,0,0,0,0,0,0,0,0,0,0,0,0,0
0,0,0,0,0,0,0,0,0,0,0,0,0,0,0,0,0,0,0,0,0,0,0,0,0,0,0,0,0,0,0,0,0
0,0,0,0,0,0,0,0,0,0,0,0,0,0,0,0,0,0,0,0,0,0,0,0,0,0,0,0,0,0,0,0,0
0,0,0,0,0,0,0,0,0,0,0,0,0,0,0,0,0,0,0,0,0,0,0,0,0,0,0,0,0,0,0,0,0
0,0,0,0,0,0,0,0,0,0,0,0,0,0,0,0,0,0,0,0,0,0,0,0,0,0,0,0,0,0,0,0,0
0,0,0,0,0,0,0,0,0,0,0,0,0,0,0,0,0,0,0,0,0,0,0,0,0,0,0,0,0,0,0,0,0
0,0,0,0,0,0,0,0,0,0,0,0,0,0,0,0,0,0,0,0,0,0,0,0,0,0,0,0,0,0,0,0,0
0,0,0,0,0,0,0,0,0,0,0,0,0,0,0,3,3,3,0,0,0,0,0,0,0,0,0,0,0,0,0,0,0
0,0,0,0,0,0,0,0,0,0,0,0,0,3,3,14,13,0,3,3,0,0,0,0,0,0,0,0,0,0,0,0,0
0,0,0,0,0,0,0,0,0,0,0,0,3,0,0,14,13,0,0,0,3,0,0,0,0,0,0,0,0,0,0,0,0
0,0,0,0,0,0,0,0,0,0,0,3,20,20,0,14,13,0,0,0,0,3,0,0,0,0,0,0,0,0,0,0,0
0,0,0,0,0,0,0,0,0,0,3,0,0,0,0,9,0,0,0,0,0,0,3,0,0,0,0,0,0,0,0,0,0
0,0,0,0,0,0,0,0,0,0,3,0,0,0,0,9,0,0,0,0,0,0,3,0,0,0,0,0,0,0,0,0,0
0,0,0,0,0,0,0,0,0,3,0,0,0,0,0,0,9,0,0,0,0,0,0,3,0,0,0,0,0,0,0,0,0
0,0,0,0,0,0,0,0,0,3,0,0,0,0,0,0,0,0,0,0,0,0,0,3,0,0,0,0,0,0,0,0,0
0,0,0,0,0,0,0,0,0,3,0,0,0,0,0,0,0,0,0,0,0,0,0,3,0,0,0,0,0,0,0,0,0
0,0,0,0,0,0,0,0,0,0,3,0,0,0,0,0,0,0,0,0,0,0,3,0,0,0,0,0,0,0,0,0,0
0,0,0,0,0,0,0,0,0,0,3,0,0,0,0,0,0,0,0,0,0,0,3,0,0,0,0,0,0,0,0,0,0
0,0,0,0,0,0,0,0,0,0,0,3,0,0,0,0,0,0,0,0,0,3,0,0,0,0,0,0,0,0,0,0,0
0,0,0,0,0,0,0,0,0,0,0,0,3,0,0,0,0,0,0,0,3,0,0,0,0,0,0,0,0,0,0,0,0
0,0,0,0,0,0,0,0,0,0,0,0,0,3,3,0,0,0,3,3,0,0,0,0,0,0,0,0,0,0,0,0,0
0,0,0,0,0,0,0,0,0,0,0,0,0,0,0,3,3,3,0,0,0,0,0,0,0,0,0,0,0,0,0,0,0
0,0,0,0,0,0,0,0,0,0,0,0,0,0,0,0,0,0,0,0,0,0,0,0,0,0,0,0,0,0,0,0,0
0,0,0,0,0,0,0,0,0,0,0,0,0,0,0,0,0,0,0,0,0,0,0,0,0,0,0,0,0,0,0,0,0
0,0,0,0,0,0,0,0,0,0,0,0,0,0,0,0,0,0,0,0,0,0,0,0,0,0,0,0,0,0,0,0,0
0,0,0,0,0,0,0,0,0,0,0,0,0,0,0,0,0,0,0,0,0,0,0,0,0,0,0,0,0,0,0,0,0
0,0,0,0,0,0,0,0,0,0,0,0,0,0,0,0,0,0,0,0,0,0,0,0,0,0,0,0,0,0,0,0,0
0,0,0,0,0,0,0,0,0,0,0,0,0,0,0,0,0,0,0,0,0,0,0,0,0,0,0,0,0,0,0,0,0
0,0,0,0,0,0,0,0,0,0,0,0,0,0,0,0,0,0,0,0,0,0,0,0,0,0,0,0,0,0,0,0,0
0,0,0,0,0,0,0,0,0,0,0,0,0,0,0,0,0,0,0,0,0,0,0,0,0,0,0,0,0,0,0,0,0
0,0,0,0,0,0,0,0,0,0,0,0,0,0,0,0,0,0,0,0,0,0,0,0,0,0,0,0,0,0,0,0,0
endlayer

layer
0,0,0,0,0,0,0,0,0,0,0,0,0,0,0,0,0,0,0,0,0,0,0,0,0,0,0,0,0,0,0,0,0
0,0,0,0,0,0,0,0,0,0,0,0,0,0,0,0,0,0,0,0,0,0,0,0,0,0,0,0,0,0,0,0,0
0,0,0,0,0,0,0,0,0,0,0,0,0,0,0,0,0,0,0,0,0,0,0,0,0,0,0,0,0,0,0,0,0
0,0,0,0,0,0,0,0,0,0,0,0,0,0,0,0,0,0,0,0,0,0,0,0,0,0,0,0,0,0,0,0,0
0,0,0,0,0,0,0,0,0,0,0,0,0,0,0,0,0,0,0,0,0,0,0,0,0,0,0,0,0,0,0,0,0
0,0,0,0,0,0,0,0,0,0,0,0,0,0,0,0,0,0,0,0,0,0,0,0,0,0,0,0,0,0,0,0,0
0,0,0,0,0,0,0,0,0,0,0,0,0,0,0,0,0,0,0,0,0,0,0,0,0,0,0,0,0,0,0,0,0
0,0,0,0,0,0,0,0,0,0,0,0,0,0,0,0,0,0,0,0,0,0,0,0,0,0,0,0,0,0,0,0,0
0,0,0,0,0,0,0,0,0,0,0,0,0,0,0,0,0,0,0,0,0,0,0,0,0,0,0,0,0,0,0,0,0
0,0,0,0,0,0,0,0,0,0,0,0,0,0,0,3,3,3,0,0,0,0,0,0,0,0,0,0,0,0,0,0,0
0,0,0,0,0,0,0,0,0,0,0,0,0,3,3,0,0,14,3,3,0,0,0,0,0,0,0,0,0,0,0,0,0
0,0,0,0,0,0,0,0,0,0,0,0,3,0,0,0,20,14,13,0,3,0,0,0,0,0,0,0,0,0,0,0,0
0,0,0,0,0,0,0,0,0,0,0,3,0,0,0,0,0,14,13,0,0,3,0,0,0,0,0,0,0,0,0,0,0
0,0,0,0,0,0,0,0,0,0,3,0,0,0,0,0,0,0,13,0,0,0,32,0,0,0,0,0,0,0,0,0,0
0,0,0,0,0,0,0,0,0,0,3,0,0,0,0,0,0,0,0,0,0,0,3,0,0,0,0,0,0,0,0,0,0
0,0,0,0,0,0,0,0,0,3,0,0,0,0,0,0,0,0,0,0,0,0,0,3,0,0,0,0,0,0,0,0,0
0,0,0,0,0,0,0,0,0,3,0,0,0,0,0,0,0,0,0,0,0,0,0,3,0,0,0,0,0,0,0,0,0
0,0,0,0,0,0,0,0,0,3,0,0,0,0,0,0,0,0,0,0,0,0,0,3,0,0,0,0,0,0,0,0,0
0,0,0,0,0,0,0,0,0,0,3,0,0,0,0,0,0,0,0,0,0,0,3,0,0,0,0,0,0,0,0,0,0
0,0,0,0,0,0,0,0,0,0,3,0,0,0,0,0,0,0,0,0,0,0,3,0,0,0,0,0,0,0,0,0,0
0,0,0,0,0,0,0,0,0,0,0,3,0,0,0,0,0,0,0,0,0,3,0,0,0,0,0,0,0,0,0,0,0
0,0,0,0,0,0,0,0,0,0,0,0,3,0,0,0,0,0,0,0,3,0,0,0,0,0,0,0,0,0,0,0,0
0,0,0,0,0,0,0,0,0,0,0,0,0,3,3,0,0,0,3,3,0,0,0,0,0,0,0,0,0,0,0,0,0
0,0,0,0,0,0,0,0,0,0,0,0,0,0,0,3,3,3,0,0,0,0,0,0,0,0,0,0,0,0,0,0,0
0,0,0,0,0,0,0,0,0,0,0,0,0,0,0,0,0,0,0,0,0,0,0,0,0,0,0,0,0,0,0,0,0
0,0,0,0,0,0,0,0,0,0,0,0,0,0,0,0,0,0,0,0,0,0,0,0,0,0,0,0,0,0,0,0,0
0,0,0,0,0,0,0,0,0,0,0,0,0,0,0,0,0,0,0,0,0,0,0,0,0,0,0,0,0,0,0,0,0
0,0,0,0,0,0,0,0,0,0,0,0,0,0,0,0,0,0,0,0,0,0,0,0,0,0,0,0,0,0,0,0,0
0,0,0,0,0,0,0,0,0,0,0,0,0,0,0,0,0,0,0,0,0,0,0,0,0,0,0,0,0,0,0,0,0
0,0,0,0,0,0,0,0,0,0,0,0,0,0,0,0,0,0,0,0,0,0,0,0,0,0,0,0,0,0,0,0,0
0,0,0,0,0,0,0,0,0,0,0,0,0,0,0,0,0,0,0,0,0,0,0,0,0,0,0,0,0,0,0,0,0
0,0,0,0,0,0,0,0,0,0,0,0,0,0,0,0,0,0,0,0,0,0,0,0,0,0,0,0,0,0,0,0,0
0,0,0,0,0,0,0,0,0,0,0,0,0,0,0,0,0,0,0,0,0,0,0,0,0,0,0,0,0,0,0,0,0
endlayer

layer
0,0,0,0,0,0,0,0,0,0,0,0,0,0,0,0,0,0,0,0,0,0,0,0,0,0,0,0,0,0,0,0,0
0,0,0,0,0,0,0,0,0,0,0,0,0,0,0,0,0,0,0,0,0,0,0,0,0,0,0,0,0,0,0,0,0
0,0,0,0,0,0,0,0,0,0,0,0,0,0,0,0,0,0,0,0,0,0,0,0,0,0,0,0,0,0,0,0,0
0,0,0,0,0,0,0,0,0,0,0,0,0,0,0,0,0,0,0,0,0,0,0,0,0,0,0,0,0,0,0,0,0
0,0,0,0,0,0,0,0,0,0,0,0,0,0,0,0,0,0,0,0,0,0,0,0,0,0,0,0,0,0,0,0,0
0,0,0,0,0,0,0,0,0,0,0,0,0,0,0,0,0,0,0,0,0,0,0,0,0,0,0,0,0,0,0,0,0
0,0,0,0,0,0,0,0,0,0,0,0,0,0,0,0,0,0,0,0,0,0,0,0,0,0,0,0,0,0,0,0,0
0,0,0,0,0,0,0,0,0,0,0,0,0,0,0,0,0,0,0,0,0,0,0,0,0,0,0,0,0,0,0,0,0
0,0,0,0,0,0,0,0,0,0,0,0,0,0,0,0,0,0,0,0,0,0,0,0,0,0,0,0,0,0,0,0,0
0,0,0,0,0,0,0,0,0,0,0,0,0,0,0,3,3,3,0,0,0,0,0,0,0,0,0,0,0,0,0,0,0
0,0,0,0,0,0,0,0,0,0,0,0,0,3,3,0,0,0,3,3,0,0,0,0,0,0,0,0,0,0,0,0,0
0,0,0,0,0,0,0,0,0,0,0,0,3,0,0,0,0,0,0,14,3,0,0,0,0,0,0,0,0,0,0,0,0
0,0,0,0,0,0,0,0,0,0,0,3,0,0,0,0,0,9,0,14,13,3,0,0,0,0,0,0,0,0,0,0,0
0,0,0,0,0,0,0,0,0,0,3,0,0,0,0,0,0,0,20,14,13,13,3,0,0,0,0,0,0,0,0,0,0
0,0,0,0,0,0,0,0,0,0,3,0,0,0,0,0,0,0,0,13,13,13,3,0,0,0,0,0,0,0,0,0,0
0,0,0,0,0,0,0,0,0,3,0,0,0,0,0,0,0,9,0,0,0,0,0,3,0,0,0,0,0,0,0,0,0
0,0,0,0,0,0,0,0,0,3,0,0,0,0,0,0,0,0,0,0,0,0,0,3,0,0,0,0,0,0,0,0,0
0,0,0,0,0,0,0,0,0,3,0,0,0,0,0,0,0,0,0,0,0,0,0,3,0,0,0,0,0,0,0,0,0
0,0,0,0,0,0,0,0,0,0,3,0,0,0,0,0,0,0,0,0,0,0,3,0,0,0,0,0,0,0,0,0,0
0,0,0,0,0,0,0,0,0,0,3,0,0,0,0,0,0,0,0,0,0,0,3,0,0,0,0,0,0,0,0,0,0
0,0,0,0,0,0,0,0,0,0,0,32,0,0,0,0,0,0,0,0,0,3,0,0,0,0,0,0,0,0,0,0,0
0,0,0,0,0,0,0,0,0,0,0,0,3,0,0,0,0,0,0,0,3,0,0,0,0,0,0,0,0,0,0,0,0
0,0,0,0,0,0,0,0,0,0,0,0,0,3,3,0,0,0,3,3,0,0,0,0,0,0,0,0,0,0,0,0,0
0,0,0,0,0,0,0,0,0,0,0,0,0,0,0,3,3,3,0,0,0,0,0,0,0,0,0,0,0,0,0,0,0
0,0,0,0,0,0,0,0,0,0,0,0,0,0,0,0,0,0,0,0,0,0,0,0,0,0,0,0,0,0,0,0,0
0,0,0,0,0,0,0,0,0,0,0,0,0,0,0,0,0,0,0,0,0,0,0,0,0,0,0,0,0,0,0,0,0
0,0,0,0,0,0,0,0,0,0,0,0,0,0,0,0,0,0,0,0,0,0,0,0,0,0,0,0,0,0,0,0,0
0,0,0,0,0,0,0,0,0,0,0,0,0,0,0,0,0,0,0,0,0,0,0,0,0,0,0,0,0,0,0,0,0
0,0,0,0,0,0,0,0,0,0,0,0,0,0,0,0,0,0,0,0,0,0,0,0,0,0,0,0,0,0,0,0,0
0,0,0,0,0,0,0,0,0,0,0,0,0,0,0,0,0,0,0,0,0,0,0,0,0,0,0,0,0,0,0,0,0
0,0,0,0,0,0,0,0,0,0,0,0,0,0,0,0,0,0,0,0,0,0,0,0,0,0,0,0,0,0,0,0,0
0,0,0,0,0,0,0,0,0,0,0,0,0,0,0,0,0,0,0,0,0,0,0,0,0,0,0,0,0,0,0,0,0
0,0,0,0,0,0,0,0,0,0,0,0,0,0,0,0,0,0,0,0,0,0,0,0,0,0,0,0,0,0,0,0,0
endlayer

layer
0,0,0,0,0,0,0,0,0,0,0,0,0,0,0,0,0,0,0,0,0,0,0,0,0,0,0,0,0,0,0,0,0
0,0,0,0,0,0,0,0,0,0,0,0,0,0,0,0,0,0,0,0,0,0,0,0,0,0,0,0,0,0,0,0,0
0,0,0,0,0,0,0,0,0,0,0,0,0,0,0,0,0,0,0,0,0,0,0,0,0,0,0,0,0,0,0,0,0
0,0,0,0,0,0,0,0,0,0,0,0,0,0,0,0,0,0,0,0,0,0,0,0,0,0,0,0,0,0,0,0,0
0,0,0,0,0,0,0,0,0,0,0,0,0,0,0,0,0,0,0,0,0,0,0,0,0,0,0,0,0,0,0,0,0
0,0,0,0,0,0,0,0,0,0,0,0,0,0,0,0,0,0,0,0,0,0,0,0,0,0,0,0,0,0,0,0,0
0,0,0,0,0,0,0,0,0,0,0,0,0,0,0,0,0,0,0,0,0,0,0,0,0,0,0,0,0,0,0,0,0
0,0,0,0,0,0,0,0,0,0,0,0,0,0,0,0,0,0,0,0,0,0,0,0,0,0,0,0,0,0,0,0,0
0,0,0,0,0,0,0,0,0,0,0,0,0,0,0,0,0,0,0,0,0,0,0,0,0,0,0,0,0,0,0,0,0
0,0,0,0,0,0,0,0,0,0,0,0,0,0,0,3,3,3,0,0,0,0,0,0,0,0,0,0,0,0,0,0,0
0,0,0,0,0,0,0,0,0,0,0,0,0,3,3,0,0,0,3,3,0,0,0,0,0,0,0,0,0,0,0,0,0
0,0,0,0,0,0,0,0,0,0,0,0,3,0,0,0,0,0,0,0,3,0,0,0,0,0,0,0,0,0,0,0,0
0,0,0,0,0,0,0,0,0,0,0,3,0,0,0,0,0,0,0,0,0,3,0,0,0,0,0,0,0,0,0,0,0
0,0,0,0,0,0,0,0,0,0,3,0,0,0,0,0,0,0,0,9,0,0,3,0,0,0,0,0,0,0,0,0,0
0,0,0,0,0,0,0,0,0,0,3,0,0,0,0,0,0,0,0,0,20,0,3,0,0,0,0,0,0,0,0,0,0
0,0,0,0,0,0,0,0,0,3,0,0,0,0,0,0,0,0,0,0,14,14,14,3,0,0,0,0,0,0,0,0,0
0,0,0,0,0,0,0,0,0,3,0,0,0,0,0,0,0,0,0,0,13,13,13,3,0,0,0,0,0,0,0,0,0
0,0,0,0,0,0,0,0,0,3,0,0,0,0,0,0,0,0,0,0,0,0,0,3,0,0,0,0,0,0,0,0,0
0,0,0,0,0,0,0,0,0,0,3,0,0,0,0,0,0,0,0,0,0,0,3,0,0,0,0,0,0,0,0,0,0
0,0,0,0,0,0,0,0,0,0,3,0,0,0,0,0,0,0,0,0,0,0,3,0,0,0,0,0,0,0,0,0,0
0,0,0,0,0,0,0,0,0,0,0,3,0,0,0,0,0,0,0,0,0,3,0,0,0,0,0,0,0,0,0,0,0
0,0,0,0,0,0,0,0,0,0,0,0,3,0,0,0,0,0,0,0,3,0,0,0,0,0,0,0,0,0,0,0,0
0,0,0,0,0,0,0,0,0,0,0,0,0,3,3,0,0,0,3,3,0,0,0,0,0,0,0,0,0,0,0,0,0
0,0,0,0,0,0,0,0,0,0,0,0,0,0,0,3,3,3,0,0,0,0,0,0,0,0,0,0,0,0,0,0,0
0,0,0,0,0,0,0,0,0,0,0,0,0,0,0,0,0,0,0,0,0,0,0,0,0,0,0,0,0,0,0,0,0
0,0,0,0,0,0,0,0,0,0,0,0,0,0,0,0,0,0,0,0,0,0,0,0,0,0,0,0,0,0,0,0,0
0,0,0,0,0,0,0,0,0,0,0,0,0,0,0,0,0,0,0,0,0,0,0,0,0,0,0,0,0,0,0,0,0
0,0,0,0,0,0,0,0,0,0,0,0,0,0,0,0,0,0,0,0,0,0,0,0,0,0,0,0,0,0,0,0,0
0,0,0,0,0,0,0,0,0,0,0,0,0,0,0,0,0,0,0,0,0,0,0,0,0,0,0,0,0,0,0,0,0
0,0,0,0,0,0,0,0,0,0,0,0,0,0,0,0,0,0,0,0,0,0,0,0,0,0,0,0,0,0,0,0,0
0,0,0,0,0,0,0,0,0,0,0,0,0,0,0,0,0,0,0,0,0,0,0,0,0,0,0,0,0,0,0,0,0
0,0,0,0,0,0,0,0,0,0,0,0,0,0,0,0,0,0,0,0,0,0,0,0,0,0,0,0,0,0,0,0,0
0,0,0,0,0,0,0,0,0,0,0,0,0,0,0,0,0,0,0,0,0,0,0,0,0,0,0,0,0,0,0,0,0
endlayer

layer
0,0,0,0,0,0,0,0,0,0,0,0,0,0,0,0,0,0,0,0,0,0,0,0,0,0,0,0,0,0,0,0,0
0,0,0,0,0,0,0,0,0,0,0,0,0,0,0,0,0,0,0,0,0,0,0,0,0,0,0,0,0,0,0,0,0
0,0,0,0,0,0,0,0,0,0,0,0,0,0,0,0,0,0,0,0,0,0,0,0,0,0,0,0,0,0,0,0,0
0,0,0,0,0,0,0,0,0,0,0,0,0,0,0,0,0,0,0,0,0,0,0,0,0,0,0,0,0,0,0,0,0
0,0,0,0,0,0,0,0,0,0,0,0,0,0,0,0,0,0,0,0,0,0,0,0,0,0,0,0,0,0,0,0,0
0,0,0,0,0,0,0,0,0,0,0,0,0,0,0,0,0,0,0,0,0,0,0,0,0,0,0,0,0,0,0,0,0
0,0,0,0,0,0,0,0,0,0,0,0,0,0,0,0,0,0,0,0,0,0,0,0,0,0,0,0,0,0,0,0,0
0,0,0,0,0,0,0,0,0,0,0,0,0,0,0,0,0,0,0,0,0,0,0,0,0,0,0,0,0,0,0,0,0
0,0,0,0,0,0,0,0,0,0,0,0,0,0,0,0,0,0,0,0,0,0,0,0,0,0,0,0,0,0,0,0,0
0,0,0,0,0,0,0,0,0,0,0,0,0,0,0,0,3,0,0,0,0,0,0,0,0,0,0,0,0,0,0,0,0
0,0,0,0,0,0,0,0,0,0,0,0,0,0,3,3,0,3,3,0,0,0,0,0,0,0,0,0,0,0,0,0,0
0,0,0,0,0,0,0,0,0,0,0,0,3,3,0,0,0,0,0,3,3,0,0,0,0,0,0,0,0,0,0,0,0
0,0,0,0,0,0,0,0,0,0,0,3,3,0,0,0,0,0,0,0,3,3,0,0,0,0,0,0,0,0,0,0,0
0,0,0,0,0,0,0,0,0,0,0,3,0,0,0,0,0,0,0,0,0,3,0,0,0,0,0,0,0,0,0,0,0
0,0,0,0,0,0,0,0,0,0,3,0,0,0,0,0,0,0,0,0,0,0,3,0,0,0,0,0,0,0,0,0,0
0,0,0,0,0,0,0,0,0,0,3,0,0,0,0,0,9,9,0,0,20,20,3,0,0,0,0,0,0,0,0,0,0
0,0,0,0,0,0,0,0,0,3,0,0,0,0,0,0,0,0,0,0,9,0,0,3,0,0,0,0,0,0,0,0,0
0,0,0,0,0,0,0,0,0,0,3,0,0,0,0,0,0,9,9,14,14,14,3,0,0,0,0,0,0,0,0,0,0
0,0,0,0,0,0,0,0,0,0,3,0,0,0,0,0,0,0,0,13,13,13,3,0,0,0,0,0,0,0,0,0,0
0,0,0,0,0,0,0,0,0,0,0,3,0,0,0,0,0,0,0,0,0,3,0,0,0,0,0,0,0,0,0,0,0
0,0,0,0,0,0,0,0,0,0,0,3,3,0,0,0,0,0,0,0,3,3,0,0,0,0,0,0,0,0,0,0,0
0,0,0,0,0,0,0,0,0,0,0,0,3,3,0,0,0,0,0,3,3,0,0,0,0,0,0,0,0,0,0,0,0
0,0,0,0,0,0,0,0,0,0,0,0,0,0,3,3,0,3,3,0,0,0,0,0,0,0,0,0,0,0,0,0,0
0,0,0,0,0,0,0,0,0,0,0,0,0,0,0,0,3,0,0,0,0,0,0,0,0,0,0,0,0,0,0,0,0
0,0,0,0,0,0,0,0,0,0,0,0,0,0,0,0,0,0,0,0,0,0,0,0,0,0,0,0,0,0,0,0,0
0,0,0,0,0,0,0,0,0,0,0,0,0,0,0,0,0,0,0,0,0,0,0,0,0,0,0,0,0,0,0,0,0
0,0,0,0,0,0,0,0,0,0,0,0,0,0,0,0,0,0,0,0,0,0,0,0,0,0,0,0,0,0,0,0,0
0,0,0,0,0,0,0,0,0,0,0,0,0,0,0,0,0,0,0,0,0,0,0,0,0,0,0,0,0,0,0,0,0
0,0,0,0,0,0,0,0,0,0,0,0,0,0,0,0,0,0,0,0,0,0,0,0,0,0,0,0,0,0,0,0,0
0,0,0,0,0,0,0,0,0,0,0,0,0,0,0,0,0,0,0,0,0,0,0,0,0,0,0,0,0,0,0,0,0
0,0,0,0,0,0,0,0,0,0,0,0,0,0,0,0,0,0,0,0,0,0,0,0,0,0,0,0,0,0,0,0,0
0,0,0,0,0,0,0,0,0,0,0,0,0,0,0,0,0,0,0,0,0,0,0,0,0,0,0,0,0,0,0,0,0
0,0,0,0,0,0,0,0,0,0,0,0,0,0,0,0,0,0,0,0,0,0,0,0,0,0,0,0,0,0,0,0,0
endlayer

layer
0,0,0,0,0,0,0,0,0,0,0,0,0,0,0,0,0,0,0,0,0,0,0,0,0,0,0,0,0,0,0,0,0
0,0,0,0,0,0,0,0,0,0,0,0,0,0,0,0,0,0,0,0,0,0,0,0,0,0,0,0,0,0,0,0,0
0,0,0,0,0,0,0,0,0,0,0,0,0,0,0,0,0,0,0,0,0,0,0,0,0,0,0,0,0,0,0,0,0
0,0,0,0,0,0,0,0,0,0,0,0,0,0,0,0,0,0,0,0,0,0,0,0,0,0,0,0,0,0,0,0,0
0,0,0,0,0,0,0,0,0,0,0,0,0,0,0,0,0,0,0,0,0,0,0,0,0,0,0,0,0,0,0,0,0
0,0,0,0,0,0,0,0,0,0,0,0,0,0,0,0,0,0,0,0,0,0,0,0,0,0,0,0,0,0,0,0,0
0,0,0,0,0,0,0,0,0,0,0,0,0,0,0,0,0,0,0,0,0,0,0,0,0,0,0,0,0,0,0,0,0
0,0,0,0,0,0,0,0,0,0,0,0,0,0,0,0,0,0,0,0,0,0,0,0,0,0,0,0,0,0,0,0,0
0,0,0,0,0,0,0,0,0,0,0,0,0,0,0,0,0,0,0,0,0,0,0,0,0,0,0,0,0,0,0,0,0
0,0,0,0,0,0,0,0,0,0,0,0,0,0,0,0,3,0,0,0,0,0,0,0,0,0,0,0,0,0,0,0,0
0,0,0,0,0,0,0,0,0,0,0,0,0,0,3,3,0,3,3,0,0,0,0,0,0,0,0,0,0,0,0,0,0
0,0,0,0,0,0,0,0,0,0,0,0,3,3,0,0,0,0,0,3,3,0,0,0,0,0,0,0,0,0,0,0,0
0,0,0,0,0,0,0,0,0,0,0,3,3,0,0,0,0,0,0,0,3,3,0,0,0,0,0,0,0,0,0,0,0
0,0,0,0,0,0,0,0,0,0,0,3,0,0,0,0,0,0,0,0,0,3,0,0,0,0,0,0,0,0,0,0,0
0,0,0,0,0,0,0,0,0,0,3,0,0,0,0,0,0,0,0,0,0,0,3,0,0,0,0,0,0,0,0,0,0
0,0,0,0,0,0,0,0,0,0,3,0,0,0,0,0,0,0,0,0,0,0,32,0,0,0,0,0,0,0,0,0,0
0,0,0,0,0,0,0,0,0,3,0,0,0,0,0,0,0,0,0,0,0,0,0,3,0,0,0,0,0,0,0,0,0
0,0,0,0,0,0,0,0,0,0,3,0,0,0,0,9,0,0,0,0,20,0,21,0,0,0,0,0,0,0,0,0,0
0,0,0,0,0,0,0,0,0,0,3,0,0,0,0,0,0,0,20,0,0,0,32,0,0,0,0,0,0,0,0,0,0
0,0,0,0,0,0,0,0,0,0,0,3,0,0,0,0,0,0,13,14,14,3,0,0,0,0,0,0,0,0,0,0,0
0,0,0,0,0,0,0,0,0,0,0,3,3,0,0,0,0,0,13,14,3,3,0,0,0,0,0,0,0,0,0,0,0
0,0,0,0,0,0,0,0,0,0,0,0,32,3,0,0,0,0,13,3,3,0,0,0,0,0,0,0,0,0,0,0,0
0,0,0,0,0,0,0,0,0,0,0,0,0,0,3,3,0,3,3,0,0,0,0,0,0,0,0,0,0,0,0,0,0
0,0,0,0,0,0,0,0,0,0,0,0,0,0,0,0,3,0,0,0,0,0,0,0,0,0,0,0,0,0,0,0,0
0,0,0,0,0,0,0,0,0,0,0,0,0,0,0,0,0,0,0,0,0,0,0,0,0,0,0,0,0,0,0,0,0
0,0,0,0,0,0,0,0,0,0,0,0,0,0,0,0,0,0,0,0,0,0,0,0,0,0,0,0,0,0,0,0,0
0,0,0,0,0,0,0,0,0,0,0,0,0,0,0,0,0,0,0,0,0,0,0,0,0,0,0,0,0,0,0,0,0
0,0,0,0,0,0,0,0,0,0,0,0,0,0,0,0,0,0,0,0,0,0,0,0,0,0,0,0,0,0,0,0,0
0,0,0,0,0,0,0,0,0,0,0,0,0,0,0,0,0,0,0,0,0,0,0,0,0,0,0,0,0,0,0,0,0
0,0,0,0,0,0,0,0,0,0,0,0,0,0,0,0,0,0,0,0,0,0,0,0,0,0,0,0,0,0,0,0,0
0,0,0,0,0,0,0,0,0,0,0,0,0,0,0,0,0,0,0,0,0,0,0,0,0,0,0,0,0,0,0,0,0
0,0,0,0,0,0,0,0,0,0,0,0,0,0,0,0,0,0,0,0,0,0,0,0,0,0,0,0,0,0,0,0,0
0,0,0,0,0,0,0,0,0,0,0,0,0,0,0,0,0,0,0,0,0,0,0,0,0,0,0,0,0,0,0,0,0
endlayer

layer
0,0,0,0,0,0,0,0,0,0,0,0,0,0,0,0,0,0,0,0,0,0,0,0,0,0,0,0,0,0,0,0,0
0,0,0,0,0,0,0,0,0,0,0,0,0,0,0,0,0,0,0,0,0,0,0,0,0,0,0,0,0,0,0,0,0
0,0,0,0,0,0,0,0,0,0,0,0,0,0,0,0,0,0,0,0,0,0,0,0,0,0,0,0,0,0,0,0,0
0,0,0,0,0,0,0,0,0,0,0,0,0,0,0,0,0,0,0,0,0,0,0,0,0,0,0,0,0,0,0,0,0
0,0,0,0,0,0,0,0,0,0,0,0,0,0,0,0,0,0,0,0,0,0,0,0,0,0,0,0,0,0,0,0,0
0,0,0,0,0,0,0,0,0,0,0,0,0,0,0,0,0,0,0,0,0,0,0,0,0,0,0,0,0,0,0,0,0
0,0,0,0,0,0,0,0,0,0,0,0,0,0,0,0,0,0,0,0,0,0,0,0,0,0,0,0,0,0,0,0,0
0,0,0,0,0,0,0,0,0,0,0,0,0,0,0,0,0,0,0,0,0,0,0,0,0,0,0,0,0,0,0,0,0
0,0,0,0,0,0,0,0,0,0,0,0,0,0,0,0,0,0,0,0,0,0,0,0,0,0,0,0,0,0,0,0,0
0,0,0,0,0,0,0,0,0,0,0,0,0,0,0,0,3,0,0,0,0,0,0,0,0,0,0,0,0,0,0,0,0
0,0,0,0,0,0,0,0,0,0,0,0,0,0,3,3,0,3,3,0,0,0,0,0,0,0,0,0,0,0,0,0,0
0,0,0,0,0,0,0,0,0,0,0,0,3,3,0,0,0,0,0,3,3,0,0,0,0,0,0,0,0,0,0,0,0
0,0,0,0,0,0,0,0,0,0,0,3,3,0,0,0,0,0,0,0,3,3,0,0,0,0,0,0,0,0,0,0,0
0,0,0,0,0,0,0,0,0,0,0,3,0,0,0,0,0,0,0,0,0,3,0,0,0,0,0,0,0,0,0,0,0
0,0,0,0,0,0,0,0,0,0,3,0,0,0,0,0,0,0,0,0,0,0,3,0,0,0,0,0,0,0,0,0,0
0,0,0,0,0,0,0,0,0,0,3,0,0,0,0,0,0,0,0,0,0,0,3,0,0,0,0,0,0,0,0,0,0
0,0,0,0,0,0,0,0,0,3,0,0,0,0,0,0,0,0,0,0,0,0,0,3,0,0,0,0,0,0,0,0,0
0,0,0,0,0,0,0,0,0,0,3,0,0,0,0,0,0,0,0,0,0,0,3,0,0,0,0,0,0,0,0,0,0
0,0,0,0,0,0,0,0,0,0,3,0,0,0,0,0,0,9,0,9,0,0,3,0,0,0,0,0,0,0,0,0,0
0,0,0,0,0,0,0,0,0,0,0,3,0,0,0,0,13,14,0,0,0,3,0,0,0,0,0,0,0,0,0,0,0
0,0,0,0,0,0,0,0,0,0,0,3,3,0,0,0,13,14,0,20,21,3,0,0,0,0,0,0,0,0,0,0,0
0,0,0,0,0,0,0,0,0,0,0,0,3,3,0,0,13,14,20,3,3,0,0,0,0,0,0,0,0,0,0,0,0
0,0,0,0,0,0,0,0,0,0,0,0,0,0,3,3,13,3,3,0,0,0,0,0,0,0,0,0,0,0,0,0,0
0,0,0,0,0,0,0,0,0,0,0,0,0,0,0,0,32,0,0,0,0,0,0,0,0,0,0,0,0,0,0,0,0
0,0,0,0,0,0,0,0,0,0,0,0,0,0,0,0,0,0,0,0,0,0,0,0,0,0,0,0,0,0,0,0,0
0,0,0,0,0,0,0,0,0,0,0,0,0,0,0,0,0,0,0,0,0,0,0,0,0,0,0,0,0,0,0,0,0
0,0,0,0,0,0,0,0,0,0,0,0,0,0,0,0,0,0,0,0,0,0,0,0,0,0,0,0,0,0,0,0,0
0,0,0,0,0,0,0,0,0,0,0,0,0,0,0,0,0,0,0,0,0,0,0,0,0,0,0,0,0,0,0,0,0
0,0,0,0,0,0,0,0,0,0,0,0,0,0,0,0,0,0,0,0,0,0,0,0,0,0,0,0,0,0,0,0,0
0,0,0,0,0,0,0,0,0,0,0,0,0,0,0,0,0,0,0,0,0,0,0,0,0,0,0,0,0,0,0,0,0
0,0,0,0,0,0,0,0,0,0,0,0,0,0,0,0,0,0,0,0,0,0,0,0,0,0,0,0,0,0,0,0,0
0,0,0,0,0,0,0,0,0,0,0,0,0,0,0,0,0,0,0,0,0,0,0,0,0,0,0,0,0,0,0,0,0
0,0,0,0,0,0,0,0,0,0,0,0,0,0,0,0,0,0,0,0,0,0,0,0,0,0,0,0,0,0,0,0,0
endlayer

layer
0,0,0,0,0,0,0,0,0,0,0,0,0,0,0,0,0,0,0,0,0,0,0,0,0,0,0,0,0,0,0,0,0
0,0,0,0,0,0,0,0,0,0,0,0,0,0,0,0,0,0,0,0,0,0,0,0,0,0,0,0,0,0,0,0,0
0,0,0,0,0,0,0,0,0,0,0,0,0,0,0,0,0,0,0,0,0,0,0,0,0,0,0,0,0,0,0,0,0
0,0,0,0,0,0,0,0,0,0,0,0,0,0,0,0,0,0,0,0,0,0,0,0,0,0,0,0,0,0,0,0,0
0,0,0,0,0,0,0,0,0,0,0,0,0,0,0,0,0,0,0,0,0,0,0,0,0,0,0,0,0,0,0,0,0
0,0,0,0,0,0,0,0,0,0,0,0,0,0,0,0,0,0,0,0,0,0,0,0,0,0,0,0,0,0,0,0,0
0,0,0,0,0,0,0,0,0,0,0,0,0,0,0,0,0,0,0,0,0,0,0,0,0,0,0,0,0,0,0,0,0
0,0,0,0,0,0,0,0,0,0,0,0,0,0,0,0,0,0,0,0,0,0,0,0,0,0,0,0,0,0,0,0,0
0,0,0,0,0,0,0,0,0,0,0,0,0,0,0,0,0,0,0,0,0,0,0,0,0,0,0,0,0,0,0,0,0
0,0,0,0,0,0,0,0,0,0,0,0,0,0,0,0,3,0,0,0,0,0,0,0,0,0,0,0,0,0,0,0,0
0,0,0,0,0,0,0,0,0,0,0,0,0,0,3,3,0,3,3,0,0,0,0,0,0,0,0,0,0,0,0,0,0
0,0,0,0,0,0,0,0,0,0,0,0,3,3,0,0,0,0,0,3,3,0,0,0,0,0,0,0,0,0,0,0,0
0,0,0,0,0,0,0,0,0,0,0,3,3,0,0,0,0,0,0,0,3,3,0,0,0,0,0,0,0,0,0,0,0
0,0,0,0,0,0,0,0,0,0,0,3,0,0,0,0,0,0,0,0,0,3,0,0,0,0,0,0,0,0,0,0,0
0,0,0,0,0,0,0,0,0,0,3,0,0,0,0,0,0,0,0,0,0,0,3,0,0,0,0,0,0,0,0,0,0
0,0,0,0,0,0,0,0,0,0,3,0,0,0,0,0,0,0,0,0,0,0,3,0,0,0,0,0,0,0,0,0,0
0,0,0,0,0,0,0,0,0,3,0,0,0,0,0,0,0,0,0,0,0,0,0,3,0,0,0,0,0,0,0,0,0
0,0,0,0,0,0,0,0,0,0,3,0,0,0,0,0,0,0,0,0,0,0,3,0,0,0,0,0,0,0,0,0,0
0,0,0,0,0,0,0,0,0,0,3,0,0,0,0,0,0,0,0,0,0,0,3,0,0,0,0,0,0,0,0,0,0
0,0,0,0,0,0,0,0,0,0,0,3,0,0,13,14,0,9,0,0,0,3,0,0,0,0,0,0,0,0,0,0,0
0,0,0,0,0,0,0,0,0,0,0,3,3,0,13,14,9,20,0,0,3,3,0,0,0,0,0,0,0,0,0,0,0
0,0,0,0,0,0,0,0,0,0,0,0,3,3,13,14,0,0,0,3,3,0,0,0,0,0,0,0,0,0,0,0,0
0,0,0,0,0,0,0,0,0,0,0,0,0,0,3,3,10,3,3,0,0,0,0,0,0,0,0,0,0,0,0,0,0
0,0,0,0,0,0,0,0,0,0,0,0,0,0,0,0,3,0,0,0,0,0,0,0,0,0,0,0,0,0,0,0,0
0,0,0,0,0,0,0,0,0,0,0,0,0,0,0,0,0,0,0,0,0,0,0,0,0,0,0,0,0,0,0,0,0
0,0,0,0,0,0,0,0,0,0,0,0,0,0,0,0,0,0,0,0,0,0,0,0,0,0,0,0,0,0,0,0,0
0,0,0,0,0,0,0,0,0,0,0,0,0,0,0,0,0,0,0,0,0,0,0,0,0,0,0,0,0,0,0,0,0
0,0,0,0,0,0,0,0,0,0,0,0,0,0,0,0,0,0,0,0,0,0,0,0,0,0,0,0,0,0,0,0,0
0,0,0,0,0,0,0,0,0,0,0,0,0,0,0,0,0,0,0,0,0,0,0,0,0,0,0,0,0,0,0,0,0
0,0,0,0,0,0,0,0,0,0,0,0,0,0,0,0,0,0,0,0,0,0,0,0,0,0,0,0,0,0,0,0,0
0,0,0,0,0,0,0,0,0,0,0,0,0,0,0,0,0,0,0,0,0,0,0,0,0,0,0,0,0,0,0,0,0
0,0,0,0,0,0,0,0,0,0,0,0,0,0,0,0,0,0,0,0,0,0,0,0,0,0,0,0,0,0,0,0,0
0,0,0,0,0,0,0,0,0,0,0,0,0,0,0,0,0,0,0,0,0,0,0,0,0,0,0,0,0,0,0,0,0
endlayer

layer
0,0,0,0,0,0,0,0,0,0,0,0,0,0,0,0,0,0,0,0,0,0,0,0,0,0,0,0,0,0,0,0,0
0,0,0,0,0,0,0,0,0,0,0,0,0,0,0,0,0,0,0,0,0,0,0,0,0,0,0,0,0,0,0,0,0
0,0,0,0,0,0,0,0,0,0,0,0,0,0,0,0,0,0,0,0,0,0,0,0,0,0,0,0,0,0,0,0,0
0,0,0,0,0,0,0,0,0,0,0,0,0,0,0,0,0,0,0,0,0,0,0,0,0,0,0,0,0,0,0,0,0
0,0,0,0,0,0,0,0,0,0,0,0,0,0,0,0,0,0,0,0,0,0,0,0,0,0,0,0,0,0,0,0,0
0,0,0,0,0,0,0,0,0,0,0,0,0,0,0,0,0,0,0,0,0,0,0,0,0,0,0,0,0,0,0,0,0
0,0,0,0,0,0,0,0,0,0,0,0,0,0,0,0,0,0,0,0,0,0,0,0,0,0,0,0,0,0,0,0,0
0,0,0,0,0,0,0,0,0,0,0,0,0,0,0,0,0,0,0,0,0,0,0,0,0,0,0,0,0,0,0,0,0
0,0,0,0,0,0,0,0,0,0,0,0,0,0,0,0,0,0,0,0,0,0,0,0,0,0,0,0,0,0,0,0,0
0,0,0,0,0,0,0,0,0,0,0,0,0,0,0,0,0,0,0,0,0,0,0,0,0,0,0,0,0,0,0,0,0
0,0,0,0,0,0,0,0,0,0,0,0,0,0,0,3,3,3,0,0,0,0,0,0,0,0,0,0,0,0,0,0,0
0,0,0,0,0,0,0,0,0,0,0,0,0,3,3,0,0,0,3,3,0,0,0,0,0,0,0,0,0,0,0,0,0
0,0,0,0,0,0,0,0,0,0,0,0,3,0,0,0,0,0,0,0,3,0,0,0,0,0,0,0,0,0,0,0,0
0,0,0,0,0,0,0,0,0,0,0,3,0,0,0,0,0,0,0,0,0,3,0,0,0,0,0,0,0,0,0,0,0
0,0,0,0,0,0,0,0,0,0,0,3,0,0,0,0,0,0,0,0,0,3,0,0,0,0,0,0,0,0,0,0,0
0,0,0,0,0,0,0,0,0,0,3,0,0,0,0,0,0,0,0,0,0,0,3,0,0,0,0,0,0,0,0,0,0
0,0,0,0,0,0,0,0,0,0,3,0,0,0,0,0,0,0,0,0,0,0,3,0,0,0,0,0,0,0,0,0,0
0,0,0,0,0,0,0,0,0,0,3,13,13,13,0,0,0,0,0,0,0,0,3,0,0,0,0,0,0,0,0,0,0
0,0,0,0,0,0,0,0,0,0,0,3,14,14,0,0,0,0,0,0,0,3,0,0,0,0,0,0,0,0,0,0,0
0,0,0,0,0,0,0,0,0,0,0,3,14,14,9,9,0,0,0,0,0,3,0,0,0,0,0,0,0,0,0,0,0
0,0,0,0,0,0,0,0,0,0,0,0,3,14,0,0,0,0,0,0,3,0,0,0,0,0,0,0,0,0,0,0,0
0,0,0,0,0,0,0,0,0,0,0,0,0,3,3,0,0,0,3,3,0,0,0,0,0,0,0,0,0,0,0,0,0
0,0,0,0,0,0,0,0,0,0,0,0,0,0,0,3,3,3,0,0,0,0,0,0,0,0,0,0,0,0,0,0,0
0,0,0,0,0,0,0,0,0,0,0,0,0,0,0,0,0,0,0,0,0,0,0,0,0,0,0,0,0,0,0,0,0
0,0,0,0,0,0,0,0,0,0,0,0,0,0,0,0,0,0,0,0,0,0,0,0,0,0,0,0,0,0,0,0,0
0,0,0,0,0,0,0,0,0,0,0,0,0,0,0,0,0,0,0,0,0,0,0,0,0,0,0,0,0,0,0,0,0
0,0,0,0,0,0,0,0,0,0,0,0,0,0,0,0,0,0,0,0,0,0,0,0,0,0,0,0,0,0,0,0,0
0,0,0,0,0,0,0,0,0,0,0,0,0,0,0,0,0,0,0,0,0,0,0,0,0,0,0,0,0,0,0,0,0
0,0,0,0,0,0,0,0,0,0,0,0,0,0,0,0,0,0,0,0,0,0,0,0,0,0,0,0,0,0,0,0,0
0,0,0,0,0,0,0,0,0,0,0,0,0,0,0,0,0,0,0,0,0,0,0,0,0,0,0,0,0,0,0,0,0
0,0,0,0,0,0,0,0,0,0,0,0,0,0,0,0,0,0,0,0,0,0,0,0,0,0,0,0,0,0,0,0,0
0,0,0,0,0,0,0,0,0,0,0,0,0,0,0,0,0,0,0,0,0,0,0,0,0,0,0,0,0,0,0,0,0
0,0,0,0,0,0,0,0,0,0,0,0,0,0,0,0,0,0,0,0,0,0,0,0,0,0,0,0,0,0,0,0,0
endlayer

layer
0,0,0,0,0,0,0,0,0,0,0,0,0,0,0,0,0,0,0,0,0,0,0,0,0,0,0,0,0,0,0,0,0
0,0,0,0,0,0,0,0,0,0,0,0,0,0,0,0,0,0,0,0,0,0,0,0,0,0,0,0,0,0,0,0,0
0,0,0,0,0,0,0,0,0,0,0,0,0,0,0,0,0,0,0,0,0,0,0,0,0,0,0,0,0,0,0,0,0
0,0,0,0,0,0,0,0,0,0,0,0,0,0,0,0,0,0,0,0,0,0,0,0,0,0,0,0,0,0,0,0,0
0,0,0,0,0,0,0,0,0,0,0,0,0,0,0,0,0,0,0,0,0,0,0,0,0,0,0,0,0,0,0,0,0
0,0,0,0,0,0,0,0,0,0,0,0,0,0,0,0,0,0,0,0,0,0,0,0,0,0,0,0,0,0,0,0,0
0,0,0,0,0,0,0,0,0,0,0,0,0,0,0,0,0,0,0,0,0,0,0,0,0,0,0,0,0,0,0,0,0
0,0,0,0,0,0,0,0,0,0,0,0,0,0,0,0,0,0,0,0,0,0,0,0,0,0,0,0,0,0,0,0,0
0,0,0,0,0,0,0,0,0,0,0,0,0,0,0,0,0,0,0,0,0,0,0,0,0,0,0,0,0,0,0,0,0
0,0,0,0,0,0,0,0,0,0,0,0,0,0,0,0,0,0,0,0,0,0,0,0,0,0,0,0,0,0,0,0,0
0,0,0,0,0,0,0,0,0,0,0,0,0,0,0,3,3,3,0,0,0,0,0,0,0,0,0,0,0,0,0,0,0
0,0,0,0,0,0,0,0,0,0,0,0,0,3,3,0,0,0,3,3,0,0,0,0,0,0,0,0,0,0,0,0,0
0,0,0,0,0,0,0,0,0,0,0,0,3,0,0,0,0,0,0,0,3,0,0,0,0,0,0,0,0,0,0,0,0
0,0,0,0,0,0,0,0,0,0,0,3,0,0,0,0,0,0,0,0,0,3,0,0,0,0,0,0,0,0,0,0,0
0,0,0,0,0,0,0,0,0,0,0,3,0,0,0,0,0,0,0,0,0,3,0,0,0,0,0,0,0,0,0,0,0
0,0,0,0,0,0,0,0,0,0,3,13,13,13,0,0,0,0,0,0,0,0,32,0,0,0,0,0,0,0,0,0,0
0,0,0,0,0,0,0,0,0,0,3,14,14,14,0,0,0,0,0,0,0,0,32,0,0,0,0,0,0,0,0,0,0
0,0,0,0,0,0,0,0,0,0,3,0,0,0,0,0,0,0,0,0,0,0,3,0,0,0,0,0,0,0,0,0,0
0,0,0,0,0,0,0,0,0,0,0,3,20,0,0,0,0,0,0,0,0,3,0,0,0,0,0,0,0,0,0,0,0
0,0,0,0,0,0,0,0,0,0,0,3,0,0,0,0,0,0,0,0,0,3,0,0,0,0,0,0,0,0,0,0,0
0,0,0,0,0,0,0,0,0,0,0,0,3,20,0,0,0,0,0,0,3,0,0,0,0,0,0,0,0,0,0,0,0
0,0,0,0,0,0,0,0,0,0,0,0,0,3,3,0,0,0,3,3,0,0,0,0,0,0,0,0,0,0,0,0,0
0,0,0,0,0,0,0,0,0,0,0,0,0,0,0,3,3,3,0,0,0,0,0,0,0,0,0,0,0,0,0,0,0
0,0,0,0,0,0,0,0,0,0,0,0,0,0,0,0,0,0,0,0,0,0,0,0,0,0,0,0,0,0,0,0,0
0,0,0,0,0,0,0,0,0,0,0,0,0,0,0,0,0,0,0,0,0,0,0,0,0,0,0,0,0,0,0,0,0
0,0,0,0,0,0,0,0,0,0,0,0,0,0,0,0,0,0,0,0,0,0,0,0,0,0,0,0,0,0,0,0,0
0,0,0,0,0,0,0,0,0,0,0,0,0,0,0,0,0,0,0,0,0,0,0,0,0,0,0,0,0,0,0,0,0
0,0,0,0,0,0,0,0,0,0,0,0,0,0,0,0,0,0,0,0,0,0,0,0,0,0,0,0,0,0,0,0,0
0,0,0,0,0,0,0,0,0,0,0,0,0,0,0,0,0,0,0,0,0,0,0,0,0,0,0,0,0,0,0,0,0
0,0,0,0,0,0,0,0,0,0,0,0,0,0,0,0,0,0,0,0,0,0,0,0,0,0,0,0,0,0,0,0,0
0,0,0,0,0,0,0,0,0,0,0,0,0,0,0,0,0,0,0,0,0,0,0,0,0,0,0,0,0,0,0,0,0
0,0,0,0,0,0,0,0,0,0,0,0,0,0,0,0,0,0,0,0,0,0,0,0,0,0,0,0,0,0,0,0,0
0,0,0,0,0,0,0,0,0,0,0,0,0,0,0,0,0,0,0,0,0,0,0,0,0,0,0,0,0,0,0,0,0
endlayer

layer
0,0,0,0,0,0,0,0,0,0,0,0,0,0,0,0,0,0,0,0,0,0,0,0,0,0,0,0,0,0,0,0,0
0,0,0,0,0,0,0,0,0,0,0,0,0,0,0,0,0,0,0,0,0,0,0,0,0,0,0,0,0,0,0,0,0
0,0,0,0,0,0,0,0,0,0,0,0,0,0,0,0,0,0,0,0,0,0,0,0,0,0,0,0,0,0,0,0,0
0,0,0,0,0,0,0,0,0,0,0,0,0,0,0,0,0,0,0,0,0,0,0,0,0,0,0,0,0,0,0,0,0
0,0,0,0,0,0,0,0,0,0,0,0,0,0,0,0,0,0,0,0,0,0,0,0,0,0,0,0,0,0,0,0,0
0,0,0,0,0,0,0,0,0,0,0,0,0,0,0,0,0,0,0,0,0,0,0,0,0,0,0,0,0,0,0,0,0
0,0,0,0,0,0,0,0,0,0,0,0,0,0,0,0,0,0,0,0,0,0,0,0,0,0,0,0,0,0,0,0,0
0,0,0,0,0,0,0,0,0,0,0,0,0,0,0,0,0,0,0,0,0,0,0,0,0,0,0,0,0,0,0,0,0
0,0,0,0,0,0,0,0,0,0,0,0,0,0,0,0,0,0,0,0,0,0,0,0,0,0,0,0,0,0,0,0,0
0,0,0,0,0,0,0,0,0,0,0,0,0,0,0,0,0,0,0,0,0,0,0,0,0,0,0,0,0,0,0,0,0
0,0,0,0,0,0,0,0,0,0,0,0,0,0,0,3,3,3,0,0,0,0,0,0,0,0,0,0,0,0,0,0,0
0,0,0,0,0,0,0,0,0,0,0,0,0,3,3,0,0,0,3,3,0,0,0,0,0,0,0,0,0,0,0,0,0
0,0,0,0,0,0,0,0,0,0,0,0,3,13,13,0,0,0,0,0,3,0,0,0,0,0,0,0,0,0,0,0,0
0,0,0,0,0,0,0,0,0,0,0,3,13,13,13,0,0,0,0,0,0,32,0,0,0,0,0,0,0,0,0,0,0
0,0,0,0,0,0,0,0,0,0,0,3,14,14,14,0,0,0,0,0,0,3,0,0,0,0,0,0,0,0,0,0,0
0,0,0,0,0,0,0,0,0,0,3,0,20,9,0,0,0,0,0,0,0,0,3,0,0,0,0,0,0,0,0,0,0
0,0,0,0,0,0,0,0,0,0,21,0,0,0,0,0,0,0,0,0,0,0,3,0,0,0,0,0,0,0,0,0,0
0,0,0,0,0,0,0,0,0,0,3,0,0,0,0,0,0,0,0,0,0,0,3,0,0,0,0,0,0,0,0,0,0
0,0,0,0,0,0,0,0,0,0,0,3,0,0,0,0,0,0,0,0,0,3,0,0,0,0,0,0,0,0,0,0,0
0,0,0,0,0,0,0,0,0,0,0,3,0,0,0,0,0,0,0,0,0,3,0,0,0,0,0,0,0,0,0,0,0
0,0,0,0,0,0,0,0,0,0,0,0,3,0,0,0,0,0,0,0,3,0,0,0,0,0,0,0,0,0,0,0,0
0,0,0,0,0,0,0,0,0,0,0,0,0,3,3,0,0,0,3,3,0,0,0,0,0,0,0,0,0,0,0,0,0
0,0,0,0,0,0,0,0,0,0,0,0,0,0,0,3,3,3,0,0,0,0,0,0,0,0,0,0,0,0,0,0,0
0,0,0,0,0,0,0,0,0,0,0,0,0,0,0,0,0,0,0,0,0,0,0,0,0,0,0,0,0,0,0,0,0
0,0,0,0,0,0,0,0,0,0,0,0,0,0,0,0,0,0,0,0,0,0,0,0,0,0,0,0,0,0,0,0,0
0,0,0,0,0,0,0,0,0,0,0,0,0,0,0,0,0,0,0,0,0,0,0,0,0,0,0,0,0,0,0,0,0
0,0,0,0,0,0,0,0,0,0,0,0,0,0,0,0,0,0,0,0,0,0,0,0,0,0,0,0,0,0,0,0,0
0,0,0,0,0,0,0,0,0,0,0,0,0,0,0,0,0,0,0,0,0,0,0,0,0,0,0,0,0,0,0,0,0
0,0,0,0,0,0,0,0,0,0,0,0,0,0,0,0,0,0,0,0,0,0,0,0,0,0,0,0,0,0,0,0,0
0,0,0,0,0,0,0,0,0,0,0,0,0,0,0,0,0,0,0,0,0,0,0,0,0,0,0,0,0,0,0,0,0
0,0,0,0,0,0,0,0,0,0,0,0,0,0,0,0,0,0,0,0,0,0,0,0,0,0,0,0,0,0,0,0,0
0,0,0,0,0,0,0,0,0,0,0,0,0,0,0,0,0,0,0,0,0,0,0,0,0,0,0,0,0,0,0,0,0
0,0,0,0,0,0,0,0,0,0,0,0,0,0,0,0,0,0,0,0,0,0,0,0,0,0,0,0,0,0,0,0,0
endlayer

layer
0,0,0,0,0,0,0,0,0,0,0,0,0,0,0,0,0,0,0,0,0,0,0,0,0,0,0,0,0,0,0,0,0
0,0,0,0,0,0,0,0,0,0,0,0,0,0,0,0,0,0,0,0,0,0,0,0,0,0,0,0,0,0,0,0,0
0,0,0,0,0,0,0,0,0,0,0,0,0,0,0,0,0,0,0,0,0,0,0,0,0,0,0,0,0,0,0,0,0
0,0,0,0,0,0,0,0,0,0,0,0,0,0,0,0,0,0,0,0,0,0,0,0,0,0,0,0,0,0,0,0,0
0,0,0,0,0,0,0,0,0,0,0,0,0,0,0,0,0,0,0,0,0,0,0,0,0,0,0,0,0,0,0,0,0
0,0,0,0,0,0,0,0,0,0,0,0,0,0,0,0,0,0,0,0,0,0,0,0,0,0,0,0,0,0,0,0,0
0,0,0,0,0,0,0,0,0,0,0,0,0,0,0,0,0,0,0,0,0,0,0,0,0,0,0,0,0,0,0,0,0
0,0,0,0,0,0,0,0,0,0,0,0,0,0,0,0,0,0,0,0,0,0,0,0,0,0,0,0,0,0,0,0,0
0,0,0,0,0,0,0,0,0,0,0,0,0,0,0,0,0,0,0,0,0,0,0,0,0,0,0,0,0,0,0,0,0
0,0,0,0,0,0,0,0,0,0,0,0,0,0,0,0,0,0,0,0,0,0,0,0,0,0,0,0,0,0,0,0,0
0,0,0,0,0,0,0,0,0,0,0,0,0,0,0,3,3,3,0,0,0,0,0,0,0,0,0,0,0,0,0,0,0
0,0,0,0,0,0,0,0,0,0,0,0,0,3,3,14,13,0,3,3,0,0,0,0,0,0,0,0,0,0,0,0,0
0,0,0,0,0,0,0,0,0,0,0,0,3,0,0,14,13,0,0,0,3,0,0,0,0,0,0,0,0,0,0,0,0
0,0,0,0,0,0,0,0,0,0,0,3,0,0,0,14,13,0,0,0,0,3,0,0,0,0,0,0,0,0,0,0,0
0,0,0,0,0,0,0,0,0,0,0,21,0,9,0,0,0,0,0,0,0,3,0,0,0,0,0,0,0,0,0,0,0
0,0,0,0,0,0,0,0,0,0,3,0,0,0,0,0,0,0,0,0,0,0,3,0,0,0,0,0,0,0,0,0,0
0,0,0,0,0,0,0,0,0,0,3,20,0,0,0,0,0,0,0,0,0,0,3,0,0,0,0,0,0,0,0,0,0
0,0,0,0,0,0,0,0,0,0,3,0,0,0,0,0,0,0,0,0,0,0,3,0,0,0,0,0,0,0,0,0,0
0,0,0,0,0,0,0,0,0,0,0,3,0,0,0,0,0,0,0,0,0,3,0,0,0,0,0,0,0,0,0,0,0
0,0,0,0,0,0,0,0,0,0,0,3,0,0,0,0,0,0,0,0,0,3,0,0,0,0,0,0,0,0,0,0,0
0,0,0,0,0,0,0,0,0,0,0,0,3,0,0,0,0,0,0,0,3,0,0,0,0,0,0,0,0,0,0,0,0
0,0,0,0,0,0,0,0,0,0,0,0,0,3,3,0,0,0,3,3,0,0,0,0,0,0,0,0,0,0,0,0,0
0,0,0,0,0,0,0,0,0,0,0,0,0,0,0,3,3,3,0,0,0,0,0,0,0,0,0,0,0,0,0,0,0
0,0,0,0,0,0,0,0,0,0,0,0,0,0,0,0,0,0,0,0,0,0,0,0,0,0,0,0,0,0,0,0,0
0,0,0,0,0,0,0,0,0,0,0,0,0,0,0,0,0,0,0,0,0,0,0,0,0,0,0,0,0,0,0,0,0
0,0,0,0,0,0,0,0,0,0,0,0,0,0,0,0,0,0,0,0,0,0,0,0,0,0,0,0,0,0,0,0,0
0,0,0,0,0,0,0,0,0,0,0,0,0,0,0,0,0,0,0,0,0,0,0,0,0,0,0,0,0,0,0,0,0
0,0,0,0,0,0,0,0,0,0,0,0,0,0,0,0,0,0,0,0,0,0,0,0,0,0,0,0,0,0,0,0,0
0,0,0,0,0,0,0,0,0,0,0,0,0,0,0,0,0,0,0,0,0,0,0,0,0,0,0,0,0,0,0,0,0
0,0,0,0,0,0,0,0,0,0,0,0,0,0,0,0,0,0,0,0,0,0,0,0,0,0,0,0,0,0,0,0,0
0,0,0,0,0,0,0,0,0,0,0,0,0,0,0,0,0,0,0,0,0,0,0,0,0,0,0,0,0,0,0,0,0
0,0,0,0,0,0,0,0,0,0,0,0,0,0,0,0,0,0,0,0,0,0,0,0,0,0,0,0,0,0,0,0,0
0,0,0,0,0,0,0,0,0,0,0,0,0,0,0,0,0,0,0,0,0,0,0,0,0,0,0,0,0,0,0,0,0
endlayer

layer
0,0,0,0,0,0,0,0,0,0,0,0,0,0,0,0,0,0,0,0,0,0,0,0,0,0,0,0,0,0,0,0,0
0,0,0,0,0,0,0,0,0,0,0,0,0,0,0,0,0,0,0,0,0,0,0,0,0,0,0,0,0,0,0,0,0
0,0,0,0,0,0,0,0,0,0,0,0,0,0,0,0,0,0,0,0,0,0,0,0,0,0,0,0,0,0,0,0,0
0,0,0,0,0,0,0,0,0,0,0,0,0,0,0,0,0,0,0,0,0,0,0,0,0,0,0,0,0,0,0,0,0
0,0,0,0,0,0,0,0,0,0,0,0,0,0,0,0,0,0,0,0,0,0,0,0,0,0,0,0,0,0,0,0,0
0,0,0,0,0,0,0,0,0,0,0,0,0,0,0,0,0,0,0,0,0,0,0,0,0,0,0,0,0,0,0,0,0
0,0,0,0,0,0,0,0,0,0,0,0,0,0,0,0,0,0,0,0,0,0,0,0,0,0,0,0,0,0,0,0,0
0,0,0,0,0,0,0,0,0,0,0,0,0,0,0,0,0,0,0,0,0,0,0,0,0,0,0,0,0,0,0,0,0
0,0,0,0,0,0,0,0,0,0,0,0,0,0,0,0,0,0,0,0,0,0,0,0,0,0,0,0,0,0,0,0,0
0,0,0,0,0,0,0,0,0,0,0,0,0,0,0,0,0,0,0,0,0,0,0,0,0,0,0,0,0,0,0,0,0
0,0,0,0,0,0,0,0,0,0,0,0,0,0,0,0,0,0,0,0,0,0,0,0,0,0,0,0,0,0,0,0,0
0,0,0,0,0,0,0,0,0,0,0,0,0,0,30,46,46,30,30,0,0,0,0,0,0,0,0,0,0,0,0,0,0
0,0,0,0,0,0,0,0,0,0,0,0,0,30,0,0,20,14,47,30,0,0,0,0,0,0,0,0,0,0,0,0,0
0,0,0,0,0,0,0,0,0,0,0,0,30,0,0,47,47,14,47,47,30,0,0,0,0,0,0,0,0,0,0,0,0
0,0,0,0,0,0,0,0,0,0,0,30,0,0,0,47,47,47,47,47,47,30,0,0,0,0,0,0,0,0,0,0,0
0,0,0,0,0,0,0,0,0,0,0,30,0,0,47,47,47,47,47,47,47,30,0,0,0,0,0,0,0,0,0,0,0
0,0,0,0,0,0,0,0,0,0,0,30,47,47,47,47,47,47,47,47,47,30,0,0,0,0,0,0,0,0,0,0,0
0,0,0,0,0,0,0,0,0,0,0,30,47,47,47,47,47,47,47,47,47,30,0,0,0,0,0,0,0,0,0,0,0
0,0,0,0,0,0,0,0,0,0,0,30,47,47,47,47,47,47,47,47,47,46,0,0,0,0,0,0,0,0,0,0,0
0,0,0,0,0,0,0,0,0,0,0,0,30,47,47,47,47,47,47,47,30,0,0,0,0,0,0,0,0,0,0,0,0
0,0,0,0,0,0,0,0,0,0,0,0,0,30,47,47,47,47,47,46,0,0,0,0,0,0,0,0,0,0,0,0,0
0,0,0,0,0,0,0,0,0,0,0,0,0,0,30,30,30,30,30,0,0,0,0,0,0,0,0,0,0,0,0,0,0
0,0,0,0,0,0,0,0,0,0,0,0,0,0,0,0,0,0,0,0,0,0,0,0,0,0,0,0,0,0,0,0,0
0,0,0,0,0,0,0,0,0,0,0,0,0,0,0,0,0,0,0,0,0,0,0,0,0,0,0,0,0,0,0,0,0
0,0,0,0,0,0,0,0,0,0,0,0,0,0,0,0,0,0,0,0,0,0,0,0,0,0,0,0,0,0,0,0,0
0,0,0,0,0,0,0,0,0,0,0,0,0,0,0,0,0,0,0,0,0,0,0,0,0,0,0,0,0,0,0,0,0
0,0,0,0,0,0,0,0,0,0,0,0,0,0,0,0,0,0,0,0,0,0,0,0,0,0,0,0,0,0,0,0,0
0,0,0,0,0,0,0,0,0,0,0,0,0,0,0,0,0,0,0,0,0,0,0,0,0,0,0,0,0,0,0,0,0
0,0,0,0,0,0,0,0,0,0,0,0,0,0,0,0,0,0,0,0,0,0,0,0,0,0,0,0,0,0,0,0,0
0,0,0,0,0,0,0,0,0,0,0,0,0,0,0,0,0,0,0,0,0,0,0,0,0,0,0,0,0,0,0,0,0
0,0,0,0,0,0,0,0,0,0,0,0,0,0,0,0,0,0,0,0,0,0,0,0,0,0,0,0,0,0,0,0,0
0,0,0,0,0,0,0,0,0,0,0,0,0,0,0,0,0,0,0,0,0,0,0,0,0,0,0,0,0,0,0,0,0
0,0,0,0,0,0,0,0,0,0,0,0,0,0,0,0,0,0,0,0,0,0,0,0,0,0,0,0,0,0,0,0,0
endlayer

layer
0,0,0,0,0,0,0,0,0,0,0,0,0,0,0,0,0,0,0,0,0,0,0,0,0,0,0,0,0,0,0,0,0
0,0,0,0,0,0,0,0,0,0,0,0,0,0,0,0,0,0,0,0,0,0,0,0,0,0,0,0,0,0,0,0,0
0,0,0,0,0,0,0,0,0,0,0,0,0,0,0,0,0,0,0,0,0,0,0,0,0,0,0,0,0,0,0,0,0
0,0,0,0,0,0,0,0,0,0,0,0,0,0,0,0,0,0,0,0,0,0,0,0,0,0,0,0,0,0,0,0,0
0,0,0,0,0,0,0,0,0,0,0,0,0,0,0,0,0,0,0,0,0,0,0,0,0,0,0,0,0,0,0,0,0
0,0,0,0,0,0,0,0,0,0,0,0,0,0,0,0,0,0,0,0,0,0,0,0,0,0,0,0,0,0,0,0,0
0,0,0,0,0,0,0,0,0,0,0,0,0,0,0,0,0,0,0,0,0,0,0,0,0,0,0,0,0,0,0,0,0
0,0,0,0,0,0,0,0,0,0,0,0,0,0,0,0,0,0,0,0,0,0,0,0,0,0,0,0,0,0,0,0,0
0,0,0,0,0,0,0,0,0,0,0,0,0,0,47,47,47,47,47,0,0,0,0,0,0,0,0,0,0,0,0,0,0
0,0,0,0,0,0,0,0,0,0,0,0,47,47,47,48,48,48,47,47,47,0,0,0,0,0,0,0,0,0,0,0,0
0,0,0,0,0,0,0,0,0,0,0,47,47,48,48,48,48,48,48,48,47,47,0,0,0,0,0,0,0,0,0,0,0
0,0,0,0,0,0,0,0,0,0,47,47,48,48,30,0,20,0,30,48,48,47,47,0,0,0,0,0,0,0,0,0,0
0,0,0,0,0,0,0,0,0,47,47,48,48,0,0,0,0,20,0,0,48,48,47,47,0,0,0,0,0,0,0,0,0
0,0,0,0,0,0,0,0,47,47,48,48,0,9,0,0,0,20,0,0,46,48,48,47,0,0,0,0,0,0,0,0,0
0,0,0,0,0,0,0,0,47,47,48,30,0,0,0,0,9,9,0,9,0,49,48,47,47,0,0,0,0,0,0,0,0
0,0,0,0,0,0,0,0,47,48,48,0,0,0,0,20,9,0,0,0,20,49,48,48,47,0,0,0,0,0,0,0,0
0,0,0,0,0,0,0,0,47,48,48,0,0,9,0,0,0,9,0,9,0,50,48,48,47,0,0,0,0,0,0,0,0
0,0,0,0,0,0,0,0,47,48,48,0,0,9,0,0,20,0,9,0,20,49,48,48,47,0,0,0,0,0,0,0,0
0,0,0,0,0,0,0,0,47,47,48,30,0,0,9,9,0,0,0,0,20,49,48,47,47,0,0,0,0,0,0,0,0
0,0,0,0,0,0,0,0,0,47,48,48,0,0,9,0,0,0,0,0,46,48,48,47,0,0,0,0,0,0,0,0,0
0,0,0,0,0,0,0,0,0,47,47,48,48,20,0,0,0,0,0,0,48,48,47,47,0,0,0,0,0,0,0,0,0
0,0,0,0,0,0,0,0,0,0,47,47,48,48,30,0,0,0,46,48,48,47,47,0,0,0,0,0,0,0,0,0,0
0,0,0,0,0,0,0,0,0,0,0,47,47,48,48,48,48,48,48,48,47,47,0,0,0,0,0,0,0,0,0,0,0
0,0,0,0,0,0,0,0,0,0,0,0,47,47,47,48,48,48,47,47,47,0,0,0,0,0,0,0,0,0,0,0,0
0,0,0,0,0,0,0,0,0,0,0,0,9,0,47,47,47,47,47,47,0,0,0,0,0,0,0,0,0,0,0,0,0
0,0,0,0,0,0,0,0,0,0,0,0,0,9,0,0,0,0,0,0,0,0,0,0,0,0,0,0,0,0,0,0,0
0,0,0,0,0,0,0,0,0,0,0,0,0,0,0,0,0,0,0,0,0,0,0,0,0,0,0,0,0,0,0,0,0
0,0,0,0,0,0,0,0,0,0,0,0,0,0,0,0,0,0,0,0,0,0,0,0,0,0,0,0,0,0,0,0,0
0,0,0,0,0,0,0,0,0,0,0,0,0,0,0,0,0,0,0,0,0,0,0,0,0,0,0,0,0,0,0,0,0
0,0,0,0,0,0,0,0,0,0,0,0,0,0,0,0,0,0,0,0,0,0,0,0,0,0,0,0,0,0,0,0,0
0,0,0,0,0,0,0,0,0,0,0,0,0,0,0,0,0,0,0,0,0,0,0,0,0,0,0,0,0,0,0,0,0
0,0,0,0,0,0,0,0,0,0,0,0,0,0,0,0,0,0,0,0,0,0,0,0,0,0,0,0,0,0,0,0,0
0,0,0,0,0,0,0,0,0,0,0,0,0,0,0,0,0,0,0,0,0,0,0,0,0,0,0,0,0,0,0,0,0
endlayer

layer
0,0,0,0,0,0,0,0,0,0,0,0,0,0,0,0,0,0,0,0,0,0,0,0,0,0,0,0,0,0,0,0,0
0,0,0,0,0,0,0,0,0,0,0,0,0,0,0,0,0,0,0,0,0,0,0,0,0,0,0,0,0,0,0,0,0
0,0,0,0,0,0,0,0,0,0,0,0,0,0,0,0,0,0,0,0,0,0,0,0,0,0,0,0,0,0,0,0,0
0,0,0,0,0,0,0,0,0,0,0,0,0,0,0,0,0,0,0,0,0,0,0,0,0,0,0,0,0,0,0,0,0
0,0,0,0,0,0,0,0,0,0,0,0,0,0,0,0,0,0,0,0,0,0,0,0,0,0,0,0,0,0,0,0,0
0,0,0,0,0,0,0,0,0,0,0,0,0,0,0,29,29,29,0,0,0,0,0,0,0,0,0,0,0,0,0,0,0
0,0,0,0,0,0,0,0,0,0,0,51,51,29,29,3,3,3,29,29,51,51,0,0,0,0,0,0,0,0,0,0,0
0,0,0,0,0,0,0,0,0,51,51,3,52,48,48,48,48,48,48,48,52,3,0,51,0,0,0,0,0,0,0,0,0
0,0,0,0,0,0,0,0,51,51,52,48,48,48,0,0,0,0,0,48,48,48,52,52,51,0,0,0,0,0,0,0,0
0,0,0,0,0,0,0,51,51,52,48,48,0,47,0,0,0,0,0,0,0,48,48,52,52,51,0,0,0,0,0,0,0
0,0,0,0,0,0,0,51,52,48,48,0,0,0,0,0,0,0,0,0,0,0,48,48,52,53,0,0,0,0,0,0,0
0,0,0,0,0,0,51,53,48,48,0,0,0,0,30,0,0,0,30,0,0,0,0,48,48,53,51,0,0,0,0,0,0
0,0,0,0,0,0,51,52,48,0,0,0,0,0,0,0,0,0,0,0,0,0,0,0,48,52,51,0,0,0,0,0,0
0,0,0,0,0,0,54,48,48,0,0,0,0,0,0,0,0,0,0,0,30,0,0,0,48,48,3,0,0,0,0,0,0
0,0,0,0,0,0,54,48,0,0,0,30,0,0,0,0,0,0,0,0,0,0,0,0,0,48,3,55,0,0,0,0,0
0,0,0,0,0,54,3,48,0,0,0,0,0,0,0,0,0,0,0,0,0,0,0,0,0,48,3,55,0,0,0,0,0
0,0,0,0,0,54,3,48,0,0,0,9,0,0,0,0,0,0,0,0,0,56,0,0,0,48,3,55,0,0,0,0,0
0,0,0,0,0,54,3,48,0,0,0,0,0,0,0,0,0,0,0,0,0,0,0,0,0,48,3,55,0,0,0,0,0
0,0,0,0,0,0,54,48,0,0,0,30,0,0,0,0,0,0,0,0,0,0,0,0,0,48,3,55,0,0,0,0,0
0,0,0,0,0,0,54,48,48,0,0,0,0,0,0,0,0,0,0,0,30,0,0,0,48,48,3,0,0,0,0,0,0
0,0,0,0,0,0,51,52,48,0,0,0,0,0,0,0,0,0,0,0,0,0,0,0,48,52,3,0,0,0,0,0,0
0,0,0,0,0,0,51,53,48,48,0,0,9,0,46,0,0,0,30,0,0,0,0,48,48,53,51,0,0,0,0,0,0
0,0,0,0,0,0,0,51,52,48,48,0,0,0,0,20,0,0,0,0,0,0,48,48,52,51,0,0,0,0,0,0,0
0,0,0,0,0,0,0,51,51,52,48,48,0,20,0,0,0,0,0,0,0,48,48,52,51,51,0,0,0,0,0,0,0
0,0,0,0,0,0,0,0,51,51,52,48,48,48,0,20,0,0,0,48,48,48,52,51,51,0,0,0,0,0,0,0,0
0,0,0,0,0,0,0,0,0,51,51,53,52,48,48,48,48,48,48,48,52,53,51,51,0,0,0,0,0,0,0,0,0
0,0,0,0,0,0,0,0,0,0,0,51,51,28,28,3,3,3,28,28,51,51,0,0,0,0,0,0,0,0,0,0,0
0,0,0,0,0,0,0,0,0,0,0,0,0,0,0,28,28,28,0,0,0,0,0,0,0,0,0,0,0,0,0,0,0
0,0,0,0,0,0,0,0,0,0,0,0,0,0,0,0,0,0,0,0,0,0,0,0,0,0,0,0,0,0,0,0,0
0,0,0,0,0,0,0,0,0,0,0,0,0,0,0,0,0,0,0,0,0,0,0,0,0,0,0,0,0,0,0,0,0
0,0,0,0,0,0,0,0,0,0,0,0,0,0,0,0,0,0,0,0,0,0,0,0,0,0,0,0,0,0,0,0,0
0,0,0,0,0,0,0,0,0,0,0,0,0,0,0,0,0,0,0,0,0,0,0,0,0,0,0,0,0,0,0,0,0
0,0,0,0,0,0,0,0,0,0,0,0,0,0,0,0,0,0,0,0,0,0,0,0,0,0,0,0,0,0,0,0,0
endlayer

layer
0,0,0,0,0,0,0,0,0,0,0,0,0,0,0,0,0,0,0,0,0,0,0,0,0,0,0,0,0,0,0,0,0
0,0,0,0,0,0,0,0,0,0,0,0,0,0,0,0,0,0,0,0,0,0,0,0,0,0,0,0,0,0,0,0,0
0,0,0,0,0,0,0,0,0,0,0,0,0,0,0,0,0,0,0,0,0,0,0,0,0,0,0,0,0,0,0,0,0
0,0,0,0,0,0,0,0,0,0,0,0,0,0,0,0,0,0,0,0,0,0,0,0,0,0,0,0,0,0,0,0,0
0,0,0,0,0,0,0,0,0,0,0,0,0,0,0,0,0,0,0,0,0,0,0,0,0,0,0,0,0,0,0,0,0
0,0,0,0,0,0,0,0,0,0,51,29,29,3,3,3,3,3,3,3,51,51,51,0,0,0,0,0,0,0,0,0,0
0,0,0,0,0,0,0,0,0,3,53,52,52,0,3,21,57,0,0,0,52,52,21,3,0,0,0,0,0,0,0,0,0
0,0,0,0,0,0,0,0,53,0,0,0,0,47,0,0,0,0,0,0,0,0,0,0,3,0,0,0,0,0,0,0,0
0,0,0,0,0,0,0,53,0,0,0,0,0,47,0,0,0,0,0,0,0,0,0,0,0,3,0,0,0,0,0,0,0
0,0,0,0,0,0,3,0,0,0,0,0,0,0,0,0,0,0,0,0,0,0,0,0,0,0,3,0,0,0,0,0,0
0,0,0,0,0,51,3,0,0,0,0,0,0,0,0,0,0,0,0,0,0,0,0,0,0,0,3,51,0,0,0,0,0
0,0,0,0,0,54,52,0,0,0,0,0,0,0,30,0,0,0,30,0,0,0,0,0,0,0,52,51,0,0,0,0,0
0,0,0,0,0,54,52,0,0,0,0,0,0,0,0,0,0,0,0,0,0,0,0,0,0,0,52,3,0,0,0,0,0
0,0,0,0,0,3,59,0,0,0,0,0,0,0,0,0,0,0,0,0,30,0,0,0,0,0,58,3,0,0,0,0,0
0,0,0,0,0,3,60,0,0,0,0,30,0,0,0,0,0,0,0,0,0,0,0,0,0,0,58,21,0,0,0,0,0
0,0,0,0,0,3,0,0,0,0,0,0,0,0,9,0,0,0,0,0,0,0,0,0,0,0,58,3,0,0,0,0,0
0,0,0,0,0,3,0,0,0,0,0,0,9,0,0,0,0,0,0,0,0,0,0,0,0,0,58,3,0,0,0,0,0
0,0,0,0,0,3,0,0,0,0,0,0,0,0,0,9,0,0,0,0,0,0,0,0,0,0,58,3,0,0,0,0,0
0,0,0,0,0,3,61,0,0,0,0,30,0,0,0,9,9,0,0,0,0,0,0,0,0,0,58,3,0,0,0,0,0
0,0,0,0,0,3,62,20,20,0,0,0,0,0,0,0,0,0,0,0,30,0,0,0,0,0,58,3,0,0,0,0,0
0,0,0,0,0,54,52,0,20,0,0,0,0,0,0,0,0,0,0,0,0,0,0,0,0,0,52,3,0,0,0,0,0
0,0,0,0,0,54,52,0,0,0,0,0,0,0,30,0,0,0,30,0,0,0,0,0,0,0,52,55,0,0,0,0,0
0,0,0,0,0,54,3,0,0,9,0,0,0,0,0,0,0,0,0,0,0,0,0,0,0,0,3,55,0,0,0,0,0
0,0,0,0,0,0,3,0,20,9,0,20,0,0,0,0,0,0,0,0,0,0,0,0,0,0,3,0,0,0,0,0,0
0,0,0,0,0,0,0,3,0,0,0,0,0,0,0,0,0,0,0,0,0,0,0,0,0,3,0,0,0,0,0,0,0
0,0,0,0,0,0,0,0,3,0,0,0,9,0,0,0,0,0,0,0,0,0,0,0,3,0,0,0,0,0,0,0,0
0,0,0,0,0,0,0,0,0,3,21,52,52,0,0,0,38,3,3,0,52,52,3,3,0,0,0,0,0,0,0,0,0
0,0,0,0,0,0,0,0,0,0,28,28,28,3,3,3,3,3,3,21,28,28,28,0,0,0,0,0,0,0,0,0,0
0,0,0,0,0,0,0,0,0,0,0,0,0,0,0,0,0,0,0,0,0,0,0,0,0,0,0,0,0,0,0,0,0
0,0,0,0,0,0,0,0,0,0,0,0,0,0,0,0,0,0,0,0,0,0,0,0,0,0,0,0,0,0,0,0,0
0,0,0,0,0,0,0,0,0,0,0,0,0,0,0,0,0,0,0,0,0,0,0,0,0,0,0,0,0,0,0,0,0
0,0,0,0,0,0,0,0,0,0,0,0,0,0,0,0,0,0,0,0,0,0,0,0,0,0,0,0,0,0,0,0,0
0,0,0,0,0,0,0,0,0,0,0,0,0,0,0,0,0,0,0,0,0,0,0,0,0,0,0,0,0,0,0,0,0
endlayer

layer
0,0,0,0,0,0,0,0,0,0,0,0,0,0,0,0,0,0,0,0,0,0,0,0,0,0,0,0,0,0,0,0,0
0,0,0,0,0,0,0,0,0,0,0,0,0,0,0,0,0,0,0,0,0,0,0,0,0,0,0,0,0,0,0,0,0
0,0,0,0,0,0,0,0,0,0,0,0,0,0,0,0,0,0,0,0,0,0,0,0,0,0,0,0,0,0,0,0,0
0,0,0,0,0,0,0,0,0,0,0,0,0,0,0,0,0,0,0,0,0,0,0,0,0,0,0,0,0,0,0,0,0
0,0,0,0,0,0,0,0,0,0,0,0,29,29,29,29,29,29,29,29,29,0,0,0,0,0,0,0,0,0,0,0,0
