
# Created by Ruins mod version 14.4 Ingame Parser
# authoring Player: Mikhaila666

weight=1
embed_into_distance=0
acceptable_target_blocks=
unacceptable_target_blocks=flowing_water,water,flowing_lava,lava
dimensions=12,27,30
allowable_overhang=0
max_leveling=2
leveling_buffer=0
preserve_water=0
preserve_lava=0

rule1=0,100,Railcraft:tile.railcraft.residual.heat-0
rule2=0,100,minecraft:grass-0
rule3=0,100,minecraft:cobblestone-0
rule4=0,100,minecraft:gravel-0
rule5=0,100,minecraft:sandstone-0
rule6=0,100,minecraft:dirt-0
rule7=0,100,minecraft:hay_block-0
rule8=0,100,minecraft:stone-0
rule9=0,100,minecraft:log-0
rule10=0,100,minecraft:wooden_door-6
rule11=0,100,minecraft:log-1
rule12=0,100,minecraft:fence-0
rule13=0,100,minecraft:cobblestone_wall-0
rule14=0,100,minecraft:cauldron-0
rule15=0,100,minecraft:fence_gate-2
rule16=0,100,minecraft:tallgrass-1
rule17=0,100,minecraft:fence_gate-0
rule18=0,100,minecraft:cauldron-3
rule19=0,100,minecraft:anvil-3
rule20=0,100,minecraft:crafting_table-0
rule21=0,100,minecraft:stone_stairs-3
rule22=0,100,minecraft:stone_slab-3
rule23=0,100,minecraft:stone_stairs-2
rule24=0,100,minecraft:stone_stairs-6
rule25=0,100,minecraft:stone_stairs-7
rule26=0,100,minecraft:stone_stairs-5
rule27=0,100,minecraft:ladder-4
rule28=0,100,minecraft:wooden_door-9
rule29=0,100,minecraft:wooden_door-8
rule30=0,100,minecraft:log-3
rule31=0,100,minecraft:wooden_slab-9
rule32=2,100,minecraft:torch-1
rule33=2,100,minecraft:torch-2
rule34=0,100,minecraft:ladder-5
rule35=0,100,minecraft:stone_slab-11
rule36=0,100,minecraft:wooden_slab-2
rule37=0,100,minecraft:wooden_slab-10
rule38=0,100,minecraft:wooden_slab-1
rule39=0,100,minecraft:stone_stairs-4
rule40=0,100,minecraft:spruce_stairs-2
rule41=0,100,minecraft:spruce_stairs-7
rule42=0,100,minecraft:spruce_stairs-6
rule43=0,100,minecraft:spruce_stairs-3
rule44=0,100,minecraft:double_wooden_slab-1
rule45=0,100,minecraft:iron_bars-0
rule46=0,100,minecraft:stone_stairs-1
rule47=0,100,minecraft:birch_stairs-3
rule48=0,100,minecraft:birch_stairs-2
rule49=0,100,minecraft:spruce_stairs-0
rule50=0,100,minecraft:spruce_stairs-1
rule51=0,100,ChestGenHook:dungeonChest:5-4
rule52=0,100,minecraft:birch_stairs-7
rule53=0,100,minecraft:birch_stairs-6
rule54=0,100,minecraft:spruce_stairs-4
rule55=0,100,minecraft:spruce_stairs-5
rule56=0,100,minecraft:birch_stairs-4
rule57=0,100,minecraft:stonebrick-3

layer
0,0,2,2,2,2,2,2,2,2,3,3,3,3,2,2,2,2,2,2,2,2,2,1,0,0,0,0,0,0
2,2,2,2,2,2,3,2,2,2,4,3,3,3,2,2,2,2,2,2,2,2,2,0,1,1,0,0,0,0
0,2,2,2,2,2,0,2,0,3,3,3,0,2,0,2,2,2,2,2,2,2,2,0,1,0,0,0,0,0
2,0,2,2,2,0,0,0,3,2,2,2,3,0,0,0,2,2,2,0,2,2,2,0,0,0,1,0,0,0
2,2,2,2,2,0,3,3,2,2,3,2,3,3,0,0,2,2,2,2,2,2,2,0,0,0,0,0,0,0
2,2,2,2,2,2,4,2,2,2,2,3,2,2,2,2,2,2,2,2,2,2,2,0,0,0,0,0,0,0
2,2,0,2,2,4,4,2,2,2,2,2,4,2,2,4,4,2,0,2,2,2,2,0,0,0,0,0,0,0
2,2,2,2,4,0,4,4,2,4,2,2,2,2,4,0,4,4,2,2,2,2,2,0,0,0,0,0,0,0
2,2,2,2,4,4,2,2,4,4,4,2,2,4,2,4,4,2,2,2,2,2,2,0,0,0,0,0,0,0
2,2,0,2,2,4,2,4,2,4,4,4,2,4,4,4,4,4,5,2,2,2,2,0,0,0,0,0,0,0
2,2,2,2,2,0,4,4,6,6,2,4,4,6,2,0,4,4,4,2,2,2,2,0,0,0,0,1,1,0
2,2,5,4,2,4,2,2,6,4,2,2,2,4,4,4,2,2,5,2,2,2,2,0,0,0,0,0,0,0
2,2,2,2,4,4,4,4,4,2,2,4,2,4,2,4,2,4,4,2,2,2,2,0,0,0,0,0,0,0
2,2,2,4,4,0,2,2,4,2,4,4,4,4,2,0,4,4,4,2,2,2,2,0,0,0,0,0,0,0
2,2,2,4,4,4,4,4,4,4,2,4,2,4,4,4,4,2,2,2,2,2,2,0,0,0,0,0,0,0
2,2,0,2,4,4,2,2,4,2,4,2,4,6,2,4,2,2,0,2,2,2,2,0,0,0,0,0,0,0
2,2,2,4,4,0,4,4,4,4,2,4,2,4,4,0,2,2,2,2,2,2,2,0,0,0,0,0,0,0
2,2,0,2,2,4,4,4,2,4,2,4,2,2,4,4,2,2,0,2,2,2,2,0,0,0,0,0,0,0
2,2,2,2,4,4,2,2,2,4,2,4,4,4,2,4,2,2,2,2,2,2,2,0,0,0,0,0,0,0
2,2,2,4,4,0,2,2,4,4,4,2,4,4,2,0,2,2,2,2,2,2,2,0,0,0,0,0,0,0
2,2,0,2,4,4,2,4,2,2,2,2,2,4,2,2,2,2,0,2,2,2,2,0,0,0,0,0,0,0
2,2,2,2,2,4,4,4,4,2,2,4,4,2,2,2,2,2,2,2,2,2,2,0,0,0,0,0,0,0
2,2,2,2,2,0,0,2,4,2,2,2,2,2,0,0,2,2,2,2,0,2,2,0,0,0,0,0,0,0
2,6,2,2,2,0,0,0,2,2,2,2,2,0,0,0,2,2,2,0,0,0,2,0,0,0,0,0,0,0
2,2,2,2,2,2,0,0,0,8,8,8,0,2,0,2,2,2,0,0,0,7,2,0,0,0,0,0,0,0
2,2,2,2,2,2,2,2,8,8,8,8,2,2,2,2,2,2,2,0,7,2,2,0,0,0,0,0,0,0
2,2,2,2,2,2,2,2,2,2,2,2,2,2,2,2,2,2,2,2,2,2,2,0,0,0,0,0,0,0
endlayer

layer
3,3,0,0,0,0,0,0,1,0,0,0,0,0,0,0,0,0,0,0,0,0,0,0,0,0,0,0,0,0
0,0,0,0,1,0,0,0,0,0,0,0,0,0,0,0,0,0,0,0,0,0,0,0,0,0,0,0,0,0
3,0,0,0,0,0,9,0,9,10,1,10,9,0,9,0,0,0,0,0,0,0,0,0,0,0,0,0,0,0
0,11,12,12,12,11,0,3,13,0,0,0,13,3,0,11,12,12,12,11,0,0,0,0,0,0,0,0,0,0
0,13,13,13,13,3,3,13,0,0,0,1,0,13,3,3,13,13,13,13,0,0,0,0,0,0,0,0,0,0
0,13,14,0,0,15,0,0,0,1,0,1,0,0,0,15,0,0,14,13,0,0,0,1,0,1,0,0,0,0
0,13,7,16,0,15,0,0,0,0,0,0,0,0,0,15,0,0,7,13,0,0,1,0,0,0,0,0,0,0
0,13,13,13,13,3,0,0,0,0,0,0,0,0,0,3,13,13,13,13,0,0,1,0,0,0,0,0,0,0
0,13,14,0,0,15,0,0,1,0,0,0,0,0,0,15,0,0,14,13,0,0,0,0,0,0,0,0,0,0
0,13,7,0,0,15,0,0,0,0,0,0,0,1,0,15,0,0,7,13,0,0,1,0,0,0,0,0,0,0
16,13,13,13,13,3,0,0,0,0,0,0,0,0,0,3,13,13,13,13,0,1,0,0,0,0,0,0,0,0
16,13,7,0,16,17,0,0,0,0,0,0,0,1,0,17,0,0,7,13,0,0,0,0,0,0,0,0,0,0
16,13,14,0,0,17,0,0,0,0,0,0,0,0,0,17,0,0,14,13,0,1,0,0,0,0,0,0,0,0
0,13,13,13,13,3,0,0,1,0,0,0,0,0,0,3,13,13,13,13,0,1,0,0,0,0,0,0,0,0
0,13,14,0,0,15,0,0,0,0,0,0,0,0,0,15,0,0,14,13,0,1,0,0,0,0,0,0,0,0
0,13,7,0,0,15,0,1,0,0,0,1,0,0,0,15,16,16,7,13,0,0,0,0,0,0,0,0,0,0
0,13,13,13,13,3,0,0,0,0,0,0,0,0,0,3,13,13,13,13,0,0,0,0,0,0,0,0,0,0
0,13,7,0,0,17,0,0,0,0,0,0,1,0,0,17,16,16,7,13,0,0,0,0,0,0,0,0,0,0
0,13,14,0,0,17,0,0,0,1,0,1,0,0,0,17,16,16,14,13,0,0,1,0,0,0,0,0,0,0
0,13,13,13,13,3,1,0,0,1,0,0,0,0,0,3,13,13,13,13,0,0,0,0,0,0,0,0,0,0
0,13,7,0,0,17,0,0,0,0,0,0,0,0,0,17,0,0,7,13,0,0,0,0,0,0,0,0,0,0
0,13,14,0,0,17,0,0,0,0,0,0,0,0,0,17,0,0,14,13,0,0,0,0,0,0,0,0,0,0
0,13,13,13,13,3,3,13,20,0,0,0,19,13,3,3,13,13,13,13,7,0,18,0,0,0,0,0,0,0
0,11,12,12,12,11,0,3,13,23,22,21,13,3,0,11,12,12,12,11,0,7,0,0,0,0,0,0,0,0
0,0,0,0,0,0,9,2,3,0,0,0,3,0,9,0,0,0,7,7,7,0,0,0,0,0,0,0,0,0
0,0,0,0,0,0,0,0,25,0,0,0,24,0,0,0,0,0,0,7,0,0,0,0,0,0,0,0,0,0
0,0,0,0,0,0,0,0,0,26,26,26,0,0,0,0,0,0,0,0,0,0,0,0,0,0,0,0,0,0
endlayer

layer
3,3,0,0,0,0,0,0,0,0,0,0,0,0,0,0,0,0,1,0,0,0,0,1,0,0,0,0,0,0
0,0,0,0,0,0,27,0,27,0,0,0,27,0,27,0,0,0,0,0,0,0,1,0,1,0,0,0,0,0
3,27,0,0,0,27,9,22,9,29,0,28,9,22,9,27,0,0,0,27,0,0,0,0,0,0,0,0,0,0
0,9,0,0,0,9,0,30,12,0,0,0,12,30,0,9,0,0,0,9,0,0,0,0,0,0,0,0,0,0
31,12,0,12,0,3,30,12,0,0,0,0,0,12,30,3,0,12,0,12,31,0,0,1,0,1,0,0,0,0
0,0,0,0,0,32,0,0,0,0,0,0,0,0,0,32,0,0,0,0,0,0,0,0,0,0,0,0,0,0
0,0,0,0,0,0,0,0,0,0,0,0,0,0,0,0,0,0,0,0,0,0,0,0,0,0,0,0,0,0
0,12,0,12,0,13,0,0,0,0,0,0,0,0,0,13,0,12,0,12,0,0,0,0,0,0,0,0,0,0
0,0,0,0,0,0,0,0,0,0,0,0,0,0,0,0,0,0,0,0,0,0,0,0,0,0,0,0,0,0
0,0,0,0,0,0,0,0,0,0,0,0,0,0,0,0,0,0,0,0,0,0,0,0,0,0,0,0,0,0
0,12,0,12,0,13,0,0,0,0,0,0,0,0,0,13,0,12,0,12,0,0,0,0,0,0,0,0,0,0
0,0,0,0,0,0,0,0,0,0,0,0,0,0,0,0,0,0,0,0,0,0,0,0,0,0,0,0,0,0
0,0,0,0,0,0,0,0,0,0,0,0,0,0,0,0,0,0,0,0,0,0,0,0,0,0,0,0,0,0
0,12,0,12,0,13,0,0,0,0,0,0,0,0,0,13,0,12,0,12,0,0,0,0,0,0,0,0,0,0
0,0,0,0,0,0,0,0,0,0,0,0,0,0,0,0,0,0,0,0,0,1,0,0,0,0,0,0,0,0
0,0,0,0,0,0,0,0,0,0,0,0,0,0,0,0,0,0,0,0,0,0,0,0,0,0,0,0,0,0
0,12,0,12,0,13,0,0,0,0,0,0,0,0,0,13,0,12,0,12,0,0,0,0,0,0,0,0,0,0
0,0,0,0,0,0,0,0,0,0,0,0,0,0,0,0,0,0,0,0,0,1,0,0,0,0,0,0,0,0
0,0,0,0,0,0,0,0,0,0,0,0,0,0,0,0,0,0,0,0,0,0,0,0,0,0,0,0,0,0
0,12,0,12,0,13,0,0,0,0,0,0,0,0,0,13,0,12,0,12,0,0,0,0,0,0,0,0,0,0
0,0,0,0,0,0,0,0,0,0,0,0,0,0,0,0,0,0,0,0,0,0,0,0,0,0,0,0,0,0
0,0,0,0,0,33,0,0,0,0,0,0,0,0,0,33,0,0,0,0,0,0,0,0,0,0,0,0,0,0
31,12,0,12,0,3,30,12,0,0,0,0,0,12,30,3,0,12,0,12,31,0,0,0,0,0,0,0,0,0
0,9,0,0,0,9,0,30,13,24,0,25,13,30,0,9,0,0,0,9,7,0,0,0,0,1,0,0,0,0
0,34,0,0,0,34,9,22,3,0,0,0,3,22,9,34,0,0,0,34,0,0,0,0,0,0,0,0,0,0
0,0,0,0,0,0,34,0,3,0,0,0,3,0,34,0,0,0,0,0,0,0,0,0,1,0,0,0,0,0
0,0,0,0,0,0,0,0,0,3,35,3,0,0,0,0,0,0,0,0,0,0,0,0,0,0,0,0,0,0
endlayer

layer
3,3,0,0,0,0,0,0,0,0,0,0,0,0,0,0,0,0,0,0,0,0,0,0,0,0,0,0,0,0
22,0,0,31,0,0,27,0,27,0,0,0,27,0,27,0,0,31,0,0,0,0,0,0,0,0,0,0,0,0
3,0,0,31,0,27,9,0,9,0,0,0,9,0,9,27,0,31,0,0,0,0,0,0,0,0,0,0,0,0
0,13,36,37,0,9,0,30,12,0,0,0,12,30,0,9,0,37,36,13,0,0,0,0,0,0,0,0,0,0
0,38,31,12,0,3,30,12,0,0,0,0,0,12,30,3,0,12,31,38,0,0,0,0,0,0,0,0,0,0
38,7,7,31,0,0,0,0,0,0,0,0,0,0,0,0,0,31,7,7,38,0,0,0,0,0,0,0,0,0
38,7,7,31,0,0,0,0,0,0,0,0,0,0,0,0,0,31,7,7,38,0,0,0,0,0,0,0,0,0
38,7,7,12,0,12,0,0,0,0,0,0,0,0,0,12,0,12,7,7,38,0,0,0,0,0,0,0,0,0
38,7,7,31,0,0,0,0,0,0,0,0,0,0,0,0,0,31,7,7,38,0,0,0,0,0,1,0,0,0
38,7,7,31,0,0,0,0,0,0,0,0,0,0,0,0,0,31,7,7,38,0,0,0,0,0,0,0,0,0
38,7,7,12,0,12,0,0,0,0,0,0,0,0,0,12,0,12,7,7,38,0,0,0,0,0,0,0,0,0
38,7,7,31,0,0,0,0,0,0,0,0,0,0,0,0,0,31,7,7,38,0,0,0,0,0,0,0,0,0
38,7,7,31,0,0,0,0,0,0,0,0,0,0,0,0,0,31,7,7,38,0,0,0,0,0,0,0,0,0
38,7,7,12,0,12,0,0,0,0,0,0,0,0,0,12,0,12,7,7,38,0,0,0,0,0,0,0,0,0
38,7,7,31,0,0,0,0,0,0,0,0,0,0,0,0,0,31,7,7,38,0,0,0,0,0,0,0,0,0
38,7,7,31,0,0,0,0,0,0,0,0,0,0,0,0,0,31,7,7,38,0,0,0,0,0,0,0,0,0
38,7,7,12,0,12,0,0,0,0,0,0,0,0,0,12,0,12,7,7,38,0,0,0,0,0,0,0,0,0
38,7,7,31,0,0,0,0,0,0,0,0,0,0,0,0,0,31,7,7,38,0,0,0,0,0,0,0,0,0
38,7,7,31,0,0,0,0,0,0,0,0,0,0,0,0,0,31,7,7,38,0,0,0,0,0,0,0,0,0
38,7,7,12,0,12,0,0,0,0,0,0,0,0,0,12,0,12,7,7,38,0,0,0,0,0,0,0,0,0
38,7,7,31,0,0,0,0,0,0,0,0,0,0,0,0,0,31,7,7,38,0,0,0,0,0,0,0,0,0
38,7,7,31,0,0,0,0,0,0,0,0,0,0,0,0,0,31,7,7,38,0,0,0,0,0,0,0,0,0
0,38,31,12,0,3,30,12,0,0,0,0,0,12,30,3,0,12,31,38,0,0,0,0,0,0,0,0,0,0
0,13,36,37,0,9,0,30,13,21,39,23,13,30,0,9,0,37,36,13,0,0,0,0,0,0,0,0,0,0
0,0,0,31,0,34,9,0,3,24,0,25,3,0,9,34,0,31,0,0,0,0,0,1,0,0,1,0,0,0
0,0,0,31,0,0,34,0,21,24,0,25,23,0,34,0,0,31,0,0,0,0,0,0,0,0,0,0,0,0
0,0,0,0,0,0,0,0,0,3,3,3,0,0,0,0,0,0,0,0,0,0,0,0,0,0,0,0,0,0
endlayer

layer
9,23,0,0,0,0,0,0,0,0,0,0,0,0,0,0,0,0,0,0,0,0,0,0,0,0,0,0,0,0
0,0,0,0,43,42,27,0,27,0,0,0,27,0,27,41,40,0,0,0,0,0,0,0,0,0,0,0,0,0
23,0,0,0,7,0,9,42,9,42,31,41,9,41,9,0,7,0,0,0,0,0,0,0,0,0,0,0,0,0
0,12,0,0,36,9,0,30,13,0,0,0,13,30,0,9,36,0,0,12,0,0,0,0,0,0,0,0,0,0
0,0,0,38,31,3,30,44,31,31,31,31,31,44,30,3,31,38,0,0,0,0,0,0,0,0,0,0,0,0
0,0,38,7,7,12,42,0,0,0,0,0,0,0,41,12,7,7,38,0,0,0,0,0,0,0,0,0,0,0
0,0,38,7,7,12,42,45,0,0,0,0,0,45,41,12,7,7,38,0,0,0,0,0,0,0,0,0,0,0
0,0,38,7,7,12,0,0,0,0,0,0,0,0,0,12,7,7,38,0,0,0,0,0,0,0,0,0,0,0
0,0,38,7,7,12,42,45,0,0,0,0,0,45,41,12,7,7,38,0,0,0,0,0,0,0,0,0,0,0
0,0,38,7,7,12,42,0,0,0,0,0,0,0,41,12,7,7,38,0,0,0,0,0,0,0,0,0,0,0
0,0,38,7,7,12,42,45,0,0,0,0,0,45,41,12,7,7,38,0,0,0,0,0,0,0,0,0,0,0
0,0,38,7,7,12,0,0,0,0,0,0,0,0,0,12,7,7,38,0,0,0,0,0,0,0,0,0,0,0
0,0,38,7,7,12,42,45,0,0,0,0,0,45,41,12,7,7,38,0,0,0,0,0,0,0,0,0,0,0
0,0,38,7,7,12,42,0,0,0,0,0,0,0,41,12,7,7,38,0,0,0,0,0,0,0,0,0,0,0
0,0,38,7,7,12,42,45,0,0,0,0,0,45,41,12,7,7,38,0,0,0,0,0,0,0,0,0,0,0
0,0,38,7,7,12,0,0,0,0,0,0,0,0,0,12,7,7,38,0,0,0,0,0,0,0,0,0,0,0
0,0,38,7,7,12,42,45,0,0,0,0,0,45,41,12,7,7,38,0,0,0,0,0,0,0,0,0,0,0
0,0,38,7,7,12,42,0,0,0,0,0,0,0,41,12,7,7,38,0,0,0,0,0,0,0,0,0,0,0
0,0,38,7,7,12,42,45,0,0,0,0,0,45,41,12,7,7,38,0,0,0,0,0,0,0,0,0,0,0
0,0,38,7,7,12,0,0,0,0,0,0,0,0,0,12,7,7,38,0,0,0,0,0,0,0,0,0,0,0
0,0,38,7,7,12,42,45,0,0,0,0,0,45,41,12,7,7,38,0,0,0,0,0,0,0,0,0,0,0
0,0,38,7,7,12,42,0,0,0,0,0,0,0,41,12,7,7,38,0,0,0,0,0,0,0,0,0,0,0
0,0,0,38,31,3,30,44,31,31,31,31,31,44,30,3,31,38,0,0,0,0,0,0,0,0,0,0,0,0
0,12,0,0,36,9,0,30,13,0,3,0,13,30,0,9,36,0,0,12,0,0,0,0,0,0,0,0,0,0
0,0,0,0,7,0,9,42,3,3,3,3,3,41,9,0,7,0,0,0,0,0,0,0,0,0,0,0,0,0
0,0,0,0,43,42,34,0,0,21,3,23,0,0,34,41,40,0,0,0,0,0,0,0,0,0,0,0,0,0
0,0,0,0,0,0,0,0,0,21,46,23,0,0,0,0,0,0,0,0,0,0,0,0,0,0,0,0,0,0
endlayer

layer
9,12,0,0,0,0,0,0,0,1,0,0,0,0,0,0,0,0,0,0,0,0,0,0,0,0,0,0,0,0
0,0,0,0,0,43,42,0,0,0,0,0,0,0,41,40,0,0,0,0,0,0,0,0,0,0,0,0,0,0
12,0,0,0,0,7,9,48,38,47,49,48,38,47,9,7,0,0,0,0,0,0,0,0,0,0,0,0,0,0
0,0,0,0,0,13,9,9,9,9,50,9,9,9,9,13,0,0,0,0,0,0,0,0,0,0,0,0,0,0
0,0,0,0,0,38,9,12,0,12,0,12,0,12,9,38,0,0,0,0,0,0,0,0,0,0,0,0,0,0
0,0,0,0,38,7,9,0,0,0,0,0,0,0,9,7,38,0,0,0,0,0,0,0,0,0,0,0,0,0
0,0,0,0,38,7,9,12,0,0,0,0,0,12,9,7,38,0,0,0,0,0,0,0,0,0,0,0,0,0
0,0,0,0,38,7,42,0,0,0,0,0,0,0,41,7,38,0,0,0,0,0,0,0,0,0,0,0,0,0
0,0,0,0,38,7,9,12,0,0,0,0,0,12,9,7,38,0,0,0,0,0,0,0,0,0,0,0,0,0
0,0,0,0,38,7,9,0,0,0,0,0,0,0,9,7,38,0,0,0,0,0,0,0,0,0,0,0,0,0
0,0,0,0,38,7,9,12,0,0,0,0,0,12,9,7,38,0,0,0,0,0,0,0,0,0,0,0,0,0
0,0,0,0,38,7,42,0,0,0,0,0,0,0,41,7,38,0,0,0,0,0,0,0,0,0,0,0,0,0
0,0,0,0,38,7,9,12,0,0,0,0,0,12,9,7,38,0,0,0,0,0,0,0,0,0,0,0,0,0
0,0,0,0,38,7,9,0,0,0,0,0,0,0,9,7,38,0,0,0,0,0,0,0,0,0,0,0,0,0
0,0,0,0,38,7,9,12,0,0,0,0,0,12,9,7,38,0,0,0,0,0,0,0,0,0,0,0,0,0
0,0,0,0,38,7,42,0,0,0,0,0,0,0,41,7,38,0,0,0,0,0,0,0,0,0,0,0,0,0
0,0,0,0,38,7,9,12,0,0,0,0,0,12,9,7,38,0,0,0,0,0,0,0,0,0,0,0,0,0
0,0,0,0,38,7,9,0,0,0,0,0,0,0,9,7,38,0,0,0,0,0,0,0,0,0,0,0,0,0
0,0,0,0,38,7,9,12,0,0,0,0,0,12,9,7,38,0,0,0,0,0,0,0,0,0,0,0,0,0
0,0,0,0,38,7,42,0,0,0,0,0,0,0,41,7,38,0,0,0,0,0,0,0,0,0,0,0,0,0
0,0,0,0,38,7,9,12,0,0,0,0,0,12,9,7,38,0,0,0,0,0,0,0,0,0,0,0,0,0
0,0,0,0,38,7,9,0,0,0,0,0,0,0,9,7,38,0,0,0,0,0,0,0,0,0,0,0,0,0
0,0,0,0,0,38,9,12,51,12,51,12,51,12,9,38,0,0,0,0,0,0,0,0,0,0,0,0,0,0
0,0,0,0,0,13,9,9,9,9,49,9,9,9,9,13,0,0,0,0,0,0,0,0,0,0,0,0,0,0
0,0,0,0,0,7,9,48,38,47,50,48,38,47,9,7,0,0,0,0,0,0,0,0,0,0,0,0,0,0
0,0,0,0,0,43,42,0,0,0,3,0,0,0,41,40,0,0,0,0,0,0,0,0,0,0,0,0,0,0
0,0,0,0,0,0,0,0,0,0,0,0,0,0,0,0,0,0,0,0,0,0,0,0,0,0,0,0,0,0
endlayer

layer
9,12,0,0,0,0,0,0,0,0,0,0,0,0,0,0,0,0,0,0,0,0,0,0,0,0,0,0,0,0
0,0,0,0,0,0,43,42,0,0,0,0,0,41,40,0,0,0,0,0,0,0,0,0,0,0,0,0,0,0
12,0,0,0,0,0,7,53,0,12,0,12,0,52,7,0,0,0,0,0,0,0,0,0,0,0,0,0,0,0
0,0,0,0,0,12,7,9,9,9,12,9,9,9,7,12,0,0,0,0,0,0,0,0,0,0,0,0,0,0
0,0,0,0,0,0,7,9,0,12,0,12,0,9,7,0,0,0,0,0,0,0,0,0,0,0,0,0,0,0
0,0,0,0,0,0,7,42,0,0,0,0,0,41,7,0,0,0,0,0,0,0,0,0,0,0,0,0,0,0
0,0,0,0,0,0,7,9,42,0,0,0,41,9,7,0,0,0,0,0,0,0,0,0,0,0,0,0,0,0
0,0,0,0,0,0,7,42,0,0,0,0,0,41,7,0,0,0,0,0,0,0,0,0,0,0,0,0,0,0
0,0,0,0,0,0,7,9,42,0,0,0,41,9,7,0,0,0,0,0,0,0,0,0,0,0,0,0,0,0
0,0,0,0,0,0,7,42,0,0,0,0,0,41,7,0,0,0,0,0,0,0,0,0,0,0,0,0,0,0
0,0,0,0,0,0,7,9,42,0,0,0,41,9,7,0,0,0,0,0,0,0,0,0,0,0,0,0,0,0
0,0,0,0,0,0,7,42,0,0,0,0,0,41,7,0,0,0,0,0,0,0,0,0,0,0,0,0,0,0
0,0,0,0,0,0,7,9,42,0,0,0,41,9,7,0,0,0,0,0,0,0,0,0,0,0,0,0,0,0
0,0,0,0,0,0,7,42,0,0,0,0,0,41,7,0,0,0,0,0,0,0,0,0,0,0,0,0,0,0
0,0,0,0,0,0,7,9,42,0,0,0,41,9,7,0,0,0,0,0,0,0,0,0,0,0,0,0,0,0
0,0,0,0,0,0,7,42,0,0,0,0,0,41,7,0,0,0,0,0,0,0,0,0,0,0,0,0,0,0
0,0,0,0,0,0,7,9,42,0,0,0,41,9,7,0,0,0,0,0,0,0,0,0,0,0,0,0,0,0
0,0,0,0,0,0,7,42,0,0,0,0,0,41,7,0,0,0,0,0,0,0,0,0,0,0,0,0,0,0
0,0,0,0,0,0,7,9,42,0,0,0,41,9,7,0,0,0,0,0,0,0,0,0,0,0,0,0,0,0
0,0,0,0,0,0,7,42,0,0,0,0,0,41,7,0,0,0,0,0,0,0,0,0,0,0,0,0,0,0
0,0,0,0,0,0,7,9,42,0,0,0,41,9,7,0,0,0,0,0,0,0,0,0,0,0,0,0,0,0
0,0,0,0,0,0,7,42,0,0,0,0,0,41,7,0,0,0,0,0,0,0,0,0,0,0,0,0,0,0
0,0,0,0,0,0,7,9,0,12,0,12,0,9,7,0,0,0,0,0,0,0,0,0,0,0,0,0,0,0
0,0,0,0,0,12,7,9,9,9,12,9,9,9,7,12,0,0,0,0,0,0,0,0,0,0,0,0,0,0
0,0,0,0,0,0,7,53,0,12,0,12,0,52,7,0,0,0,0,0,0,0,0,0,0,0,0,0,0,0
0,0,0,0,0,0,43,42,0,0,3,0,0,41,40,0,0,0,0,0,0,0,0,0,0,0,0,0,0,0
0,0,0,0,0,0,0,0,0,0,0,0,0,0,0,0,0,0,0,0,0,0,0,0,0,0,0,0,0,0
endlayer

layer
9,12,0,0,0,0,0,0,0,0,0,0,0,0,0,0,0,0,0,0,0,0,0,0,0,0,0,0,0,0
0,0,0,0,0,0,0,43,42,0,0,0,41,40,0,0,0,0,0,0,0,0,0,0,0,0,0,0,0,0
12,0,0,0,0,0,0,7,53,52,54,53,52,7,0,0,0,0,0,0,0,0,0,0,0,0,0,0,0,0
0,0,0,0,0,0,0,7,9,9,55,9,9,7,0,0,0,0,0,0,0,0,0,0,0,0,0,0,0,0
0,0,0,0,0,0,0,7,12,12,0,12,12,7,0,0,0,0,0,0,0,0,0,0,0,0,0,0,0,0
0,0,0,0,0,0,0,7,0,0,0,0,0,7,0,0,0,0,0,0,0,0,0,0,0,0,0,0,0,0
0,0,0,0,0,0,0,7,38,44,31,44,38,7,0,0,0,0,0,0,0,0,0,0,0,0,0,0,0,0
0,0,0,0,0,0,0,7,0,0,0,0,0,7,0,0,0,0,0,0,0,0,0,0,0,0,0,0,0,0
0,0,0,0,0,0,0,7,38,44,31,44,38,7,0,0,0,0,0,0,0,0,0,0,0,0,0,0,0,0
0,0,0,0,0,0,0,7,0,0,0,0,0,7,0,0,0,0,0,0,0,0,0,0,0,0,0,0,0,0
0,0,0,0,0,0,0,7,38,44,31,44,38,7,0,0,0,0,0,0,0,0,0,0,0,0,0,0,0,0
0,0,0,0,0,0,0,7,0,0,0,0,0,7,0,0,0,0,0,0,0,0,0,0,0,0,0,0,0,0
0,0,0,0,0,0,0,7,38,44,31,44,38,7,0,0,0,0,0,0,0,0,0,0,0,0,0,0,0,0
0,0,0,0,0,0,0,7,0,0,0,0,0,7,0,0,0,0,0,0,0,0,0,0,0,0,0,0,0,0
0,0,0,0,0,0,0,7,38,44,31,44,38,7,0,0,0,0,0,0,0,0,0,0,0,0,0,0,0,0
0,0,0,0,0,0,0,7,0,0,0,0,0,7,0,0,0,0,0,0,0,0,0,0,0,0,0,0,0,0
0,0,0,0,0,0,0,7,38,44,31,44,38,7,0,0,0,0,0,0,0,0,0,0,0,0,0,0,0,0
0,0,0,0,0,0,0,7,0,0,0,0,0,7,0,0,0,0,0,0,0,0,0,0,0,0,0,0,0,0
0,0,0,0,0,0,0,7,38,44,31,44,38,7,0,0,0,0,0,0,0,0,0,0,0,0,0,0,0,0
0,0,0,0,0,0,0,7,0,0,0,0,0,7,0,0,0,0,0,0,0,0,0,0,0,0,0,0,0,0
0,0,0,0,0,0,0,7,38,44,31,44,38,7,0,0,0,0,0,0,0,0,0,0,0,0,0,0,0,0
0,0,0,0,0,0,0,7,0,0,0,0,0,7,0,0,0,0,0,0,0,0,0,0,0,0,0,0,0,0
0,0,0,0,0,0,0,7,12,12,0,12,12,7,0,0,0,0,0,0,0,0,0,0,0,0,0,0,0,0
0,0,0,0,0,0,0,7,9,9,54,9,9,7,0,0,0,0,0,0,0,0,0,0,0,0,0,0,0,0
0,0,0,0,0,0,0,7,53,52,55,53,52,7,0,0,0,0,0,0,0,0,0,0,0,0,0,0,0,0
0,0,0,0,0,0,0,43,42,0,3,0,41,40,0,0,0,0,0,0,0,0,0,0,0,0,0,0,0,0
0,0,0,0,0,0,0,0,0,0,26,0,0,0,0,0,0,0,0,0,0,0,0,0,0,0,0,0,0,0
endlayer

layer
9,12,0,0,0,0,0,0,0,0,0,0,0,0,0,0,0,0,0,0,0,0,0,0,0,0,0,0,0,0
0,0,0,0,0,0,0,0,38,44,44,44,38,0,0,0,0,0,0,0,0,0,0,0,0,0,0,0,0,0
12,0,0,0,0,0,0,0,7,7,9,7,7,0,0,0,0,0,0,0,0,0,0,0,0,0,0,0,0,0
0,0,0,0,0,0,0,0,7,7,9,7,7,0,0,0,0,0,0,0,0,0,0,0,0,0,0,0,0,0
0,0,0,0,0,0,0,0,7,7,12,7,7,0,0,0,0,0,0,0,0,0,0,0,0,0,0,0,0,0
0,0,0,0,0,0,0,0,7,7,0,7,7,0,0,0,0,0,0,0,0,0,0,0,0,0,0,0,0,0
0,0,0,0,0,0,0,0,7,7,12,7,7,0,0,0,0,0,0,0,0,0,0,0,0,0,0,0,0,0
0,0,0,0,0,0,0,0,7,7,0,7,7,0,0,0,0,0,0,0,0,0,0,0,0,0,0,0,0,0
0,0,0,0,0,0,0,0,7,7,12,7,7,0,0,0,0,0,0,0,0,0,0,0,0,0,0,0,0,0
0,0,0,0,0,0,0,0,7,7,0,7,7,0,0,0,0,0,0,0,0,0,0,0,0,0,0,0,0,0
0,0,0,0,0,0,0,0,7,7,12,7,7,0,0,0,0,0,0,0,0,0,0,0,0,0,0,0,0,0
0,0,0,0,0,0,0,0,7,7,0,7,7,0,0,0,0,0,0,0,0,0,0,0,0,0,0,0,0,0
0,0,0,0,0,0,0,0,7,7,12,7,7,0,0,0,0,0,0,0,0,0,0,0,0,0,0,0,0,0
0,0,0,0,0,0,0,0,7,7,0,7,7,0,0,0,0,0,0,0,0,0,0,0,0,0,0,0,0,0
0,0,0,0,0,0,0,0,7,7,12,7,7,0,0,0,0,0,0,0,0,0,0,0,0,0,0,0,0,0
0,0,0,0,0,0,0,0,7,7,0,7,7,0,0,0,0,0,0,0,0,0,0,0,0,0,0,0,0,0
0,0,0,0,0,0,0,0,7,7,12,7,7,0,0,0,0,0,0,0,0,0,0,0,0,0,0,0,0,0
0,0,0,0,0,0,0,0,7,7,0,7,7,0,0,0,0,0,0,0,0,0,0,0,0,0,0,0,0,0
0,0,0,0,0,0,0,0,7,7,12,7,7,0,0,0,0,0,0,0,0,0,0,0,0,0,0,0,0,0
0,0,0,0,0,0,0,0,7,7,0,7,7,0,0,0,0,0,0,0,0,0,0,0,0,0,0,0,0,0
0,0,0,0,0,0,0,0,7,7,12,7,7,0,0,0,0,0,0,0,0,0,0,0,0,0,0,0,0,0
0,0,0,0,0,0,0,0,7,7,0,7,7,0,0,0,0,0,0,0,0,0,0,0,0,0,0,0,0,0
0,0,0,0,0,0,0,0,7,7,12,7,7,0,0,0,0,0,0,0,0,0,0,0,0,0,0,0,0,0
0,0,0,0,0,0,0,0,7,7,9,7,7,0,0,0,0,0,0,0,0,0,0,0,0,0,0,0,0,0
0,0,0,0,0,0,0,0,7,7,9,7,7,0,0,0,0,0,0,0,0,0,0,0,0,0,0,0,0,0
0,0,0,0,0,0,0,0,38,44,44,44,38,0,0,0,0,0,0,0,0,0,0,0,0,0,0,0,0,0
0,0,0,0,0,0,0,0,0,0,3,0,0,0,0,0,0,0,0,0,0,0,0,0,0,0,0,0,0,0
endlayer

layer
40,0,0,0,0,0,0,0,0,41,56,42,0,0,0,0,0,0,0,0,0,0,0,0,0,0,0,0,0,0
0,0,0,0,0,0,0,0,0,0,49,0,0,0,0,0,0,0,0,0,0,0,0,0,0,0,0,0,0,0
0,0,0,0,0,0,0,0,0,38,7,38,0,0,0,0,0,0,0,0,0,0,0,0,0,0,0,0,0,0
0,0,0,0,0,0,0,0,0,38,7,38,0,0,0,0,0,0,0,0,0,0,0,0,0,0,0,0,0,0
0,0,0,0,0,0,0,0,0,38,7,38,0,0,0,0,0,0,0,0,0,0,0,0,0,0,0,0,0,0
0,0,0,0,0,0,0,0,0,38,7,38,0,0,0,0,0,0,0,0,0,0,0,0,0,0,0,0,0,0
0,0,0,0,0,0,0,0,0,38,7,38,0,0,0,0,0,0,0,0,0,0,0,0,0,0,0,0,0,0
0,0,0,0,0,0,0,0,0,38,7,38,0,0,0,0,0,0,0,0,0,0,0,0,0,0,0,0,0,0
0,0,0,0,0,0,0,0,0,38,7,38,0,0,0,0,0,0,0,0,0,0,0,0,0,0,0,0,0,0
0,0,0,0,0,0,0,0,0,38,7,38,0,0,0,0,0,0,0,0,0,0,0,0,0,0,0,0,0,0
0,0,0,0,0,0,0,0,0,38,7,38,0,0,0,0,0,0,0,0,0,0,0,0,0,0,0,0,0,0
0,0,0,0,0,0,0,0,0,38,7,38,0,0,0,0,0,0,0,0,0,0,0,0,0,0,0,0,0,0
0,0,0,0,0,0,0,0,0,38,7,38,0,0,0,0,0,0,0,0,0,0,0,0,0,0,0,0,0,0
0,0,0,0,0,0,0,0,0,38,7,38,0,0,0,0,0,0,0,0,0,0,0,0,0,0,0,0,0,0
0,0,0,0,0,0,0,0,0,38,7,38,0,0,0,0,0,0,0,0,0,0,0,0,0,0,0,0,0,0
0,0,0,0,0,0,0,0,0,38,7,38,0,0,0,0,0,0,0,0,0,0,0,0,0,0,0,0,0,0
0,0,0,0,0,0,0,0,0,38,7,38,0,0,0,0,0,0,0,0,0,0,0,0,0,0,0,0,0,0
0,0,0,0,0,0,0,0,0,38,7,38,0,0,0,0,0,0,0,0,0,0,0,0,0,0,0,0,0,0
0,0,0,0,0,0,0,0,0,38,7,38,0,0,0,0,0,0,0,0,0,0,0,0,0,0,0,0,0,0
0,0,0,0,0,0,0,0,0,38,7,38,0,0,0,0,0,0,0,0,0,0,0,0,0,0,0,0,0,0
0,0,0,0,0,0,0,0,0,38,7,38,0,0,0,0,0,0,0,0,0,0,0,0,0,0,0,0,0,0
0,0,0,0,0,0,0,0,0,38,7,38,0,0,0,0,0,0,0,0,0,0,0,0,0,0,0,0,0,0
0,0,0,0,0,0,0,0,0,38,7,38,0,0,0,0,0,0,0,0,0,0,0,0,0,0,0,0,0,0
0,0,0,0,0,0,0,0,0,38,7,38,0,0,0,0,0,0,0,0,0,0,0,0,0,0,0,0,0,0
0,0,0,0,0,0,0,0,0,38,7,38,0,0,0,0,0,0,0,0,0,0,0,0,0,0,0,0,0,0
0,0,0,0,0,0,0,0,0,0,50,0,0,0,0,0,0,0,0,0,0,0,0,0,0,0,0,0,0,0
0,0,0,0,0,0,0,0,0,41,3,42,0,0,0,0,0,0,0,0,0,0,0,0,0,0,0,0,0,0
endlayer

layer
0,0,0,0,0,0,0,0,0,40,0,43,0,0,0,0,0,0,0,0,0,0,0,0,0,0,0,0,0,0
0,0,0,0,0,0,0,0,0,0,0,0,0,0,0,0,0,0,0,0,0,0,0,0,0,0,0,0,0,0
0,0,0,0,0,0,0,0,0,0,0,0,0,0,0,0,0,0,0,0,0,0,0,0,0,0,0,0,0,0
0,0,0,0,0,0,0,0,0,0,0,0,0,0,0,0,0,0,0,0,0,0,0,0,0,0,0,0,0,0
0,0,0,0,0,0,0,0,0,0,0,0,0,0,0,0,0,0,0,0,0,0,0,0,0,0,0,0,0,0
0,0,0,0,0,0,0,0,0,0,0,0,0,0,0,0,0,0,0,0,0,0,0,0,0,0,0,0,0,0
0,0,0,0,0,0,0,0,0,0,0,0,0,0,0,0,0,0,0,0,0,0,0,0,0,0,0,0,0,0
0,0,0,0,0,0,0,0,0,0,0,0,0,0,0,0,0,0,0,0,0,0,0,0,0,0,0,0,0,0
0,0,0,0,0,0,0,0,0,0,0,0,0,0,0,0,0,0,0,0,0,0,0,0,0,0,0,0,0,0
0,0,0,0,0,0,0,0,0,0,0,0,0,0,0,0,0,0,0,0,0,0,0,0,0,0,0,0,0,0
0,0,0,0,0,0,0,0,0,0,0,0,0,0,0,0,0,0,0,0,0,0,0,0,0,0,0,0,0,0
0,0,0,0,0,0,0,0,0,0,0,0,0,0,0,0,0,0,0,0,0,0,0,0,0,0,0,0,0,0
0,0,0,0,0,0,0,0,0,0,0,0,0,0,0,0,0,0,0,0,0,0,0,0,0,0,0,0,0,0
0,0,0,0,0,0,0,0,0,0,0,0,0,0,0,0,0,0,0,0,0,0,0,0,0,0,0,0,0,0
0,0,0,0,0,0,0,0,0,0,0,0,0,0,0,0,0,0,0,0,0,0,0,0,0,0,0,0,0,0
0,0,0,0,0,0,0,0,0,0,0,0,0,0,0,0,0,0,0,0,0,0,0,0,0,0,0,0,0,0
0,0,0,0,0,0,0,0,0,0,0,0,0,0,0,0,0,0,0,0,0,0,0,0,0,0,0,0,0,0
0,0,0,0,0,0,0,0,0,0,0,0,0,0,0,0,0,0,0,0,0,0,0,0,0,0,0,0,0,0
0,0,0,0,0,0,0,0,0,0,0,0,0,0,0,0,0,0,0,0,0,0,0,0,0,0,0,0,0,0
0,0,0,0,0,0,0,0,0,0,0,0,0,0,0,0,0,0,0,0,0,0,0,0,0,0,0,0,0,0
0,0,0,0,0,0,0,0,0,0,0,0,0,0,0,0,0,0,0,0,0,0,0,0,0,0,0,0,0,0
0,0,0,0,0,0,0,0,0,0,0,0,0,0,0,0,0,0,0,0,0,0,0,0,0,0,0,0,0,0
0,0,0,0,0,0,0,0,0,0,0,0,0,0,0,0,0,0,0,0,0,0,0,0,0,0,0,0,0,0
0,0,0,0,0,0,0,0,0,0,0,0,0,0,0,0,0,0,0,0,0,0,0,0,0,0,0,0,0,0
0,0,0,0,0,0,0,0,0,0,0,0,0,0,0,0,0,0,0,0,0,0,0,0,0,0,0,0,0,0
0,0,0,0,0,0,0,0,0,0,0,0,0,0,0,0,0,0,0,0,0,0,0,0,0,0,0,0,0,0
0,0,0,0,0,0,0,0,0,40,3,43,0,0,0,0,0,0,0,0,0,0,0,0,0,0,0,0,0,0
endlayer

layer
0,0,0,0,0,0,0,0,0,0,0,0,0,0,0,0,0,0,0,0,0,0,0,0,0,0,0,0,0,0
0,0,0,0,0,0,0,0,0,0,0,0,0,0,0,0,0,0,0,0,0,0,0,0,0,0,0,0,0,0
0,0,0,0,0,0,0,0,0,0,0,0,0,0,0,0,0,0,0,0,0,0,0,0,0,0,0,0,0,0
0,0,0,0,0,0,0,0,0,0,0,0,0,0,0,0,0,0,0,0,0,0,0,0,0,0,0,0,0,0
0,0,0,0,0,0,0,0,0,0,0,0,0,0,0,0,0,0,0,0,0,0,0,0,0,0,0,0,0,0
0,0,0,0,0,0,0,0,0,0,0,0,0,0,0,0,0,0,0,0,0,0,0,0,0,0,0,0,0,0
0,0,0,0,0,0,0,0,0,0,0,0,0,0,0,0,0,0,0,0,0,0,0,0,0,0,0,0,0,0
0,0,0,0,0,0,0,0,0,0,0,0,0,0,0,0,0,0,0,0,0,0,0,0,0,0,0,0,0,0
0,0,0,0,0,0,0,0,0,0,0,0,0,0,0,0,0,0,0,0,0,0,0,0,0,0,0,0,0,0
0,0,0,0,0,0,0,0,0,0,0,0,0,0,0,0,0,0,0,0,0,0,0,0,0,0,0,0,0,0
0,0,0,0,0,0,0,0,0,0,0,0,0,0,0,0,0,0,0,0,0,0,0,0,0,0,0,0,0,0
0,0,0,0,0,0,0,0,0,0,0,0,0,0,0,0,0,0,0,0,0,0,0,0,0,0,0,0,0,0
0,0,0,0,0,0,0,0,0,0,0,0,0,0,0,0,0,0,0,0,0,0,0,0,0,0,0,0,0,0
0,0,0,0,0,0,0,0,0,0,0,0,0,0,0,0,0,0,0,0,0,0,0,0,0,0,0,0,0,0
0,0,0,0,0,0,0,0,0,0,0,0,0,0,0,0,0,0,0,0,0,0,0,0,0,0,0,0,0,0
0,0,0,0,0,0,0,0,0,0,0,0,0,0,0,0,0,0,0,0,0,0,0,0,0,0,0,0,0,0
0,0,0,0,0,0,0,0,0,0,0,0,0,0,0,0,0,0,0,0,0,0,0,0,0,0,0,0,0,0
0,0,0,0,0,0,0,0,0,0,0,0,0,0,0,0,0,0,0,0,0,0,0,0,0,0,0,0,0,0
0,0,0,0,0,0,0,0,0,0,0,0,0,0,0,0,0,0,0,0,0,0,0,0,0,0,0,0,0,0
0,0,0,0,0,0,0,0,0,0,0,0,0,0,0,0,0,0,0,0,0,0,0,0,0,0,0,0,0,0
0,0,0,0,0,0,0,0,0,0,0,0,0,0,0,0,0,0,0,0,0,0,0,0,0,0,0,0,0,0
0,0,0,0,0,0,0,0,0,0,0,0,0,0,0,0,0,0,0,0,0,0,0,0,0,0,0,0,0,0
0,0,0,0,0,0,0,0,0,0,0,0,0,0,0,0,0,0,0,0,0,0,0,0,0,0,0,0,0,0
0,0,0,0,0,0,0,0,0,0,0,0,0,0,0,0,0,0,0,0,0,0,0,0,0,0,0,0,0,0
0,0,0,0,0,0,0,0,0,0,0,0,0,0,0,0,0,0,0,0,0,0,0,0,0,0,0,0,0,0
0,0,0,0,0,0,0,0,0,0,0,0,0,0,0,0,0,0,0,0,0,0,0,0,0,0,0,0,0,0
0,0,0,0,0,0,0,0,0,0,57,0,0,0,0,0,0,0,0,0,0,0,0,0,0,0,0,0,0,0
endlayer

