
# Created by Ruins mod version 14.4 Ingame Parser
# authoring Player: Mikhaila666

weight=1
embed_into_distance=0
acceptable_target_blocks=
unacceptable_target_blocks=flowing_water,water,flowing_lava,lava
dimensions=22,13,40
allowable_overhang=0
max_leveling=2
leveling_buffer=0
preserve_water=0
preserve_lava=0

rule1=0,100,minecraft:stone-0
rule2=0,100,minecraft:quartz_block-0
rule3=0,100,minecraft:quartz_stairs-0
rule4=0,100,minecraft:quartz_stairs-2
rule5=0,100,minecraft:quartz_stairs-3
rule6=0,100,minecraft:quartz_stairs-1
rule7=0,100,minecraft:quartz_stairs-4
rule8=0,100,minecraft:quartz_block-2
rule9=0,100,minecraft:stone_slab-7
rule10=0,100,minecraft:quartz_stairs-6
rule11=0,100,minecraft:quartz_stairs-7
rule12=0,100,Railcraft:tile.railcraft.residual.heat-0
rule13=0,100,minecraft:quartz_stairs-5
rule14=2,100,minecraft:torch-1
rule15=2,100,minecraft:torch-3
rule16=2,100,minecraft:torch-4
rule17=2,100,minecraft:torch-2
rule18=0,100,minecraft:stone_slab-15
rule19=0,100,minecraft:stone_stairs-0
rule20=0,100,minecraft:stone_stairs-1
rule21=0,100,minecraft:cobblestone-0

layer
1,1,1,0,1,1,1,0,1,1,1,0,1,1,1,0,1,1,1,0,1,1,1,0,0,0,0,0,0,0,0,0,0,0,0,0,0,0,0,0
1,1,0,0,0,0,0,0,0,0,0,0,0,0,0,0,0,0,0,0,0,1,1,0,0,0,0,0,0,0,0,0,0,0,0,0,0,0,0,0
1,0,0,1,1,1,1,1,1,1,1,1,1,1,1,1,1,1,1,1,0,0,1,0,0,0,0,0,0,0,0,0,0,0,0,0,0,0,0,0
1,1,0,1,1,1,1,1,1,1,1,1,1,1,1,1,1,1,1,1,0,1,1,0,0,0,0,0,0,0,0,0,0,0,0,0,0,0,0,0
1,1,0,1,1,1,1,1,1,1,1,1,1,1,1,1,1,1,1,1,0,2,1,0,0,0,0,0,0,0,0,0,0,0,0,0,0,0,0,0
1,1,0,1,1,1,1,1,1,1,1,1,1,1,1,1,1,1,1,1,0,2,1,0,0,0,0,0,0,0,0,0,0,0,0,0,0,0,0,0
1,0,0,1,1,1,1,1,1,1,1,1,1,1,1,1,1,1,1,1,0,0,1,0,0,0,0,0,0,0,0,0,0,0,0,0,0,0,0,0
1,1,0,1,1,1,1,1,1,1,1,1,1,1,1,1,1,1,1,1,0,1,1,0,0,0,0,0,0,0,0,0,0,0,0,0,0,0,0,0
1,1,0,1,1,1,1,1,1,1,1,1,1,1,1,1,1,1,1,1,0,1,1,0,0,0,0,0,0,0,0,0,0,0,0,0,0,0,0,0
1,1,0,1,1,1,1,1,1,1,1,1,1,1,1,1,1,1,1,1,0,1,1,0,0,0,0,0,0,0,0,0,0,0,0,0,0,0,0,0
1,0,0,1,1,1,1,1,1,1,1,1,1,1,1,1,1,1,1,1,0,0,1,0,0,0,0,0,0,0,0,0,0,0,0,0,0,0,0,0
1,1,0,0,0,0,0,0,0,0,0,0,0,0,0,0,0,0,0,0,0,1,1,0,0,0,0,0,0,0,0,0,0,0,0,0,0,0,0,0
1,1,1,0,1,1,1,0,1,1,1,0,1,1,1,0,1,1,1,0,1,1,1,0,0,0,0,0,0,0,0,0,0,0,0,0,0,0,0,0
endlayer

layer
0,3,3,2,3,3,3,2,3,3,3,2,3,3,3,2,3,3,3,2,3,3,0,0,0,0,0,0,0,0,0,0,0,0,0,0,0,0,0,0
0,5,2,2,2,2,2,2,2,2,2,2,2,2,2,2,2,2,2,2,2,4,0,0,0,0,0,0,0,0,0,0,0,0,0,0,0,0,0,0
0,2,2,0,0,0,0,0,0,0,0,0,0,0,0,0,0,0,0,0,2,2,0,0,0,0,0,0,0,0,0,0,0,0,0,0,0,0,0,0
0,5,2,0,0,0,0,0,0,0,0,0,0,0,0,0,0,0,0,0,2,4,0,0,0,0,0,0,0,0,0,0,0,0,0,0,0,0,0,0
0,5,2,0,0,0,0,0,0,0,0,0,0,0,0,0,0,0,0,0,2,4,0,0,0,0,0,0,0,0,0,0,0,0,0,0,0,0,0,0
0,5,2,0,0,0,0,0,0,0,0,0,0,0,0,0,0,0,0,0,2,4,0,0,0,0,0,0,0,0,0,0,0,0,0,0,0,0,0,0
0,2,2,0,0,0,0,0,0,0,0,0,0,0,0,0,0,0,0,0,2,2,0,0,0,0,0,0,0,0,0,0,0,0,0,0,0,0,0,0
0,5,2,0,0,0,0,0,0,0,0,0,0,0,0,0,0,0,0,0,2,4,0,0,0,0,0,0,0,0,0,0,0,0,0,0,0,0,0,0
0,5,2,0,0,0,0,0,0,0,0,0,0,0,0,0,0,0,0,0,2,4,0,0,0,0,0,0,0,0,0,0,0,0,0,0,0,0,0,0
0,5,2,0,0,0,0,0,0,0,0,0,0,0,0,0,0,0,0,0,2,4,0,0,0,0,0,0,0,0,0,0,0,0,0,0,0,0,0,0
0,2,2,0,0,0,0,0,0,0,0,0,0,0,0,0,0,0,0,0,2,2,0,0,0,0,0,0,0,0,0,0,0,0,0,0,0,0,0,0
0,5,2,2,2,2,2,2,2,2,2,2,2,2,2,2,2,2,2,2,2,4,0,0,0,0,0,0,0,0,0,0,0,0,0,0,0,0,0,0
0,6,6,2,6,6,6,2,6,6,6,2,6,6,6,2,6,6,6,2,6,6,0,0,0,0,0,0,0,0,0,0,0,0,0,0,0,0,0,0
endlayer

layer
0,7,7,8,9,9,9,8,0,0,0,8,0,0,0,8,9,9,9,8,7,7,0,0,0,0,0,0,0,0,0,0,0,0,0,0,0,0,0,0
0,11,2,0,2,3,2,2,0,0,0,2,0,0,0,2,2,3,2,0,2,10,0,0,0,0,0,0,0,0,0,0,0,0,0,0,0,0,0,0
0,8,0,0,0,0,0,0,0,0,0,0,0,0,0,0,0,0,0,0,0,8,0,0,0,0,0,0,0,0,0,0,0,0,0,0,0,0,0,0
0,9,2,0,0,0,0,0,0,0,0,0,0,0,0,0,0,0,0,0,2,9,0,0,0,0,0,0,0,0,0,0,0,0,0,0,0,0,0,0
0,9,5,0,0,0,0,0,0,0,0,0,0,0,0,0,0,0,0,0,4,9,0,0,12,0,0,0,0,0,0,0,0,0,0,0,0,0,0,0
0,9,2,0,0,0,0,0,0,0,0,0,0,0,0,0,0,0,0,0,2,9,0,0,0,0,0,0,0,0,0,0,0,0,0,0,0,0,0,0
0,8,0,0,0,0,0,0,0,0,0,0,0,0,0,0,0,0,0,0,0,8,0,0,0,0,0,0,0,0,0,0,0,0,0,0,0,0,0,0
0,9,2,0,0,0,0,0,0,0,0,0,0,0,0,0,0,0,0,0,2,9,0,0,0,0,0,0,0,0,0,0,0,0,0,0,0,0,0,0
0,9,5,0,0,0,0,0,0,0,0,0,0,0,0,0,0,0,0,0,4,9,0,0,0,0,0,0,0,0,0,0,0,0,0,0,0,0,0,0
0,9,2,0,0,0,0,0,0,0,0,0,0,0,0,0,0,0,0,0,2,9,0,0,0,0,0,0,0,0,0,0,0,0,0,0,0,0,0,0
0,8,0,0,0,0,0,0,0,0,0,0,0,0,0,0,0,0,0,0,0,8,0,0,0,0,0,0,0,0,0,0,0,0,0,0,0,0,0,0
0,11,2,0,2,6,2,2,0,0,0,2,0,0,0,2,2,6,2,0,2,10,0,0,0,0,0,0,0,0,0,0,0,0,0,0,0,0,0,0
0,13,13,8,9,9,9,8,0,0,0,8,0,0,0,8,9,9,9,8,13,13,0,0,0,0,0,0,0,0,0,0,0,0,0,0,0,0,0,0
endlayer

layer
0,0,0,8,0,0,0,8,0,0,0,8,0,0,0,8,0,0,0,8,0,0,0,0,0,0,0,0,0,0,0,0,0,0,0,0,0,0,0,0
0,0,2,0,2,0,2,2,0,0,0,2,0,0,0,2,2,0,2,0,2,0,0,0,0,0,0,0,0,0,0,0,0,0,0,0,0,0,0,0
0,8,0,0,0,0,0,0,0,0,0,14,0,0,0,0,0,0,0,0,0,8,0,0,0,0,0,0,0,0,0,0,0,0,0,0,0,0,0,0
0,0,2,0,0,0,0,0,0,0,0,0,0,0,0,0,0,0,0,0,2,0,0,0,0,0,0,0,0,0,0,0,0,0,0,0,0,0,0,0
0,0,0,0,0,0,0,0,0,0,0,0,0,0,0,0,0,0,0,0,0,0,0,0,0,0,0,0,0,0,0,0,0,0,0,0,0,0,0,0
0,0,2,0,0,0,0,0,0,0,0,0,0,0,0,0,0,0,0,0,2,0,0,0,0,0,0,0,0,0,0,0,0,0,0,0,0,0,0,0
0,8,16,0,0,0,0,0,0,0,0,0,0,0,0,0,0,0,0,0,15,8,0,0,0,0,0,0,0,0,0,0,0,0,0,0,0,0,0,0
0,0,2,0,0,0,0,0,0,0,0,0,0,0,0,0,0,0,0,0,2,0,0,0,0,0,0,0,0,0,0,0,0,0,0,0,0,0,0,0
0,0,0,0,0,0,0,0,0,0,0,0,0,0,0,0,0,0,0,0,0,0,0,0,0,0,0,0,0,0,0,0,0,0,0,0,0,0,0,0
0,0,2,0,0,0,0,0,0,0,0,0,0,0,0,0,0,0,0,0,2,0,0,0,0,0,0,0,0,0,0,0,0,0,0,0,0,0,0,0
0,8,0,0,0,0,0,0,0,0,0,17,0,0,0,0,0,0,0,0,0,8,0,0,0,0,0,0,0,0,0,0,0,0,0,0,0,0,0,0
0,0,2,0,2,0,2,2,0,0,0,2,0,0,0,2,2,0,2,0,2,0,0,0,0,0,0,0,0,0,0,0,0,0,0,0,0,0,0,0
0,0,0,8,0,0,0,8,0,0,0,8,0,0,0,8,0,0,0,8,0,0,0,0,0,0,0,0,0,0,0,0,0,0,0,0,0,0,0,0
endlayer

layer
0,0,0,8,0,0,0,8,0,0,0,8,0,0,0,8,0,0,0,8,0,0,0,0,0,0,0,0,0,0,0,0,0,0,0,0,0,0,0,0
0,0,2,0,2,0,2,2,0,0,0,2,0,0,0,2,2,0,2,0,2,0,0,0,0,0,0,0,0,0,0,0,0,0,0,0,0,0,0,0
0,8,0,0,0,0,0,0,0,0,0,0,0,0,0,0,0,0,0,0,0,8,0,0,0,0,0,0,0,0,0,0,0,0,0,0,0,0,0,0
0,0,2,0,0,0,0,0,0,0,0,0,0,0,0,0,0,0,0,0,2,0,0,0,0,0,0,0,0,0,0,0,0,0,0,0,0,0,0,0
0,0,0,0,0,0,0,0,0,0,0,0,0,0,0,0,0,0,0,0,0,0,0,0,0,0,0,0,0,0,0,0,0,0,0,0,0,0,0,0
0,0,2,0,0,0,0,0,0,0,0,0,0,0,0,0,0,0,0,0,2,0,0,0,0,0,0,0,0,0,0,0,0,0,0,0,0,0,0,0
0,8,0,0,0,0,0,0,0,0,0,0,0,0,0,0,0,0,0,0,0,8,0,0,0,0,0,0,0,0,0,0,0,0,0,0,0,0,0,0
0,0,2,0,0,0,0,0,0,0,0,0,0,0,0,0,0,0,0,0,2,0,0,0,0,0,0,0,0,0,0,0,0,0,0,0,0,0,0,0
0,0,0,0,0,0,0,0,0,0,0,0,0,0,0,0,0,0,0,0,0,0,0,0,0,0,0,0,0,0,0,0,0,0,0,0,0,0,0,0
0,0,2,0,0,0,0,0,0,0,0,0,0,0,0,0,0,0,0,0,2,0,0,0,0,0,0,0,0,0,0,0,0,0,0,0,0,0,0,0
0,8,0,0,0,0,0,0,0,0,0,0,0,0,0,0,0,0,0,0,0,8,0,0,0,0,0,0,0,0,0,0,0,0,0,0,0,0,0,0
0,0,2,0,2,0,2,2,0,0,0,2,0,0,0,2,2,0,2,0,2,0,0,0,0,0,0,0,0,0,0,0,0,0,0,0,0,0,0,0
0,0,0,8,0,0,0,8,0,0,0,8,0,0,0,8,0,0,0,8,0,0,0,0,0,0,0,0,0,0,0,0,0,0,0,0,0,0,0,0
endlayer

layer
0,0,0,8,0,0,0,8,0,0,0,8,0,0,0,8,0,0,0,8,0,0,0,0,0,0,0,0,0,0,0,0,0,0,0,0,0,0,0,0
0,0,2,0,2,7,2,2,10,18,11,2,10,18,11,2,2,7,2,0,2,0,0,0,0,0,0,0,0,0,0,0,0,0,0,0,0,0,0,0
0,8,0,0,0,0,0,0,0,0,0,0,0,0,0,0,0,0,0,0,0,8,0,0,0,0,0,0,0,0,0,0,0,0,0,0,0,0,0,0
0,0,2,0,0,0,0,0,0,0,0,0,0,0,0,0,0,0,0,0,2,0,0,0,0,0,0,0,0,0,0,0,0,0,0,0,0,0,0,0
0,0,11,0,0,0,0,0,0,0,0,0,0,0,0,0,0,0,0,0,10,0,0,0,0,0,0,0,0,0,0,0,0,0,0,0,0,0,0,0
0,0,2,0,0,0,0,0,0,0,0,0,0,0,0,0,0,0,0,0,2,0,0,0,0,0,0,0,0,0,0,0,0,0,0,0,0,0,0,0
0,8,0,0,0,0,0,0,0,0,0,0,0,0,0,0,0,0,0,0,0,8,0,0,0,0,0,0,0,0,0,0,0,0,0,0,0,0,0,0
0,0,2,0,0,0,0,0,0,0,0,0,0,0,0,0,0,0,0,0,2,0,0,0,0,0,0,0,0,0,0,0,0,0,0,0,0,0,0,0
0,0,11,0,0,0,0,0,0,0,0,0,0,0,0,0,0,0,0,0,10,0,0,0,0,0,0,0,0,0,0,0,0,0,0,0,0,0,0,0
0,0,2,0,0,0,0,0,0,0,0,0,0,0,0,0,0,0,0,0,2,0,0,0,0,0,0,0,0,0,0,0,0,0,0,0,0,0,0,0
0,8,0,0,0,0,0,0,0,0,0,0,0,0,0,0,0,0,0,0,0,8,0,0,0,0,0,0,0,0,0,0,0,0,0,0,0,0,0,0
0,0,2,0,2,13,2,2,10,18,11,2,10,18,11,2,2,13,2,0,2,0,0,0,0,0,0,0,0,0,0,0,0,0,0,0,0,0,0,0
0,0,0,8,0,0,0,8,0,0,0,8,0,0,0,8,0,0,0,8,0,0,0,0,0,0,0,0,0,0,0,0,0,0,0,0,0,0,0,0
endlayer

layer
0,5,3,2,10,0,11,2,10,0,11,2,10,0,11,2,10,0,11,2,3,4,0,0,0,0,0,0,0,0,0,0,0,0,0,0,0,0,0,0
0,5,2,0,2,2,2,0,2,2,2,0,2,2,2,0,2,2,2,0,2,4,0,0,0,0,0,0,0,0,0,0,0,0,0,0,0,0,0,0
11,2,0,0,0,0,0,0,0,0,0,0,0,0,0,0,0,0,0,0,0,2,10,0,0,0,0,0,0,0,0,0,0,0,0,0,0,0,0,0
11,13,2,0,0,0,0,0,0,0,0,0,0,0,0,0,0,0,0,0,2,13,10,0,0,0,0,0,0,0,0,0,0,0,0,0,0,0,0,0
0,0,2,0,0,0,0,0,0,0,0,0,0,0,0,0,0,0,0,0,2,0,0,0,0,0,0,0,0,0,0,0,0,0,0,0,0,0,0,0
11,7,2,0,0,0,0,0,0,0,0,0,0,0,0,0,0,0,0,0,2,7,10,0,0,0,0,0,0,0,0,0,0,0,0,0,0,0,0,0
11,2,0,0,0,0,0,0,0,0,0,0,0,0,0,0,0,0,0,0,0,2,10,0,0,0,0,0,0,0,0,0,0,0,0,0,0,0,0,0
11,13,2,0,0,0,0,0,0,0,0,0,0,0,0,0,0,0,0,0,2,13,10,0,0,0,0,0,0,0,0,0,0,0,0,0,0,0,0,0
0,0,2,0,0,0,0,0,0,0,0,0,0,0,0,0,0,0,0,0,2,0,0,0,0,0,0,0,0,0,0,0,0,0,0,0,0,0,0,0
11,7,2,0,0,0,0,0,0,0,0,0,0,0,0,0,0,0,0,0,2,7,10,0,0,0,0,0,0,0,0,0,0,0,0,0,0,0,0,0
11,2,0,0,0,0,0,0,0,0,0,0,0,0,0,0,0,0,0,0,0,2,10,0,0,0,0,0,0,0,0,0,0,0,0,0,0,0,0,0
0,5,2,0,2,2,2,0,2,2,2,0,2,2,2,0,2,2,2,0,2,4,0,0,0,0,0,0,0,0,0,0,0,0,0,0,0,0,0,0
0,5,6,2,10,0,11,2,10,0,11,2,10,0,11,2,10,0,11,2,6,4,0,0,0,0,0,0,0,0,0,0,0,0,0,0,0,0,0,0
endlayer

layer
0,11,7,2,2,2,2,2,2,2,2,2,2,2,2,2,2,2,2,2,7,10,0,0,0,0,0,0,0,0,0,0,0,0,0,0,0,0,0,0
0,11,2,0,0,0,0,0,0,0,0,0,0,0,0,0,0,0,0,0,2,10,0,0,0,0,0,0,0,0,0,0,0,0,0,0,0,0,0,0
0,2,0,0,0,0,0,0,0,0,0,0,0,0,0,0,0,0,0,0,0,2,0,0,0,0,0,0,0,0,0,0,0,0,0,0,0,0,0,0
3,2,0,0,0,0,0,0,0,0,0,0,0,0,0,0,0,0,0,0,0,2,3,0,0,0,0,0,0,0,0,0,0,0,0,0,0,0,0,0
2,2,0,0,0,0,0,0,0,0,0,0,0,0,0,0,0,0,0,0,0,2,2,0,0,0,0,0,0,0,0,0,0,0,0,0,0,0,0,0
6,2,0,0,0,0,0,0,0,0,0,0,0,0,0,0,0,0,0,0,0,2,6,0,0,0,0,0,0,0,0,0,0,0,0,0,0,0,0,0
0,2,0,0,0,0,0,0,0,0,0,0,0,0,0,0,0,0,0,0,0,2,0,0,0,0,0,0,0,0,0,0,0,0,0,0,0,0,0,0
3,2,0,0,0,0,0,0,0,0,0,0,0,0,0,0,0,0,0,0,0,2,3,0,0,0,0,0,0,0,0,0,0,0,0,0,0,0,0,0
2,2,0,0,0,0,0,0,0,0,0,0,0,0,0,0,0,0,0,0,0,2,2,0,0,0,0,0,0,0,0,0,0,0,0,0,0,0,0,0
6,2,0,0,0,0,0,0,0,0,0,0,0,0,0,0,0,0,0,0,0,2,6,0,0,0,0,0,0,0,0,0,0,0,0,0,0,0,0,0
0,2,0,0,0,0,0,0,0,0,0,0,0,0,0,0,0,0,0,0,0,2,0,0,0,0,0,0,0,0,0,0,0,0,0,0,0,0,0,0
0,11,2,0,0,0,0,0,0,0,0,0,0,0,0,0,0,0,0,0,2,10,0,0,0,0,0,0,0,0,0,0,0,0,0,0,0,0,0,0
0,11,13,2,2,2,2,2,2,2,2,2,2,2,2,2,2,2,2,2,13,10,0,0,0,0,0,0,0,0,0,0,0,0,0,0,0,0,0,0
endlayer

layer
0,0,0,2,0,0,0,2,0,0,0,2,0,0,0,2,0,0,0,2,0,0,0,0,0,0,0,0,0,0,0,0,0,0,0,0,0,0,0,0
0,0,2,2,2,2,2,2,2,2,2,2,2,2,2,2,2,2,2,2,2,0,0,0,0,0,0,0,0,0,0,0,0,0,0,0,0,0,0,0
0,2,2,0,0,0,0,0,0,0,0,0,0,0,0,0,0,0,0,0,2,2,0,0,0,0,0,0,0,0,0,0,0,0,0,0,0,0,0,0
0,0,2,0,0,0,0,0,0,0,0,0,0,0,0,0,0,0,0,0,2,0,0,0,0,0,0,0,0,0,0,0,0,0,0,0,0,0,0,0
0,0,2,0,0,0,0,0,0,0,0,0,0,0,0,0,0,0,0,0,2,0,0,0,0,0,0,0,0,0,0,0,0,0,0,0,0,0,0,0
0,0,2,0,0,0,0,0,0,0,0,0,0,0,0,0,0,0,0,0,2,0,0,0,0,0,0,0,0,0,0,0,0,0,0,0,0,0,0,0
0,2,2,0,0,0,0,0,0,0,0,0,0,0,0,0,0,0,0,0,2,2,0,0,0,0,0,0,0,0,0,0,0,0,0,0,0,0,0,0
0,0,2,0,0,0,0,0,0,0,0,0,0,0,0,0,0,0,0,0,2,0,0,0,0,0,0,0,0,0,0,0,0,0,0,0,0,0,0,0
0,0,2,0,0,0,0,0,0,0,0,0,0,0,0,0,0,0,0,0,2,0,0,0,0,0,0,0,0,0,0,0,0,0,0,0,0,0,0,0
0,0,2,0,0,0,0,0,0,0,0,0,0,0,0,0,0,0,0,0,2,0,0,0,0,0,0,0,0,0,0,0,0,0,0,0,0,0,0,0
0,2,2,0,0,0,0,0,0,0,0,0,0,0,0,0,0,0,0,0,2,2,0,0,0,0,0,0,0,0,0,0,0,0,0,0,0,0,0,0
0,0,2,2,2,2,2,2,2,2,2,2,2,2,2,2,2,2,2,2,2,0,0,0,0,0,0,0,0,0,0,0,0,0,0,0,0,0,0,0
0,0,0,2,0,0,0,2,0,0,0,2,0,0,0,2,0,0,0,2,0,0,0,0,0,0,0,0,0,0,0,0,0,0,0,0,0,0,0,0
endlayer

layer
0,0,0,8,0,0,0,8,0,0,0,8,0,0,0,8,0,0,0,8,0,0,0,0,0,0,0,0,0,0,0,0,0,0,0,0,0,0,0,0
0,0,2,0,2,3,2,0,2,3,2,0,2,3,2,0,2,3,2,0,2,0,0,0,0,0,0,0,0,0,0,0,0,0,0,0,0,0,0,0
0,8,0,0,0,0,0,0,0,0,0,0,0,0,0,0,0,0,0,0,0,8,0,0,0,0,0,0,0,0,0,0,0,0,0,0,0,0,0,0
0,0,2,0,0,0,0,0,0,0,0,0,0,0,0,0,0,0,0,0,2,0,0,0,0,0,0,0,0,0,0,0,0,0,0,0,0,0,0,0
0,0,5,0,0,0,0,0,0,0,0,0,0,0,0,0,0,0,0,0,4,0,0,0,0,0,0,0,0,0,0,0,0,0,0,0,0,0,0,0
0,0,2,0,0,0,0,0,0,0,0,0,0,0,0,0,0,0,0,0,2,0,0,0,0,0,0,0,0,0,0,0,0,0,0,0,0,0,0,0
0,8,0,0,0,0,0,0,0,0,0,0,0,0,0,0,0,0,0,0,0,8,0,0,0,0,0,0,0,0,0,0,0,0,0,0,0,0,0,0
0,0,2,0,0,0,0,0,0,0,0,0,0,0,0,0,0,0,0,0,2,0,0,0,0,0,0,0,0,0,0,0,0,0,0,0,0,0,0,0
0,0,5,0,0,0,0,0,0,0,0,0,0,0,0,0,0,0,0,0,4,0,0,0,0,0,0,0,0,0,0,0,0,0,0,0,0,0,0,0
0,0,2,0,0,0,0,0,0,0,0,0,0,0,0,0,0,0,0,0,2,0,0,0,0,0,0,0,0,0,0,0,0,0,0,0,0,0,0,0
0,8,0,0,0,0,0,0,0,0,0,0,0,0,0,0,0,0,0,0,0,8,0,0,0,0,0,0,0,0,0,0,0,0,0,0,0,0,0,0
0,0,2,0,2,6,2,0,2,6,2,0,2,6,2,0,2,6,2,0,2,0,0,0,0,0,0,0,0,0,0,0,0,0,0,0,0,0,0,0
0,0,0,8,0,0,0,8,0,0,0,8,0,0,0,8,0,0,0,8,0,0,0,0,0,0,0,0,0,0,0,0,0,0,0,0,0,0,0,0
endlayer

layer
0,0,0,8,0,0,0,8,0,0,0,8,0,0,0,8,0,0,0,8,0,0,0,0,0,0,0,0,0,0,0,0,0,0,0,0,0,0,0,0
0,0,2,14,2,0,2,14,2,0,2,14,2,0,2,14,2,0,2,14,2,0,0,0,0,0,0,0,0,0,0,0,0,0,0,0,0,0,0,0
0,8,0,0,0,0,0,0,0,0,0,0,0,0,0,0,0,0,0,0,0,8,0,0,0,0,0,0,0,0,0,0,0,0,0,0,0,0,0,0
0,0,2,0,0,0,0,0,0,0,0,0,0,0,0,0,0,0,0,0,2,0,0,0,0,0,0,0,0,0,0,0,0,0,0,0,0,0,0,0
0,0,0,0,0,0,0,0,0,0,0,0,0,0,0,0,0,0,0,0,0,0,0,0,0,0,0,0,0,0,0,0,0,0,0,0,0,0,0,0
0,0,2,0,0,0,0,0,0,0,0,0,0,0,0,0,0,0,0,0,2,0,0,0,0,0,0,0,0,0,0,0,0,0,0,0,0,0,0,0
0,8,0,0,0,0,0,0,0,0,0,0,0,0,0,0,0,0,0,0,0,8,0,0,0,0,0,0,0,0,0,0,0,0,0,0,0,0,0,0
0,0,2,0,0,0,0,0,0,0,0,0,0,0,0,0,0,0,0,0,2,0,0,0,0,0,0,0,0,0,0,0,0,0,0,0,0,0,0,0
0,0,0,0,0,0,0,0,0,0,0,0,0,0,0,0,0,0,0,0,0,0,0,0,0,0,0,0,0,0,0,0,0,0,0,0,0,0,0,0
0,0,2,0,0,0,0,0,0,0,0,0,0,0,0,0,0,0,0,0,2,0,0,0,0,0,0,0,0,0,0,0,0,0,0,0,0,0,0,0
0,8,0,0,0,0,0,0,0,0,0,0,0,0,0,0,0,0,0,0,0,8,0,0,0,0,0,0,0,0,0,0,0,0,0,0,0,0,0,0
0,0,2,17,2,0,2,17,2,0,2,17,2,0,2,17,2,0,2,17,2,0,0,0,0,0,0,0,0,0,0,0,0,0,0,0,0,0,0,0
0,0,0,8,0,0,0,8,0,0,0,8,0,0,0,8,0,0,0,8,0,0,0,0,0,0,0,0,0,0,0,0,0,0,0,0,0,0,0,0
endlayer

layer
0,0,0,8,0,0,0,8,0,0,0,8,0,0,0,8,0,0,0,8,0,0,0,0,0,0,0,0,0,0,0,0,0,0,0,0,0,0,0,0
0,0,2,0,2,0,2,0,2,0,2,0,2,0,2,0,2,0,2,0,2,0,0,0,0,0,0,0,0,0,0,0,0,0,0,0,0,0,0,0
0,8,0,0,0,0,0,0,0,0,0,0,0,0,0,0,0,0,0,0,0,8,0,0,0,0,0,0,0,0,0,0,0,0,0,0,0,0,0,0
0,0,2,0,0,0,0,0,0,0,0,0,0,0,0,0,0,0,0,0,2,0,0,0,0,0,0,0,0,0,0,0,0,0,0,0,0,0,0,0
0,0,0,0,0,0,0,0,0,0,0,0,0,0,0,0,0,0,0,0,0,0,0,0,0,0,0,0,0,0,0,0,0,0,0,0,0,0,0,0
0,0,2,0,0,0,0,0,0,0,0,0,0,0,0,0,0,0,0,0,2,0,0,0,0,0,0,0,0,0,0,0,0,0,0,0,0,0,0,0
0,8,0,0,0,0,0,0,0,0,0,0,0,0,0,0,0,0,0,0,0,8,0,0,0,0,0,0,0,0,0,0,0,0,0,0,0,0,0,0
0,0,2,0,0,0,0,0,0,0,0,0,0,0,0,0,0,0,0,0,2,0,0,0,0,0,0,0,0,0,0,0,0,0,0,0,0,0,0,0
0,0,0,0,0,0,0,0,0,0,0,0,0,0,0,0,0,0,0,0,0,0,0,0,0,0,0,0,0,0,0,0,0,0,0,0,0,0,0,0
0,0,2,0,0,0,0,0,0,0,0,0,0,0,0,0,0,0,0,0,2,0,0,0,0,0,0,0,0,0,0,0,0,0,0,0,0,0,0,0
0,8,0,0,0,0,0,0,0,0,0,0,0,0,0,0,0,0,0,0,0,8,0,0,0,0,0,0,0,0,0,0,0,0,0,0,0,0,0,0
0,0,2,0,2,0,2,0,2,0,2,0,2,0,2,0,2,0,2,0,2,0,0,0,0,0,0,0,0,0,0,0,0,0,0,0,0,0,0,0
0,0,0,8,0,0,0,8,0,0,0,8,0,0,0,8,0,0,0,8,0,0,0,0,0,0,0,0,0,0,0,0,0,0,0,0,0,0,0,0
endlayer

layer
0,0,0,8,0,0,0,8,0,0,0,8,0,0,0,8,0,0,0,8,0,0,0,0,0,0,0,0,0,0,0,0,0,0,0,0,0,0,0,0
0,0,2,0,2,7,2,0,2,7,2,0,2,7,2,0,2,7,2,0,2,0,0,0,0,0,0,0,0,0,0,0,0,0,0,0,0,0,0,0
0,8,0,0,0,0,0,0,0,0,0,0,0,0,0,0,0,0,0,0,0,8,0,0,0,0,0,0,0,0,0,0,0,0,0,0,0,0,0,0
0,0,2,0,0,0,0,0,0,0,0,0,0,0,0,0,0,0,0,0,2,0,0,0,0,0,0,0,0,0,0,0,0,0,0,0,0,0,0,0
0,0,11,0,0,0,0,0,0,0,0,0,0,0,0,0,0,0,0,0,10,0,0,0,0,0,0,0,0,0,0,0,0,0,0,0,0,0,0,0
0,0,2,0,0,0,0,0,0,0,0,0,0,0,0,0,0,0,0,0,2,0,0,0,0,0,0,0,0,0,0,0,0,0,0,0,0,0,0,0
0,8,0,0,0,0,0,0,0,0,0,0,0,0,0,0,0,0,0,0,0,8,0,0,0,0,0,0,0,0,0,0,0,0,0,0,0,0,0,0
0,0,2,0,0,0,0,0,0,0,0,0,0,0,0,0,0,0,0,0,2,0,0,0,0,0,0,0,0,0,0,0,0,0,0,0,0,0,0,0
0,0,11,0,0,0,0,0,0,0,0,0,0,0,0,0,0,0,0,0,10,0,0,0,0,0,0,0,0,0,0,0,0,0,0,0,0,0,0,0
0,0,2,0,0,0,0,0,0,0,0,0,0,0,0,0,0,0,0,0,2,0,0,0,0,0,0,0,0,0,0,0,0,0,0,0,0,0,0,0
0,8,0,0,0,0,0,0,0,0,0,0,0,0,0,0,0,0,0,0,0,8,0,0,0,0,0,0,0,0,0,0,0,0,0,0,0,0,0,0
0,0,2,0,2,13,2,0,2,13,2,0,2,13,2,0,2,13,2,0,2,0,0,0,0,0,0,0,0,0,0,0,0,0,0,0,0,0,0,0
0,0,0,8,0,0,0,8,0,0,0,8,0,0,0,8,0,0,0,8,0,0,0,0,0,0,0,0,0,0,0,0,0,0,0,0,0,0,0,0
endlayer

layer
0,3,3,2,10,0,11,2,10,0,11,2,10,0,11,2,10,0,11,2,3,3,0,0,0,0,0,0,0,0,0,0,0,0,0,0,0,0,0,0
0,5,2,0,2,2,2,0,2,2,2,0,2,2,2,0,2,2,2,0,2,4,0,0,0,0,0,0,0,0,0,0,0,0,0,0,0,0,0,0
11,2,0,0,0,0,0,0,0,0,0,0,0,0,0,0,0,0,0,0,0,2,10,0,0,0,0,0,0,0,0,0,0,0,0,0,0,0,0,0
11,13,2,0,0,0,0,0,0,0,0,0,0,0,0,0,0,0,0,0,2,13,10,0,0,0,0,0,0,0,0,0,0,0,0,0,0,0,0,0
0,0,2,0,0,0,0,0,0,0,0,0,0,0,0,0,0,0,0,0,2,0,0,0,0,0,0,0,0,0,0,0,0,0,0,0,0,0,0,0
11,7,2,0,0,0,0,0,0,0,0,0,0,0,0,0,0,0,0,0,2,7,10,0,0,0,0,0,0,0,0,0,0,0,0,0,0,0,0,0
11,2,0,0,0,0,0,0,0,0,0,0,0,0,0,0,0,0,0,0,0,2,10,0,0,0,0,0,0,0,0,0,0,0,0,0,0,0,0,0
11,13,2,0,0,0,0,0,0,0,0,0,0,0,0,0,0,0,0,0,2,13,10,0,0,0,0,0,0,0,0,0,0,0,0,0,0,0,0,0
0,0,2,0,0,0,0,0,0,0,0,0,0,0,0,0,0,0,0,0,2,0,0,0,0,0,0,0,0,0,0,0,0,0,0,0,0,0,0,0
11,7,2,0,0,0,0,0,0,0,0,0,0,0,0,0,0,0,0,0,2,7,10,0,0,0,0,0,0,0,0,0,0,0,0,0,0,0,0,0
11,2,0,0,0,0,0,0,0,0,0,0,0,0,0,0,0,0,0,0,0,2,10,0,0,0,0,0,0,0,0,0,0,0,0,0,0,0,0,0
0,5,2,0,2,2,2,0,2,2,2,0,2,2,2,0,2,2,2,0,2,4,0,0,0,0,0,0,0,0,0,0,0,0,0,0,0,0,0,0
0,6,6,2,10,0,11,2,10,0,11,2,10,0,11,2,10,0,11,2,6,6,0,0,0,0,0,0,0,0,0,0,0,0,0,0,0,0,0,0
endlayer

layer
0,7,7,2,2,2,2,2,2,2,2,2,2,2,2,2,2,2,2,2,7,7,0,0,0,0,0,0,0,0,0,0,0,0,0,0,0,0,0,0
0,11,2,0,0,0,0,0,0,0,0,0,0,0,0,0,0,0,0,0,2,10,0,0,0,0,0,0,0,0,0,0,0,0,0,0,0,0,0,0
0,2,0,0,0,0,0,0,0,0,0,0,0,0,0,0,0,0,0,0,0,2,0,0,0,0,0,0,0,0,0,0,0,0,0,0,0,0,0,0
3,2,0,0,0,0,0,0,0,0,0,0,0,0,0,0,0,0,0,0,0,2,3,0,0,0,0,0,0,0,0,0,0,0,0,0,0,0,0,0
2,2,0,0,0,0,0,0,0,0,0,0,0,0,0,0,0,0,0,0,0,2,2,0,0,0,0,0,0,0,0,0,0,0,0,0,0,0,0,0
6,2,0,0,0,0,0,0,0,0,0,0,0,0,0,0,0,0,0,0,0,2,6,0,0,0,0,0,0,0,0,0,0,0,0,0,0,0,0,0
0,2,0,0,0,0,0,0,0,0,0,0,0,0,0,0,0,0,0,0,0,2,0,0,0,0,0,0,0,0,0,0,0,0,0,0,0,0,0,0
3,2,0,0,0,0,0,0,0,0,0,0,0,0,0,0,0,0,0,0,0,2,3,0,0,0,0,0,0,0,0,0,0,0,0,0,0,0,0,0
2,2,0,0,0,0,0,0,0,0,0,0,0,0,0,0,0,0,0,0,0,2,2,0,0,0,0,0,0,0,0,0,0,0,0,0,0,0,0,0
6,2,0,0,0,0,0,0,0,0,0,0,0,0,0,0,0,0,0,0,0,2,6,0,0,0,0,0,0,0,0,0,0,0,0,0,0,0,0,0
0,2,0,0,0,0,0,0,0,0,0,0,0,0,0,0,0,0,0,0,0,2,0,0,0,0,0,0,0,0,0,0,0,0,0,0,0,0,0,0
0,11,2,0,0,0,0,0,0,0,0,0,0,0,0,0,0,0,0,0,2,10,0,0,0,0,0,0,0,0,0,0,0,0,0,0,0,0,0,0
0,13,13,2,2,2,2,2,2,2,2,2,2,2,2,2,2,2,2,2,13,13,0,0,0,0,0,0,0,0,0,0,0,0,0,0,0,0,0,0
endlayer

layer
9,3,9,9,9,9,9,9,9,9,9,9,9,9,9,9,9,9,9,9,9,3,9,0,0,0,0,0,0,0,0,0,0,0,0,0,0,0,0,0
9,2,19,19,19,19,19,19,19,19,19,19,19,19,19,19,19,19,19,19,19,2,9,0,0,0,0,0,0,0,0,0,0,0,0,0,0,0,0,0
9,2,0,0,0,0,0,0,0,0,0,0,0,0,0,0,0,0,0,0,0,2,9,0,0,0,0,0,0,0,0,0,0,0,0,0,0,0,0,0
9,2,0,0,0,0,0,0,0,0,0,0,0,0,0,0,0,0,0,0,0,2,9,0,0,0,0,0,0,0,0,0,0,0,0,0,0,0,0,0
9,2,0,0,0,0,0,0,0,0,0,0,0,0,0,0,0,0,0,0,0,2,9,0,0,0,0,0,0,0,0,0,0,0,0,0,0,0,0,0
9,2,0,0,0,0,0,0,0,0,0,0,0,0,0,0,0,0,0,0,0,2,9,0,0,0,0,0,0,0,0,0,0,0,0,0,0,0,0,0
9,2,0,0,0,0,0,0,0,0,0,0,0,0,0,0,0,0,0,0,0,2,9,0,0,0,0,0,0,0,0,0,0,0,0,0,0,0,0,0
9,2,0,0,0,0,0,0,0,0,0,0,0,0,0,0,0,0,0,0,0,2,9,0,0,0,0,0,0,0,0,0,0,0,0,0,0,0,0,0
9,2,0,0,0,0,0,0,0,0,0,0,0,0,0,0,0,0,0,0,0,2,9,0,0,0,0,0,0,0,0,0,0,0,0,0,0,0,0,0
9,2,0,0,0,0,0,0,0,0,0,0,0,0,0,0,0,0,0,0,0,2,9,0,0,0,0,0,0,0,0,0,0,0,0,0,0,0,0,0
9,2,0,0,0,0,0,0,0,0,0,0,0,0,0,0,0,0,0,0,0,2,9,0,0,0,0,0,0,0,0,0,0,0,0,0,0,0,0,0
9,2,20,20,20,20,20,20,20,20,20,20,20,20,20,20,20,20,20,20,20,2,9,0,0,0,0,0,0,0,0,0,0,0,0,0,0,0,0,0
9,6,9,9,9,9,9,9,9,9,9,9,9,9,9,9,9,9,9,9,9,6,9,0,0,0,0,0,0,0,0,0,0,0,0,0,0,0,0,0
endlayer

layer
0,0,0,0,0,0,0,0,0,0,0,0,0,0,0,0,0,0,0,0,0,0,0,0,0,0,0,0,0,0,0,0,0,0,0,0,0,0,0,0
0,3,0,0,0,0,0,0,0,0,0,0,0,0,0,0,0,0,0,0,0,3,0,0,0,0,0,0,0,0,0,0,0,0,0,0,0,0,0,0
0,2,19,19,19,19,19,19,19,19,19,19,19,19,19,19,19,19,19,19,19,2,0,0,0,0,0,0,0,0,0,0,0,0,0,0,0,0,0,0
0,2,0,0,0,0,0,0,0,0,0,0,0,0,0,0,0,0,0,0,0,2,0,0,0,0,0,0,0,0,0,0,0,0,0,0,0,0,0,0
0,2,0,0,0,0,0,0,0,0,0,0,0,0,0,0,0,0,0,0,0,2,0,0,0,0,0,0,0,0,0,0,0,0,0,0,0,0,0,0
0,2,0,0,0,0,0,0,0,0,0,0,0,0,0,0,0,0,0,0,0,2,0,0,0,0,0,0,0,0,0,0,0,0,0,0,0,0,0,0
0,2,0,0,0,0,0,0,0,0,0,0,0,0,0,0,0,0,0,0,0,2,0,0,0,0,0,0,0,0,0,0,0,0,0,0,0,0,0,0
0,2,0,0,0,0,0,0,0,0,0,0,0,0,0,0,0,0,0,0,0,2,0,0,0,0,0,0,0,0,0,0,0,0,0,0,0,0,0,0
0,2,0,0,0,0,0,0,0,0,0,0,0,0,0,0,0,0,0,0,0,2,0,0,0,0,0,0,0,0,0,0,0,0,0,0,0,0,0,0
0,2,0,0,0,0,0,0,0,0,0,0,0,0,0,0,0,0,0,0,0,2,0,0,0,0,0,0,0,0,0,0,0,0,0,0,0,0,0,0
0,2,20,20,20,20,20,20,20,20,20,20,20,20,20,20,20,20,20,20,20,2,0,0,0,0,0,0,0,0,0,0,0,0,0,0,0,0,0,0
0,6,0,0,0,0,0,0,0,0,0,0,0,0,0,0,0,0,0,0,0,6,0,0,0,0,0,0,0,0,0,0,0,0,0,0,0,0,0,0
0,0,0,0,0,0,0,0,0,0,0,0,0,0,0,0,0,0,0,0,0,0,0,0,0,0,0,0,0,0,0,0,0,0,0,0,0,0,0,0
endlayer

layer
0,0,0,0,0,0,0,0,0,0,0,0,0,0,0,0,0,0,0,0,0,0,0,0,0,0,0,0,0,0,0,0,0,0,0,0,0,0,0,0
0,0,0,0,0,0,0,0,0,0,0,0,0,0,0,0,0,0,0,0,0,0,0,0,0,0,0,0,0,0,0,0,0,0,0,0,0,0,0,0
0,3,0,0,0,0,0,0,0,0,0,0,0,0,0,0,0,0,0,0,0,3,0,0,0,0,0,0,0,0,0,0,0,0,0,0,0,0,0,0
0,2,19,19,19,19,19,19,19,19,19,19,19,19,19,19,19,19,19,19,19,2,0,0,0,0,0,0,0,0,0,0,0,0,0,0,0,0,0,0
0,2,0,0,0,0,0,0,0,0,0,0,0,0,0,0,0,0,0,0,0,2,0,0,0,0,0,0,0,0,0,0,0,0,0,0,0,0,0,0
0,2,0,0,0,0,0,0,0,0,0,0,0,0,0,0,0,0,0,0,0,2,0,0,0,0,0,0,0,0,0,0,0,0,0,0,0,0,0,0
0,2,0,0,0,0,0,0,0,0,0,0,0,0,0,0,0,0,0,0,0,2,0,0,0,0,0,0,0,0,0,0,0,0,0,0,0,0,0,0
0,2,0,0,0,0,0,0,0,0,0,0,0,0,0,0,0,0,0,0,0,2,0,0,0,0,0,0,0,0,0,0,0,0,0,0,0,0,0,0
0,2,0,0,0,0,0,0,0,0,0,0,0,0,0,0,0,0,0,0,0,2,0,0,0,0,0,0,0,0,0,0,0,0,0,0,0,0,0,0
0,2,20,20,20,20,20,20,20,20,20,20,20,20,20,20,20,20,20,20,20,2,0,0,0,0,0,0,0,0,0,0,0,0,0,0,0,0,0,0
0,6,0,0,0,0,0,0,0,0,0,0,0,0,0,0,0,0,0,0,0,6,0,0,0,0,0,0,0,0,0,0,0,0,0,0,0,0,0,0
0,0,0,0,0,0,0,0,0,0,0,0,0,0,0,0,0,0,0,0,0,0,0,0,0,0,0,0,0,0,0,0,0,0,0,0,0,0,0,0
0,0,0,0,0,0,0,0,0,0,0,0,0,0,0,0,0,0,0,0,0,0,0,0,0,0,0,0,0,0,0,0,0,0,0,0,0,0,0,0
endlayer

layer
0,0,0,0,0,0,0,0,0,0,0,0,0,0,0,0,0,0,0,0,0,0,0,0,0,0,0,0,0,0,0,0,0,0,0,0,0,0,0,0
0,0,0,0,0,0,0,0,0,0,0,0,0,0,0,0,0,0,0,0,0,0,0,0,0,0,0,0,0,0,0,0,0,0,0,0,0,0,0,0
0,0,0,0,0,0,0,0,0,0,0,0,0,0,0,0,0,0,0,0,0,0,0,0,0,0,0,0,0,0,0,0,0,0,0,0,0,0,0,0
0,3,0,0,0,0,0,0,0,0,0,0,0,0,0,0,0,0,0,0,0,3,0,0,0,0,0,0,0,0,0,0,0,0,0,0,0,0,0,0
0,2,19,19,19,19,19,19,19,19,19,19,19,19,19,19,19,19,19,19,19,2,0,0,0,0,0,0,0,0,0,0,0,0,0,0,0,0,0,0
0,2,0,0,0,0,0,0,0,0,0,0,0,0,0,0,0,0,0,0,0,2,0,0,0,0,0,0,0,0,0,0,0,0,0,0,0,0,0,0
0,2,0,0,0,0,0,0,0,0,0,0,0,0,0,0,0,0,0,0,0,2,0,0,0,0,0,0,0,0,0,0,0,0,0,0,0,0,0,0
0,2,0,0,0,0,0,0,0,0,0,0,0,0,0,0,0,0,0,0,0,2,0,0,0,0,0,0,0,0,0,0,0,0,0,0,0,0,0,0
0,2,20,20,20,20,20,20,20,20,20,20,20,20,20,20,20,20,20,20,20,2,0,0,0,0,0,0,0,0,0,0,0,0,0,0,0,0,0,0
0,6,0,0,0,0,0,0,0,0,0,0,0,0,0,0,0,0,0,0,0,6,0,0,0,0,0,0,0,0,0,0,0,0,0,0,0,0,0,0
0,0,0,0,0,0,0,0,0,0,0,0,0,0,0,0,0,0,0,0,0,0,0,0,0,0,0,0,0,0,0,0,0,0,0,0,0,0,0,0
0,0,0,0,0,0,0,0,0,0,0,0,0,0,0,0,0,0,0,0,0,0,0,0,0,0,0,0,0,0,0,0,0,0,0,0,0,0,0,0
0,0,0,0,0,0,0,0,0,0,0,0,0,0,0,0,0,0,0,0,0,0,0,0,0,0,0,0,0,0,0,0,0,0,0,0,0,0,0,0
endlayer

layer
0,0,0,0,0,0,0,0,0,0,0,0,0,0,0,0,0,0,0,0,0,0,0,0,0,0,0,0,0,0,0,0,0,0,0,0,0,0,0,0
0,0,0,0,0,0,0,0,0,0,0,0,0,0,0,0,0,0,0,0,0,0,0,0,0,0,0,0,0,0,0,0,0,0,0,0,0,0,0,0
0,0,0,0,0,0,0,0,0,0,0,0,0,0,0,0,0,0,0,0,0,0,0,0,0,0,0,0,0,0,0,0,0,0,0,0,0,0,0,0
0,0,0,0,0,0,0,0,0,0,0,0,0,0,0,0,0,0,0,0,0,0,0,0,0,0,0,0,0,0,0,0,0,0,0,0,0,0,0,0
0,3,0,0,0,0,0,0,0,0,0,0,0,0,0,0,0,0,0,0,0,3,0,0,0,0,0,0,0,0,0,0,0,0,0,0,0,0,0,0
0,2,19,19,19,19,19,19,19,19,19,19,19,19,19,19,19,19,19,19,19,2,0,0,0,0,0,0,0,0,0,0,0,0,0,0,0,0,0,0
0,2,0,0,0,0,0,0,0,0,0,0,0,0,0,0,0,0,0,0,0,2,0,0,0,0,0,0,0,0,0,0,0,0,0,0,0,0,0,0
0,2,20,20,20,20,20,20,20,20,20,20,20,20,20,20,20,20,20,20,20,2,0,0,0,0,0,0,0,0,0,0,0,0,0,0,0,0,0,0
0,6,0,0,0,0,0,0,0,0,0,0,0,0,0,0,0,0,0,0,0,6,0,0,0,0,0,0,0,0,0,0,0,0,0,0,0,0,0,0
0,0,0,0,0,0,0,0,0,0,0,0,0,0,0,0,0,0,0,0,0,0,0,0,0,0,0,0,0,0,0,0,0,0,0,0,0,0,0,0
0,0,0,0,0,0,0,0,0,0,0,0,0,0,0,0,0,0,0,0,0,0,0,0,0,0,0,0,0,0,0,0,0,0,0,0,0,0,0,0
0,0,0,0,0,0,0,0,0,0,0,0,0,0,0,0,0,0,0,0,0,0,0,0,0,0,0,0,0,0,0,0,0,0,0,0,0,0,0,0
0,0,0,0,0,0,0,0,0,0,0,0,0,0,0,0,0,0,0,0,0,0,0,0,0,0,0,0,0,0,0,0,0,0,0,0,0,0,0,0
endlayer

layer
0,0,0,0,0,0,0,0,0,0,0,0,0,0,0,0,0,0,0,0,0,0,0,0,0,0,0,0,0,0,0,0,0,0,0,0,0,0,0,0
0,0,0,0,0,0,0,0,0,0,0,0,0,0,0,0,0,0,0,0,0,0,0,0,0,0,0,0,0,0,0,0,0,0,0,0,0,0,0,0
0,0,0,0,0,0,0,0,0,0,0,0,0,0,0,0,0,0,0,0,0,0,0,0,0,0,0,0,0,0,0,0,0,0,0,0,0,0,0,0
0,0,0,0,0,0,0,0,0,0,0,0,0,0,0,0,0,0,0,0,0,0,0,0,0,0,0,0,0,0,0,0,0,0,0,0,0,0,0,0
0,0,0,0,0,0,0,0,0,0,0,0,0,0,0,0,0,0,0,0,0,0,0,0,0,0,0,0,0,0,0,0,0,0,0,0,0,0,0,0
0,3,0,0,0,0,0,0,0,0,0,0,0,0,0,0,0,0,0,0,0,3,0,0,0,0,0,0,0,0,0,0,0,0,0,0,0,0,0,0
0,2,21,21,21,21,21,21,21,21,21,21,21,21,21,21,21,21,21,21,21,2,0,0,0,0,0,0,0,0,0,0,0,0,0,0,0,0,0,0
0,6,0,0,0,0,0,0,0,0,0,0,0,0,0,0,0,0,0,0,0,6,0,0,0,0,0,0,0,0,0,0,0,0,0,0,0,0,0,0
0,0,0,0,0,0,0,0,0,0,0,0,0,0,0,0,0,0,0,0,0,0,0,0,0,0,0,0,0,0,0,0,0,0,0,0,0,0,0,0
0,0,0,0,0,0,0,0,0,0,0,0,0,0,0,0,0,0,0,0,0,0,0,0,0,0,0,0,0,0,0,0,0,0,0,0,0,0,0,0
0,0,0,0,0,0,0,0,0,0,0,0,0,0,0,0,0,0,0,0,0,0,0,0,0,0,0,0,0,0,0,0,0,0,0,0,0,0,0,0
0,0,0,0,0,0,0,0,0,0,0,0,0,0,0,0,0,0,0,0,0,0,0,0,0,0,0,0,0,0,0,0,0,0,0,0,0,0,0,0
0,0,0,0,0,0,0,0,0,0,0,0,0,0,0,0,0,0,0,0,0,0,0,0,0,0,0,0,0,0,0,0,0,0,0,0,0,0,0,0
endlayer

layer
0,0,0,0,0,0,0,0,0,0,0,0,0,0,0,0,0,0,0,0,0,0,0,0,0,0,0,0,0,0,0,0,0,0,0,0,0,0,0,0
0,0,0,0,0,0,0,0,0,0,0,0,0,0,0,0,0,0,0,0,0,0,0,0,0,0,0,0,0,0,0,0,0,0,0,0,0,0,0,0
0,0,0,0,0,0,0,0,0,0,0,0,0,0,0,0,0,0,0,0,0,0,0,0,0,0,0,0,0,0,0,0,0,0,0,0,0,0,0,0
0,0,0,0,0,0,0,0,0,0,0,0,0,0,0,0,0,0,0,0,0,0,0,0,0,0,0,0,0,0,0,0,0,0,0,0,0,0,0,0
0,0,0,0,0,0,0,0,0,0,0,0,0,0,0,0,0,0,0,0,0,0,0,0,0,0,0,0,0,0,0,0,0,0,0,0,0,0,0,0
0,0,0,0,0,0,0,0,0,0,0,0,0,0,0,0,0,0,0,0,0,0,0,0,0,0,0,0,0,0,0,0,0,0,0,0,0,0,0,0
0,9,0,0,0,0,0,0,0,0,0,0,0,0,0,0,0,0,0,0,0,9,0,0,0,0,0,0,0,0,0,0,0,0,0,0,0,0,0,0
0,0,0,0,0,0,0,0,0,0,0,0,0,0,0,0,0,0,0,0,0,0,0,0,0,0,0,0,0,0,0,0,0,0,0,0,0,0,0,0
0,0,0,0,0,0,0,0,0,0,0,0,0,0,0,0,0,0,0,0,0,0,0,0,0,0,0,0,0,0,0,0,0,0,0,0,0,0,0,0
0,0,0,0,0,0,0,0,0,0,0,0,0,0,0,0,0,0,0,0,0,0,0,0,0,0,0,0,0,0,0,0,0,0,0,0,0,0,0,0
0,0,0,0,0,0,0,0,0,0,0,0,0,0,0,0,0,0,0,0,0,0,0,0,0,0,0,0,0,0,0,0,0,0,0,0,0,0,0,0
0,0,0,0,0,0,0,0,0,0,0,0,0,0,0,0,0,0,0,0,0,0,0,0,0,0,0,0,0,0,0,0,0,0,0,0,0,0,0,0
0,0,0,0,0,0,0,0,0,0,0,0,0,0,0,0,0,0,0,0,0,0,0,0,0,0,0,0,0,0,0,0,0,0,0,0,0,0,0,0
endlayer

